Workbook

Sheet Proximal Validation
A1: Ground Truth | G1: 6-Axis FT Sensor | M1: SoRoSim get_proximal_value | S1: Proximal Errors
A2: F (N) | B2: s (m) | C2: theta (rad) | D2: tau1 (N) | E2: tau2 (N) | F2: tau3 (N) | G2: Tx (Nm) | H2: Ty (Nm) | I2: Tz(Nm) | J2: Fx (N) | K2: Fy (N) | L2: Fz (N) | M2: Tx (Nm) | N2: Ty (Nm) | O2: Tz(Nm) | P2: Fx (N) | Q2: Fy (N) | R2: Fz (N) | S2: Tx (Nm) | T2: Ty (Nm) | U2: Tz(Nm) | V2: Fx (N) | W2: Fy (N) | X2: Fz (N)
A3: 0.4 | B3: 0.06 | C3: =PI()/2 -> 1.5707963 | D3: 0 | E3: 0 | F3: 0 | G3: 0.00042863237 | H3: -0.060315419 | I3: -0.00025572156 | J3: -0.04101181 | K3: 0.0007423833 | L3: 0.38065329 | S3: =G3-M3 -> 0.00042863237 | T3: =H3-N3 -> -0.060315419 | U3: =I3-O3 -> -0.00025572156 | V3: =J3-P3 -> -0.04101181 | W3: =K3-Q3 -> 0.0007423833 | X3: =L3-R3 -> 0.38065329
A4: 0.8 | B4: 0.06 | C4: =PI()/2 -> 1.5707963 | D4: 0 | E4: 0 | F4: 0 | G4: 0.00062025362 | H4: -0.1331491 | I4: -0.0002361295 | J4: -0.19782805 | K4: 0.0035987794 | L4: 0.83635294 | S4: =G4-M4 -> 0.00062025362 | T4: =H4-N4 -> -0.1331491 | U4: =I4-O4 -> -0.0002361295 | V4: =J4-P4 -> -0.19782805 | W4: =K4-Q4 -> 0.0035987794 | X4: =L4-R4 -> 0.83635294
A5: 0.3 | B5: 0.08 | C5: =PI()/2 -> 1.5707963 | D5: 0 | E5: 0 | F5: 0 | G5: 0.00016799069 | H5: -0.045721896 | I5: -0.00038841026 | J5: -0.033596165 | K5: -0.0010348894 | L5: 0.25438803 | S5: =G5-M5 -> 0.00016799069 | T5: =H5-N5 -> -0.045721896 | U5: =I5-O5 -> -0.00038841026 | V5: =J5-P5 -> -0.033596165 | W5: =K5-Q5 -> -0.0010348894 | X5: =L5-R5 -> 0.25438803
A6: 0.5 | B6: 0.1 | C6: =PI()/2 -> 1.5707963 | D6: 0 | E6: 0 | F6: 0 | G6: 0.00033436844 | H6: -0.091593102 | I6: -0.0010956251 | J6: -0.13726634 | K6: -0.0029727668 | L6: 0.44673038 | S6: =G6-M6 -> 0.00033436844 | T6: =H6-N6 -> -0.091593102 | U6: =I6-O6 -> -0.0010956251 | V6: =J6-P6 -> -0.13726634 | W6: =K6-Q6 -> -0.0029727668 | X6: =L6-R6 -> 0.44673038
A7: 0.7 | B7: 0.1 | C7: =PI()/2 -> 1.5707963 | D7: 0 | E7: 0 | F7: 0 | G7: 5.2663498e-05 | H7: -0.12548637 | I7: -0.00097444712 | J7: -0.25848296 | K7: 0.00061889738 | L7: 0.60252059 | S7: =G7-M7 -> 5.2663498e-05 | T7: =H7-N7 -> -0.12548637 | U7: =I7-O7 -> -0.00097444712 | V7: =J7-P7 -> -0.25848296 | W7: =K7-Q7 -> 0.00061889738 | X7: =L7-R7 -> 0.60252059
A8: 0.4 | B8: 0.16 | C8: =PI()/2 -> 1.5707963 | D8: 0 | E8: 0 | F8: 0 | G8: 0.00031168538 | H8: -0.07882379 | I8: -0.001017861 | J8: -0.13838193 | K8: -0.0011457466 | L8: 0.27298316 | S8: =G8-M8 -> 0.00031168538 | T8: =H8-N8 -> -0.07882379 | U8: =I8-O8 -> -0.001017861 | V8: =J8-P8 -> -0.13838193 | W8: =K8-Q8 -> -0.0011457466 | X8: =L8-R8 -> 0.27298316
A9: 0.6 | B9: 0.16 | C9: =PI()/2 -> 1.5707963 | D9: 0 | E9: 0 | F9: 0 | G9: 0.00046556734 | H9: -0.13455996 | I9: -0.0015497463 | J9: -0.33463472 | K9: -0.00056979433 | L9: 0.42998898 | S9: =G9-M9 -> 0.00046556734 | T9: =H9-N9 -> -0.13455996 | U9: =I9-O9 -> -0.0015497463 | V9: =J9-P9 -> -0.33463472 | W9: =K9-Q9 -> -0.00056979433 | X9: =L9-R9 -> 0.42998898
A10: 0.8 | B10: 0.18 | C10: =PI()/2 -> 1.5707963 | D10: 0 | E10: 0 | F10: 0 | G10: 0.0012284045 | H10: -0.11391517 | I10: -0.0020511765 | J10: -0.53618127 | K10: -0.0036365408 | L10: 0.10571924 | S10: =G10-M10 -> 0.0012284045 | T10: =H10-N10 -> -0.11391517 | U10: =I10-O10 -> -0.0020511765 | V10: =J10-P10 -> -0.53618127 | W10: =K10-Q10 -> -0.0036365408 | X10: =L10-R10 -> 0.10571924
A11: 0.3 | B11: 0.2 | C11: =PI()/2 -> 1.5707963 | D11: 0 | E11: 0 | F11: 0 | G11: -9.6103904e-05 | H11: -0.05968694 | I11: -0.00063943007 | J11: -0.076781243 | K11: -0.0018407814 | L11: 0.17655885 | S11: =G11-M11 -> -9.6103904e-05 | T11: =H11-N11 -> -0.05968694 | U11: =I11-O11 -> -0.00063943007 | V11: =J11-P11 -> -0.076781243 | W11: =K11-Q11 -> -0.0018407814 | X11: =L11-R11 -> 0.17655885
A12: 0.7 | B12: 0.2 | C12: =PI()/2 -> 1.5707963 | D12: 0 | E12: 0 | F12: 0 | G12: 0.00068014755 | H12: -0.082236603 | I12: -0.0020893728 | J12: -0.38728482 | K12: -0.00078587607 | L12: 0.033172652 | S12: =G12-M12 -> 0.00068014755 | T12: =H12-N12 -> -0.082236603 | U12: =I12-O12 -> -0.0020893728 | V12: =J12-P12 -> -0.38728482 | W12: =K12-Q12 -> -0.00078587607 | X12: =L12-R12 -> 0.033172652

Sheet Distal Vali (0N perturb)
A1: Ground Truth | G1: 6-Axis FT Sensor | M1: SoRoSim get_distal_value | Q1: Distal Errors | T1: ABS Distal Errors
A2: F (N) | B2: s (m) | C2: theta (rad) | D2: tau1 (N) | E2: tau2 (N) | F2: tau3 (N) | G2: Tx (Nm) | H2: Ty (Nm) | I2: Tz(Nm) | J2: Fx (N) | K2: Fy (N) | L2: Fz (N) | M2: F (N) | N2: s (m) | O2: theta (rad) | P2: f_final | Q2: F (N) | R2: s (m) | S2: theta (rad) | T2: F (N) | U2: s (m) | V2: theta (rad) | W2: Absolute Mean Error
A3: ='Proximal Validation'!A3 -> 0.4 | B3: ='Proximal Validation'!B3 -> 0.06 | C3: ='Proximal Validation'!C3 -> 1.5707963 | D3: ='Proximal Validation'!D3 -> 0 | E3: ='Proximal Validation'!E3 -> 0 | F3: ='Proximal Validation'!F3 -> 0 | G3: ='Proximal Validation'!G3 -> 0.00042863237 | H3: ='Proximal Validation'!H3 -> -0.060315419 | ... L3: ='Proximal Validation'!L3 -> 0.38065329 | Q3: =M3-A3 -> -0.4 | R3: =N3-B3 -> -0.06 | S3: =O3-C3 -> -1.5707963 | T3: =ABS(Q3) -> 0.4 | U3: =ABS(R3) -> 0.06 | V3: =ABS(S3) -> 1.5707963 | W3: F1 (N) | X3: s1 (m) | Y3: el1 (rad)
A4: ='Proximal Validation'!A4 -> 0.8 | B4: ='Proximal Validation'!B4 -> 0.06 | C4: ='Proximal Validation'!C4 -> 1.5707963 | D4: ='Proximal Validation'!D4 -> 0 | E4: ='Proximal Validation'!E4 -> 0 | F4: ='Proximal Validation'!F4 -> 0 | G4: ='Proximal Validation'!G4 -> 0.00062025362 | H4: ='Proximal Validation'!H4 -> -0.1331491 | ... L4: ='Proximal Validation'!L4 -> 0.83635294 | Q4: =M4-A4 -> -0.8 | R4: =N4-B4 -> -0.06 | S4: =O4-C4 -> -1.5707963 | T4: =ABS(Q4) -> 0.8 | U4: =ABS(R4) -> 0.06 | V4: =ABS(S4) -> 1.5707963 | W4: {=AVERAGE(ABS(Q3:Q12))} -> 0.55 | X4: {=AVERAGE(ABS(R3:R12))} -> 0.13 | Y4: {=AVERAGE(ABS(S3:S12))} -> 1.5707963
A5: ='Proximal Validation'!A5 -> 0.3 | B5: ='Proximal Validation'!B5 -> 0.08 | C5: ='Proximal Validation'!C5 -> 1.5707963 | D5: ='Proximal Validation'!D5 -> 0 | E5: ='Proximal Validation'!E5 -> 0 | F5: ='Proximal Validation'!F5 -> 0 | G5: ='Proximal Validation'!G5 -> 0.00016799069 | H5: ='Proximal Validation'!H5 -> -0.045721896 | ... L5: ='Proximal Validation'!L5 -> 0.25438803 | Q5: =M5-A5 -> -0.3 | R5: =N5-B5 -> -0.08 | S5: =O5-C5 -> -1.5707963 | T5: =ABS(Q5) -> 0.3 | U5: =ABS(R5) -> 0.08 | V5: =ABS(S5) -> 1.5707963
A6: ='Proximal Validation'!A6 -> 0.5 | B6: ='Proximal Validation'!B6 -> 0.1 | C6: ='Proximal Validation'!C6 -> 1.5707963 | D6: ='Proximal Validation'!D6 -> 0 | E6: ='Proximal Validation'!E6 -> 0 | F6: ='Proximal Validation'!F6 -> 0 | G6: ='Proximal Validation'!G6 -> 0.00033436844 | H6: ='Proximal Validation'!H6 -> -0.091593102 | ... L6: ='Proximal Validation'!L6 -> 0.44673038 | Q6: =M6-A6 -> -0.5 | R6: =N6-B6 -> -0.1 | S6: =O6-C6 -> -1.5707963 | T6: =ABS(Q6) -> 0.5 | U6: =ABS(R6) -> 0.1 | V6: =ABS(S6) -> 1.5707963
A7: ='Proximal Validation'!A7 -> 0.7 | B7: ='Proximal Validation'!B7 -> 0.1 | C7: ='Proximal Validation'!C7 -> 1.5707963 | D7: ='Proximal Validation'!D7 -> 0 | E7: ='Proximal Validation'!E7 -> 0 | F7: ='Proximal Validation'!F7 -> 0 | G7: ='Proximal Validation'!G7 -> 5.2663498e-05 | H7: ='Proximal Validation'!H7 -> -0.12548637 | ... L7: ='Proximal Validation'!L7 -> 0.60252059 | Q7: =M7-A7 -> -0.7 | R7: =N7-B7 -> -0.1 | S7: =O7-C7 -> -1.5707963 | T7: =ABS(Q7) -> 0.7 | U7: =ABS(R7) -> 0.1 | V7: =ABS(S7) -> 1.5707963
A8: ='Proximal Validation'!A8 -> 0.4 | B8: ='Proximal Validation'!B8 -> 0.16 | C8: ='Proximal Validation'!C8 -> 1.5707963 | D8: ='Proximal Validation'!D8 -> 0 | E8: ='Proximal Validation'!E8 -> 0 | F8: ='Proximal Validation'!F8 -> 0 | G8: ='Proximal Validation'!G8 -> 0.00031168538 | H8: ='Proximal Validation'!H8 -> -0.07882379 | ... L8: ='Proximal Validation'!L8 -> 0.27298316 | Q8: =M8-A8 -> -0.4 | R8: =N8-B8 -> -0.16 | S8: =O8-C8 -> -1.5707963 | T8: =ABS(Q8) -> 0.4 | U8: =ABS(R8) -> 0.16 | V8: =ABS(S8) -> 1.5707963
A9: ='Proximal Validation'!A9 -> 0.6 | B9: ='Proximal Validation'!B9 -> 0.16 | C9: ='Proximal Validation'!C9 -> 1.5707963 | D9: ='Proximal Validation'!D9 -> 0 | E9: ='Proximal Validation'!E9 -> 0 | F9: ='Proximal Validation'!F9 -> 0 | G9: ='Proximal Validation'!G9 -> 0.00046556734 | H9: ='Proximal Validation'!H9 -> -0.13455996 | ... L9: ='Proximal Validation'!L9 -> 0.42998898 | Q9: =M9-A9 -> -0.6 | R9: =N9-B9 -> -0.16 | S9: =O9-C9 -> -1.5707963 | T9: =ABS(Q9) -> 0.6 | U9: =ABS(R9) -> 0.16 | V9: =ABS(S9) -> 1.5707963
A10: ='Proximal Validation'!A10 -> 0.8 | B10: ='Proximal Validation'!B10 -> 0.18 | C10: ='Proximal Validation'!C10 -> 1.5707963 | D10: ='Proximal Validation'!D10 -> 0 | E10: ='Proximal Validation'!E10 -> 0 | F10: ='Proximal Validation'!F10 -> 0 | G10: ='Proximal Validation'!G10 -> 0.0012284045 | H10: ='Proximal Validation'!H10 -> -0.11391517 | ... L10: ='Proximal Validation'!L10 -> 0.10571924 | Q10: =M10-A10 -> -0.8 | R10: =N10-B10 -> -0.18 | S10: =O10-C10 -> -1.5707963 | T10: =ABS(Q10) -> 0.8 | U10: =ABS(R10) -> 0.18 | V10: =ABS(S10) -> 1.5707963
A11: ='Proximal Validation'!A11 -> 0.3 | B11: ='Proximal Validation'!B11 -> 0.2 | C11: ='Proximal Validation'!C11 -> 1.5707963 | D11: ='Proximal Validation'!D11 -> 0 | E11: ='Proximal Validation'!E11 -> 0 | F11: ='Proximal Validation'!F11 -> 0 | G11: ='Proximal Validation'!G11 -> -9.6103904e-05 | H11: ='Proximal Validation'!H11 -> -0.05968694 | ... L11: ='Proximal Validation'!L11 -> 0.17655885 | Q11: =M11-A11 -> -0.3 | R11: =N11-B11 -> -0.2 | S11: =O11-C11 -> -1.5707963 | T11: =ABS(Q11) -> 0.3 | U11: =ABS(R11) -> 0.2 | V11: =ABS(S11) -> 1.5707963
A12: ='Proximal Validation'!A12 -> 0.7 | B12: ='Proximal Validation'!B12 -> 0.2 | C12: ='Proximal Validation'!C12 -> 1.5707963 | D12: ='Proximal Validation'!D12 -> 0 | E12: ='Proximal Validation'!E12 -> 0 | F12: ='Proximal Validation'!F12 -> 0 | G12: ='Proximal Validation'!G12 -> 0.00068014755 | H12: ='Proximal Validation'!H12 -> -0.082236603 | ... L12: ='Proximal Validation'!L12 -> 0.033172652 | Q12: =M12-A12 -> -0.7 | R12: =N12-B12 -> -0.2 | S12: =O12-C12 -> -1.5707963 | T12: =ABS(Q12) -> 0.7 | U12: =ABS(R12) -> 0.2 | V12: =ABS(S12) -> 1.5707963

Sheet Distal Vali (0.5N perturb)
A1: Ground Truth | G1: 6-Axis FT Sensor | M1: SoRoSim get_distal_value (lambda = 0.5) | Q1: Distal Errors | T1: ABS Distal Errors
A2: F (N) | B2: s (m) | C2: theta (rad) | D2: tau1 (N) | E2: tau2 (N) | F2: tau3 (N) | G2: Tx (Nm) | H2: Ty (Nm) | I2: Tz(Nm) | J2: Fx (N) | K2: Fy (N) | L2: Fz (N) | M2: F (N) | N2: s (m) | O2: theta (rad) | P2: f_final | Q2: F (N) | R2: s (m) | S2: theta (rad) | T2: F (N) | U2: s (m) | V2: theta (rad) | W2: Absolute Mean Error
A3: ='Proximal Validation'!A3 -> 0.4 | B3: ='Proximal Validation'!B3 -> 0.06 | C3: ='Proximal Validation'!C3 -> 1.5707963 | D3: ='Proximal Validation'!D3 -> 0 | E3: ='Proximal Validation'!E3 -> 0 | F3: ='Proximal Validation'!F3 -> 0 | G3: ='Proximal Validation'!G3 -> 0.00042863237 | H3: ='Proximal Validation'!H3 -> -0.060315419 | ... L3: ='Proximal Validation'!L3 -> 0.38065329 | Q3: =M3-A3 -> -0.4 | R3: =N3-B3 -> -0.06 | S3: =O3-C3 -> -1.5707963 | T3: =ABS(Q3) -> 0.4 | U3: =ABS(R3) -> 0.06 | V3: =ABS(S3) -> 1.5707963 | W3: F1 (N) | X3: s1 (m) | Y3: el1 (rad)
A4: ='Proximal Validation'!A4 -> 0.8 | B4: ='Proximal Validation'!B4 -> 0.06 | C4: ='Proximal Validation'!C4 -> 1.5707963 | D4: ='Proximal Validation'!D4 -> 0 | E4: ='Proximal Validation'!E4 -> 0 | F4: ='Proximal Validation'!F4 -> 0 | G4: ='Proximal Validation'!G4 -> 0.00062025362 | H4: ='Proximal Validation'!H4 -> -0.1331491 | ... L4: ='Proximal Validation'!L4 -> 0.83635294 | Q4: =M4-A4 -> -0.8 | R4: =N4-B4 -> -0.06 | S4: =O4-C4 -> -1.5707963 | T4: =ABS(Q4) -> 0.8 | U4: =ABS(R4) -> 0.06 | V4: =ABS(S4) -> 1.5707963 | W4: {=AVERAGE(ABS(Q3:Q12))} -> 0.55 | X4: {=AVERAGE(ABS(R3:R12))} -> 0.13 | Y4: {=AVERAGE(ABS(S3:S12))} -> 1.5707963
A5: ='Proximal Validation'!A5 -> 0.3 | B5: ='Proximal Validation'!B5 -> 0.08 | C5: ='Proximal Validation'!C5 -> 1.5707963 | D5: ='Proximal Validation'!D5 -> 0 | E5: ='Proximal Validation'!E5 -> 0 | F5: ='Proximal Validation'!F5 -> 0 | G5: ='Proximal Validation'!G5 -> 0.00016799069 | H5: ='Proximal Validation'!H5 -> -0.045721896 | ... L5: ='Proximal Validation'!L5 -> 0.25438803 | Q5: =M5-A5 -> -0.3 | R5: =N5-B5 -> -0.08 | S5: =O5-C5 -> -1.5707963 | T5: =ABS(Q5) -> 0.3 | U5: =ABS(R5) -> 0.08 | V5: =ABS(S5) -> 1.5707963
A6: ='Proximal Validation'!A6 -> 0.5 | B6: ='Proximal Validation'!B6 -> 0.1 | C6: ='Proximal Validation'!C6 -> 1.5707963 | D6: ='Proximal Validation'!D6 -> 0 | E6: ='Proximal Validation'!E6 -> 0 | F6: ='Proximal Validation'!F6 -> 0 | G6: ='Proximal Validation'!G6 -> 0.00033436844 | H6: ='Proximal Validation'!H6 -> -0.091593102 | ... L6: ='Proximal Validation'!L6 -> 0.44673038 | Q6: =M6-A6 -> -0.5 | R6: =N6-B6 -> -0.1 | S6: =O6-C6 -> -1.5707963 | T6: =ABS(Q6) -> 0.5 | U6: =ABS(R6) -> 0.1 | V6: =ABS(S6) -> 1.5707963
A7: ='Proximal Validation'!A7 -> 0.7 | B7: ='Proximal Validation'!B7 -> 0.1 | C7: ='Proximal Validation'!C7 -> 1.5707963 | D7: ='Proximal Validation'!D7 -> 0 | E7: ='Proximal Validation'!E7 -> 0 | F7: ='Proximal Validation'!F7 -> 0 | G7: ='Proximal Validation'!G7 -> 5.2663498e-05 | H7: ='Proximal Validation'!H7 -> -0.12548637 | ... L7: ='Proximal Validation'!L7 -> 0.60252059 | Q7: =M7-A7 -> -0.7 | R7: =N7-B7 -> -0.1 | S7: =O7-C7 -> -1.5707963 | T7: =ABS(Q7) -> 0.7 | U7: =ABS(R7) -> 0.1 | V7: =ABS(S7) -> 1.5707963
A8: ='Proximal Validation'!A8 -> 0.4 | B8: ='Proximal Validation'!B8 -> 0.16 | C8: ='Proximal Validation'!C8 -> 1.5707963 | D8: ='Proximal Validation'!D8 -> 0 | E8: ='Proximal Validation'!E8 -> 0 | F8: ='Proximal Validation'!F8 -> 0 | G8: ='Proximal Validation'!G8 -> 0.00031168538 | H8: ='Proximal Validation'!H8 -> -0.07882379 | ... L8: ='Proximal Validation'!L8 -> 0.27298316 | Q8: =M8-A8 -> -0.4 | R8: =N8-B8 -> -0.16 | S8: =O8-C8 -> -1.5707963 | T8: =ABS(Q8) -> 0.4 | U8: =ABS(R8) -> 0.16 | V8: =ABS(S8) -> 1.5707963
A9: ='Proximal Validation'!A9 -> 0.6 | B9: ='Proximal Validation'!B9 -> 0.16 | C9: ='Proximal Validation'!C9 -> 1.5707963 | D9: ='Proximal Validation'!D9 -> 0 | E9: ='Proximal Validation'!E9 -> 0 | F9: ='Proximal Validation'!F9 -> 0 | G9: ='Proximal Validation'!G9 -> 0.00046556734 | H9: ='Proximal Validation'!H9 -> -0.13455996 | ... L9: ='Proximal Validation'!L9 -> 0.42998898 | Q9: =M9-A9 -> -0.6 | R9: =N9-B9 -> -0.16 | S9: =O9-C9 -> -1.5707963 | T9: =ABS(Q9) -> 0.6 | U9: =ABS(R9) -> 0.16 | V9: =ABS(S9) -> 1.5707963
A10: ='Proximal Validation'!A10 -> 0.8 | B10: ='Proximal Validation'!B10 -> 0.18 | C10: ='Proximal Validation'!C10 -> 1.5707963 | D10: ='Proximal Validation'!D10 -> 0 | E10: ='Proximal Validation'!E10 -> 0 | F10: ='Proximal Validation'!F10 -> 0 | G10: ='Proximal Validation'!G10 -> 0.0012284045 | H10: ='Proximal Validation'!H10 -> -0.11391517 | ... L10: ='Proximal Validation'!L10 -> 0.10571924 | Q10: =M10-A10 -> -0.8 | R10: =N10-B10 -> -0.18 | S10: =O10-C10 -> -1.5707963 | T10: =ABS(Q10) -> 0.8 | U10: =ABS(R10) -> 0.18 | V10: =ABS(S10) -> 1.5707963
A11: ='Proximal Validation'!A11 -> 0.3 | B11: ='Proximal Validation'!B11 -> 0.2 | C11: ='Proximal Validation'!C11 -> 1.5707963 | D11: ='Proximal Validation'!D11 -> 0 | E11: ='Proximal Validation'!E11 -> 0 | F11: ='Proximal Validation'!F11 -> 0 | G11: ='Proximal Validation'!G11 -> -9.6103904e-05 | H11: ='Proximal Validation'!H11 -> -0.05968694 | ... L11: ='Proximal Validation'!L11 -> 0.17655885 | Q11: =M11-A11 -> -0.3 | R11: =N11-B11 -> -0.2 | S11: =O11-C11 -> -1.5707963 | T11: =ABS(Q11) -> 0.3 | U11: =ABS(R11) -> 0.2 | V11: =ABS(S11) -> 1.5707963
A12: ='Proximal Validation'!A12 -> 0.7 | B12: ='Proximal Validation'!B12 -> 0.2 | C12: ='Proximal Validation'!C12 -> 1.5707963 | D12: ='Proximal Validation'!D12 -> 0 | E12: ='Proximal Validation'!E12 -> 0 | F12: ='Proximal Validation'!F12 -> 0 | G12: ='Proximal Validation'!G12 -> 0.00068014755 | H12: ='Proximal Validation'!H12 -> -0.082236603 | ... L12: ='Proximal Validation'!L12 -> 0.033172652 | Q12: =M12-A12 -> -0.7 | R12: =N12-B12 -> -0.2 | S12: =O12-C12 -> -1.5707963 | T12: =ABS(Q12) -> 0.7 | U12: =ABS(R12) -> 0.2 | V12: =ABS(S12) -> 1.5707963
A14: Perturbation
A15: 0.5 | B15: 0 | C15: 0
A16: 0 | B16: 0.5 | C16: 0
A17: 0 | B17: 0 | C17: 0.5
C20: Trial # | D20: tau1 (N) | E20: tau2 (N) | F20: tau3 (N) | G20: Supporting Measurments w Perturbation
C21: 1 | D21: =D3 -> 0 | E21: =E3 -> 0 | F21: =F3 -> 0 | G21: =G3 -> 0.00042863237 | H21: =H3 -> -0.060315419 | I21: =I3 -> -0.00025572156 | J21: =J3 -> -0.04101181 | K21: =K3 -> 0.0007423833 | L21: =L3 -> 0.38065329
C22: 1 | D22: =A15+D$21 -> 0.5 | E22: =B15+E$21 -> 0 | F22: =C15+F$21 -> 0 | G22: 0.00086028787 | H22: -0.054633942 | I22: -0.00037012715 | J22: -0.032283239 | K22: -0.0013680384 | L22: 0.34609789
C23: 1 | D23: =A16+D$21 -> 0 | E23: =B16+E$21 -> 0.5 | F23: =C16+F$21 -> 0 | G23: 0.00018462073 | H23: -0.054243878 | I23: -0.0001413835 | J23: -0.029981159 | K23: 0.0028523654 | L23: 0.34563753
C24: 1 | D24: =A17+D$21 -> 0 | E24: =B17+E$21 -> 0 | F24: =C17+F$21 -> 0.5 | G24: 0.00055083912 | H24: -0.065338537 | I24: -0.00026577309 | J24: -0.037093602 | K24: 0.0021730885 | L24: 0.41739151
C25: 2 | D25: 0 | E25: 0 | F25: 0 | G25: =G4 -> 0.00062025362 | H25: =H4 -> -0.1331491 | I25: =I4 -> -0.0002361295 | J25: =J4 -> -0.19782805 | K25: =K4 -> 0.0035987794 | L25: =L4 -> 0.83635294
C26: 2 | D26: 0.5 | E26: 0 | F26: 0 | G26: 0.0015044098 | H26: -0.127428 | I26: -0.00065068551 | J26: -0.18055283 | K26: -0.0018212646 | L26: 0.80400848
C27: 2 | D27: 0 | E27: 0.5 | F27: 0 | G27: -2.257782e-05 | H27: -0.12724584 | I27: 0.00015240058 | J27: -0.18084601 | K27: 0.0077832192 | L27: 0.80454743
C28: 2 | D28: 0 | E28: 0 | F28: 0.5 | G28: 0.00063802861 | H28: -0.13588068 | I28: -0.000177457 | J28: -0.19523038 | K28: 0.0048250556 | L28: 0.85887843
C29: 3 | D29: 0 | E29: 0 | F29: 0 | G29: =G5 -> 0.00016799069 | H29: =H5 -> -0.045721896 | I29: =I5 -> -0.00038841026 | J29: =J5 -> -0.033596165 | K29: =K5 -> -0.0010348894 | L29: =L5 -> 0.25438803
C30: 3 | D30: 0.5 | E30: 0 | F30: 0 | G30: 0.00042449817 | H30: -0.035818946 | I30: -0.0003615694 | J30: -0.025007732 | K30: -0.0023072995 | L30: 0.19934788
C31: 3 | D31: 0 | E31: 0.5 | F31: 0 | G31: -0.00022571202 | H31: -0.035002835 | I31: -0.00016244553 | J31: -0.024023473 | K31: 0.0017078817 | L31: 0.19539683
C32: 3 | D32: 0 | E32: 0 | F32: 0.5 | G32: 0.00014800509 | H32: -0.049277842 | I32: -0.00039798077 | J32: -0.033752002 | K32: -0.00042555109 | L32: 0.27567622
C33: 4 | D33: 0 | E33: 0 | F33: 0 | G33: =G6 -> 0.00033436844 | H33: =H6 -> -0.091593102 | I33: =I6 -> -0.0010956251 | J33: =J6 -> -0.13726634 | K33: =K6 -> -0.0029727668 | L33: =L6 -> 0.44673038
C34: 4 | D34: 0.5 | E34: 0 | F34: 0 | G34: 0.0013491128 | H34: -0.085293487 | I34: -0.001677751 | J34: -0.1257275 | K34: -0.0083918944 | L34: 0.41700935
C35: 4 | D35: 0 | E35: 0.5 | F35: 0 | G35: -0.00036837126 | H35: -0.084716849 | I35: -0.00051677279 | J35: -0.12281179 | K35: 0.0012440085 | L35: 0.41547343
C36: 4 | D36: 0 | E36: 0 | F36: 0.5 | G36: 0.00037457701 | H36: -0.096383326 | I36: -0.0011086813 | J36: -0.14044142 | K36: -0.0028370842 | L36: 0.47231984
C37: 5 | D37: 0 | E37: 0 | F37: 0 | G37: =G7 -> 5.2663498e-05 | H37: =H7 -> -0.12548637 | I37: =I7 -> -0.00097444712 | J37: =J7 -> -0.25848296 | K37: =K7 -> 0.00061889738 | L37: =L7 -> 0.60252059
C38: 5 | D38: 0.5 | E38: 0 | F38: 0 | G38: 0.0010382534 | H38: -0.11760183 | I38: -0.0015172213 | J38: -0.24127609 | K38: -0.0051122457 | L38: 0.566203
C39: 5 | D39: 0 | E39: 0.5 | F39: 0 | G39: -0.00093458337 | H39: -0.11774843 | I39: -0.00024520652 | J39: -0.24096185 | K39: 0.0066969097 | L39: 0.56751299
C40: 5 | D40: 0 | E40: 0 | F40: 0.5 | G40: -0.00013320404 | H40: -0.12632681 | I40: -0.00083597953 | J40: -0.25912681 | K40: 0.0020228773 | L40: 0.60838902
C41: 6 | D41: 0 | E41: 0 | F41: 0 | G41: =G8 -> 0.00031168538 | H41: =H8 -> -0.07882379 | I41: =I8 -> -0.001017861 | J41: =J8 -> -0.13838193 | K41: =K8 -> -0.0011457466 | L41: =L8 -> 0.27298316
C42: 6 | D42: 0.5 | E42: 0 | F42: 0 | G42: 0.0016261921 | H42: -0.072682023 | I42: -0.0021703593 | J42: -0.12710483 | K42: -0.0082274601 | L42: 0.25242263
C43: 6 | D43: 0 | E43: 0.5 | F43: 0 | G43: -0.00082752109 | H43: -0.072226621 | I43: 8.8032219e-05 | J43: -0.12602137 | K43: 0.0050658286 | L43: 0.25155869
...

Sheet Distal Vali (1N perturb)
A1: 3 Perturbations | AA1: 3 Perturbation (relative only)
A2: Ground Truth | G2: 6-Axis FT Sensor | M2: SoRoSim get_distal_value (lambda = 1) | Q2: Distal Errors | T2: ABS Distal Errors | AA2: Ground Truth | AG2: 6-Axis FT Sensor | AM2: SoRoSim get_distal_value (lambda = 1) | AQ2: Distal Errors | AT2: ABS Distal Errors
A3: F (N) | B3: s (m) | C3: theta (rad) | D3: tau1 (N) | E3: tau2 (N) | F3: tau3 (N) | G3: Tx (Nm) | H3: Ty (Nm) | I3: Tz(Nm) | J3: Fx (N) | K3: Fy (N) | L3: Fz (N) | M3: F (N) | N3: s (m) | O3: theta (rad) | P3: f_final | Q3: F (N) | R3: s (m) | S3: theta (rad) | T3: F (N) | U3: s (m) | V3: theta (rad) | W3: Absolute Mean Error | AA3: F (N) | AB3: s (m) | AC3: theta (rad) | AD3: tau1 (N) | AE3: tau2 (N) | AF3: tau3 (N) | AG3: Tx (Nm) | AH3: Ty (Nm) | AI3: Tz(Nm) | AJ3: Fx (N) | AK3: Fy (N) | AL3: Fz (N) | AM3: F (N) | AN3: s (m) | AO3: theta (rad) | AP3: f_final | AQ3: F (N) | AR3: s (m) | AS3: theta (rad) | AT3: F (N) | AU3: s (m) | AV3: theta (rad) | AW3: Absolute Mean Error
A4: ='Proximal Validation'!A3 -> 0.4 | B4: ='Proximal Validation'!B3 -> 0.06 | C4: ='Proximal Validation'!C3 -> 1.5707963 | D4: ='Proximal Validation'!D3 -> 0 | E4: ='Proximal Validation'!E3 -> 0 | F4: ='Proximal Validation'!F3 -> 0 | G4: ='Proximal Validation'!G3 -> 0.00042863237 | H4: ='Proximal Validation'!H3 -> -0.060315419 | ... L4: ='Proximal Validation'!L3 -> 0.38065329 | Q4: =M4-A4 -> -0.4 | R4: =N4-B4 -> -0.06 | S4: =O4-C4 -> -1.5707963 | T4: =ABS(Q4) -> 0.4 | U4: =ABS(R4) -> 0.06 | V4: =ABS(S4) -> 1.5707963 | W4: F1 (N) | X4: s1 (m) | Y4: el1 (rad) | AA4: ='Proximal Validation'!A3 -> 0.4 | AB4: ='Proximal Validation'!B3 -> 0.06 | AC4: ='Proximal Validation'!C3 -> 1.5707963 | AD4: ='Proximal Validation'!D3 -> 0 | AE4: ='Proximal Validation'!E3 -> 0 | AF4: ='Proximal Validation'!F3 -> 0 | AG4: ='Proximal Validation'!G3 -> 0.00042863237 | AH4: ='Proximal Validation'!H3 -> -0.060315419 | ... AL4: ='Proximal Validation'!L3 -> 0.38065329 | AM4: 0.90280937 | AN4: 0.073504807 | AO4: 1.5860914 | AP4: 0.00021199761 | AQ4: =AM4-AA4 -> 0.50280937 | AR4: =AN4-AB4 -> 0.013504807 | AS4: =AO4-AC4 -> 0.01529503 | AT4: =ABS(AQ4) -> 0.50280937 | AU4: =ABS(AR4) -> 0.013504807 | AV4: =ABS(AS4) -> 0.01529503 | AW4: F1 (N) | AX4: s1 (m) | AY4: el1 (rad)
A5: ='Proximal Validation'!A4 -> 0.8 | B5: ='Proximal Validation'!B4 -> 0.06 | C5: ='Proximal Validation'!C4 -> 1.5707963 | D5: ='Proximal Validation'!D4 -> 0 | E5: ='Proximal Validation'!E4 -> 0 | F5: ='Proximal Validation'!F4 -> 0 | G5: ='Proximal Validation'!G4 -> 0.00062025362 | H5: ='Proximal Validation'!H4 -> -0.1331491 | ... L5: ='Proximal Validation'!L4 -> 0.83635294 | Q5: =M5-A5 -> -0.8 | R5: =N5-B5 -> -0.06 | S5: =O5-C5 -> -1.5707963 | T5: =ABS(Q5) -> 0.8 | U5: =ABS(R5) -> 0.06 | V5: =ABS(S5) -> 1.5707963 | W5: {=AVERAGE(ABS(Q4:Q13))} -> 0.55 | X5: {=AVERAGE(ABS(R4:R13))} -> 0.13 | Y5: {=AVERAGE(ABS(S4:S13))} -> 1.5707963 | AA5: ='Proximal Validation'!A4 -> 0.8 | AB5: ='Proximal Validation'!B4 -> 0.06 | AC5: ='Proximal Validation'!C4 -> 1.5707963 | AD5: ='Proximal Validation'!D4 -> 0 | AE5: ='Proximal Validation'!E4 -> 0 | AF5: ='Proximal Validation'!F4 -> 0 | AG5: ='Proximal Validation'!G4 -> 0.00062025362 | AH5: ='Proximal Validation'!H4 -> -0.1331491 | ... AL5: ='Proximal Validation'!L4 -> 0.83635294 | AM5: 0.88619394 | AN5: 0.077520968 | AO5: 1.59932 | AP5: 0.00077792135 | AQ5: =AM5-AA5 -> 0.086193938 | AR5: =AN5-AB5 -> 0.017520968 | AS5: =AO5-AC5 -> 0.028523639 | AT5: =ABS(AQ5) -> 0.086193938 | AU5: =ABS(AR5) -> 0.017520968 | AV5: =ABS(AS5) -> 0.028523639 | AW5: {=AVERAGE(ABS(AQ4:AQ13))} -> 0.16765909 | AX5: {=AVERAGE(ABS(AR4:AR13))} -> 0.010799263 | AY5: {=AVERAGE(ABS(AS4:AS13))} -> 0.01340021
A6: ='Proximal Validation'!A5 -> 0.3 | B6: ='Proximal Validation'!B5 -> 0.08 | C6: ='Proximal Validation'!C5 -> 1.5707963 | D6: ='Proximal Validation'!D5 -> 0 | E6: ='Proximal Validation'!E5 -> 0 | F6: ='Proximal Validation'!F5 -> 0 | G6: ='Proximal Validation'!G5 -> 0.00016799069 | H6: ='Proximal Validation'!H5 -> -0.045721896 | ... L6: ='Proximal Validation'!L5 -> 0.25438803 | Q6: =M6-A6 -> -0.3 | R6: =N6-B6 -> -0.08 | S6: =O6-C6 -> -1.5707963 | T6: =ABS(Q6) -> 0.3 | U6: =ABS(R6) -> 0.08 | V6: =ABS(S6) -> 1.5707963 | AA6: ='Proximal Validation'!A5 -> 0.3 | AB6: ='Proximal Validation'!B5 -> 0.08 | AC6: ='Proximal Validation'!C5 -> 1.5707963 | AD6: ='Proximal Validation'!D5 -> 0 | AE6: ='Proximal Validation'!E5 -> 0 | AF6: ='Proximal Validation'!F5 -> 0 | AG6: ='Proximal Validation'!G5 -> 0.00016799069 | AH6: ='Proximal Validation'!H5 -> -0.045721896 | ... AL6: ='Proximal Validation'!L5 -> 0.25438803 | AM6: 0.63721852 | AN6: 0.08779344 | AO6: 1.5812845 | AP6: 2.170911e-05 | AQ6: =AM6-AA6 -> 0.33721852 | AR6: =AN6-AB6 -> 0.0077934401 | AS6: =AO6-AC6 -> 0.010488174 | AT6: =ABS(AQ6) -> 0.33721852 | AU6: =ABS(AR6) -> 0.0077934401 | AV6: =ABS(AS6) -> 0.010488174
A7: ='Proximal Validation'!A6 -> 0.5 | B7: ='Proximal Validation'!B6 -> 0.1 | C7: ='Proximal Validation'!C6 -> 1.5707963 | D7: ='Proximal Validation'!D6 -> 0 | E7: ='Proximal Validation'!E6 -> 0 | F7: ='Proximal Validation'!F6 -> 0 | G7: ='Proximal Validation'!G6 -> 0.00033436844 | H7: ='Proximal Validation'!H6 -> -0.091593102 | ... L7: ='Proximal Validation'!L6 -> 0.44673038 | Q7: =M7-A7 -> -0.5 | R7: =N7-B7 -> -0.1 | S7: =O7-C7 -> -1.5707963 | T7: =ABS(Q7) -> 0.5 | U7: =ABS(R7) -> 0.1 | V7: =ABS(S7) -> 1.5707963 | AA7: ='Proximal Validation'!A6 -> 0.5 | AB7: ='Proximal Validation'!B6 -> 0.1 | AC7: ='Proximal Validation'!C6 -> 1.5707963 | AD7: ='Proximal Validation'!D6 -> 0 | AE7: ='Proximal Validation'!E6 -> 0 | AF7: ='Proximal Validation'!F6 -> 0 | AG7: ='Proximal Validation'!G6 -> 0.00033436844 | AH7: ='Proximal Validation'!H6 -> -0.091593102 | ... AL7: ='Proximal Validation'!L6 -> 0.44673038 | AM7: 0.80752081 | AN7: 0.11162012 | AO7: 1.587466 | AP7: 6.3464188e-05 | AQ7: =AM7-AA7 -> 0.30752081 | AR7: =AN7-AB7 -> 0.01162012 | AS7: =AO7-AC7 -> 0.016669676 | AT7: =ABS(AQ7) -> 0.30752081 | AU7: =ABS(AR7) -> 0.01162012 | AV7: =ABS(AS7) -> 0.016669676
A8: ='Proximal Validation'!A7 -> 0.7 | B8: ='Proximal Validation'!B7 -> 0.1 | C8: ='Proximal Validation'!C7 -> 1.5707963 | D8: ='Proximal Validation'!D7 -> 0 | E8: ='Proximal Validation'!E7 -> 0 | F8: ='Proximal Validation'!F7 -> 0 | G8: ='Proximal Validation'!G7 -> 5.2663498e-05 | H8: ='Proximal Validation'!H7 -> -0.12548637 | ... L8: ='Proximal Validation'!L7 -> 0.60252059 | Q8: =M8-A8 -> -0.7 | R8: =N8-B8 -> -0.1 | S8: =O8-C8 -> -1.5707963 | T8: =ABS(Q8) -> 0.7 | U8: =ABS(R8) -> 0.1 | V8: =ABS(S8) -> 1.5707963 | AA8: ='Proximal Validation'!A7 -> 0.7 | AB8: ='Proximal Validation'!B7 -> 0.1 | AC8: ='Proximal Validation'!C7 -> 1.5707963 | AD8: ='Proximal Validation'!D7 -> 0 | AE8: ='Proximal Validation'!E7 -> 0 | AF8: ='Proximal Validation'!F7 -> 0 | AG8: ='Proximal Validation'!G7 -> 5.2663498e-05 | AH8: ='Proximal Validation'!H7 -> -0.12548637 | ... AL8: ='Proximal Validation'!L7 -> 0.60252059 | AM8: 0.88379744 | AN8: 0.11268547 | AO8: 1.5867762 | AP8: 9.2289562e-05 | AQ8: =AM8-AA8 -> 0.18379744 | AR8: =AN8-AB8 -> 0.01268547 | AS8: =AO8-AC8 -> 0.015979906 | AT8: =ABS(AQ8) -> 0.18379744 | AU8: =ABS(AR8) -> 0.01268547 | AV8: =ABS(AS8) -> 0.015979906
A9: ='Proximal Validation'!A8 -> 0.4 | B9: ='Proximal Validation'!B8 -> 0.16 | C9: ='Proximal Validation'!C8 -> 1.5707963 | D9: ='Proximal Validation'!D8 -> 0 | E9: ='Proximal Validation'!E8 -> 0 | F9: ='Proximal Validation'!F8 -> 0 | G9: ='Proximal Validation'!G8 -> 0.00031168538 | H9: ='Proximal Validation'!H8 -> -0.07882379 | ... L9: ='Proximal Validation'!L8 -> 0.27298316 | Q9: =M9-A9 -> -0.4 | R9: =N9-B9 -> -0.16 | S9: =O9-C9 -> -1.5707963 | T9: =ABS(Q9) -> 0.4 | U9: =ABS(R9) -> 0.16 | V9: =ABS(S9) -> 1.5707963 | AA9: ='Proximal Validation'!A8 -> 0.4 | AB9: ='Proximal Validation'!B8 -> 0.16 | AC9: ='Proximal Validation'!C8 -> 1.5707963 | AD9: ='Proximal Validation'!D8 -> 0 | AE9: ='Proximal Validation'!E8 -> 0 | AF9: ='Proximal Validation'!F8 -> 0 | AG9: ='Proximal Validation'!G8 -> 0.00031168538 | AH9: ='Proximal Validation'!H8 -> -0.07882379 | ... AL9: ='Proximal Validation'!L8 -> 0.27298316 | AM9: 0.37681577 | AN9: 0.17145294 | AO9: 1.5789639 | AP9: 0.00033490254 | AQ9: =AM9-AA9 -> -0.023184233 | AR9: =AN9-AB9 -> 0.011452938 | AS9: =AO9-AC9 -> 0.00816754 | AT9: =ABS(AQ9) -> 0.023184233 | AU9: =ABS(AR9) -> 0.011452938 | AV9: =ABS(AS9) -> 0.00816754
A10: ='Proximal Validation'!A9 -> 0.6 | B10: ='Proximal Validation'!B9 -> 0.16 | C10: ='Proximal Validation'!C9 -> 1.5707963 | D10: ='Proximal Validation'!D9 -> 0 | E10: ='Proximal Validation'!E9 -> 0 | F10: ='Proximal Validation'!F9 -> 0 | G10: ='Proximal Validation'!G9 -> 0.00046556734 | H10: ='Proximal Validation'!H9 -> -0.13455996 | ... L10: ='Proximal Validation'!L9 -> 0.42998898 | Q10: =M10-A10 -> -0.6 | R10: =N10-B10 -> -0.16 | S10: =O10-C10 -> -1.5707963 | T10: =ABS(Q10) -> 0.6 | U10: =ABS(R10) -> 0.16 | V10: =ABS(S10) -> 1.5707963 | AA10: ='Proximal Validation'!A9 -> 0.6 | AB10: ='Proximal Validation'!B9 -> 0.16 | AC10: ='Proximal Validation'!C9 -> 1.5707963 | AD10: ='Proximal Validation'!D9 -> 0 | AE10: ='Proximal Validation'!E9 -> 0 | AF10: ='Proximal Validation'!F9 -> 0 | AG10: ='Proximal Validation'!G9 -> 0.00046556734 | AH10: ='Proximal Validation'!H9 -> -0.13455996 | ... AL10: ='Proximal Validation'!L9 -> 0.42998898 | AM10: 0.53446525 | AN10: 0.16715554 | AO10: 1.5778248 | AP10: 0.00037814702 | AQ10: =AM10-AA10 -> -0.065534753 | AR10: =AN10-AB10 -> 0.0071555363 | AS10: =AO10-AC10 -> 0.0070285012 | AT10: =ABS(AQ10) -> 0.065534753 | AU10: =ABS(AR10) -> 0.0071555363 | AV10: =ABS(AS10) -> 0.0070285012
A11: ='Proximal Validation'!A10 -> 0.8 | B11: ='Proximal Validation'!B10 -> 0.18 | C11: ='Proximal Validation'!C10 -> 1.5707963 | D11: ='Proximal Validation'!D10 -> 0 | E11: ='Proximal Validation'!E10 -> 0 | F11: ='Proximal Validation'!F10 -> 0 | G11: ='Proximal Validation'!G10 -> 0.0012284045 | H11: ='Proximal Validation'!H10 -> -0.11391517 | ... L11: ='Proximal Validation'!L10 -> 0.10571924 | Q11: =M11-A11 -> -0.8 | R11: =N11-B11 -> -0.18 | S11: =O11-C11 -> -1.5707963 | T11: =ABS(Q11) -> 0.8 | U11: =ABS(R11) -> 0.18 | V11: =ABS(S11) -> 1.5707963 | AA11: ='Proximal Validation'!A10 -> 0.8 | AB11: ='Proximal Validation'!B10 -> 0.18 | AC11: ='Proximal Validation'!C10 -> 1.5707963 | AD11: ='Proximal Validation'!D10 -> 0 | AE11: ='Proximal Validation'!E10 -> 0 | AF11: ='Proximal Validation'!F10 -> 0 | AG11: ='Proximal Validation'!G10 -> 0.0012284045 | AH11: ='Proximal Validation'!H10 -> -0.11391517 | ... AL11: ='Proximal Validation'!L10 -> 0.10571924 | AM11: 0.7316347 | AN11: 0.17208978 | AO11: 1.5857556 | AP11: 0.00030318542 | AQ11: =AM11-AA11 -> -0.068365303 | AR11: =AN11-AB11 -> -0.0079102167 | AS11: =AO11-AC11 -> 0.014959296 | AT11: =ABS(AQ11) -> 0.068365303 | AU11: =ABS(AR11) -> 0.0079102167 | AV11: =ABS(AS11) -> 0.014959296
A12: ='Proximal Validation'!A11 -> 0.3 | B12: ='Proximal Validation'!B11 -> 0.2 | C12: ='Proximal Validation'!C11 -> 1.5707963 | D12: ='Proximal Validation'!D11 -> 0 | E12: ='Proximal Validation'!E11 -> 0 | F12: ='Proximal Validation'!F11 -> 0 | G12: ='Proximal Validation'!G11 -> -9.6103904e-05 | H12: ='Proximal Validation'!H11 -> -0.05968694 | ... L12: ='Proximal Validation'!L11 -> 0.17655885 | Q12: =M12-A12 -> -0.3 | R12: =N12-B12 -> -0.2 | S12: =O12-C12 -> -1.5707963 | T12: =ABS(Q12) -> 0.3 | U12: =ABS(R12) -> 0.2 | V12: =ABS(S12) -> 1.5707963 | AA12: ='Proximal Validation'!A11 -> 0.3 | AB12: ='Proximal Validation'!B11 -> 0.2 | AC12: ='Proximal Validation'!C11 -> 1.5707963 | AD12: ='Proximal Validation'!D11 -> 0 | AE12: ='Proximal Validation'!E11 -> 0 | AF12: ='Proximal Validation'!F11 -> 0 | AG12: ='Proximal Validation'!G11 -> -9.6103904e-05 | AH12: ='Proximal Validation'!H11 -> -0.05968694 | ... AL12: ='Proximal Validation'!L11 -> 0.17655885 | AM12: 0.29592508 | AN12: 0.2 | AO12: 1.578543 | AP12: 0.00069725326 | AQ12: =AM12-AA12 -> -0.0040749184 | AR12: =AN12-AB12 -> -2.220446e-14 | AS12: =AO12-AC12 -> 0.0077466234 | AT12: =ABS(AQ12) -> 0.0040749184 | AU12: =ABS(AR12) -> 2.220446e-14 | AV12: =ABS(AS12) -> 0.0077466234
A13: ='Proximal Validation'!A12 -> 0.7 | B13: ='Proximal Validation'!B12 -> 0.2 | C13: ='Proximal Validation'!C12 -> 1.5707963 | D13: ='Proximal Validation'!D12 -> 0 | E13: ='Proximal Validation'!E12 -> 0 | F13: ='Proximal Validation'!F12 -> 0 | G13: ='Proximal Validation'!G12 -> 0.00068014755 | H13: ='Proximal Validation'!H12 -> -0.082236603 | ... L13: ='Proximal Validation'!L12 -> 0.033172652 | Q13: =M13-A13 -> -0.7 | R13: =N13-B13 -> -0.2 | S13: =O13-C13 -> -1.5707963 | T13: =ABS(Q13) -> 0.7 | U13: =ABS(R13) -> 0.2 | V13: =ABS(S13) -> 1.5707963 | AA13: ='Proximal Validation'!A12 -> 0.7 | AB13: ='Proximal Validation'!B12 -> 0.2 | AC13: ='Proximal Validation'!C12 -> 1.5707963 | AD13: ='Proximal Validation'!D12 -> 0 | AE13: ='Proximal Validation'!E12 -> 0 | AF13: ='Proximal Validation'!F12 -> 0 | AG13: ='Proximal Validation'!G12 -> 0.00068014755 | AH13: ='Proximal Validation'!H12 -> -0.082236603 | ... AL13: ='Proximal Validation'!L12 -> 0.033172652 | AM13: 0.6021084 | AN13: 0.18165086 | AO13: 1.57994 | AP13: 0.00034643972 | AQ13: =AM13-AA13 -> -0.097891598 | AR13: =AN13-AB13 -> -0.018349136 | AS13: =AO13-AC13 -> 0.0091437122 | AT13: =ABS(AQ13) -> 0.097891598 | AU13: =ABS(AR13) -> 0.018349136 | AV13: =ABS(AS13) -> 0.0091437122
A15: Perturbation
A16: 1 | B16: 0 | C16: 0
A17: 0 | B17: 1 | C17: 0
A18: 0 | B18: 0 | C18: 1
C21: Trial # | D21: tau1 (N) | E21: tau2 (N) | F21: tau3 (N) | G21: Supporting Measurments w Perturbation
C22: 1 | D22: =D4 -> 0 | E22: =E4 -> 0 | F22: =F4 -> 0 | G22: =G4 -> 0.00042863237 | H22: =H4 -> -0.060315419 | I22: =I4 -> -0.00025572156 | J22: =J4 -> -0.04101181 | K22: =K4 -> 0.0007423833 | L22: =L4 -> 0.38065329
C23: 1 | D23: 1 | E23: 0 | F23: 0 | G23: 0.0012604678 | H23: -0.047446787 | I23: -0.00034751283 | J23: -0.021835238 | K23: -0.002463676 | L23: 0.30359501
C24: 1 | D24: 0 | E24: 1 | F24: 0 | G24: -7.1317889e-05 | H24: -0.047169726 | I24: -5.8462902e-05 | J24: -0.013929162 | K24: 0.0057888255 | L24: 0.3014673
C25: 1 | D25: 0 | E25: 0 | F25: 1 | G25: 0.00072116789 | H25: -0.073741317 | I25: -0.00031679875 | J25: -0.040545702 | K25: 0.0030917302 | L25: 0.47281098
C26: 2 | D26: 0 | E26: 0 | F26: 0 | G26: =G5 -> 0.00062025362 | H26: =H5 -> -0.1331491 | I26: =I5 -> -0.0002361295 | J26: =J5 -> -0.19782805 | K26: =K5 -> 0.0035987794 | L26: =L5 -> 0.83635294
C27: 2 | D27: 1 | E27: 0 | F27: 0 | G27: 0.0020731345 | H27: -0.12220272 | I27: -0.00084010127 | J27: -0.16897944 | K27: -0.00472413 | L27: 0.77549177
C28: 2 | D28: 0 | E28: 1 | F28: 0 | G28: -0.001110248 | H28: -0.12042395 | I28: 0.00074647646 | J28: -0.16515125 | K28: 0.014706075 | L28: 0.76510286
C29: 2 | D29: 0 | E29: 0 | F29: 1 | G29: 0.00074507506 | H29: -0.1422361 | I29: -0.00020663149 | J29: -0.20041969 | K29: 0.0049352646 | L29: 0.90020645
C30: 3 | D30: 0 | E30: 0 | F30: 0 | G30: =G6 -> 0.00016799069 | H30: =H6 -> -0.045721896 | I30: =I6 -> -0.00038841026 | J30: =J6 -> -0.033596165 | K30: =K6 -> -0.0010348894 | L30: =L6 -> 0.25438803
C31: 3 | D31: 1 | E31: 0 | F31: 0 | G31: 0.00067202863 | H31: -0.028641611 | I31: -0.00031960325 | J31: -0.014194215 | K31: -0.0034365356 | L31: 0.16055159
C32: 3 | D32: 0 | E32: 1 | F32: 0 | G32: -0.00051244441 | H32: -0.028414283 | I32: -0.00011310563 | J32: -0.012105987 | K32: 0.0034243353 | L32: 0.15853801
C33: 3 | D33: 0 | E33: 0 | F33: 1 | G33: 7.2014634e-05 | H33: -0.06300199 | I33: -0.0004600684 | J33: -0.043199942 | K33: 0.00015255436 | L33: 0.35322821
C34: 4 | D34: 0 | E34: 0 | F34: 0 | G34: =G7 -> 0.00033436844 | H34: =H7 -> -0.091593102 | I34: =I7 -> -0.0010956251 | J34: =J7 -> -0.13726634 | K34: =K7 -> -0.0029727668 | L34: =L7 -> 0.44673038
C35: 4 | D35: 1 | E35: 0 | F35: 0 | G35: 0.0022847848 | H35: -0.078242004 | I35: -0.0021650253 | J35: -0.10976673 | K35: -0.013771079 | L35: 0.38438755
C36: 4 | D36: 0 | E36: 1 | F36: 0 | G36: -0.0015284836 | H36: -0.077229537 | I36: 0.00029118359 | J36: -0.10693848 | K36: 0.0076940209 | L36: 0.37955633
C37: 4 | D37: 0 | E37: 0 | F37: 1 | G37: 0.00040927564 | H37: -0.10435088 | I37: -0.0012141229 | J37: -0.15015039 | K37: -0.0032331124 | L37: 0.51237005
C38: 5 | D38: 0 | E38: 0 | F38: 0 | G38: =G8 -> 5.2663498e-05 | H38: =H8 -> -0.12548637 | I38: =I8 -> -0.00097444712 | J38: =J8 -> -0.25848296 | K38: =K8 -> 0.00061889738 | L38: =L8 -> 0.60252059
C39: 5 | D39: 1 | E39: 0 | F39: 0 | G39: 0.0025354521 | H39: -0.11063793 | I39: -0.0023652061 | J39: -0.22408065 | K39: -0.013283357 | L39: 0.53405982
C40: 5 | D40: 0 | E40: 1 | F40: 0 | G40: -0.0024969904 | H40: -0.10935673 | I40: 0.00080027385 | J40: -0.21961303 | K40: 0.015953016 | L40: 0.52850235
C41: 5 | D41: 0 | E41: 0 | F41: 1 | G41: 0.00011015311 | H41: -0.13439533 | I41: -0.0010627366 | J41: -0.27552006 | K41: 0.00088381767 | L41: 0.64680564
C42: 6 | D42: 0 | E42: 0 | F42: 0 | G42: =G9 -> 0.00031168538 | H42: =H9 -> -0.07882379 | I42: =I9 -> -0.001017861 | J42: =J9 -> -0.13838193 | K42: =K9 -> -0.0011457466 | L42: =L9 -> 0.27298316
C43: 6 | D43: 1 | E43: 0 | F43: 0 | G43: 0.0026779515 | H43: -0.06634111 | I43: -0.0029997558 | J43: -0.11294723 | K43: -0.013725493 | L43: 0.23122345
...

Sheet Distal Vali (1.5N perturb)
A1: Ground Truth | G1: 6-Axis FT Sensor | M1: SoRoSim get_distal_value (3 Perturbations) | Q1: Distal Errors | T1: ABS Distal Errors
A2: F (N) | B2: s (m) | C2: theta (rad) | D2: tau1 (N) | E2: tau2 (N) | F2: tau3 (N) | G2: Tx (Nm) | H2: Ty (Nm) | I2: Tz(Nm) | J2: Fx (N) | K2: Fy (N) | L2: Fz (N) | M2: F (N) | N2: s (m) | O2: theta (rad) | P2: f_final | Q2: F (N) | R2: s (m) | S2: theta (rad) | T2: F (N) | U2: s (m) | V2: theta (rad) | W2: Absolute Mean Error
A3: ='Proximal Validation'!A3 -> 0.4 | B3: ='Proximal Validation'!B3 -> 0.06 | C3: ='Proximal Validation'!C3 -> 1.5707963 | D3: ='Proximal Validation'!D3 -> 0 | E3: ='Proximal Validation'!E3 -> 0 | F3: ='Proximal Validation'!F3 -> 0 | G3: ='Proximal Validation'!G3 -> 0.00042863237 | H3: ='Proximal Validation'!H3 -> -0.060315419 | ... L3: ='Proximal Validation'!L3 -> 0.38065329 | M3: 0.50342154 | N3: 0.11421361 | O3: 1.5794505 | P3: 0.0049441955 | Q3: =M3-A3 -> 0.10342154 | R3: =N3-B3 -> 0.054213613 | S3: =O3-C3 -> 0.0086542072 | T3: =ABS(Q3) -> 0.10342154 | U3: =ABS(R3) -> 0.054213613 | V3: =ABS(S3) -> 0.0086542072 | W3: F1 (N) | X3: s1 (m) | Y3: el1 (rad)
A4: ='Proximal Validation'!A4 -> 0.8 | B4: ='Proximal Validation'!B4 -> 0.06 | C4: ='Proximal Validation'!C4 -> 1.5707963 | D4: ='Proximal Validation'!D4 -> 0 | E4: ='Proximal Validation'!E4 -> 0 | F4: ='Proximal Validation'!F4 -> 0 | G4: ='Proximal Validation'!G4 -> 0.00062025362 | H4: ='Proximal Validation'!H4 -> -0.1331491 | ... L4: ='Proximal Validation'!L4 -> 0.83635294 | M4: 0.84020607 | N4: 0.067841102 | O4: 1.5840994 | P4: 0.00082990703 | Q4: =M4-A4 -> 0.040206073 | R4: =N4-B4 -> 0.0078411024 | S4: =O4-C4 -> 0.013303059 | T4: =ABS(Q4) -> 0.040206073 | U4: =ABS(R4) -> 0.0078411024 | V4: =ABS(S4) -> 0.013303059 | W4: {=AVERAGE(ABS(Q3:Q12))} -> 0.14599081 | X4: {=AVERAGE(ABS(R3:R12))} -> 0.065569154 | Y4: {=AVERAGE(ABS(S3:S12))} -> 0.026800483
A5: ='Proximal Validation'!A5 -> 0.3 | B5: ='Proximal Validation'!B5 -> 0.08 | C5: ='Proximal Validation'!C5 -> 1.5707963 | D5: ='Proximal Validation'!D5 -> 0 | E5: ='Proximal Validation'!E5 -> 0 | F5: ='Proximal Validation'!F5 -> 0 | G5: ='Proximal Validation'!G5 -> 0.00016799069 | H5: ='Proximal Validation'!H5 -> -0.045721896 | ... L5: ='Proximal Validation'!L5 -> 0.25438803 | M5: 0.3039601 | N5: 0.14859362 | O5: 1.5830559 | P5: 0.00051123128 | Q5: =M5-A5 -> 0.0039601021 | R5: =N5-B5 -> 0.068593617 | S5: =O5-C5 -> 0.012259615 | T5: =ABS(Q5) -> 0.0039601021 | U5: =ABS(R5) -> 0.068593617 | V5: =ABS(S5) -> 0.012259615
A6: ='Proximal Validation'!A6 -> 0.5 | B6: ='Proximal Validation'!B6 -> 0.1 | C6: ='Proximal Validation'!C6 -> 1.5707963 | D6: ='Proximal Validation'!D6 -> 0 | E6: ='Proximal Validation'!E6 -> 0 | F6: ='Proximal Validation'!F6 -> 0 | G6: ='Proximal Validation'!G6 -> 0.00033436844 | H6: ='Proximal Validation'!H6 -> -0.091593102 | ... L6: ='Proximal Validation'!L6 -> 0.44673038 | M6: 0.72563499 | N6: 0.055441851 | O6: 1.5865824 | P6: 0.0010507664 | Q6: =M6-A6 -> 0.22563499 | R6: =N6-B6 -> -0.044558149 | S6: =O6-C6 -> 0.015786099 | T6: =ABS(Q6) -> 0.22563499 | U6: =ABS(R6) -> 0.044558149 | V6: =ABS(S6) -> 0.015786099
A7: ='Proximal Validation'!A7 -> 0.7 | B7: ='Proximal Validation'!B7 -> 0.1 | C7: ='Proximal Validation'!C7 -> 1.5707963 | D7: ='Proximal Validation'!D7 -> 0 | E7: ='Proximal Validation'!E7 -> 0 | F7: ='Proximal Validation'!F7 -> 0 | G7: ='Proximal Validation'!G7 -> 5.2663498e-05 | H7: ='Proximal Validation'!H7 -> -0.12548637 | ... L7: ='Proximal Validation'!L7 -> 0.60252059 | M7: 0.76457766 | N7: 0.084992952 | O7: 1.582788 | P7: 0.0011277325 | Q7: =M7-A7 -> 0.064577655 | R7: =N7-B7 -> -0.015007048 | S7: =O7-C7 -> 0.011991644 | T7: =ABS(Q7) -> 0.064577655 | U7: =ABS(R7) -> 0.015007048 | V7: =ABS(S7) -> 0.011991644
A8: ='Proximal Validation'!A8 -> 0.4 | B8: ='Proximal Validation'!B8 -> 0.16 | C8: ='Proximal Validation'!C8 -> 1.5707963 | D8: ='Proximal Validation'!D8 -> 0 | E8: ='Proximal Validation'!E8 -> 0 | F8: ='Proximal Validation'!F8 -> 0 | G8: ='Proximal Validation'!G8 -> 0.00031168538 | H8: ='Proximal Validation'!H8 -> -0.07882379 | ... L8: ='Proximal Validation'!L8 -> 0.27298316 | M8: 0.54316803 | N8: 0.083679631 | O8: 1.5825541 | P8: 0.014308456 | Q8: =M8-A8 -> 0.14316803 | R8: =N8-B8 -> -0.076320369 | S8: =O8-C8 -> 0.011757726 | T8: =ABS(Q8) -> 0.14316803 | U8: =ABS(R8) -> 0.076320369 | V8: =ABS(S8) -> 0.011757726
A9: ='Proximal Validation'!A9 -> 0.6 | B9: ='Proximal Validation'!B9 -> 0.16 | C9: ='Proximal Validation'!C9 -> 1.5707963 | D9: ='Proximal Validation'!D9 -> 0 | E9: ='Proximal Validation'!E9 -> 0 | F9: ='Proximal Validation'!F9 -> 0 | G9: ='Proximal Validation'!G9 -> 0.00046556734 | H9: ='Proximal Validation'!H9 -> -0.13455996 | ... L9: ='Proximal Validation'!L9 -> 0.42998898 | M9: 0.46742238 | N9: 0.2 | O9: 1.4552091 | P9: 0.072814077 | Q9: =M9-A9 -> -0.13257762 | R9: =N9-B9 -> 0.04 | S9: =O9-C9 -> -0.11558725 | T9: =ABS(Q9) -> 0.13257762 | U9: =ABS(R9) -> 0.04 | V9: =ABS(S9) -> 0.11558725
A10: ='Proximal Validation'!A10 -> 0.8 | B10: ='Proximal Validation'!B10 -> 0.18 | C10: ='Proximal Validation'!C10 -> 1.5707963 | D10: ='Proximal Validation'!D10 -> 0 | E10: ='Proximal Validation'!E10 -> 0 | F10: ='Proximal Validation'!F10 -> 0 | G10: ='Proximal Validation'!G10 -> 0.0012284045 | H10: ='Proximal Validation'!H10 -> -0.11391517 | ... L10: ='Proximal Validation'!L10 -> 0.10571924 | M10: 0.98156669 | N10: 0.1008723 | O10: 1.5922926 | P10: 0.0010861504 | Q10: =M10-A10 -> 0.18156669 | R10: =N10-B10 -> -0.079127699 | S10: =O10-C10 -> 0.021496263 | T10: =ABS(Q10) -> 0.18156669 | U10: =ABS(R10) -> 0.079127699 | V10: =ABS(S10) -> 0.021496263
A11: ='Proximal Validation'!A11 -> 0.3 | B11: ='Proximal Validation'!B11 -> 0.2 | C11: ='Proximal Validation'!C11 -> 1.5707963 | D11: ='Proximal Validation'!D11 -> 0 | E11: ='Proximal Validation'!E11 -> 0 | F11: ='Proximal Validation'!F11 -> 0 | G11: ='Proximal Validation'!G11 -> -9.6103904e-05 | H11: ='Proximal Validation'!H11 -> -0.05968694 | ... L11: ='Proximal Validation'!L11 -> 0.17655885 | M11: 0.56479537 | N11: 0.051739799 | O11: 1.5763557 | P11: 0.0339162 | Q11: =M11-A11 -> 0.26479537 | R11: =N11-B11 -> -0.1482602 | S11: =O11-C11 -> 0.0055593653 | T11: =ABS(Q11) -> 0.26479537 | U11: =ABS(R11) -> 0.1482602 | V11: =ABS(S11) -> 0.0055593653
A12: ='Proximal Validation'!A12 -> 0.7 | B12: ='Proximal Validation'!B12 -> 0.2 | C12: ='Proximal Validation'!C12 -> 1.5707963 | D12: ='Proximal Validation'!D12 -> 0 | E12: ='Proximal Validation'!E12 -> 0 | F12: ='Proximal Validation'!F12 -> 0 | G12: ='Proximal Validation'!G12 -> 0.00068014755 | H12: ='Proximal Validation'!H12 -> -0.082236603 | ... L12: ='Proximal Validation'!L12 -> 0.033172652 | M12: 1 | N12: 0.078230259 | O12: 1.6224059 | P12: 0.0098170272 | Q12: =M12-A12 -> 0.3 | R12: =N12-B12 -> -0.12176974 | S12: =O12-C12 -> 0.051609599 | T12: =ABS(Q12) -> 0.3 | U12: =ABS(R12) -> 0.12176974 | V12: =ABS(S12) -> 0.051609599
M13: SoRoSim get_distal_value (2 Perturbations) | Q13: Distal Errors | T13: ABS Distal Errors
A14: Perturbation | M14: F (N) | N14: s (m) | O14: theta (rad) | P14: f_final | Q14: F (N) | R14: s (m) | S14: theta (rad) | T14: F (N) | U14: s (m) | V14: theta (rad) | W14: Absolute Mean Error
A15: 1.5 | B15: 0 | C15: 0 | Q15: =M15-A3 -> -0.4 | R15: =N15-B3 -> -0.06 | S15: =O15-C3 -> -1.5707963 | T15: =ABS(Q15) -> 0.4 | U15: =ABS(R15) -> 0.06 | V15: =ABS(S15) -> 1.5707963 | W15: F1 (N) | X15: s1 (m) | Y15: el1 (rad)
A16: 0 | B16: 1.5 | C16: 0 | Q16: =M16-A4 -> -0.8 | R16: =N16-B4 -> -0.06 | S16: =O16-C4 -> -1.5707963 | T16: =ABS(Q16) -> 0.8 | U16: =ABS(R16) -> 0.06 | V16: =ABS(S16) -> 1.5707963 | W16: {=AVERAGE(ABS(Q19:Q24))} -> 0.58333333 | X16: {=AVERAGE(ABS(R19:R24))} -> 0.16666667 | Y16: {=AVERAGE(ABS(S19:S24))} -> 1.5707963
A17: 0 | B17: 0 | C17: 1.5 | Q17: =M17-A5 -> -0.3 | R17: =N17-B5 -> -0.08 | S17: =O17-C5 -> -1.5707963 | T17: =ABS(Q17) -> 0.3 | U17: =ABS(R17) -> 0.08 | V17: =ABS(S17) -> 1.5707963
Q18: =M18-A6 -> -0.5 | R18: =N18-B6 -> -0.1 | S18: =O18-C6 -> -1.5707963 | T18: =ABS(Q18) -> 0.5 | U18: =ABS(R18) -> 0.1 | V18: =ABS(S18) -> 1.5707963
Q19: =M19-A7 -> -0.7 | R19: =N19-B7 -> -0.1 | S19: =O19-C7 -> -1.5707963 | T19: =ABS(Q19) -> 0.7 | U19: =ABS(R19) -> 0.1 | V19: =ABS(S19) -> 1.5707963
C20: Trial # | D20: tau1 (N) | E20: tau2 (N) | F20: tau3 (N) | G20: Supporting Measurments w Perturbation | Q20: =M20-A8 -> -0.4 | R20: =N20-B8 -> -0.16 | S20: =O20-C8 -> -1.5707963 | T20: =ABS(Q20) -> 0.4 | U20: =ABS(R20) -> 0.16 | V20: =ABS(S20) -> 1.5707963
C21: 1 | D21: =D3 -> 0 | E21: =E3 -> 0 | F21: =F3 -> 0 | G21: =G3 -> 0.00042863237 | H21: =H3 -> -0.060315419 | I21: =I3 -> -0.00025572156 | J21: =J3 -> -0.04101181 | K21: =K3 -> 0.0007423833 | L21: =L3 -> 0.38065329 | Q21: =M21-A9 -> -0.6 | R21: =N21-B9 -> -0.16 | S21: =O21-C9 -> -1.5707963 | T21: =ABS(Q21) -> 0.6 | U21: =ABS(R21) -> 0.16 | V21: =ABS(S21) -> 1.5707963
C22: 1 | D22: 1.5 | E22: 0 | F22: 0 | G22: 0.0016412667 | H22: -0.039588783 | I22: -0.00034840038 | J22: -0.0059798043 | K22: -0.0032678023 | L22: 0.25482219 | Q22: =M22-A10 -> -0.8 | R22: =N22-B10 -> -0.18 | S22: =O22-C10 -> -1.5707963 | T22: =ABS(Q22) -> 0.8 | U22: =ABS(R22) -> 0.18 | V22: =ABS(S22) -> 1.5707963
C23: 1 | D23: 0 | E23: 1.5 | F23: 0 | G23: -0.00021547312 | H23: -0.038401622 | I23: -0.0001083111 | J23: -0.00042969082 | K23: 0.0081410967 | L23: 0.2473141 | Q23: =M23-A11 -> -0.3 | R23: =N23-B11 -> -0.2 | S23: =O23-C11 -> -1.5707963 | T23: =ABS(Q23) -> 0.3 | U23: =ABS(R23) -> 0.2 | V23: =ABS(S23) -> 1.5707963
C24: 1 | D24: 0 | E24: 0 | F24: 1.5 | G24: 0.00096457568 | H24: -0.081467949 | I24: -0.00039827195 | J24: -0.034821972 | K24: 0.0038996786 | L24: 0.52454042 | Q24: =M24-A12 -> -0.7 | R24: =N24-B12 -> -0.2 | S24: =O24-C12 -> -1.5707963 | T24: =ABS(Q24) -> 0.7 | U24: =ABS(R24) -> 0.2 | V24: =ABS(S24) -> 1.5707963
C25: 2 | D25: 0 | E25: 0 | F25: 0 | G25: =G4 -> 0.00062025362 | H25: =H4 -> -0.1331491 | I25: =I4 -> -0.0002361295 | J25: =J4 -> -0.19782805 | K25: =K4 -> 0.0035987794 | L25: =L4 -> 0.83635294 | M25: SoRoSim get_distal_value (1 Perturbations) | Q25: Distal Errors | T25: ABS Distal Errors
C26: 2 | D26: 1.5 | E26: 0 | F26: 0 | G26: 0.0030786544 | H26: -0.11442684 | I26: -0.0012956498 | J26: -0.15954234 | K26: -0.010915563 | L26: 0.72994769 | M26: F (N) | N26: s (m) | O26: theta (rad) | P26: f_final | Q26: F (N) | R26: s (m) | S26: theta (rad) | T26: F (N) | U26: s (m) | V26: theta (rad) | W26: Absolute Mean Error
C27: 2 | D27: 0 | E27: 1.5 | F27: 0 | G27: -0.001955969 | H27: -0.11285923 | I27: 0.0011151043 | J27: -0.14631234 | K27: 0.019970797 | L27: 0.72010243 | Q27: =M27-A3 -> -0.4 | R27: =N27-B3 -> -0.06 | S27: =O27-C3 -> -1.5707963 | T27: =ABS(Q27) -> 0.4 | U27: =ABS(R27) -> 0.06 | V27: =ABS(S27) -> 1.5707963 | W27: F1 (N) | X27: s1 (m) | Y27: el1 (rad)
C28: 2 | D28: 0 | E28: 0 | F28: 1.5 | G28: 0.00085117668 | H28: -0.14573252 | I28: -0.00025534653 | J28: -0.19965956 | K28: 0.0052101761 | L28: 0.92426777 | Q28: =M28-A4 -> -0.8 | R28: =N28-B4 -> -0.06 | S28: =O28-C4 -> -1.5707963 | T28: =ABS(Q28) -> 0.8 | U28: =ABS(R28) -> 0.06 | V28: =ABS(S28) -> 1.5707963 | W28: {=AVERAGE(ABS(Q31:Q36))} -> 0.58333333 | X28: {=AVERAGE(ABS(R31:R36))} -> 0.16666667 | Y28: {=AVERAGE(ABS(S31:S36))} -> 1.5707963
C29: 3 | D29: 0 | E29: 0 | F29: 0 | G29: =G5 -> 0.00016799069 | H29: =H5 -> -0.045721896 | I29: =I5 -> -0.00038841026 | J29: =J5 -> -0.033596165 | K29: =K5 -> -0.0010348894 | L29: =L5 -> 0.25438803 | Q29: =M29-A5 -> -0.3 | R29: =N29-B5 -> -0.08 | S29: =O29-C5 -> -1.5707963 | T29: =ABS(Q29) -> 0.3 | U29: =ABS(R29) -> 0.08 | V29: =ABS(S29) -> 1.5707963
C30: 3 | D30: 1.5 | E30: 0 | F30: 0 | G30: 0.00075818668 | H30: -0.019146863 | I30: -8.1150036e-05 | J30: -0.003430659 | K30: -0.0043338463 | L30: 0.10736291 | Q30: =M30-A6 -> -0.5 | R30: =N30-B6 -> -0.1 | S30: =O30-C6 -> -1.5707963 | T30: =ABS(Q30) -> 0.5 | U30: =ABS(R30) -> 0.1 | V30: =ABS(S30) -> 1.5707963
C31: 3 | D31: 0 | E31: 1.5 | F31: 0 | G31: -0.000552012 | H31: -0.019014897 | I31: -0.00025363834 | J31: -0.00080577668 | K31: 0.0035313419 | L31: 0.10630399 | Q31: =M31-A7 -> -0.7 | R31: =N31-B7 -> -0.1 | S31: =O31-C7 -> -1.5707963 | T31: =ABS(Q31) -> 0.7 | U31: =ABS(R31) -> 0.1 | V31: =ABS(S31) -> 1.5707963
C32: 3 | D32: 0 | E32: 0 | F32: 1.5 | G32: -2.3332541e-05 | H32: -0.070407443 | I32: -0.00045982725 | J32: -0.045281 | K32: 0.00088363141 | L32: 0.39579356 | Q32: =M32-A8 -> -0.4 | R32: =N32-B8 -> -0.16 | S32: =O32-C8 -> -1.5707963 | T32: =ABS(Q32) -> 0.4 | U32: =ABS(R32) -> 0.16 | V32: =ABS(S32) -> 1.5707963
C33: 4 | D33: 0 | E33: 0 | F33: 0 | G33: =G6 -> 0.00033436844 | H33: =H6 -> -0.091593102 | I33: =I6 -> -0.0010956251 | J33: =J6 -> -0.13726634 | K33: =K6 -> -0.0029727668 | L33: =L6 -> 0.44673038 | Q33: =M33-A9 -> -0.6 | R33: =N33-B9 -> -0.16 | S33: =O33-C9 -> -1.5707963 | T33: =ABS(Q33) -> 0.6 | U33: =ABS(R33) -> 0.16 | V33: =ABS(S33) -> 1.5707963
C34: 4 | D34: 1.5 | E34: 0 | F34: 0 | G34: 0.0030973882 | H34: -0.06951946 | I34: -0.0025332393 | J34: -0.0918229 | K34: -0.018441685 | L34: 0.34359932 | Q34: =M34-A10 -> -0.8 | R34: =N34-B10 -> -0.18 | S34: =O34-C10 -> -1.5707963 | T34: =ABS(Q34) -> 0.8 | U34: =ABS(R34) -> 0.18 | V34: =ABS(S34) -> 1.5707963
C35: 4 | D35: 0 | E35: 1.5 | F35: 0 | G35: -0.0023715664 | H35: -0.068494059 | I35: 0.00080478378 | J35: -0.087323129 | K35: 0.012371423 | L35: 0.33844605 | Q35: =M35-A11 -> -0.3 | R35: =N35-B11 -> -0.2 | S35: =O35-C11 -> -1.5707963 | T35: =ABS(Q35) -> 0.3 | U35: =ABS(R35) -> 0.2 | V35: =ABS(S35) -> 1.5707963
C36: 4 | D36: 0 | E36: 0 | F36: 1.5 | G36: 0.00040871603 | H36: -0.10985789 | I36: -0.0012635047 | J36: -0.15462209 | K36: -0.0030250028 | L36: 0.54040027 | Q36: =M36-A12 -> -0.7 | R36: =N36-B12 -> -0.2 | S36: =O36-C12 -> -1.5707963 | T36: =ABS(Q36) -> 0.7 | U36: =ABS(R36) -> 0.2 | V36: =ABS(S36) -> 1.5707963
C37: 5 | D37: 0 | E37: 0 | F37: 0 | G37: =G7 -> 5.2663498e-05 | H37: =H7 -> -0.12548637 | I37: =I7 -> -0.00097444712 | J37: =J7 -> -0.25848296 | K37: =K7 -> 0.00061889738 | L37: =L7 -> 0.60252059
C38: 5 | D38: 1.5 | E38: 0 | F38: 0 | G38: 0.0038735552 | H38: -0.10250039 | I38: -0.0030874428 | J38: -0.20087767 | K38: -0.020546243 | L38: 0.49526519
C39: 5 | D39: 0 | E39: 1.5 | F39: 0 | G39: -0.0034122341 | H39: -0.10108612 | I39: 0.001379653 | J39: -0.19690238 | K39: 0.021174792 | L39: 0.48914975
C40: 5 | D40: 0 | E40: 0 | F40: 1.5 | G40: -0.00010955497 | H40: -0.13760942 | I40: -0.00094528223 | J40: -0.27856466 | K40: 0.0021467954 | L40: 0.66296279
...

Sheet Conversion
A1: Raw Data | H1: Converted
A2: Fx | B2: Fy | C2: Fz | D2: Tx | E2: Ty | F2: Tz | H2: Tx | I2: Ty | J2: Tz | K2: Fx | L2: Fy | M2: Fz
A3: 0.27298316 | B3: 0.0011457466 | C3: -0.13838193 | D3: -0.001017861 | E3: 0.07882379 | F3: 0.00031168538 | H3: =$F3 -> 0.00031168538 | I3: =-1*$E3 -> -0.07882379 | J3: =$D3 -> -0.001017861 | K3: =$C3 -> -0.13838193 | L3: =-1*$B3 -> -0.0011457466 | M3: =$A3 -> 0.27298316
A4: 0.25242263 | B4: 0.0082274601 | C4: -0.12710483 | D4: -0.0021703593 | E4: 0.072682023 | F4: 0.0016261921 | H4: =$F4 -> 0.0016261921 | I4: =-1*$E4 -> -0.072682023 | J4: =$D4 -> -0.0021703593 | K4: =$C4 -> -0.12710483 | L4: =-1*$B4 -> -0.0082274601 | M4: =$A4 -> 0.25242263
A5: 0.25155869 | B5: -0.0050658286 | C5: -0.12602137 | D5: 8.8032219e-05 | E5: 0.072226621 | F5: -0.00082752109 | H5: =$F5 -> -0.00082752109 | I5: =-1*$E5 -> -0.072226621 | J5: =$D5 -> 8.8032219e-05 | K5: =$C5 -> -0.12602137 | L5: =-1*$B5 -> 0.0050658286 | M5: =$A5 -> 0.25155869
A6: 0.28976071 | B6: 0.0004754588 | C6: -0.1359383 | D6: -0.0010331525 | E6: 0.083331585 | F6: 0.00028748519 | H6: =$F6 -> 0.00028748519 | I6: =-1*$E6 -> -0.083331585 | J6: =$D6 -> -0.0010331525 | K6: =$C6 -> -0.1359383 | L6: =-1*$B6 -> -0.0004754588 | M6: =$A6 -> 0.28976071
A7: 0.23122345 | B7: 0.013725493 | C7: -0.11294723 | D7: -0.0029997558 | E7: 0.06634111 | F7: 0.0026779515 | H7: =$F7 -> 0.0026779515 | I7: =-1*$E7 -> -0.06634111 | J7: =$D7 -> -0.0029997558 | K7: =$C7 -> -0.11294723 | L7: =-1*$B7 -> -0.013725493 | M7: =$A7 -> 0.23122345
A8: 0.22469406 | B8: -0.012914394 | C8: -0.10667694 | D8: 0.0014156965 | E8: 0.064458705 | F8: -0.002300886 | H8: =$F8 -> -0.002300886 | I8: =-1*$E8 -> -0.064458705 | J8: =$D8 -> 0.0014156965 | K8: =$C8 -> -0.10667694 | L8: =-1*$B8 -> 0.012914394 | M8: =$A8 -> 0.22469406
A9: 0.31581044 | B9: -7.6498836e-05 | C9: -0.15762711 | D9: -0.0009970956 | E9: 0.090588927 | F9: 0.00015420001 | H9: =$F9 -> 0.00015420001 | I9: =-1*$E9 -> -0.090588927 | J9: =$D9 -> -0.0009970956 | K9: =$C9 -> -0.15762711 | L9: =-1*$B9 -> 7.6498836e-05 | M9: =$A9 -> 0.31581044
A10: 0.20442483 | B10: 0.018327087 | C10: -0.095448636 | D10: -0.0036627327 | E10: 0.058664918 | F10: 0.0035489257 | H10: =$F10 -> 0.0035489257 | I10: =-1*$E10 -> -0.058664918 | J10: =$D10 -> -0.0036627327 | K10: =$C10 -> -0.095448636 | L10: =-1*$B10 -> -0.018327087 | M10: =$A10 -> 0.20442483
A11: 0.19912243 | B11: -0.018111419 | C11: -0.090512805 | D11: 0.0022233273 | E11: 0.056882564 | F11: -0.0032538974 | H11: =$F11 -> -0.0032538974 | I11: =-1*$E11 -> -0.056882564 | J11: =$D11 -> 0.0022233273 | K11: =$C11 -> -0.090512805 | L11: =-1*$B11 -> 0.018111419 | M11: =$A11 -> 0.19912243
A12: 0.33190307 | B12: -0.00048611313 | C12: -0.16297053 | D12: -0.0010439778 | E12: 0.095207483 | F12: 0.00012265332 | H12: =$F12 -> 0.00012265332 | I12: =-1*$E12 -> -0.095207483 | J12: =$D12 -> -0.0010439778 | K12: =$C12 -> -0.16297053 | L12: =-1*$B12 -> 0.00048611313 | M12: =$A12 -> 0.33190307
A13: 0.42998898 | B13: 0.00056979433 | C13: -0.33463472 | D13: -0.0015497463 | E13: 0.13455996 | F13: 0.00046556734 | H13: =$F13 -> 0.00046556734 | I13: =-1*$E13 -> -0.13455996 | J13: =$D13 -> -0.0015497463 | K13: =$C13 -> -0.33463472 | L13: =-1*$B13 -> -0.00056979433 | M13: =$A13 -> 0.42998898
A14: 0.40445051 | B14: 0.012799814 | C14: -0.31214833 | D14: -0.0034107193 | E14: 0.12638347 | F14: 0.00276356 | H14: =$F14 -> 0.00276356 | I14: =-1*$E14 -> -0.12638347 | J14: =$D14 -> -0.0034107193 | K14: =$C14 -> -0.31214833 | L14: =-1*$B14 -> -0.012799814 | M14: =$A14 -> 0.40445051
... A52: 0.014540315 | B52: -0.0050625987 | C52: -0.3176094 | D52: -0.00066437421 | E52: 0.068202309 | F52: -0.00057212543 | H52: =$F52 -> -0.00057212543 | I52: =-1*$E52 -> -0.068202309 | J52: =$D52 -> -0.00066437421 | K52: =$C52 -> -0.3176094 | L52: =-1*$B52 -> 0.0050625987 | M52: =$A52 -> 0.014540315
H53: =$F53 -> 0 | I53: =-1*$E53 -> 0 | J53: =$D53 -> 0 | K53: =$C53 -> 0 | L53: =-1*$B53 -> 0 | M53: =$A53 -> 0
H54: =$F54 -> 0 | I54: =-1*$E54 -> 0 | J54: =$D54 -> 0 | K54: =$C54 -> 0 | L54: =-1*$B54 -> 0 | M54: =$A54 -> 0
H55: =$F55 -> 0 | I55: =-1*$E55 -> 0 | J55: =$D55 -> 0 | K55: =$C55 -> 0 | L55: =-1*$B55 -> 0 | M55: =$A55 -> 0
H56: =$F56 -> 0 | I56: =-1*$E56 -> 0 | J56: =$D56 -> 0 | K56: =$C56 -> 0 | L56: =-1*$B56 -> 0 | M56: =$A56 -> 0
H57: =$F57 -> 0 | I57: =-1*$E57 -> 0 | J57: =$D57 -> 0 | K57: =$C57 -> 0 | L57: =-1*$B57 -> 0 | M57: =$A57 -> 0
H58: =$F58 -> 0 | I58: =-1*$E58 -> 0 | J58: =$D58 -> 0 | K58: =$C58 -> 0 | L58: =-1*$B58 -> 0 | M58: =$A58 -> 0
H59: =$F59 -> 0 | I59: =-1*$E59 -> 0 | J59: =$D59 -> 0 | K59: =$C59 -> 0 | L59: =-1*$B59 -> 0 | M59: =$A59 -> 0
H60: =$F60 -> 0 | I60: =-1*$E60 -> 0 | J60: =$D60 -> 0 | K60: =$C60 -> 0 | L60: =-1*$B60 -> 0 | M60: =$A60 -> 0
H61: =$F61 -> 0 | I61: =-1*$E61 -> 0 | J61: =$D61 -> 0 | K61: =$C61 -> 0 | L61: =-1*$B61 -> 0 | M61: =$A61 -> 0
H62: =$F62 -> 0 | I62: =-1*$E62 -> 0 | J62: =$D62 -> 0 | K62: =$C62 -> 0 | L62: =-1*$B62 -> 0 | M62: =$A62 -> 0

Sheet Sheet5
T73: { | U73: [ | V73: 0.00042863237 | W73: -0.060315419 | X73: -0.00025572156 | Y73: -0.04101181 | Z73: 0.0007423833 | AA73: 0.38065329 | AB73: 0 | AC73: 0 | AD73: 0 | AE73: ;
V74: 0.0016412667 | W74: -0.039588783 | X74: -0.00034840038 | Y74: -0.0059798043 | Z74: -0.0032678023 | AA74: 0.25482219 | AB74: 1.5 | AC74: 0 | AD74: 0 | AE74: ;
V75: -0.00021547312 | W75: -0.038401622 | X75: -0.0001083111 | Y75: -0.00042969082 | Z75: 0.0081410967 | AA75: 0.2473141 | AB75: 0 | AC75: 1.5 | AD75: 0 | AE75: ;
V76: 0.00096457568 | W76: -0.081467949 | X76: -0.00039827195 | Y76: -0.034821972 | Z76: 0.0038996786 | AA76: 0.52454042 | AB76: 0 | AC76: 0 | AD76: 1.5 | AE76: ]
U77: [ | V77: 0.00062025362 | W77: -0.1331491 | X77: -0.0002361295 | Y77: -0.19782805 | Z77: 0.0035987794 | AA77: 0.83635294 | AB77: 0 | AC77: 0 | AD77: 0 | AE77: ;
V78: 0.0030786544 | W78: -0.11442684 | X78: -0.0012956498 | Y78: -0.15954234 | Z78: -0.010915563 | AA78: 0.72994769 | AB78: 1.5 | AC78: 0 | AD78: 0 | AE78: ;
V79: -0.001955969 | W79: -0.11285923 | X79: 0.0011151043 | Y79: -0.14631234 | Z79: 0.019970797 | AA79: 0.72010243 | AB79: 0 | AC79: 1.5 | AD79: 0 | AE79: ;
V80: 0.00085117668 | W80: -0.14573252 | X80: -0.00025534653 | Y80: -0.19965956 | Z80: 0.0052101761 | AA80: 0.92426777 | AB80: 0 | AC80: 0 | AD80: 1.5 | AE80: ]
U81: [ | V81: 0.00016799069 | W81: -0.045721896 | X81: -0.00038841026 | Y81: -0.033596165 | Z81: -0.0010348894 | AA81: 0.25438803 | AB81: 0 | AC81: 0 | AD81: 0 | AE81: ;
V82: 0.00075818668 | W82: -0.019146863 | X82: -8.1150036e-05 | Y82: -0.003430659 | Z82: -0.0043338463 | AA82: 0.10736291 | AB82: 1.5 | AC82: 0 | AD82: 0 | AE82: ;
V83: -0.000552012 | W83: -0.019014897 | X83: -0.00025363834 | Y83: -0.00080577668 | Z83: 0.0035313419 | AA83: 0.10630399 | AB83: 0 | AC83: 1.5 | AD83: 0 | AE83: ;
V84: -2.3332541e-05 | W84: -0.070407443 | X84: -0.00045982725 | Y84: -0.045281 | Z84: 0.00088363141 | AA84: 0.39579356 | AB84: 0 | AC84: 0 | AD84: 1.5 | AE84: ]
U85: [ | V85: 0.00033436844 | W85: -0.091593102 | X85: -0.0010956251 | Y85: -0.13726634 | Z85: -0.0029727668 | AA85: 0.44673038 | AB85: 0 | AC85: 0 | AD85: 0 | AE85: ;
V86: 0.0030973882 | W86: -0.06951946 | X86: -0.0025332393 | Y86: -0.0918229 | Z86: -0.018441685 | AA86: 0.34359932 | AB86: 1.5 | AC86: 0 | AD86: 0 | AE86: ;
V87: -0.0023715664 | W87: -0.068494059 | X87: 0.00080478378 | Y87: -0.087323129 | Z87: 0.012371423 | AA87: 0.33844605 | AB87: 0 | AC87: 1.5 | AD87: 0 | AE87: ;
V88: 0.00040871603 | W88: -0.10985789 | X88: -0.0012635047 | Y88: -0.15462209 | Z88: -0.0030250028 | AA88: 0.54040027 | AB88: 0 | AC88: 0 | AD88: 1.5 | AE88: ]
U89: [ | V89: 5.2663498e-05 | W89: -0.12548637 | X89: -0.00097444712 | Y89: -0.25848296 | Z89: 0.00061889738 | AA89: 0.60252059 | AB89: 0 | AC89: 0 | AD89: 0 | AE89: ;
V90: 0.0038735552 | W90: -0.10250039 | X90: -0.0030874428 | Y90: -0.20087767 | Z90: -0.020546243 | AA90: 0.49526519 | AB90: 1.5 | AC90: 0 | AD90: 0 | AE90: ;
