Workbook

Sheet Proximal Validation (double)
A1: Ground Truth | L1: 6-Axis FT Sensor | R1: SoRoSim get_proximal_value | X1: Proximal Errors
A2: F1 (N) | B2: s1 (m) | C2: el1 (rad) | D2: az1 (rad) | E2: F2 (N) | F2: s2 (m) | G2: el2 (rad) | H2: az2 (rad) | I2: tau1 (N) | J2: tau2 (N) | K2: tau3 (N) | L2: Tx (Nm) | M2: Ty (Nm) | N2: Tz(Nm) | O2: Fx (N) | P2: Fy (N) | Q2: Fz (N) | R2: Tx (Nm) | S2: Ty (Nm) | T2: Tz(Nm) | U2: Fx (N) | V2: Fy (N) | W2: Fz (N) | X2: Tx (Nm) | Y2: Ty (Nm) | Z2: Tz(Nm) | AA2: Fx (N) | AB2: Fy (N) | AC2: Fz (N)
A3: 0.2 | B3: 0.1 | C3: 1.571 | D3: =PI()/2 -> 1.5707963 | E3: 1 | F3: 0.04 | G3: 3.142 | H3: =PI()/2 -> 1.5707963 | I3: 1.4 | J3: 0 | K3: 0 | L3: -8.4695406e-05 | M3: -0.011448632 | N3: -0.13048847 | O3: 0.018870793 | P3: -0.97202778 | Q3: 0.029205024 | R3: 0.0007 | S3: -0.0379 | T3: -0.1297 | U3: -0.0336 | V3: -0.9997 | W3: 0.1988 | X3: =ABS(L3-R3) -> 0.00078469541 | Y3: =ABS(M3-S3) -> 0.026451368 | Z3: =ABS(N3-T3) -> 0.0007884702 | AA3: =ABS(O3-U3) -> 0.052470793 | AB3: =ABS(P3-V3) -> 0.027672221 | AC3: =ABS(Q3-W3) -> 0.16959498
A4: 1 | B4: 0.1 | C4: 1.571 | D4: =PI()/2 -> 1.5707963 | E4: 1 | F4: 0.08 | G4: 3.142 | H4: =PI()/2 -> 1.5707963 | I4: 0 | J4: 0 | K4: 0 | L4: -0.0013048807 | M4: -0.18739954 | N4: -0.14850681 | O4: -0.4587166 | P4: -0.81002575 | Q4: 0.92483175 | R4: 0 | S4: -0.1854 | T4: -0.1667 | U4: -0.3763 | V4: -0.9696 | W4: 0.958 | X4: =ABS(L4-R4) -> 0.0013048807 | Y4: =ABS(M4-S4) -> 0.0019995364 | Z4: =ABS(N4-T4) -> 0.018193195 | AA4: =ABS(O4-U4) -> 0.082416601 | AB4: =ABS(P4-V4) -> 0.15957425 | AC4: =ABS(Q4-W4) -> 0.033168252
A5: 0.5 | B5: 0.1 | C5: 1.571 | D5: =PI()/2 -> 1.5707963 | E5: 0.2 | F5: 0.02 | G5: 3.927 | H5: =PI()/2 -> 1.5707963 | I5: 0 | J5: 0 | K5: 0 | L5: -8.817346e-05 | M5: -0.09024971 | N5: -0.015381615 | O5: -0.059044521 | P5: -0.14255172 | Q5: 0.40386674 | R5: 0 | S5: -0.0792 | T5: -0.0155 | U5: -0.0521 | V5: -0.1415 | W5: 0.3554 | X5: =ABS(L5-R5) -> 8.817346e-05 | Y5: =ABS(M5-S5) -> 0.01104971 | Z5: =ABS(N5-T5) -> 0.00011838532 | AA5: =ABS(O5-U5) -> 0.0069445213 | AB5: =ABS(P5-V5) -> 0.0010517201 | AC5: =ABS(Q5-W5) -> 0.048466738
A6: 0.9 | B6: 0.1 | C6: 1.571 | D6: =PI()/2 -> 1.5707963 | E6: 0.2 | F6: 0.08 | G6: 4.712 | H6: =PI()/2 -> 1.5707963 | I6: 1.2 | J6: 0 | K6: 0 | L6: 0.004064511 | M6: -0.15509437 | N6: 0.0011263725 | O6: -0.22939645 | P6: 0.006297946 | Q6: 0.75826401 | R6: 0.0015 | S6: -0.1353 | T6: -0.0002 | U6: -0.1438 | V6: -0.0024 | W6: 0.6851 | X6: =ABS(L6-R6) -> 0.002564511 | Y6: =ABS(M6-S6) -> 0.01979437 | Z6: =ABS(N6-T6) -> 0.0013263725 | AA6: =ABS(O6-U6) -> 0.085596448 | AB6: =ABS(P6-V6) -> 0.008697946 | AC6: =ABS(Q6-W6) -> 0.073164005
A7: 0.1 | B7: 0.12 | C7: 1.571 | D7: =PI()/2 -> 1.5707963 | E7: 1 | F7: 0.06 | G7: 3.927 | H7: =PI()/2 -> 1.5707963 | I7: 0 | J7: 0 | K7: 0 | L7: -3.3720862e-05 | M7: 0.055788416 | N7: -0.10684345 | O7: 0.023180401 | P7: -0.69266725 | Q7: -0.43824503 | R7: 0 | S7: 0.0849 | T7: -0.1058 | U7: -0.063 | V7: -0.7053 | W7: -0.6059 | X7: =ABS(L7-R7) -> 3.3720862e-05 | Y7: =ABS(M7-S7) -> 0.029111584 | Z7: =ABS(N7-T7) -> 0.0010434492 | AA7: =ABS(O7-U7) -> 0.086180401 | AB7: =ABS(P7-V7) -> 0.012632754 | AC7: =ABS(Q7-W7) -> 0.16765497
A8: 0.8 | B8: 0.16 | C8: 1.571 | D8: =PI()/2 -> 1.5707963 | E8: 0.8 | F8: 0.06 | G8: 3.927 | H8: =PI()/2 -> 1.5707963 | I8: 1.4 | J8: 0 | K8: 0 | L8: 0.0082578762 | M8: -0.10636095 | N8: -0.076963931 | O8: -0.29881915 | P8: -0.50920194 | Q8: 0.10888903 | R8: 0.0044 | S8: -0.1064 | T8: -0.0839 | U8: -0.2294 | V8: -0.5643 | W8: 0.1658 | X8: =ABS(L8-R8) -> 0.0038578762 | Y8: =ABS(M8-S8) -> 3.9050424e-05 | Z8: =ABS(N8-T8) -> 0.0069360687 | AA8: =ABS(O8-U8) -> 0.069419155 | AB8: =ABS(P8-V8) -> 0.055098056 | AC8: =ABS(Q8-W8) -> 0.056910972
A9: 0.1 | B9: 0.18 | C9: 1.571 | D9: =PI()/2 -> 1.5707963 | E9: 0.1 | F9: 0.02 | G9: 3.142 | H9: =PI()/2 -> 1.5707963 | I9: 1.2 | J9: 0 | K9: 0 | L9: 0.00025301205 | M9: -0.0061941464 | N9: -0.012296888 | O9: 0.015694043 | P9: -0.10866395 | Q9: 0.01807829 | R9: 0.0006 | S9: -0.027 | T9: -0.011 | U9: -0.011 | V9: -0.1003 | W9: 0.0993 | X9: =ABS(L9-R9) -> 0.00034698795 | Y9: =ABS(M9-S9) -> 0.020805854 | Z9: =ABS(N9-T9) -> 0.001296888 | AA9: =ABS(O9-U9) -> 0.026694043 | AB9: =ABS(P9-V9) -> 0.0083639538 | AC9: =ABS(Q9-W9) -> 0.08122171
A10: 0.9 | B10: 0.18 | C10: 1.571 | D10: =PI()/2 -> 1.5707963 | E10: 0.1 | F10: 0.08 | G10: 4.712 | H10: =PI()/2 -> 1.5707963 | I10: 0 | J10: 0 | K10: 0 | L10: -0.00089414953 | M10: -0.18082152 | N10: 0.008007491 | O10: -0.40553841 | P10: 0.058199946 | Q10: 0.51686221 | R10: 0 | S10: -0.2033 | T10: -0.0001 | U10: -0.5104 | V10: -0.0002 | W10: 0.6193 | X10: =ABS(L10-R10) -> 0.00089414953 | Y10: =ABS(M10-S10) -> 0.022478477 | Z10: =ABS(N10-T10) -> 0.008107491 | AA10: =ABS(O10-U10) -> 0.10486159 | AB10: =ABS(P10-V10) -> 0.058399946 | AC10: =ABS(Q10-W10) -> 0.10243779
A11: 0.3 | B11: 0.18 | C11: 1.571 | D11: =PI()/2 -> 1.5707963 | E11: 0.9 | F11: 0.08 | G11: 4.712 | H11: =PI()/2 -> 1.5707963 | I11: 1 | J11: 0 | K11: 0 | L11: 0.00024180603 | M11: 0.073132612 | N11: -0.0042187301 | O11: 0.042406578 | P11: -0.02149988 | Q11: -0.58056563 | R11: 0.0006 | S11: 0.0721 | T11: -0.0001 | U11: -0.0031 | V11: -0.0009 | W11: -0.6018 | X11: =ABS(L11-R11) -> 0.00035819397 | Y11: =ABS(M11-S11) -> 0.0010326118 | Z11: =ABS(N11-T11) -> 0.0041187301 | AA11: =ABS(O11-U11) -> 0.045506578 | AB11: =ABS(P11-V11) -> 0.02059988 | AC11: =ABS(Q11-W11) -> 0.021234369
A12: 0.9 | B12: 0.2 | C12: 1.571 | D12: =PI()/2 -> 1.5707963 | E12: 1 | F12: 0.02 | G12: 3.142 | H12: =PI()/2 -> 1.5707963 | I12: 0.4 | J12: 0 | K12: 0 | L12: -0.0001589302 | M12: -0.14518361 | N12: -0.10818373 | O12: -0.5584237 | P12: -0.97605288 | Q12: 0.27430844 | R12: 0.0022 | S12: -0.2213 | T12: -0.1089 | U12: -0.6623 | V12: -1.001 | W12: 0.6136 | X12: =ABS(L12-R12) -> 0.0023589302 | Y12: =ABS(M12-S12) -> 0.076116392 | Z12: =ABS(N12-T12) -> 0.00071626588 | AA12: =ABS(O12-U12) -> 0.1038763 | AB12: =ABS(P12-V12) -> 0.02494712 | AC12: =ABS(Q12-W12) -> 0.33929156
A13: 0.1 | B13: 0.2 | C13: 1.571 | D13: =PI()/2 -> 1.5707963 | E13: 0.3 | F13: 0.08 | G13: 3.142 | H13: =PI()/2 -> 1.5707963 | I13: 0.2 | J13: 0 | K13: 0 | L13: -0.0001415771 | M13: 0.0045513404 | N13: -0.049289763 | O13: 0.026178073 | P13: -0.27640635 | Q13: -0.036308467 | R13: 0.0002 | S13: -0.0287 | T13: -0.0509 | U13: -0.0216 | V13: -0.2995 | W13: 0.0991 | X13: =ABS(L13-R13) -> 0.0003415771 | Y13: =ABS(M13-S13) -> 0.03325134 | Z13: =ABS(N13-T13) -> 0.001610237 | AA13: =ABS(O13-U13) -> 0.047778073 | AB13: =ABS(P13-V13) -> 0.023093652 | AC13: =ABS(Q13-W13) -> 0.13540847
A14: 0.9 | B14: 0.2 | C14: 1.571 | D14: =PI()/2 -> 1.5707963 | E14: 0.3 | F14: 0.02 | G14: 4.712 | H14: =PI()/2 -> 1.5707963 | I14: 1.4 | J14: 0 | K14: 0 | L14: 0.0092607206 | M14: -0.11755939 | N14: -0.0084324358 | O14: -0.58649874 | P14: -0.05003164 | Q14: 0.042876139 | R14: 0.0077 | S14: -0.1855 | T14: -0.0003 | U14: -0.6323 | V14: -0.0247 | W14: 0.297 | X14: =ABS(L14-R14) -> 0.0015607206 | Y14: =ABS(M14-S14) -> 0.067940612 | Z14: =ABS(N14-T14) -> 0.0081324358 | AA14: =ABS(O14-U14) -> 0.045801263 | AB14: =ABS(P14-V14) -> 0.02533164 | AC14: =ABS(Q14-W14) -> 0.25412386
... A42: 0.2 | B42: 0.2 | C42: 4.712 | D42: =PI()/2 -> 1.5707963 | E42: 0.1 | F42: 0.08 | G42: 3.927 | H42: =PI()/2 -> 1.5707963 | I42: 0 | J42: 0 | K42: 0 | L42: 0.00022576435 | M42: 0.054294631 | N42: -0.014319235 | O42: -0.0385371 | P42: -0.08568342 | Q42: -0.20783865 | R42: 0 | S42: 0.069 | T42: -0.012 | U42: -0.0482 | V42: -0.0704 | W42: -0.2664 | X42: =ABS(L42-R42) -> 0.00022576435 | Y42: =ABS(M42-S42) -> 0.014705369 | Z42: =ABS(N42-T42) -> 0.0023192345 | AA42: =ABS(O42-U42) -> 0.0096629 | AB42: =ABS(P42-V42) -> 0.01528342 | AC42: =ABS(Q42-W42) -> 0.058561345
X44: =AVERAGE(X3:X42) -> 0.0013409449 | Y44: =AVERAGE(Y3:Y42) -> 0.017838622 | Z44: =AVERAGE(Z3:Z42) -> 0.0081971453 | AA44: =AVERAGE(AA3:AA42) -> 0.065999681 | AB44: =AVERAGE(AB3:AB42) -> 0.042622724 | AC44: =AVERAGE(AC3:AC42) -> 0.086322411

Sheet Distal Vali (double, loose)
A1: Ground Truth | L1: 6-Axis FT Sensor | R1: SoRoSim get_distal_value | AA1: Distal Errors | AI1: Stats
A2: F1 (N) | B2: s1 (m) | C2: el1 (rad) | D2: az1 (rad) | E2: F2 (N) | F2: s2 (m) | G2: el2 (rad) | H2: az2 (rad) | I2: tau1 (N) | J2: tau2 (N) | K2: tau3 (N) | L2: Tx (Nm) | M2: Ty (Nm) | N2: Tz(Nm) | O2: Fx (N) | P2: Fy (N) | Q2: Fz (N) | R2: F1 (N) | S2: s1 (m) | T2: el1 (rad) | U2: az1 (rad) | V2: F2 (N) | W2: s2 (m) | X2: el2 (rad) | Y2: az2 (rad) | Z2: f_final | AA2: F1 (N) | AB2: s1 (m) | AC2: el1 (rad) | AD2: az1 (rad) | AE2: F2 (N) | AF2: s2 (m) | AG2: el2 (rad) | AH2: az2 (rad) | AI2: force_error | AJ2: position_error | AK2: angle_error | AL2: min_f | AN2: Absolute Mean Error
A3: ='Proximal Validation (double)'!A3 -> 0.2 | B3: ='Proximal Validation (double)'!B3 -> 0.1 | C3: ='Proximal Validation (double)'!C3 -> 1.571 | D3: ='Proximal Validation (double)'!D3 -> 1.5707963 | E3: ='Proximal Validation (double)'!E3 -> 1 | F3: ='Proximal Validation (double)'!F3 -> 0.04 | G3: ='Proximal Validation (double)'!G3 -> 3.142 | H3: ='Proximal Validation (double)'!H3 -> 1.5707963 | ... Q3: ='Proximal Validation (double)'!Q3 -> 0.029205024 | R3: 0.12365518 | S3: 0.03072374 | T3: 2.1432407 | U3: 1.5707963 | V3: 0.90962688 | W3: 0.026104835 | X3: 3.2230505 | Y3: 1.5707963 | Z3: 0.00085362849 | AA3: =R3-A3 -> -0.07634482 | AB3: =S3-B3 -> -0.06927626 | AC3: =T3-C3 -> 0.57224067 | AD3: =U3-D3 -> 0 | AE3: =V3-E3 -> -0.090373118 | AF3: =W3-F3 -> -0.013895165 | AG3: =X3-G3 -> 0.08105053 | AH3: =Y3-H3 -> 0 | AI3: =AVERAGE(ABS(AA3),ABS(AE3)) -> 0.083358969 | AJ3: =AVERAGE(ABS(AB3),ABS(AF3)) -> 0.041585713 | AK3: =AVERAGE(ABS(AC3),ABS(AG3)) -> 0.3266456 | AL3: =MIN(A3,E3) -> 0.2 | AN3: F1 (N) | AO3: s1 (m) | AP3: el1 (rad) | AQ3: az1 (rad) | AR3: F2 (N) | AS3: s2 (m) | AT3: el2 (rad) | AU3: az2 (rad)
A4: ='Proximal Validation (double)'!A4 -> 1 | B4: ='Proximal Validation (double)'!B4 -> 0.1 | C4: ='Proximal Validation (double)'!C4 -> 1.571 | D4: ='Proximal Validation (double)'!D4 -> 1.5707963 | E4: ='Proximal Validation (double)'!E4 -> 1 | F4: ='Proximal Validation (double)'!F4 -> 0.08 | G4: ='Proximal Validation (double)'!G4 -> 3.142 | H4: ='Proximal Validation (double)'!H4 -> 1.5707963 | ... Q4: ='Proximal Validation (double)'!Q4 -> 0.92483175 | R4: 0.79968704 | S4: 0.12165839 | T4: 1.7741893 | U4: 1.5707963 | V4: 0.72538438 | W4: 0.091362624 | X4: 2.8488835 | Y4: 1.5707963 | Z4: 0.00012260444 | AA4: =R4-A4 -> -0.20031296 | AB4: =S4-B4 -> 0.021658393 | AC4: =T4-C4 -> 0.2031893 | AD4: =U4-D4 -> 0 | AE4: =V4-E4 -> -0.27461562 | AF4: =W4-F4 -> 0.011362624 | AG4: =X4-G4 -> -0.29311652 | AH4: =Y4-H4 -> 0 | AI4: =AVERAGE(ABS(AA4),ABS(AE4)) -> 0.23746429 | AJ4: =AVERAGE(ABS(AB4),ABS(AF4)) -> 0.016510508 | AK4: =AVERAGE(ABS(AC4),ABS(AG4)) -> 0.24815291 | AL4: =MIN(A4,E4) -> 1 | AN4: {=AVERAGE(ABS(AA3:AA42))} -> 0.19393953 | AO4: {=AVERAGE(ABS(AB3:AB42))} -> 0.041850898 | AP4: {=AVERAGE(ABS(AC3:AC42))} -> 0.76423486 | AQ4: {=AVERAGE(ABS(AD3:AD42))} -> 0 | AR4: {=AVERAGE(ABS(AE3:AE42))} -> 0.22106596 | AS4: {=AVERAGE(ABS(AF3:AF42))} -> 0.028732106 | AT4: {=AVERAGE(ABS(AG3:AG42))} -> 0.62001345 | AU4: {=AVERAGE(ABS(AH3:AH42))} -> 0
A5: ='Proximal Validation (double)'!A5 -> 0.5 | B5: ='Proximal Validation (double)'!B5 -> 0.1 | C5: ='Proximal Validation (double)'!C5 -> 1.571 | D5: ='Proximal Validation (double)'!D5 -> 1.5707963 | E5: ='Proximal Validation (double)'!E5 -> 0.2 | F5: ='Proximal Validation (double)'!F5 -> 0.02 | G5: ='Proximal Validation (double)'!G5 -> 3.927 | H5: ='Proximal Validation (double)'!H5 -> 1.5707963 | ... Q5: ='Proximal Validation (double)'!Q5 -> 0.40386674 | R5: 0.73206812 | S5: 0.082722675 | T5: 1.5261981 | U5: 1.5707963 | V5: 0.36781316 | W5: 0.028822358 | X5: 4.2157205 | Y5: 1.5707963 | Z5: 8.7591708e-06 | AA5: =R5-A5 -> 0.23206812 | AB5: =S5-B5 -> -0.017277325 | AC5: =T5-C5 -> -0.044801914 | AD5: =U5-D5 -> 0 | AE5: =V5-E5 -> 0.16781316 | AF5: =W5-F5 -> 0.0088223583 | AG5: =X5-G5 -> 0.28872046 | AH5: =Y5-H5 -> 0 | AI5: =AVERAGE(ABS(AA5),ABS(AE5)) -> 0.19994064 | AJ5: =AVERAGE(ABS(AB5),ABS(AF5)) -> 0.013049842 | AK5: =AVERAGE(ABS(AC5),ABS(AG5)) -> 0.16676119 | AL5: =MIN(A5,E5) -> 0.2 | AN5: Absolute Mean Error (Across Both Forces)
A6: ='Proximal Validation (double)'!A6 -> 0.9 | B6: ='Proximal Validation (double)'!B6 -> 0.1 | C6: ='Proximal Validation (double)'!C6 -> 1.571 | D6: ='Proximal Validation (double)'!D6 -> 1.5707963 | E6: ='Proximal Validation (double)'!E6 -> 0.2 | F6: ='Proximal Validation (double)'!F6 -> 0.08 | G6: ='Proximal Validation (double)'!G6 -> 4.712 | H6: ='Proximal Validation (double)'!H6 -> 1.5707963 | ... Q6: ='Proximal Validation (double)'!Q6 -> 0.75826401 | R6: 0.1654761 | S6: 0.12135033 | T6: 3.4454387 | U6: 1.5707963 | V6: 0.85733569 | W6: 0.11961841 | X6: 1.373267 | Y6: 1.5707963 | Z6: 5.2554117e-05 | AA6: =R6-A6 -> -0.7345239 | AB6: =S6-B6 -> 0.021350327 | AC6: =T6-C6 -> 1.8744387 | AD6: =U6-D6 -> 0 | AE6: =V6-E6 -> 0.65733569 | AF6: =W6-F6 -> 0.039618411 | AG6: =X6-G6 -> -3.338733 | AH6: =Y6-H6 -> 0 | AI6: =AVERAGE(ABS(AA6),ABS(AE6)) -> 0.6959298 | AJ6: =AVERAGE(ABS(AB6),ABS(AF6)) -> 0.030484369 | AK6: =AVERAGE(ABS(AC6),ABS(AG6)) -> 2.6065859 | AL6: =MIN(A6,E6) -> 0.2 | AN6: force_error | AO6: position_error | AP6: angle_error
A7: ='Proximal Validation (double)'!A7 -> 0.1 | B7: ='Proximal Validation (double)'!B7 -> 0.12 | C7: ='Proximal Validation (double)'!C7 -> 1.571 | D7: ='Proximal Validation (double)'!D7 -> 1.5707963 | E7: ='Proximal Validation (double)'!E7 -> 1 | F7: ='Proximal Validation (double)'!F7 -> 0.06 | G7: ='Proximal Validation (double)'!G7 -> 3.927 | H7: ='Proximal Validation (double)'!H7 -> 1.5707963 | ... Q7: ='Proximal Validation (double)'!Q7 -> -0.43824503 | R7: 0.18750369 | S7: 0.044917344 | T7: 2.281403 | U7: 1.5707963 | V7: 0.81644059 | W7: 0.022206903 | X7: 3.9346549 | Y7: 1.5707963 | Z7: 0.0017594221 | AA7: =R7-A7 -> 0.087503689 | AB7: =S7-B7 -> -0.075082656 | AC7: =T7-C7 -> 0.71040301 | AD7: =U7-D7 -> 0 | AE7: =V7-E7 -> -0.18355941 | AF7: =W7-F7 -> -0.037793097 | AG7: =X7-G7 -> 0.0076548672 | AH7: =Y7-H7 -> 0 | AI7: =AVERAGE(ABS(AA7),ABS(AE7)) -> 0.13553155 | AJ7: =AVERAGE(ABS(AB7),ABS(AF7)) -> 0.056437877 | AK7: =AVERAGE(ABS(AC7),ABS(AG7)) -> 0.35902894 | AL7: =MIN(A7,E7) -> 0.1 | AN7: =AVERAGE(AN4,AR4) -> 0.20750275 | AO7: =AVERAGE(AO4,AS4) -> 0.035291502 | AP7: =AVERAGE(AP4,AT4) -> 0.69212415
A8: ='Proximal Validation (double)'!A8 -> 0.8 | B8: ='Proximal Validation (double)'!B8 -> 0.16 | C8: ='Proximal Validation (double)'!C8 -> 1.571 | D8: ='Proximal Validation (double)'!D8 -> 1.5707963 | E8: ='Proximal Validation (double)'!E8 -> 0.8 | F8: ='Proximal Validation (double)'!F8 -> 0.06 | G8: ='Proximal Validation (double)'!G8 -> 3.927 | H8: ='Proximal Validation (double)'!H8 -> 1.5707963 | ... Q8: ='Proximal Validation (double)'!Q8 -> 0.10888903 | R8: 0.6501892 | S8: 0.19973744 | T8: 1.7082561 | U8: 1.5707963 | V8: 0.60390629 | W8: 0.040781542 | X8: 3.9259979 | Y8: 1.5707963 | Z8: 8.5180463e-05 | AA8: =R8-A8 -> -0.1498108 | AB8: =S8-B8 -> 0.039737444 | AC8: =T8-C8 -> 0.13725609 | AD8: =U8-D8 -> 0 | AE8: =V8-E8 -> -0.19609371 | AF8: =W8-F8 -> -0.019218458 | AG8: =X8-G8 -> -0.0010021325 | AH8: =Y8-H8 -> 0 | AI8: =AVERAGE(ABS(AA8),ABS(AE8)) -> 0.17295225 | AJ8: =AVERAGE(ABS(AB8),ABS(AF8)) -> 0.029477951 | AK8: =AVERAGE(ABS(AC8),ABS(AG8)) -> 0.06912911 | AL8: =MIN(A8,E8) -> 0.8 | AN8: with 0.1 cuttof
A9: ='Proximal Validation (double)'!A9 -> 0.1 | B9: ='Proximal Validation (double)'!B9 -> 0.18 | C9: ='Proximal Validation (double)'!C9 -> 1.571 | D9: ='Proximal Validation (double)'!D9 -> 1.5707963 | E9: ='Proximal Validation (double)'!E9 -> 0.1 | F9: ='Proximal Validation (double)'!F9 -> 0.02 | G9: ='Proximal Validation (double)'!G9 -> 3.142 | H9: ='Proximal Validation (double)'!H9 -> 1.5707963 | ... Q9: ='Proximal Validation (double)'!Q9 -> 0.01807829 | R9: 0.32346654 | S9: 0.11918126 | T9: 7.8697616e-06 | U9: 1.5707963 | V9: 0.43230649 | W9: 0.10013197 | X9: 3.0995695 | Y9: 1.5707963 | Z9: 0.00023036382 | AA9: =R9-A9 -> 0.22346654 | AB9: =S9-B9 -> -0.060818737 | AC9: =T9-C9 -> -1.5709921 | AD9: =U9-D9 -> 0 | AE9: =V9-E9 -> 0.33230649 | AF9: =W9-F9 -> 0.080131974 | AG9: =X9-G9 -> -0.042430497 | AH9: =Y9-H9 -> 0 | AI9: =AVERAGE(ABS(AA9),ABS(AE9)) -> 0.27788651 | AJ9: =AVERAGE(ABS(AB9),ABS(AF9)) -> 0.070475356 | AK9: =AVERAGE(ABS(AC9),ABS(AG9)) -> 0.80671131 | AL9: =MIN(A9,E9) -> 0.1 | AN9: =AVERAGE(AI3,AI4,AI5,AI6,AI8,AI11,AI12,AI14,AI15,AI17,AI18,AI20,AI23,AI24,AI25,AI26,AI29,AI30,AI32,AI35,AI36,AI37,AI38,AI40,AI41) -> 0.20962991 | AO9: =AVERAGE(AJ3,AJ4,AJ5,AJ6,AJ8,AJ11,AJ12,AJ14,AJ15,AJ17,AJ18,AJ20,AJ23,AJ24,AJ25,AJ26,AJ29,AJ30,AJ32,AJ35,AJ36,AJ37,AJ38,AJ40,AJ41) -> 0.029998472 | AP9: =AVERAGE(AK3,AK4,AK5,AK6,AK8,AK11,AK12,AK14,AK15,AK17,AK18,AK20,AK23,AK24,AK25,AK26,AK29,AK30,AK32,AK35,AK36,AK37,AK38,AK40,AK41) -> 0.56146641
A10: ='Proximal Validation (double)'!A10 -> 0.9 | B10: ='Proximal Validation (double)'!B10 -> 0.18 | C10: ='Proximal Validation (double)'!C10 -> 1.571 | D10: ='Proximal Validation (double)'!D10 -> 1.5707963 | E10: ='Proximal Validation (double)'!E10 -> 0.1 | F10: ='Proximal Validation (double)'!F10 -> 0.08 | G10: ='Proximal Validation (double)'!G10 -> 4.712 | H10: ='Proximal Validation (double)'!H10 -> 1.5707963 | ... Q10: ='Proximal Validation (double)'!Q10 -> 0.51686221 | R10: 0.87468633 | S10: 0.16002164 | T10: 1.5576105 | U10: 1.5707963 | V10: 0.24885794 | W10: 0.020000218 | X10: 4.908112 | Y10: 1.5707963 | Z10: 7.8553308e-06 | AA10: =R10-A10 -> -0.025313666 | AB10: =S10-B10 -> -0.019978357 | AC10: =T10-C10 -> -0.013389496 | AD10: =U10-D10 -> 0 | AE10: =V10-E10 -> 0.14885794 | AF10: =W10-F10 -> -0.059999782 | AG10: =X10-G10 -> 0.19611196 | AH10: =Y10-H10 -> 0 | AI10: =AVERAGE(ABS(AA10),ABS(AE10)) -> 0.087085805 | AJ10: =AVERAGE(ABS(AB10),ABS(AF10)) -> 0.039989069 | AK10: =AVERAGE(ABS(AC10),ABS(AG10)) -> 0.10475073 | AL10: =MIN(A10,E10) -> 0.1 | AN10: with 0.2 cuttof
A11: ='Proximal Validation (double)'!A11 -> 0.3 | B11: ='Proximal Validation (double)'!B11 -> 0.18 | C11: ='Proximal Validation (double)'!C11 -> 1.571 | D11: ='Proximal Validation (double)'!D11 -> 1.5707963 | E11: ='Proximal Validation (double)'!E11 -> 0.9 | F11: ='Proximal Validation (double)'!F11 -> 0.08 | G11: ='Proximal Validation (double)'!G11 -> 4.712 | H11: ='Proximal Validation (double)'!H11 -> 1.5707963 | ... Q11: ='Proximal Validation (double)'!Q11 -> -0.58056563 | R11: 0.77011557 | S11: 0.021206796 | T11: 4.1494885 | U11: 1.5707963 | V11: 0.39537903 | W11: 0.020001241 | X11: 0.17828393 | Y11: 1.5707963 | Z11: 0.0019206175 | AA11: =R11-A11 -> 0.47011557 | AB11: =S11-B11 -> -0.1587932 | AC11: =T11-C11 -> 2.5784885 | AD11: =U11-D11 -> 0 | AE11: =V11-E11 -> -0.50462097 | AF11: =W11-F11 -> -0.059998759 | AG11: =X11-G11 -> -4.5337161 | AH11: =Y11-H11 -> 0 | AI11: =AVERAGE(ABS(AA11),ABS(AE11)) -> 0.48736827 | AJ11: =AVERAGE(ABS(AB11),ABS(AF11)) -> 0.10939598 | AK11: =AVERAGE(ABS(AC11),ABS(AG11)) -> 3.5561023 | AL11: =MIN(A11,E11) -> 0.3 | AN11: =AVERAGE(AI4,AI8,AI11,AI12,AI14,AI15,AI17,AI18,AI20,AI25,AI26,AI30,AI32,AI35,AI36,AI37,AI40,AI41) -> 0.19908791 | AO11: =AVERAGE(AJ4,AJ8,AJ11,AJ12,AJ14,AJ15,AJ17,AJ18,AJ20,AJ25,AJ26,AJ30,AJ32,AJ35,AJ36,AJ37,AJ40,AJ41) -> 0.028651958 | AP11: =AVERAGE(AK4,AK8,AK11,AK12,AK14,AK15,AK17,AK18,AK20,AK25,AK26,AK30,AK32,AK35,AK36,AK37,AK40,AK41) -> 0.45044866
A12: ='Proximal Validation (double)'!A12 -> 0.9 | B12: ='Proximal Validation (double)'!B12 -> 0.2 | C12: ='Proximal Validation (double)'!C12 -> 1.571 | D12: ='Proximal Validation (double)'!D12 -> 1.5707963 | E12: ='Proximal Validation (double)'!E12 -> 1 | F12: ='Proximal Validation (double)'!F12 -> 0.02 | G12: ='Proximal Validation (double)'!G12 -> 3.142 | H12: ='Proximal Validation (double)'!H12 -> 1.5707963 | ... Q12: ='Proximal Validation (double)'!Q12 -> 0.27430844 | R12: 0.85420592 | S12: 0.19581669 | T12: 1.6301671 | U12: 1.5707963 | V12: 0.99982159 | W12: 0.021487383 | X12: 3.4963871 | Y12: 1.5707963 | Z12: 0.00096995279 | AA12: =R12-A12 -> -0.045794077 | AB12: =S12-B12 -> -0.0041833065 | AC12: =T12-C12 -> 0.059167104 | AD12: =U12-D12 -> 0 | AE12: =V12-E12 -> -0.0001784109 | AF12: =W12-F12 -> 0.0014873832 | AG12: =X12-G12 -> 0.35438708 | AH12: =Y12-H12 -> 0 | AI12: =AVERAGE(ABS(AA12),ABS(AE12)) -> 0.022986244 | AJ12: =AVERAGE(ABS(AB12),ABS(AF12)) -> 0.0028353449 | AK12: =AVERAGE(ABS(AC12),ABS(AG12)) -> 0.20677709 | AL12: =MIN(A12,E12) -> 0.9 | AN12: 0.2 cutoof + no close
A13: ='Proximal Validation (double)'!A13 -> 0.1 | B13: ='Proximal Validation (double)'!B13 -> 0.2 | C13: ='Proximal Validation (double)'!C13 -> 1.571 | D13: ='Proximal Validation (double)'!D13 -> 1.5707963 | E13: ='Proximal Validation (double)'!E13 -> 0.3 | F13: ='Proximal Validation (double)'!F13 -> 0.08 | G13: ='Proximal Validation (double)'!G13 -> 3.142 | H13: ='Proximal Validation (double)'!H13 -> 1.5707963 | ... Q13: ='Proximal Validation (double)'!Q13 -> -0.036308467 | R13: 0.25286653 | S13: 0.14110367 | T13: 0.16521301 | U13: 1.5707963 | V13: 0.53277154 | W13: 0.087478028 | X13: 3.288401 | Y13: 1.5707963 | Z13: 0.00094798207 | AA13: =R13-A13 -> 0.15286653 | AB13: =S13-B13 -> -0.058896332 | AC13: =T13-C13 -> -1.405787 | AD13: =U13-D13 -> 0 | AE13: =V13-E13 -> 0.23277154 | AF13: =W13-F13 -> 0.0074780276 | AG13: =X13-G13 -> 0.14640101 | AH13: =Y13-H13 -> 0 | AI13: =AVERAGE(ABS(AA13),ABS(AE13)) -> 0.19281903 | AJ13: =AVERAGE(ABS(AB13),ABS(AF13)) -> 0.03318718 | AK13: =AVERAGE(ABS(AC13),ABS(AG13)) -> 0.776094 | AL13: =MIN(A13,E13) -> 0.1 | AN13: =AVERAGE(AI8,AI11,AI12,AI14,AI15,AI17,AI18,AI20,AI26,AI30,AI32,AI35,AI37,AI40,AI41) -> 0.17939104 | AO13: =AVERAGE(AJ8,AJ11,AJ12,AJ14,AJ15,AJ17,AJ18,AJ20,AJ26,AJ30,AJ32,AJ35,AJ37,AJ40,AJ41) -> 0.02908275 | AP13: =AVERAGE(AK8,AK11,AK12,AK14,AK15,AK17,AK18,AK20,AK26,AK30,AK32,AK35,AK37,AK40,AK41) -> 0.46185746
A14: ='Proximal Validation (double)'!A14 -> 0.9 | B14: ='Proximal Validation (double)'!B14 -> 0.2 | C14: ='Proximal Validation (double)'!C14 -> 1.571 | D14: ='Proximal Validation (double)'!D14 -> 1.5707963 | E14: ='Proximal Validation (double)'!E14 -> 0.3 | F14: ='Proximal Validation (double)'!F14 -> 0.02 | G14: ='Proximal Validation (double)'!G14 -> 4.712 | H14: ='Proximal Validation (double)'!H14 -> 1.5707963 | ... Q14: ='Proximal Validation (double)'!Q14 -> 0.042876139 | R14: 0.94895011 | S14: 0.19193087 | T14: 1.5942902 | U14: 1.5707963 | V14: 0.60419374 | W14: 0.02941633 | X14: 4.6950774 | Y14: 1.5707963 | Z14: 0.0015049131 | AA14: =R14-A14 -> 0.048950112 | AB14: =S14-B14 -> -0.0080691344 | AC14: =T14-C14 -> 0.023290192 | AD14: =U14-D14 -> 0 | AE14: =V14-E14 -> 0.30419374 | AF14: =W14-F14 -> 0.0094163303 | AG14: =X14-G14 -> -0.016922604 | AH14: =Y14-H14 -> 0 | AI14: =AVERAGE(ABS(AA14),ABS(AE14)) -> 0.17657193 | AJ14: =AVERAGE(ABS(AB14),ABS(AF14)) -> 0.0087427324 | AK14: =AVERAGE(ABS(AC14),ABS(AG14)) -> 0.020106398 | AL14: =MIN(A14,E14) -> 0.3
A15: ='Proximal Validation (double)'!A15 -> 0.9 | B15: ='Proximal Validation (double)'!B15 -> 0.1 | C15: ='Proximal Validation (double)'!C15 -> 2.356 | D15: ='Proximal Validation (double)'!D15 -> 1.5707963 | E15: ='Proximal Validation (double)'!E15 -> 0.9 | F15: ='Proximal Validation (double)'!F15 -> 0.02 | G15: ='Proximal Validation (double)'!G15 -> 4.712 | H15: ='Proximal Validation (double)'!H15 -> 1.5707963 | ... Q15: ='Proximal Validation (double)'!Q15 -> -0.18459481 | R15: 0.63221595 | S15: 0.18015921 | T15: 2.3388021 | U15: 1.5707963 | V15: 0.63654976 | W15: 0.029117786 | X15: 4.3390431 | Y15: 1.5707963 | Z15: 0.00016191079 | AA15: =R15-A15 -> -0.26778405 | AB15: =S15-B15 -> 0.080159206 | AC15: =T15-C15 -> -0.017197875 | AD15: =U15-D15 -> 0 | AE15: =V15-E15 -> -0.26345024 | AF15: =W15-F15 -> 0.0091177861 | AG15: =X15-G15 -> -0.37295691 | AH15: =Y15-H15 -> 0 | AI15: =AVERAGE(ABS(AA15),ABS(AE15)) -> 0.26561714 | AJ15: =AVERAGE(ABS(AB15),ABS(AF15)) -> 0.044638496 | AK15: =AVERAGE(ABS(AC15),ABS(AG15)) -> 0.19507739 | AL15: =MIN(A15,E15) -> 0.9
A16: ='Proximal Validation (double)'!A16 -> 0.4 | B16: ='Proximal Validation (double)'!B16 -> 0.12 | C16: ='Proximal Validation (double)'!C16 -> 2.356 | D16: ='Proximal Validation (double)'!D16 -> 1.5707963 | E16: ='Proximal Validation (double)'!E16 -> 0.1 | F16: ='Proximal Validation (double)'!F16 -> 0.06 | G16: ='Proximal Validation (double)'!G16 -> 3.142 | H16: ='Proximal Validation (double)'!H16 -> 1.5707963 | ... Q16: ='Proximal Validation (double)'!Q16 -> 0.24705727 | R16: 0.49979549 | S16: 0.072360425 | T16: 2.6206928 | U16: 1.5707963 | V16: 0.10398351 | W16: 0.0573916 | X16: 6.2825949 | Y16: 1.5707963 | Z16: 0.00067608224 | AA16: =R16-A16 -> 0.099795491 | AB16: =S16-B16 -> -0.047639575 | AC16: =T16-C16 -> 0.26469283 | AD16: =U16-D16 -> 0 | AE16: =V16-E16 -> 0.003983509 | AF16: =W16-F16 -> -0.0026083996 | AG16: =X16-G16 -> 3.1405949 | AH16: =Y16-H16 -> 0 | AI16: =AVERAGE(ABS(AA16),ABS(AE16)) -> 0.0518895 | AJ16: =AVERAGE(ABS(AB16),ABS(AF16)) -> 0.025123988 | AK16: =AVERAGE(ABS(AC16),ABS(AG16)) -> 1.7026439 | AL16: =MIN(A16,E16) -> 0.1
A17: ='Proximal Validation (double)'!A17 -> 1 | B17: ='Proximal Validation (double)'!B17 -> 0.14 | C17: ='Proximal Validation (double)'!C17 -> 2.356 | D17: ='Proximal Validation (double)'!D17 -> 1.5707963 | E17: ='Proximal Validation (double)'!E17 -> 0.4 | F17: ='Proximal Validation (double)'!F17 -> 0.04 | G17: ='Proximal Validation (double)'!G17 -> 3.927 | H17: ='Proximal Validation (double)'!H17 -> 1.5707963 | ... Q17: ='Proximal Validation (double)'!Q17 -> 0.42077422 | R17: 0.95187652 | S17: 0.15066597 | T17: 2.4241415 | U17: 1.5707963 | V17: 0.32906563 | W17: 0.020000212 | X17: 3.5356751 | Y17: 1.5707963 | Z17: 0.00012830069 | AA17: =R17-A17 -> -0.048123484 | AB17: =S17-B17 -> 0.010665971 | AC17: =T17-C17 -> 0.068141512 | AD17: =U17-D17 -> 0 | AE17: =V17-E17 -> -0.070934372 | AF17: =W17-F17 -> -0.019999788 | AG17: =X17-G17 -> -0.39132495 | AH17: =Y17-H17 -> 0 | AI17: =AVERAGE(ABS(AA17),ABS(AE17)) -> 0.059528928 | AJ17: =AVERAGE(ABS(AB17),ABS(AF17)) -> 0.01533288 | AK17: =AVERAGE(ABS(AC17),ABS(AG17)) -> 0.22973323 | AL17: =MIN(A17,E17) -> 0.4
A18: ='Proximal Validation (double)'!A18 -> 0.4 | B18: ='Proximal Validation (double)'!B18 -> 0.18 | C18: ='Proximal Validation (double)'!C18 -> 2.356 | D18: ='Proximal Validation (double)'!D18 -> 1.5707963 | E18: ='Proximal Validation (double)'!E18 -> 0.7 | F18: ='Proximal Validation (double)'!F18 -> 0.04 | G18: ='Proximal Validation (double)'!G18 -> 3.142 | H18: ='Proximal Validation (double)'!H18 -> 1.5707963 | ... Q18: ='Proximal Validation (double)'!Q18 -> 0.23870468 | R18: 0.96413093 | S18: 0.073033514 | T18: 2.4495466 | U18: 1.5707963 | V18: 0.38543393 | W18: 0.025633396 | X18: 4.4495976 | Y18: 1.5707963 | Z18: 8.8079781e-05 | AA18: =R18-A18 -> 0.56413093 | AB18: =S18-B18 -> -0.10696649 | AC18: =T18-C18 -> 0.093546608 | AD18: =U18-D18 -> 0 | AE18: =V18-E18 -> -0.31456607 | AF18: =W18-F18 -> -0.014366604 | AG18: =X18-G18 -> 1.3075976 | AH18: =Y18-H18 -> 0 | AI18: =AVERAGE(ABS(AA18),ABS(AE18)) -> 0.4393485 | AJ18: =AVERAGE(ABS(AB18),ABS(AF18)) -> 0.060666545 | AK18: =AVERAGE(ABS(AC18),ABS(AG18)) -> 0.70057211 | AL18: =MIN(A18,E18) -> 0.4
A19: ='Proximal Validation (double)'!A19 -> 0.1 | B19: ='Proximal Validation (double)'!B19 -> 0.18 | C19: ='Proximal Validation (double)'!C19 -> 2.356 | D19: ='Proximal Validation (double)'!D19 -> 1.5707963 | E19: ='Proximal Validation (double)'!E19 -> 0.2 | F19: ='Proximal Validation (double)'!F19 -> 0.06 | G19: ='Proximal Validation (double)'!G19 -> 4.712 | H19: ='Proximal Validation (double)'!H19 -> 1.5707963 | ... Q19: ='Proximal Validation (double)'!Q19 -> -0.15806177 | R19: 0.51439997 | S19: 0.12664908 | T19: 1.7915008 | U19: 1.5707963 | V19: 0.66590288 | W19: 0.10215892 | X19: 4.8431692 | Y19: 1.5707963 | Z19: 0.00027635102 | AA19: =R19-A19 -> 0.41439997 | AB19: =S19-B19 -> -0.053350922 | AC19: =T19-C19 -> -0.56449915 | AD19: =U19-D19 -> 0 | AE19: =V19-E19 -> 0.46590288 | AF19: =W19-F19 -> 0.04215892 | AG19: =X19-G19 -> 0.13116919 | AH19: =Y19-H19 -> 0 | AI19: =AVERAGE(ABS(AA19),ABS(AE19)) -> 0.44015143 | AJ19: =AVERAGE(ABS(AB19),ABS(AF19)) -> 0.047754921 | AK19: =AVERAGE(ABS(AC19),ABS(AG19)) -> 0.34783417 | AL19: =MIN(A19,E19) -> 0.1
A20: ='Proximal Validation (double)'!A20 -> 0.9 | B20: ='Proximal Validation (double)'!B20 -> 0.2 | C20: ='Proximal Validation (double)'!C20 -> 2.356 | D20: ='Proximal Validation (double)'!D20 -> 1.5707963 | E20: ='Proximal Validation (double)'!E20 -> 0.3 | F20: ='Proximal Validation (double)'!F20 -> 0.06 | G20: ='Proximal Validation (double)'!G20 -> 3.142 | H20: ='Proximal Validation (double)'!H20 -> 1.5707963 | ... Q20: ='Proximal Validation (double)'!Q20 -> 0.2630704 | R20: 0.82050338 | S20: 0.19116464 | T20: 2.4039776 | U20: 1.5707963 | V20: 0.17502923 | W20: 0.045763709 | X20: 4.3213098 | Y20: 1.5707963 | Z20: 5.9261602e-05 | AA20: =R20-A20 -> -0.079496615 | AB20: =S20-B20 -> -0.0088353617 | AC20: =T20-C20 -> 0.04797758 | AD20: =U20-D20 -> 0 | AE20: =V20-E20 -> -0.12497077 | AF20: =W20-F20 -> -0.014236291 | AG20: =X20-G20 -> 1.1793098 | AH20: =Y20-H20 -> 0 | AI20: =AVERAGE(ABS(AA20),ABS(AE20)) -> 0.10223369 | AJ20: =AVERAGE(ABS(AB20),ABS(AF20)) -> 0.011535826 | AK20: =AVERAGE(ABS(AC20),ABS(AG20)) -> 0.61364367 | AL20: =MIN(A20,E20) -> 0.3
A21: ='Proximal Validation (double)'!A21 -> 0.1 | B21: ='Proximal Validation (double)'!B21 -> 0.1 | C21: ='Proximal Validation (double)'!C21 -> 3.142 | D21: ='Proximal Validation (double)'!D21 -> 1.5707963 | E21: ='Proximal Validation (double)'!E21 -> 0.3 | F21: ='Proximal Validation (double)'!F21 -> 0.08 | G21: ='Proximal Validation (double)'!G21 -> 3.927 | H21: ='Proximal Validation (double)'!H21 -> 1.5707963 | ... Q21: ='Proximal Validation (double)'!Q21 -> -0.20531408 | R21: 0.22103877 | S21: 0.13320011 | T21: 0.64679327 | U21: 1.5707963 | V21: 0.55652122 | W21: 0.092139069 | X21: 3.7965951 | Y21: 1.5707963 | Z21: 0.00025491071 | AA21: =R21-A21 -> 0.12103877 | AB21: =S21-B21 -> 0.033200109 | AC21: =T21-C21 -> -2.4952067 | AD21: =U21-D21 -> 0 | AE21: =V21-E21 -> 0.25652122 | AF21: =W21-F21 -> 0.012139069 | AG21: =X21-G21 -> -0.13040494 | AH21: =Y21-H21 -> 0 | AI21: =AVERAGE(ABS(AA21),ABS(AE21)) -> 0.18877999 | AJ21: =AVERAGE(ABS(AB21),ABS(AF21)) -> 0.022669589 | AK21: =AVERAGE(ABS(AC21),ABS(AG21)) -> 1.3128058 | AL21: =MIN(A21,E21) -> 0.1
A22: ='Proximal Validation (double)'!A22 -> 0.1 | B22: ='Proximal Validation (double)'!B22 -> 0.2 | C22: ='Proximal Validation (double)'!C22 -> 3.142 | D22: ='Proximal Validation (double)'!D22 -> 1.5707963 | E22: ='Proximal Validation (double)'!E22 -> 0.8 | F22: ='Proximal Validation (double)'!F22 -> 0.02 | G22: ='Proximal Validation (double)'!G22 -> 3.927 | H22: ='Proximal Validation (double)'!H22 -> 1.5707963 | ... Q22: ='Proximal Validation (double)'!Q22 -> -0.54190034 | R22: 0.16991676 | S22: 0.050818834 | T22: 1.4964866 | U22: 1.5707963 | V22: 0.94314727 | W22: 0.025205779 | X22: 3.9971529 | Y22: 1.5707963 | Z22: 0.00029164015 | AA22: =R22-A22 -> 0.069916761 | AB22: =S22-B22 -> -0.14918117 | AC22: =T22-C22 -> -1.6455134 | AD22: =U22-D22 -> 0 | AE22: =V22-E22 -> 0.14314727 | AF22: =W22-F22 -> 0.0052057791 | AG22: =X22-G22 -> 0.070152906 | AH22: =Y22-H22 -> 0 | AI22: =AVERAGE(ABS(AA22),ABS(AE22)) -> 0.10653202 | AJ22: =AVERAGE(ABS(AB22),ABS(AF22)) -> 0.077193473 | AK22: =AVERAGE(ABS(AC22),ABS(AG22)) -> 0.85783317 | AL22: =MIN(A22,E22) -> 0.1
A23: ='Proximal Validation (double)'!A23 -> 0.9 | B23: ='Proximal Validation (double)'!B23 -> 0.1 | C23: ='Proximal Validation (double)'!C23 -> 3.927 | D23: ='Proximal Validation (double)'!D23 -> 1.5707963 | E23: ='Proximal Validation (double)'!E23 -> 0.2 | F23: ='Proximal Validation (double)'!F23 -> 0.02 | G23: ='Proximal Validation (double)'!G23 -> 3.142 | H23: ='Proximal Validation (double)'!H23 -> 1.5707963 | ... Q23: ='Proximal Validation (double)'!Q23 -> -0.7054401 | R23: 0.89327261 | S23: 0.090695103 | T23: 4.1994207 | U23: 1.5707963 | V23: 0.40104104 | W23: 0.058711014 | X23: 2.9820319 | Y23: 1.5707963 | Z23: 0.00019171096 | AA23: =R23-A23 -> -0.0067273873 | AB23: =S23-B23 -> -0.0093048969 | AC23: =T23-C23 -> 0.27242074 | AD23: =U23-D23 -> 0 | AE23: =V23-E23 -> 0.20104104 | AF23: =W23-F23 -> 0.038711014 | AG23: =X23-G23 -> -0.15996814 | AH23: =Y23-H23 -> 0 | AI23: =AVERAGE(ABS(AA23),ABS(AE23)) -> 0.10388421 | AJ23: =AVERAGE(ABS(AB23),ABS(AF23)) -> 0.024007956 | AK23: =AVERAGE(ABS(AC23),ABS(AG23)) -> 0.21619444 | AL23: =MIN(A23,E23) -> 0.2
A24: ='Proximal Validation (double)'!A24 -> 0.2 | B24: ='Proximal Validation (double)'!B24 -> 0.12 | C24: ='Proximal Validation (double)'!C24 -> 3.927 | D24: ='Proximal Validation (double)'!D24 -> 1.5707963 | E24: ='Proximal Validation (double)'!E24 -> 0.2 | F24: ='Proximal Validation (double)'!F24 -> 0.02 | G24: ='Proximal Validation (double)'!G24 -> 4.712 | H24: ='Proximal Validation (double)'!H24 -> 1.5707963 | ... Q24: ='Proximal Validation (double)'!Q24 -> -0.2977441 | R24: 0.4047224 | S24: 0.1277961 | T24: 1.7226836 | U24: 1.5707963 | V24: 0.69999223 | W24: 0.096652763 | X24: 4.638951 | Y24: 1.5707963 | Z24: 5.9704159e-05 | AA24: =R24-A24 -> 0.2047224 | AB24: =S24-B24 -> 0.0077961022 | AC24: =T24-C24 -> -2.2043164 | AD24: =U24-D24 -> 0 | AE24: =V24-E24 -> 0.49999223 | AF24: =W24-F24 -> 0.076652763 | AG24: =X24-G24 -> -0.073049011 | AH24: =Y24-H24 -> 0 | AI24: =AVERAGE(ABS(AA24),ABS(AE24)) -> 0.35235731 | AJ24: =AVERAGE(ABS(AB24),ABS(AF24)) -> 0.042224432 | AK24: =AVERAGE(ABS(AC24),ABS(AG24)) -> 1.1386827 | AL24: =MIN(A24,E24) -> 0.2
A25: ='Proximal Validation (double)'!A25 -> 0.6 | B25: ='Proximal Validation (double)'!B25 -> 0.12 | C25: ='Proximal Validation (double)'!C25 -> 3.927 | D25: ='Proximal Validation (double)'!D25 -> 1.5707963 | E25: ='Proximal Validation (double)'!E25 -> 0.5 | F25: ='Proximal Validation (double)'!F25 -> 0.08 | G25: ='Proximal Validation (double)'!G25 -> 4.712 | H25: ='Proximal Validation (double)'!H25 -> 1.5707963 | ... Q25: ='Proximal Validation (double)'!Q25 -> -0.93568027 | R25: 0.13122037 | S25: 0.15829391 | T25: 3.2429475 | U25: 1.5707963 | V25: 0.9853185 | W25: 0.093217225 | X25: 4.4306843 | Y25: 1.5707963 | Z25: 0.00018738898 | AA25: =R25-A25 -> -0.46877963 | AB25: =S25-B25 -> 0.038293906 | AC25: =T25-C25 -> -0.68405245 | AD25: =U25-D25 -> 0 | AE25: =V25-E25 -> 0.4853185 | AF25: =W25-F25 -> 0.013217225 | AG25: =X25-G25 -> -0.28131571 | AH25: =Y25-H25 -> 0 | AI25: =AVERAGE(ABS(AA25),ABS(AE25)) -> 0.47704907 | AJ25: =AVERAGE(ABS(AB25),ABS(AF25)) -> 0.025755565 | AK25: =AVERAGE(ABS(AC25),ABS(AG25)) -> 0.48268408 | AL25: =MIN(A25,E25) -> 0.5
... A42: ='Proximal Validation (double)'!A42 -> 0.2 | B42: ='Proximal Validation (double)'!B42 -> 0.2 | C42: ='Proximal Validation (double)'!C42 -> 4.712 | D42: ='Proximal Validation (double)'!D42 -> 1.5707963 | E42: ='Proximal Validation (double)'!E42 -> 0.1 | F42: ='Proximal Validation (double)'!F42 -> 0.08 | G42: ='Proximal Validation (double)'!G42 -> 3.927 | H42: ='Proximal Validation (double)'!H42 -> 1.5707963 | ... Q42: ='Proximal Validation (double)'!Q42 -> -0.20783865 | R42: 0.66375697 | S42: 0.10305129 | T42: 4.6446017 | U42: 1.5707963 | V42: 0.45374075 | W42: 0.065374902 | X42: 1.6615157 | Y42: 1.5707963 | Z42: 1.2728068e-05 | AA42: =R42-A42 -> 0.46375697 | AB42: =S42-B42 -> -0.09694871 | AC42: =T42-C42 -> -0.067398299 | AD42: =U42-D42 -> 0 | AE42: =V42-E42 -> 0.35374075 | AF42: =W42-F42 -> -0.014625098 | AG42: =X42-G42 -> -2.2654843 | AH42: =Y42-H42 -> 0 | AI42: =AVERAGE(ABS(AA42),ABS(AE42)) -> 0.40874886 | AJ42: =AVERAGE(ABS(AB42),ABS(AF42)) -> 0.055786904 | AK42: =AVERAGE(ABS(AC42),ABS(AG42)) -> 1.1664413 | AL42: =MIN(A42,E42) -> 0.1

Sheet Distal Vali (double 1.75 0.2F+)
A1: Ground Truth | L1: 6-Axis FT Sensor | R1: SoRoSim get_distal_value | AA1: Distal Errors | AI1: Stats
A2: F1 (N) | B2: s1 (m) | C2: el1 (rad) | D2: az1 (rad) | E2: F2 (N) | F2: s2 (m) | G2: el2 (rad) | H2: az2 (rad) | I2: tau1 (N) | J2: tau2 (N) | K2: tau3 (N) | L2: Tx (Nm) | M2: Ty (Nm) | N2: Tz(Nm) | O2: Fx (N) | P2: Fy (N) | Q2: Fz (N) | R2: F1 (N) | S2: s1 (m) | T2: el1 (rad) | U2: az1 (rad) | V2: F2 (N) | W2: s2 (m) | X2: el2 (rad) | Y2: az2 (rad) | Z2: f_final | AA2: F1 (N) | AB2: s1 (m) | AC2: el1 (rad) | AD2: az1 (rad) | AE2: F2 (N) | AF2: s2 (m) | AG2: el2 (rad) | AH2: az2 (rad) | AI2: force_error | AJ2: position_error | AK2: angle_error | AL2: min_f | AM2: Absolute Mean Error
A3: ='Proximal Validation (double)'!A11 -> 0.3 | B3: ='Proximal Validation (double)'!B11 -> 0.18 | C3: ='Proximal Validation (double)'!C11 -> 1.571 | D3: ='Proximal Validation (double)'!D11 -> 1.5707963 | E3: ='Proximal Validation (double)'!E11 -> 0.9 | F3: ='Proximal Validation (double)'!F11 -> 0.08 | G3: ='Proximal Validation (double)'!G11 -> 4.712 | H3: ='Proximal Validation (double)'!H11 -> 1.5707963 | ... Q3: ='Proximal Validation (double)'!Q11 -> -0.58056563 | R3: 0.77011557 | S3: 0.021206796 | T3: 4.1494885 | U3: 1.5707963 | V3: 0.39537903 | W3: 0.020001241 | X3: 0.17828393 | Y3: 1.5707963 | Z3: 0.0019206175 | AA3: =R3-A3 -> 0.47011557 | AB3: =S3-B3 -> -0.1587932 | AC3: =T3-C3 -> 2.5784885 | AD3: =U3-D3 -> 0 | AE3: =V3-E3 -> -0.50462097 | AF3: =W3-F3 -> -0.059998759 | AG3: =X3-G3 -> -4.5337161 | AH3: =Y3-H3 -> 0 | AI3: =AVERAGE(ABS(AA3),ABS(AE3)) -> 0.48736827 | AJ3: =AVERAGE(ABS(AB3),ABS(AF3)) -> 0.10939598 | AK3: =AVERAGE(ABS(AC3),ABS(AG3)) -> 3.5561023 | AL3: =MIN(A3,E3) -> 0.3 | AM3: {=AVERAGE(ABS(AA3:AA7))} -> 0.4173657 | AN3: {=AVERAGE(ABS(AB3:AB7))} -> 0.077510441 | AO3: {=AVERAGE(ABS(AC3:AC7))} -> 0.68053297 | AP3: {=AVERAGE(ABS(AD3:AD7))} -> 0 | AQ3: {=AVERAGE(ABS(AE3:AE7))} -> 0.35521044 | AR3: {=AVERAGE(ABS(AF3:AF7))} -> 0.023171056 | AS3: {=AVERAGE(ABS(AG3:AG7))} -> 1.3288273 | AT3: {=AVERAGE(ABS(AH3:AH20))} -> 0
A4: ='Proximal Validation (double)'!A25 -> 0.6 | B4: ='Proximal Validation (double)'!B25 -> 0.12 | C4: ='Proximal Validation (double)'!C25 -> 3.927 | D4: ='Proximal Validation (double)'!D25 -> 1.5707963 | E4: ='Proximal Validation (double)'!E25 -> 0.5 | F4: ='Proximal Validation (double)'!F25 -> 0.08 | G4: ='Proximal Validation (double)'!G25 -> 4.712 | H4: ='Proximal Validation (double)'!H25 -> 1.5707963 | ... Q4: ='Proximal Validation (double)'!Q25 -> -0.93568027 | R4: 0.13122037 | S4: 0.15829391 | T4: 3.2429475 | U4: 1.5707963 | V4: 0.9853185 | W4: 0.093217225 | X4: 4.4306843 | Y4: 1.5707963 | Z4: 0.00018738898 | AA4: =R4-A4 -> -0.46877963 | AB4: =S4-B4 -> 0.038293906 | AC4: =T4-C4 -> -0.68405245 | AD4: =U4-D4 -> 0 | AE4: =V4-E4 -> 0.4853185 | AF4: =W4-F4 -> 0.013217225 | AG4: =X4-G4 -> -0.28131571 | AH4: =Y4-H4 -> 0 | AI4: =AVERAGE(ABS(AA4),ABS(AE4)) -> 0.47704907 | AJ4: =AVERAGE(ABS(AB4),ABS(AF4)) -> 0.025755565 | AK4: =AVERAGE(ABS(AC4),ABS(AG4)) -> 0.48268408 | AL4: =MIN(A4,E4) -> 0.5 | AM4: =AVERAGE(AM3,AQ3) -> 0.38628807 | AN4: =AVERAGE(AN3,AR3) -> 0.050340748 | AO4: =AVERAGE(AO3,AS3) -> 1.0046801
A5: ='Proximal Validation (double)'!A18 -> 0.4 | B5: ='Proximal Validation (double)'!B18 -> 0.18 | C5: ='Proximal Validation (double)'!C18 -> 2.356 | D5: ='Proximal Validation (double)'!D18 -> 1.5707963 | E5: ='Proximal Validation (double)'!E18 -> 0.7 | F5: ='Proximal Validation (double)'!F18 -> 0.04 | G5: ='Proximal Validation (double)'!G18 -> 3.142 | H5: ='Proximal Validation (double)'!H18 -> 1.5707963 | ... Q5: ='Proximal Validation (double)'!Q18 -> 0.23870468 | R5: 0.96413093 | S5: 0.073033514 | T5: 2.4495466 | U5: 1.5707963 | V5: 0.38543393 | W5: 0.025633396 | X5: 4.4495976 | Y5: 1.5707963 | Z5: 8.8079781e-05 | AA5: =R5-A5 -> 0.56413093 | AB5: =S5-B5 -> -0.10696649 | AC5: =T5-C5 -> 0.093546608 | AD5: =U5-D5 -> 0 | AE5: =V5-E5 -> -0.31456607 | AF5: =W5-F5 -> -0.014366604 | AG5: =X5-G5 -> 1.3075976 | AH5: =Y5-H5 -> 0 | AI5: =AVERAGE(ABS(AA5),ABS(AE5)) -> 0.4393485 | AJ5: =AVERAGE(ABS(AB5),ABS(AF5)) -> 0.060666545 | AK5: =AVERAGE(ABS(AC5),ABS(AG5)) -> 0.70057211 | AL5: =MIN(A5,E5) -> 0.4
A6: ='Proximal Validation (double)'!A15 -> 0.9 | B6: ='Proximal Validation (double)'!B15 -> 0.1 | C6: ='Proximal Validation (double)'!C15 -> 2.356 | D6: ='Proximal Validation (double)'!D15 -> 1.5707963 | E6: ='Proximal Validation (double)'!E15 -> 0.9 | F6: ='Proximal Validation (double)'!F15 -> 0.02 | G6: ='Proximal Validation (double)'!G15 -> 4.712 | H6: ='Proximal Validation (double)'!H15 -> 1.5707963 | ... Q6: ='Proximal Validation (double)'!Q15 -> -0.18459481 | R6: 0.63221595 | S6: 0.18015921 | T6: 2.3388021 | U6: 1.5707963 | V6: 0.63654976 | W6: 0.029117786 | X6: 4.3390431 | Y6: 1.5707963 | Z6: 0.00016191079 | AA6: =R6-A6 -> -0.26778405 | AB6: =S6-B6 -> 0.080159206 | AC6: =T6-C6 -> -0.017197875 | AD6: =U6-D6 -> 0 | AE6: =V6-E6 -> -0.26345024 | AF6: =W6-F6 -> 0.0091177861 | AG6: =X6-G6 -> -0.37295691 | AH6: =Y6-H6 -> 0 | AI6: =AVERAGE(ABS(AA6),ABS(AE6)) -> 0.26561714 | AJ6: =AVERAGE(ABS(AB6),ABS(AF6)) -> 0.044638496 | AK6: =AVERAGE(ABS(AC6),ABS(AG6)) -> 0.19507739 | AL6: =MIN(A6,E6) -> 0.9
A7: ='Proximal Validation (double)'!A40 -> 0.8 | B7: ='Proximal Validation (double)'!B40 -> 0.18 | C7: ='Proximal Validation (double)'!C40 -> 4.712 | D7: ='Proximal Validation (double)'!D40 -> 1.5707963 | E7: ='Proximal Validation (double)'!E40 -> 0.6 | F7: ='Proximal Validation (double)'!F40 -> 0.06 | G7: ='Proximal Validation (double)'!G40 -> 4.712 | H7: ='Proximal Validation (double)'!H40 -> 1.5707963 | ... Q7: ='Proximal Validation (double)'!Q40 -> -1.1885303 | R7: 0.48398169 | S7: 0.17666059 | T7: 4.7413795 | U7: 1.5707963 | V7: 0.80809642 | W7: 0.079154903 | X7: 4.5634499 | Y7: 1.5707963 | Z7: 0.00055185796 | AA7: =R7-A7 -> -0.31601831 | AB7: =S7-B7 -> -0.0033394052 | AC7: =T7-C7 -> 0.029379485 | AD7: =U7-D7 -> 0 | AE7: =V7-E7 -> 0.20809642 | AF7: =W7-F7 -> 0.019154903 | AG7: =X7-G7 -> -0.14855005 | AH7: =Y7-H7 -> 0 | AI7: =AVERAGE(ABS(AA7),ABS(AE7)) -> 0.26205736 | AJ7: =AVERAGE(ABS(AB7),ABS(AF7)) -> 0.011247154 | AK7: =AVERAGE(ABS(AC7),ABS(AG7)) -> 0.088964768 | AL7: =MIN(A7,E7) -> 0.6
A8: ='Proximal Validation (double)'!A4 -> 1 | B8: ='Proximal Validation (double)'!B4 -> 0.1 | C8: ='Proximal Validation (double)'!C4 -> 1.571 | D8: ='Proximal Validation (double)'!D4 -> 1.5707963 | E8: ='Proximal Validation (double)'!E4 -> 1 | F8: ='Proximal Validation (double)'!F4 -> 0.08 | G8: ='Proximal Validation (double)'!G4 -> 3.142 | H8: ='Proximal Validation (double)'!H4 -> 1.5707963 | ... Q8: ='Proximal Validation (double)'!Q4 -> 0.92483175 | R8: 0.79968704 | S8: 0.12165839 | T8: 1.7741893 | U8: 1.5707963 | V8: 0.72538438 | W8: 0.091362624 | X8: 2.8488835 | Y8: 1.5707963 | Z8: 0.00012260444 | AA8: =R8-A8 -> -0.20031296 | AB8: =S8-B8 -> 0.021658393 | AC8: =T8-C8 -> 0.2031893 | AD8: =U8-D8 -> 0 | AE8: =V8-E8 -> -0.27461562 | AF8: =W8-F8 -> 0.011362624 | AG8: =X8-G8 -> -0.29311652 | AH8: =Y8-H8 -> 0 | AI8: =AVERAGE(ABS(AA8),ABS(AE8)) -> 0.23746429 | AJ8: =AVERAGE(ABS(AB8),ABS(AF8)) -> 0.016510508 | AK8: =AVERAGE(ABS(AC8),ABS(AG8)) -> 0.24815291 | AL8: =MIN(A8,E8) -> 1
A9: ='Proximal Validation (double)'!A26 -> 0.7 | B9: ='Proximal Validation (double)'!B26 -> 0.16 | C9: ='Proximal Validation (double)'!C26 -> 3.927 | D9: ='Proximal Validation (double)'!D26 -> 1.5707963 | E9: ='Proximal Validation (double)'!E26 -> 1 | F9: ='Proximal Validation (double)'!F26 -> 0.04 | G9: ='Proximal Validation (double)'!G26 -> 3.927 | H9: ='Proximal Validation (double)'!H26 -> 1.5707963 | ... Q9: ='Proximal Validation (double)'!Q26 -> -1.0432312 | R9: 0.9464302 | S9: 0.094223379 | T9: 4.1978261 | U9: 1.5707963 | V9: 0.79929207 | W9: 0.068498072 | X9: 3.459853 | Y9: 1.5707963 | Z9: 0.00028292554 | AA9: =R9-A9 -> 0.2464302 | AB9: =S9-B9 -> -0.065776621 | AC9: =T9-C9 -> 0.27082605 | AD9: =U9-D9 -> 0 | AE9: =V9-E9 -> -0.20070793 | AF9: =W9-F9 -> 0.028498072 | AG9: =X9-G9 -> -0.467147 | AH9: =Y9-H9 -> 0 | AI9: =AVERAGE(ABS(AA9),ABS(AE9)) -> 0.22356907 | AJ9: =AVERAGE(ABS(AB9),ABS(AF9)) -> 0.047137346 | AK9: =AVERAGE(ABS(AC9),ABS(AG9)) -> 0.36898653 | AL9: =MIN(A9,E9) -> 0.7
A10: ='Proximal Validation (double)'!A37 -> 0.3 | B10: ='Proximal Validation (double)'!B37 -> 0.18 | C10: ='Proximal Validation (double)'!C37 -> 4.712 | D10: ='Proximal Validation (double)'!D37 -> 1.5707963 | E10: ='Proximal Validation (double)'!E37 -> 0.3 | F10: ='Proximal Validation (double)'!F37 -> 0.06 | G10: ='Proximal Validation (double)'!G37 -> 3.142 | H10: ='Proximal Validation (double)'!H37 -> 1.5707963 | ... Q10: ='Proximal Validation (double)'!Q37 -> -0.22226512 | R10: 0.36582449 | S10: 0.18256423 | T10: 5.6029386 | U10: 1.5707963 | V10: 0.605742 | W10: 0.12105936 | X10: 3.1319591 | Y10: 1.5707963 | Z10: 2.526967e-06 | AA10: =R10-A10 -> 0.065824489 | AB10: =S10-B10 -> 0.002564235 | AC10: =T10-C10 -> 0.89093863 | AD10: =U10-D10 -> 0 | AE10: =V10-E10 -> 0.305742 | AF10: =W10-F10 -> 0.06105936 | AG10: =X10-G10 -> -0.010040913 | AH10: =Y10-H10 -> 0 | AI10: =AVERAGE(ABS(AA10),ABS(AE10)) -> 0.18578325 | AJ10: =AVERAGE(ABS(AB10),ABS(AF10)) -> 0.031811798 | AK10: =AVERAGE(ABS(AC10),ABS(AG10)) -> 0.45048977 | AL10: =MIN(A10,E10) -> 0.3
A11: ='Proximal Validation (double)'!A36 -> 1 | B11: ='Proximal Validation (double)'!B36 -> 0.12 | C11: ='Proximal Validation (double)'!C36 -> 4.712 | D11: ='Proximal Validation (double)'!D36 -> 1.5707963 | E11: ='Proximal Validation (double)'!E36 -> 0.8 | F11: ='Proximal Validation (double)'!F36 -> 0.08 | G11: ='Proximal Validation (double)'!G36 -> 3.142 | H11: ='Proximal Validation (double)'!H36 -> 1.5707963 | ... Q11: ='Proximal Validation (double)'!Q36 -> -1.0263081 | R11: 0.66147629 | S11: 0.17957821 | T11: 4.4950146 | U11: 1.5707963 | V11: 0.78211703 | W11: 0.065122336 | X11: 3.8237687 | Y11: 1.5707963 | Z11: 8.3957532e-06 | AA11: =R11-A11 -> -0.33852371 | AB11: =S11-B11 -> 0.059578207 | AC11: =T11-C11 -> -0.21698538 | AD11: =U11-D11 -> 0 | AE11: =V11-E11 -> -0.017882974 | AF11: =W11-F11 -> -0.014877664 | AG11: =X11-G11 -> 0.68176868 | AH11: =Y11-H11 -> 0 | AI11: =AVERAGE(ABS(AA11),ABS(AE11)) -> 0.17820334 | AJ11: =AVERAGE(ABS(AB11),ABS(AF11)) -> 0.037227935 | AK11: =AVERAGE(ABS(AC11),ABS(AG11)) -> 0.44937703 | AL11: =MIN(A11,E11) -> 0.8
A12: ='Proximal Validation (double)'!A14 -> 0.9 | B12: ='Proximal Validation (double)'!B14 -> 0.2 | C12: ='Proximal Validation (double)'!C14 -> 1.571 | D12: ='Proximal Validation (double)'!D14 -> 1.5707963 | E12: ='Proximal Validation (double)'!E14 -> 0.3 | F12: ='Proximal Validation (double)'!F14 -> 0.02 | G12: ='Proximal Validation (double)'!G14 -> 4.712 | H12: ='Proximal Validation (double)'!H14 -> 1.5707963 | ... Q12: ='Proximal Validation (double)'!Q14 -> 0.042876139 | R12: 0.94895011 | S12: 0.19193087 | T12: 1.5942902 | U12: 1.5707963 | V12: 0.60419374 | W12: 0.02941633 | X12: 4.6950774 | Y12: 1.5707963 | Z12: 0.0015049131 | AA12: =R12-A12 -> 0.048950112 | AB12: =S12-B12 -> -0.0080691344 | AC12: =T12-C12 -> 0.023290192 | AD12: =U12-D12 -> 0 | AE12: =V12-E12 -> 0.30419374 | AF12: =W12-F12 -> 0.0094163303 | AG12: =X12-G12 -> -0.016922604 | AH12: =Y12-H12 -> 0 | AI12: =AVERAGE(ABS(AA12),ABS(AE12)) -> 0.17657193 | AJ12: =AVERAGE(ABS(AB12),ABS(AF12)) -> 0.0087427324 | AK12: =AVERAGE(ABS(AC12),ABS(AG12)) -> 0.020106398 | AL12: =MIN(A12,E12) -> 0.3
A13: ='Proximal Validation (double)'!A8 -> 0.8 | B13: ='Proximal Validation (double)'!B8 -> 0.16 | C13: ='Proximal Validation (double)'!C8 -> 1.571 | D13: ='Proximal Validation (double)'!D8 -> 1.5707963 | E13: ='Proximal Validation (double)'!E8 -> 0.8 | F13: ='Proximal Validation (double)'!F8 -> 0.06 | G13: ='Proximal Validation (double)'!G8 -> 3.927 | H13: ='Proximal Validation (double)'!H8 -> 1.5707963 | ... Q13: ='Proximal Validation (double)'!Q8 -> 0.10888903 | R13: 0.6501892 | S13: 0.19973744 | T13: 1.7082561 | U13: 1.5707963 | V13: 0.60390629 | W13: 0.040781542 | X13: 3.9259979 | Y13: 1.5707963 | Z13: 8.5180463e-05 | AA13: =R13-A13 -> -0.1498108 | AB13: =S13-B13 -> 0.039737444 | AC13: =T13-C13 -> 0.13725609 | AD13: =U13-D13 -> 0 | AE13: =V13-E13 -> -0.19609371 | AF13: =W13-F13 -> -0.019218458 | AG13: =X13-G13 -> -0.0010021325 | AH13: =Y13-H13 -> 0 | AI13: =AVERAGE(ABS(AA13),ABS(AE13)) -> 0.17295225 | AJ13: =AVERAGE(ABS(AB13),ABS(AF13)) -> 0.029477951 | AK13: =AVERAGE(ABS(AC13),ABS(AG13)) -> 0.06912911 | AL13: =MIN(A13,E13) -> 0.8
A14: ='Proximal Validation (double)'!A30 -> 1 | B14: ='Proximal Validation (double)'!B30 -> 0.2 | C14: ='Proximal Validation (double)'!C30 -> 3.927 | D14: ='Proximal Validation (double)'!D30 -> 1.5707963 | E14: ='Proximal Validation (double)'!E30 -> 1 | F14: ='Proximal Validation (double)'!F30 -> 0.06 | G14: ='Proximal Validation (double)'!G30 -> 3.927 | H14: ='Proximal Validation (double)'!H30 -> 1.5707963 | ... Q14: ='Proximal Validation (double)'!Q30 -> -0.96642387 | R14: 0.74026519 | S14: 0.17100885 | T14: 4.1318126 | U14: 1.5707963 | V14: 0.9938591 | W14: 0.089261331 | X14: 3.7616383 | Y14: 1.5707963 | Z14: 0.00085402583 | AA14: =R14-A14 -> -0.25973481 | AB14: =S14-B14 -> -0.028991152 | AC14: =T14-C14 -> 0.20481258 | AD14: =U14-D14 -> 0 | AE14: =V14-E14 -> -0.0061408993 | AF14: =W14-F14 -> 0.029261331 | AG14: =X14-G14 -> -0.16536167 | AH14: =Y14-H14 -> 0 | AI14: =AVERAGE(ABS(AA14),ABS(AE14)) -> 0.13293785 | AJ14: =AVERAGE(ABS(AB14),ABS(AF14)) -> 0.029126241 | AK14: =AVERAGE(ABS(AC14),ABS(AG14)) -> 0.18508712 | AL14: =MIN(A14,E14) -> 1
A15: ='Proximal Validation (double)'!A20 -> 0.9 | B15: ='Proximal Validation (double)'!B20 -> 0.2 | C15: ='Proximal Validation (double)'!C20 -> 2.356 | D15: ='Proximal Validation (double)'!D20 -> 1.5707963 | E15: ='Proximal Validation (double)'!E20 -> 0.3 | F15: ='Proximal Validation (double)'!F20 -> 0.06 | G15: ='Proximal Validation (double)'!G20 -> 3.142 | H15: ='Proximal Validation (double)'!H20 -> 1.5707963 | ... Q15: ='Proximal Validation (double)'!Q20 -> 0.2630704 | R15: 0.82050338 | S15: 0.19116464 | T15: 2.4039776 | U15: 1.5707963 | V15: 0.17502923 | W15: 0.045763709 | X15: 4.3213098 | Y15: 1.5707963 | Z15: 5.9261602e-05 | AA15: =R15-A15 -> -0.079496615 | AB15: =S15-B15 -> -0.0088353617 | AC15: =T15-C15 -> 0.04797758 | AD15: =U15-D15 -> 0 | AE15: =V15-E15 -> -0.12497077 | AF15: =W15-F15 -> -0.014236291 | AG15: =X15-G15 -> 1.1793098 | AH15: =Y15-H15 -> 0 | AI15: =AVERAGE(ABS(AA15),ABS(AE15)) -> 0.10223369 | AJ15: =AVERAGE(ABS(AB15),ABS(AF15)) -> 0.011535826 | AK15: =AVERAGE(ABS(AC15),ABS(AG15)) -> 0.61364367 | AL15: =MIN(A15,E15) -> 0.3
A16: ='Proximal Validation (double)'!A35 -> 0.9 | B16: ='Proximal Validation (double)'!B35 -> 0.12 | C16: ='Proximal Validation (double)'!C35 -> 4.712 | D16: ='Proximal Validation (double)'!D35 -> 1.5707963 | E16: ='Proximal Validation (double)'!E35 -> 0.9 | F16: ='Proximal Validation (double)'!F35 -> 0.02 | G16: ='Proximal Validation (double)'!G35 -> 3.142 | H16: ='Proximal Validation (double)'!H35 -> 1.5707963 | ... Q16: ='Proximal Validation (double)'!Q35 -> -0.97470814 | R16: 0.7892788 | S16: 0.14691501 | T16: 4.6946445 | U16: 1.5707963 | V16: 0.87998906 | W16: 0.02 | X16: 3.429109 | Y16: 1.5707963 | Z16: 7.2325827e-06 | AA16: =R16-A16 -> -0.1107212 | AB16: =S16-B16 -> 0.026915013 | AC16: =T16-C16 -> -0.017355471 | AD16: =U16-D16 -> 0 | AE16: =V16-E16 -> -0.020010943 | AF16: =W16-F16 -> 2.7033388e-10 | AG16: =X16-G16 -> 0.28710895 | AH16: =Y16-H16 -> 0 | AI16: =AVERAGE(ABS(AA16),ABS(AE16)) -> 0.06536607 | AJ16: =AVERAGE(ABS(AB16),ABS(AF16)) -> 0.013457507 | AK16: =AVERAGE(ABS(AC16),ABS(AG16)) -> 0.15223221 | AL16: =MIN(A16,E16) -> 0.9
A17: ='Proximal Validation (double)'!A41 -> 1 | B17: ='Proximal Validation (double)'!B41 -> 0.2 | C17: ='Proximal Validation (double)'!C41 -> 4.712 | D17: ='Proximal Validation (double)'!D41 -> 1.5707963 | E17: ='Proximal Validation (double)'!E41 -> 0.8 | F17: ='Proximal Validation (double)'!F41 -> 0.02 | G17: ='Proximal Validation (double)'!G41 -> 3.142 | H17: ='Proximal Validation (double)'!H41 -> 1.5707963 | ... Q17: ='Proximal Validation (double)'!Q41 -> -0.6635071 | R17: 0.96188984 | S17: 0.19999835 | T17: 4.8131945 | U17: 1.5707963 | V17: 0.88410801 | W17: 0.046815506 | X17: 3.1452616 | Y17: 1.5707963 | Z17: 2.6586357e-05 | AA17: =R17-A17 -> -0.038110165 | AB17: =S17-B17 -> -1.6545516e-06 | AC17: =T17-C17 -> 0.10119447 | AD17: =U17-D17 -> 0 | AE17: =V17-E17 -> 0.084108015 | AF17: =W17-F17 -> 0.026815506 | AG17: =X17-G17 -> 0.003261596 | AH17: =Y17-H17 -> 0 | AI17: =AVERAGE(ABS(AA17),ABS(AE17)) -> 0.06110909 | AJ17: =AVERAGE(ABS(AB17),ABS(AF17)) -> 0.01340858 | AK17: =AVERAGE(ABS(AC17),ABS(AG17)) -> 0.052228032 | AL17: =MIN(A17,E17) -> 0.8
A18: ='Proximal Validation (double)'!A17 -> 1 | B18: ='Proximal Validation (double)'!B17 -> 0.14 | C18: ='Proximal Validation (double)'!C17 -> 2.356 | D18: ='Proximal Validation (double)'!D17 -> 1.5707963 | E18: ='Proximal Validation (double)'!E17 -> 0.4 | F18: ='Proximal Validation (double)'!F17 -> 0.04 | G18: ='Proximal Validation (double)'!G17 -> 3.927 | H18: ='Proximal Validation (double)'!H17 -> 1.5707963 | ... Q18: ='Proximal Validation (double)'!Q17 -> 0.42077422 | R18: 0.95187652 | S18: 0.15066597 | T18: 2.4241415 | U18: 1.5707963 | V18: 0.32906563 | W18: 0.020000212 | X18: 3.5356751 | Y18: 1.5707963 | Z18: 0.00012830069 | AA18: =R18-A18 -> -0.048123484 | AB18: =S18-B18 -> 0.010665971 | AC18: =T18-C18 -> 0.068141512 | AD18: =U18-D18 -> 0 | AE18: =V18-E18 -> -0.070934372 | AF18: =W18-F18 -> -0.019999788 | AG18: =X18-G18 -> -0.39132495 | AH18: =Y18-H18 -> 0 | AI18: =AVERAGE(ABS(AA18),ABS(AE18)) -> 0.059528928 | AJ18: =AVERAGE(ABS(AB18),ABS(AF18)) -> 0.01533288 | AK18: =AVERAGE(ABS(AC18),ABS(AG18)) -> 0.22973323 | AL18: =MIN(A18,E18) -> 0.4
A19: ='Proximal Validation (double)'!A32 -> 0.3 | B19: ='Proximal Validation (double)'!B32 -> 0.1 | C19: ='Proximal Validation (double)'!C32 -> 4.712 | D19: ='Proximal Validation (double)'!D32 -> 1.5707963 | E19: ='Proximal Validation (double)'!E32 -> 0.8 | F19: ='Proximal Validation (double)'!F32 -> 0.04 | G19: ='Proximal Validation (double)'!G32 -> 3.927 | H19: ='Proximal Validation (double)'!H32 -> 1.5707963 | ... Q19: ='Proximal Validation (double)'!Q32 -> -0.79531831 | R19: 0.28359371 | S19: 0.10950988 | T19: 4.761095 | U19: 1.5707963 | V19: 0.74953438 | W19: 0.045343844 | X19: 3.8986305 | Y19: 1.5707963 | Z19: 1.1491936e-05 | AA19: =R19-A19 -> -0.016406294 | AB19: =S19-B19 -> 0.009509879 | AC19: =T19-C19 -> 0.049094972 | AD19: =U19-D19 -> 0 | AE19: =V19-E19 -> -0.050465616 | AF19: =W19-F19 -> 0.0053438439 | AG19: =X19-G19 -> -0.028369458 | AH19: =Y19-H19 -> 0 | AI19: =AVERAGE(ABS(AA19),ABS(AE19)) -> 0.033435955 | AJ19: =AVERAGE(ABS(AB19),ABS(AF19)) -> 0.0074268614 | AK19: =AVERAGE(ABS(AC19),ABS(AG19)) -> 0.038732215 | AL19: =MIN(A19,E19) -> 0.3
A20: ='Proximal Validation (double)'!A12 -> 0.9 | B20: ='Proximal Validation (double)'!B12 -> 0.2 | C20: ='Proximal Validation (double)'!C12 -> 1.571 | D20: ='Proximal Validation (double)'!D12 -> 1.5707963 | E20: ='Proximal Validation (double)'!E12 -> 1 | F20: ='Proximal Validation (double)'!F12 -> 0.02 | G20: ='Proximal Validation (double)'!G12 -> 3.142 | H20: ='Proximal Validation (double)'!H12 -> 1.5707963 | ... Q20: ='Proximal Validation (double)'!Q12 -> 0.27430844 | R20: 0.85420592 | S20: 0.19581669 | T20: 1.6301671 | U20: 1.5707963 | V20: 0.99982159 | W20: 0.021487383 | X20: 3.4963871 | Y20: 1.5707963 | Z20: 0.00096995279 | AA20: =R20-A20 -> -0.045794077 | AB20: =S20-B20 -> -0.0041833065 | AC20: =T20-C20 -> 0.059167104 | AD20: =U20-D20 -> 0 | AE20: =V20-E20 -> -0.0001784109 | AF20: =W20-F20 -> 0.0014873832 | AG20: =X20-G20 -> 0.35438708 | AH20: =Y20-H20 -> 0 | AI20: =AVERAGE(ABS(AA20),ABS(AE20)) -> 0.022986244 | AJ20: =AVERAGE(ABS(AB20),ABS(AF20)) -> 0.0028353449 | AK20: =AVERAGE(ABS(AC20),ABS(AG20)) -> 0.20677709 | AL20: =MIN(A20,E20) -> 0.9

Sheet Distal Vali (double 2to1.25)
A1: Ground Truth | L1: 6-Axis FT Sensor | R1: SoRoSim get_distal_value | AA1: Distal Errors | AI1: Stats
A2: F1 (N) | B2: s1 (m) | C2: el1 (rad) | D2: az1 (rad) | E2: F2 (N) | F2: s2 (m) | G2: el2 (rad) | H2: az2 (rad) | I2: tau1 (N) | J2: tau2 (N) | K2: tau3 (N) | L2: Tx (Nm) | M2: Ty (Nm) | N2: Tz(Nm) | O2: Fx (N) | P2: Fy (N) | Q2: Fz (N) | R2: F1 (N) | S2: s1 (m) | T2: el1 (rad) | U2: az1 (rad) | V2: F2 (N) | W2: s2 (m) | X2: el2 (rad) | Y2: az2 (rad) | Z2: f_final | AA2: F1 (N) | AB2: s1 (m) | AC2: el1 (rad) | AD2: az1 (rad) | AE2: F2 (N) | AF2: s2 (m) | AG2: el2 (rad) | AH2: az2 (rad) | AI2: force_error | AJ2: position_error | AK2: angle_error | AL2: min_f | AM2: Absolute Mean Error
A3: ='Proximal Validation (double)'!A11 -> 0.3 | B3: ='Proximal Validation (double)'!B11 -> 0.18 | C3: ='Proximal Validation (double)'!C11 -> 1.571 | D3: ='Proximal Validation (double)'!D11 -> 1.5707963 | E3: ='Proximal Validation (double)'!E11 -> 0.9 | F3: ='Proximal Validation (double)'!F11 -> 0.08 | G3: ='Proximal Validation (double)'!G11 -> 4.712 | H3: ='Proximal Validation (double)'!H11 -> 1.5707963 | ... K3: ='Proximal Validation (double)'!K11 -> 0 | L3: 0.0030450388 | M3: 0.047261626 | N3: -0.0074511659 | O3: 0.12820806 | P3: -0.039163809 | Q3: -0.45776021 | R3: 0.2016754 | S3: 0.16928928 | T3: 1.7030059 | U3: 1.5707963 | V3: 0.59808472 | W3: 0.050158687 | X3: 4.7070139 | Y3: 1.5707963 | Z3: 0.016429074 | AA3: =R3-A3 -> -0.098324597 | AB3: =S3-B3 -> -0.010710724 | AC3: =T3-C3 -> 0.13200594 | AD3: =U3-D3 -> 0 | AE3: =V3-E3 -> -0.30191528 | AF3: =W3-F3 -> -0.029841313 | AG3: =X3-G3 -> -0.0049860586 | AH3: =Y3-H3 -> 0 | AI3: =AVERAGE(ABS(AA3),ABS(AE3)) -> 0.20011994 | AJ3: =AVERAGE(ABS(AB3),ABS(AF3)) -> 0.020276019 | AK3: =AVERAGE(ABS(AC3),ABS(AG3)) -> 0.068496 | AL3: =MIN(A3,E3) -> 0.3 | AM3: {=AVERAGE(ABS(AA3:AA7))} -> 0.23323854 | AN3: {=AVERAGE(ABS(AB3:AB7))} -> 0.033548445 | AO3: {=AVERAGE(ABS(AC3:AC7))} -> 0.30584415 | AP3: {=AVERAGE(ABS(AD3:AD7))} -> 0 | AQ3: {=AVERAGE(ABS(AE3:AE7))} -> 0.28984687 | AR3: {=AVERAGE(ABS(AF3:AF7))} -> 0.014961019 | AS3: {=AVERAGE(ABS(AG3:AG7))} -> 0.28217382 | AT3: {=AVERAGE(ABS(AH3:AH7))} -> 0
A4: ='Proximal Validation (double)'!A25 -> 0.6 | B4: ='Proximal Validation (double)'!B25 -> 0.12 | C4: ='Proximal Validation (double)'!C25 -> 3.927 | D4: ='Proximal Validation (double)'!D25 -> 1.5707963 | E4: ='Proximal Validation (double)'!E25 -> 0.5 | F4: ='Proximal Validation (double)'!F25 -> 0.08 | G4: ='Proximal Validation (double)'!G25 -> 4.712 | H4: ='Proximal Validation (double)'!H25 -> 1.5707963 | ... K4: ='Proximal Validation (double)'!K25 -> 0 | L4: -0.00041553983 | M4: 0.1688444 | N4: -0.087348476 | O4: -0.11381689 | P4: -0.40894815 | Q4: -0.88041389 | R4: 0.12297766 | S4: 0.13581733 | T4: 2.8696467 | U4: 1.5707963 | V4: 0.967547 | W4: 0.084995815 | X4: 4.4023507 | Y4: 1.5707963 | Z4: 0.00037036029 | AA4: =R4-A4 -> -0.47702234 | AB4: =S4-B4 -> 0.015817327 | AC4: =T4-C4 -> -1.0573533 | AD4: =U4-D4 -> 0 | AE4: =V4-E4 -> 0.467547 | AF4: =W4-F4 -> 0.0049958148 | AG4: =X4-G4 -> -0.30964934 | AH4: =Y4-H4 -> 0 | AI4: =AVERAGE(ABS(AA4),ABS(AE4)) -> 0.47228467 | AJ4: =AVERAGE(ABS(AB4),ABS(AF4)) -> 0.010406571 | AK4: =AVERAGE(ABS(AC4),ABS(AG4)) -> 0.68350134 | AL4: =MIN(A4,E4) -> 0.5 | AM4: =AVERAGE(AM3,AQ3) -> 0.2615427 | AN4: =AVERAGE(AN3,AR3) -> 0.024254732 | AO4: =AVERAGE(AO3,AS3) -> 0.29400899
