Workbook

Sheet Proximal Validation
A1: Ground Truth | L1: 6-Axis FT Sensor | R1: SoRoSim get_proximal_value | X1: Proximal Errors
A2: F1 (N) | B2: s1 (m) | C2: el1 (rad) | D2: az1 (rad) | E2: F2 (N) | F2: s2 (m) | G2: el2 (rad) | H2: az2 (rad) | I2: tau1 (N) | J2: tau2 (N) | K2: tau3 (N) | L2: Tx (Nm) | M2: Ty (Nm) | N2: Tz(Nm) | O2: Fx (N) | P2: Fy (N) | Q2: Fz (N) | R2: Tx (Nm) | S2: Ty (Nm) | T2: Tz(Nm) | U2: Fx (N) | V2: Fy (N) | W2: Fz (N) | X2: Tx (Nm) | Y2: Ty (Nm) | Z2: Tz(Nm) | AA2: Fx (N) | AB2: Fy (N) | AC2: Fz (N)
A3: 0.5 | B3: 0.12 | C3: 1.57 | D3: =PI()/2 -> 1.5707963 | E3: 0.3 | F3: 0.02 | G3: 3.142 | H3: =PI()/2 -> 1.5707963 | I3: 0.8 | J3: 0 | K3: 0 | L3: 0.0033966473 | M3: -0.084817789 | N3: -0.032525759 | O3: -0.18618348 | P3: -0.29094619 | Q3: 0.34101567 | R3: 0.0019545273 | S3: -0.10069081 | T3: -0.032823109 | U3: -0.18735701 | V3: -0.30311109 | W3: 0.46281575 | X3: =L3-R3 -> 0.00144212 | Y3: =M3-S3 -> 0.01587302 | Z3: =N3-T3 -> 0.00029734971 | AA3: =O3-U3 -> 0.0011735261 | AB3: =P3-V3 -> 0.012164901 | AC3: =Q3-W3 -> -0.12180008
A4: 0.5 | B4: 0.12 | C4: 1.57 | D4: =PI()/2 -> 1.5707963 | E4: 0.7 | F4: 0.06 | G4: 4.712 | H4: =PI()/2 -> 1.5707963 | I4: 0 | J4: 0 | K4: 0 | L4: 0.00029206369 | M4: -0.014378886 | N4: 0.00051419169 | O4: -0.014039525 | P4: -0.003988117 | Q4: -0.14813778 | R4: -1.3559137e-13 | S4: 0.00076156042 | T4: 4.1979748e-05 | U4: -0.01684176 | V4: 0.00011952157 | W4: -0.20632188 | X4: =L4-R4 -> 0.00029206369 | Y4: =M4-S4 -> -0.015140446 | Z4: =N4-T4 -> 0.00047221194 | AA4: =O4-U4 -> 0.0028022356 | AB4: =P4-V4 -> -0.0041076385 | AC4: =Q4-W4 -> 0.058184097
A5: 0.8 | B5: 0.18 | C5: 1.57 | D5: =PI()/2 -> 1.5707963 | E5: 0.4 | F5: 0.08 | G5: 4.712 | H5: =PI()/2 -> 1.5707963 | I5: 0.4 | J5: 0 | K5: 0 | L5: 0.0026918571 | M5: -0.097128831 | N5: 0.0050861202 | O5: -0.40724513 | P5: 0.01080508 | Q5: 0.032090679 | R5: 0.0030075772 | S5: -0.099540625 | T5: -0.00013747882 | U5: -0.45870309 | V5: -0.013254376 | W5: 0.046920031 | X5: =L5-R5 -> -0.00031572014 | Y5: =M5-S5 -> 0.0024117938 | Z5: =N5-T5 -> 0.005223599 | AA5: =O5-U5 -> 0.051457958 | AB5: =P5-V5 -> 0.024059455 | AC5: =Q5-W5 -> -0.014829352
A6: 0.3 | B6: 0.2 | C6: 1.57 | D6: =PI()/2 -> 1.5707963 | E6: 0.7 | F6: 0.04 | G6: 3.142 | H6: =PI()/2 -> 1.5707963 | I6: 0.4 | J6: 0 | K6: 0 | L6: 0.0012694518 | M6: -0.052426334 | N6: -0.088403538 | O6: -0.16237766 | P6: -0.67368567 | Q6: 0.068886459 | R6: 0.0016498792 | S6: -0.079321292 | T6: -0.089875435 | U6: -0.19783019 | V6: -0.69435989 | W6: 0.2459013 | X6: =L6-R6 -> -0.00038042744 | Y6: =M6-S6 -> 0.026894958 | Z6: =N6-T6 -> 0.0014718976 | AA6: =O6-U6 -> 0.035452533 | AB6: =P6-V6 -> 0.020674224 | AC6: =Q6-W6 -> -0.17701484
A7: 0.3 | B7: 0.1 | C7: 3.142 | D7: =PI()/2 -> 1.5707963 | E7: 0.8 | F7: 0.08 | G7: 3.927 | H7: =PI()/2 -> 1.5707963 | I7: 0.8 | J7: 0 | K7: 0 | L7: -0.00026597269 | M7: 0.086320065 | N7: -0.15243518 | O7: -0.22609875 | P7: -0.812931 | Q7: -0.47338951 | R7: 5.4319143e-05 | S7: 0.093585113 | T7: -0.14874569 | U7: -0.31230493 | V7: -0.82395787 | W7: -0.54138321 | X7: =L7-R7 -> -0.00032029183 | Y7: =M7-S7 -> -0.0072650484 | Z7: =N7-T7 -> -0.0036894887 | AA7: =O7-U7 -> 0.086206185 | AB7: =P7-V7 -> 0.011026872 | AC7: =Q7-W7 -> 0.067993701
A8: 0.7 | B8: 0.1 | C8: 3.142 | D8: =PI()/2 -> 1.5707963 | E8: 0.4 | F8: 0.04 | G8: 3.927 | H8: =PI()/2 -> 1.5707963 | I8: 0.4 | J8: 0 | K8: 0 | L8: -0.0011004871 | M8: 0.036083326 | N8: -0.18029018 | O8: -0.18137529 | P8: -0.99236429 | Q8: -0.25453395 | R8: 0.0005194893 | S8: 0.036361942 | T8: -0.16473009 | U8: -0.29797363 | V8: -0.93629909 | W8: -0.27990705 | X8: =L8-R8 -> -0.0016199764 | Y8: =M8-S8 -> -0.0002786163 | Z8: =N8-T8 -> -0.01556009 | AA8: =O8-U8 -> 0.11659834 | AB8: =P8-V8 -> -0.0560652 | AC8: =Q8-W8 -> 0.025373103
A9: 0.5 | B9: 0.14 | C9: 3.142 | D9: =PI()/2 -> 1.5707963 | E9: 0.7 | F9: 0.08 | G9: 3.927 | H9: =PI()/2 -> 1.5707963 | I9: 0.4 | J9: 0 | K9: 0 | L9: 0.00012140814 | M9: 0.06093071 | N9: -0.19216824 | O9: -0.4532392 | P9: -0.8637259 | Q9: -0.33691111 | R9: 0.00057942734 | S9: 0.078552182 | T9: -0.18101381 | U9: -0.58593933 | V9: -0.83195069 | W9: -0.4451111 | X9: =L9-R9 -> -0.00045801919 | Y9: =M9-S9 -> -0.017621471 | Z9: =N9-T9 -> -0.011154423 | AA9: =O9-U9 -> 0.13270013 | AB9: =P9-V9 -> -0.031775207 | AC9: =Q9-W9 -> 0.10819999
A10: 0.7 | B10: 0.14 | C10: 3.142 | D10: =PI()/2 -> 1.5707963 | E10: 0.5 | F10: 0.06 | G10: 3.927 | H10: =PI()/2 -> 1.5707963 | I10: 0.8 | J10: 0 | K10: 0 | L10: 0.0020413408 | M10: 0.053677611 | N10: -0.22552121 | O10: -0.44799793 | P10: -1.034426 | Q10: -0.3438628 | R10: 0.0019834103 | S10: 0.050548454 | T10: -0.1934356 | U10: -0.59727203 | V10: -0.87068578 | W10: -0.33608249 | X10: =L10-R10 -> 5.7930467e-05 | Y10: =M10-S10 -> 0.0031291568 | Z10: =N10-T10 -> -0.032085602 | AA10: =O10-U10 -> 0.1492741 | AB10: =P10-V10 -> -0.16374019 | AC10: =Q10-W10 -> -0.0077803069
A11: 0.4 | B11: 0.18 | C11: 3.142 | D11: =PI()/2 -> 1.5707963 | E11: 0.4 | F11: 0.02 | G11: 3.927 | H11: =PI()/2 -> 1.5707963 | I11: 0 | J11: 0 | K11: 0 | L11: -0.0018034787 | M11: 0.030678485 | N11: -0.13010471 | O11: -0.34587803 | P11: -0.53015172 | Q11: -0.25460425 | R11: 6.6348352e-11 | S11: 0.030850405 | T11: -0.12907839 | U11: -0.2745961 | V11: -0.60247643 | W11: -0.28165595 | X11: =L11-R11 -> -0.0018034788 | Y11: =M11-S11 -> -0.00017192021 | Z11: =N11-T11 -> -0.0010263124 | AA11: =O11-U11 -> -0.071281936 | AB11: =P11-V11 -> 0.072324703 | AC11: =Q11-W11 -> 0.027051701
A12: 0.7 | B12: 0.18 | C12: 3.142 | D12: =PI()/2 -> 1.5707963 | E12: 0.8 | F12: 0.04 | G12: 3.927 | H12: =PI()/2 -> 1.5707963 | I12: 0.4 | J12: 0 | K12: 0 | R12: 0.0016736191 | S12: 0.070412555 | T12: -0.21093571 | U12: -0.87367216 | V12: -0.84353888 | W12: -0.54323494 | X12: =L12-R12 -> -0.0016736191 | Y12: =M12-S12 -> -0.070412555 | Z12: =N12-T12 -> 0.21093571 | AA12: =O12-U12 -> 0.87367216 | AB12: =P12-V12 -> 0.84353888 | AC12: =Q12-W12 -> 0.54323494
A13: 0.3 | B13: 0.12 | C13: 4.712 | D13: =PI()/2 -> 1.5707963 | E13: 0.3 | F13: 0.04 | G13: 4.712 | H13: =PI()/2 -> 1.5707963 | I13: 0.4 | J13: 0 | K13: 0 | L13: -0.0009027482 | M13: 0.095996417 | N13: -0.0087546632 | O13: -0.11151029 | P13: -0.063374788 | Q13: -0.5337559 | R13: -0.0006493028 | S13: 0.10090282 | T13: -6.0118817e-05 | U13: -0.10382416 | V13: -0.0010447927 | W13: -0.59042129 | X13: =L13-R13 -> -0.0002534454 | Y13: =M13-S13 -> -0.0049064018 | Z13: =N13-T13 -> -0.0086945444 | AA13: =O13-U13 -> -0.0076861303 | AB13: =P13-V13 -> -0.062329995 | AC13: =Q13-W13 -> 0.056665394
A14: 0.8 | B14: 0.12 | C14: 4.712 | D14: =PI()/2 -> 1.5707963 | E14: 0.7 | F14: 0.02 | G14: 3.142 | H14: =PI()/2 -> 1.5707963 | I14: 0 | J14: 0 | K14: 0 | L14: 0.00073054992 | M14: 0.18510914 | N14: -0.078640699 | O14: -0.26385891 | P14: -0.6934616 | Q14: -0.87223375 | R14: -8.6035866e-11 | S14: 0.15407638 | T14: -0.076119944 | U14: -0.43180189 | V14: -0.69496821 | W14: -0.67810472 | X14: =L14-R14 -> 0.00073055 | Y14: =M14-S14 -> 0.031032763 | Z14: =N14-T14 -> -0.0025207553 | AA14: =O14-U14 -> 0.16794298 | AB14: =P14-V14 -> 0.0015066147 | AC14: =Q14-W14 -> -0.19412903
A15: 0.4 | B15: 0.18 | C15: 4.712 | D15: =PI()/2 -> 1.5707963 | E15: 0.5 | F15: 0.06 | G15: 3.142 | H15: =PI()/2 -> 1.5707963 | I15: 0.4 | J15: 0 | K15: 0 | L15: -0.002943269 | M15: 0.098053239 | N15: -0.070226938 | O15: -0.23587371 | P15: -0.46341708 | Q15: -0.29305437 | R15: -0.0016050094 | S15: 0.099109979 | T15: -0.073136977 | U15: -0.2603705 | V15: -0.48686499 | W15: -0.32623057 | X15: =L15-R15 -> -0.0013382596 | Y15: =M15-S15 -> -0.0010567396 | Z15: =N15-T15 -> 0.0029100391 | AA15: =O15-U15 -> 0.024496784 | AB15: =P15-V15 -> 0.023447907 | AC15: =Q15-W15 -> 0.033176199
A16: 0.5 | B16: 0.2 | C16: 4.712 | D16: =PI()/2 -> 1.5707963 | E16: 0.7 | F16: 0.02 | G16: 4.712 | H16: =PI()/2 -> 1.5707963 | I16: 0.8 | J16: 0 | K16: 0 | L16: -0.0089650583 | M16: 0.193453 | N16: -0.02267966 | O16: -0.44403204 | P16: -0.17503352 | Q16: -0.91890478 | R16: -0.005246932 | S16: 0.19565598 | T16: 3.2828765e-06 | U16: -0.50486682 | V16: -0.017334136 | W16: -1.0071399 | X16: =L16-R16 -> -0.0037181262 | Y16: =M16-S16 -> -0.0022029765 | Z16: =N16-T16 -> -0.022682943 | AA16: =O16-U16 -> 0.060834774 | AB16: =P16-V16 -> -0.15769939 | AC16: =Q16-W16 -> 0.08823509
A17: 0.7 | B17: 0.2 | C17: 4.712 | D17: =PI()/2 -> 1.5707963 | E17: 0.3 | F17: 0.08 | G17: 3.142 | H17: =PI()/2 -> 1.5707963 | I17: 0 | J17: 0 | K17: 0 | R17: -1.681837e-11 | S17: 0.13536801 | T17: -0.044999656 | U17: -0.69017175 | V17: -0.24716895 | W17: -0.20603559 | X17: =L17-R17 -> 1.681837e-11 | Y17: =M17-S17 -> -0.13536801 | Z17: =N17-T17 -> 0.044999656 | AA17: =O17-U17 -> 0.69017175 | AB17: =P17-V17 -> 0.24716895 | AC17: =Q17-W17 -> 0.20603559

Sheet Distal Validation (no perturb)
A1: Ground Truth | L1: 6-Axis FT Sensor | R1: SoRoSim get_distal_value | AA1: Distal Errors | AI1: Stats
A2: F1 (N) | B2: s1 (m) | C2: el1 (rad) | D2: az1 (rad) | E2: F2 (N) | F2: s2 (m) | G2: el2 (rad) | H2: az2 (rad) | I2: tau1 (N) | J2: tau2 (N) | K2: tau3 (N) | L2: Tx (Nm) | M2: Ty (Nm) | N2: Tz(Nm) | O2: Fx (N) | P2: Fy (N) | Q2: Fz (N) | R2: F1 (N) | S2: s1 (m) | T2: el1 (rad) | U2: az1 (rad) | V2: F2 (N) | W2: s2 (m) | X2: el2 (rad) | Y2: az2 (rad) | Z2: f_final | AA2: F1 (N) | AB2: s1 (m) | AC2: el1 (rad) | AD2: az1 (rad) | AE2: F2 (N) | AF2: s2 (m) | AG2: el2 (rad) | AH2: az2 (rad) | AI2: force_error | AJ2: position_error | AK2: angle_error | AL2: Absolute Mean Error
A3: ='Proximal Validation'!A3 -> 0.5 | B3: ='Proximal Validation'!B3 -> 0.12 | C3: ='Proximal Validation'!C3 -> 1.57 | D3: ='Proximal Validation'!D3 -> 1.5707963 | E3: ='Proximal Validation'!E3 -> 0.3 | F3: ='Proximal Validation'!F3 -> 0.02 | G3: ='Proximal Validation'!G3 -> 3.142 | H3: ='Proximal Validation'!H3 -> 1.5707963 | ... Q3: ='Proximal Validation'!Q3 -> 0.34101567 | R3: 0.30284644 | S3: 0.18042201 | T3: 1.3170036 | U3: 1.5707963 | V3: 0.36631749 | W3: 0.057266698 | X3: 2.9130067 | Y3: 1.5707963 | Z3: 5.3817154e-07 | AA3: =R3-A3 -> -0.19715356 | AB3: =S3-B3 -> 0.060422014 | AC3: =T3-C3 -> -0.25299642 | AD3: =U3-D3 -> 0 | AE3: =V3-E3 -> 0.066317486 | AF3: =W3-F3 -> 0.037266698 | AG3: =X3-G3 -> -0.22899327 | AH3: =Y3-H3 -> 0 | AI3: =AVERAGE(ABS(AA3),ABS(AE3)) -> 0.13173552 | AJ3: =AVERAGE(ABS(AB3),ABS(AF3)) -> 0.048844356 | AK3: =AVERAGE(ABS(AC3),ABS(AG3)) -> 0.24099485 | AL3: F1 (N) | AM3: s1 (m) | AN3: el1 (rad) | AO3: az1 (rad) | AP3: F2 (N) | AQ3: s2 (m) | AR3: el2 (rad) | AS3: az2 (rad)
A4: ='Proximal Validation'!A4 -> 0.5 | B4: ='Proximal Validation'!B4 -> 0.12 | C4: ='Proximal Validation'!C4 -> 1.57 | D4: ='Proximal Validation'!D4 -> 1.5707963 | E4: ='Proximal Validation'!E4 -> 0.7 | F4: ='Proximal Validation'!F4 -> 0.06 | G4: ='Proximal Validation'!G4 -> 4.712 | H4: ='Proximal Validation'!H4 -> 1.5707963 | ... Q4: ='Proximal Validation'!Q4 -> -0.14813778 | R4: 0.52129897 | S4: 0.079133524 | T4: 1.5393488 | U4: 1.5707963 | V4: 0.66120326 | W4: 0.022504063 | X4: 4.6818603 | Y4: 1.5707963 | Z4: 3.3718545e-07 | AA4: =R4-A4 -> 0.021298974 | AB4: =S4-B4 -> -0.040866476 | AC4: =T4-C4 -> -0.03065121 | AD4: =U4-D4 -> 0 | AE4: =V4-E4 -> -0.038796739 | AF4: =W4-F4 -> -0.037495937 | AG4: =X4-G4 -> -0.030139744 | AH4: =Y4-H4 -> 0 | AI4: =AVERAGE(ABS(AA4),ABS(AE4)) -> 0.030047856 | AJ4: =AVERAGE(ABS(AB4),ABS(AF4)) -> 0.039181206 | AK4: =AVERAGE(ABS(AC4),ABS(AG4)) -> 0.030395477 | AL4: {=AVERAGE(ABS(AA3:AA17))} -> 0.16177431 | AM4: {=AVERAGE(ABS(AB3:AB17))} -> 0.031944272 | AN4: {=AVERAGE(ABS(AC3:AC17))} -> 0.17613991 | AO4: {=AVERAGE(ABS(AD3:AD17))} -> 0 | AP4: {=AVERAGE(ABS(AE3:AE17))} -> 0.13823527 | AQ4: {=AVERAGE(ABS(AF3:AF17))} -> 0.021558605 | AR4: {=AVERAGE(ABS(AG3:AG17))} -> 0.26261473 | AS4: {=AVERAGE(ABS(AH3:AH17))} -> 0
A5: ='Proximal Validation'!A5 -> 0.8 | B5: ='Proximal Validation'!B5 -> 0.18 | C5: ='Proximal Validation'!C5 -> 1.57 | D5: ='Proximal Validation'!D5 -> 1.5707963 | E5: ='Proximal Validation'!E5 -> 0.4 | F5: ='Proximal Validation'!F5 -> 0.08 | G5: ='Proximal Validation'!G5 -> 4.712 | H5: ='Proximal Validation'!H5 -> 1.5707963 | ... Q5: ='Proximal Validation'!Q5 -> 0.032090679 | R5: 0.55844561 | S5: 0.19992272 | T5: 1.543949 | U5: 1.5707963 | V5: 0.24253143 | W5: 0.028014793 | X5: 4.7748408 | Y5: 1.5707963 | Z5: 6.4217081e-07 | AA5: =R5-A5 -> -0.24155439 | AB5: =S5-B5 -> 0.019922717 | AC5: =T5-C5 -> -0.026051029 | AD5: =U5-D5 -> 0 | AE5: =V5-E5 -> -0.15746857 | AF5: =W5-F5 -> -0.051985207 | AG5: =X5-G5 -> 0.062840768 | AH5: =Y5-H5 -> 0 | AI5: =AVERAGE(ABS(AA5),ABS(AE5)) -> 0.19951148 | AJ5: =AVERAGE(ABS(AB5),ABS(AF5)) -> 0.035953962 | AK5: =AVERAGE(ABS(AC5),ABS(AG5)) -> 0.044445898 | AL5: Absolute Mean Error (Across Both Forces)
A6: ='Proximal Validation'!A6 -> 0.3 | B6: ='Proximal Validation'!B6 -> 0.2 | C6: ='Proximal Validation'!C6 -> 1.57 | D6: ='Proximal Validation'!D6 -> 1.5707963 | E6: ='Proximal Validation'!E6 -> 0.7 | F6: ='Proximal Validation'!F6 -> 0.04 | G6: ='Proximal Validation'!G6 -> 3.142 | H6: ='Proximal Validation'!H6 -> 1.5707963 | ... Q6: ='Proximal Validation'!Q6 -> 0.068886459 | R6: 0.49796523 | S6: 0.12990301 | T6: 1.5890684 | U6: 1.5707963 | V6: 0.77787615 | W6: 0.041331057 | X6: 3.6828586 | Y6: 1.5707963 | Z6: 2.2918875e-07 | AA6: =R6-A6 -> 0.19796523 | AB6: =S6-B6 -> -0.070096988 | AC6: =T6-C6 -> 0.019068392 | AD6: =U6-D6 -> 0 | AE6: =V6-E6 -> 0.077876149 | AF6: =W6-F6 -> 0.0013310573 | AG6: =X6-G6 -> 0.54085857 | AH6: =Y6-H6 -> 0 | AI6: =AVERAGE(ABS(AA6),ABS(AE6)) -> 0.13792069 | AJ6: =AVERAGE(ABS(AB6),ABS(AF6)) -> 0.035714023 | AK6: =AVERAGE(ABS(AC6),ABS(AG6)) -> 0.27996348 | AL6: force_error | AM6: position_error | AN6: angle_error
A7: ='Proximal Validation'!A7 -> 0.3 | B7: ='Proximal Validation'!B7 -> 0.1 | C7: ='Proximal Validation'!C7 -> 3.142 | D7: ='Proximal Validation'!D7 -> 1.5707963 | E7: ='Proximal Validation'!E7 -> 0.8 | F7: ='Proximal Validation'!F7 -> 0.08 | G7: ='Proximal Validation'!G7 -> 3.927 | H7: ='Proximal Validation'!H7 -> 1.5707963 | ... Q7: ='Proximal Validation'!Q7 -> -0.47338951 | R7: 0.68417193 | S7: 0.084075972 | T7: 2.9216294 | U7: 1.5707963 | V7: 0.69261821 | W7: 0.080477929 | X7: 4.3999244 | Y7: 1.5707963 | Z7: 5.6476285e-06 | AA7: =R7-A7 -> 0.38417193 | AB7: =S7-B7 -> -0.015924028 | AC7: =T7-C7 -> -0.22037062 | AD7: =U7-D7 -> 0 | AE7: =V7-E7 -> -0.10738179 | AF7: =W7-F7 -> 0.00047792859 | AG7: =X7-G7 -> 0.47292442 | AH7: =Y7-H7 -> 0 | AI7: =AVERAGE(ABS(AA7),ABS(AE7)) -> 0.24577686 | AJ7: =AVERAGE(ABS(AB7),ABS(AF7)) -> 0.0082009784 | AK7: =AVERAGE(ABS(AC7),ABS(AG7)) -> 0.34664752 | AL7: =AVERAGE(AI3:AI17) -> 0.17308245 | AM7: =AVERAGE(AJ3:AJ17) -> 0.030867044 | AN7: =AVERAGE(AK3:AK17) -> 0.25312768
A8: ='Proximal Validation'!A8 -> 0.7 | B8: ='Proximal Validation'!B8 -> 0.1 | C8: ='Proximal Validation'!C8 -> 3.142 | D8: ='Proximal Validation'!D8 -> 1.5707963 | E8: ='Proximal Validation'!E8 -> 0.4 | F8: ='Proximal Validation'!F8 -> 0.04 | G8: ='Proximal Validation'!G8 -> 3.927 | H8: ='Proximal Validation'!H8 -> 1.5707963 | ... Q8: ='Proximal Validation'!Q8 -> -0.25453395 | R8: 0.83102237 | S8: 0.077190458 | T8: 2.9299411 | U8: 1.5707963 | V8: 0.52007697 | W8: 0.057299649 | X8: 4.1467522 | Y8: 1.5707963 | Z8: 1.7362168e-05 | AA8: =R8-A8 -> 0.13102237 | AB8: =S8-B8 -> -0.022809542 | AC8: =T8-C8 -> -0.21205893 | AD8: =U8-D8 -> 0 | AE8: =V8-E8 -> 0.12007697 | AF8: =W8-F8 -> 0.017299649 | AG8: =X8-G8 -> 0.21975217 | AH8: =Y8-H8 -> 0 | AI8: =AVERAGE(ABS(AA8),ABS(AE8)) -> 0.12554967 | AJ8: =AVERAGE(ABS(AB8),ABS(AF8)) -> 0.020054595 | AK8: =AVERAGE(ABS(AC8),ABS(AG8)) -> 0.21590555
A9: ='Proximal Validation'!A9 -> 0.5 | B9: ='Proximal Validation'!B9 -> 0.14 | C9: ='Proximal Validation'!C9 -> 3.142 | D9: ='Proximal Validation'!D9 -> 1.5707963 | E9: ='Proximal Validation'!E9 -> 0.7 | F9: ='Proximal Validation'!F9 -> 0.08 | G9: ='Proximal Validation'!G9 -> 3.927 | H9: ='Proximal Validation'!H9 -> 1.5707963 | ... Q9: ='Proximal Validation'!Q9 -> -0.33691111 | R9: 0.17255368 | S9: 0.19999571 | T9: 3.0069863 | U9: 1.5707963 | V9: 0.96495519 | W9: 0.081650406 | X9: 3.572525 | Y9: 1.5707963 | Z9: 1.1095832e-05 | AA9: =R9-A9 -> -0.32744632 | AB9: =S9-B9 -> 0.059995708 | AC9: =T9-C9 -> -0.1350137 | AD9: =U9-D9 -> 0 | AE9: =V9-E9 -> 0.26495519 | AF9: =W9-F9 -> 0.0016504056 | AG9: =X9-G9 -> -0.35447501 | AH9: =Y9-H9 -> 0 | AI9: =AVERAGE(ABS(AA9),ABS(AE9)) -> 0.29620075 | AJ9: =AVERAGE(ABS(AB9),ABS(AF9)) -> 0.030823057 | AK9: =AVERAGE(ABS(AC9),ABS(AG9)) -> 0.24474436
A10: ='Proximal Validation'!A10 -> 0.7 | B10: ='Proximal Validation'!B10 -> 0.14 | C10: ='Proximal Validation'!C10 -> 3.142 | D10: ='Proximal Validation'!D10 -> 1.5707963 | E10: ='Proximal Validation'!E10 -> 0.5 | F10: ='Proximal Validation'!F10 -> 0.06 | G10: ='Proximal Validation'!G10 -> 3.927 | H10: ='Proximal Validation'!H10 -> 1.5707963 | ... Q10: ='Proximal Validation'!Q10 -> -0.3438628 | R10: 0.7596706 | S10: 0.10425675 | T10: 2.9249839 | U10: 1.5707963 | V10: 0.74669142 | W10: 0.069753026 | X10: 3.9384839 | Y10: 1.5707963 | Z10: 3.3438676e-05 | AA10: =R10-A10 -> 0.059670601 | AB10: =S10-B10 -> -0.035743253 | AC10: =T10-C10 -> -0.21701614 | AD10: =U10-D10 -> 0 | AE10: =V10-E10 -> 0.24669142 | AF10: =W10-F10 -> 0.0097530255 | AG10: =X10-G10 -> 0.011483895 | AH10: =Y10-H10 -> 0 | AI10: =AVERAGE(ABS(AA10),ABS(AE10)) -> 0.15318101 | AJ10: =AVERAGE(ABS(AB10),ABS(AF10)) -> 0.022748139 | AK10: =AVERAGE(ABS(AC10),ABS(AG10)) -> 0.11425002
A11: ='Proximal Validation'!A11 -> 0.4 | B11: ='Proximal Validation'!B11 -> 0.18 | C11: ='Proximal Validation'!C11 -> 3.142 | D11: ='Proximal Validation'!D11 -> 1.5707963 | E11: ='Proximal Validation'!E11 -> 0.4 | F11: ='Proximal Validation'!F11 -> 0.02 | G11: ='Proximal Validation'!G11 -> 3.927 | H11: ='Proximal Validation'!H11 -> 1.5707963 | ... Q11: ='Proximal Validation'!Q11 -> -0.25460425 | R11: 0.53092335 | S11: 0.165293 | T11: 2.0603627 | U11: 1.5707963 | V11: 0.81271157 | W11: 0.11791139 | X11: 4.2270775 | Y11: 1.5707963 | Z11: 3.3730571e-07 | AA11: =R11-A11 -> 0.13092335 | AB11: =S11-B11 -> -0.014706999 | AC11: =T11-C11 -> -1.0816373 | AD11: =U11-D11 -> 0 | AE11: =V11-E11 -> 0.41271157 | AF11: =W11-F11 -> 0.097911391 | AG11: =X11-G11 -> 0.30007754 | AH11: =Y11-H11 -> 0 | AI11: =AVERAGE(ABS(AA11),ABS(AE11)) -> 0.27181746 | AJ11: =AVERAGE(ABS(AB11),ABS(AF11)) -> 0.056309195 | AK11: =AVERAGE(ABS(AC11),ABS(AG11)) -> 0.69085742
A12: ='Proximal Validation'!A12 -> 0.7 | B12: ='Proximal Validation'!B12 -> 0.18 | C12: ='Proximal Validation'!C12 -> 3.142 | D12: ='Proximal Validation'!D12 -> 1.5707963 | E12: ='Proximal Validation'!E12 -> 0.8 | F12: ='Proximal Validation'!F12 -> 0.04 | G12: ='Proximal Validation'!G12 -> 3.927 | H12: ='Proximal Validation'!H12 -> 1.5707963 | ... Q12: ='Proximal Validation'!Q12 -> 0
A13: ='Proximal Validation'!A13 -> 0.3 | B13: ='Proximal Validation'!B13 -> 0.12 | C13: ='Proximal Validation'!C13 -> 4.712 | D13: ='Proximal Validation'!D13 -> 1.5707963 | E13: ='Proximal Validation'!E13 -> 0.3 | F13: ='Proximal Validation'!F13 -> 0.04 | G13: ='Proximal Validation'!G13 -> 4.712 | H13: ='Proximal Validation'!H13 -> 1.5707963 | ... Q13: ='Proximal Validation'!Q13 -> -0.5337559 | R13: 0.4616227 | S13: 0.093433784 | T13: 4.829782 | U13: 1.5707963 | V13: 0.14375713 | W13: 0.069578722 | X13: 3.76053 | Y13: 1.5707963 | Z13: 4.9581431e-08 | AA13: =R13-A13 -> 0.1616227 | AB13: =S13-B13 -> -0.026566216 | AC13: =T13-C13 -> 0.117782 | AD13: =U13-D13 -> 0 | AE13: =V13-E13 -> -0.15624287 | AF13: =W13-F13 -> 0.029578722 | AG13: =X13-G13 -> -0.95147003 | AH13: =Y13-H13 -> 0 | AI13: =AVERAGE(ABS(AA13),ABS(AE13)) -> 0.15893279 | AJ13: =AVERAGE(ABS(AB13),ABS(AF13)) -> 0.028072469 | AK13: =AVERAGE(ABS(AC13),ABS(AG13)) -> 0.53462601
A14: ='Proximal Validation'!A14 -> 0.8 | B14: ='Proximal Validation'!B14 -> 0.12 | C14: ='Proximal Validation'!C14 -> 4.712 | D14: ='Proximal Validation'!D14 -> 1.5707963 | E14: ='Proximal Validation'!E14 -> 0.7 | F14: ='Proximal Validation'!F14 -> 0.02 | G14: ='Proximal Validation'!G14 -> 3.142 | H14: ='Proximal Validation'!H14 -> 1.5707963 | ... Q14: ='Proximal Validation'!Q14 -> -0.87223375 | R14: 0.99771769 | S14: 0.088686523 | T14: 4.7212671 | U14: 1.5707963 | V14: 0.72212749 | W14: 0.020000167 | X14: 3.195068 | Y14: 1.5707963 | Z14: 3.1008065e-05 | AA14: =R14-A14 -> 0.19771769 | AB14: =S14-B14 -> -0.031313477 | AC14: =T14-C14 -> 0.0092670638 | AD14: =U14-D14 -> 0 | AE14: =V14-E14 -> 0.022127491 | AF14: =W14-F14 -> 1.6733006e-07 | AG14: =X14-G14 -> 0.053068041 | AH14: =Y14-H14 -> 0 | AI14: =AVERAGE(ABS(AA14),ABS(AE14)) -> 0.10992259 | AJ14: =AVERAGE(ABS(AB14),ABS(AF14)) -> 0.015656822 | AK14: =AVERAGE(ABS(AC14),ABS(AG14)) -> 0.031167552
A15: ='Proximal Validation'!A15 -> 0.4 | B15: ='Proximal Validation'!B15 -> 0.18 | C15: ='Proximal Validation'!C15 -> 4.712 | D15: ='Proximal Validation'!D15 -> 1.5707963 | E15: ='Proximal Validation'!E15 -> 0.5 | F15: ='Proximal Validation'!F15 -> 0.06 | G15: ='Proximal Validation'!G15 -> 3.142 | H15: ='Proximal Validation'!H15 -> 1.5707963 | ... Q15: ='Proximal Validation'!Q15 -> -0.29305437 | R15: 0.71559104 | S15: 0.14254757 | T15: 4.9899435 | U15: 1.5707963 | V15: 0.74094454 | W15: 0.083532292 | X15: 2.7087326 | Y15: 1.5707963 | Z15: 6.9781135e-07 | AA15: =R15-A15 -> 0.31559104 | AB15: =S15-B15 -> -0.037452428 | AC15: =T15-C15 -> 0.27794346 | AD15: =U15-D15 -> 0 | AE15: =V15-E15 -> 0.24094454 | AF15: =W15-F15 -> 0.023532292 | AG15: =X15-G15 -> -0.43326744 | AH15: =Y15-H15 -> 0 | AI15: =AVERAGE(ABS(AA15),ABS(AE15)) -> 0.27826779 | AJ15: =AVERAGE(ABS(AB15),ABS(AF15)) -> 0.03049236 | AK15: =AVERAGE(ABS(AC15),ABS(AG15)) -> 0.35560545
A16: ='Proximal Validation'!A16 -> 0.5 | B16: ='Proximal Validation'!B16 -> 0.2 | C16: ='Proximal Validation'!C16 -> 4.712 | D16: ='Proximal Validation'!D16 -> 1.5707963 | E16: ='Proximal Validation'!E16 -> 0.7 | F16: ='Proximal Validation'!F16 -> 0.02 | G16: ='Proximal Validation'!G16 -> 4.712 | H16: ='Proximal Validation'!H16 -> 1.5707963 | ... Q16: ='Proximal Validation'!Q16 -> -0.91890478 | R16: 0.56047643 | S16: 0.15665577 | T16: 4.6697576 | U16: 1.5707963 | V16: 0.5380617 | W16: 0.03509659 | X16: 4.4321299 | Y16: 1.5707963 | Z16: 7.5649389e-06 | AA16: =R16-A16 -> 0.060476429 | AB16: =S16-B16 -> -0.043344231 | AC16: =T16-C16 -> -0.042242419 | AD16: =U16-D16 -> 0 | AE16: =V16-E16 -> -0.1619383 | AF16: =W16-F16 -> 0.01509659 | AG16: =X16-G16 -> -0.27987007 | AH16: =Y16-H16 -> 0 | AI16: =AVERAGE(ABS(AA16),ABS(AE16)) -> 0.11120736 | AJ16: =AVERAGE(ABS(AB16),ABS(AF16)) -> 0.029220411 | AK16: =AVERAGE(ABS(AC16),ABS(AG16)) -> 0.16105625
A17: ='Proximal Validation'!A17 -> 0.7 | B17: ='Proximal Validation'!B17 -> 0.2 | C17: ='Proximal Validation'!C17 -> 4.712 | D17: ='Proximal Validation'!D17 -> 1.5707963 | E17: ='Proximal Validation'!E17 -> 0.3 | F17: ='Proximal Validation'!F17 -> 0.08 | G17: ='Proximal Validation'!G17 -> 3.142 | H17: ='Proximal Validation'!H17 -> 1.5707963 | ... Q17: ='Proximal Validation'!Q17 -> 0

Sheet Distal Vali (0.6N perturb)
A1: Ground Truth | L1: 6-Axis FT Sensor | R1: SoRoSim get_distal_value | AA1: Distal Errors | AI1: Stats
A2: F1 (N) | B2: s1 (m) | C2: el1 (rad) | D2: az1 (rad) | E2: F2 (N) | F2: s2 (m) | G2: el2 (rad) | H2: az2 (rad) | I2: tau1 (N) | J2: tau2 (N) | K2: tau3 (N) | L2: Tx (Nm) | M2: Ty (Nm) | N2: Tz(Nm) | O2: Fx (N) | P2: Fy (N) | Q2: Fz (N) | R2: F1 (N) | S2: s1 (m) | T2: el1 (rad) | U2: az1 (rad) | V2: F2 (N) | W2: s2 (m) | X2: el2 (rad) | Y2: az2 (rad) | Z2: f_final | AA2: F1 (N) | AB2: s1 (m) | AC2: el1 (rad) | AD2: az1 (rad) | AE2: F2 (N) | AF2: s2 (m) | AG2: el2 (rad) | AH2: az2 (rad) | AI2: force_error | AJ2: position_error | AK2: angle_error | AL2: Absolute Mean Error
A3: ='Proximal Validation'!A3 -> 0.5 | B3: ='Proximal Validation'!B3 -> 0.12 | C3: ='Proximal Validation'!C3 -> 1.57 | D3: ='Proximal Validation'!D3 -> 1.5707963 | E3: ='Proximal Validation'!E3 -> 0.3 | F3: ='Proximal Validation'!F3 -> 0.02 | G3: ='Proximal Validation'!G3 -> 3.142 | H3: ='Proximal Validation'!H3 -> 1.5707963 | ... Q3: ='Proximal Validation'!Q3 -> 0.34101567 | R3: 0.3681259 | S3: 0.15632349 | T3: 1.5295315 | U3: 1.5707963 | V3: 0.30024142 | W3: 0.031014315 | X3: 3.1262105 | Y3: 1.5707963 | Z3: 1.3240493e-06 | AA3: =R3-A3 -> -0.1318741 | AB3: =S3-B3 -> 0.036323486 | AC3: =T3-C3 -> -0.04046854 | AD3: =U3-D3 -> 0 | AE3: =V3-E3 -> 0.00024142251 | AF3: =W3-F3 -> 0.011014315 | AG3: =X3-G3 -> -0.015789514 | AH3: =Y3-H3 -> 0 | AI3: =AVERAGE(ABS(AA3),ABS(AE3)) -> 0.066057762 | AJ3: =AVERAGE(ABS(AB3),ABS(AF3)) -> 0.023668901 | AK3: =AVERAGE(ABS(AC3),ABS(AG3)) -> 0.028129027 | AL3: F1 (N) | AM3: s1 (m) | AN3: el1 (rad) | AO3: az1 (rad) | AP3: F2 (N) | AQ3: s2 (m) | AR3: el2 (rad) | AS3: az2 (rad)
A4: ='Proximal Validation'!A4 -> 0.5 | B4: ='Proximal Validation'!B4 -> 0.12 | C4: ='Proximal Validation'!C4 -> 1.57 | D4: ='Proximal Validation'!D4 -> 1.5707963 | E4: ='Proximal Validation'!E4 -> 0.7 | F4: ='Proximal Validation'!F4 -> 0.06 | G4: ='Proximal Validation'!G4 -> 4.712 | H4: ='Proximal Validation'!H4 -> 1.5707963 | ... Q4: ='Proximal Validation'!Q4 -> -0.14813778 | R4: 0.5600493 | S4: 0.16686694 | T4: 1.5348193 | U4: 1.5707963 | V4: 0.68274928 | W4: 0.094720719 | X4: 4.6774163 | Y4: 1.5707963 | Z4: 7.6862678e-06 | AA4: =R4-A4 -> 0.060049301 | AB4: =S4-B4 -> 0.046866937 | AC4: =T4-C4 -> -0.035180682 | AD4: =U4-D4 -> 0 | AE4: =V4-E4 -> -0.017250717 | AF4: =W4-F4 -> 0.034720719 | AG4: =X4-G4 -> -0.034583736 | AH4: =Y4-H4 -> 0 | AI4: =AVERAGE(ABS(AA4),ABS(AE4)) -> 0.038650009 | AJ4: =AVERAGE(ABS(AB4),ABS(AF4)) -> 0.040793828 | AK4: =AVERAGE(ABS(AC4),ABS(AG4)) -> 0.034882209 | AL4: {=AVERAGE(ABS(AA3:AA17))} -> 0.090258175 | AM4: {=AVERAGE(ABS(AB3:AB17))} -> 0.013586958 | AN4: {=AVERAGE(ABS(AC3:AC17))} -> 0.078320488 | AO4: {=AVERAGE(ABS(AD3:AD17))} -> 0 | AP4: {=AVERAGE(ABS(AE3:AE17))} -> 0.08136773 | AQ4: {=AVERAGE(ABS(AF3:AF17))} -> 0.0097343565 | AR4: {=AVERAGE(ABS(AG3:AG17))} -> 0.17403615 | AS4: {=AVERAGE(ABS(AH3:AH17))} -> 0
A5: ='Proximal Validation'!A5 -> 0.8 | B5: ='Proximal Validation'!B5 -> 0.18 | C5: ='Proximal Validation'!C5 -> 1.57 | D5: ='Proximal Validation'!D5 -> 1.5707963 | E5: ='Proximal Validation'!E5 -> 0.4 | F5: ='Proximal Validation'!F5 -> 0.08 | G5: ='Proximal Validation'!G5 -> 4.712 | H5: ='Proximal Validation'!H5 -> 1.5707963 | ... Q5: ='Proximal Validation'!Q5 -> 0.032090679 | R5: 0.85920178 | S5: 0.18519334 | T5: 1.6012035 | U5: 1.5707963 | V5: 0.47344361 | W5: 0.10687621 | X5: 4.8430914 | Y5: 1.5707963 | Z5: 1.3311327e-05 | AA5: =R5-A5 -> 0.059201775 | AB5: =S5-B5 -> 0.0051933419 | AC5: =T5-C5 -> 0.031203523 | AD5: =U5-D5 -> 0 | AE5: =V5-E5 -> 0.073443613 | AF5: =W5-F5 -> 0.026876208 | AG5: =X5-G5 -> 0.1310914 | AH5: =Y5-H5 -> 0 | AI5: =AVERAGE(ABS(AA5),ABS(AE5)) -> 0.066322694 | AJ5: =AVERAGE(ABS(AB5),ABS(AF5)) -> 0.016034775 | AK5: =AVERAGE(ABS(AC5),ABS(AG5)) -> 0.081147461 | AL5: Absolute Mean Error (Across Both Forces)
A6: ='Proximal Validation'!A6 -> 0.3 | B6: ='Proximal Validation'!B6 -> 0.2 | C6: ='Proximal Validation'!C6 -> 1.57 | D6: ='Proximal Validation'!D6 -> 1.5707963 | E6: ='Proximal Validation'!E6 -> 0.7 | F6: ='Proximal Validation'!F6 -> 0.04 | G6: ='Proximal Validation'!G6 -> 3.142 | H6: ='Proximal Validation'!H6 -> 1.5707963 | ... Q6: ='Proximal Validation'!Q6 -> 0.068886459 | R6: 0.29978583 | S6: 0.19980745 | T6: 1.4734901 | U6: 1.5707963 | V6: 0.72588707 | W6: 0.049748909 | X6: 3.4079606 | Y6: 1.5707963 | Z6: 3.4862002e-06 | AA6: =R6-A6 -> -0.00021417106 | AB6: =S6-B6 -> -0.00019255456 | AC6: =T6-C6 -> -0.096509928 | AD6: =U6-D6 -> 0 | AE6: =V6-E6 -> 0.025887067 | AF6: =W6-F6 -> 0.0097489085 | AG6: =X6-G6 -> 0.2659606 | AH6: =Y6-H6 -> 0 | AI6: =AVERAGE(ABS(AA6),ABS(AE6)) -> 0.013050619 | AJ6: =AVERAGE(ABS(AB6),ABS(AF6)) -> 0.0049707315 | AK6: =AVERAGE(ABS(AC6),ABS(AG6)) -> 0.18123527 | AL6: force_error | AM6: position_error | AN6: angle_error
A7: ='Proximal Validation'!A7 -> 0.3 | B7: ='Proximal Validation'!B7 -> 0.1 | C7: ='Proximal Validation'!C7 -> 3.142 | D7: ='Proximal Validation'!D7 -> 1.5707963 | E7: ='Proximal Validation'!E7 -> 0.8 | F7: ='Proximal Validation'!F7 -> 0.08 | G7: ='Proximal Validation'!G7 -> 3.927 | H7: ='Proximal Validation'!H7 -> 1.5707963 | ... Q7: ='Proximal Validation'!Q7 -> -0.47338951 | R7: 0.6806332 | S7: 0.08602643 | T7: 2.9409908 | U7: 1.5707963 | V7: 0.6790101 | W7: 0.080471233 | X7: 4.4003432 | Y7: 1.5707963 | Z7: 8.1464083e-06 | AA7: =R7-A7 -> 0.3806332 | AB7: =S7-B7 -> -0.01397357 | AC7: =T7-C7 -> -0.20100921 | AD7: =U7-D7 -> 0 | AE7: =V7-E7 -> -0.1209899 | AF7: =W7-F7 -> 0.00047123276 | AG7: =X7-G7 -> 0.47334319 | AH7: =Y7-H7 -> 0 | AI7: =AVERAGE(ABS(AA7),ABS(AE7)) -> 0.25081155 | AJ7: =AVERAGE(ABS(AB7),ABS(AF7)) -> 0.0072224012 | AK7: =AVERAGE(ABS(AC7),ABS(AG7)) -> 0.3371762 | AL7: =AVERAGE(AI3:AI17) -> 0.099014945 | AM7: =AVERAGE(AJ3:AJ17) -> 0.013454605 | AN7: =AVERAGE(AK3:AK17) -> 0.14559037
A8: ='Proximal Validation'!A8 -> 0.7 | B8: ='Proximal Validation'!B8 -> 0.1 | C8: ='Proximal Validation'!C8 -> 3.142 | D8: ='Proximal Validation'!D8 -> 1.5707963 | E8: ='Proximal Validation'!E8 -> 0.4 | F8: ='Proximal Validation'!F8 -> 0.04 | G8: ='Proximal Validation'!G8 -> 3.927 | H8: ='Proximal Validation'!H8 -> 1.5707963 | ... Q8: ='Proximal Validation'!Q8 -> -0.25453395 | R8: 0.77393892 | S8: 0.082857599 | T8: 3.1045395 | U8: 1.5707963 | V8: 0.43045698 | W8: 0.048545752 | X8: 3.8935494 | Y8: 1.5707963 | Z8: 1.93581e-05 | AA8: =R8-A8 -> 0.073938923 | AB8: =S8-B8 -> -0.017142401 | AC8: =T8-C8 -> -0.037460476 | AD8: =U8-D8 -> 0 | AE8: =V8-E8 -> 0.030456985 | AF8: =W8-F8 -> 0.0085457518 | AG8: =X8-G8 -> -0.033450614 | AH8: =Y8-H8 -> 0 | AI8: =AVERAGE(ABS(AA8),ABS(AE8)) -> 0.052197954 | AJ8: =AVERAGE(ABS(AB8),ABS(AF8)) -> 0.012844076 | AK8: =AVERAGE(ABS(AC8),ABS(AG8)) -> 0.035455545
A9: ='Proximal Validation'!A9 -> 0.5 | B9: ='Proximal Validation'!B9 -> 0.14 | C9: ='Proximal Validation'!C9 -> 3.142 | D9: ='Proximal Validation'!D9 -> 1.5707963 | E9: ='Proximal Validation'!E9 -> 0.7 | F9: ='Proximal Validation'!F9 -> 0.08 | G9: ='Proximal Validation'!G9 -> 3.927 | H9: ='Proximal Validation'!H9 -> 1.5707963 | ... Q9: ='Proximal Validation'!Q9 -> -0.33691111 | R9: 0.24090802 | S9: 0.15326384 | T9: 2.867759 | U9: 1.5707963 | V9: 0.9285667 | W9: 0.085631391 | X9: 3.6422949 | Y9: 1.5707963 | Z9: 1.7063388e-05 | AA9: =R9-A9 -> -0.25909198 | AB9: =S9-B9 -> 0.013263837 | AC9: =T9-C9 -> -0.27424098 | AD9: =U9-D9 -> 0 | AE9: =V9-E9 -> 0.2285667 | AF9: =W9-F9 -> 0.0056313912 | AG9: =X9-G9 -> -0.28470512 | AH9: =Y9-H9 -> 0 | AI9: =AVERAGE(ABS(AA9),ABS(AE9)) -> 0.24382934 | AJ9: =AVERAGE(ABS(AB9),ABS(AF9)) -> 0.009447614 | AK9: =AVERAGE(ABS(AC9),ABS(AG9)) -> 0.27947305
A10: ='Proximal Validation'!A10 -> 0.7 | B10: ='Proximal Validation'!B10 -> 0.14 | C10: ='Proximal Validation'!C10 -> 3.142 | D10: ='Proximal Validation'!D10 -> 1.5707963 | E10: ='Proximal Validation'!E10 -> 0.5 | F10: ='Proximal Validation'!F10 -> 0.06 | G10: ='Proximal Validation'!G10 -> 3.927 | H10: ='Proximal Validation'!H10 -> 1.5707963 | ... Q10: ='Proximal Validation'!Q10 -> -0.3438628 | R10: 0.69162729 | S10: 0.11092201 | T10: 3.0127858 | U10: 1.5707963 | V10: 0.73867832 | W10: 0.06509124 | X10: 3.8151842 | Y10: 1.5707963 | Z10: 4.2574099e-05 | AA10: =R10-A10 -> -0.0083727051 | AB10: =S10-B10 -> -0.029077988 | AC10: =T10-C10 -> -0.12921421 | AD10: =U10-D10 -> 0 | AE10: =V10-E10 -> 0.23867832 | AF10: =W10-F10 -> 0.0050912397 | AG10: =X10-G10 -> -0.1118158 | AH10: =Y10-H10 -> 0 | AI10: =AVERAGE(ABS(AA10),ABS(AE10)) -> 0.12352551 | AJ10: =AVERAGE(ABS(AB10),ABS(AF10)) -> 0.017084614 | AK10: =AVERAGE(ABS(AC10),ABS(AG10)) -> 0.120515
A11: ='Proximal Validation'!A11 -> 0.4 | B11: ='Proximal Validation'!B11 -> 0.18 | C11: ='Proximal Validation'!C11 -> 3.142 | D11: ='Proximal Validation'!D11 -> 1.5707963 | E11: ='Proximal Validation'!E11 -> 0.4 | F11: ='Proximal Validation'!F11 -> 0.02 | G11: ='Proximal Validation'!G11 -> 3.927 | H11: ='Proximal Validation'!H11 -> 1.5707963 | ... Q11: ='Proximal Validation'!Q11 -> -0.25460425 | R11: 0.44227333 | S11: 0.1848532 | T11: 3.1601558 | U11: 1.5707963 | V11: 0.3213177 | W11: 0.027491823 | X11: 4.0307143 | Y11: 1.5707963 | Z11: 3.7671145e-06 | AA11: =R11-A11 -> 0.042273327 | AB11: =S11-B11 -> 0.0048532033 | AC11: =T11-C11 -> 0.018155821 | AD11: =U11-D11 -> 0 | AE11: =V11-E11 -> -0.0786823 | AF11: =W11-F11 -> 0.0074918227 | AG11: =X11-G11 -> 0.1037143 | AH11: =Y11-H11 -> 0 | AI11: =AVERAGE(ABS(AA11),ABS(AE11)) -> 0.060477813 | AJ11: =AVERAGE(ABS(AB11),ABS(AF11)) -> 0.006172513 | AK11: =AVERAGE(ABS(AC11),ABS(AG11)) -> 0.060935061
A12: ='Proximal Validation'!A12 -> 0.7 | B12: ='Proximal Validation'!B12 -> 0.18 | C12: ='Proximal Validation'!C12 -> 3.142 | D12: ='Proximal Validation'!D12 -> 1.5707963 | E12: ='Proximal Validation'!E12 -> 0.8 | F12: ='Proximal Validation'!F12 -> 0.04 | G12: ='Proximal Validation'!G12 -> 3.927 | H12: ='Proximal Validation'!H12 -> 1.5707963 | ... Q12: ='Proximal Validation'!Q12 -> 0
A13: ='Proximal Validation'!A13 -> 0.3 | B13: ='Proximal Validation'!B13 -> 0.12 | C13: ='Proximal Validation'!C13 -> 4.712 | D13: ='Proximal Validation'!D13 -> 1.5707963 | E13: ='Proximal Validation'!E13 -> 0.3 | F13: ='Proximal Validation'!F13 -> 0.04 | G13: ='Proximal Validation'!G13 -> 4.712 | H13: ='Proximal Validation'!H13 -> 1.5707963 | ... Q13: ='Proximal Validation'!Q13 -> -0.5337559 | R13: 0.38361275 | S13: 0.11941426 | T13: 4.6791184 | U13: 1.5707963 | V13: 0.16441798 | W13: 0.023999915 | X13: 4.3756609 | Y13: 1.5707963 | Z13: 9.9352469e-07 | AA13: =R13-A13 -> 0.083612749 | AB13: =S13-B13 -> -0.00058573802 | AC13: =T13-C13 -> -0.032881567 | AD13: =U13-D13 -> 0 | AE13: =V13-E13 -> -0.13558202 | AF13: =W13-F13 -> -0.016000085 | AG13: =X13-G13 -> -0.33633914 | AH13: =Y13-H13 -> 0 | AI13: =AVERAGE(ABS(AA13),ABS(AE13)) -> 0.10959738 | AJ13: =AVERAGE(ABS(AB13),ABS(AF13)) -> 0.0082929114 | AK13: =AVERAGE(ABS(AC13),ABS(AG13)) -> 0.18461035
A14: ='Proximal Validation'!A14 -> 0.8 | B14: ='Proximal Validation'!B14 -> 0.12 | C14: ='Proximal Validation'!C14 -> 4.712 | D14: ='Proximal Validation'!D14 -> 1.5707963 | E14: ='Proximal Validation'!E14 -> 0.7 | F14: ='Proximal Validation'!F14 -> 0.02 | G14: ='Proximal Validation'!G14 -> 3.142 | H14: ='Proximal Validation'!H14 -> 1.5707963 | ... Q14: ='Proximal Validation'!Q14 -> -0.87223375 | R14: 0.57884489 | S14: 0.13428601 | T14: 4.8180209 | U14: 1.5707963 | V14: 0.90555986 | W14: 0.027514195 | X14: 3.6914931 | Y14: 1.5707963 | Z14: 3.7581439e-05 | AA14: =R14-A14 -> -0.22115511 | AB14: =S14-B14 -> 0.014286013 | AC14: =T14-C14 -> 0.10602088 | AD14: =U14-D14 -> 0 | AE14: =V14-E14 -> 0.20555986 | AF14: =W14-F14 -> 0.0075141953 | AG14: =X14-G14 -> 0.5494931 | AH14: =Y14-H14 -> 0 | AI14: =AVERAGE(ABS(AA14),ABS(AE14)) -> 0.21335749 | AJ14: =AVERAGE(ABS(AB14),ABS(AF14)) -> 0.010900104 | AK14: =AVERAGE(ABS(AC14),ABS(AG14)) -> 0.32775699
A15: ='Proximal Validation'!A15 -> 0.4 | B15: ='Proximal Validation'!B15 -> 0.18 | C15: ='Proximal Validation'!C15 -> 4.712 | D15: ='Proximal Validation'!D15 -> 1.5707963 | E15: ='Proximal Validation'!E15 -> 0.5 | F15: ='Proximal Validation'!F15 -> 0.06 | G15: ='Proximal Validation'!G15 -> 3.142 | H15: ='Proximal Validation'!H15 -> 1.5707963 | ... Q15: ='Proximal Validation'!Q15 -> -0.29305437 | R15: 0.36903296 | S15: 0.19896051 | T15: 4.8428323 | U15: 1.5707963 | V15: 0.52304823 | W15: 0.072909479 | X15: 3.1668763 | Y15: 1.5707963 | Z15: 3.9444e-06 | AA15: =R15-A15 -> -0.030967043 | AB15: =S15-B15 -> 0.018960507 | AC15: =T15-C15 -> 0.13083227 | AD15: =U15-D15 -> 0 | AE15: =V15-E15 -> 0.023048229 | AF15: =W15-F15 -> 0.012909479 | AG15: =X15-G15 -> 0.024876271 | AH15: =Y15-H15 -> 0 | AI15: =AVERAGE(ABS(AA15),ABS(AE15)) -> 0.027007636 | AJ15: =AVERAGE(ABS(AB15),ABS(AF15)) -> 0.015934993 | AK15: =AVERAGE(ABS(AC15),ABS(AG15)) -> 0.077854273
A16: ='Proximal Validation'!A16 -> 0.5 | B16: ='Proximal Validation'!B16 -> 0.2 | C16: ='Proximal Validation'!C16 -> 4.712 | D16: ='Proximal Validation'!D16 -> 1.5707963 | E16: ='Proximal Validation'!E16 -> 0.7 | F16: ='Proximal Validation'!F16 -> 0.02 | G16: ='Proximal Validation'!G16 -> 4.712 | H16: ='Proximal Validation'!H16 -> 1.5707963 | ... Q16: ='Proximal Validation'!Q16 -> -0.91890478 | R16: 0.50248823 | S16: 0.1969152 | T16: 4.6703708 | U16: 1.5707963 | V16: 0.65787118 | W16: 0.02 | X16: 4.4666206 | Y16: 1.5707963 | Z16: 2.3669181e-05 | AA16: =R16-A16 -> 0.0024882319 | AB16: =S16-B16 -> -0.0030848002 | AC16: =T16-C16 -> -0.041629228 | AD16: =U16-D16 -> 0 | AE16: =V16-E16 -> -0.042128825 | AF16: =W16-F16 -> 2.220446e-14 | AG16: =X16-G16 -> -0.24537941 | AH16: =Y16-H16 -> 0 | AI16: =AVERAGE(ABS(AA16),ABS(AE16)) -> 0.022308528 | AJ16: =AVERAGE(ABS(AB16),ABS(AF16)) -> 0.0015424001 | AK16: =AVERAGE(ABS(AC16),ABS(AG16)) -> 0.14350432
A17: ='Proximal Validation'!A17 -> 0.7 | B17: ='Proximal Validation'!B17 -> 0.2 | C17: ='Proximal Validation'!C17 -> 4.712 | D17: ='Proximal Validation'!D17 -> 1.5707963 | E17: ='Proximal Validation'!E17 -> 0.3 | F17: ='Proximal Validation'!F17 -> 0.08 | G17: ='Proximal Validation'!G17 -> 3.142 | H17: ='Proximal Validation'!H17 -> 1.5707963 | ... Q17: ='Proximal Validation'!Q17 -> 0
A19: Perturbation | H19: Trial # | I19: tau1 (N) | J19: tau2 (N) | K19: tau3 (N) | L19: Supporting Measurments w Perturbation
A20: 0.6 | B20: 0 | C20: 0 | H20: 1 | I20: ='Distal Vali (0.6N perturb)'!I3 -> 0.8 | J20: ='Distal Vali (0.6N perturb)'!J3 -> 0 | K20: ='Distal Vali (0.6N perturb)'!K3 -> 0 | L20: ='Distal Vali (0.6N perturb)'!L3 -> 0.0033966473 | M20: ='Distal Vali (0.6N perturb)'!M3 -> -0.084817789 | N20: ='Distal Vali (0.6N perturb)'!N3 -> -0.032525759 | O20: ='Distal Vali (0.6N perturb)'!O3 -> -0.18618348 | P20: ='Distal Vali (0.6N perturb)'!P3 -> -0.29094619 | Q20: ='Distal Vali (0.6N perturb)'!Q3 -> 0.34101567
A21: 0 | B21: 0.6 | C21: 0 | H21: 1 | I21: =I$20+A20 -> 1.4 | J21: =J$20+B20 -> 0 | K21: =K$20+C20 -> 0 | L21: 0.0047846525 | M21: -0.076770626 | N21: -0.035355296 | O21: -0.16215064 | P21: -0.31568015 | Q21: 0.30814046
A22: 0 | B22: 0 | C22: 0.6 | H22: 1 | I22: =I$20+A21 -> 0.8 | J22: =J$20+B21 -> 0.6 | K22: =K$20+C21 -> 0 | L22: 0.0017510115 | M22: -0.075815342 | N22: -0.029226383 | O22: -0.15830263 | P22: -0.26379287 | Q22: 0.30544508
H23: 1 | I23: =I$20+A22 -> 0.8 | J23: =J$20+B22 -> 0 | K23: =K$20+C22 -> 0.6 | L23: 0.0035732281 | M23: -0.091100767 | N23: -0.031735785 | O23: -0.19084784 | P23: -0.28625211 | Q23: 0.3713474
H24: 2 | I24: ='Distal Vali (0.6N perturb)'!I4 -> 0 | J24: ='Distal Vali (0.6N perturb)'!J4 -> 0 | K24: ='Distal Vali (0.6N perturb)'!K4 -> 0 | L24: ='Distal Vali (0.6N perturb)'!L4 -> 0.00029206369 | M24: ='Distal Vali (0.6N perturb)'!M4 -> -0.014378886 | N24: ='Distal Vali (0.6N perturb)'!N4 -> 0.00051419169 | O24: ='Distal Vali (0.6N perturb)'!O4 -> -0.014039525 | P24: ='Distal Vali (0.6N perturb)'!P4 -> -0.003988117 | Q24: ='Distal Vali (0.6N perturb)'!Q4 -> -0.14813778
H25: 2 | I25: =I$24+A20 -> 0.6 | J25: =J$24+B20 -> 0 | K25: =K$24+C20 -> 0 | L25: 0.0015791627 | M25: -0.0070527084 | N25: -0.0020805015 | O25: 0.0040111663 | P25: -0.020677028 | Q25: -0.17866048
H26: 2 | I26: =I$24+A21 -> 0 | J26: =J$24+B21 -> 0.6 | K26: =K$24+C21 -> 0 | L26: -0.0011583648 | M26: -0.0071569895 | N26: 0.0029734096 | O26: 0.0036321939 | P26: 0.011851855 | Q26: -0.17981857
H27: 2 | I27: =I$24+A22 -> 0 | J27: =J$24+B22 -> 0 | K27: =K$24+C22 -> 0.6 | L27: -3.6913669e-05 | M27: -0.02358564 | N27: 0.0012023193 | O27: -0.025370907 | P27: -0.00074703619 | Q27: -0.10559404
H28: 3 | I28: ='Distal Vali (0.6N perturb)'!I5 -> 0.4 | J28: ='Distal Vali (0.6N perturb)'!J5 -> 0 | K28: ='Distal Vali (0.6N perturb)'!K5 -> 0 | L28: ='Distal Vali (0.6N perturb)'!L5 -> 0.0026918571 | M28: ='Distal Vali (0.6N perturb)'!M5 -> -0.097128831 | N28: ='Distal Vali (0.6N perturb)'!N5 -> 0.0050861202 | O28: ='Distal Vali (0.6N perturb)'!O5 -> -0.40724513 | P28: ='Distal Vali (0.6N perturb)'!P5 -> 0.01080508 | Q28: ='Distal Vali (0.6N perturb)'!Q5 -> 0.032090679
H29: 3 | I29: =I$28+A20 -> 1 | J29: =J$28+B20 -> 0 | K29: =K$28+C20 -> 0 | L29: 0.0071417103 | M29: -0.091151893 | N29: 0.00037218275 | O29: -0.38164517 | P29: -0.020746578 | Q29: 0.026900358
H30: 3 | I30: =I$28+A21 -> 0.4 | J30: =J$28+B21 -> 0.6 | K30: =K$28+C21 -> 0 | L30: -0.00099307718 | M30: -0.088719904 | N30: 0.0085697956 | O30: -0.37443939 | P30: 0.034079839 | Q30: 0.016371489
H31: 3 | I31: =I$28+A22 -> 0.4 | J31: =J$28+B22 -> 0 | K31: =K$28+C22 -> 0.6 | L31: 0.0023157138 | M31: -0.099095643 | N31: 0.0055827959 | O31: -0.41846365 | P31: 0.013112237 | Q31: 0.032927413
H32: 4 | I32: ='Distal Vali (0.6N perturb)'!I6 -> 0.4 | J32: ='Distal Vali (0.6N perturb)'!J6 -> 0 | K32: ='Distal Vali (0.6N perturb)'!K6 -> 0 | L32: ='Distal Vali (0.6N perturb)'!L6 -> 0.0012694518 | M32: ='Distal Vali (0.6N perturb)'!M6 -> -0.052426334 | N32: ='Distal Vali (0.6N perturb)'!N6 -> -0.088403538 | O32: ='Distal Vali (0.6N perturb)'!O6 -> -0.16237766 | P32: ='Distal Vali (0.6N perturb)'!P6 -> -0.67368567 | Q32: ='Distal Vali (0.6N perturb)'!Q6 -> 0.068886459
H33: 4 | I33: =I$32+A20 -> 1 | J33: =J$32+B20 -> 0 | K33: =K$32+C20 -> 0 | L33: 0.0039274767 | M33: -0.04400054 | N33: -0.095036954 | O33: -0.14485145 | P33: -0.71704698 | Q33: 0.046903402
H34: 4 | I34: =I$32+A21 -> 0.4 | J34: =J$32+B21 -> 0.6 | K34: =K$32+C21 -> 0 | L34: -0.00095364777 | M34: -0.045862302 | N34: -0.081878006 | O34: -0.14690472 | P34: -0.63195258 | Q34: 0.056958616
H35: 4 | I35: =I$32+A22 -> 0.4 | J35: =J$32+B22 -> 0 | K35: =K$32+C22 -> 0.6 | L35: 0.0009064367 | M35: -0.06001747 | N35: -0.086739369 | O35: -0.18440372 | P35: -0.66644299 | Q35: 0.092208803
H36: 5 | I36: ='Distal Vali (0.6N perturb)'!I7 -> 0.8 | J36: ='Distal Vali (0.6N perturb)'!J7 -> 0 | K36: ='Distal Vali (0.6N perturb)'!K7 -> 0 | L36: ='Distal Vali (0.6N perturb)'!L7 -> -0.00026597269 | M36: ='Distal Vali (0.6N perturb)'!M7 -> 0.086320065 | N36: ='Distal Vali (0.6N perturb)'!N7 -> -0.15243518 | O36: ='Distal Vali (0.6N perturb)'!O7 -> -0.22609875 | P36: ='Distal Vali (0.6N perturb)'!P7 -> -0.812931 | Q36: ='Distal Vali (0.6N perturb)'!Q7 -> -0.47338951
H37: 5 | I37: =I$36+A20 -> 1.4 | J37: =J$36+B20 -> 0 | K37: =K$36+C20 -> 0 | L37: -0.0003334824 | M37: 0.088781089 | N37: -0.16011225 | O37: -0.2329109 | P37: -0.85305935 | Q37: -0.48643208
H38: 5 | I38: =I$36+A21 -> 0.8 | J38: =J$36+B21 -> 0.6 | K38: =K$36+C21 -> 0 | L38: 0.0013329796 | M38: 0.088260546 | N38: -0.13754681 | O38: -0.20097205 | P38: -0.74244308 | Q38: -0.48660368
H39: 5 | I39: =I$36+A22 -> 0.8 | J39: =J$36+B22 -> 0 | K39: =K$36+C22 -> 0.6 | L39: -0.0018139016 | M39: 0.075751185 | N39: -0.14450066 | O39: -0.19105113 | P39: -0.77179682 | Q39: -0.41100234
H40: 6 | I40: ='Distal Vali (0.6N perturb)'!I8 -> 0.4 | J40: ='Distal Vali (0.6N perturb)'!J8 -> 0 | K40: ='Distal Vali (0.6N perturb)'!K8 -> 0 | L40: ='Distal Vali (0.6N perturb)'!L8 -> -0.0011004871 | M40: ='Distal Vali (0.6N perturb)'!M8 -> 0.036083326 | N40: ='Distal Vali (0.6N perturb)'!N8 -> -0.18029018 | O40: ='Distal Vali (0.6N perturb)'!O8 -> -0.18137529 | P40: ='Distal Vali (0.6N perturb)'!P8 -> -0.99236429 | Q40: ='Distal Vali (0.6N perturb)'!Q8 -> -0.25453395
H41: 6 | I41: =I$40+A20 -> 1 | J41: =J$40+B20 -> 0 | K41: =K$40+C20 -> 0 | L41: -7.9773366e-05 | M41: 0.04057971 | N41: -0.19076373 | O41: -0.19178027 | P41: -1.0544391 | Q41: -0.28682235
...

Sheet Conversion
A1: Raw Data | H1: Converted
A2: Fx | B2: Fy | C2: Fz | D2: Tx | E2: Ty | F2: Tz | H2: Tx | I2: Ty | J2: Tz | K2: Fx | L2: Fy | M2: Fz
A3: 0.34101567 | B3: 0.29094619 | C3: -0.18618348 | D3: -0.032525759 | E3: 0.084817789 | F3: 0.0033966473 | H3: =$F3 -> 0.0033966473 | I3: =-1*$E3 -> -0.084817789 | J3: =$D3 -> -0.032525759 | K3: =$C3 -> -0.18618348 | L3: =-1*$B3 -> -0.29094619 | M3: =$A3 -> 0.34101567
A4: 0.30814046 | B4: 0.31568015 | C4: -0.16215064 | D4: -0.035355296 | E4: 0.076770626 | F4: 0.0047846525 | H4: =$F4 -> 0.0047846525 | I4: =-1*$E4 -> -0.076770626 | J4: =$D4 -> -0.035355296 | K4: =$C4 -> -0.16215064 | L4: =-1*$B4 -> -0.31568015 | M4: =$A4 -> 0.30814046
A5: 0.30544508 | B5: 0.26379287 | C5: -0.15830263 | D5: -0.029226383 | E5: 0.075815342 | F5: 0.0017510115 | H5: =$F5 -> 0.0017510115 | I5: =-1*$E5 -> -0.075815342 | J5: =$D5 -> -0.029226383 | K5: =$C5 -> -0.15830263 | L5: =-1*$B5 -> -0.26379287 | M5: =$A5 -> 0.30544508
A6: 0.3713474 | B6: 0.28625211 | C6: -0.19084784 | D6: -0.031735785 | E6: 0.091100767 | F6: 0.0035732281 | H6: =$F6 -> 0.0035732281 | I6: =-1*$E6 -> -0.091100767 | J6: =$D6 -> -0.031735785 | K6: =$C6 -> -0.19084784 | L6: =-1*$B6 -> -0.28625211 | M6: =$A6 -> 0.3713474
A7: -0.14813778 | B7: 0.003988117 | C7: -0.014039525 | D7: 0.00051419169 | E7: 0.014378886 | F7: 0.00029206369 | H7: =$F7 -> 0.00029206369 | I7: =-1*$E7 -> -0.014378886 | J7: =$D7 -> 0.00051419169 | K7: =$C7 -> -0.014039525 | L7: =-1*$B7 -> -0.003988117 | M7: =$A7 -> -0.14813778
A8: -0.17866048 | B8: 0.020677028 | C8: 0.0040111663 | D8: -0.0020805015 | E8: 0.0070527084 | F8: 0.0015791627 | H8: =$F8 -> 0.0015791627 | I8: =-1*$E8 -> -0.0070527084 | J8: =$D8 -> -0.0020805015 | K8: =$C8 -> 0.0040111663 | L8: =-1*$B8 -> -0.020677028 | M8: =$A8 -> -0.17866048
A9: -0.17981857 | B9: -0.011851855 | C9: 0.0036321939 | D9: 0.0029734096 | E9: 0.0071569895 | F9: -0.0011583648 | H9: =$F9 -> -0.0011583648 | I9: =-1*$E9 -> -0.0071569895 | J9: =$D9 -> 0.0029734096 | K9: =$C9 -> 0.0036321939 | L9: =-1*$B9 -> 0.011851855 | M9: =$A9 -> -0.17981857
A10: -0.10559404 | B10: 0.00074703619 | C10: -0.025370907 | D10: 0.0012023193 | E10: 0.02358564 | F10: -3.6913669e-05 | H10: =$F10 -> -3.6913669e-05 | I10: =-1*$E10 -> -0.02358564 | J10: =$D10 -> 0.0012023193 | K10: =$C10 -> -0.025370907 | L10: =-1*$B10 -> -0.00074703619 | M10: =$A10 -> -0.10559404
A11: 0.032090679 | B11: -0.01080508 | C11: -0.40724513 | D11: 0.0050861202 | E11: 0.097128831 | F11: 0.0026918571 | H11: =$F11 -> 0.0026918571 | I11: =-1*$E11 -> -0.097128831 | J11: =$D11 -> 0.0050861202 | K11: =$C11 -> -0.40724513 | L11: =-1*$B11 -> 0.01080508 | M11: =$A11 -> 0.032090679
A12: 0.026900358 | B12: 0.020746578 | C12: -0.38164517 | D12: 0.00037218275 | E12: 0.091151893 | F12: 0.0071417103 | H12: =$F12 -> 0.0071417103 | I12: =-1*$E12 -> -0.091151893 | J12: =$D12 -> 0.00037218275 | K12: =$C12 -> -0.38164517 | L12: =-1*$B12 -> -0.020746578 | M12: =$A12 -> 0.026900358
A13: 0.016371489 | B13: -0.034079839 | C13: -0.37443939 | D13: 0.0085697956 | E13: 0.088719904 | F13: -0.00099307718 | H13: =$F13 -> -0.00099307718 | I13: =-1*$E13 -> -0.088719904 | J13: =$D13 -> 0.0085697956 | K13: =$C13 -> -0.37443939 | L13: =-1*$B13 -> 0.034079839 | M13: =$A13 -> 0.016371489
A14: 0.032927413 | B14: -0.013112237 | C14: -0.41846365 | D14: 0.0055827959 | E14: 0.099095643 | F14: 0.0023157138 | H14: =$F14 -> 0.0023157138 | I14: =-1*$E14 -> -0.099095643 | J14: =$D14 -> 0.0055827959 | K14: =$C14 -> -0.41846365 | L14: =-1*$B14 -> 0.013112237 | M14: =$A14 -> 0.032927413
... A54: -0.87853527 | B54: 0.16112147 | C54: -0.38894972 | D54: -0.020251552 | E54: -0.17864496 | F54: -0.0067889746 | H54: =$F54 -> -0.0067889746 | I54: =-1*$E54 -> 0.17864496 | J54: =$D54 -> -0.020251552 | K54: =$C54 -> -0.38894972 | L54: =-1*$B54 -> -0.16112147 | M54: =$A54 -> -0.87853527

Sheet Sheet5
A2: [ | B2: -0.0013721101 | C2: 0.087113634 | D2: -0.16279364 | E2: -0.090744965 | F2: -0.87937129 | G2: -0.48219949 | H2: ; | J2: [ | K2: 0.8 | L2: 0 | M2: 0 | N2: ; | S2: [ | T2: 0.5 | U2: 0.12 | V2: 1.57 | W2: 1.5707963 | X2: 0.3 | Y2: 0.02 | Z2: 3.142 | AA2: 1.5707963 | AB2: 0.8 | AC2: 0 | AD2: 0 | AE2: ;
B3: -0.001360558 | C3: 0.090598643 | D3: -0.17294137 | E3: -0.094194762 | F3: -0.93448365 | G3: -0.50216889 | H3: ; | K3: 1.4 | L3: 0 | M3: 0 | N3: ; | T3: 0.5 | U3: 0.12 | V3: 1.57 | W3: 1.5707963 | X3: 0.7 | Y3: 0.06 | Z3: 4.712 | AA3: 1.5707963 | AB3: 0 | AC3: 0 | AD3: 0 | AE3: ;
B4: -0.00044362899 | C4: 0.087859079 | D4: -0.14970051 | E4: -0.083662197 | F4: -0.81903315 | G4: -0.48939896 | H4: ; | K4: 0.8 | L4: 0.6 | M4: 0 | N4: ; | T4: 0.8 | U4: 0.18 | V4: 1.57 | W4: 1.5707963 | X4: 0.4 | Y4: 0.08 | Z4: 4.712 | AA4: 1.5707963 | AB4: 0.4 | AC4: 0 | AD4: 0 | AE4: ;
B5: -0.00217553 | C5: 0.079079501 | D5: -0.15534256 | E5: -0.084770121 | F5: -0.84200013 | G5: -0.43774006 | H5: ] | K5: 0.8 | L5: 0 | M5: 0.6 | N5: ] | T5: 0.3 | U5: 0.2 | V5: 1.57 | W5: 1.5707963 | X5: 0.7 | Y5: 0.04 | Z5: 3.142 | AA5: 1.5707963 | AB5: 0.4 | AC5: 0 | AD5: 0 | AE5: ;
T6: 0.3 | U6: 0.1 | V6: 3.142 | W6: 1.5707963 | X6: 0.8 | Y6: 0.08 | Z6: 3.927 | AA6: 1.5707963 | AB6: 0.8 | AC6: 0 | AD6: 0 | AE6: ;
T7: 0.7 | U7: 0.1 | V7: 3.142 | W7: 1.5707963 | X7: 0.4 | Y7: 0.04 | Z7: 3.927 | AA7: 1.5707963 | AB7: 0.4 | AC7: 0 | AD7: 0 | AE7: ;
T8: 0.5 | U8: 0.14 | V8: 3.142 | W8: 1.5707963 | X8: 0.7 | Y8: 0.08 | Z8: 3.927 | AA8: 1.5707963 | AB8: 0.4 | AC8: 0 | AD8: 0 | AE8: ;
T9: 0.7 | U9: 0.14 | V9: 3.142 | W9: 1.5707963 | X9: 0.5 | Y9: 0.06 | Z9: 3.927 | AA9: 1.5707963 | AB9: 0.8 | AC9: 0 | AD9: 0 | AE9: ;
T10: 0.4 | U10: 0.18 | V10: 3.142 | W10: 1.5707963 | X10: 0.4 | Y10: 0.02 | Z10: 3.927 | AA10: 1.5707963 | AB10: 0 | AC10: 0 | AD10: 0 | AE10: ;
T11: 0.7 | U11: 0.18 | V11: 3.142 | W11: 1.5707963 | X11: 0.8 | Y11: 0.04 | Z11: 3.927 | AA11: 1.5707963 | AB11: 0.4 | AC11: 0 | AD11: 0 | AE11: ;
C12: { | D12: [ | E12: 0.0033966473 | F12: -0.084817789 | G12: -0.032525759 | H12: -0.18618348 | I12: -0.29094619 | J12: 0.34101567 | K12: 0.8 | L12: 0 | M12: 0 | N12: ] | O12: ; | T12: 0.3 | U12: 0.12 | V12: 4.712 | W12: 1.5707963 | X12: 0.3 | Y12: 0.04 | Z12: 4.712 | AA12: 1.5707963 | AB12: 0.4 | AC12: 0 | AD12: 0 | AE12: ;
D13: [ | E13: 0.00029206369 | F13: -0.014378886 | G13: 0.00051419169 | H13: -0.014039525 | I13: -0.003988117 | J13: -0.14813778 | K13: 0 | L13: 0 | M13: 0 | N13: ] | O13: ; | T13: 0.8 | U13: 0.12 | V13: 4.712 | W13: 1.5707963 | X13: 0.7 | Y13: 0.02 | Z13: 3.142 | AA13: 1.5707963 | AB13: 0 | AC13: 0 | AD13: 0 | AE13: ;
D14: [ | E14: 0.0026918571 | F14: -0.097128831 | G14: 0.0050861202 | H14: -0.40724513 | I14: 0.01080508 | J14: 0.032090679 | K14: 0.4 | L14: 0 | M14: 0 | N14: ] | O14: ; | T14: 0.4 | U14: 0.18 | V14: 4.712 | W14: 1.5707963 | X14: 0.5 | Y14: 0.06 | Z14: 3.142 | AA14: 1.5707963 | AB14: 0.4 | AC14: 0 | AD14: 0 | AE14: ;
D15: [ | E15: 0.0012694518 | F15: -0.052426334 | G15: -0.088403538 | H15: -0.16237766 | I15: -0.67368567 | J15: 0.068886459 | K15: 0.4 | L15: 0 | M15: 0 | N15: ] | O15: ; | T15: 0.5 | U15: 0.2 | V15: 4.712 | W15: 1.5707963 | X15: 0.7 | Y15: 0.02 | Z15: 4.712 | AA15: 1.5707963 | AB15: 0.8 | AC15: 0 | AD15: 0 | AE15: ;
D16: [ | E16: -0.00026597269 | F16: 0.086320065 | G16: -0.15243518 | H16: -0.22609875 | I16: -0.812931 | J16: -0.47338951 | K16: 0.8 | L16: 0 | M16: 0 | N16: ] | O16: ; | T16: 0.7 | U16: 0.2 | V16: 4.712 | W16: 1.5707963 | X16: 0.3 | Y16: 0.08 | Z16: 3.142 | AA16: 1.5707963 | AB16: 0 | AC16: 0 | AD16: 0 | AE16: ]
D17: [ | E17: -0.0011004871 | F17: 0.036083326 | G17: -0.18029018 | H17: -0.18137529 | I17: -0.99236429 | J17: -0.25453395 | K17: 0.4 | L17: 0 | M17: 0 | N17: ] | O17: ;
D18: [ | E18: 0.00012140814 | F18: 0.06093071 | G18: -0.19216824 | H18: -0.4532392 | I18: -0.8637259 | J18: -0.33691111 | K18: 0.4 | L18: 0 | M18: 0 | N18: ] | O18: ;
D19: [ | E19: 0.0020413408 | F19: 0.053677611 | G19: -0.22552121 | H19: -0.44799793 | I19: -1.034426 | J19: -0.3438628 | K19: 0.8 | L19: 0 | M19: 0 | N19: ] | O19: ;
D20: [ | E20: -0.0018034787 | F20: 0.030678485 | G20: -0.13010471 | H20: -0.34587803 | I20: -0.53015172 | J20: -0.25460425 | K20: 0 | L20: 0 | M20: 0 | N20: ] | O20: ;
D21: [ | E21: 0.0033966473 | F21: -0.084817789 | G21: -0.032525759 | H21: -0.18618348 | I21: -0.29094619 | J21: 0.34101567 | K21: 0.4 | L21: 0 | M21: 0 | N21: ] | O21: ;
D22: [ | E22: -0.0009027482 | F22: 0.095996417 | G22: -0.0087546632 | H22: -0.11151029 | I22: -0.063374788 | J22: -0.5337559 | K22: 0.4 | L22: 0 | M22: 0 | N22: ] | O22: ;
D23: [ | E23: 0.00073054992 | F23: 0.18510914 | G23: -0.078640699 | H23: -0.26385891 | I23: -0.6934616 | J23: -0.87223375 | K23: 0 | L23: 0 | M23: 0 | N23: ] | O23: ;
D24: [ | E24: -0.002943269 | F24: 0.098053239 | G24: -0.070226938 | H24: -0.23587371 | I24: -0.46341708 | J24: -0.29305437 | K24: 0.4 | L24: 0 | M24: 0 | N24: ] | O24: ;
D25: [ | E25: -0.0089650583 | F25: 0.193453 | G25: -0.02267966 | H25: -0.44403204 | I25: -0.17503352 | J25: -0.91890478 | K25: 0.8 | L25: 0 | M25: 0 | N25: ] | O25: ;
D26: [ | E26: 0.0033966473 | F26: -0.084817789 | G26: -0.032525759 | H26: -0.18618348 | I26: -0.29094619 | J26: 0.34101567 | K26: 0 | L26: 0 | M26: 0 | N26: ] | O26: ; | P26: }
C29: { | D29: [ | E29: 0.0033966473 | F29: -0.084817789 | G29: -0.032525759 | H29: -0.18618348 | I29: -0.29094619 | J29: 0.34101567 | K29: 0.8 | L29: 0 | M29: 0 | N29: ;
E30: 0.0047846525 | F30: -0.076770626 | G30: -0.035355296 | H30: -0.16215064 | I30: -0.31568015 | J30: 0.30814046 | K30: 1.4 | L30: 0 | M30: 0 | N30: ;
E31: 0.0017510115 | F31: -0.075815342 | G31: -0.029226383 | H31: -0.15830263 | I31: -0.26379287 | J31: 0.30544508 | K31: 0.8 | L31: 0.6 | M31: 0 | N31: ;
E32: 0.0035732281 | F32: -0.091100767 | G32: -0.031735785 | H32: -0.19084784 | I32: -0.28625211 | J32: 0.3713474 | K32: 0.8 | L32: 0 | M32: 0.6 | N32: ] | O32: ;
D33: [ | E33: 0.00029206369 | F33: -0.014378886 | G33: 0.00051419169 | H33: -0.014039525 | I33: -0.003988117 | J33: -0.14813778 | K33: 0 | L33: 0 | M33: 0 | N33: ;
E34: 0.0015791627 | F34: -0.0070527084 | G34: -0.0020805015 | H34: 0.0040111663 | I34: -0.020677028 | J34: -0.17866048 | K34: 0.6 | L34: 0 | M34: 0 | N34: ;
E35: -0.0011583648 | F35: -0.0071569895 | G35: 0.0029734096 | H35: 0.0036321939 | I35: 0.011851855 | J35: -0.17981857 | K35: 0 | L35: 0.6 | M35: 0 | N35: ;
E36: -3.6913669e-05 | F36: -0.02358564 | G36: 0.0012023193 | H36: -0.025370907 | I36: -0.00074703619 | J36: -0.10559404 | K36: 0 | L36: 0 | M36: 0.6 | N36: ] | O36: ;
D37: [ | E37: 0.0026918571 | F37: -0.097128831 | G37: 0.0050861202 | H37: -0.40724513 | I37: 0.01080508 | J37: 0.032090679 | K37: 0.4 | L37: 0 | M37: 0 | N37: ;
E38: 0.0071417103 | F38: -0.091151893 | G38: 0.00037218275 | H38: -0.38164517 | I38: -0.020746578 | J38: 0.026900358 | K38: 1 | L38: 0 | M38: 0 | N38: ;
E39: -0.00099307718 | F39: -0.088719904 | G39: 0.0085697956 | H39: -0.37443939 | I39: 0.034079839 | J39: 0.016371489 | K39: 0.4 | L39: 0.6 | M39: 0 | N39: ;
E40: 0.0023157138 | F40: -0.099095643 | G40: 0.0055827959 | H40: -0.41846365 | I40: 0.013112237 | J40: 0.032927413 | K40: 0.4 | L40: 0 | M40: 0.6 | N40: ] | O40: ;
D41: [ | E41: 0.0012694518 | F41: -0.052426334 | G41: -0.088403538 | H41: -0.16237766 | I41: -0.67368567 | J41: 0.068886459 | K41: 0.4 | L41: 0 | M41: 0 | N41: ;
E42: 0.0039274767 | F42: -0.04400054 | G42: -0.095036954 | H42: -0.14485145 | I42: -0.71704698 | J42: 0.046903402 | K42: 1 | L42: 0 | M42: 0 | N42: ;
E43: -0.00095364777 | F43: -0.045862302 | G43: -0.081878006 | H43: -0.14690472 | I43: -0.63195258 | J43: 0.056958616 | K43: 0.4 | L43: 0.6 | M43: 0 | N43: ;
...
