Workbook

Sheet Proximal Validation
A1: Ground Truth | L1: 6-Axis FT Sensor | R1: SoRoSim get_proximal_value | X1: Proximal Errors
A2: F1 (N) | B2: s1 (m) | C2: el1 (rad) | D2: az1 (rad) | E2: F2 (N) | F2: s2 (m) | G2: el2 (rad) | H2: az2 (rad) | I2: tau1 (N) | J2: tau2 (N) | K2: tau3 (N) | L2: Tx (Nm) | M2: Ty (Nm) | N2: Tz(Nm) | O2: Fx (N) | P2: Fy (N) | Q2: Fz (N) | R2: Tx (Nm) | S2: Ty (Nm) | T2: Tz(Nm) | U2: Fx (N) | V2: Fy (N) | W2: Fz (N) | X2: Tx (Nm) | Y2: Ty (Nm) | Z2: Tz(Nm) | AA2: Fx (N) | AB2: Fy (N) | AC2: Fz (N)
A3: 0.5 | B3: 0.12 | C3: 1.57 | D3: =PI()/2 -> 1.5707963 | E3: 0.3 | F3: 0.02 | G3: 3.142 | H3: =PI()/2 -> 1.5707963 | I3: 0.8 | J3: 0 | K3: 0 | L3: 0.00038069719 | M3: -0.096344933 | N3: -0.033478599 | O3: -0.082021892 | P3: -0.28456718 | Q3: 0.41270199 | R3: 0.00087917115 | S3: -0.10405197 | T3: -0.032777475 | U3: -0.087466346 | V3: -0.30046979 | W3: 0.49207697 | X3: =L3-R3 -> -0.00049847395 | Y3: =M3-S3 -> 0.0077070386 | Z3: =N3-T3 -> -0.00070112447 | AA3: =O3-U3 -> 0.0054444541 | AB3: =P3-V3 -> 0.015902615 | AC3: =Q3-W3 -> -0.079374976
A4: 0.5 | B4: 0.12 | C4: 1.57 | D4: =PI()/2 -> 1.5707963 | E4: 0.7 | F4: 0.06 | G4: 4.712 | H4: =PI()/2 -> 1.5707963 | I4: 0 | J4: 0 | K4: 0 | L4: -0.00081903394 | M4: -0.00532459 | N4: -0.0023375959 | O4: -0.0024775807 | P4: -0.0034357905 | Q4: -0.19096869 | R4: -1.3823731e-14 | S4: 0.00014285633 | T4: 4.2584332e-05 | U4: -0.013684032 | V4: 0.00012410347 | W4: -0.20181289 | X4: =L4-R4 -> -0.00081903394 | Y4: =M4-S4 -> -0.0054674464 | Z4: =N4-T4 -> -0.0023801802 | AA4: =O4-U4 -> 0.011206451 | AB4: =P4-V4 -> -0.003559894 | AC4: =Q4-W4 -> 0.010844198
A5: 0.8 | B5: 0.18 | C5: 1.57 | D5: =PI()/2 -> 1.5707963 | E5: 0.4 | F5: 0.08 | G5: 4.712 | H5: =PI()/2 -> 1.5707963 | I5: 0.4 | J5: 0 | K5: 0 | L5: 0.00034113688 | M5: -0.14381006 | N5: -0.003464737 | O5: -0.43965021 | P5: -0.0037686527 | Q5: 0.28356427 | R5: 0.0017927865 | S5: -0.12503457 | T5: -0.00024335725 | U5: -0.37350224 | V5: -0.0055078117 | W5: 0.24571879 | X5: =L5-R5 -> -0.0014516496 | Y5: =M5-S5 -> -0.018775495 | Z5: =N5-T5 -> -0.0032213797 | AA5: =O5-U5 -> -0.066147966 | AB5: =P5-V5 -> 0.001739159 | AC5: =Q5-W5 -> 0.037845478
A6: 0.3 | B6: 0.2 | C6: 1.57 | D6: =PI()/2 -> 1.5707963 | E6: 0.7 | F6: 0.04 | G6: 3.142 | H6: =PI()/2 -> 1.5707963 | I6: 0.4 | J6: 0 | K6: 0 | L6: -0.00028536888 | M6: -0.063574255 | N6: -0.090447113 | O6: -0.08588402 | P6: -0.67203629 | Q6: 0.13295281 | R6: 0.00097767751 | S6: -0.083235739 | T6: -0.090648802 | U6: -0.1182666 | V6: -0.69929383 | W6: 0.2793725 | X6: =L6-R6 -> -0.0012630464 | Y6: =M6-S6 -> 0.019661484 | Z6: =N6-T6 -> 0.00020168879 | AA6: =O6-U6 -> 0.032382583 | AB6: =P6-V6 -> 0.027257537 | AC6: =Q6-W6 -> -0.14641969
A7: 0.3 | B7: 0.1 | C7: 3.142 | D7: =PI()/2 -> 1.5707963 | E7: 0.8 | F7: 0.08 | G7: 3.927 | H7: =PI()/2 -> 1.5707963 | I7: 0.8 | J7: 0 | K7: 0 | L7: -0.0013721101 | M7: 0.087113634 | N7: -0.16279364 | O7: -0.090744965 | P7: -0.87937129 | Q7: -0.48219949 | R7: 3.3176637e-05 | S7: 0.095752021 | T7: -0.15243226 | U7: -0.12459057 | V7: -0.85915383 | W7: -0.56202764 | X7: =L7-R7 -> -0.0014052867 | Y7: =M7-S7 -> -0.0086383877 | Z7: =N7-T7 -> -0.010361376 | AA7: =O7-U7 -> 0.033845609 | AB7: =P7-V7 -> -0.020217455 | AC7: =Q7-W7 -> 0.079828151
A8: 0.7 | B8: 0.1 | C8: 3.142 | D8: =PI()/2 -> 1.5707963 | E8: 0.4 | F8: 0.04 | G8: 3.927 | H8: =PI()/2 -> 1.5707963 | I8: 0.4 | J8: 0 | K8: 0 | L8: -0.0014753519 | M8: 0.031907491 | N8: -0.19490382 | O8: -0.17070602 | P8: -1.0707257 | Q8: -0.2222923 | R8: 0.00022079077 | S8: 0.036698297 | T8: -0.16885528 | U8: -0.12120746 | V8: -0.97516655 | W8: -0.28267572 | X8: =L8-R8 -> -0.0016961426 | Y8: =M8-S8 -> -0.0047908054 | Z8: =N8-T8 -> -0.026048541 | AA8: =O8-U8 -> -0.049498559 | AB8: =P8-V8 -> -0.095559129 | AC8: =Q8-W8 -> 0.060383417
A9: 0.5 | B9: 0.14 | C9: 3.142 | D9: =PI()/2 -> 1.5707963 | E9: 0.7 | F9: 0.08 | G9: 3.927 | H9: =PI()/2 -> 1.5707963 | I9: 0.4 | J9: 0 | K9: 0 | L9: -0.0028121248 | M9: 0.070382752 | N9: -0.20890267 | O9: -0.32640225 | P9: -0.97189969 | Q9: -0.38067478 | R9: 0.00029578987 | S9: 0.083115239 | T9: -0.1955101 | U9: -0.26459098 | V9: -0.96342145 | W9: -0.48609593 | X9: =L9-R9 -> -0.0031079147 | Y9: =M9-S9 -> -0.012732487 | Z9: =N9-T9 -> -0.013392577 | AA9: =O9-U9 -> -0.06181127 | AB9: =P9-V9 -> -0.0084782392 | AC9: =Q9-W9 -> 0.10542115
A10: 0.7 | B10: 0.14 | C10: 3.142 | D10: =PI()/2 -> 1.5707963 | E10: 0.5 | F10: 0.06 | G10: 3.927 | H10: =PI()/2 -> 1.5707963 | I10: 0.8 | J10: 0 | K10: 0 | L10: -0.0018884372 | M10: 0.048766464 | N10: -0.22089446 | O10: -0.32184327 | P10: -1.0122297 | Q10: -0.29647687 | R10: 0.00097454532 | S10: 0.052603302 | T10: -0.20967304 | U10: -0.27595867 | V10: -1.0164549 | W10: -0.35089206 | X10: =L10-R10 -> -0.0028629825 | Y10: =M10-S10 -> -0.0038368379 | Z10: =N10-T10 -> -0.011221416 | AA10: =O10-U10 -> -0.045884594 | AB10: =P10-V10 -> 0.0042251728 | AC10: =Q10-W10 -> 0.054415186
A11: 0.4 | B11: 0.18 | C11: 3.142 | D11: =PI()/2 -> 1.5707963 | E11: 0.4 | F11: 0.02 | G11: 3.927 | H11: =PI()/2 -> 1.5707963 | I11: 0 | J11: 0 | K11: 0 | L11: -0.0025915056 | M11: 0.027324185 | N11: -0.13145609 | O11: -0.13658202 | P11: -0.61641645 | Q11: -0.2340374 | R11: 8.4515915e-12 | S11: 0.030958316 | T11: -0.13556173 | U11: -0.15334217 | V11: -0.6571475 | W11: -0.28274149 | X11: =L11-R11 -> -0.0025915057 | Y11: =M11-S11 -> -0.0036341308 | Z11: =N11-T11 -> 0.0041056365 | AA11: =O11-U11 -> 0.016760149 | AB11: =P11-V11 -> 0.040731045 | AC11: =Q11-W11 -> 0.048704089
A12: 0.7 | B12: 0.18 | C12: 3.142 | D12: =PI()/2 -> 1.5707963 | E12: 0.8 | F12: 0.04 | G12: 3.927 | H12: =PI()/2 -> 1.5707963 | I12: 0.4 | J12: 0 | K12: 0 | L12: -0.0028818771 | M12: 0.064880513 | N12: -0.26836297 | O12: -0.61091924 | P12: -1.1492969 | Q12: -0.46333063 | R12: 0.00096703958 | S12: 0.07290917 | T12: -0.24514893 | U12: -0.49398521 | V12: -1.1364824 | W12: -0.56209018 | X12: =L12-R12 -> -0.0038489167 | Y12: =M12-S12 -> -0.0080286575 | Z12: =N12-T12 -> -0.023214041 | AA12: =O12-U12 -> -0.11693403 | AB12: =P12-V12 -> -0.012814436 | AC12: =Q12-W12 -> 0.098759555
A13: 0.3 | B13: 0.12 | C13: 4.712 | D13: =PI()/2 -> 1.5707963 | E13: 0.3 | F13: 0.04 | G13: 4.712 | H13: =PI()/2 -> 1.5707963 | I13: 0.4 | J13: 0 | K13: 0 | L13: -0.0010846329 | M13: 0.10540774 | N13: -0.0075431094 | O13: -0.044421639 | P13: -0.053632915 | Q13: -0.59106356 | R13: -0.00028518833 | S13: 0.10175917 | T13: -4.4451007e-05 | U13: -0.042191472 | V13: -0.00038628722 | W13: -0.59837104 | X13: =L13-R13 -> -0.00079944461 | Y13: =M13-S13 -> 0.003648571 | Z13: =N13-T13 -> -0.0074986584 | AA13: =O13-U13 -> -0.0022301669 | AB13: =P13-V13 -> -0.053246628 | AC13: =Q13-W13 -> 0.0073074798
A14: 0.8 | B14: 0.12 | C14: 4.712 | D14: =PI()/2 -> 1.5707963 | E14: 0.7 | F14: 0.02 | G14: 3.142 | H14: =PI()/2 -> 1.5707963 | I14: 0 | J14: 0 | K14: 0 | L14: -0.0012127757 | M14: 0.18917631 | N14: -0.080510885 | O14: -0.25100401 | P14: -0.70138603 | Q14: -0.86990654 | R14: -4.0541496e-11 | S14: 0.16506378 | T14: -0.076550233 | U14: -0.20130329 | V14: -0.69944974 | W14: -0.77520021 | X14: =L14-R14 -> -0.0012127757 | Y14: =M14-S14 -> 0.024112527 | Z14: =N14-T14 -> -0.003960651 | AA14: =O14-U14 -> -0.049700716 | AB14: =P14-V14 -> -0.0019362958 | AC14: =Q14-W14 -> -0.094706338
... A17: 0.7 | B17: 0.2 | C17: 4.712 | D17: =PI()/2 -> 1.5707963 | E17: 0.3 | F17: 0.08 | G17: 3.142 | H17: =PI()/2 -> 1.5707963 | I17: 0 | J17: 0 | K17: 0 | L17: -0.0014520943 | M17: 0.15855817 | N17: -0.046406556 | O17: -0.53051335 | P17: -0.2509959 | Q17: -0.37296328 | R17: -1.2322467e-10 | S17: 0.1707873 | T17: -0.049180873 | U17: -0.50274448 | V17: -0.28437686 | W17: -0.4964949 | X17: =L17-R17 -> -0.0014520942 | Y17: =M17-S17 -> -0.012229129 | Z17: =N17-T17 -> 0.0027743169 | AA17: =O17-U17 -> -0.027768865 | AB17: =P17-V17 -> 0.03338096 | AC17: =Q17-W17 -> 0.12353162

Sheet Distal Validation (no perturb)
A1: Ground Truth | L1: 6-Axis FT Sensor | R1: SoRoSim get_distal_value | AA1: Distal Errors | AI1: Stats
A2: F1 (N) | B2: s1 (m) | C2: el1 (rad) | D2: az1 (rad) | E2: F2 (N) | F2: s2 (m) | G2: el2 (rad) | H2: az2 (rad) | I2: tau1 (N) | J2: tau2 (N) | K2: tau3 (N) | L2: Tx (Nm) | M2: Ty (Nm) | N2: Tz(Nm) | O2: Fx (N) | P2: Fy (N) | Q2: Fz (N) | R2: F1 (N) | S2: s1 (m) | T2: el1 (rad) | U2: az1 (rad) | V2: F2 (N) | W2: s2 (m) | X2: el2 (rad) | Y2: az2 (rad) | Z2: f_final | AA2: F1 (N) | AB2: s1 (m) | AC2: el1 (rad) | AD2: az1 (rad) | AE2: F2 (N) | AF2: s2 (m) | AG2: el2 (rad) | AH2: az2 (rad) | AI2: force_error | AJ2: position_error | AK2: angle_error | AL2: Absolute Mean Error
A3: ='Proximal Validation'!A3 -> 0.5 | B3: ='Proximal Validation'!B3 -> 0.12 | C3: ='Proximal Validation'!C3 -> 1.57 | D3: ='Proximal Validation'!D3 -> 1.5707963 | E3: ='Proximal Validation'!E3 -> 0.3 | F3: ='Proximal Validation'!F3 -> 0.02 | G3: ='Proximal Validation'!G3 -> 3.142 | H3: ='Proximal Validation'!H3 -> 1.5707963 | ... Q3: ='Proximal Validation'!Q3 -> 0.41270199 | R3: 0.75348612 | S3: 0.089198917 | T3: 1.598588 | U3: 1.5707963 | V3: 0.4258619 | W3: 0.023589396 | X3: 4.0469513 | Y3: 1.5707963 | Z3: 5.7404209e-09 | AA3: =R3-A3 -> 0.25348612 | AB3: =S3-B3 -> -0.030801083 | AC3: =T3-C3 -> 0.028588026 | AD3: =U3-D3 -> 0 | AE3: =V3-E3 -> 0.1258619 | AF3: =W3-F3 -> 0.0035893962 | AG3: =X3-G3 -> 0.90495125 | AH3: =Y3-H3 -> 0 | AI3: =AVERAGE(ABS(AA3),ABS(AE3)) -> 0.18967401 | AJ3: =AVERAGE(ABS(AB3),ABS(AF3)) -> 0.01719524 | AK3: =AVERAGE(ABS(AC3),ABS(AG3)) -> 0.46676964 | AL3: F1 (N) | AM3: s1 (m) | AN3: el1 (rad) | AO3: az1 (rad) | AP3: F2 (N) | AQ3: s2 (m) | AR3: el2 (rad) | AS3: az2 (rad)
A4: ='Proximal Validation'!A4 -> 0.5 | B4: ='Proximal Validation'!B4 -> 0.12 | C4: ='Proximal Validation'!C4 -> 1.57 | D4: ='Proximal Validation'!D4 -> 1.5707963 | E4: ='Proximal Validation'!E4 -> 0.7 | F4: ='Proximal Validation'!F4 -> 0.06 | G4: ='Proximal Validation'!G4 -> 4.712 | H4: ='Proximal Validation'!H4 -> 1.5707963 | ... Q4: ='Proximal Validation'!Q4 -> -0.19096869 | R4: 0.61501211 | S4: 0.07385411 | T4: 1.637027 | U4: 1.5707963 | V4: 0.80438642 | W4: 0.028884891 | X4: 4.7586045 | Y4: 1.5707963 | Z4: 1.4900725e-07 | AA4: =R4-A4 -> 0.11501211 | AB4: =S4-B4 -> -0.04614589 | AC4: =T4-C4 -> 0.067027038 | AD4: =U4-D4 -> 0 | AE4: =V4-E4 -> 0.10438642 | AF4: =W4-F4 -> -0.031115109 | AG4: =X4-G4 -> 0.046604508 | AH4: =Y4-H4 -> 0 | AI4: =AVERAGE(ABS(AA4),ABS(AE4)) -> 0.10969926 | AJ4: =AVERAGE(ABS(AB4),ABS(AF4)) -> 0.038630499 | AK4: =AVERAGE(ABS(AC4),ABS(AG4)) -> 0.056815773 | AL4: {=AVERAGE(ABS(AA3:AA17))} -> 0.20415322 | AM4: {=AVERAGE(ABS(AB3:AB17))} -> 0.027095626 | AN4: {=AVERAGE(ABS(AC3:AC17))} -> 0.19243522 | AO4: {=AVERAGE(ABS(AD3:AD17))} -> 0 | AP4: {=AVERAGE(ABS(AE3:AE17))} -> 0.12485516 | AQ4: {=AVERAGE(ABS(AF3:AF17))} -> 0.024544252 | AR4: {=AVERAGE(ABS(AG3:AG17))} -> 0.48429377 | AS4: {=AVERAGE(ABS(AH3:AH17))} -> 0
A5: ='Proximal Validation'!A5 -> 0.8 | B5: ='Proximal Validation'!B5 -> 0.18 | C5: ='Proximal Validation'!C5 -> 1.57 | D5: ='Proximal Validation'!D5 -> 1.5707963 | E5: ='Proximal Validation'!E5 -> 0.4 | F5: ='Proximal Validation'!F5 -> 0.08 | G5: ='Proximal Validation'!G5 -> 4.712 | H5: ='Proximal Validation'!H5 -> 1.5707963 | ... Q5: ='Proximal Validation'!Q5 -> 0.28356427 | R5: 0.80192803 | S5: 0.17603228 | T5: 1.6027353 | U5: 1.5707963 | V5: 0.3501702 | W5: 0.040320914 | X5: 4.7766013 | Y5: 1.5707963 | Z5: 9.5545539e-10 | AA5: =R5-A5 -> 0.0019280299 | AB5: =S5-B5 -> -0.0039677168 | AC5: =T5-C5 -> 0.032735286 | AD5: =U5-D5 -> 0 | AE5: =V5-E5 -> -0.049829804 | AF5: =W5-F5 -> -0.039679086 | AG5: =X5-G5 -> 0.064601255 | AH5: =Y5-H5 -> 0 | AI5: =AVERAGE(ABS(AA5),ABS(AE5)) -> 0.025878917 | AJ5: =AVERAGE(ABS(AB5),ABS(AF5)) -> 0.021823401 | AK5: =AVERAGE(ABS(AC5),ABS(AG5)) -> 0.048668271 | AL5: Absolute Mean Error (Across Both Forces)
A6: ='Proximal Validation'!A6 -> 0.3 | B6: ='Proximal Validation'!B6 -> 0.2 | C6: ='Proximal Validation'!C6 -> 1.57 | D6: ='Proximal Validation'!D6 -> 1.5707963 | E6: ='Proximal Validation'!E6 -> 0.7 | F6: ='Proximal Validation'!F6 -> 0.04 | G6: ='Proximal Validation'!G6 -> 3.142 | H6: ='Proximal Validation'!H6 -> 1.5707963 | ... Q6: ='Proximal Validation'!Q6 -> 0.13295281 | R6: 0.42046697 | S6: 0.14460776 | T6: 1.8162797 | U6: 1.5707963 | V6: 0.63046312 | W6: 0.027212857 | X6: 3.576137 | Y6: 1.5707963 | Z6: 6.6253941e-10 | AA6: =R6-A6 -> 0.12046697 | AB6: =S6-B6 -> -0.055392245 | AC6: =T6-C6 -> 0.24627974 | AD6: =U6-D6 -> 0 | AE6: =V6-E6 -> -0.069536877 | AF6: =W6-F6 -> -0.012787143 | AG6: =X6-G6 -> 0.43413696 | AH6: =Y6-H6 -> 0 | AI6: =AVERAGE(ABS(AA6),ABS(AE6)) -> 0.095001925 | AJ6: =AVERAGE(ABS(AB6),ABS(AF6)) -> 0.034089694 | AK6: =AVERAGE(ABS(AC6),ABS(AG6)) -> 0.34020835 | AL6: force_error | AM6: position_error | AN6: angle_error
A7: ='Proximal Validation'!A7 -> 0.3 | B7: ='Proximal Validation'!B7 -> 0.1 | C7: ='Proximal Validation'!C7 -> 3.142 | D7: ='Proximal Validation'!D7 -> 1.5707963 | E7: ='Proximal Validation'!E7 -> 0.8 | F7: ='Proximal Validation'!F7 -> 0.08 | G7: ='Proximal Validation'!G7 -> 3.927 | H7: ='Proximal Validation'!H7 -> 1.5707963 | ... Q7: ='Proximal Validation'!Q7 -> -0.48219949 | R7: 0.60707541 | S7: 0.091008946 | T7: 2.9864979 | U7: 1.5707963 | V7: 0.66197407 | W7: 0.086409605 | X7: 4.2357289 | Y7: 1.5707963 | Z7: 5.2607573e-06 | AA7: =R7-A7 -> 0.30707541 | AB7: =S7-B7 -> -0.0089910539 | AC7: =T7-C7 -> -0.15550212 | AD7: =U7-D7 -> 0 | AE7: =V7-E7 -> -0.13802593 | AF7: =W7-F7 -> 0.0064096051 | AG7: =X7-G7 -> 0.30872893 | AH7: =Y7-H7 -> 0 | AI7: =AVERAGE(ABS(AA7),ABS(AE7)) -> 0.22255067 | AJ7: =AVERAGE(ABS(AB7),ABS(AF7)) -> 0.0077003295 | AK7: =AVERAGE(ABS(AC7),ABS(AG7)) -> 0.23211552 | AL7: =AVERAGE(AL4,AP4) -> 0.16450419 | AM7: =AVERAGE(AM4,AQ4) -> 0.025819939 | AN7: =AVERAGE(AN4,AR4) -> 0.33836449
A8: ='Proximal Validation'!A8 -> 0.7 | B8: ='Proximal Validation'!B8 -> 0.1 | C8: ='Proximal Validation'!C8 -> 3.142 | D8: ='Proximal Validation'!D8 -> 1.5707963 | E8: ='Proximal Validation'!E8 -> 0.4 | F8: ='Proximal Validation'!F8 -> 0.04 | G8: ='Proximal Validation'!G8 -> 3.927 | H8: ='Proximal Validation'!H8 -> 1.5707963 | ... Q8: ='Proximal Validation'!Q8 -> -0.2222923 | R8: 0.15312984 | S8: 0.15881284 | T8: 2.6353327 | U8: 1.5707963 | V8: 0.99998512 | W8: 0.08056207 | X8: 3.4427387 | Y8: 1.5707963 | Z8: 1.9521376e-07 | AA8: =R8-A8 -> -0.54687016 | AB8: =S8-B8 -> 0.058812841 | AC8: =T8-C8 -> -0.50666735 | AD8: =U8-D8 -> 0 | AE8: =V8-E8 -> 0.59998512 | AF8: =W8-F8 -> 0.04056207 | AG8: =X8-G8 -> -0.48426126 | AH8: =Y8-H8 -> 0 | AI8: =AVERAGE(ABS(AA8),ABS(AE8)) -> 0.57342764 | AJ8: =AVERAGE(ABS(AB8),ABS(AF8)) -> 0.049687455 | AK8: =AVERAGE(ABS(AC8),ABS(AG8)) -> 0.4954643
A9: ='Proximal Validation'!A9 -> 0.5 | B9: ='Proximal Validation'!B9 -> 0.14 | C9: ='Proximal Validation'!C9 -> 3.142 | D9: ='Proximal Validation'!D9 -> 1.5707963 | E9: ='Proximal Validation'!E9 -> 0.7 | F9: ='Proximal Validation'!F9 -> 0.08 | G9: ='Proximal Validation'!G9 -> 3.927 | H9: ='Proximal Validation'!H9 -> 1.5707963 | ... Q9: ='Proximal Validation'!Q9 -> -0.38067478 | R9: 0.59153808 | S9: 0.13314791 | T9: 2.9154405 | U9: 1.5707963 | V9: 0.68888685 | W9: 0.10293203 | X9: 4.0087739 | Y9: 1.5707963 | Z9: 1.0436399e-08 | AA9: =R9-A9 -> 0.091538082 | AB9: =S9-B9 -> -0.0068520935 | AC9: =T9-C9 -> -0.22655947 | AD9: =U9-D9 -> 0 | AE9: =V9-E9 -> -0.011113152 | AF9: =W9-F9 -> 0.022932029 | AG9: =X9-G9 -> 0.081773904 | AH9: =Y9-H9 -> 0 | AI9: =AVERAGE(ABS(AA9),ABS(AE9)) -> 0.051325617 | AJ9: =AVERAGE(ABS(AB9),ABS(AF9)) -> 0.014892061 | AK9: =AVERAGE(ABS(AC9),ABS(AG9)) -> 0.15416669
A10: ='Proximal Validation'!A10 -> 0.7 | B10: ='Proximal Validation'!B10 -> 0.14 | C10: ='Proximal Validation'!C10 -> 3.142 | D10: ='Proximal Validation'!D10 -> 1.5707963 | E10: ='Proximal Validation'!E10 -> 0.5 | F10: ='Proximal Validation'!F10 -> 0.06 | G10: ='Proximal Validation'!G10 -> 3.927 | H10: ='Proximal Validation'!H10 -> 1.5707963 | ... Q10: ='Proximal Validation'!Q10 -> -0.29647687 | R10: 0.77150887 | S10: 0.13141799 | T10: 2.8261691 | U10: 1.5707963 | V10: 0.63741601 | W10: 0.099296152 | X10: 4.154485 | Y10: 1.5707963 | Z10: 3.8361133e-07 | AA10: =R10-A10 -> 0.071508867 | AB10: =S10-B10 -> -0.0085820055 | AC10: =T10-C10 -> -0.31583088 | AD10: =U10-D10 -> 0 | AE10: =V10-E10 -> 0.13741601 | AF10: =W10-F10 -> 0.039296152 | AG10: =X10-G10 -> 0.22748496 | AH10: =Y10-H10 -> 0 | AI10: =AVERAGE(ABS(AA10),ABS(AE10)) -> 0.10446244 | AJ10: =AVERAGE(ABS(AB10),ABS(AF10)) -> 0.023939079 | AK10: =AVERAGE(ABS(AC10),ABS(AG10)) -> 0.27165792
A11: ='Proximal Validation'!A11 -> 0.4 | B11: ='Proximal Validation'!B11 -> 0.18 | C11: ='Proximal Validation'!C11 -> 3.142 | D11: ='Proximal Validation'!D11 -> 1.5707963 | E11: ='Proximal Validation'!E11 -> 0.4 | F11: ='Proximal Validation'!F11 -> 0.02 | G11: ='Proximal Validation'!G11 -> 3.927 | H11: ='Proximal Validation'!H11 -> 1.5707963 | ... Q11: ='Proximal Validation'!Q11 -> -0.2340374 | R11: 0.26411481 | S11: 0.18202031 | T11: 2.4192451 | U11: 1.5707963 | V11: 0.59373936 | W11: 0.093598742 | X11: 3.8958881 | Y11: 1.5707963 | Z11: 5.2798408e-09 | AA11: =R11-A11 -> -0.13588519 | AB11: =S11-B11 -> 0.0020203122 | AC11: =T11-C11 -> -0.72275485 | AD11: =U11-D11 -> 0 | AE11: =V11-E11 -> 0.19373936 | AF11: =W11-F11 -> 0.073598742 | AG11: =X11-G11 -> -0.031111883 | AH11: =Y11-H11 -> 0 | AI11: =AVERAGE(ABS(AA11),ABS(AE11)) -> 0.16481227 | AJ11: =AVERAGE(ABS(AB11),ABS(AF11)) -> 0.037809527 | AK11: =AVERAGE(ABS(AC11),ABS(AG11)) -> 0.37693337
A12: ='Proximal Validation'!A12 -> 0.7 | B12: ='Proximal Validation'!B12 -> 0.18 | C12: ='Proximal Validation'!C12 -> 3.142 | D12: ='Proximal Validation'!D12 -> 1.5707963 | E12: ='Proximal Validation'!E12 -> 0.8 | F12: ='Proximal Validation'!F12 -> 0.04 | G12: ='Proximal Validation'!G12 -> 3.927 | H12: ='Proximal Validation'!H12 -> 1.5707963 | ... Q12: ='Proximal Validation'!Q12 -> -0.46333063 | R12: 0.74443735 | S12: 0.16739676 | T12: 2.9054994 | U12: 1.5707963 | V12: 0.86835712 | W12: 0.082162012 | X12: 3.9663756 | Y12: 1.5707963 | Z12: 1.7358186e-07 | AA12: =R12-A12 -> 0.04443735 | AB12: =S12-B12 -> -0.012603239 | AC12: =T12-C12 -> -0.23650063 | AD12: =U12-D12 -> 0 | AE12: =V12-E12 -> 0.068357123 | AF12: =W12-F12 -> 0.042162012 | AG12: =X12-G12 -> 0.039375565 | AH12: =Y12-H12 -> 0 | AI12: =AVERAGE(ABS(AA12),ABS(AE12)) -> 0.056397236 | AJ12: =AVERAGE(ABS(AB12),ABS(AF12)) -> 0.027382626 | AK12: =AVERAGE(ABS(AC12),ABS(AG12)) -> 0.1379381
A13: ='Proximal Validation'!A13 -> 0.3 | B13: ='Proximal Validation'!B13 -> 0.12 | C13: ='Proximal Validation'!C13 -> 4.712 | D13: ='Proximal Validation'!D13 -> 1.5707963 | E13: ='Proximal Validation'!E13 -> 0.3 | F13: ='Proximal Validation'!F13 -> 0.04 | G13: ='Proximal Validation'!G13 -> 4.712 | H13: ='Proximal Validation'!H13 -> 1.5707963 | ... Q13: ='Proximal Validation'!Q13 -> -0.59106356 | R13: 0.85056816 | S13: 0.077557827 | T13: 4.7205625 | U13: 1.5707963 | V13: 0.26360679 | W13: 0.054148219 | X13: 1.8021128 | Y13: 1.5707963 | Z13: 3.7672501e-08 | AA13: =R13-A13 -> 0.55056816 | AB13: =S13-B13 -> -0.042442173 | AC13: =T13-C13 -> 0.0085624614 | AD13: =U13-D13 -> 0 | AE13: =V13-E13 -> -0.036393206 | AF13: =W13-F13 -> 0.014148219 | AG13: =X13-G13 -> -2.9098872 | AH13: =Y13-H13 -> 0 | AI13: =AVERAGE(ABS(AA13),ABS(AE13)) -> 0.29348068 | AJ13: =AVERAGE(ABS(AB13),ABS(AF13)) -> 0.028295196 | AK13: =AVERAGE(ABS(AC13),ABS(AG13)) -> 1.4592249
A14: ='Proximal Validation'!A14 -> 0.8 | B14: ='Proximal Validation'!B14 -> 0.12 | C14: ='Proximal Validation'!C14 -> 4.712 | D14: ='Proximal Validation'!D14 -> 1.5707963 | E14: ='Proximal Validation'!E14 -> 0.7 | F14: ='Proximal Validation'!F14 -> 0.02 | G14: ='Proximal Validation'!G14 -> 3.142 | H14: ='Proximal Validation'!H14 -> 1.5707963 | ... Q14: ='Proximal Validation'!Q14 -> -0.86990654 | R14: 0.96313294 | S14: 0.1157346 | T14: 4.6718823 | U14: 1.5707963 | V14: 0.66503572 | W14: 0.020203519 | X14: 3.067349 | Y14: 1.5707963 | Z14: 5.8574947e-07 | AA14: =R14-A14 -> 0.16313294 | AB14: =S14-B14 -> -0.0042654 | AC14: =T14-C14 -> -0.040117706 | AD14: =U14-D14 -> 0 | AE14: =V14-E14 -> -0.034964276 | AF14: =W14-F14 -> 0.00020351925 | AG14: =X14-G14 -> -0.07465104 | AH14: =Y14-H14 -> 0 | AI14: =AVERAGE(ABS(AA14),ABS(AE14)) -> 0.099048609 | AJ14: =AVERAGE(ABS(AB14),ABS(AF14)) -> 0.0022344596 | AK14: =AVERAGE(ABS(AC14),ABS(AG14)) -> 0.057384373
A15: ='Proximal Validation'!A15 -> 0.4 | B15: ='Proximal Validation'!B15 -> 0.18 | C15: ='Proximal Validation'!C15 -> 4.712 | D15: ='Proximal Validation'!D15 -> 1.5707963 | E15: ='Proximal Validation'!E15 -> 0.5 | F15: ='Proximal Validation'!F15 -> 0.06 | G15: ='Proximal Validation'!G15 -> 3.142 | H15: ='Proximal Validation'!H15 -> 1.5707963 | ... Q15: ='Proximal Validation'!Q15 -> -0.37272522 | R15: 0.79908971 | S15: 0.10679226 | T15: 4.463987 | U15: 1.5707963 | V15: 0.49357079 | W15: 0.029187507 | X15: 2.2319727 | Y15: 1.5707963 | Z15: 3.044195e-08 | AA15: =R15-A15 -> 0.39908971 | AB15: =S15-B15 -> -0.073207744 | AC15: =T15-C15 -> -0.24801302 | AD15: =U15-D15 -> 0 | AE15: =V15-E15 -> -0.0064292127 | AF15: =W15-F15 -> -0.030812493 | AG15: =X15-G15 -> -0.91002735 | AH15: =Y15-H15 -> 0 | AI15: =AVERAGE(ABS(AA15),ABS(AE15)) -> 0.20275946 | AJ15: =AVERAGE(ABS(AB15),ABS(AF15)) -> 0.052010118 | AK15: =AVERAGE(ABS(AC15),ABS(AG15)) -> 0.57902018
A16: ='Proximal Validation'!A16 -> 0.5 | B16: ='Proximal Validation'!B16 -> 0.2 | C16: ='Proximal Validation'!C16 -> 4.712 | D16: ='Proximal Validation'!D16 -> 1.5707963 | E16: ='Proximal Validation'!E16 -> 0.7 | F16: ='Proximal Validation'!F16 -> 0.02 | G16: ='Proximal Validation'!G16 -> 4.712 | H16: ='Proximal Validation'!H16 -> 1.5707963 | ... Q16: ='Proximal Validation'!Q16 -> -1.0507474 | R16: 0.61153018 | S16: 0.15908245 | T16: 4.6633997 | U16: 1.5707963 | V16: 0.45827335 | W16: 0.02 | X16: 4.6784401 | Y16: 1.5707963 | Z16: 1.3411289e-06 | AA16: =R16-A16 -> 0.11153018 | AB16: =S16-B16 -> -0.040917553 | AC16: =T16-C16 -> -0.048600276 | AD16: =U16-D16 -> 0 | AE16: =V16-E16 -> -0.24172665 | AF16: =W16-F16 -> 2.7543731e-12 | AG16: =X16-G16 -> -0.033559924 | AH16: =Y16-H16 -> 0 | AI16: =AVERAGE(ABS(AA16),ABS(AE16)) -> 0.17662842 | AJ16: =AVERAGE(ABS(AB16),ABS(AF16)) -> 0.020458776 | AK16: =AVERAGE(ABS(AC16),ABS(AG16)) -> 0.0410801
A17: ='Proximal Validation'!A17 -> 0.7 | B17: ='Proximal Validation'!B17 -> 0.2 | C17: ='Proximal Validation'!C17 -> 4.712 | D17: ='Proximal Validation'!D17 -> 1.5707963 | E17: ='Proximal Validation'!E17 -> 0.3 | F17: ='Proximal Validation'!F17 -> 0.08 | G17: ='Proximal Validation'!G17 -> 3.142 | H17: ='Proximal Validation'!H17 -> 1.5707963 | ... Q17: ='Proximal Validation'!Q17 -> -0.37296328 | R17: 0.84976901 | S17: 0.18856696 | T17: 4.7092106 | U17: 1.5707963 | V17: 0.35506231 | W17: 0.090868204 | X17: 2.4287494 | Y17: 1.5707963 | Z17: 4.6937917e-08 | AA17: =R17-A17 -> 0.14976901 | AB17: =S17-B17 -> -0.011433039 | AC17: =T17-C17 -> -0.0027893844 | AD17: =U17-D17 -> 0 | AE17: =V17-E17 -> 0.05506231 | AF17: =W17-F17 -> 0.010868204 | AG17: =X17-G17 -> -0.71325057 | AH17: =Y17-H17 -> 0 | AI17: =AVERAGE(ABS(AA17),ABS(AE17)) -> 0.10241566 | AJ17: =AVERAGE(ABS(AB17),ABS(AF17)) -> 0.011150622 | AK17: =AVERAGE(ABS(AC17),ABS(AG17)) -> 0.35801998

Sheet Distal Vali (0.6N perturb)
A1: Ground Truth | L1: 6-Axis FT Sensor | R1: SoRoSim get_distal_value | AA1: Distal Errors | AI1: Stats
A2: F1 (N) | B2: s1 (m) | C2: el1 (rad) | D2: az1 (rad) | E2: F2 (N) | F2: s2 (m) | G2: el2 (rad) | H2: az2 (rad) | I2: tau1 (N) | J2: tau2 (N) | K2: tau3 (N) | L2: Tx (Nm) | M2: Ty (Nm) | N2: Tz(Nm) | O2: Fx (N) | P2: Fy (N) | Q2: Fz (N) | R2: F1 (N) | S2: s1 (m) | T2: el1 (rad) | U2: az1 (rad) | V2: F2 (N) | W2: s2 (m) | X2: el2 (rad) | Y2: az2 (rad) | Z2: f_final | AA2: F1 (N) | AB2: s1 (m) | AC2: el1 (rad) | AD2: az1 (rad) | AE2: F2 (N) | AF2: s2 (m) | AG2: el2 (rad) | AH2: az2 (rad) | AI2: force_error | AJ2: position_error | AK2: angle_error | AL2: Absolute Mean Error
A3: ='Proximal Validation'!A3 -> 0.5 | B3: ='Proximal Validation'!B3 -> 0.12 | C3: ='Proximal Validation'!C3 -> 1.57 | D3: ='Proximal Validation'!D3 -> 1.5707963 | E3: ='Proximal Validation'!E3 -> 0.3 | F3: ='Proximal Validation'!F3 -> 0.02 | G3: ='Proximal Validation'!G3 -> 3.142 | H3: ='Proximal Validation'!H3 -> 1.5707963 | ... Q3: ='Proximal Validation'!Q3 -> 0.41270199 | R3: 0.46494919 | S3: 0.12939585 | T3: 1.6190715 | U3: 1.5707963 | V3: 0.26409831 | W3: 0.020009488 | X3: 3.3050219 | Y3: 1.5707963 | Z3: 5.5579084e-06 | AA3: =R3-A3 -> -0.035050806 | AB3: =S3-B3 -> 0.0093958493 | AC3: =T3-C3 -> 0.049071508 | AD3: =U3-D3 -> 0 | AE3: =V3-E3 -> -0.035901688 | AF3: =W3-F3 -> 9.4877074e-06 | AG3: =X3-G3 -> 0.16302187 | AH3: =Y3-H3 -> 0 | AI3: =AVERAGE(ABS(AA3),ABS(AE3)) -> 0.035476247 | AJ3: =AVERAGE(ABS(AB3),ABS(AF3)) -> 0.0047026685 | AK3: =AVERAGE(ABS(AC3),ABS(AG3)) -> 0.10604669 | AL3: F1 (N) | AM3: s1 (m) | AN3: el1 (rad) | AO3: az1 (rad) | AP3: F2 (N) | AQ3: s2 (m) | AR3: el2 (rad) | AS3: az2 (rad)
A4: ='Proximal Validation'!A4 -> 0.5 | B4: ='Proximal Validation'!B4 -> 0.12 | C4: ='Proximal Validation'!C4 -> 1.57 | D4: ='Proximal Validation'!D4 -> 1.5707963 | E4: ='Proximal Validation'!E4 -> 0.7 | F4: ='Proximal Validation'!F4 -> 0.06 | G4: ='Proximal Validation'!G4 -> 4.712 | H4: ='Proximal Validation'!H4 -> 1.5707963 | ... Q4: ='Proximal Validation'!Q4 -> -0.19096869 | R4: 0.45295587 | S4: 0.083362563 | T4: 1.5780253 | U4: 1.5707963 | V4: 0.64275082 | W4: 0.024290449 | X4: 4.6985017 | Y4: 1.5707963 | Z4: 3.748656e-06 | AA4: =R4-A4 -> -0.047044131 | AB4: =S4-B4 -> -0.036637437 | AC4: =T4-C4 -> 0.0080252517 | AD4: =U4-D4 -> 0 | AE4: =V4-E4 -> -0.057249178 | AF4: =W4-F4 -> -0.035709551 | AG4: =X4-G4 -> -0.013498327 | AH4: =Y4-H4 -> 0 | AI4: =AVERAGE(ABS(AA4),ABS(AE4)) -> 0.052146655 | AJ4: =AVERAGE(ABS(AB4),ABS(AF4)) -> 0.036173494 | AK4: =AVERAGE(ABS(AC4),ABS(AG4)) -> 0.010761789 | AL4: {=AVERAGE(ABS(AA3:AA17))} -> 0.10875582 | AM4: {=AVERAGE(ABS(AB3:AB17))} -> 0.01240881 | AN4: {=AVERAGE(ABS(AC3:AC17))} -> 0.26855322 | AO4: {=AVERAGE(ABS(AD3:AD17))} -> 0 | AP4: {=AVERAGE(ABS(AE3:AE17))} -> 0.15177723 | AQ4: {=AVERAGE(ABS(AF3:AF17))} -> 0.015460665 | AR4: {=AVERAGE(ABS(AG3:AG17))} -> 0.11680569 | AS4: {=AVERAGE(ABS(AH3:AH17))} -> 0
A5: ='Proximal Validation'!A5 -> 0.8 | B5: ='Proximal Validation'!B5 -> 0.18 | C5: ='Proximal Validation'!C5 -> 1.57 | D5: ='Proximal Validation'!D5 -> 1.5707963 | E5: ='Proximal Validation'!E5 -> 0.4 | F5: ='Proximal Validation'!F5 -> 0.08 | G5: ='Proximal Validation'!G5 -> 4.712 | H5: ='Proximal Validation'!H5 -> 1.5707963 | ... Q5: ='Proximal Validation'!Q5 -> 0.28356427 | R5: 0.94551213 | S5: 0.17370533 | T5: 1.6005352 | U5: 1.5707963 | V5: 0.45037435 | W5: 0.0814599 | X5: 4.7635013 | Y5: 1.5707963 | Z5: 1.8978163e-05 | AA5: =R5-A5 -> 0.14551213 | AB5: =S5-B5 -> -0.0062946654 | AC5: =T5-C5 -> 0.030535196 | AD5: =U5-D5 -> 0 | AE5: =V5-E5 -> 0.050374348 | AF5: =W5-F5 -> 0.0014598995 | AG5: =X5-G5 -> 0.051501254 | AH5: =Y5-H5 -> 0 | AI5: =AVERAGE(ABS(AA5),ABS(AE5)) -> 0.097943238 | AJ5: =AVERAGE(ABS(AB5),ABS(AF5)) -> 0.0038772825 | AK5: =AVERAGE(ABS(AC5),ABS(AG5)) -> 0.041018225 | AL5: Absolute Mean Error (Across Both Forces)
A6: ='Proximal Validation'!A6 -> 0.3 | B6: ='Proximal Validation'!B6 -> 0.2 | C6: ='Proximal Validation'!C6 -> 1.57 | D6: ='Proximal Validation'!D6 -> 1.5707963 | E6: ='Proximal Validation'!E6 -> 0.7 | F6: ='Proximal Validation'!F6 -> 0.04 | G6: ='Proximal Validation'!G6 -> 3.142 | H6: ='Proximal Validation'!H6 -> 1.5707963 | ... Q6: ='Proximal Validation'!Q6 -> 0.13295281 | R6: 0.30138395 | S6: 0.1970567 | T6: 1.4640147 | U6: 1.5707963 | V6: 0.7182483 | W6: 0.051420659 | X6: 3.3402764 | Y6: 1.5707963 | Z6: 6.9264733e-06 | AA6: =R6-A6 -> 0.0013839521 | AB6: =S6-B6 -> -0.0029432959 | AC6: =T6-C6 -> -0.10598531 | AD6: =U6-D6 -> 0 | AE6: =V6-E6 -> 0.018248299 | AF6: =W6-F6 -> 0.011420659 | AG6: =X6-G6 -> 0.19827639 | AH6: =Y6-H6 -> 0 | AI6: =AVERAGE(ABS(AA6),ABS(AE6)) -> 0.0098161254 | AJ6: =AVERAGE(ABS(AB6),ABS(AF6)) -> 0.0071819775 | AK6: =AVERAGE(ABS(AC6),ABS(AG6)) -> 0.15213085 | AL6: force_error | AM6: position_error | AN6: angle_error
A7: ='Proximal Validation'!A7 -> 0.3 | B7: ='Proximal Validation'!B7 -> 0.1 | C7: ='Proximal Validation'!C7 -> 3.142 | D7: ='Proximal Validation'!D7 -> 1.5707963 | E7: ='Proximal Validation'!E7 -> 0.8 | F7: ='Proximal Validation'!F7 -> 0.08 | G7: ='Proximal Validation'!G7 -> 3.927 | H7: ='Proximal Validation'!H7 -> 1.5707963 | ... Q7: ='Proximal Validation'!Q7 -> -0.48219949 | R7: 0.52289293 | S7: 0.096838081 | T7: 3.4082519 | U7: 1.5707963 | V7: 0.53361402 | W7: 0.081257673 | X7: 3.8731406 | Y7: 1.5707963 | Z7: 6.1657187e-06 | AA7: =R7-A7 -> 0.22289293 | AB7: =S7-B7 -> -0.0031619194 | AC7: =T7-C7 -> 0.26625188 | AD7: =U7-D7 -> 0 | AE7: =V7-E7 -> -0.26638598 | AF7: =W7-F7 -> 0.0012576735 | AG7: =X7-G7 -> -0.053859431 | AH7: =Y7-H7 -> 0 | AI7: =AVERAGE(ABS(AA7),ABS(AE7)) -> 0.24463946 | AJ7: =AVERAGE(ABS(AB7),ABS(AF7)) -> 0.0022097964 | AK7: =AVERAGE(ABS(AC7),ABS(AG7)) -> 0.16005566 | AL7: =AVERAGE(AL4,AP4) -> 0.13026653 | AM7: =AVERAGE(AM4,AQ4) -> 0.013934737 | AN7: =AVERAGE(AN4,AR4) -> 0.19267946
A8: ='Proximal Validation'!A8 -> 0.7 | B8: ='Proximal Validation'!B8 -> 0.1 | C8: ='Proximal Validation'!C8 -> 3.142 | D8: ='Proximal Validation'!D8 -> 1.5707963 | E8: ='Proximal Validation'!E8 -> 0.4 | F8: ='Proximal Validation'!F8 -> 0.04 | G8: ='Proximal Validation'!G8 -> 3.927 | H8: ='Proximal Validation'!H8 -> 1.5707963 | ... Q8: ='Proximal Validation'!Q8 -> -0.2222923 | R8: 0.22585847 | S8: 0.14652386 | T8: 2.8694938 | U8: 1.5707963 | V8: 0.91536177 | W8: 0.076147257 | X8: 3.453591 | Y8: 1.5707963 | Z8: 3.0325799e-06 | AA8: =R8-A8 -> -0.47414153 | AB8: =S8-B8 -> 0.046523858 | AC8: =T8-C8 -> -0.27250623 | AD8: =U8-D8 -> 0 | AE8: =V8-E8 -> 0.51536177 | AF8: =W8-F8 -> 0.036147257 | AG8: =X8-G8 -> -0.47340902 | AH8: =Y8-H8 -> 0 | AI8: =AVERAGE(ABS(AA8),ABS(AE8)) -> 0.49475165 | AJ8: =AVERAGE(ABS(AB8),ABS(AF8)) -> 0.041335557 | AK8: =AVERAGE(ABS(AC8),ABS(AG8)) -> 0.37295762
A9: ='Proximal Validation'!A9 -> 0.5 | B9: ='Proximal Validation'!B9 -> 0.14 | C9: ='Proximal Validation'!C9 -> 3.142 | D9: ='Proximal Validation'!D9 -> 1.5707963 | E9: ='Proximal Validation'!E9 -> 0.7 | F9: ='Proximal Validation'!F9 -> 0.08 | G9: ='Proximal Validation'!G9 -> 3.927 | H9: ='Proximal Validation'!H9 -> 1.5707963 | ... Q9: ='Proximal Validation'!Q9 -> -0.38067478 | R9: 0.58036382 | S9: 0.14532857 | T9: 3.2124008 | U9: 1.5707963 | V9: 0.56646971 | W9: 0.086797073 | X9: 3.811864 | Y9: 1.5707963 | Z9: 2.5724568e-06 | AA9: =R9-A9 -> 0.08036382 | AB9: =S9-B9 -> 0.0053285719 | AC9: =T9-C9 -> 0.070400846 | AD9: =U9-D9 -> 0 | AE9: =V9-E9 -> -0.13353029 | AF9: =W9-F9 -> 0.0067970733 | AG9: =X9-G9 -> -0.11513604 | AH9: =Y9-H9 -> 0 | AI9: =AVERAGE(ABS(AA9),ABS(AE9)) -> 0.10694705 | AJ9: =AVERAGE(ABS(AB9),ABS(AF9)) -> 0.0060628226 | AK9: =AVERAGE(ABS(AC9),ABS(AG9)) -> 0.092768442
A10: ='Proximal Validation'!A10 -> 0.7 | B10: ='Proximal Validation'!B10 -> 0.14 | C10: ='Proximal Validation'!C10 -> 3.142 | D10: ='Proximal Validation'!D10 -> 1.5707963 | E10: ='Proximal Validation'!E10 -> 0.5 | F10: ='Proximal Validation'!F10 -> 0.06 | G10: ='Proximal Validation'!G10 -> 3.927 | H10: ='Proximal Validation'!H10 -> 1.5707963 | ... Q10: ='Proximal Validation'!Q10 -> -0.29647687 | R10: 0.71638031 | S10: 0.14350432 | T10: 3.135817 | U10: 1.5707963 | V10: 0.46810314 | W10: 0.076234715 | X10: 3.8492953 | Y10: 1.5707963 | Z10: 5.0031203e-06 | AA10: =R10-A10 -> 0.01638031 | AB10: =S10-B10 -> 0.0035043196 | AC10: =T10-C10 -> -0.0061829582 | AD10: =U10-D10 -> 0 | AE10: =V10-E10 -> -0.031896856 | AF10: =W10-F10 -> 0.016234715 | AG10: =X10-G10 -> -0.077704739 | AH10: =Y10-H10 -> 0 | AI10: =AVERAGE(ABS(AA10),ABS(AE10)) -> 0.024138583 | AJ10: =AVERAGE(ABS(AB10),ABS(AF10)) -> 0.0098695174 | AK10: =AVERAGE(ABS(AC10),ABS(AG10)) -> 0.041943849
A11: ='Proximal Validation'!A11 -> 0.4 | B11: ='Proximal Validation'!B11 -> 0.18 | C11: ='Proximal Validation'!C11 -> 3.142 | D11: ='Proximal Validation'!D11 -> 1.5707963 | E11: ='Proximal Validation'!E11 -> 0.4 | F11: ='Proximal Validation'!F11 -> 0.02 | G11: ='Proximal Validation'!G11 -> 3.927 | H11: ='Proximal Validation'!H11 -> 1.5707963 | ... Q11: ='Proximal Validation'!Q11 -> -0.2340374 | R11: 0.39115139 | S11: 0.17848613 | T11: 3.1553352 | U11: 1.5707963 | V11: 0.33769169 | W11: 0.026753076 | X11: 3.8761624 | Y11: 1.5707963 | Z11: 3.0215967e-06 | AA11: =R11-A11 -> -0.0088486061 | AB11: =S11-B11 -> -0.0015138677 | AC11: =T11-C11 -> 0.013335233 | AD11: =U11-D11 -> 0 | AE11: =V11-E11 -> -0.06230831 | AF11: =W11-F11 -> 0.0067530758 | AG11: =X11-G11 -> -0.05083762 | AH11: =Y11-H11 -> 0 | AI11: =AVERAGE(ABS(AA11),ABS(AE11)) -> 0.035578458 | AJ11: =AVERAGE(ABS(AB11),ABS(AF11)) -> 0.0041334718 | AK11: =AVERAGE(ABS(AC11),ABS(AG11)) -> 0.032086426
A12: ='Proximal Validation'!A12 -> 0.7 | B12: ='Proximal Validation'!B12 -> 0.18 | C12: ='Proximal Validation'!C12 -> 3.142 | D12: ='Proximal Validation'!D12 -> 1.5707963 | E12: ='Proximal Validation'!E12 -> 0.8 | F12: ='Proximal Validation'!F12 -> 0.04 | G12: ='Proximal Validation'!G12 -> 3.927 | H12: ='Proximal Validation'!H12 -> 1.5707963 | ... Q12: ='Proximal Validation'!Q12 -> -0.46333063 | R12: 0.95500777 | S12: 0.16187131 | T12: 3.2004099 | U12: 1.5707963 | V12: 0.56929918 | W12: 0.038310976 | X12: 3.9543422 | Y12: 1.5707963 | Z12: 1.3946084e-05 | AA12: =R12-A12 -> 0.25500777 | AB12: =S12-B12 -> -0.018128687 | AC12: =T12-C12 -> 0.058409884 | AD12: =U12-D12 -> 0 | AE12: =V12-E12 -> -0.23070082 | AF12: =W12-F12 -> -0.0016890238 | AG12: =X12-G12 -> 0.027342155 | AH12: =Y12-H12 -> 0 | AI12: =AVERAGE(ABS(AA12),ABS(AE12)) -> 0.24285429 | AJ12: =AVERAGE(ABS(AB12),ABS(AF12)) -> 0.0099088552 | AK12: =AVERAGE(ABS(AC12),ABS(AG12)) -> 0.04287602
A13: ='Proximal Validation'!A13 -> 0.3 | B13: ='Proximal Validation'!B13 -> 0.12 | C13: ='Proximal Validation'!C13 -> 4.712 | D13: ='Proximal Validation'!D13 -> 1.5707963 | E13: ='Proximal Validation'!E13 -> 0.3 | F13: ='Proximal Validation'!F13 -> 0.04 | G13: ='Proximal Validation'!G13 -> 4.712 | H13: ='Proximal Validation'!H13 -> 1.5707963 | ... Q13: ='Proximal Validation'!Q13 -> -0.59106356 | R13: 0.22895453 | S13: 0.09242568 | T13: 1.9435176 | U13: 1.5707963 | V13: 0.80200267 | W13: 0.090845807 | X13: 4.7613997 | Y13: 1.5707963 | Z13: 4.5058826e-06 | AA13: =R13-A13 -> -0.071045467 | AB13: =S13-B13 -> -0.02757432 | AC13: =T13-C13 -> -2.7684824 | AD13: =U13-D13 -> 0 | AE13: =V13-E13 -> 0.50200267 | AF13: =W13-F13 -> 0.050845807 | AG13: =X13-G13 -> 0.049399727 | AH13: =Y13-H13 -> 0 | AI13: =AVERAGE(ABS(AA13),ABS(AE13)) -> 0.28652407 | AJ13: =AVERAGE(ABS(AB13),ABS(AF13)) -> 0.039210063 | AK13: =AVERAGE(ABS(AC13),ABS(AG13)) -> 1.4089411
A14: ='Proximal Validation'!A14 -> 0.8 | B14: ='Proximal Validation'!B14 -> 0.12 | C14: ='Proximal Validation'!C14 -> 4.712 | D14: ='Proximal Validation'!D14 -> 1.5707963 | E14: ='Proximal Validation'!E14 -> 0.7 | F14: ='Proximal Validation'!F14 -> 0.02 | G14: ='Proximal Validation'!G14 -> 3.142 | H14: ='Proximal Validation'!H14 -> 1.5707963 | ... Q14: ='Proximal Validation'!Q14 -> -0.86990654 | R14: 0.90114116 | S14: 0.1221237 | T14: 4.7879032 | U14: 1.5707963 | V14: 0.77076019 | W14: 0.03344219 | X14: 3.1657458 | Y14: 1.5707963 | Z14: 5.27219e-06 | AA14: =R14-A14 -> 0.10114116 | AB14: =S14-B14 -> 0.0021236985 | AC14: =T14-C14 -> 0.07590321 | AD14: =U14-D14 -> 0 | AE14: =V14-E14 -> 0.07076019 | AF14: =W14-F14 -> 0.01344219 | AG14: =X14-G14 -> 0.023745789 | AH14: =Y14-H14 -> 0 | AI14: =AVERAGE(ABS(AA14),ABS(AE14)) -> 0.085950673 | AJ14: =AVERAGE(ABS(AB14),ABS(AF14)) -> 0.0077829445 | AK14: =AVERAGE(ABS(AC14),ABS(AG14)) -> 0.049824499
A15: ='Proximal Validation'!A15 -> 0.4 | B15: ='Proximal Validation'!B15 -> 0.18 | C15: ='Proximal Validation'!C15 -> 4.712 | D15: ='Proximal Validation'!D15 -> 1.5707963 | E15: ='Proximal Validation'!E15 -> 0.5 | F15: ='Proximal Validation'!F15 -> 0.06 | G15: ='Proximal Validation'!G15 -> 3.142 | H15: ='Proximal Validation'!H15 -> 1.5707963 | ... Q15: ='Proximal Validation'!Q15 -> -0.37272522 | R15: 0.3902956 | S15: 0.17939658 | T15: 4.7752433 | U15: 1.5707963 | V15: 0.52073103 | W15: 0.066167146 | X15: 3.1652411 | Y15: 1.5707963 | Z15: 4.1341226e-06 | AA15: =R15-A15 -> -0.0097044002 | AB15: =S15-B15 -> -0.00060342088 | AC15: =T15-C15 -> 0.063243331 | AD15: =U15-D15 -> 0 | AE15: =V15-E15 -> 0.020731026 | AF15: =W15-F15 -> 0.0061671456 | AG15: =X15-G15 -> 0.023241139 | AH15: =Y15-H15 -> 0 | AI15: =AVERAGE(ABS(AA15),ABS(AE15)) -> 0.015217713 | AJ15: =AVERAGE(ABS(AB15),ABS(AF15)) -> 0.0033852833 | AK15: =AVERAGE(ABS(AC15),ABS(AG15)) -> 0.043242235
A16: ='Proximal Validation'!A16 -> 0.5 | B16: ='Proximal Validation'!B16 -> 0.2 | C16: ='Proximal Validation'!C16 -> 4.712 | D16: ='Proximal Validation'!D16 -> 1.5707963 | E16: ='Proximal Validation'!E16 -> 0.7 | F16: ='Proximal Validation'!F16 -> 0.02 | G16: ='Proximal Validation'!G16 -> 4.712 | H16: ='Proximal Validation'!H16 -> 1.5707963 | ... Q16: ='Proximal Validation'!Q16 -> -1.0507474 | R16: 0.53194927 | S16: 0.17760177 | T16: 4.6376371 | U16: 1.5707963 | V16: 0.55991927 | W16: 0.02 | X16: 4.7214666 | Y16: 1.5707963 | Z16: 1.8974768e-05 | AA16: =R16-A16 -> 0.03194927 | AB16: =S16-B16 -> -0.022398234 | AC16: =T16-C16 -> -0.074362862 | AD16: =U16-D16 -> 0 | AE16: =V16-E16 -> -0.14008073 | AF16: =W16-F16 -> 2.220446e-14 | AG16: =X16-G16 -> 0.0094665516 | AH16: =Y16-H16 -> 0 | AI16: =AVERAGE(ABS(AA16),ABS(AE16)) -> 0.086015 | AJ16: =AVERAGE(ABS(AB16),ABS(AF16)) -> 0.011199117 | AK16: =AVERAGE(ABS(AC16),ABS(AG16)) -> 0.041914707
A17: ='Proximal Validation'!A17 -> 0.7 | B17: ='Proximal Validation'!B17 -> 0.2 | C17: ='Proximal Validation'!C17 -> 4.712 | D17: ='Proximal Validation'!D17 -> 1.5707963 | E17: ='Proximal Validation'!E17 -> 0.3 | F17: ='Proximal Validation'!F17 -> 0.08 | G17: ='Proximal Validation'!G17 -> 3.142 | H17: ='Proximal Validation'!H17 -> 1.5707963 | ... Q17: ='Proximal Validation'!Q17 -> -0.37296328 | R17: 0.83087102 | S17: 0.2 | T17: 4.8776022 | U17: 1.5707963 | V17: 0.44112637 | W17: 0.12397642 | X17: 2.7203547 | Y17: 1.5707963 | Z17: 2.5288065e-05 | AA17: =R17-A17 -> 0.13087102 | AB17: =S17-B17 -> -9.2725053e-10 | AC17: =T17-C17 -> 0.16560222 | AD17: =U17-D17 -> 0 | AE17: =V17-E17 -> 0.14112637 | AF17: =W17-F17 -> 0.04397642 | AG17: =X17-G17 -> -0.42164529 | AH17: =Y17-H17 -> 0 | AI17: =AVERAGE(ABS(AA17),ABS(AE17)) -> 0.13599869 | AJ17: =AVERAGE(ABS(AB17),ABS(AF17)) -> 0.021988211 | AK17: =AVERAGE(ABS(AC17),ABS(AG17)) -> 0.29362375
A19: Perturbation | H19: Trial # | I19: tau1 (N) | J19: tau2 (N) | K19: tau3 (N) | L19: Supporting Measurments w Perturbation
A20: 0.6 | B20: 0 | C20: 0 | H20: 1 | I20: ='Distal Vali (0.6N perturb)'!I3 -> 0.8 | J20: ='Distal Vali (0.6N perturb)'!J3 -> 0 | K20: ='Distal Vali (0.6N perturb)'!K3 -> 0 | L20: ='Distal Vali (0.6N perturb)'!L3 -> 0.00038069719 | M20: ='Distal Vali (0.6N perturb)'!M3 -> -0.096344933 | N20: ='Distal Vali (0.6N perturb)'!N3 -> -0.033478599 | O20: ='Distal Vali (0.6N perturb)'!O3 -> -0.082021892 | P20: ='Distal Vali (0.6N perturb)'!P3 -> -0.28456718 | Q20: ='Distal Vali (0.6N perturb)'!Q3 -> 0.41270199
A21: 0 | B21: 0.6 | C21: 0 | H21: 1 | I21: =I$20+A20 -> 1.4 | J21: =J$20+B20 -> 0 | K21: =K$20+C20 -> 0 | L21: 0.0014565979 | M21: -0.088410288 | N21: -0.034315299 | O21: -0.074583113 | P21: -0.30525967 | Q21: 0.38623139
A22: 0 | B22: 0 | C22: 0.6 | H22: 1 | I22: =I$20+A21 -> 0.8 | J22: =J$20+B21 -> 0.6 | K22: =K$20+C21 -> 0 | L22: -4.269043e-05 | M22: -0.088799715 | N22: -0.03124157 | O22: -0.071892038 | P22: -0.28315312 | Q22: 0.38960463
H23: 1 | I23: =I$20+A22 -> 0.8 | J23: =J$20+B22 -> 0 | K23: =K$20+C22 -> 0.6 | L23: 0.00076588849 | M23: -0.10394147 | N23: -0.032754429 | O23: -0.084739812 | P23: -0.2910926 | Q23: 0.4586626
H24: 2 | I24: ='Distal Vali (0.6N perturb)'!I4 -> 0 | J24: ='Distal Vali (0.6N perturb)'!J4 -> 0 | K24: ='Distal Vali (0.6N perturb)'!K4 -> 0 | L24: ='Distal Vali (0.6N perturb)'!L4 -> -0.00081903394 | M24: ='Distal Vali (0.6N perturb)'!M4 -> -0.00532459 | N24: ='Distal Vali (0.6N perturb)'!N4 -> -0.0023375959 | O24: ='Distal Vali (0.6N perturb)'!O4 -> -0.0024775807 | P24: ='Distal Vali (0.6N perturb)'!P4 -> -0.0034357905 | Q24: ='Distal Vali (0.6N perturb)'!Q4 -> -0.19096869
H25: 2 | I25: =I$24+A20 -> 0.6 | J25: =J$24+B20 -> 0 | K25: =K$24+C20 -> 0 | L25: -0.00017358817 | M25: 0.00013063895 | N25: -0.0035042311 | O25: 0.0026354161 | P25: -0.011821691 | Q25: -0.21522439
H26: 2 | I26: =I$24+A21 -> 0 | J26: =J$24+B21 -> 0.6 | K26: =K$24+C21 -> 0 | L26: -0.0011212043 | M26: 0.0007195574 | N26: -0.0012248631 | O26: 0.0041815089 | P26: -0.0056836084 | Q26: -0.21486381
H27: 2 | I27: =I$24+A22 -> 0 | J27: =J$24+B22 -> 0 | K27: =K$24+C22 -> 0.6 | L27: -0.00066979585 | M27: -0.015029212 | N27: -0.0021230108 | O27: -0.0065803281 | P27: -0.0077823959 | Q27: -0.14025083
H28: 3 | I28: ='Distal Vali (0.6N perturb)'!I5 -> 0.4 | J28: ='Distal Vali (0.6N perturb)'!J5 -> 0 | K28: ='Distal Vali (0.6N perturb)'!K5 -> 0 | L28: ='Distal Vali (0.6N perturb)'!L5 -> 0.00034113688 | M28: ='Distal Vali (0.6N perturb)'!M5 -> -0.14381006 | N28: ='Distal Vali (0.6N perturb)'!N5 -> -0.003464737 | O28: ='Distal Vali (0.6N perturb)'!O5 -> -0.43965021 | P28: ='Distal Vali (0.6N perturb)'!P5 -> -0.0037686527 | Q28: ='Distal Vali (0.6N perturb)'!Q5 -> 0.28356427
H29: 3 | I29: =I$28+A20 -> 1 | J29: =J$28+B20 -> 0 | K29: =K$28+C20 -> 0 | L29: 0.0042280313 | M29: -0.13657358 | N29: -0.0074278452 | O29: -0.41066289 | P29: -0.029423211 | Q29: 0.26725352
H30: 3 | I30: =I$28+A21 -> 0.4 | J30: =J$28+B21 -> 0.6 | K30: =K$28+C21 -> 0 | L30: -0.001792528 | M30: -0.13576709 | N30: -0.00061983016 | O30: -0.40795222 | P30: 0.0036501549 | Q30: 0.27262843
H31: 3 | I31: =I$28+A22 -> 0.4 | J31: =J$28+B22 -> 0 | K31: =K$28+C22 -> 0.6 | L31: 0.0004223643 | M31: -0.1483375 | N31: -0.0032022025 | O31: -0.4504495 | P31: -0.0097873732 | Q31: 0.29778695
H32: 4 | I32: ='Distal Vali (0.6N perturb)'!I6 -> 0.4 | J32: ='Distal Vali (0.6N perturb)'!J6 -> 0 | K32: ='Distal Vali (0.6N perturb)'!K6 -> 0 | L32: ='Distal Vali (0.6N perturb)'!L6 -> -0.00028536888 | M32: ='Distal Vali (0.6N perturb)'!M6 -> -0.063574255 | N32: ='Distal Vali (0.6N perturb)'!N6 -> -0.090447113 | O32: ='Distal Vali (0.6N perturb)'!O6 -> -0.08588402 | P32: ='Distal Vali (0.6N perturb)'!P6 -> -0.67203629 | Q32: ='Distal Vali (0.6N perturb)'!Q6 -> 0.13295281
H33: 4 | I33: =I$32+A20 -> 1 | J33: =J$32+B20 -> 0 | K33: =K$32+C20 -> 0 | L33: 0.0015889388 | M33: -0.055109333 | N33: -0.094750039 | O33: -0.075877033 | P33: -0.69757289 | Q33: 0.10756204
H34: 4 | I34: =I$32+A21 -> 0.4 | J34: =J$32+B21 -> 0.6 | K34: =K$32+C21 -> 0 | L34: -0.0015058562 | M34: -0.055391017 | N34: -0.086338341 | O34: -0.072327547 | P34: -0.66003758 | Q34: 0.11620241
H35: 4 | I35: =I$32+A22 -> 0.4 | J35: =J$32+B22 -> 0 | K35: =K$32+C22 -> 0.6 | L35: -0.00028814236 | M35: -0.074884176 | N35: -0.089398891 | O35: -0.10567357 | P35: -0.67512369 | Q35: 0.16946965
H36: 5 | I36: ='Distal Vali (0.6N perturb)'!I7 -> 0.8 | J36: ='Distal Vali (0.6N perturb)'!J7 -> 0 | K36: ='Distal Vali (0.6N perturb)'!K7 -> 0 | L36: ='Distal Vali (0.6N perturb)'!L7 -> -0.0013721101 | M36: ='Distal Vali (0.6N perturb)'!M7 -> 0.087113634 | N36: ='Distal Vali (0.6N perturb)'!N7 -> -0.16279364 | O36: ='Distal Vali (0.6N perturb)'!O7 -> -0.090744965 | P36: ='Distal Vali (0.6N perturb)'!P7 -> -0.87937129 | Q36: ='Distal Vali (0.6N perturb)'!Q7 -> -0.48219949
H37: 5 | I37: =I$36+A20 -> 1.4 | J37: =J$36+B20 -> 0 | K37: =K$36+C20 -> 0 | L37: -0.001360558 | M37: 0.090598643 | N37: -0.17294137 | O37: -0.094194762 | P37: -0.93448365 | Q37: -0.50216889
H38: 5 | I38: =I$36+A21 -> 0.8 | J38: =J$36+B21 -> 0.6 | K38: =K$36+C21 -> 0 | L38: -0.00044362899 | M38: 0.087859079 | N38: -0.14970051 | O38: -0.083662197 | P38: -0.81903315 | Q38: -0.48939896
H39: 5 | I39: =I$36+A22 -> 0.8 | J39: =J$36+B22 -> 0 | K39: =K$36+C22 -> 0.6 | L39: -0.00217553 | M39: 0.079079501 | N39: -0.15534256 | O39: -0.084770121 | P39: -0.84200013 | Q39: -0.43774006
H40: 6 | I40: ='Distal Vali (0.6N perturb)'!I8 -> 0.4 | J40: ='Distal Vali (0.6N perturb)'!J8 -> 0 | K40: ='Distal Vali (0.6N perturb)'!K8 -> 0 | L40: ='Distal Vali (0.6N perturb)'!L8 -> -0.0014753519 | M40: ='Distal Vali (0.6N perturb)'!M8 -> 0.031907491 | N40: ='Distal Vali (0.6N perturb)'!N8 -> -0.19490382 | O40: ='Distal Vali (0.6N perturb)'!O8 -> -0.17070602 | P40: ='Distal Vali (0.6N perturb)'!P8 -> -1.0707257 | Q40: ='Distal Vali (0.6N perturb)'!Q8 -> -0.2222923
H41: 6 | I41: =I$40+A20 -> 1 | J41: =J$40+B20 -> 0 | K41: =K$40+C20 -> 0 | L41: -0.00095861685 | M41: 0.033118188 | N41: -0.20282634 | O41: -0.17964211 | P41: -1.1134599 | Q41: -0.23012918
...

Sheet Sheet1
S1: 2.0 weight
A2: 0.5 | B2: 0.12 | C2: 1.57 | D2: 1.5707963 | E2: 0.3 | F2: 0.02 | G2: 3.142 | H2: 1.5707963 | J2: 0.7535 | K2: 0.0892 | L2: 1.5986 | M2: 1.5708 | N2: 0.4259 | O2: 0.0236 | P2: 4.047 | Q2: 1.5708 | S2: 0.4656 | T2: 0.1292 | U2: 1.6195 | V2: 1.5708 | W2: 0.2639 | X2: 0.02 | Y2: 3.3085 | Z2: 1.5708
A4: 0.8 | B4: 0.18 | C4: 1.57 | D4: 1.5707963 | E4: 0.4 | F4: 0.08 | G4: 4.712 | H4: 1.5707963 | J4: 0.7552 | K4: 0.1815 | L4: 1.6024 | M4: 1.5708 | N4: 0.2994 | O4: 0.0331 | P4: 4.7822 | Q4: 1.5708 | S4: 0.9456 | T4: 0.1737 | U4: 1.6017 | V4: 1.5708 | W4: 0.4506 | X4: 0.0814 | Y4: 4.7667 | Z4: 1.5708
A6: 0.3 | B6: 0.2 | C6: 1.57 | D6: 1.5707963 | E6: 0.7 | F6: 0.04 | G6: 3.142 | H6: 1.5707963 | J6: 0.4549 | K6: 0.1397 | L6: 1.6882 | M6: 1.5708 | N6: 0.6931 | O6: 0.0367 | P6: 3.6036 | Q6: 1.5708 | S6: 0.3047 | T6: 0.1945 | U6: 1.4612 | V6: 1.5708 | W6: 0.7201 | X6: 0.0516 | Y6: 3.3448 | Z6: 1.5708
A8: 0.3 | B8: 0.1 | C8: 3.142 | D8: 1.5707963 | E8: 0.8 | F8: 0.08 | G8: 3.927 | H8: 1.5707963 | J8: 0.3204 | K8: 0.0998 | L8: 3.2689 | M8: 1.5708 | N8: 0.7404 | O8: 0.0839 | P8: 3.8016 | Q8: 1.5708 | S8: 0.6252 | T8: 0.0922 | U8: 3.0066 | V8: 1.5708 | W8: 0.6437 | X8: 0.0861 | Y8: 4.2612 | Z8: 1.5708
A10: 0.7 | B10: 0.1 | C10: 3.142 | D10: 1.5707963 | E10: 0.4 | F10: 0.04 | G10: 3.927 | H10: 1.5707963 | J10: 0.1531 | K10: 0.1588 | L10: 2.6353 | M10: 1.5708 | N10: 1 | O10: 0.0806 | P10: 3.4427 | Q10: 1.5708 | S10: 0.8685 | T10: 0.1038 | U10: 3.2111 | V10: 1.5708 | W10: 0.2763 | X10: 0.0371 | Y10: 3.768 | Z10: 1.5708

Sheet Sheet5
A2: [ | B2: -0.0014753519 | C2: 0.031907491 | D2: -0.19490382 | E2: -0.17070602 | F2: -1.0707257 | G2: -0.2222923 | H2: ; | J2: [ | K2: 0.4 | L2: 0 | M2: 0 | N2: ;
B3: -0.00095861685 | C3: 0.033118188 | D3: -0.20282634 | E3: -0.17964211 | F3: -1.1134599 | G3: -0.23012918 | H3: ; | K3: 1 | L3: 0 | M3: 0 | N3: ;
B4: -0.00095200352 | C4: 0.031913918 | D4: -0.18534166 | E4: -0.15961531 | F4: -1.0270278 | G4: -0.22407839 | H4: ; | K4: 0.4 | L4: 0.6 | M4: 0 | N4: ;
B5: -0.0025325799 | C5: 0.029947657 | D5: -0.19052435 | E5: -0.16586432 | F5: -1.0503713 | G5: -0.20897406 | H5: ] | K5: 0.4 | L5: 0 | M5: 0.6 | N5: ]
C12: { | D12: [ | E12: 0.00038069719 | F12: -0.096344933 | G12: -0.033478599 | H12: -0.082021892 | I12: -0.28456718 | J12: 0.41270199 | K12: 0.8 | L12: 0 | M12: 0 | N12: ] | O12: ;
D13: [ | E13: -0.00081903394 | F13: -0.00532459 | G13: -0.0023375959 | H13: -0.0024775807 | I13: -0.0034357905 | J13: -0.19096869 | K13: 0 | L13: 0 | M13: 0 | N13: ] | O13: ;
D14: [ | E14: 0.00034113688 | F14: -0.14381006 | G14: -0.003464737 | H14: -0.43965021 | I14: -0.0037686527 | J14: 0.28356427 | K14: 0.4 | L14: 0 | M14: 0 | N14: ] | O14: ;
D15: [ | E15: -0.00028536888 | F15: -0.063574255 | G15: -0.090447113 | H15: -0.08588402 | I15: -0.67203629 | J15: 0.13295281 | K15: 0.4 | L15: 0 | M15: 0 | N15: ] | O15: ;
D16: [ | E16: -0.0013721101 | F16: 0.087113634 | G16: -0.16279364 | H16: -0.090744965 | I16: -0.87937129 | J16: -0.48219949 | K16: 0.8 | L16: 0 | M16: 0 | N16: ] | O16: ;
D17: [ | E17: -0.0014753519 | F17: 0.031907491 | G17: -0.19490382 | H17: -0.17070602 | I17: -1.0707257 | J17: -0.2222923 | K17: 0.4 | L17: 0 | M17: 0 | N17: ] | O17: ;
D18: [ | E18: -0.0028121248 | F18: 0.070382752 | G18: -0.20890267 | H18: -0.32640225 | I18: -0.97189969 | J18: -0.38067478 | K18: 0.4 | L18: 0 | M18: 0 | N18: ] | O18: ;
D19: [ | E19: -0.0018884372 | F19: 0.048766464 | G19: -0.22089446 | H19: -0.32184327 | I19: -1.0122297 | J19: -0.29647687 | K19: 0.8 | L19: 0 | M19: 0 | N19: ] | O19: ;
D20: [ | E20: -0.0025915056 | F20: 0.027324185 | G20: -0.13145609 | H20: -0.13658202 | I20: -0.61641645 | J20: -0.2340374 | K20: 0 | L20: 0 | M20: 0 | N20: ] | O20: ;
D21: [ | E21: -0.0028818771 | F21: 0.064880513 | G21: -0.26836297 | H21: -0.61091924 | I21: -1.1492969 | J21: -0.46333063 | K21: 0.4 | L21: 0 | M21: 0 | N21: ] | O21: ;
D22: [ | E22: -0.0010846329 | F22: 0.10540774 | G22: -0.0075431094 | H22: -0.044421639 | I22: -0.053632915 | J22: -0.59106356 | K22: 0.4 | L22: 0 | M22: 0 | N22: ] | O22: ;
D23: [ | E23: -0.0012127757 | F23: 0.18917631 | G23: -0.080510885 | H23: -0.25100401 | I23: -0.70138603 | J23: -0.86990654 | K23: 0 | L23: 0 | M23: 0 | N23: ] | O23: ;
D24: [ | E24: -0.0024155118 | F24: 0.10498013 | G24: -0.074356906 | H24: -0.11680464 | I24: -0.49594429 | J24: -0.37272522 | K24: 0.4 | L24: 0 | M24: 0 | N24: ] | O24: ;
D25: [ | E25: -0.0070373835 | F25: 0.19658189 | G25: -0.0090219676 | H25: -0.25380778 | I25: -0.046346724 | J25: -1.0507474 | K25: 0.8 | L25: 0 | M25: 0 | N25: ] | O25: ;
D26: [ | E26: -0.0014520943 | F26: 0.15855817 | G26: -0.046406556 | H26: -0.53051335 | I26: -0.2509959 | J26: -0.37296328 | K26: 0 | L26: 0 | M26: 0 | N26: ] | O26: ; | P26: }
C29: { | D29: [ | E29: 0.00038069719 | F29: -0.096344933 | G29: -0.033478599 | H29: -0.082021892 | I29: -0.28456718 | J29: 0.41270199 | K29: 0.8 | L29: 0 | M29: 0 | N29: ;
E30: 0.0014565979 | F30: -0.088410288 | G30: -0.034315299 | H30: -0.074583113 | I30: -0.30525967 | J30: 0.38623139 | K30: 1.4 | L30: 0 | M30: 0 | N30: ;
E31: -4.269043e-05 | F31: -0.088799715 | G31: -0.03124157 | H31: -0.071892038 | I31: -0.28315312 | J31: 0.38960463 | K31: 0.8 | L31: 0.6 | M31: 0 | N31: ;
E32: 0.00076588849 | F32: -0.10394147 | G32: -0.032754429 | H32: -0.084739812 | I32: -0.2910926 | J32: 0.4586626 | K32: 0.8 | L32: 0 | M32: 0.6 | N32: ] | O32: ;
D33: [ | E33: -0.00081903394 | F33: -0.00532459 | G33: -0.0023375959 | H33: -0.0024775807 | I33: -0.0034357905 | J33: -0.19096869 | K33: 0 | L33: 0 | M33: 0 | N33: ;
E34: -0.00017358817 | F34: 0.00013063895 | G34: -0.0035042311 | H34: 0.0026354161 | I34: -0.011821691 | J34: -0.21522439 | K34: 0.6 | L34: 0 | M34: 0 | N34: ;
E35: -0.0011212043 | F35: 0.0007195574 | G35: -0.0012248631 | H35: 0.0041815089 | I35: -0.0056836084 | J35: -0.21486381 | K35: 0 | L35: 0.6 | M35: 0 | N35: ;
E36: -0.00066979585 | F36: -0.015029212 | G36: -0.0021230108 | H36: -0.0065803281 | I36: -0.0077823959 | J36: -0.14025083 | K36: 0 | L36: 0 | M36: 0.6 | N36: ] | O36: ;
D37: [ | E37: 0.00034113688 | F37: -0.14381006 | G37: -0.003464737 | H37: -0.43965021 | I37: -0.0037686527 | J37: 0.28356427 | K37: 0.4 | L37: 0 | M37: 0 | N37: ;
E38: 0.0042280313 | F38: -0.13657358 | G38: -0.0074278452 | H38: -0.41066289 | I38: -0.029423211 | J38: 0.26725352 | K38: 1 | L38: 0 | M38: 0 | N38: ;
E39: -0.001792528 | F39: -0.13576709 | G39: -0.00061983016 | H39: -0.40795222 | I39: 0.0036501549 | J39: 0.27262843 | K39: 0.4 | L39: 0.6 | M39: 0 | N39: ;
E40: 0.0004223643 | F40: -0.1483375 | G40: -0.0032022025 | H40: -0.4504495 | I40: -0.0097873732 | J40: 0.29778695 | K40: 0.4 | L40: 0 | M40: 0.6 | N40: ] | O40: ;
D41: [ | E41: -0.00028536888 | F41: -0.063574255 | G41: -0.090447113 | H41: -0.08588402 | I41: -0.67203629 | J41: 0.13295281 | K41: 0.4 | L41: 0 | M41: 0 | N41: ;
E42: 0.0015889388 | F42: -0.055109333 | G42: -0.094750039 | H42: -0.075877033 | I42: -0.69757289 | J42: 0.10756204 | K42: 1 | L42: 0 | M42: 0 | N42: ;
E43: -0.0015058562 | F43: -0.055391017 | G43: -0.086338341 | H43: -0.072327547 | I43: -0.66003758 | J43: 0.11620241 | K43: 0.4 | L43: 0.6 | M43: 0 | N43: ;
E44: -0.00028814236 | F44: -0.074884176 | G44: -0.089398891 | H44: -0.10567357 | I44: -0.67512369 | J44: 0.16946965 | K44: 0.4 | L44: 0 | M44: 0.6 | N44: ] | O44: ;
D45: [ | E45: -0.0013721101 | F45: 0.087113634 | G45: -0.16279364 | H45: -0.090744965 | I45: -0.87937129 | J45: -0.48219949 | K45: 0.8 | L45: 0 | M45: 0 | N45: ;
E46: -0.001360558 | F46: 0.090598643 | G46: -0.17294137 | H46: -0.094194762 | I46: -0.93448365 | J46: -0.50216889 | K46: 1.4 | L46: 0 | M46: 0 | N46: ;
E47: -0.00044362899 | F47: 0.087859079 | G47: -0.14970051 | H47: -0.083662197 | I47: -0.81903315 | J47: -0.48939896 | K47: 0.8 | L47: 0.6 | M47: 0 | N47: ;
E48: -0.00217553 | F48: 0.079079501 | G48: -0.15534256 | H48: -0.084770121 | I48: -0.84200013 | J48: -0.43774006 | K48: 0.8 | L48: 0 | M48: 0.6 | N48: ] | O48: ;
D49: [ | E49: -0.0014753519 | F49: 0.031907491 | G49: -0.19490382 | H49: -0.17070602 | I49: -1.0707257 | J49: -0.2222923 | K49: 0.4 | L49: 0 | M49: 0 | N49: ;
...

Sheet Conversion
A1: Raw Data | H1: Converted
A2: Fx | B2: Fy | C2: Fz | D2: Tx | E2: Ty | F2: Tz | H2: Tx | I2: Ty | J2: Tz | K2: Fx | L2: Fy | M2: Fz
A3: -0.37272522 | B3: 0.49594429 | C3: -0.11680464 | D3: -0.074356906 | E3: -0.10498013 | F3: -0.0024155118 | H3: =$F3 -> -0.0024155118 | I3: =-1*$E3 -> 0.10498013 | J3: =$D3 -> -0.074356906 | K3: =$C3 -> -0.11680464 | L3: =-1*$B3 -> -0.49594429 | M3: =$A3 -> -0.37272522
A4: -0.39405558 | B4: 0.52405667 | C4: -0.12376702 | D4: -0.079401433 | E4: -0.11069238 | F4: -0.0042061894 | H4: =$F4 -> -0.0042061894 | I4: =-1*$E4 -> 0.11069238 | J4: =$D4 -> -0.079401433 | K4: =$C4 -> -0.12376702 | L4: =-1*$B4 -> -0.52405667 | M4: =$A4 -> -0.39405558
A5: -0.39102972 | B5: 0.46096909 | C5: -0.12060862 | D5: -0.067554012 | E5: -0.1099504 | F5: -1.2431759e-05 | H5: =$F5 -> -1.2431759e-05 | I5: =-1*$E5 -> 0.1099504 | J5: =$D5 -> -0.067554012 | K5: =$C5 -> -0.12060862 | L5: =-1*$B5 -> -0.46096909 | M5: =$A5 -> -0.39102972
A6: -0.32724214 | B6: 0.49263996 | C6: -0.094696291 | D6: -0.0727579 | E6: -0.09023831 | F6: -0.0019208933 | H6: =$F6 -> -0.0019208933 | I6: =-1*$E6 -> 0.09023831 | J6: =$D6 -> -0.0727579 | K6: =$C6 -> -0.094696291 | L6: =-1*$B6 -> -0.49263996 | M6: =$A6 -> -0.32724214
A7: -1.0507474 | B7: 0.046346724 | C7: -0.25380778 | D7: -0.0090219676 | E7: -0.19658189 | F7: -0.0070373835 | H7: =$F7 -> -0.0070373835 | I7: =-1*$E7 -> 0.19658189 | J7: =$D7 -> -0.0090219676 | K7: =$C7 -> -0.25380778 | L7: =-1*$B7 -> -0.046346724 | M7: =$A7 -> -1.0507474
A8: -1.0618409 | B8: 0.060807854 | C8: -0.25792149 | D8: -0.012096893 | E8: -0.19916533 | F8: -0.0095165186 | H8: =$F8 -> -0.0095165186 | I8: =-1*$E8 -> 0.19916533 | J8: =$D8 -> -0.012096893 | K8: =$C8 -> -0.25792149 | L8: =-1*$B8 -> -0.060807854 | M8: =$A8 -> -1.0618409
A9: -1.0567825 | B9: 0.031391993 | C9: -0.26251405 | D9: -0.0060360665 | E9: -0.19921809 | F9: -0.0042758919 | H9: =$F9 -> -0.0042758919 | I9: =-1*$E9 -> 0.19921809 | J9: =$D9 -> -0.0060360665 | K9: =$C9 -> -0.26251405 | L9: =-1*$B9 -> -0.031391993 | M9: =$A9 -> -1.0567825
A10: -1.0179758 | B10: 0.041011304 | C10: -0.22237787 | D10: -0.0072069587 | E10: -0.18305945 | F10: -0.0052960673 | H10: =$F10 -> -0.0052960673 | I10: =-1*$E10 -> 0.18305945 | J10: =$D10 -> -0.0072069587 | K10: =$C10 -> -0.22237787 | L10: =-1*$B10 -> -0.041011304 | M10: =$A10 -> -1.0179758
A11: -0.37296328 | B11: 0.2509959 | C11: -0.53051335 | D11: -0.046406556 | E11: -0.15855817 | F11: -0.0014520943 | H11: =$F11 -> -0.0014520943 | I11: =-1*$E11 -> 0.15855817 | J11: =$D11 -> -0.046406556 | K11: =$C11 -> -0.53051335 | L11: =-1*$B11 -> -0.2509959 | M11: =$A11 -> -0.37296328
A12: -0.38318056 | B12: 0.29847211 | C12: -0.55159247 | D12: -0.054400574 | E12: -0.16300923 | F12: -0.0056697223 | H12: =$F12 -> -0.0056697223 | I12: =-1*$E12 -> 0.16300923 | J12: =$D12 -> -0.054400574 | K12: =$C12 -> -0.55159247 | L12: =-1*$B12 -> -0.29847211 | M12: =$A12 -> -0.38318056
A13: -0.38281131 | B13: 0.20056297 | C13: -0.53685087 | D13: -0.037582073 | E13: -0.16158326 | F13: 0.0029093889 | H13: =$F13 -> 0.0029093889 | I13: =-1*$E13 -> 0.16158326 | J13: =$D13 -> -0.037582073 | K13: =$C13 -> -0.53685087 | L13: =-1*$B13 -> -0.20056297 | M13: =$A13 -> -0.38281131
A14: -0.35976207 | B14: 0.24365807 | C14: -0.49502161 | D14: -0.044777002 | E14: -0.14788705 | F14: -0.00060013111 | H14: =$F14 -> -0.00060013111 | I14: =-1*$E14 -> 0.14788705 | J14: =$D14 -> -0.044777002 | K14: =$C14 -> -0.49502161 | L14: =-1*$B14 -> -0.24365807 | M14: =$A14 -> -0.35976207
H15: =$F15 -> 0 | I15: =-1*$E15 -> 0 | J15: =$D15 -> 0 | K15: =$C15 -> 0 | L15: =-1*$B15 -> 0 | M15: =$A15 -> 0
H16: =$F16 -> 0 | I16: =-1*$E16 -> 0 | J16: =$D16 -> 0 | K16: =$C16 -> 0 | L16: =-1*$B16 -> 0 | M16: =$A16 -> 0
H17: =$F17 -> 0 | I17: =-1*$E17 -> 0 | J17: =$D17 -> 0 | K17: =$C17 -> 0 | L17: =-1*$B17 -> 0 | M17: =$A17 -> 0
H18: =$F18 -> 0 | I18: =-1*$E18 -> 0 | J18: =$D18 -> 0 | K18: =$C18 -> 0 | L18: =-1*$B18 -> 0 | M18: =$A18 -> 0
H19: =$F19 -> 0 | I19: =-1*$E19 -> 0 | J19: =$D19 -> 0 | K19: =$C19 -> 0 | L19: =-1*$B19 -> 0 | M19: =$A19 -> 0
H20: =$F20 -> 0 | I20: =-1*$E20 -> 0 | J20: =$D20 -> 0 | K20: =$C20 -> 0 | L20: =-1*$B20 -> 0 | M20: =$A20 -> 0
H21: =$F21 -> 0 | I21: =-1*$E21 -> 0 | J21: =$D21 -> 0 | K21: =$C21 -> 0 | L21: =-1*$B21 -> 0 | M21: =$A21 -> 0
H22: =$F22 -> 0 | I22: =-1*$E22 -> 0 | J22: =$D22 -> 0 | K22: =$C22 -> 0 | L22: =-1*$B22 -> 0 | M22: =$A22 -> 0
H23: =$F23 -> 0 | I23: =-1*$E23 -> 0 | J23: =$D23 -> 0 | K23: =$C23 -> 0 | L23: =-1*$B23 -> 0 | M23: =$A23 -> 0
H24: =$F24 -> 0 | I24: =-1*$E24 -> 0 | J24: =$D24 -> 0 | K24: =$C24 -> 0 | L24: =-1*$B24 -> 0 | M24: =$A24 -> 0
H25: =$F25 -> 0 | I25: =-1*$E25 -> 0 | J25: =$D25 -> 0 | K25: =$C25 -> 0 | L25: =-1*$B25 -> 0 | M25: =$A25 -> 0
H26: =$F26 -> 0 | I26: =-1*$E26 -> 0 | J26: =$D26 -> 0 | K26: =$C26 -> 0 | L26: =-1*$B26 -> 0 | M26: =$A26 -> 0
