Workbook

Sheet Proximal Validation (double)
A1: Ground Truth | L1: 6-Axis FT Sensor | R1: SoRoSim get_proximal_value | X1: Proximal Errors
A2: F1 (N) | B2: s1 (m) | C2: el1 (rad) | D2: az1 (rad) | E2: F2 (N) | F2: s2 (m) | G2: el2 (rad) | H2: az2 (rad) | I2: tau1 (N) | J2: tau2 (N) | K2: tau3 (N) | L2: Tx (Nm) | M2: Ty (Nm) | N2: Tz(Nm) | O2: Fx (N) | P2: Fy (N) | Q2: Fz (N) | R2: Tx (Nm) | S2: Ty (Nm) | T2: Tz(Nm) | U2: Fx (N) | V2: Fy (N) | W2: Fz (N) | X2: Tx (Nm) | Y2: Ty (Nm) | Z2: Tz(Nm) | AA2: Fx (N) | AB2: Fy (N) | AC2: Fz (N)
A3: 0.2 | B3: 0.1 | C3: 1.571 | D3: =PI()/2 -> 1.5707963 | E3: 1 | F3: 0.04 | G3: 3.142 | H3: =PI()/2 -> 1.5707963 | I3: 1.4 | J3: 0 | K3: 0 | L3: -8.4695406e-05 | M3: -0.011448632 | N3: -0.13048847 | O3: 0.018870793 | P3: -0.97202778 | Q3: 0.029205024 | R3: 0.0007 | S3: -0.0379 | T3: -0.1297 | U3: -0.0336 | V3: -0.9997 | W3: 0.1988 | X3: =ABS(L3-R3) -> 0.00078469541 | Y3: =ABS(M3-S3) -> 0.026451368 | Z3: =ABS(N3-T3) -> 0.0007884702 | AA3: =ABS(O3-U3) -> 0.052470793 | AB3: =ABS(P3-V3) -> 0.027672221 | AC3: =ABS(Q3-W3) -> 0.16959498
A4: 1 | B4: 0.1 | C4: 1.571 | D4: =PI()/2 -> 1.5707963 | E4: 1 | F4: 0.08 | G4: 3.142 | H4: =PI()/2 -> 1.5707963 | I4: 0 | J4: 0 | K4: 0 | L4: -0.0013048807 | M4: -0.18739954 | N4: -0.14850681 | O4: -0.4587166 | P4: -0.81002575 | Q4: 0.92483175 | R4: 0 | S4: -0.1854 | T4: -0.1667 | U4: -0.3763 | V4: -0.9696 | W4: 0.958 | X4: =ABS(L4-R4) -> 0.0013048807 | Y4: =ABS(M4-S4) -> 0.0019995364 | Z4: =ABS(N4-T4) -> 0.018193195 | AA4: =ABS(O4-U4) -> 0.082416601 | AB4: =ABS(P4-V4) -> 0.15957425 | AC4: =ABS(Q4-W4) -> 0.033168252
A5: 0.5 | B5: 0.1 | C5: 1.571 | D5: =PI()/2 -> 1.5707963 | E5: 0.2 | F5: 0.02 | G5: 3.927 | H5: =PI()/2 -> 1.5707963 | I5: 0 | J5: 0 | K5: 0 | L5: -8.817346e-05 | M5: -0.09024971 | N5: -0.015381615 | O5: -0.059044521 | P5: -0.14255172 | Q5: 0.40386674 | R5: 0 | S5: -0.0792 | T5: -0.0155 | U5: -0.0521 | V5: -0.1415 | W5: 0.3554 | X5: =ABS(L5-R5) -> 8.817346e-05 | Y5: =ABS(M5-S5) -> 0.01104971 | Z5: =ABS(N5-T5) -> 0.00011838532 | AA5: =ABS(O5-U5) -> 0.0069445213 | AB5: =ABS(P5-V5) -> 0.0010517201 | AC5: =ABS(Q5-W5) -> 0.048466738
A6: 0.9 | B6: 0.1 | C6: 1.571 | D6: =PI()/2 -> 1.5707963 | E6: 0.2 | F6: 0.08 | G6: 4.712 | H6: =PI()/2 -> 1.5707963 | I6: 1.2 | J6: 0 | K6: 0 | L6: 0.004064511 | M6: -0.15509437 | N6: 0.0011263725 | O6: -0.22939645 | P6: 0.006297946 | Q6: 0.75826401 | R6: 0.0015 | S6: -0.1353 | T6: -0.0002 | U6: -0.1438 | V6: -0.0024 | W6: 0.6851 | X6: =ABS(L6-R6) -> 0.002564511 | Y6: =ABS(M6-S6) -> 0.01979437 | Z6: =ABS(N6-T6) -> 0.0013263725 | AA6: =ABS(O6-U6) -> 0.085596448 | AB6: =ABS(P6-V6) -> 0.008697946 | AC6: =ABS(Q6-W6) -> 0.073164005
A7: 0.1 | B7: 0.12 | C7: 1.571 | D7: =PI()/2 -> 1.5707963 | E7: 1 | F7: 0.06 | G7: 3.927 | H7: =PI()/2 -> 1.5707963 | I7: 0 | J7: 0 | K7: 0 | L7: -3.3720862e-05 | M7: 0.055788416 | N7: -0.10684345 | O7: 0.023180401 | P7: -0.69266725 | Q7: -0.43824503 | R7: 0 | S7: 0.0849 | T7: -0.1058 | U7: -0.063 | V7: -0.7053 | W7: -0.6059 | X7: =ABS(L7-R7) -> 3.3720862e-05 | Y7: =ABS(M7-S7) -> 0.029111584 | Z7: =ABS(N7-T7) -> 0.0010434492 | AA7: =ABS(O7-U7) -> 0.086180401 | AB7: =ABS(P7-V7) -> 0.012632754 | AC7: =ABS(Q7-W7) -> 0.16765497
A8: 0.8 | B8: 0.16 | C8: 1.571 | D8: =PI()/2 -> 1.5707963 | E8: 0.8 | F8: 0.06 | G8: 3.927 | H8: =PI()/2 -> 1.5707963 | I8: 1.4 | J8: 0 | K8: 0 | L8: 0.0082578762 | M8: -0.10636095 | N8: -0.076963931 | O8: -0.29881915 | P8: -0.50920194 | Q8: 0.10888903 | R8: 0.0044 | S8: -0.1064 | T8: -0.0839 | U8: -0.2294 | V8: -0.5643 | W8: 0.1658 | X8: =ABS(L8-R8) -> 0.0038578762 | Y8: =ABS(M8-S8) -> 3.9050424e-05 | Z8: =ABS(N8-T8) -> 0.0069360687 | AA8: =ABS(O8-U8) -> 0.069419155 | AB8: =ABS(P8-V8) -> 0.055098056 | AC8: =ABS(Q8-W8) -> 0.056910972
A9: 0.1 | B9: 0.18 | C9: 1.571 | D9: =PI()/2 -> 1.5707963 | E9: 0.1 | F9: 0.02 | G9: 3.142 | H9: =PI()/2 -> 1.5707963 | I9: 1.2 | J9: 0 | K9: 0 | L9: 0.00025301205 | M9: -0.0061941464 | N9: -0.012296888 | O9: 0.015694043 | P9: -0.10866395 | Q9: 0.01807829 | R9: 0.0006 | S9: -0.027 | T9: -0.011 | U9: -0.011 | V9: -0.1003 | W9: 0.0993 | X9: =ABS(L9-R9) -> 0.00034698795 | Y9: =ABS(M9-S9) -> 0.020805854 | Z9: =ABS(N9-T9) -> 0.001296888 | AA9: =ABS(O9-U9) -> 0.026694043 | AB9: =ABS(P9-V9) -> 0.0083639538 | AC9: =ABS(Q9-W9) -> 0.08122171
A10: 0.9 | B10: 0.18 | C10: 1.571 | D10: =PI()/2 -> 1.5707963 | E10: 0.1 | F10: 0.08 | G10: 4.712 | H10: =PI()/2 -> 1.5707963 | I10: 0 | J10: 0 | K10: 0 | L10: -0.00089414953 | M10: -0.18082152 | N10: 0.008007491 | O10: -0.40553841 | P10: 0.058199946 | Q10: 0.51686221 | R10: 0 | S10: -0.2033 | T10: -0.0001 | U10: -0.5104 | V10: -0.0002 | W10: 0.6193 | X10: =ABS(L10-R10) -> 0.00089414953 | Y10: =ABS(M10-S10) -> 0.022478477 | Z10: =ABS(N10-T10) -> 0.008107491 | AA10: =ABS(O10-U10) -> 0.10486159 | AB10: =ABS(P10-V10) -> 0.058399946 | AC10: =ABS(Q10-W10) -> 0.10243779
A11: 0.3 | B11: 0.18 | C11: 1.571 | D11: =PI()/2 -> 1.5707963 | E11: 0.9 | F11: 0.08 | G11: 4.712 | H11: =PI()/2 -> 1.5707963 | I11: 1 | J11: 0 | K11: 0 | L11: 0.00024180603 | M11: 0.073132612 | N11: -0.0042187301 | O11: 0.042406578 | P11: -0.02149988 | Q11: -0.58056563 | R11: 0.0006 | S11: 0.0721 | T11: -0.0001 | U11: -0.0031 | V11: -0.0009 | W11: -0.6018 | X11: =ABS(L11-R11) -> 0.00035819397 | Y11: =ABS(M11-S11) -> 0.0010326118 | Z11: =ABS(N11-T11) -> 0.0041187301 | AA11: =ABS(O11-U11) -> 0.045506578 | AB11: =ABS(P11-V11) -> 0.02059988 | AC11: =ABS(Q11-W11) -> 0.021234369
A12: 0.9 | B12: 0.2 | C12: 1.571 | D12: =PI()/2 -> 1.5707963 | E12: 1 | F12: 0.02 | G12: 3.142 | H12: =PI()/2 -> 1.5707963 | I12: 0.4 | J12: 0 | K12: 0 | L12: -0.0001589302 | M12: -0.14518361 | N12: -0.10818373 | O12: -0.5584237 | P12: -0.97605288 | Q12: 0.27430844 | R12: 0.0022 | S12: -0.2213 | T12: -0.1089 | U12: -0.6623 | V12: -1.001 | W12: 0.6136 | X12: =ABS(L12-R12) -> 0.0023589302 | Y12: =ABS(M12-S12) -> 0.076116392 | Z12: =ABS(N12-T12) -> 0.00071626588 | AA12: =ABS(O12-U12) -> 0.1038763 | AB12: =ABS(P12-V12) -> 0.02494712 | AC12: =ABS(Q12-W12) -> 0.33929156
A13: 0.1 | B13: 0.2 | C13: 1.571 | D13: =PI()/2 -> 1.5707963 | E13: 0.3 | F13: 0.08 | G13: 3.142 | H13: =PI()/2 -> 1.5707963 | I13: 0.2 | J13: 0 | K13: 0 | L13: -0.0001415771 | M13: 0.0045513404 | N13: -0.049289763 | O13: 0.026178073 | P13: -0.27640635 | Q13: -0.036308467 | R13: 0.0002 | S13: -0.0287 | T13: -0.0509 | U13: -0.0216 | V13: -0.2995 | W13: 0.0991 | X13: =ABS(L13-R13) -> 0.0003415771 | Y13: =ABS(M13-S13) -> 0.03325134 | Z13: =ABS(N13-T13) -> 0.001610237 | AA13: =ABS(O13-U13) -> 0.047778073 | AB13: =ABS(P13-V13) -> 0.023093652 | AC13: =ABS(Q13-W13) -> 0.13540847
A14: 0.9 | B14: 0.2 | C14: 1.571 | D14: =PI()/2 -> 1.5707963 | E14: 0.3 | F14: 0.02 | G14: 4.712 | H14: =PI()/2 -> 1.5707963 | I14: 1.4 | J14: 0 | K14: 0 | L14: 0.0092607206 | M14: -0.11755939 | N14: -0.0084324358 | O14: -0.58649874 | P14: -0.05003164 | Q14: 0.042876139 | R14: 0.0077 | S14: -0.1855 | T14: -0.0003 | U14: -0.6323 | V14: -0.0247 | W14: 0.297 | X14: =ABS(L14-R14) -> 0.0015607206 | Y14: =ABS(M14-S14) -> 0.067940612 | Z14: =ABS(N14-T14) -> 0.0081324358 | AA14: =ABS(O14-U14) -> 0.045801263 | AB14: =ABS(P14-V14) -> 0.02533164 | AC14: =ABS(Q14-W14) -> 0.25412386
... A42: 0.2 | B42: 0.2 | C42: 4.712 | D42: =PI()/2 -> 1.5707963 | E42: 0.1 | F42: 0.08 | G42: 3.927 | H42: =PI()/2 -> 1.5707963 | I42: 0 | J42: 0 | K42: 0 | L42: 0.00022576435 | M42: 0.054294631 | N42: -0.014319235 | O42: -0.0385371 | P42: -0.08568342 | Q42: -0.20783865 | R42: 0 | S42: 0.069 | T42: -0.012 | U42: -0.0482 | V42: -0.0704 | W42: -0.2664 | X42: =ABS(L42-R42) -> 0.00022576435 | Y42: =ABS(M42-S42) -> 0.014705369 | Z42: =ABS(N42-T42) -> 0.0023192345 | AA42: =ABS(O42-U42) -> 0.0096629 | AB42: =ABS(P42-V42) -> 0.01528342 | AC42: =ABS(Q42-W42) -> 0.058561345
X44: =AVERAGE(X3:X42) -> 0.0013409449 | Y44: =AVERAGE(Y3:Y42) -> 0.017838622 | Z44: =AVERAGE(Z3:Z42) -> 0.0081971453 | AA44: =AVERAGE(AA3:AA42) -> 0.065999681 | AB44: =AVERAGE(AB3:AB42) -> 0.042622724 | AC44: =AVERAGE(AC3:AC42) -> 0.086322411

Sheet Distal Vali (double, simulated)
A1: Ground Truth | L1: 6-Axis FT Sensor | R1: SoRoSim get_distal_value | AA1: Distal Errors | AI1: Stats
A2: F1 (N) | B2: s1 (m) | C2: el1 (rad) | D2: az1 (rad) | E2: F2 (N) | F2: s2 (m) | G2: el2 (rad) | H2: az2 (rad) | I2: tau1 (N) | J2: tau2 (N) | K2: tau3 (N) | L2: Tx (Nm) | M2: Ty (Nm) | N2: Tz(Nm) | O2: Fx (N) | P2: Fy (N) | Q2: Fz (N) | R2: F1 (N) | S2: s1 (m) | T2: el1 (rad) | U2: az1 (rad) | V2: F2 (N) | W2: s2 (m) | X2: el2 (rad) | Y2: az2 (rad) | Z2: f_final | AA2: F1 (N) | AB2: s1 (m) | AC2: el1 (rad) | AD2: az1 (rad) | AE2: F2 (N) | AF2: s2 (m) | AG2: el2 (rad) | AH2: az2 (rad) | AI2: force_error | AJ2: position_error | AK2: angle_error | AL2: min_f | AN2: Absolute Mean Error
A3: ='Proximal Validation (double)'!A3 -> 0.2 | B3: ='Proximal Validation (double)'!B3 -> 0.1 | C3: ='Proximal Validation (double)'!C3 -> 1.571 | D3: ='Proximal Validation (double)'!D3 -> 1.5707963 | E3: ='Proximal Validation (double)'!E3 -> 1 | F3: ='Proximal Validation (double)'!F3 -> 0.04 | G3: ='Proximal Validation (double)'!G3 -> 3.142 | H3: ='Proximal Validation (double)'!H3 -> 1.5707963 | ... K3: ='Proximal Validation (double)'!K3 -> 0 | R3: 0.72402043 | S3: 0.0552445 | T3: 2.4520908 | U3: 1.5707963 | V3: 0.51299035 | W3: 0.020997154 | X3: 3.6758994 | Y3: 1.5707963 | Z3: 3.1328117e-08 | AA3: =R3-A3 -> 0.52402043 | AB3: =S3-B3 -> -0.0447555 | AC3: =T3-C3 -> 0.88109081 | AD3: =U3-D3 -> 0 | AE3: =V3-E3 -> -0.48700965 | AF3: =W3-F3 -> -0.019002846 | AG3: =X3-G3 -> 0.53389939 | AH3: =Y3-H3 -> 0 | AI3: =AVERAGE(ABS(AA3),ABS(AE3)) -> 0.50551504 | AJ3: =AVERAGE(ABS(AB3),ABS(AF3)) -> 0.031879173 | AK3: =AVERAGE(ABS(AC3),ABS(AG3)) -> 0.7074951 | AL3: =MIN(A3,E3) -> 0.2 | AN3: F1 (N) | AO3: s1 (m) | AP3: el1 (rad) | AQ3: az1 (rad) | AR3: F2 (N) | AS3: s2 (m) | AT3: el2 (rad) | AU3: az2 (rad)
A4: ='Proximal Validation (double)'!A4 -> 1 | B4: ='Proximal Validation (double)'!B4 -> 0.1 | C4: ='Proximal Validation (double)'!C4 -> 1.571 | D4: ='Proximal Validation (double)'!D4 -> 1.5707963 | E4: ='Proximal Validation (double)'!E4 -> 1 | F4: ='Proximal Validation (double)'!F4 -> 0.08 | G4: ='Proximal Validation (double)'!G4 -> 3.142 | H4: ='Proximal Validation (double)'!H4 -> 1.5707963 | ... K4: ='Proximal Validation (double)'!K4 -> 0 | R4: 0.80543713 | S4: 0.10820832 | T4: 1.8556018 | U4: 1.5707963 | V4: 0.80650217 | W4: 0.071660668 | X4: 2.8566709 | Y4: 1.5707963 | Z4: 1.405474e-08 | AA4: =R4-A4 -> -0.19456287 | AB4: =S4-B4 -> 0.0082083237 | AC4: =T4-C4 -> 0.28460178 | AD4: =U4-D4 -> 0 | AE4: =V4-E4 -> -0.19349783 | AF4: =W4-F4 -> -0.0083393322 | AG4: =X4-G4 -> -0.28532913 | AH4: =Y4-H4 -> 0 | AI4: =AVERAGE(ABS(AA4),ABS(AE4)) -> 0.19403035 | AJ4: =AVERAGE(ABS(AB4),ABS(AF4)) -> 0.008273828 | AK4: =AVERAGE(ABS(AC4),ABS(AG4)) -> 0.28496545 | AL4: =MIN(A4,E4) -> 1 | AN4: {=AVERAGE(ABS(AA3:AA42))} -> 0.22571672 | AO4: {=AVERAGE(ABS(AB3:AB42))} -> 0.03094346 | AP4: {=AVERAGE(ABS(AC3:AC42))} -> 0.35897313 | AQ4: {=AVERAGE(ABS(AD3:AD42))} -> 0 | AR4: {=AVERAGE(ABS(AE3:AE42))} -> 0.21049436 | AS4: {=AVERAGE(ABS(AF3:AF42))} -> 0.029710517 | AT4: {=AVERAGE(ABS(AG3:AG42))} -> 0.52874467 | AU4: {=AVERAGE(ABS(AH3:AH42))} -> 0
A5: ='Proximal Validation (double)'!A5 -> 0.5 | B5: ='Proximal Validation (double)'!B5 -> 0.1 | C5: ='Proximal Validation (double)'!C5 -> 1.571 | D5: ='Proximal Validation (double)'!D5 -> 1.5707963 | E5: ='Proximal Validation (double)'!E5 -> 0.2 | F5: ='Proximal Validation (double)'!F5 -> 0.02 | G5: ='Proximal Validation (double)'!G5 -> 3.927 | H5: ='Proximal Validation (double)'!H5 -> 1.5707963 | ... K5: ='Proximal Validation (double)'!K5 -> 0 | R5: 0.26916403 | S5: 0.16720341 | T5: 0.4630939 | U5: 1.5707963 | V5: 0.45064398 | W5: 0.1127292 | X5: 2.5823832 | Y5: 1.5707963 | Z5: 5.5404561e-08 | AA5: =R5-A5 -> -0.23083597 | AB5: =S5-B5 -> 0.067203413 | AC5: =T5-C5 -> -1.1079061 | AD5: =U5-D5 -> 0 | AE5: =V5-E5 -> 0.25064398 | AF5: =W5-F5 -> 0.092729196 | AG5: =X5-G5 -> -1.3446168 | AH5: =Y5-H5 -> 0 | AI5: =AVERAGE(ABS(AA5),ABS(AE5)) -> 0.24073997 | AJ5: =AVERAGE(ABS(AB5),ABS(AF5)) -> 0.079966305 | AK5: =AVERAGE(ABS(AC5),ABS(AG5)) -> 1.2262614 | AL5: =MIN(A5,E5) -> 0.2 | AN5: Absolute Mean Error (Across Both Forces)
A6: ='Proximal Validation (double)'!A6 -> 0.9 | B6: ='Proximal Validation (double)'!B6 -> 0.1 | C6: ='Proximal Validation (double)'!C6 -> 1.571 | D6: ='Proximal Validation (double)'!D6 -> 1.5707963 | E6: ='Proximal Validation (double)'!E6 -> 0.2 | F6: ='Proximal Validation (double)'!F6 -> 0.08 | G6: ='Proximal Validation (double)'!G6 -> 4.712 | H6: ='Proximal Validation (double)'!H6 -> 1.5707963 | ... K6: ='Proximal Validation (double)'!K6 -> 0 | R6: 0.3302633 | S6: 0.10583976 | T6: 3.2787607 | U6: 1.5707963 | V6: 0.81373513 | W6: 0.10570429 | X6: 1.1574205 | Y6: 1.5707963 | Z6: 6.1985455e-10 | AA6: =R6-A6 -> -0.5697367 | AB6: =S6-B6 -> 0.0058397565 | AC6: =T6-C6 -> 1.7077607 | AD6: =U6-D6 -> 0 | AE6: =V6-E6 -> 0.61373513 | AF6: =W6-F6 -> 0.02570429 | AG6: =X6-G6 -> -3.5545795 | AH6: =Y6-H6 -> 0 | AI6: =AVERAGE(ABS(AA6),ABS(AE6)) -> 0.59173592 | AJ6: =AVERAGE(ABS(AB6),ABS(AF6)) -> 0.015772023 | AK6: =AVERAGE(ABS(AC6),ABS(AG6)) -> 2.6311701 | AL6: =MIN(A6,E6) -> 0.2 | AN6: force_error | AO6: position_error | AP6: angle_error
A7: ='Proximal Validation (double)'!A7 -> 0.1 | B7: ='Proximal Validation (double)'!B7 -> 0.12 | C7: ='Proximal Validation (double)'!C7 -> 1.571 | D7: ='Proximal Validation (double)'!D7 -> 1.5707963 | E7: ='Proximal Validation (double)'!E7 -> 1 | F7: ='Proximal Validation (double)'!F7 -> 0.06 | G7: ='Proximal Validation (double)'!G7 -> 3.927 | H7: ='Proximal Validation (double)'!H7 -> 1.5707963 | ... K7: ='Proximal Validation (double)'!K7 -> 0 | R7: 0.70609936 | S7: 0.059973476 | T7: 2.9586795 | U7: 1.5707963 | V7: 0.73564243 | W7: 0.051771671 | X7: 4.6950019 | Y7: 1.5707963 | Z7: 2.9796245e-08 | AA7: =R7-A7 -> 0.60609936 | AB7: =S7-B7 -> -0.060026524 | AC7: =T7-C7 -> 1.3876795 | AD7: =U7-D7 -> 0 | AE7: =V7-E7 -> -0.26435757 | AF7: =W7-F7 -> -0.0082283292 | AG7: =X7-G7 -> 0.76800193 | AH7: =Y7-H7 -> 0 | AI7: =AVERAGE(ABS(AA7),ABS(AE7)) -> 0.43522847 | AJ7: =AVERAGE(ABS(AB7),ABS(AF7)) -> 0.034127427 | AK7: =AVERAGE(ABS(AC7),ABS(AG7)) -> 1.0778407 | AL7: =MIN(A7,E7) -> 0.1 | AN7: =AVERAGE(AN4,AR4) -> 0.21810554 | AO7: =AVERAGE(AO4,AS4) -> 0.030326988 | AP7: =AVERAGE(AP4,AT4) -> 0.4438589
A8: ='Proximal Validation (double)'!A8 -> 0.8 | B8: ='Proximal Validation (double)'!B8 -> 0.16 | C8: ='Proximal Validation (double)'!C8 -> 1.571 | D8: ='Proximal Validation (double)'!D8 -> 1.5707963 | E8: ='Proximal Validation (double)'!E8 -> 0.8 | F8: ='Proximal Validation (double)'!F8 -> 0.06 | G8: ='Proximal Validation (double)'!G8 -> 3.927 | H8: ='Proximal Validation (double)'!H8 -> 1.5707963 | ... K8: ='Proximal Validation (double)'!K8 -> 0 | R8: 0.59796517 | S8: 0.17307097 | T8: 1.8198679 | U8: 1.5707963 | V8: 0.55497423 | W8: 0.02093923 | X8: 3.8426223 | Y8: 1.5707963 | Z8: 5.6810497e-08 | AA8: =R8-A8 -> -0.20203483 | AB8: =S8-B8 -> 0.013070974 | AC8: =T8-C8 -> 0.24886786 | AD8: =U8-D8 -> 0 | AE8: =V8-E8 -> -0.24502577 | AF8: =W8-F8 -> -0.03906077 | AG8: =X8-G8 -> -0.084377742 | AH8: =Y8-H8 -> 0 | AI8: =AVERAGE(ABS(AA8),ABS(AE8)) -> 0.2235303 | AJ8: =AVERAGE(ABS(AB8),ABS(AF8)) -> 0.026065872 | AK8: =AVERAGE(ABS(AC8),ABS(AG8)) -> 0.1666228 | AL8: =MIN(A8,E8) -> 0.8 | AN8: with 0.1 cuttof
A9: ='Proximal Validation (double)'!A9 -> 0.1 | B9: ='Proximal Validation (double)'!B9 -> 0.18 | C9: ='Proximal Validation (double)'!C9 -> 1.571 | D9: ='Proximal Validation (double)'!D9 -> 1.5707963 | E9: ='Proximal Validation (double)'!E9 -> 0.1 | F9: ='Proximal Validation (double)'!F9 -> 0.02 | G9: ='Proximal Validation (double)'!G9 -> 3.142 | H9: ='Proximal Validation (double)'!H9 -> 1.5707963 | ... K9: ='Proximal Validation (double)'!K9 -> 0 | R9: 0.58495958 | S9: 0.11082423 | T9: 0.89894756 | U9: 1.5707963 | V9: 0.58591178 | W9: 0.091256717 | X9: 3.7985208 | Y9: 1.5707963 | Z9: 2.3551041e-08 | AA9: =R9-A9 -> 0.48495958 | AB9: =S9-B9 -> -0.069175772 | AC9: =T9-C9 -> -0.67205244 | AD9: =U9-D9 -> 0 | AE9: =V9-E9 -> 0.48591178 | AF9: =W9-F9 -> 0.071256717 | AG9: =X9-G9 -> 0.65652079 | AH9: =Y9-H9 -> 0 | AI9: =AVERAGE(ABS(AA9),ABS(AE9)) -> 0.48543568 | AJ9: =AVERAGE(ABS(AB9),ABS(AF9)) -> 0.070216244 | AK9: =AVERAGE(ABS(AC9),ABS(AG9)) -> 0.66428661 | AL9: =MIN(A9,E9) -> 0.1 | AN9: =AVERAGE(AI3,AI4,AI5,AI6,AI8,AI11,AI12,AI14,AI15,AI17,AI18,AI20,AI23,AI24,AI25,AI26,AI29,AI30,AI32,AI35,AI36,AI37,AI38,AI40,AI41) -> 0.15284886 | AO9: =AVERAGE(AJ3,AJ4,AJ5,AJ6,AJ8,AJ11,AJ12,AJ14,AJ15,AJ17,AJ18,AJ20,AJ23,AJ24,AJ25,AJ26,AJ29,AJ30,AJ32,AJ35,AJ36,AJ37,AJ38,AJ40,AJ41) -> 0.025376973 | AP9: =AVERAGE(AK3,AK4,AK5,AK6,AK8,AK11,AK12,AK14,AK15,AK17,AK18,AK20,AK23,AK24,AK25,AK26,AK29,AK30,AK32,AK35,AK36,AK37,AK38,AK40,AK41) -> 0.33220058
A10: ='Proximal Validation (double)'!A10 -> 0.9 | B10: ='Proximal Validation (double)'!B10 -> 0.18 | C10: ='Proximal Validation (double)'!C10 -> 1.571 | D10: ='Proximal Validation (double)'!D10 -> 1.5707963 | E10: ='Proximal Validation (double)'!E10 -> 0.1 | F10: ='Proximal Validation (double)'!F10 -> 0.08 | G10: ='Proximal Validation (double)'!G10 -> 4.712 | H10: ='Proximal Validation (double)'!H10 -> 1.5707963 | ... K10: ='Proximal Validation (double)'!K10 -> 0 | R10: 0.1902122 | S10: 0.19175285 | T10: 3.5499847 | U10: 1.5707963 | V10: 0.89517591 | W10: 0.19161291 | X10: 1.3748819 | Y10: 1.5707963 | Z10: 4.498874e-09 | AA10: =R10-A10 -> -0.7097878 | AB10: =S10-B10 -> 0.011752854 | AC10: =T10-C10 -> 1.9789847 | AD10: =U10-D10 -> 0 | AE10: =V10-E10 -> 0.79517591 | AF10: =W10-F10 -> 0.11161291 | AG10: =X10-G10 -> -3.3371181 | AH10: =Y10-H10 -> 0 | AI10: =AVERAGE(ABS(AA10),ABS(AE10)) -> 0.75248185 | AJ10: =AVERAGE(ABS(AB10),ABS(AF10)) -> 0.06168288 | AK10: =AVERAGE(ABS(AC10),ABS(AG10)) -> 2.6580514 | AL10: =MIN(A10,E10) -> 0.1 | AN10: with 0.2 cuttof
A11: ='Proximal Validation (double)'!A11 -> 0.3 | B11: ='Proximal Validation (double)'!B11 -> 0.18 | C11: ='Proximal Validation (double)'!C11 -> 1.571 | D11: ='Proximal Validation (double)'!D11 -> 1.5707963 | E11: ='Proximal Validation (double)'!E11 -> 0.9 | F11: ='Proximal Validation (double)'!F11 -> 0.08 | G11: ='Proximal Validation (double)'!G11 -> 4.712 | H11: ='Proximal Validation (double)'!H11 -> 1.5707963 | ... K11: ='Proximal Validation (double)'!K11 -> 0 | R11: 0.24986239 | S11: 0.1715676 | T11: 1.5694355 | U11: 1.5707963 | V11: 0.85064549 | W11: 0.07157796 | X11: 4.7113271 | Y11: 1.5707963 | Z11: 1.4358013e-08 | AA11: =R11-A11 -> -0.050137611 | AB11: =S11-B11 -> -0.0084323979 | AC11: =T11-C11 -> -0.0015644578 | AD11: =U11-D11 -> 0 | AE11: =V11-E11 -> -0.049354506 | AF11: =W11-F11 -> -0.0084220396 | AG11: =X11-G11 -> -0.00067293774 | AH11: =Y11-H11 -> 0 | AI11: =AVERAGE(ABS(AA11),ABS(AE11)) -> 0.049746059 | AJ11: =AVERAGE(ABS(AB11),ABS(AF11)) -> 0.0084272187 | AK11: =AVERAGE(ABS(AC11),ABS(AG11)) -> 0.0011186978 | AL11: =MIN(A11,E11) -> 0.3 | AN11: =AVERAGE(AI4,AI8,AI11,AI12,AI14,AI15,AI17,AI18,AI20,AI25,AI26,AI30,AI32,AI35,AI36,AI37,AI40,AI41) -> 0.10491483 | AO11: =AVERAGE(AJ4,AJ8,AJ11,AJ12,AJ14,AJ15,AJ17,AJ18,AJ20,AJ25,AJ26,AJ30,AJ32,AJ35,AJ36,AJ37,AJ40,AJ41) -> 0.018914551 | AP11: =AVERAGE(AK4,AK8,AK11,AK12,AK14,AK15,AK17,AK18,AK20,AK25,AK26,AK30,AK32,AK35,AK36,AK37,AK40,AK41) -> 0.12173739
A12: ='Proximal Validation (double)'!A12 -> 0.9 | B12: ='Proximal Validation (double)'!B12 -> 0.2 | C12: ='Proximal Validation (double)'!C12 -> 1.571 | D12: ='Proximal Validation (double)'!D12 -> 1.5707963 | E12: ='Proximal Validation (double)'!E12 -> 1 | F12: ='Proximal Validation (double)'!F12 -> 0.02 | G12: ='Proximal Validation (double)'!G12 -> 3.142 | H12: ='Proximal Validation (double)'!H12 -> 1.5707963 | ... K12: ='Proximal Validation (double)'!K12 -> 0 | R12: 0.912986 | S12: 0.1937946 | T12: 1.5725636 | U12: 1.5707963 | V12: 0.99921403 | W12: 0.020000001 | X12: 3.1588654 | Y12: 1.5707963 | Z12: 7.5700692e-08 | AA12: =R12-A12 -> 0.012986002 | AB12: =S12-B12 -> -0.006205396 | AC12: =T12-C12 -> 0.0015635637 | AD12: =U12-D12 -> 0 | AE12: =V12-E12 -> -0.00078596509 | AF12: =W12-F12 -> 9.5178815e-10 | AG12: =X12-G12 -> 0.016865381 | AH12: =Y12-H12 -> 0 | AI12: =AVERAGE(ABS(AA12),ABS(AE12)) -> 0.0068859838 | AJ12: =AVERAGE(ABS(AB12),ABS(AF12)) -> 0.0031026985 | AK12: =AVERAGE(ABS(AC12),ABS(AG12)) -> 0.0092144722 | AL12: =MIN(A12,E12) -> 0.9 | AN12: 0.2 cutoof + no close
A13: ='Proximal Validation (double)'!A13 -> 0.1 | B13: ='Proximal Validation (double)'!B13 -> 0.2 | C13: ='Proximal Validation (double)'!C13 -> 1.571 | D13: ='Proximal Validation (double)'!D13 -> 1.5707963 | E13: ='Proximal Validation (double)'!E13 -> 0.3 | F13: ='Proximal Validation (double)'!F13 -> 0.08 | G13: ='Proximal Validation (double)'!G13 -> 3.142 | H13: ='Proximal Validation (double)'!H13 -> 1.5707963 | ... K13: ='Proximal Validation (double)'!K13 -> 0 | R13: 0.582585 | S13: 0.11872247 | T13: 1.0461197 | U13: 1.5707963 | V13: 0.71681921 | W13: 0.099074786 | X13: 3.7410144 | Y13: 1.5707963 | Z13: 5.3719826e-09 | AA13: =R13-A13 -> 0.482585 | AB13: =S13-B13 -> -0.081277535 | AC13: =T13-C13 -> -0.52488028 | AD13: =U13-D13 -> 0 | AE13: =V13-E13 -> 0.41681921 | AF13: =W13-F13 -> 0.019074786 | AG13: =X13-G13 -> 0.59901443 | AH13: =Y13-H13 -> 0 | AI13: =AVERAGE(ABS(AA13),ABS(AE13)) -> 0.4497021 | AJ13: =AVERAGE(ABS(AB13),ABS(AF13)) -> 0.05017616 | AK13: =AVERAGE(ABS(AC13),ABS(AG13)) -> 0.56194736 | AL13: =MIN(A13,E13) -> 0.1 | AN13: =AVERAGE(AI8,AI11,AI12,AI14,AI15,AI17,AI18,AI20,AI26,AI30,AI32,AI35,AI37,AI40,AI41) -> 0.092166424 | AO13: =AVERAGE(AJ8,AJ11,AJ12,AJ14,AJ15,AJ17,AJ18,AJ20,AJ26,AJ30,AJ32,AJ35,AJ37,AJ40,AJ41) -> 0.019408169 | AP13: =AVERAGE(AK8,AK11,AK12,AK14,AK15,AK17,AK18,AK20,AK26,AK30,AK32,AK35,AK37,AK40,AK41) -> 0.092247072
A14: ='Proximal Validation (double)'!A14 -> 0.9 | B14: ='Proximal Validation (double)'!B14 -> 0.2 | C14: ='Proximal Validation (double)'!C14 -> 1.571 | D14: ='Proximal Validation (double)'!D14 -> 1.5707963 | E14: ='Proximal Validation (double)'!E14 -> 0.3 | F14: ='Proximal Validation (double)'!F14 -> 0.02 | G14: ='Proximal Validation (double)'!G14 -> 4.712 | H14: ='Proximal Validation (double)'!H14 -> 1.5707963 | ... K14: ='Proximal Validation (double)'!K14 -> 0 | R14: 0.90193284 | S14: 0.19893349 | T14: 1.5711347 | U14: 1.5707963 | V14: 0.30209589 | W14: 0.020243284 | X14: 4.7123231 | Y14: 1.5707963 | Z14: 1.2457203e-09 | AA14: =R14-A14 -> 0.0019328435 | AB14: =S14-B14 -> -0.0010665115 | AC14: =T14-C14 -> 0.00013474529 | AD14: =U14-D14 -> 0 | AE14: =V14-E14 -> 0.0020958859 | AF14: =W14-F14 -> 0.00024328416 | AG14: =X14-G14 -> 0.00032309171 | AH14: =Y14-H14 -> 0 | AI14: =AVERAGE(ABS(AA14),ABS(AE14)) -> 0.0020143647 | AJ14: =AVERAGE(ABS(AB14),ABS(AF14)) -> 0.00065489784 | AK14: =AVERAGE(ABS(AC14),ABS(AG14)) -> 0.0002289185 | AL14: =MIN(A14,E14) -> 0.3
A15: ='Proximal Validation (double)'!A15 -> 0.9 | B15: ='Proximal Validation (double)'!B15 -> 0.1 | C15: ='Proximal Validation (double)'!C15 -> 2.356 | D15: ='Proximal Validation (double)'!D15 -> 1.5707963 | E15: ='Proximal Validation (double)'!E15 -> 0.9 | F15: ='Proximal Validation (double)'!F15 -> 0.02 | G15: ='Proximal Validation (double)'!G15 -> 4.712 | H15: ='Proximal Validation (double)'!H15 -> 1.5707963 | ... K15: ='Proximal Validation (double)'!K15 -> 0 | R15: 0.48777438 | S15: 0.16761235 | T15: 2.3567286 | U15: 1.5707963 | V15: 0.67195457 | W15: 0.020007018 | X15: 4.2562617 | Y15: 1.5707963 | Z15: 3.1640606e-07 | AA15: =R15-A15 -> -0.41222562 | AB15: =S15-B15 -> 0.067612348 | AC15: =T15-C15 -> 0.00072864331 | AD15: =U15-D15 -> 0 | AE15: =V15-E15 -> -0.22804543 | AF15: =W15-F15 -> 7.018154e-06 | AG15: =X15-G15 -> -0.45573826 | AH15: =Y15-H15 -> 0 | AI15: =AVERAGE(ABS(AA15),ABS(AE15)) -> 0.32013553 | AJ15: =AVERAGE(ABS(AB15),ABS(AF15)) -> 0.033809683 | AK15: =AVERAGE(ABS(AC15),ABS(AG15)) -> 0.22823345 | AL15: =MIN(A15,E15) -> 0.9
A16: ='Proximal Validation (double)'!A16 -> 0.4 | B16: ='Proximal Validation (double)'!B16 -> 0.12 | C16: ='Proximal Validation (double)'!C16 -> 2.356 | D16: ='Proximal Validation (double)'!D16 -> 1.5707963 | E16: ='Proximal Validation (double)'!E16 -> 0.1 | F16: ='Proximal Validation (double)'!F16 -> 0.06 | G16: ='Proximal Validation (double)'!G16 -> 3.142 | H16: ='Proximal Validation (double)'!H16 -> 1.5707963 | ... K16: ='Proximal Validation (double)'!K16 -> 0 | R16: 0.29366715 | S16: 0.12128405 | T16: 1.9966101 | U16: 1.5707963 | V16: 0.261961 | W16: 0.096509797 | X16: 3.0827775 | Y16: 1.5707963 | Z16: 1.9942343e-09 | AA16: =R16-A16 -> -0.10633285 | AB16: =S16-B16 -> 0.0012840472 | AC16: =T16-C16 -> -0.35938992 | AD16: =U16-D16 -> 0 | AE16: =V16-E16 -> 0.161961 | AF16: =W16-F16 -> 0.036509797 | AG16: =X16-G16 -> -0.059222451 | AH16: =Y16-H16 -> 0 | AI16: =AVERAGE(ABS(AA16),ABS(AE16)) -> 0.13414693 | AJ16: =AVERAGE(ABS(AB16),ABS(AF16)) -> 0.018896922 | AK16: =AVERAGE(ABS(AC16),ABS(AG16)) -> 0.20930618 | AL16: =MIN(A16,E16) -> 0.1
A17: ='Proximal Validation (double)'!A17 -> 1 | B17: ='Proximal Validation (double)'!B17 -> 0.14 | C17: ='Proximal Validation (double)'!C17 -> 2.356 | D17: ='Proximal Validation (double)'!D17 -> 1.5707963 | E17: ='Proximal Validation (double)'!E17 -> 0.4 | F17: ='Proximal Validation (double)'!F17 -> 0.04 | G17: ='Proximal Validation (double)'!G17 -> 3.927 | H17: ='Proximal Validation (double)'!H17 -> 1.5707963 | ... K17: ='Proximal Validation (double)'!K17 -> 0 | R17: 0.85651596 | S17: 0.15985977 | T17: 2.407478 | U17: 1.5707963 | V17: 0.38888866 | W17: 0.025796373 | X17: 3.5237205 | Y17: 1.5707963 | Z17: 6.5751522e-08 | AA17: =R17-A17 -> -0.14348404 | AB17: =S17-B17 -> 0.019859768 | AC17: =T17-C17 -> 0.051477977 | AD17: =U17-D17 -> 0 | AE17: =V17-E17 -> -0.011111344 | AF17: =W17-F17 -> -0.014203627 | AG17: =X17-G17 -> -0.40327954 | AH17: =Y17-H17 -> 0 | AI17: =AVERAGE(ABS(AA17),ABS(AE17)) -> 0.07729769 | AJ17: =AVERAGE(ABS(AB17),ABS(AF17)) -> 0.017031697 | AK17: =AVERAGE(ABS(AC17),ABS(AG17)) -> 0.22737876 | AL17: =MIN(A17,E17) -> 0.4
A18: ='Proximal Validation (double)'!A18 -> 0.4 | B18: ='Proximal Validation (double)'!B18 -> 0.18 | C18: ='Proximal Validation (double)'!C18 -> 2.356 | D18: ='Proximal Validation (double)'!D18 -> 1.5707963 | E18: ='Proximal Validation (double)'!E18 -> 0.7 | F18: ='Proximal Validation (double)'!F18 -> 0.04 | G18: ='Proximal Validation (double)'!G18 -> 3.142 | H18: ='Proximal Validation (double)'!H18 -> 1.5707963 | ... K18: ='Proximal Validation (double)'!K18 -> 0 | R18: 0.91331588 | S18: 0.10143053 | T18: 2.3180348 | U18: 1.5707963 | V18: 0.53031257 | W18: 0.044074814 | X18: 3.9682446 | Y18: 1.5707963 | Z18: 3.575745e-11 | AA18: =R18-A18 -> 0.51331588 | AB18: =S18-B18 -> -0.078569473 | AC18: =T18-C18 -> -0.037965188 | AD18: =U18-D18 -> 0 | AE18: =V18-E18 -> -0.16968743 | AF18: =W18-F18 -> 0.0040748142 | AG18: =X18-G18 -> 0.82624464 | AH18: =Y18-H18 -> 0 | AI18: =AVERAGE(ABS(AA18),ABS(AE18)) -> 0.34150166 | AJ18: =AVERAGE(ABS(AB18),ABS(AF18)) -> 0.041322144 | AK18: =AVERAGE(ABS(AC18),ABS(AG18)) -> 0.43210491 | AL18: =MIN(A18,E18) -> 0.4
A19: ='Proximal Validation (double)'!A19 -> 0.1 | B19: ='Proximal Validation (double)'!B19 -> 0.18 | C19: ='Proximal Validation (double)'!C19 -> 2.356 | D19: ='Proximal Validation (double)'!D19 -> 1.5707963 | E19: ='Proximal Validation (double)'!E19 -> 0.2 | F19: ='Proximal Validation (double)'!F19 -> 0.06 | G19: ='Proximal Validation (double)'!G19 -> 4.712 | H19: ='Proximal Validation (double)'!H19 -> 1.5707963 | ... K19: ='Proximal Validation (double)'!K19 -> 0 | R19: 0.51282581 | S19: 0.14703435 | T19: 1.8540572 | U19: 1.5707963 | V19: 0.62576632 | W19: 0.11519254 | X19: 4.828571 | Y19: 1.5707963 | Z19: 1.8167426e-09 | AA19: =R19-A19 -> 0.41282581 | AB19: =S19-B19 -> -0.032965652 | AC19: =T19-C19 -> -0.50194278 | AD19: =U19-D19 -> 0 | AE19: =V19-E19 -> 0.42576632 | AF19: =W19-F19 -> 0.055192538 | AG19: =X19-G19 -> 0.11657098 | AH19: =Y19-H19 -> 0 | AI19: =AVERAGE(ABS(AA19),ABS(AE19)) -> 0.41929606 | AJ19: =AVERAGE(ABS(AB19),ABS(AF19)) -> 0.044079095 | AK19: =AVERAGE(ABS(AC19),ABS(AG19)) -> 0.30925688 | AL19: =MIN(A19,E19) -> 0.1
A20: ='Proximal Validation (double)'!A20 -> 0.9 | B20: ='Proximal Validation (double)'!B20 -> 0.2 | C20: ='Proximal Validation (double)'!C20 -> 2.356 | D20: ='Proximal Validation (double)'!D20 -> 1.5707963 | E20: ='Proximal Validation (double)'!E20 -> 0.3 | F20: ='Proximal Validation (double)'!F20 -> 0.06 | G20: ='Proximal Validation (double)'!G20 -> 3.142 | H20: ='Proximal Validation (double)'!H20 -> 1.5707963 | ... K20: ='Proximal Validation (double)'!K20 -> 0 | R20: 0.9033542 | S20: 0.19590396 | T20: 2.3481909 | U20: 1.5707963 | V20: 0.30114477 | W20: 0.064264263 | X20: 3.1704355 | Y20: 1.5707963 | Z20: 2.94794e-09 | AA20: =R20-A20 -> 0.0033541995 | AB20: =S20-B20 -> -0.0040960387 | AC20: =T20-C20 -> -0.0078091054 | AD20: =U20-D20 -> 0 | AE20: =V20-E20 -> 0.0011447744 | AF20: =W20-F20 -> 0.0042642631 | AG20: =X20-G20 -> 0.028435478 | AH20: =Y20-H20 -> 0 | AI20: =AVERAGE(ABS(AA20),ABS(AE20)) -> 0.002249487 | AJ20: =AVERAGE(ABS(AB20),ABS(AF20)) -> 0.0041801509 | AK20: =AVERAGE(ABS(AC20),ABS(AG20)) -> 0.018122291 | AL20: =MIN(A20,E20) -> 0.3
A21: ='Proximal Validation (double)'!A21 -> 0.1 | B21: ='Proximal Validation (double)'!B21 -> 0.1 | C21: ='Proximal Validation (double)'!C21 -> 3.142 | D21: ='Proximal Validation (double)'!D21 -> 1.5707963 | E21: ='Proximal Validation (double)'!E21 -> 0.3 | F21: ='Proximal Validation (double)'!F21 -> 0.08 | G21: ='Proximal Validation (double)'!G21 -> 3.927 | H21: ='Proximal Validation (double)'!H21 -> 1.5707963 | ... K21: ='Proximal Validation (double)'!K21 -> 0 | R21: 0.5040426 | S21: 0.079969627 | T21: 3.5852611 | U21: 1.5707963 | V21: 0.14320857 | W21: 0.06625358 | X21: 0.029350441 | Y21: 1.5707963 | Z21: 4.5059462e-10 | AA21: =R21-A21 -> 0.4040426 | AB21: =S21-B21 -> -0.020030373 | AC21: =T21-C21 -> 0.44326111 | AD21: =U21-D21 -> 0 | AE21: =V21-E21 -> -0.15679143 | AF21: =W21-F21 -> -0.01374642 | AG21: =X21-G21 -> -3.8976496 | AH21: =Y21-H21 -> 0 | AI21: =AVERAGE(ABS(AA21),ABS(AE21)) -> 0.28041702 | AJ21: =AVERAGE(ABS(AB21),ABS(AF21)) -> 0.016888396 | AK21: =AVERAGE(ABS(AC21),ABS(AG21)) -> 2.1704553 | AL21: =MIN(A21,E21) -> 0.1
A22: ='Proximal Validation (double)'!A22 -> 0.1 | B22: ='Proximal Validation (double)'!B22 -> 0.2 | C22: ='Proximal Validation (double)'!C22 -> 3.142 | D22: ='Proximal Validation (double)'!D22 -> 1.5707963 | E22: ='Proximal Validation (double)'!E22 -> 0.8 | F22: ='Proximal Validation (double)'!F22 -> 0.02 | G22: ='Proximal Validation (double)'!G22 -> 3.927 | H22: ='Proximal Validation (double)'!H22 -> 1.5707963 | ... K22: ='Proximal Validation (double)'!K22 -> 0 | R22: 0.18500725 | S22: 0.095021753 | T22: 2.5576798 | U22: 1.5707963 | V22: 0.8410095 | W22: 0.031197448 | X22: 4.0588268 | Y22: 1.5707963 | Z22: 1.5228861e-07 | AA22: =R22-A22 -> 0.085007255 | AB22: =S22-B22 -> -0.10497825 | AC22: =T22-C22 -> -0.58432019 | AD22: =U22-D22 -> 0 | AE22: =V22-E22 -> 0.0410095 | AF22: =W22-F22 -> 0.011197448 | AG22: =X22-G22 -> 0.13182677 | AH22: =Y22-H22 -> 0 | AI22: =AVERAGE(ABS(AA22),ABS(AE22)) -> 0.063008377 | AJ22: =AVERAGE(ABS(AB22),ABS(AF22)) -> 0.058087847 | AK22: =AVERAGE(ABS(AC22),ABS(AG22)) -> 0.35807348 | AL22: =MIN(A22,E22) -> 0.1
A23: ='Proximal Validation (double)'!A23 -> 0.9 | B23: ='Proximal Validation (double)'!B23 -> 0.1 | C23: ='Proximal Validation (double)'!C23 -> 3.927 | D23: ='Proximal Validation (double)'!D23 -> 1.5707963 | E23: ='Proximal Validation (double)'!E23 -> 0.2 | F23: ='Proximal Validation (double)'!F23 -> 0.02 | G23: ='Proximal Validation (double)'!G23 -> 3.142 | H23: ='Proximal Validation (double)'!H23 -> 1.5707963 | ... K23: ='Proximal Validation (double)'!K23 -> 0 | R23: 0.79071398 | S23: 0.10257958 | T23: 4.0159791 | U23: 1.5707963 | V23: 0.33006185 | W23: 0.047362099 | X23: 3.2314784 | Y23: 1.5707963 | Z23: 5.5030004e-09 | AA23: =R23-A23 -> -0.10928602 | AB23: =S23-B23 -> 0.0025795845 | AC23: =T23-C23 -> 0.088979059 | AD23: =U23-D23 -> 0 | AE23: =V23-E23 -> 0.13006185 | AF23: =W23-F23 -> 0.027362099 | AG23: =X23-G23 -> 0.089478398 | AH23: =Y23-H23 -> 0 | AI23: =AVERAGE(ABS(AA23),ABS(AE23)) -> 0.11967394 | AJ23: =AVERAGE(ABS(AB23),ABS(AF23)) -> 0.014970842 | AK23: =AVERAGE(ABS(AC23),ABS(AG23)) -> 0.089228729 | AL23: =MIN(A23,E23) -> 0.2
A24: ='Proximal Validation (double)'!A24 -> 0.2 | B24: ='Proximal Validation (double)'!B24 -> 0.12 | C24: ='Proximal Validation (double)'!C24 -> 3.927 | D24: ='Proximal Validation (double)'!D24 -> 1.5707963 | E24: ='Proximal Validation (double)'!E24 -> 0.2 | F24: ='Proximal Validation (double)'!F24 -> 0.02 | G24: ='Proximal Validation (double)'!G24 -> 4.712 | H24: ='Proximal Validation (double)'!H24 -> 1.5707963 | ... K24: ='Proximal Validation (double)'!K24 -> 0 | R24: 0.21564377 | S24: 0.1031366 | T24: 3.7465666 | U24: 1.5707963 | V24: 0.22170445 | W24: 0.037737512 | X24: 4.8747595 | Y24: 1.5707963 | Z24: 1.0224647e-08 | AA24: =R24-A24 -> 0.015643774 | AB24: =S24-B24 -> -0.016863398 | AC24: =T24-C24 -> -0.18043337 | AD24: =U24-D24 -> 0 | AE24: =V24-E24 -> 0.021704448 | AF24: =W24-F24 -> 0.017737512 | AG24: =X24-G24 -> 0.16275949 | AH24: =Y24-H24 -> 0 | AI24: =AVERAGE(ABS(AA24),ABS(AE24)) -> 0.018674111 | AJ24: =AVERAGE(ABS(AB24),ABS(AF24)) -> 0.017300455 | AK24: =AVERAGE(ABS(AC24),ABS(AG24)) -> 0.17159643 | AL24: =MIN(A24,E24) -> 0.2
A25: ='Proximal Validation (double)'!A25 -> 0.6 | B25: ='Proximal Validation (double)'!B25 -> 0.12 | C25: ='Proximal Validation (double)'!C25 -> 3.927 | D25: ='Proximal Validation (double)'!D25 -> 1.5707963 | E25: ='Proximal Validation (double)'!E25 -> 0.5 | F25: ='Proximal Validation (double)'!F25 -> 0.08 | G25: ='Proximal Validation (double)'!G25 -> 4.712 | H25: ='Proximal Validation (double)'!H25 -> 1.5707963 | ... K25: ='Proximal Validation (double)'!K25 -> 0 | R25: 0.73534641 | S25: 0.11208058 | T25: 3.8999395 | U25: 1.5707963 | V25: 0.43259203 | W25: 0.081724503 | X25: 4.9680882 | Y25: 1.5707963 | Z25: 6.929549e-10 | AA25: =R25-A25 -> 0.13534641 | AB25: =S25-B25 -> -0.0079194216 | AC25: =T25-C25 -> -0.027060538 | AD25: =U25-D25 -> 0 | AE25: =V25-E25 -> -0.067407974 | AF25: =W25-F25 -> 0.0017245034 | AG25: =X25-G25 -> 0.25608819 | AH25: =Y25-H25 -> 0 | AI25: =AVERAGE(ABS(AA25),ABS(AE25)) -> 0.10137719 | AJ25: =AVERAGE(ABS(AB25),ABS(AF25)) -> 0.0048219625 | AK25: =AVERAGE(ABS(AC25),ABS(AG25)) -> 0.14157436 | AL25: =MIN(A25,E25) -> 0.5
... A42: ='Proximal Validation (double)'!A42 -> 0.2 | B42: ='Proximal Validation (double)'!B42 -> 0.2 | C42: ='Proximal Validation (double)'!C42 -> 4.712 | D42: ='Proximal Validation (double)'!D42 -> 1.5707963 | E42: ='Proximal Validation (double)'!E42 -> 0.1 | F42: ='Proximal Validation (double)'!F42 -> 0.08 | G42: ='Proximal Validation (double)'!G42 -> 3.927 | H42: ='Proximal Validation (double)'!H42 -> 1.5707963 | ... K42: ='Proximal Validation (double)'!K42 -> 0 | R42: 0.20744144 | S42: 0.17984528 | T42: 5.1969871 | U42: 1.5707963 | V42: 0.18867449 | W42: 0.13791692 | X42: 3.6213467 | Y42: 1.5707963 | Z42: 8.149149e-10 | AA42: =R42-A42 -> 0.0074414412 | AB42: =S42-B42 -> -0.020154725 | AC42: =T42-C42 -> 0.48498712 | AD42: =U42-D42 -> 0 | AE42: =V42-E42 -> 0.088674491 | AF42: =W42-F42 -> 0.057916918 | AG42: =X42-G42 -> -0.30565327 | AH42: =Y42-H42 -> 0 | AI42: =AVERAGE(ABS(AA42),ABS(AE42)) -> 0.048057966 | AJ42: =AVERAGE(ABS(AB42),ABS(AF42)) -> 0.039035821 | AK42: =AVERAGE(ABS(AC42),ABS(AG42)) -> 0.3953202 | AL42: =MIN(A42,E42) -> 0.1

Sheet Distal Vali (double, tight)
A1: Ground Truth | L1: 6-Axis FT Sensor | R1: SoRoSim get_distal_value | Z1: Distal Errors | AH1: Stats
A2: F1 (N) | B2: s1 (m) | C2: el1 (rad) | D2: az1 (rad) | E2: F2 (N) | F2: s2 (m) | G2: el2 (rad) | H2: az2 (rad) | I2: tau1 (N) | J2: tau2 (N) | K2: tau3 (N) | L2: Tx (Nm) | M2: Ty (Nm) | N2: Tz(Nm) | O2: Fx (N) | P2: Fy (N) | Q2: Fz (N) | R2: F1 (N) | S2: s1 (m) | T2: el1 (rad) | U2: az1 (rad) | V2: F2 (N) | W2: s2 (m) | X2: el2 (rad) | Y2: az2 (rad) | Z2: F1 (N) | AA2: s1 (m) | AB2: el1 (rad) | AC2: az1 (rad) | AD2: F2 (N) | AE2: s2 (m) | AF2: el2 (rad) | AG2: az2 (rad) | AH2: force_error | AI2: position_error | AJ2: angle_error | AK2: Absolute Mean Error
A3: ='Proximal Validation (double)'!A3 -> 0.2 | B3: ='Proximal Validation (double)'!B3 -> 0.1 | C3: ='Proximal Validation (double)'!C3 -> 1.571 | D3: ='Proximal Validation (double)'!D3 -> 1.5707963 | E3: ='Proximal Validation (double)'!E3 -> 1 | F3: ='Proximal Validation (double)'!F3 -> 0.04 | G3: ='Proximal Validation (double)'!G3 -> 3.142 | H3: ='Proximal Validation (double)'!H3 -> 1.5707963 | ... Q3: ='Proximal Validation (double)'!Q3 -> 0.029205024 | R3: 0.1 | S3: 0.1 | T3: 1.5708 | U3: 1.5708 | V3: 0.9765 | W3: 0.02 | X3: 3.2149 | Y3: 1.5708 | Z3: =R3-A3 -> -0.1 | AA3: =S3-B3 -> 0 | AB3: =T3-C3 -> -0.0002 | AC3: =U3-D3 -> 3.6732051e-06 | AD3: =V3-E3 -> -0.0235 | AE3: =W3-F3 -> -0.02 | AF3: =X3-G3 -> 0.0729 | AG3: =Y3-H3 -> 3.6732051e-06 | AH3: =AVERAGE(ABS(Z3),ABS(AD3)) -> 0.06175 | AI3: =AVERAGE(ABS(AA3),ABS(AE3)) -> 0.01 | AJ3: =AVERAGE(ABS(AB3),ABS(AF3)) -> 0.03655 | AK3: F1 (N) | AL3: s1 (m) | AM3: el1 (rad) | AN3: az1 (rad) | AO3: F2 (N) | AP3: s2 (m) | AQ3: el2 (rad) | AR3: az2 (rad)
A4: ='Proximal Validation (double)'!A4 -> 1 | B4: ='Proximal Validation (double)'!B4 -> 0.1 | C4: ='Proximal Validation (double)'!C4 -> 1.571 | D4: ='Proximal Validation (double)'!D4 -> 1.5707963 | E4: ='Proximal Validation (double)'!E4 -> 1 | F4: ='Proximal Validation (double)'!F4 -> 0.08 | G4: ='Proximal Validation (double)'!G4 -> 3.142 | H4: ='Proximal Validation (double)'!H4 -> 1.5707963 | ... Q4: ='Proximal Validation (double)'!Q4 -> 0.92483175 | R4: 1 | S4: 0.1216 | T4: 1.6911 | U4: 1.5708 | V4: 0.7308 | W4: 0.08 | X4: 3.1416 | Y4: 1.5708 | Z4: =R4-A4 -> 0 | AA4: =S4-B4 -> 0.0216 | AB4: =T4-C4 -> 0.1201 | AC4: =U4-D4 -> 3.6732051e-06 | AD4: =V4-E4 -> -0.2692 | AE4: =W4-F4 -> 0 | AF4: =X4-G4 -> -0.0004 | AG4: =Y4-H4 -> 3.6732051e-06 | AH4: =AVERAGE(ABS(Z4),ABS(AD4)) -> 0.1346 | AI4: =AVERAGE(ABS(AA4),ABS(AE4)) -> 0.0108 | AJ4: =AVERAGE(ABS(AB4),ABS(AF4)) -> 0.06025 | AK4: {=AVERAGE(ABS(Z3:Z42))} -> 0.1426625 | AL4: {=AVERAGE(ABS(AA3:AA42))} -> 0.03098 | AM4: {=AVERAGE(ABS(AB3:AB42))} -> 0.3266 | AN4: {=AVERAGE(ABS(AC3:AC42))} -> 3.6732051e-06 | AO4: {=AVERAGE(ABS(AD3:AD42))} -> 0.168705 | AP4: {=AVERAGE(ABS(AE3:AE42))} -> 0.0217375 | AQ4: {=AVERAGE(ABS(AF3:AF42))} -> 0.23864 | AR4: {=AVERAGE(ABS(AG3:AG42))} -> 3.6732051e-06
A5: ='Proximal Validation (double)'!A5 -> 0.5 | B5: ='Proximal Validation (double)'!B5 -> 0.1 | C5: ='Proximal Validation (double)'!C5 -> 1.571 | D5: ='Proximal Validation (double)'!D5 -> 1.5707963 | E5: ='Proximal Validation (double)'!E5 -> 0.2 | F5: ='Proximal Validation (double)'!F5 -> 0.02 | G5: ='Proximal Validation (double)'!G5 -> 3.927 | H5: ='Proximal Validation (double)'!H5 -> 1.5707963 | ... Q5: ='Proximal Validation (double)'!Q5 -> 0.40386674 | R5: 0.5306 | S5: 0.1 | T5: 1.604 | U5: 1.5708 | V5: 0.175 | W5: 0.02 | X5: 3.9144 | Y5: 1.5708 | Z5: =R5-A5 -> 0.0306 | AA5: =S5-B5 -> 0 | AB5: =T5-C5 -> 0.033 | AC5: =U5-D5 -> 3.6732051e-06 | AD5: =V5-E5 -> -0.025 | AE5: =W5-F5 -> 0 | AF5: =X5-G5 -> -0.0126 | AG5: =Y5-H5 -> 3.6732051e-06 | AH5: =AVERAGE(ABS(Z5),ABS(AD5)) -> 0.0278 | AI5: =AVERAGE(ABS(AA5),ABS(AE5)) -> 0 | AJ5: =AVERAGE(ABS(AB5),ABS(AF5)) -> 0.0228 | AK5: Absolute Mean Error (Across Both Forces)
A6: ='Proximal Validation (double)'!A6 -> 0.9 | B6: ='Proximal Validation (double)'!B6 -> 0.1 | C6: ='Proximal Validation (double)'!C6 -> 1.571 | D6: ='Proximal Validation (double)'!D6 -> 1.5707963 | E6: ='Proximal Validation (double)'!E6 -> 0.2 | F6: ='Proximal Validation (double)'!F6 -> 0.08 | G6: ='Proximal Validation (double)'!G6 -> 4.712 | H6: ='Proximal Validation (double)'!H6 -> 1.5707963 | ... Q6: ='Proximal Validation (double)'!Q6 -> 0.75826401 | R6: 0.8892 | S6: 0.1151 | T6: 1.5708 | U6: 1.5708 | V6: 0.1001 | W6: 0.035 | X6: 4.7052 | Y6: 1.5708 | Z6: =R6-A6 -> -0.0108 | AA6: =S6-B6 -> 0.0151 | AB6: =T6-C6 -> -0.0002 | AC6: =U6-D6 -> 3.6732051e-06 | AD6: =V6-E6 -> -0.0999 | AE6: =W6-F6 -> -0.045 | AF6: =X6-G6 -> -0.0068 | AG6: =Y6-H6 -> 3.6732051e-06 | AH6: =AVERAGE(ABS(Z6),ABS(AD6)) -> 0.05535 | AI6: =AVERAGE(ABS(AA6),ABS(AE6)) -> 0.03005 | AJ6: =AVERAGE(ABS(AB6),ABS(AF6)) -> 0.0035 | AK6: force_error | AL6: position_error | AM6: angle_error
A7: ='Proximal Validation (double)'!A7 -> 0.1 | B7: ='Proximal Validation (double)'!B7 -> 0.12 | C7: ='Proximal Validation (double)'!C7 -> 1.571 | D7: ='Proximal Validation (double)'!D7 -> 1.5707963 | E7: ='Proximal Validation (double)'!E7 -> 1 | F7: ='Proximal Validation (double)'!F7 -> 0.06 | G7: ='Proximal Validation (double)'!G7 -> 3.927 | H7: ='Proximal Validation (double)'!H7 -> 1.5707963 | ... Q7: ='Proximal Validation (double)'!Q7 -> -0.43824503 | R7: 0.1 | S7: 0.1 | T7: 2.5577 | U7: 1.5708 | V7: 0.7865 | W7: 0.02 | X7: 3.8218 | Y7: 1.5708 | Z7: =R7-A7 -> 0 | AA7: =S7-B7 -> -0.02 | AB7: =T7-C7 -> 0.9867 | AC7: =U7-D7 -> 3.6732051e-06 | AD7: =V7-E7 -> -0.2135 | AE7: =W7-F7 -> -0.04 | AF7: =X7-G7 -> -0.1052 | AG7: =Y7-H7 -> 3.6732051e-06 | AH7: =AVERAGE(ABS(Z7),ABS(AD7)) -> 0.10675 | AI7: =AVERAGE(ABS(AA7),ABS(AE7)) -> 0.03 | AJ7: =AVERAGE(ABS(AB7),ABS(AF7)) -> 0.54595 | AK7: =AVERAGE(AK4,AO4) -> 0.15568375 | AL7: =AVERAGE(AL4,AP4) -> 0.02635875 | AM7: =AVERAGE(AM4,AQ4) -> 0.28262
A8: ='Proximal Validation (double)'!A8 -> 0.8 | B8: ='Proximal Validation (double)'!B8 -> 0.16 | C8: ='Proximal Validation (double)'!C8 -> 1.571 | D8: ='Proximal Validation (double)'!D8 -> 1.5707963 | E8: ='Proximal Validation (double)'!E8 -> 0.8 | F8: ='Proximal Validation (double)'!F8 -> 0.06 | G8: ='Proximal Validation (double)'!G8 -> 3.927 | H8: ='Proximal Validation (double)'!H8 -> 1.5707963 | ... Q8: ='Proximal Validation (double)'!Q8 -> 0.10888903 | R8: 0.7045 | S8: 0.182 | T8: 1.745 | U8: 1.5708 | V8: 0.64 | W8: 0.0328 | X8: 4.0252 | Y8: 1.5708 | Z8: =R8-A8 -> -0.0955 | AA8: =S8-B8 -> 0.022 | AB8: =T8-C8 -> 0.174 | AC8: =U8-D8 -> 3.6732051e-06 | AD8: =V8-E8 -> -0.16 | AE8: =W8-F8 -> -0.0272 | AF8: =X8-G8 -> 0.0982 | AG8: =Y8-H8 -> 3.6732051e-06 | AH8: =AVERAGE(ABS(Z8),ABS(AD8)) -> 0.12775 | AI8: =AVERAGE(ABS(AA8),ABS(AE8)) -> 0.0246 | AJ8: =AVERAGE(ABS(AB8),ABS(AF8)) -> 0.1361
A9: ='Proximal Validation (double)'!A9 -> 0.1 | B9: ='Proximal Validation (double)'!B9 -> 0.18 | C9: ='Proximal Validation (double)'!C9 -> 1.571 | D9: ='Proximal Validation (double)'!D9 -> 1.5707963 | E9: ='Proximal Validation (double)'!E9 -> 0.1 | F9: ='Proximal Validation (double)'!F9 -> 0.02 | G9: ='Proximal Validation (double)'!G9 -> 3.142 | H9: ='Proximal Validation (double)'!H9 -> 1.5707963 | ... Q9: ='Proximal Validation (double)'!Q9 -> 0.01807829 | R9: 0.1 | S9: 0.1 | T9: 1.5714 | U9: 1.5708 | V9: 0.1363 | W9: 0.0393 | X9: 3.7917 | Y9: 1.5708 | Z9: =R9-A9 -> 0 | AA9: =S9-B9 -> -0.08 | AB9: =T9-C9 -> 0.0004 | AC9: =U9-D9 -> 3.6732051e-06 | AD9: =V9-E9 -> 0.0363 | AE9: =W9-F9 -> 0.0193 | AF9: =X9-G9 -> 0.6497 | AG9: =Y9-H9 -> 3.6732051e-06 | AH9: =AVERAGE(ABS(Z9),ABS(AD9)) -> 0.01815 | AI9: =AVERAGE(ABS(AA9),ABS(AE9)) -> 0.04965 | AJ9: =AVERAGE(ABS(AB9),ABS(AF9)) -> 0.32505
A10: ='Proximal Validation (double)'!A10 -> 0.9 | B10: ='Proximal Validation (double)'!B10 -> 0.18 | C10: ='Proximal Validation (double)'!C10 -> 1.571 | D10: ='Proximal Validation (double)'!D10 -> 1.5707963 | E10: ='Proximal Validation (double)'!E10 -> 0.1 | F10: ='Proximal Validation (double)'!F10 -> 0.08 | G10: ='Proximal Validation (double)'!G10 -> 4.712 | H10: ='Proximal Validation (double)'!H10 -> 1.5707963 | ... Q10: ='Proximal Validation (double)'!Q10 -> 0.51686221 | R10: 0.7627 | S10: 0.1897 | T10: 1.5708 | U10: 1.5708 | V10: 0.1082 | W10: 0.0779 | X10: 4.7124 | Y10: 1.5708 | Z10: =R10-A10 -> -0.1373 | AA10: =S10-B10 -> 0.0097 | AB10: =T10-C10 -> -0.0002 | AC10: =U10-D10 -> 3.6732051e-06 | AD10: =V10-E10 -> 0.0082 | AE10: =W10-F10 -> -0.0021 | AF10: =X10-G10 -> 0.0004 | AG10: =Y10-H10 -> 3.6732051e-06 | AH10: =AVERAGE(ABS(Z10),ABS(AD10)) -> 0.07275 | AI10: =AVERAGE(ABS(AA10),ABS(AE10)) -> 0.0059 | AJ10: =AVERAGE(ABS(AB10),ABS(AF10)) -> 0.0003
A11: ='Proximal Validation (double)'!A11 -> 0.3 | B11: ='Proximal Validation (double)'!B11 -> 0.18 | C11: ='Proximal Validation (double)'!C11 -> 1.571 | D11: ='Proximal Validation (double)'!D11 -> 1.5707963 | E11: ='Proximal Validation (double)'!E11 -> 0.9 | F11: ='Proximal Validation (double)'!F11 -> 0.08 | G11: ='Proximal Validation (double)'!G11 -> 4.712 | H11: ='Proximal Validation (double)'!H11 -> 1.5707963 | ... Q11: ='Proximal Validation (double)'!Q11 -> -0.58056563 | R11: 0.1 | S11: 0.1 | T11: 1.5836 | U11: 1.5708 | V11: 0.6827 | W11: 0.0242 | X11: 4.6833 | Y11: 1.5708 | Z11: =R11-A11 -> -0.2 | AA11: =S11-B11 -> -0.08 | AB11: =T11-C11 -> 0.0126 | AC11: =U11-D11 -> 3.6732051e-06 | AD11: =V11-E11 -> -0.2173 | AE11: =W11-F11 -> -0.0558 | AF11: =X11-G11 -> -0.0287 | AG11: =Y11-H11 -> 3.6732051e-06 | AH11: =AVERAGE(ABS(Z11),ABS(AD11)) -> 0.20865 | AI11: =AVERAGE(ABS(AA11),ABS(AE11)) -> 0.0679 | AJ11: =AVERAGE(ABS(AB11),ABS(AF11)) -> 0.02065
A12: ='Proximal Validation (double)'!A12 -> 0.9 | B12: ='Proximal Validation (double)'!B12 -> 0.2 | C12: ='Proximal Validation (double)'!C12 -> 1.571 | D12: ='Proximal Validation (double)'!D12 -> 1.5707963 | E12: ='Proximal Validation (double)'!E12 -> 1 | F12: ='Proximal Validation (double)'!F12 -> 0.02 | G12: ='Proximal Validation (double)'!G12 -> 3.142 | H12: ='Proximal Validation (double)'!H12 -> 1.5707963 | ... Q12: ='Proximal Validation (double)'!Q12 -> 0.27430844 | R12: 0.849 | S12: 0.1998 | T12: 1.6468 | U12: 1.5708 | V12: 0.9946 | W12: 0.0209 | X12: 3.4964 | Y12: 1.5708 | Z12: =R12-A12 -> -0.051 | AA12: =S12-B12 -> -0.0002 | AB12: =T12-C12 -> 0.0758 | AC12: =U12-D12 -> 3.6732051e-06 | AD12: =V12-E12 -> -0.0054 | AE12: =W12-F12 -> 0.0009 | AF12: =X12-G12 -> 0.3544 | AG12: =Y12-H12 -> 3.6732051e-06 | AH12: =AVERAGE(ABS(Z12),ABS(AD12)) -> 0.0282 | AI12: =AVERAGE(ABS(AA12),ABS(AE12)) -> 0.00055 | AJ12: =AVERAGE(ABS(AB12),ABS(AF12)) -> 0.2151
A13: ='Proximal Validation (double)'!A13 -> 0.1 | B13: ='Proximal Validation (double)'!B13 -> 0.2 | C13: ='Proximal Validation (double)'!C13 -> 1.571 | D13: ='Proximal Validation (double)'!D13 -> 1.5707963 | E13: ='Proximal Validation (double)'!E13 -> 0.3 | F13: ='Proximal Validation (double)'!F13 -> 0.08 | G13: ='Proximal Validation (double)'!G13 -> 3.142 | H13: ='Proximal Validation (double)'!H13 -> 1.5707963 | ... Q13: ='Proximal Validation (double)'!Q13 -> -0.036308467 | R13: 0.1 | S13: 0.1 | T13: 3.0446 | U13: 1.5708 | V13: 0.183 | W13: 0.02 | X13: 3.3964 | Y13: 1.5708 | Z13: =R13-A13 -> 0 | AA13: =S13-B13 -> -0.1 | AB13: =T13-C13 -> 1.4736 | AC13: =U13-D13 -> 3.6732051e-06 | AD13: =V13-E13 -> -0.117 | AE13: =W13-F13 -> -0.06 | AF13: =X13-G13 -> 0.2544 | AG13: =Y13-H13 -> 3.6732051e-06 | AH13: =AVERAGE(ABS(Z13),ABS(AD13)) -> 0.0585 | AI13: =AVERAGE(ABS(AA13),ABS(AE13)) -> 0.08 | AJ13: =AVERAGE(ABS(AB13),ABS(AF13)) -> 0.864
A14: ='Proximal Validation (double)'!A14 -> 0.9 | B14: ='Proximal Validation (double)'!B14 -> 0.2 | C14: ='Proximal Validation (double)'!C14 -> 1.571 | D14: ='Proximal Validation (double)'!D14 -> 1.5707963 | E14: ='Proximal Validation (double)'!E14 -> 0.3 | F14: ='Proximal Validation (double)'!F14 -> 0.02 | G14: ='Proximal Validation (double)'!G14 -> 4.712 | H14: ='Proximal Validation (double)'!H14 -> 1.5707963 | ... Q14: ='Proximal Validation (double)'!Q14 -> 0.042876139 | R14: 1 | S14: 0.2 | T14: 1.5892 | U14: 1.5708 | V14: 0.6364 | W14: 0.0404 | X14: 4.6517 | Y14: 1.5708 | Z14: =R14-A14 -> 0.1 | AA14: =S14-B14 -> 0 | AB14: =T14-C14 -> 0.0182 | AC14: =U14-D14 -> 3.6732051e-06 | AD14: =V14-E14 -> 0.3364 | AE14: =W14-F14 -> 0.0204 | AF14: =X14-G14 -> -0.0603 | AG14: =Y14-H14 -> 3.6732051e-06 | AH14: =AVERAGE(ABS(Z14),ABS(AD14)) -> 0.2182 | AI14: =AVERAGE(ABS(AA14),ABS(AE14)) -> 0.0102 | AJ14: =AVERAGE(ABS(AB14),ABS(AF14)) -> 0.03925
A15: ='Proximal Validation (double)'!A15 -> 0.9 | B15: ='Proximal Validation (double)'!B15 -> 0.1 | C15: ='Proximal Validation (double)'!C15 -> 2.356 | D15: ='Proximal Validation (double)'!D15 -> 1.5707963 | E15: ='Proximal Validation (double)'!E15 -> 0.9 | F15: ='Proximal Validation (double)'!F15 -> 0.02 | G15: ='Proximal Validation (double)'!G15 -> 4.712 | H15: ='Proximal Validation (double)'!H15 -> 1.5707963 | ... Q15: ='Proximal Validation (double)'!Q15 -> -0.18459481 | R15: 0.6501 | S15: 0.1765 | T15: 2.3098 | U15: 1.5708 | V15: 0.6628 | W15: 0.0342 | X15: 4.3506 | Y15: 1.5708 | Z15: =R15-A15 -> -0.2499 | AA15: =S15-B15 -> 0.0765 | AB15: =T15-C15 -> -0.0462 | AC15: =U15-D15 -> 3.6732051e-06 | AD15: =V15-E15 -> -0.2372 | AE15: =W15-F15 -> 0.0142 | AF15: =X15-G15 -> -0.3614 | AG15: =Y15-H15 -> 3.6732051e-06 | AH15: =AVERAGE(ABS(Z15),ABS(AD15)) -> 0.24355 | AI15: =AVERAGE(ABS(AA15),ABS(AE15)) -> 0.04535 | AJ15: =AVERAGE(ABS(AB15),ABS(AF15)) -> 0.2038
A16: ='Proximal Validation (double)'!A16 -> 0.4 | B16: ='Proximal Validation (double)'!B16 -> 0.12 | C16: ='Proximal Validation (double)'!C16 -> 2.356 | D16: ='Proximal Validation (double)'!D16 -> 1.5707963 | E16: ='Proximal Validation (double)'!E16 -> 0.1 | F16: ='Proximal Validation (double)'!F16 -> 0.06 | G16: ='Proximal Validation (double)'!G16 -> 3.142 | H16: ='Proximal Validation (double)'!H16 -> 1.5707963 | ... Q16: ='Proximal Validation (double)'!Q16 -> 0.24705727 | R16: 0.2495 | S16: 0.1 | T16: 1.7371 | U16: 1.5708 | V16: 0.289 | W16: 0.0598 | X16: 3.1416 | Y16: 1.5708 | Z16: =R16-A16 -> -0.1505 | AA16: =S16-B16 -> -0.02 | AB16: =T16-C16 -> -0.6189 | AC16: =U16-D16 -> 3.6732051e-06 | AD16: =V16-E16 -> 0.189 | AE16: =W16-F16 -> -0.0002 | AF16: =X16-G16 -> -0.0004 | AG16: =Y16-H16 -> 3.6732051e-06 | AH16: =AVERAGE(ABS(Z16),ABS(AD16)) -> 0.16975 | AI16: =AVERAGE(ABS(AA16),ABS(AE16)) -> 0.0101 | AJ16: =AVERAGE(ABS(AB16),ABS(AF16)) -> 0.30965
A17: ='Proximal Validation (double)'!A17 -> 1 | B17: ='Proximal Validation (double)'!B17 -> 0.14 | C17: ='Proximal Validation (double)'!C17 -> 2.356 | D17: ='Proximal Validation (double)'!D17 -> 1.5707963 | E17: ='Proximal Validation (double)'!E17 -> 0.4 | F17: ='Proximal Validation (double)'!F17 -> 0.04 | G17: ='Proximal Validation (double)'!G17 -> 3.927 | H17: ='Proximal Validation (double)'!H17 -> 1.5707963 | ... Q17: ='Proximal Validation (double)'!Q17 -> 0.42077422 | R17: 0.8233 | S17: 0.1529 | T17: 2.1145 | U17: 1.5708 | V17: 0.6253 | W17: 0.079 | X17: 3.4819 | Y17: 1.5708 | Z17: =R17-A17 -> -0.1767 | AA17: =S17-B17 -> 0.0129 | AB17: =T17-C17 -> -0.2415 | AC17: =U17-D17 -> 3.6732051e-06 | AD17: =V17-E17 -> 0.2253 | AE17: =W17-F17 -> 0.039 | AF17: =X17-G17 -> -0.4451 | AG17: =Y17-H17 -> 3.6732051e-06 | AH17: =AVERAGE(ABS(Z17),ABS(AD17)) -> 0.201 | AI17: =AVERAGE(ABS(AA17),ABS(AE17)) -> 0.02595 | AJ17: =AVERAGE(ABS(AB17),ABS(AF17)) -> 0.3433
A18: ='Proximal Validation (double)'!A18 -> 0.4 | B18: ='Proximal Validation (double)'!B18 -> 0.18 | C18: ='Proximal Validation (double)'!C18 -> 2.356 | D18: ='Proximal Validation (double)'!D18 -> 1.5707963 | E18: ='Proximal Validation (double)'!E18 -> 0.7 | F18: ='Proximal Validation (double)'!F18 -> 0.04 | G18: ='Proximal Validation (double)'!G18 -> 3.142 | H18: ='Proximal Validation (double)'!H18 -> 1.5707963 | ... Q18: ='Proximal Validation (double)'!Q18 -> 0.23870468 | R18: 0.418 | S18: 0.1288 | T18: 2.3926 | U18: 1.5708 | V18: 0.5391 | W18: 0.0318 | X18: 3.2183 | Y18: 1.5708 | Z18: =R18-A18 -> 0.018 | AA18: =S18-B18 -> -0.0512 | AB18: =T18-C18 -> 0.0366 | AC18: =U18-D18 -> 3.6732051e-06 | AD18: =V18-E18 -> -0.1609 | AE18: =W18-F18 -> -0.0082 | AF18: =X18-G18 -> 0.0763 | AG18: =Y18-H18 -> 3.6732051e-06 | AH18: =AVERAGE(ABS(Z18),ABS(AD18)) -> 0.08945 | AI18: =AVERAGE(ABS(AA18),ABS(AE18)) -> 0.0297 | AJ18: =AVERAGE(ABS(AB18),ABS(AF18)) -> 0.05645
A19: ='Proximal Validation (double)'!A19 -> 0.1 | B19: ='Proximal Validation (double)'!B19 -> 0.18 | C19: ='Proximal Validation (double)'!C19 -> 2.356 | D19: ='Proximal Validation (double)'!D19 -> 1.5707963 | E19: ='Proximal Validation (double)'!E19 -> 0.2 | F19: ='Proximal Validation (double)'!F19 -> 0.06 | G19: ='Proximal Validation (double)'!G19 -> 4.712 | H19: ='Proximal Validation (double)'!H19 -> 1.5707963 | ... Q19: ='Proximal Validation (double)'!Q19 -> -0.15806177 | R19: 0.1316 | S19: 0.1497 | T19: 1.6737 | U19: 1.5708 | V19: 0.2893 | W19: 0.08 | X19: 4.6679 | Y19: 1.5708 | Z19: =R19-A19 -> 0.0316 | AA19: =S19-B19 -> -0.0303 | AB19: =T19-C19 -> -0.6823 | AC19: =U19-D19 -> 3.6732051e-06 | AD19: =V19-E19 -> 0.0893 | AE19: =W19-F19 -> 0.02 | AF19: =X19-G19 -> -0.0441 | AG19: =Y19-H19 -> 3.6732051e-06 | AH19: =AVERAGE(ABS(Z19),ABS(AD19)) -> 0.06045 | AI19: =AVERAGE(ABS(AA19),ABS(AE19)) -> 0.02515 | AJ19: =AVERAGE(ABS(AB19),ABS(AF19)) -> 0.3632
... A42: ='Proximal Validation (double)'!A42 -> 0.2 | B42: ='Proximal Validation (double)'!B42 -> 0.2 | C42: ='Proximal Validation (double)'!C42 -> 4.712 | D42: ='Proximal Validation (double)'!D42 -> 1.5707963 | E42: ='Proximal Validation (double)'!E42 -> 0.1 | F42: ='Proximal Validation (double)'!F42 -> 0.08 | G42: ='Proximal Validation (double)'!G42 -> 3.927 | H42: ='Proximal Validation (double)'!H42 -> 1.5707963 | ... Q42: ='Proximal Validation (double)'!Q42 -> -0.20783865 | R42: 0.1617 | S42: 0.2 | T42: 4.712 | U42: 1.5708 | V42: 0.1 | W42: 0.08 | X42: 3.6767 | Y42: 1.5708 | Z42: =R42-A42 -> -0.0383 | AA42: =S42-B42 -> 0 | AB42: =T42-C42 -> 0 | AC42: =U42-D42 -> 3.6732051e-06 | AD42: =V42-E42 -> 0 | AE42: =W42-F42 -> 0 | AF42: =X42-G42 -> -0.2503 | AG42: =Y42-H42 -> 3.6732051e-06 | AH42: =AVERAGE(ABS(Z42),ABS(AD42)) -> 0.01915 | AI42: =AVERAGE(ABS(AA42),ABS(AE42)) -> 0 | AJ42: =AVERAGE(ABS(AB42),ABS(AF42)) -> 0.12515

Sheet Distal Vali (double, sim, 2to1)
A1: Ground Truth | L1: get_proximal_value | R1: SoRoSim get_distal_value | AA1: Distal Errors | AI1: Stats
A2: F1 (N) | B2: s1 (m) | C2: el1 (rad) | D2: az1 (rad) | E2: F2 (N) | F2: s2 (m) | G2: el2 (rad) | H2: az2 (rad) | I2: tau1 (N) | J2: tau2 (N) | K2: tau3 (N) | L2: Tx (Nm) | M2: Ty (Nm) | N2: Tz(Nm) | O2: Fx (N) | P2: Fy (N) | Q2: Fz (N) | R2: F1 (N) | S2: s1 (m) | T2: el1 (rad) | U2: az1 (rad) | V2: F2 (N) | W2: s2 (m) | X2: el2 (rad) | Y2: az2 (rad) | Z2: f_final | AA2: F1 (N) | AB2: s1 (m) | AC2: el1 (rad) | AD2: az1 (rad) | AE2: F2 (N) | AF2: s2 (m) | AG2: el2 (rad) | AH2: az2 (rad) | AI2: force_error | AJ2: position_error | AK2: angle_error | AL2: min_f | AN2: Absolute Mean Error
A3: ='Proximal Validation (double)'!A3 -> 0.2 | B3: ='Proximal Validation (double)'!B3 -> 0.1 | C3: ='Proximal Validation (double)'!C3 -> 1.571 | D3: ='Proximal Validation (double)'!D3 -> 1.5707963 | E3: ='Proximal Validation (double)'!E3 -> 1 | F3: ='Proximal Validation (double)'!F3 -> 0.04 | G3: ='Proximal Validation (double)'!G3 -> 3.142 | H3: ='Proximal Validation (double)'!H3 -> 1.5707963 | ... K3: ='Proximal Validation (double)'!K3 -> 0 | L3: 0.00053931649 | M3: -0.037889046 | N3: -0.12975348 | O3: -0.024894948 | P3: -0.99993893 | Q3: 0.19908331 | R3: 0.23940995 | S3: 0.11213817 | T3: 2.3291718 | U3: 1.5707963 | V3: 0.83586881 | W3: 0.026123171 | X3: 3.110872 | Y3: 1.5707963 | Z3: 1.3010925e-07 | AA3: =R3-A3 -> 0.039409946 | AB3: =S3-B3 -> 0.012138166 | AC3: =T3-C3 -> 0.7581718 | AD3: =U3-D3 -> 0 | AE3: =V3-E3 -> -0.16413119 | AF3: =W3-F3 -> -0.013876829 | AG3: =X3-G3 -> -0.031128027 | AH3: =Y3-H3 -> 0 | AI3: =AVERAGE(ABS(AA3),ABS(AE3)) -> 0.10177057 | AJ3: =AVERAGE(ABS(AB3),ABS(AF3)) -> 0.013007498 | AK3: =AVERAGE(ABS(AC3),ABS(AG3)) -> 0.39464991 | AL3: =MIN(A3,E3) -> 0.2 | AM3: =ABS(B3-F3) -> 0.06 | AN3: F1 (N) | AO3: s1 (m) | AP3: el1 (rad) | AQ3: az1 (rad) | AR3: F2 (N) | AS3: s2 (m) | AT3: el2 (rad) | AU3: az2 (rad)
A4: ='Proximal Validation (double)'!A4 -> 1 | B4: ='Proximal Validation (double)'!B4 -> 0.1 | C4: ='Proximal Validation (double)'!C4 -> 1.571 | D4: ='Proximal Validation (double)'!D4 -> 1.5707963 | E4: ='Proximal Validation (double)'!E4 -> 1 | F4: ='Proximal Validation (double)'!F4 -> 0.08 | G4: ='Proximal Validation (double)'!G4 -> 3.142 | H4: ='Proximal Validation (double)'!H4 -> 1.5707963 | ... K4: ='Proximal Validation (double)'!K4 -> 0 | L4: 2.5185186e-10 | M4: -0.18648031 | N4: -0.16762567 | O4: -0.31806636 | P4: -0.97896174 | Q4: 0.96946848 | R4: 0.92413753 | S4: 0.10808724 | T4: 2.0444632 | U4: 1.5707963 | V4: 0.60584801 | W4: 0.059094905 | X4: 2.8440511 | Y4: 1.5707963 | Z4: 5.2113348e-07 | AA4: =R4-A4 -> -0.075862467 | AB4: =S4-B4 -> 0.0080872424 | AC4: =T4-C4 -> 0.47346317 | AD4: =U4-D4 -> 0 | AE4: =V4-E4 -> -0.39415199 | AF4: =W4-F4 -> -0.020905095 | AG4: =X4-G4 -> -0.29794893 | AH4: =Y4-H4 -> 0 | AI4: =AVERAGE(ABS(AA4),ABS(AE4)) -> 0.23500723 | AJ4: =AVERAGE(ABS(AB4),ABS(AF4)) -> 0.014496169 | AK4: =AVERAGE(ABS(AC4),ABS(AG4)) -> 0.38570605 | AL4: =MIN(A4,E4) -> 1 | AM4: =ABS(B4-F4) -> 0.02 | AN4: {=AVERAGE(ABS(AA3:AA42))} -> 0.17612276 | AO4: {=AVERAGE(ABS(AB3:AB42))} -> 0.021144566 | AP4: {=AVERAGE(ABS(AC3:AC42))} -> 0.40422841 | AQ4: {=AVERAGE(ABS(AD3:AD42))} -> 0 | AR4: {=AVERAGE(ABS(AE3:AE42))} -> 0.20157424 | AS4: {=AVERAGE(ABS(AF3:AF42))} -> 0.022789402 | AT4: {=AVERAGE(ABS(AG3:AG42))} -> 0.29332356 | AU4: {=AVERAGE(ABS(AH3:AH42))} -> 0
A5: ='Proximal Validation (double)'!A5 -> 0.5 | B5: ='Proximal Validation (double)'!B5 -> 0.1 | C5: ='Proximal Validation (double)'!C5 -> 1.571 | D5: ='Proximal Validation (double)'!D5 -> 1.5707963 | E5: ='Proximal Validation (double)'!E5 -> 0.2 | F5: ='Proximal Validation (double)'!F5 -> 0.02 | G5: ='Proximal Validation (double)'!G5 -> 3.927 | H5: ='Proximal Validation (double)'!H5 -> 1.5707963 | ... K5: ='Proximal Validation (double)'!K5 -> 0 | L5: 8.015431e-13 | M5: -0.079238175 | N5: -0.015485326 | O5: -0.046898335 | P5: -0.14148384 | Q5: 0.35607196 | R5: 0.44039465 | S5: 0.11079513 | T5: 1.5294928 | U5: 1.5707963 | V5: 0.17887902 | W5: 0.029636245 | X5: 3.6110981 | Y5: 1.5707963 | Z5: 9.047671e-07 | AA5: =R5-A5 -> -0.059605346 | AB5: =S5-B5 -> 0.010795128 | AC5: =T5-C5 -> -0.041507235 | AD5: =U5-D5 -> 0 | AE5: =V5-E5 -> -0.021120978 | AF5: =W5-F5 -> 0.0096362451 | AG5: =X5-G5 -> -0.31590189 | AH5: =Y5-H5 -> 0 | AI5: =AVERAGE(ABS(AA5),ABS(AE5)) -> 0.040363162 | AJ5: =AVERAGE(ABS(AB5),ABS(AF5)) -> 0.010215687 | AK5: =AVERAGE(ABS(AC5),ABS(AG5)) -> 0.17870456 | AL5: =MIN(A5,E5) -> 0.2 | AM5: =ABS(B5-F5) -> 0.08 | AN5: Absolute Mean Error (Across Both Forces)
A6: ='Proximal Validation (double)'!A6 -> 0.9 | B6: ='Proximal Validation (double)'!B6 -> 0.1 | C6: ='Proximal Validation (double)'!C6 -> 1.571 | D6: ='Proximal Validation (double)'!D6 -> 1.5707963 | E6: ='Proximal Validation (double)'!E6 -> 0.2 | F6: ='Proximal Validation (double)'!F6 -> 0.08 | G6: ='Proximal Validation (double)'!G6 -> 4.712 | H6: ='Proximal Validation (double)'!H6 -> 1.5707963 | ... K6: ='Proximal Validation (double)'!K6 -> 0 | L6: 0.0013329517 | M6: -0.13551664 | N6: -0.00018669694 | O6: -0.13125427 | P6: -0.0022537722 | Q6: 0.68764611 | R6: 0.28507704 | S6: 0.10574956 | T6: 3.7826904 | U6: 1.5707963 | V6: 0.90000862 | W6: 0.10557529 | X6: 1.3144001 | Y6: 1.5707963 | Z6: 2.1165931e-08 | AA6: =R6-A6 -> -0.61492296 | AB6: =S6-B6 -> 0.0057495605 | AC6: =T6-C6 -> 2.2116904 | AD6: =U6-D6 -> 0 | AE6: =V6-E6 -> 0.70000862 | AF6: =W6-F6 -> 0.025575291 | AG6: =X6-G6 -> -3.3975999 | AH6: =Y6-H6 -> 0 | AI6: =AVERAGE(ABS(AA6),ABS(AE6)) -> 0.65746579 | AJ6: =AVERAGE(ABS(AB6),ABS(AF6)) -> 0.015662426 | AK6: =AVERAGE(ABS(AC6),ABS(AG6)) -> 2.8046452 | AL6: =MIN(A6,E6) -> 0.2 | AM6: =ABS(B6-F6) -> 0.02 | AN6: force_error | AO6: position_error | AP6: angle_error
