Workbook

Sheet Proximal Validation
A1: Ground Truth | J1: 6-Axis FT Sensor | P1: SoRoSim get_proximal_value | V1: Proximal Errors | AB1: RMSE | AJ1: Extra | AL1: Sensor Ranges
A2: F1 (N) | B2: s1 (m) | C2: theta1 (rad) | D2: F2 (N) | E2: s2 (m) | F2: theta2 (rad) | G2: tau1 (N) | H2: tau2 (N) | I2: tau3 (N) | J2: Tx (Nm) | K2: Ty (Nm) | L2: Tz(Nm) | M2: Fx (N) | N2: Fy (N) | O2: Fz (N) | P2: Tx (Nm) | Q2: Ty (Nm) | R2: Tz(Nm) | S2: Fx (N) | T2: Fy (N) | U2: Fz (N) | V2: Tx (Nm) | W2: Ty (Nm) | X2: Tz(Nm) | Y2: Fx (N) | Z2: Fy (N) | AA2: Fz (N) | AB2: NRMSE (%FS) | AC2: Tx (Nm) | AD2: Ty (Nm) | AE2: Tz(Nm) | AF2: Fx (N) | AG2: Fy (N) | AH2: Fz (N) | AI2: Overall NRMSE | AJ2: abs(s1-s2) | AK2: singular values | AL2: Tx | AM2: Ty | AN2: Tz | AO2: Fx | AP2: Fy | AQ2: Fz
A3: 0.57634631 | B3: 0.2 | C3: 0.7854 | D3: 1.1398025 | E3: 0.02 | F3: 5.4978 | G3: 0.49272224 | H3: 4.4756012 | I3: 4.1915537 | J3: -0.0048483536 | K3: -0.049299089 | L3: 0.11311968 | M3: -0.093563907 | N3: 1.137206 | O3: -0.73825818 | P3: -0.0053522884 | Q3: -0.063232708 | R3: 0.096597613 | S3: -0.077552464 | T3: 1.2150596 | U3: -0.4076815 | V3: =J3-P3 -> 0.00050393483 | W3: =K3-Q3 -> 0.013933619 | X3: =L3-R3 -> 0.016522063 | Y3: =M3-S3 -> -0.016011442 | Z3: =N3-T3 -> -0.077853638 | AA3: =O3-U3 -> -0.33057668 | AB3: {=SQRT(SUMPRODUCT(((J3:O3-P3:U3)/$AL$3:$AQ$3)^2)/6)*100} -> 1.1223523 | AC3: {=SQRT(SUMPRODUCT((J3:J52-P3:P52)^2)/50)} -> 0.0042957898 | AD3: {=SQRT(SUMPRODUCT((K3:K52-Q3:Q52)^2)/50)} -> 0.011340334 | AE3: {=SQRT(SUMPRODUCT((L3:L52-R3:R52)^2)/50)} -> 0.012305604 | AF3: {=SQRT(SUMPRODUCT((M3:M52-S3:S52)^2)/50)} -> 0.062312001 | AG3: {=SQRT(SUMPRODUCT((N3:N52-T3:T52)^2)/50)} -> 0.13663074 | AH3: {=SQRT(SUMPRODUCT((O3:O52-U3:U52)^2)/50)} -> 0.10205527 | AI3: {=SQRT(SUMPRODUCT(((J3:O52-P3:U52)/$AL$3:$AQ$3)^2)/(50*6))*100} -> 0.78768808 | AJ3: =ABS(B3-E3) -> 0.18 | AK3: 63364.8 | AL3: 1 | AM3: 1 | AN3: 1 | AO3: 60 | AP3: 20 | AQ3: 20
A4: 1.2961946 | B4: 0.2 | C4: 4.7124 | D4: 0.3190756 | E4: 0.02 | F4: 1.5708 | G4: 0.53253118 | H4: 1.6232894 | I4: 0.096932284 | J4: -0.0022787049 | K4: 0.23746989 | L4: -0.0038131319 | M4: -0.78536403 | N4: -0.025436234 | O4: -0.55368435 | P4: 0.0011701986 | Q4: 0.22575305 | R4: -0.0006368618 | S4: -0.84585425 | T4: 0.0015799179 | U4: -0.66154892 | V4: =J4-P4 -> -0.0034489035 | W4: =K4-Q4 -> 0.011716843 | X4: =L4-R4 -> -0.0031762701 | Y4: =M4-S4 -> 0.060490217 | Z4: =N4-T4 -> -0.027016152 | AA4: =O4-U4 -> 0.10786456 | AB4: {=SQRT(SUMPRODUCT(((J4:O4-P4:U4)/$AL$3:$AQ$3)^2)/6)*100} -> 0.56449983 | AJ4: =ABS(B4-E4) -> 0.18 | AK4: 330.78885
A5: 0.34328445 | B5: 0.2 | C5: 3.1416 | D5: 0.75633386 | E5: 0.02 | F5: 3.1416 | G5: 3.5593988 | H5: 2.6173594 | I5: 2.7214845 | J5: 0.0027396344 | K5: 2.790153e-05 | L5: -0.088981522 | M5: -0.0075504761 | N5: -0.98192942 | O5: 0.004011631 | P5: 0.00073028162 | Q5: 0.00012683371 | R5: -0.082569953 | S5: -0.040684028 | T5: -1.0974154 | U5: -0.0010869633 | V5: =J5-P5 -> 0.0020093527 | W5: =K5-Q5 -> -9.8932179e-05 | X5: =L5-R5 -> -0.0064115691 | Y5: =M5-S5 -> 0.033133551 | Z5: =N5-T5 -> 0.11548593 | AA5: =O5-U5 -> 0.0050985943 | AB5: {=SQRT(SUMPRODUCT(((J5:O5-P5:U5)/$AL$3:$AQ$3)^2)/6)*100} -> 0.36255562 | AJ5: =ABS(B5-E5) -> 0.18 | AK5: 883.99452
A6: 0.83277602 | B6: 0.2 | C6: 4.7124 | D6: 1.4193655 | E6: 0.04 | F6: 5.4978 | G6: 4.2084859 | H6: 0.52916698 | I6: 2.5150428 | J6: -0.014314156 | K6: 0.19910914 | L6: 0.029508465 | M6: -0.46529782 | N6: 0.80010873 | O6: -1.7768694 | P6: -0.0099467349 | Q6: 0.1949114 | R6: 0.036661142 | S6: -0.49143763 | T6: 0.95769984 | U6: -1.7210881 | V6: =J6-P6 -> -0.0043674211 | W6: =K6-Q6 -> 0.0041977363 | X6: =L6-R6 -> -0.0071526765 | Y6: =M6-S6 -> 0.026139811 | Z6: =N6-T6 -> -0.15759111 | AA6: =O6-U6 -> -0.055781336 | AB6: {=SQRT(SUMPRODUCT(((J6:O6-P6:U6)/$AL$3:$AQ$3)^2)/6)*100} -> 0.51301759 | AJ6: =ABS(B6-E6) -> 0.16 | AK6: 214.86349
A7: 0.38984039 | B7: 0.2 | C7: 1.5708 | D7: 0.45028829 | E7: 0.04 | F7: 2.3562 | G7: 0.34676129 | H7: 0.93612471 | I7: 2.0702513 | J7: -0.0027703205 | K7: -0.08706085 | L7: -0.010583339 | M7: -0.020597361 | N7: -0.34849352 | O7: 0.54981846 | P7: -0.00072765711 | Q7: -0.089172479 | R7: -0.012601728 | S7: -0.072633497 | T7: -0.31703067 | U7: 0.70289083 | V7: =J7-P7 -> -0.0020426634 | W7: =K7-Q7 -> 0.0021116293 | X7: =L7-R7 -> 0.0020183884 | Y7: =M7-S7 -> 0.052036136 | Z7: =N7-T7 -> -0.031462841 | AA7: =O7-U7 -> -0.15307237 | AB7: {=SQRT(SUMPRODUCT(((J7:O7-P7:U7)/$AL$3:$AQ$3)^2)/6)*100} -> 0.35239692 | AJ7: =ABS(B7-E7) -> 0.16 | AK7: 1314.4733
A8: 0.86958753 | B8: 0.2 | C8: 0.7854 | D8: 0.66933871 | E8: 0.04 | F8: 0.7854 | G8: 2.0486074 | H8: 1.4427409 | I8: 0.53737299 | J8: -0.012050613 | K8: -0.12670554 | L8: 0.14964092 | M8: -0.31113249 | N8: 1.095337 | O8: 0.92608899 | P8: -0.011367256 | Q8: -0.13335299 | R8: 0.13649071 | S8: -0.41382478 | T8: 1.0510964 | U8: 0.99726843 | V8: =J8-P8 -> -0.00068335671 | W8: =K8-Q8 -> 0.0066474546 | X8: =L8-R8 -> 0.013150203 | Y8: =M8-S8 -> 0.10269229 | Z8: =N8-T8 -> 0.044240676 | AA8: =O8-U8 -> -0.071179441 | AB8: {=SQRT(SUMPRODUCT(((J8:O8-P8:U8)/$AL$3:$AQ$3)^2)/6)*100} -> 0.62991033 | AJ8: =ABS(B8-E8) -> 0.16 | AK8: 494.45546
A9: 1.2260242 | B9: 0.2 | C9: 3.1416 | D9: 0.53124592 | E9: 0.04 | F9: 1.5708 | G9: 2.1721906 | H9: 4.859274 | I9: 4.1505258 | J9: 0.0044089789 | K9: -0.031871921 | L9: -0.23815526 | M9: -0.60743898 | N9: -0.81274194 | O9: 0.72559178 | P9: 0.00011621906 | Q9: -0.019647044 | R9: -0.22363328 | S9: -0.67981135 | T9: -1.0200332 | U9: 0.5229783 | V9: =J9-P9 -> 0.0042927598 | W9: =K9-Q9 -> -0.012224877 | X9: =L9-R9 -> -0.014521981 | Y9: =M9-S9 -> 0.072372373 | Z9: =N9-T9 -> 0.20729131 | AA9: =O9-U9 -> 0.20261347 | AB9: {=SQRT(SUMPRODUCT(((J9:O9-P9:U9)/$AL$3:$AQ$3)^2)/6)*100} -> 0.99186108 | AJ9: =ABS(B9-E9) -> 0.16 | AK9: 977.36272
A10: 1.4922792 | B10: 0.2 | C10: 2.3562 | D10: 1.2493009 | E10: 0.04 | F10: 0.7854 | G10: 0.65138204 | H10: 2.3960292 | I10: 3.8310385 | J10: 0.0039877007 | K10: -0.23812925 | L10: -0.16476847 | M10: -0.90740538 | N10: 0.22993693 | O10: 1.7137415 | P10: 0.0079854451 | Q10: -0.21923777 | R10: -0.14849959 | S10: -1.0734192 | T10: 0.092163968 | U10: 1.6250316 | V10: =J10-P10 -> -0.0039977444 | W10: =K10-Q10 -> -0.01889148 | X10: =L10-R10 -> -0.016268875 | Y10: =M10-S10 -> 0.16601382 | Z10: =N10-T10 -> 0.13777296 | AA10: =O10-U10 -> 0.088709944 | AB10: {=SQRT(SUMPRODUCT(((J10:O10-P10:U10)/$AL$3:$AQ$3)^2)/6)*100} -> 1.0895941 | AJ10: =ABS(B10-E10) -> 0.16 | AK10: 827.55067
A11: 1.425868 | B11: 0.2 | C11: 4.7124 | D11: 0.35291314 | E11: 0.04 | F11: 0 | G11: 3.481026 | H11: 1.1294031 | I11: 4.9138256 | J11: -0.025121536 | K11: 0.23443316 | L11: 0.0022260813 | M11: -1.1394191 | N11: 0.19454202 | O11: -0.71812153 | P11: -0.015059752 | Q11: 0.23034927 | R11: 0.0059929732 | S11: -1.1794759 | T11: 0.24622371 | U11: -0.79612147 | V11: =J11-P11 -> -0.010061784 | W11: =K11-Q11 -> 0.0040838902 | X11: =L11-R11 -> -0.0037668918 | Y11: =M11-S11 -> 0.040056804 | Z11: =N11-T11 -> -0.051681687 | AA11: =O11-U11 -> 0.07799994 | AB11: {=SQRT(SUMPRODUCT(((J11:O11-P11:U11)/$AL$3:$AQ$3)^2)/6)*100} -> 0.50734654 | AJ11: =ABS(B11-E11) -> 0.16 | AK11: 2387.7694
A12: 1.2847664 | B12: 0.18 | C12: 0.7854 | D12: 0.98965387 | E12: 0.04 | F12: 3.927 | G12: 3.2068327 | H12: 3.5469168 | I12: 1.1514405 | J12: -0.015617734 | K12: -0.12120571 | L12: 0.12601706 | M12: -0.64654499 | N12: -0.02815631 | O12: -0.15328422 | P12: -0.022032909 | Q12: -0.11991241 | R12: 0.12889792 | S12: -0.6091632 | T12: 0.14463191 | U12: 0.0067462752 | V12: =J12-P12 -> 0.0064151752 | W12: =K12-Q12 -> -0.0012933055 | X12: =L12-R12 -> -0.0028808579 | Y12: =M12-S12 -> -0.037381796 | Z12: =N12-T12 -> -0.17278822 | AA12: =O12-U12 -> -0.1600305 | AB12: {=SQRT(SUMPRODUCT(((J12:O12-P12:U12)/$AL$3:$AQ$3)^2)/6)*100} -> 0.56299562 | AJ12: =ABS(B12-E12) -> 0.14 | AK12: 378.09042
A13: 0.82078889 | B13: 0.18 | C13: 0 | D13: 1.3252826 | E13: 0.04 | F13: 0 | G13: 0.039081994 | H13: 2.9262885 | I13: 4.743179 | J13: 0.012357824 | K13: -0.015243557 | L13: 0.20452976 | M13: -0.23820373 | N13: 2.0633364 | O13: 0.085576177 | P13: 0.010402978 | Q13: -0.0032170355 | R13: 0.19878736 | S13: -0.17707945 | T13: 2.1297328 | U13: 0.030808254 | V13: =J13-P13 -> 0.0019548464 | W13: =K13-Q13 -> -0.012026522 | X13: =L13-R13 -> 0.0057423988 | Y13: =M13-S13 -> -0.06112428 | Z13: =N13-T13 -> -0.066396463 | AA13: =O13-U13 -> 0.054767923 | AB13: {=SQRT(SUMPRODUCT(((J13:O13-P13:U13)/$AL$3:$AQ$3)^2)/6)*100} -> 0.57877984 | AJ13: =ABS(B13-E13) -> 0.14 | AK13: 469.58688
A14: 0.51355825 | B14: 0.2 | C14: 2.3562 | D14: 0.96095191 | E14: 0.06 | F14: 0 | G14: 2.4382389 | H14: 4.2854047 | I14: 0.33901405 | J14: 0.0053502889 | K14: -0.062011333 | L14: 0.00024065852 | M14: -0.18366066 | N14: 0.79279768 | O14: 0.28229478 | P14: 0.0051326626 | Q14: -0.067299293 | R14: -0.011164187 | S14: -0.21712815 | T14: 0.62034441 | U14: 0.3126679 | V14: =J14-P14 -> 0.00021762634 | W14: =K14-Q14 -> 0.00528796 | X14: =L14-R14 -> 0.011404846 | Y14: =M14-S14 -> 0.033467492 | Z14: =N14-T14 -> 0.17245328 | AA14: =O14-U14 -> -0.030373116 | AB14: {=SQRT(SUMPRODUCT(((J14:O14-P14:U14)/$AL$3:$AQ$3)^2)/6)*100} -> 0.62589692 | AJ14: =ABS(B14-E14) -> 0.14 | AK14: 496.63892
A15: 0.35944565 | B15: 0.18 | C15: 5.4978 | D15: 1.2877653 | E15: 0.04 | F15: 2.3562 | G15: 2.1189458 | H15: 2.2606749 | I15: 0.94750634 | J15: -0.0009529111 | K15: 0.0041426769 | L15: 0.0054550426 | M15: 0.014017973 | N15: -0.72726077 | O15: 0.73515439 | P15: -9.2363259e-05 | Q15: 0.0092716868 | R15: 0.0091990366 | S15: -0.023554302 | T15: -0.65782841 | U15: 0.65738204 | V15: =J15-P15 -> -0.00086054784 | W15: =K15-Q15 -> -0.0051290099 | X15: =L15-R15 -> -0.003743994 | Y15: =M15-S15 -> 0.037572275 | Z15: =N15-T15 -> -0.069432361 | AA15: =O15-U15 -> 0.077772348 | AB15: {=SQRT(SUMPRODUCT(((J15:O15-P15:U15)/$AL$3:$AQ$3)^2)/6)*100} -> 0.338207 | AJ15: =ABS(B15-E15) -> 0.14 | AK15: 2739.2715
... A52: 0.93729511 | B52: 0.14 | C52: 0.7854 | D52: 0.49250416 | E52: 0.1 | F52: 0 | G52: 0.50502447 | H52: 3.7817598 | I52: 0.9447907 | J52: -0.0015078131 | K52: -0.097985812 | L52: 0.14369452 | M52: -0.18748981 | N52: 1.0794333 | O52: 0.62157619 | P52: -0.0084006621 | Q52: -0.091269637 | R52: 0.14186111 | S52: -0.18440193 | T52: 1.1541299 | U52: 0.63933429 | V52: =J52-P52 -> 0.006892849 | W52: =K52-Q52 -> -0.0067161746 | X52: =L52-R52 -> 0.0018334078 | Y52: =M52-S52 -> -0.0030878742 | Z52: =N52-T52 -> -0.074696561 | AA52: =O52-U52 -> -0.017758101 | AB52: {=SQRT(SUMPRODUCT(((J52:O52-P52:U52)/$AL$3:$AQ$3)^2)/6)*100} -> 0.42957288 | AJ52: =ABS(B52-E52) -> 0.04 | AK52: 4678.6266
A53: 0.32556561 | B53: 0.1 | C53: 0 | D53: 1.3745769 | E53: 0.06 | F53: 0 | G53: 2.9612942 | H53: 1.957972 | I53: 4.9734873 | V53: =AVERAGE(V3:V52) -> -0.00035313485 | W53: =AVERAGE(W3:W52) -> -0.00030225398 | X53: =AVERAGE(X3:X52) -> 0.00083417181 | Y53: =AVERAGE(Y3:Y52) -> 0.019528347 | Z53: =AVERAGE(Z3:Z52) -> -0.024389813 | AA53: =AVERAGE(AA3:AA52) -> -0.0066286088 | AK53: 5678.4546
A54: 0.34779034 | B54: 0.08 | C54: 0 | D54: 1.3138898 | E54: 0.04 | F54: 5.4978 | G54: 0.37278425 | H54: 4.7468756 | I54: 0.20226029 | AK54: 5180.4533
A55: 1.1244387 | B55: 0.06 | C55: 2.3562 | D55: 1.2912704 | E55: 0.02 | F55: 5.4978 | G55: 4.9064021 | H55: 2.1650145 | I55: 2.5559004 | AK55: 5663.0654
A56: 0.87685122 | B56: 0.08 | C56: 3.1416 | D56: 1.4399959 | E56: 0.04 | F56: 4.7124 | G56: 2.3478746 | H56: 3.5578307 | I56: 1.9921623 | AK56: 5078.3065
A57: 0.59547924 | B57: 0.08 | C57: 4.7124 | D57: 0.70510202 | E57: 0.04 | F57: 0 | G57: 0.22073046 | H57: 0.018776506 | I57: 2.3333602 | AK57: 1157.8913
A58: 1.3901837 | B58: 0.08 | C58: 4.7124 | D58: 0.3079851 | E58: 0.04 | F58: 4.7124 | G58: 0.73915014 | H58: 2.9227877 | I58: 4.1425656 | AK58: 2905.027
A59: 0.37261525 | B59: 0.16 | C59: 1.5708 | D59: 0.85894297 | E59: 0.12 | F59: 0 | G59: 1.8801243 | H59: 0.57983362 | I59: 4.195338 | AK59: 847.08203
A60: 1.4531678 | B60: 0.12 | C60: 4.7124 | D60: 0.47288274 | E60: 0.08 | F60: 0.7854 | G60: 3.2783511 | H60: 4.7389224 | I60: 3.1449469 | AK60: 5725.3441
A61: 0.36590932 | B61: 0.08 | C61: 2.3562 | D61: 0.32426251 | E61: 0.04 | F61: 5.4978 | G61: 3.2391898 | H61: 1.5107994 | I61: 0.73005405 | AK61: 4839.0903
A62: 0.71858943 | B62: 0.06 | C62: 5.4978 | D62: 1.348295 | E62: 0.02 | F62: 1.5708 | G62: 2.7719249 | H62: 4.6486856 | I62: 4.0642438 | AK62: 4286.1132

Sheet Distal Vali (five hardware)
A1: Ground Truth | J1: 6-Axis FT Sensor | P1: SoRoSim get_distal_value | W1: Distal Errors | AF1: Stats
A2: F1 (N) | B2: s1 (m) | C2: theta1 (rad) | D2: F2 (N) | E2: s2 (m) | F2: theta2 (rad) | G2: tau1 (N) | H2: tau2 (N) | I2: tau3 (N) | J2: Tx (Nm) | K2: Ty (Nm) | L2: Tz(Nm) | M2: Fx (N) | N2: Fy (N) | O2: Fz (N) | P2: F1 (N) | Q2: s1 (m) | R2: theta1 (rad) | S2: F2 (N) | T2: s2 (m) | U2: theta2 (rad) | V2: f_final | W2: F1 (N) | X2: s1 (m) | Y2: theta1 (rad) | Z2: F2 (N) | AA2: s2 (m) | AB2: theta2 (rad) | AC2: force_error | AD2: position_error | AE2: angle_error | AF2: Absolute Mean Error
A3: ='Proximal Validation'!A3 -> 0.57634631 | B3: ='Proximal Validation'!B3 -> 0.2 | C3: ='Proximal Validation'!C3 -> 0.7854 | D3: ='Proximal Validation'!D3 -> 1.1398025 | E3: ='Proximal Validation'!E3 -> 0.02 | F3: ='Proximal Validation'!F3 -> 5.4978 | G3: ='Proximal Validation'!G3 -> 0.49272224 | H3: ='Proximal Validation'!H3 -> 4.4756012 | ... O3: ='Proximal Validation'!O3 -> -0.73825818 | P3: 0.30008328 | Q3: 0.2 | R3: 0.9560814 | S3: 1.0084872 | T3: 0.068475077 | U3: 2.3531445e-14 | V3: 0.0016330647 | W3: =P3-A3 -> -0.27626303 | X3: =Q3-B3 -> -2.409184e-14 | Y3: =MIN(ABS(R3-C3),2*PI()-ABS(R3-C3)) -> 0.1706814 | Z3: =S3-D3 -> -0.1313153 | AA3: =T3-E3 -> 0.048475077 | AB3: =MIN(ABS(U3-F3),2*PI()-ABS(U3-F3)) -> 0.78538531 | AC3: =AVERAGE(ABS(W3),ABS(Z3)) -> 0.20378916 | AD3: =AVERAGE(ABS(X3),ABS(AA3)) -> 0.024237538 | AE3: =AVERAGE(ABS(Y3),ABS(AB3)) -> 0.47803335 | AF3: F1 (N) | AG3: s1 (m) | AH3: theta1 (rad) | AI3: F2 (N) | AJ3: s2 (m) | AK3: theta2 (rad)
A4: ='Proximal Validation'!A4 -> 1.2961946 | B4: ='Proximal Validation'!B4 -> 0.2 | C4: ='Proximal Validation'!C4 -> 4.7124 | D4: ='Proximal Validation'!D4 -> 0.3190756 | E4: ='Proximal Validation'!E4 -> 0.02 | F4: ='Proximal Validation'!F4 -> 1.5708 | G4: ='Proximal Validation'!G4 -> 0.53253118 | H4: ='Proximal Validation'!H4 -> 1.6232894 | ... O4: ='Proximal Validation'!O4 -> -0.55368435 | P4: 1.0563757 | Q4: 0.2 | R4: 4.9334103 | S4: 0.33948937 | T4: 0.2 | U4: 3.9303981 | V4: 0.00032070314 | W4: =P4-A4 -> -0.23981889 | X4: =Q4-B4 -> -2.509104e-14 | Y4: =MIN(ABS(R4-C4),2*PI()-ABS(R4-C4)) -> 0.2210103 | Z4: =S4-D4 -> 0.020413766 | AA4: =T4-E4 -> 0.18 | AB4: =MIN(ABS(U4-F4),2*PI()-ABS(U4-F4)) -> 2.3595981 | AC4: =AVERAGE(ABS(W4),ABS(Z4)) -> 0.13011633 | AD4: =AVERAGE(ABS(X4),ABS(AA4)) -> 0.09 | AE4: =AVERAGE(ABS(Y4),ABS(AB4)) -> 1.2903042 | AF4: {=AVERAGE(ABS(W3:W52))} -> 0.20242022 | AG4: {=AVERAGE(ABS(X3:X52))} -> 0.022673634 | AH4: {=AVERAGE(ABS(Y3:Y52))} -> 0.23784239 | AI4: {=AVERAGE(ABS(Z3:Z52))} -> 0.21950998 | AJ4: {=AVERAGE(ABS(AA3:AA52))} -> 0.024726949 | AK4: {=AVERAGE(ABS(AB3:AB52))} -> 0.3522744
A5: ='Proximal Validation'!A5 -> 0.34328445 | B5: ='Proximal Validation'!B5 -> 0.2 | C5: ='Proximal Validation'!C5 -> 3.1416 | D5: ='Proximal Validation'!D5 -> 0.75633386 | E5: ='Proximal Validation'!E5 -> 0.02 | F5: ='Proximal Validation'!F5 -> 3.1416 | G5: ='Proximal Validation'!G5 -> 3.5593988 | H5: ='Proximal Validation'!H5 -> 2.6173594 | ... O5: ='Proximal Validation'!O5 -> 0.004011631 | P5: 0.40910352 | Q5: 0.17660205 | R5: 3.1410722 | S5: 0.64431491 | T5: 0.02 | U5: 3.1396086 | V5: 9.7135534e-07 | W5: =P5-A5 -> 0.065819065 | X5: =Q5-B5 -> -0.023397954 | Y5: =MIN(ABS(R5-C5),2*PI()-ABS(R5-C5)) -> 0.00052780743 | Z5: =S5-D5 -> -0.11201895 | AA5: =T5-E5 -> 1.4960688e-10 | AB5: =MIN(ABS(U5-F5),2*PI()-ABS(U5-F5)) -> 0.0019914063 | AC5: =AVERAGE(ABS(W5),ABS(Z5)) -> 0.088919008 | AD5: =AVERAGE(ABS(X5),ABS(AA5)) -> 0.011698977 | AE5: =AVERAGE(ABS(Y5),ABS(AB5)) -> 0.0012596068 | AF5: Absolute Mean Error (Across Both Forces)
A6: ='Proximal Validation'!A6 -> 0.83277602 | B6: ='Proximal Validation'!B6 -> 0.2 | C6: ='Proximal Validation'!C6 -> 4.7124 | D6: ='Proximal Validation'!D6 -> 1.4193655 | E6: ='Proximal Validation'!E6 -> 0.04 | F6: ='Proximal Validation'!F6 -> 5.4978 | G6: ='Proximal Validation'!G6 -> 4.2084859 | H6: ='Proximal Validation'!H6 -> 0.52916698 | ... O6: ='Proximal Validation'!O6 -> -1.7768694 | P6: 0.84538624 | Q6: 0.2 | R6: 4.7135121 | S6: 1.3872615 | T6: 0.039152432 | U6: 5.460998 | V6: 2.5682735e-06 | W6: =P6-A6 -> 0.012610211 | X6: =Q6-B6 -> -2.1260652e-09 | Y6: =MIN(ABS(R6-C6),2*PI()-ABS(R6-C6)) -> 0.0011121167 | Z6: =S6-D6 -> -0.032104039 | AA6: =T6-E6 -> -0.00084756786 | AB6: =MIN(ABS(U6-F6),2*PI()-ABS(U6-F6)) -> 0.036802044 | AC6: =AVERAGE(ABS(W6),ABS(Z6)) -> 0.022357125 | AD6: =AVERAGE(ABS(X6),ABS(AA6)) -> 0.00042378499 | AE6: =AVERAGE(ABS(Y6),ABS(AB6)) -> 0.01895708 | AF6: force_error | AG6: position_error | AH6: angle_error
A7: ='Proximal Validation'!A7 -> 0.38984039 | B7: ='Proximal Validation'!B7 -> 0.2 | C7: ='Proximal Validation'!C7 -> 1.5708 | D7: ='Proximal Validation'!D7 -> 0.45028829 | E7: ='Proximal Validation'!E7 -> 0.04 | F7: ='Proximal Validation'!F7 -> 2.3562 | G7: ='Proximal Validation'!G7 -> 0.34676129 | H7: ='Proximal Validation'!H7 -> 0.93612471 | ... O7: ='Proximal Validation'!O7 -> 0.54981846 | P7: 0.39926334 | Q7: 0.2 | R7: 1.5462717 | S7: 0.42173079 | T7: 0.04070437 | U7: 2.5123148 | V7: 7.406691e-07 | W7: =P7-A7 -> 0.0094229517 | X7: =Q7-B7 -> -2.220446e-14 | Y7: =MIN(ABS(R7-C7),2*PI()-ABS(R7-C7)) -> 0.024528339 | Z7: =S7-D7 -> -0.028557496 | AA7: =T7-E7 -> 0.00070436997 | AB7: =MIN(ABS(U7-F7),2*PI()-ABS(U7-F7)) -> 0.15611477 | AC7: =AVERAGE(ABS(W7),ABS(Z7)) -> 0.018990224 | AD7: =AVERAGE(ABS(X7),ABS(AA7)) -> 0.00035218499 | AE7: =AVERAGE(ABS(Y7),ABS(AB7)) -> 0.090321552 | AF7: =AVERAGE(AF4,AI4) -> 0.2109651 | AG7: =AVERAGE(AG4,AJ4) -> 0.023700292 | AH7: =AVERAGE(AH4,AK4) -> 0.29505839
A8: ='Proximal Validation'!A8 -> 0.86958753 | B8: ='Proximal Validation'!B8 -> 0.2 | C8: ='Proximal Validation'!C8 -> 0.7854 | D8: ='Proximal Validation'!D8 -> 0.66933871 | E8: ='Proximal Validation'!E8 -> 0.04 | F8: ='Proximal Validation'!F8 -> 0.7854 | G8: ='Proximal Validation'!G8 -> 2.0486074 | H8: ='Proximal Validation'!H8 -> 1.4427409 | ... O8: ='Proximal Validation'!O8 -> 0.92608899 | P8: 0.84739596 | Q8: 0.19999456 | R8: 0.75235207 | S8: 0.67758753 | T8: 0.047895407 | U8: 0.77184972 | V8: 3.2277359e-07 | W8: =P8-A8 -> -0.022191564 | X8: =Q8-B8 -> -5.4407295e-06 | Y8: =MIN(ABS(R8-C8),2*PI()-ABS(R8-C8)) -> 0.033047929 | Z8: =S8-D8 -> 0.0082488154 | AA8: =T8-E8 -> 0.0078954065 | AB8: =MIN(ABS(U8-F8),2*PI()-ABS(U8-F8)) -> 0.013550284 | AC8: =AVERAGE(ABS(W8),ABS(Z8)) -> 0.01522019 | AD8: =AVERAGE(ABS(X8),ABS(AA8)) -> 0.0039504236 | AE8: =AVERAGE(ABS(Y8),ABS(AB8)) -> 0.023299107 | AF8: =MEDIAN(AC3:AC52) -> 0.18759022 | AG8: =MEDIAN(AD3:AD52) -> 0.013895428 | AH8: =MEDIAN(AE3:AE52) -> 0.16829292
A9: ='Proximal Validation'!A9 -> 1.2260242 | B9: ='Proximal Validation'!B9 -> 0.2 | C9: ='Proximal Validation'!C9 -> 3.1416 | D9: ='Proximal Validation'!D9 -> 0.53124592 | E9: ='Proximal Validation'!E9 -> 0.04 | F9: ='Proximal Validation'!F9 -> 1.5708 | G9: ='Proximal Validation'!G9 -> 2.1721906 | H9: ='Proximal Validation'!H9 -> 4.859274 | ... O9: ='Proximal Validation'!O9 -> 0.72559178 | P9: 1.4460702 | Q9: 0.2 | R9: 3.4298919 | S9: 0.98677932 | T9: 0.10725731 | U9: 1.3566776 | V9: 1.0049043e-05 | W9: =P9-A9 -> 0.22004603 | X9: =Q9-B9 -> -2.220446e-14 | Y9: =MIN(ABS(R9-C9),2*PI()-ABS(R9-C9)) -> 0.28829188 | Z9: =S9-D9 -> 0.4555334 | AA9: =T9-E9 -> 0.067257314 | AB9: =MIN(ABS(U9-F9),2*PI()-ABS(U9-F9)) -> 0.21412244 | AC9: =AVERAGE(ABS(W9),ABS(Z9)) -> 0.33778972 | AD9: =AVERAGE(ABS(X9),ABS(AA9)) -> 0.033628657 | AE9: =AVERAGE(ABS(Y9),ABS(AB9)) -> 0.25120716
A10: ='Proximal Validation'!A10 -> 1.4922792 | B10: ='Proximal Validation'!B10 -> 0.2 | C10: ='Proximal Validation'!C10 -> 2.3562 | D10: ='Proximal Validation'!D10 -> 1.2493009 | E10: ='Proximal Validation'!E10 -> 0.04 | F10: ='Proximal Validation'!F10 -> 0.7854 | G10: ='Proximal Validation'!G10 -> 0.65138204 | H10: ='Proximal Validation'!H10 -> 2.3960292 | ... O10: ='Proximal Validation'!O10 -> 1.7137415 | P10: 1.5 | Q10: 0.2 | R10: 2.4338701 | S10: 1.4033549 | T10: 0.051167562 | U10: 0.84389062 | V10: 5.5788099e-05 | W10: =P10-A10 -> 0.0077207725 | X10: =Q10-B10 -> -1.8045843e-12 | Y10: =MIN(ABS(R10-C10),2*PI()-ABS(R10-C10)) -> 0.077670118 | Z10: =S10-D10 -> 0.15405398 | AA10: =T10-E10 -> 0.011167562 | AB10: =MIN(ABS(U10-F10),2*PI()-ABS(U10-F10)) -> 0.058490624 | AC10: =AVERAGE(ABS(W10),ABS(Z10)) -> 0.080887375 | AD10: =AVERAGE(ABS(X10),ABS(AA10)) -> 0.005583781 | AE10: =AVERAGE(ABS(Y10),ABS(AB10)) -> 0.068080371
A11: ='Proximal Validation'!A11 -> 1.425868 | B11: ='Proximal Validation'!B11 -> 0.2 | C11: ='Proximal Validation'!C11 -> 4.7124 | D11: ='Proximal Validation'!D11 -> 0.35291314 | E11: ='Proximal Validation'!E11 -> 0.04 | F11: ='Proximal Validation'!F11 -> 0 | G11: ='Proximal Validation'!G11 -> 3.481026 | H11: ='Proximal Validation'!H11 -> 1.1294031 | ... O11: ='Proximal Validation'!O11 -> -0.71812153 | P11: 1.4999269 | Q11: 0.19996214 | R11: 4.3624651 | S11: 0.7838527 | T11: 0.14183921 | U11: 6.2831843 | V11: 1.7112993e-05 | W11: =P11-A11 -> 0.074058892 | X11: =Q11-B11 -> -3.7856811e-05 | Y11: =MIN(ABS(R11-C11),2*PI()-ABS(R11-C11)) -> 0.34993487 | Z11: =S11-D11 -> 0.43093956 | AA11: =T11-E11 -> 0.10183921 | AB11: =MIN(ABS(U11-F11),2*PI()-ABS(U11-F11)) -> 1.0256078e-06 | AC11: =AVERAGE(ABS(W11),ABS(Z11)) -> 0.25249922 | AD11: =AVERAGE(ABS(X11),ABS(AA11)) -> 0.050938531 | AE11: =AVERAGE(ABS(Y11),ABS(AB11)) -> 0.17496795
A12: ='Proximal Validation'!A12 -> 1.2847664 | B12: ='Proximal Validation'!B12 -> 0.18 | C12: ='Proximal Validation'!C12 -> 0.7854 | D12: ='Proximal Validation'!D12 -> 0.98965387 | E12: ='Proximal Validation'!E12 -> 0.04 | F12: ='Proximal Validation'!F12 -> 3.927 | G12: ='Proximal Validation'!G12 -> 3.2068327 | H12: ='Proximal Validation'!H12 -> 3.5469168 | ... O12: ='Proximal Validation'!O12 -> -0.15328422 | P12: 1.3875632 | Q12: 0.16558391 | R12: 0.78810559 | S12: 1.2095301 | T12: 0.034023728 | U12: 3.93537 | V12: 3.679893e-08 | W12: =P12-A12 -> 0.1027968 | X12: =Q12-B12 -> -0.014416089 | Y12: =MIN(ABS(R12-C12),2*PI()-ABS(R12-C12)) -> 0.0027055907 | Z12: =S12-D12 -> 0.21987623 | AA12: =T12-E12 -> -0.0059762721 | AB12: =MIN(ABS(U12-F12),2*PI()-ABS(U12-F12)) -> 0.0083699788 | AC12: =AVERAGE(ABS(W12),ABS(Z12)) -> 0.16133651 | AD12: =AVERAGE(ABS(X12),ABS(AA12)) -> 0.01019618 | AE12: =AVERAGE(ABS(Y12),ABS(AB12)) -> 0.0055377848
A13: ='Proximal Validation'!A13 -> 0.82078889 | B13: ='Proximal Validation'!B13 -> 0.18 | C13: ='Proximal Validation'!C13 -> 0 | D13: ='Proximal Validation'!D13 -> 1.3252826 | E13: ='Proximal Validation'!E13 -> 0.04 | F13: ='Proximal Validation'!F13 -> 0 | G13: ='Proximal Validation'!G13 -> 0.039081994 | H13: ='Proximal Validation'!H13 -> 2.9262885 | ... O13: ='Proximal Validation'!O13 -> 0.085576177 | P13: 0.87842047 | Q13: 0.18389758 | R13: 0.025632786 | S13: 1.2485459 | T13: 0.034209087 | U13: 1.2873175e-07 | V13: 8.4300232e-08 | W13: =P13-A13 -> 0.057631579 | X13: =Q13-B13 -> 0.0038975791 | Y13: =MIN(ABS(R13-C13),2*PI()-ABS(R13-C13)) -> 0.025632786 | Z13: =S13-D13 -> -0.076736695 | AA13: =T13-E13 -> -0.0057909125 | AB13: =MIN(ABS(U13-F13),2*PI()-ABS(U13-F13)) -> 1.2873175e-07 | AC13: =AVERAGE(ABS(W13),ABS(Z13)) -> 0.067184137 | AD13: =AVERAGE(ABS(X13),ABS(AA13)) -> 0.0048442458 | AE13: =AVERAGE(ABS(Y13),ABS(AB13)) -> 0.012816457
A14: ='Proximal Validation'!A14 -> 0.51355825 | B14: ='Proximal Validation'!B14 -> 0.2 | C14: ='Proximal Validation'!C14 -> 2.3562 | D14: ='Proximal Validation'!D14 -> 0.96095191 | E14: ='Proximal Validation'!E14 -> 0.06 | F14: ='Proximal Validation'!F14 -> 0 | G14: ='Proximal Validation'!G14 -> 2.4382389 | H14: ='Proximal Validation'!H14 -> 4.2854047 | ... O14: ='Proximal Validation'!O14 -> 0.28229478 | P14: 0.51134715 | Q14: 0.19999998 | R14: 2.383345 | S14: 1.0381958 | T14: 0.061626731 | U14: 1.8540497e-13 | V14: 3.2262855e-08 | W14: =P14-A14 -> -0.0022110981 | X14: =Q14-B14 -> -2.1761764e-08 | Y14: =MIN(ABS(R14-C14),2*PI()-ABS(R14-C14)) -> 0.027145026 | Z14: =S14-D14 -> 0.07724386 | AA14: =T14-E14 -> 0.0016267307 | AB14: =MIN(ABS(U14-F14),2*PI()-ABS(U14-F14)) -> 1.8540497e-13 | AC14: =AVERAGE(ABS(W14),ABS(Z14)) -> 0.039727479 | AD14: =AVERAGE(ABS(X14),ABS(AA14)) -> 0.00081337621 | AE14: =AVERAGE(ABS(Y14),ABS(AB14)) -> 0.013572513
A15: ='Proximal Validation'!A15 -> 0.35944565 | B15: ='Proximal Validation'!B15 -> 0.18 | C15: ='Proximal Validation'!C15 -> 5.4978 | D15: ='Proximal Validation'!D15 -> 1.2877653 | E15: ='Proximal Validation'!E15 -> 0.04 | F15: ='Proximal Validation'!F15 -> 2.3562 | G15: ='Proximal Validation'!G15 -> 2.1189458 | H15: ='Proximal Validation'!H15 -> 2.2606749 | ... O15: ='Proximal Validation'!O15 -> 0.73515439 | P15: 0.30331478 | Q15: 0.02000159 | R15: 3.2003502 | S15: 0.60830726 | T15: 0.02 | U15: 1.9675712 | V15: 0.00077532357 | W15: =P15-A15 -> -0.056130869 | X15: =Q15-B15 -> -0.15999841 | Y15: =MIN(ABS(R15-C15),2*PI()-ABS(R15-C15)) -> 2.2974498 | Z15: =S15-D15 -> -0.67945801 | AA15: =T15-E15 -> -0.02 | AB15: =MIN(ABS(U15-F15),2*PI()-ABS(U15-F15)) -> 0.38862875 | AC15: =AVERAGE(ABS(W15),ABS(Z15)) -> 0.36779444 | AD15: =AVERAGE(ABS(X15),ABS(AA15)) -> 0.089999205 | AE15: =AVERAGE(ABS(Y15),ABS(AB15)) -> 1.3430393
A16: ='Proximal Validation'!A16 -> 1.2267526 | B16: ='Proximal Validation'!B16 -> 0.16 | C16: ='Proximal Validation'!C16 -> 5.4978 | D16: ='Proximal Validation'!D16 -> 1.4944717 | E16: ='Proximal Validation'!E16 -> 0.04 | F16: ='Proximal Validation'!F16 -> 3.927 | G16: ='Proximal Validation'!G16 -> 0.31884208 | H16: ='Proximal Validation'!H16 -> 3.8007215 | ... O16: ='Proximal Validation'!O16 -> -1.7303516 | P16: 1.2826566 | Q16: 0.15567026 | R16: 5.3654494 | S16: 1.3305312 | T16: 0.023004368 | U16: 3.8293388 | V16: 1.8360964e-07 | W16: =P16-A16 -> 0.05590398 | X16: =Q16-B16 -> -0.0043297377 | Y16: =MIN(ABS(R16-C16),2*PI()-ABS(R16-C16)) -> 0.13235061 | Z16: =S16-D16 -> -0.16394043 | AA16: =T16-E16 -> -0.016995632 | AB16: =MIN(ABS(U16-F16),2*PI()-ABS(U16-F16)) -> 0.097661245 | AC16: =AVERAGE(ABS(W16),ABS(Z16)) -> 0.1099222 | AD16: =AVERAGE(ABS(X16),ABS(AA16)) -> 0.010662685 | AE16: =AVERAGE(ABS(Y16),ABS(AB16)) -> 0.11500593
A17: ='Proximal Validation'!A17 -> 0.64421489 | B17: ='Proximal Validation'!B17 -> 0.14 | C17: ='Proximal Validation'!C17 -> 0 | D17: ='Proximal Validation'!D17 -> 0.85234708 | E17: ='Proximal Validation'!E17 -> 0.02 | F17: ='Proximal Validation'!F17 -> 4.7124 | G17: ='Proximal Validation'!G17 -> 0.080437149 | H17: ='Proximal Validation'!H17 -> 0.35167971 | ... O17: ='Proximal Validation'!O17 -> -0.917853 | P17: 0.49981393 | Q17: 0.17687428 | R17: 0.033621154 | S17: 0.90619312 | T17: 0.02 | U17: 4.8528269 | V17: 2.5308656e-08 | W17: =P17-A17 -> -0.14440096 | X17: =Q17-B17 -> 0.036874282 | Y17: =MIN(ABS(R17-C17),2*PI()-ABS(R17-C17)) -> 0.033621154 | Z17: =S17-D17 -> 0.053846037 | AA17: =T17-E17 -> 2.1034809e-11 | AB17: =MIN(ABS(U17-F17),2*PI()-ABS(U17-F17)) -> 0.14042686 | AC17: =AVERAGE(ABS(W17),ABS(Z17)) -> 0.099123499 | AD17: =AVERAGE(ABS(X17),ABS(AA17)) -> 0.018437141 | AE17: =AVERAGE(ABS(Y17),ABS(AB17)) -> 0.087024007
A18: ='Proximal Validation'!A18 -> 1.1302548 | B18: ='Proximal Validation'!B18 -> 0.16 | C18: ='Proximal Validation'!C18 -> 4.7124 | D18: ='Proximal Validation'!D18 -> 1.3446433 | E18: ='Proximal Validation'!E18 -> 0.04 | F18: ='Proximal Validation'!F18 -> 0 | G18: ='Proximal Validation'!G18 -> 1.0644223 | H18: ='Proximal Validation'!H18 -> 1.4761094 | ... O18: ='Proximal Validation'!O18 -> -0.79624254 | P18: 1.3298756 | Q18: 0.14548266 | R18: 4.6266813 | S18: 1.5 | T18: 0.049676028 | U18: 0.18903784 | V18: 1.8245024e-07 | W18: =P18-A18 -> 0.19962079 | X18: =Q18-B18 -> -0.014517338 | Y18: =MIN(ABS(R18-C18),2*PI()-ABS(R18-C18)) -> 0.085718713 | Z18: =S18-D18 -> 0.15535661 | AA18: =T18-E18 -> 0.0096760282 | AB18: =MIN(ABS(U18-F18),2*PI()-ABS(U18-F18)) -> 0.18903784 | AC18: =AVERAGE(ABS(W18),ABS(Z18)) -> 0.1774887 | AD18: =AVERAGE(ABS(X18),ABS(AA18)) -> 0.012096683 | AE18: =AVERAGE(ABS(Y18),ABS(AB18)) -> 0.13737828
A19: ='Proximal Validation'!A19 -> 0.44052297 | B19: ='Proximal Validation'!B19 -> 0.14 | C19: ='Proximal Validation'!C19 -> 0.7854 | D19: ='Proximal Validation'!D19 -> 1.0539704 | E19: ='Proximal Validation'!E19 -> 0.02 | F19: ='Proximal Validation'!F19 -> 3.1416 | G19: ='Proximal Validation'!G19 -> 2.702723 | H19: ='Proximal Validation'!H19 -> 1.6080542 | ... O19: ='Proximal Validation'!O19 -> 0.34984213 | P19: 0.70938779 | Q19: 0.098200174 | R19: 0.84193466 | S19: 1.2628106 | T19: 0.020085019 | U19: 3.3028551 | V19: 1.7241117e-06 | W19: =P19-A19 -> 0.26886482 | X19: =Q19-B19 -> -0.041799826 | Y19: =MIN(ABS(R19-C19),2*PI()-ABS(R19-C19)) -> 0.056534663 | Z19: =S19-D19 -> 0.20884017 | AA19: =T19-E19 -> 8.5018689e-05 | AB19: =MIN(ABS(U19-F19),2*PI()-ABS(U19-F19)) -> 0.16125509 | AC19: =AVERAGE(ABS(W19),ABS(Z19)) -> 0.23885249 | AD19: =AVERAGE(ABS(X19),ABS(AA19)) -> 0.020942423 | AE19: =AVERAGE(ABS(Y19),ABS(AB19)) -> 0.10889488
A20: ='Proximal Validation'!A20 -> 1.4424756 | B20: ='Proximal Validation'!B20 -> 0.16 | C20: ='Proximal Validation'!C20 -> 0.7854 | D20: ='Proximal Validation'!D20 -> 1.1597422 | E20: ='Proximal Validation'!E20 -> 0.04 | F20: ='Proximal Validation'!F20 -> 2.3562 | G20: ='Proximal Validation'!G20 -> 4.8092587 | H20: ='Proximal Validation'!H20 -> 0.47844339 | ... O20: ='Proximal Validation'!O20 -> 1.7156174 | P20: 1.104589 | Q20: 0.1999138 | R20: 0.61635741 | S20: 1.3949545 | T20: 0.061932535 | U20: 2.1299652 | V20: 4.6749623e-06 | W20: =P20-A20 -> -0.33788658 | X20: =Q20-B20 -> 0.039913799 | Y20: =MIN(ABS(R20-C20),2*PI()-ABS(R20-C20)) -> 0.16904259 | Z20: =S20-D20 -> 0.23521224 | AA20: =T20-E20 -> 0.021932535 | AB20: =MIN(ABS(U20-F20),2*PI()-ABS(U20-F20)) -> 0.22623479 | AC20: =AVERAGE(ABS(W20),ABS(Z20)) -> 0.28654941 | AD20: =AVERAGE(ABS(X20),ABS(AA20)) -> 0.030923167 | AE20: =AVERAGE(ABS(Y20),ABS(AB20)) -> 0.19763869
... A52: ='Proximal Validation'!A52 -> 0.93729511 | B52: ='Proximal Validation'!B52 -> 0.14 | C52: ='Proximal Validation'!C52 -> 0.7854 | D52: ='Proximal Validation'!D52 -> 0.49250416 | E52: ='Proximal Validation'!E52 -> 0.1 | F52: ='Proximal Validation'!F52 -> 0 | G52: ='Proximal Validation'!G52 -> 0.50502447 | H52: ='Proximal Validation'!H52 -> 3.7817598 | ... O52: ='Proximal Validation'!O52 -> 0.62157619 | P52: 0.76970039 | Q52: 0.14010923 | R52: 1.080097 | S52: 0.77030431 | T52: 0.11906765 | U52: 9.3138067e-05 | V52: 1.0455682e-05 | W52: =P52-A52 -> -0.16759471 | X52: =Q52-B52 -> 0.00010923064 | Y52: =MIN(ABS(R52-C52),2*PI()-ABS(R52-C52)) -> 0.29469702 | Z52: =S52-D52 -> 0.27780015 | AA52: =T52-E52 -> 0.019067651 | AB52: =MIN(ABS(U52-F52),2*PI()-ABS(U52-F52)) -> 9.3138067e-05 | AC52: =AVERAGE(ABS(W52),ABS(Z52)) -> 0.22269743 | AD52: =AVERAGE(ABS(X52),ABS(AA52)) -> 0.0095884407 | AE52: =AVERAGE(ABS(Y52),ABS(AB52)) -> 0.14739508

Sheet Distal Vali (one truth)
A1: Ground Truth | J1: 6-Axis FT Sensor | P1: SoRoSim get_distal_value | W1: Distal Errors | AF1: Stats
A2: F1 (N) | B2: s1 (m) | C2: theta1 (rad) | D2: F2 (N) | E2: s2 (m) | F2: theta2 (rad) | G2: tau1 (N) | H2: tau2 (N) | I2: tau3 (N) | J2: Tx (Nm) | K2: Ty (Nm) | L2: Tz(Nm) | M2: Fx (N) | N2: Fy (N) | O2: Fz (N) | P2: F1 (N) | Q2: s1 (m) | R2: theta1 (rad) | S2: F2 (N) | T2: s2 (m) | U2: theta2 (rad) | V2: f_final | W2: F1 (N) | X2: s1 (m) | Y2: theta1 (rad) | Z2: F2 (N) | AA2: s2 (m) | AB2: theta2 (rad) | AC2: force_error | AD2: position_error | AE2: angle_error | AF2: Absolute Mean Error
A3: ='Proximal Validation'!A3 -> 0.57634631 | B3: ='Proximal Validation'!B3 -> 0.2 | C3: ='Proximal Validation'!C3 -> 0.7854 | D3: ='Proximal Validation'!D3 -> 1.1398025 | E3: ='Proximal Validation'!E3 -> 0.02 | F3: ='Proximal Validation'!F3 -> 5.4978 | G3: ='Proximal Validation'!G3 -> 0.49272224 | H3: ='Proximal Validation'!H3 -> 4.4756012 | ... O3: ='Proximal Validation'!O3 -> -0.73825818 | P3: 0.30005353 | Q3: 0.19999596 | R3: 1.2023905 | S3: 1.1040275 | T3: 0.068042566 | U3: 2.8076729e-14 | V3: 0.0012482456 | W3: =P3-A3 -> -0.27629278 | X3: =Q3-B3 -> -4.0424117e-06 | Y3: =MIN(ABS(R3-C3),2*PI()-ABS(R3-C3)) -> 0.41699055 | Z3: =S3-D3 -> -0.035774945 | AA3: =T3-E3 -> 0.048042566 | AB3: =MIN(ABS(U3-F3),2*PI()-ABS(U3-F3)) -> 0.78538531 | AC3: =AVERAGE(ABS(W3),ABS(Z3)) -> 0.15603386 | AD3: =AVERAGE(ABS(X3),ABS(AA3)) -> 0.024023304 | AE3: =AVERAGE(ABS(Y3),ABS(AB3)) -> 0.60118793 | AF3: F1 (N) | AG3: s1 (m) | AH3: theta1 (rad) | AI3: F2 (N) | AJ3: s2 (m) | AK3: theta2 (rad)
A4: ='Proximal Validation'!A4 -> 1.2961946 | B4: ='Proximal Validation'!B4 -> 0.2 | C4: ='Proximal Validation'!C4 -> 4.7124 | D4: ='Proximal Validation'!D4 -> 0.3190756 | E4: ='Proximal Validation'!E4 -> 0.02 | F4: ='Proximal Validation'!F4 -> 1.5708 | G4: ='Proximal Validation'!G4 -> 0.53253118 | H4: ='Proximal Validation'!H4 -> 1.6232894 | ... O4: ='Proximal Validation'!O4 -> -0.55368435 | P4: 1.0251531 | Q4: 0.2 | R4: 4.9537952 | S4: 0.34735988 | T4: 0.2 | U4: 3.928156 | V4: 0.00023235587 | W4: =P4-A4 -> -0.27104146 | X4: =Q4-B4 -> -3.3528735e-14 | Y4: =MIN(ABS(R4-C4),2*PI()-ABS(R4-C4)) -> 0.24139523 | Z4: =S4-D4 -> 0.02828428 | AA4: =T4-E4 -> 0.18 | AB4: =MIN(ABS(U4-F4),2*PI()-ABS(U4-F4)) -> 2.357356 | AC4: =AVERAGE(ABS(W4),ABS(Z4)) -> 0.14966287 | AD4: =AVERAGE(ABS(X4),ABS(AA4)) -> 0.09 | AE4: =AVERAGE(ABS(Y4),ABS(AB4)) -> 1.2993756 | AF4: {=AVERAGE(ABS(W3:W52))} -> 0.16552768 | AG4: {=AVERAGE(ABS(X3:X52))} -> 0.017229483 | AH4: {=AVERAGE(ABS(Y3:Y52))} -> 0.20978998 | AI4: {=AVERAGE(ABS(Z3:Z52))} -> 0.19678395 | AJ4: {=AVERAGE(ABS(AA3:AA52))} -> 0.022567395 | AK4: {=AVERAGE(ABS(AB3:AB52))} -> 0.3818889
A5: ='Proximal Validation'!A5 -> 0.34328445 | B5: ='Proximal Validation'!B5 -> 0.2 | C5: ='Proximal Validation'!C5 -> 3.1416 | D5: ='Proximal Validation'!D5 -> 0.75633386 | E5: ='Proximal Validation'!E5 -> 0.02 | F5: ='Proximal Validation'!F5 -> 3.1416 | G5: ='Proximal Validation'!G5 -> 3.5593988 | H5: ='Proximal Validation'!H5 -> 2.6173594 | ... O5: ='Proximal Validation'!O5 -> 0.004011631 | P5: 0.42780062 | Q5: 0.1619887 | R5: 3.1423535 | S5: 0.67084137 | T5: 0.020042706 | U5: 3.1421356 | V5: 1.1234485e-07 | W5: =P5-A5 -> 0.084516171 | X5: =Q5-B5 -> -0.038011297 | Y5: =MIN(ABS(R5-C5),2*PI()-ABS(R5-C5)) -> 0.00075345168 | Z5: =S5-D5 -> -0.085492493 | AA5: =T5-E5 -> 4.2706006e-05 | AB5: =MIN(ABS(U5-F5),2*PI()-ABS(U5-F5)) -> 0.00053557554 | AC5: =AVERAGE(ABS(W5),ABS(Z5)) -> 0.085004332 | AD5: =AVERAGE(ABS(X5),ABS(AA5)) -> 0.019027001 | AE5: =AVERAGE(ABS(Y5),ABS(AB5)) -> 0.00064451361 | AF5: Absolute Mean Error (Across Both Forces)
A6: ='Proximal Validation'!A6 -> 0.83277602 | B6: ='Proximal Validation'!B6 -> 0.2 | C6: ='Proximal Validation'!C6 -> 4.7124 | D6: ='Proximal Validation'!D6 -> 1.4193655 | E6: ='Proximal Validation'!E6 -> 0.04 | F6: ='Proximal Validation'!F6 -> 5.4978 | G6: ='Proximal Validation'!G6 -> 4.2084859 | H6: ='Proximal Validation'!H6 -> 0.52916698 | ... O6: ='Proximal Validation'!O6 -> -1.7768694 | P6: 0.8383704 | Q6: 0.19814647 | R6: 4.7126217 | S6: 1.4150758 | T6: 0.039944825 | U6: 5.5006507 | V6: 8.3439908e-09 | W6: =P6-A6 -> 0.0055943801 | X6: =Q6-B6 -> -0.0018535329 | Y6: =MIN(ABS(R6-C6),2*PI()-ABS(R6-C6)) -> 0.00022172622 | Z6: =S6-D6 -> -0.0042897618 | AA6: =T6-E6 -> -5.517469e-05 | AB6: =MIN(ABS(U6-F6),2*PI()-ABS(U6-F6)) -> 0.0028507188 | AC6: =AVERAGE(ABS(W6),ABS(Z6)) -> 0.0049420709 | AD6: =AVERAGE(ABS(X6),ABS(AA6)) -> 0.00095435381 | AE6: =AVERAGE(ABS(Y6),ABS(AB6)) -> 0.0015362225 | AF6: force_error | AG6: position_error | AH6: angle_error
A7: ='Proximal Validation'!A7 -> 0.38984039 | B7: ='Proximal Validation'!B7 -> 0.2 | C7: ='Proximal Validation'!C7 -> 1.5708 | D7: ='Proximal Validation'!D7 -> 0.45028829 | E7: ='Proximal Validation'!E7 -> 0.04 | F7: ='Proximal Validation'!F7 -> 2.3562 | G7: ='Proximal Validation'!G7 -> 0.34676129 | H7: ='Proximal Validation'!H7 -> 0.93612471 | ... O7: ='Proximal Validation'!O7 -> 0.54981846 | P7: 0.47050505 | Q7: 0.17374168 | R7: 1.6073795 | S7: 0.38325241 | T7: 0.032343177 | U7: 2.4738429 | V7: 5.2096842e-08 | W7: =P7-A7 -> 0.080664664 | X7: =Q7-B7 -> -0.026258319 | Y7: =MIN(ABS(R7-C7),2*PI()-ABS(R7-C7)) -> 0.036579533 | Z7: =S7-D7 -> -0.067035874 | AA7: =T7-E7 -> -0.0076568228 | AB7: =MIN(ABS(U7-F7),2*PI()-ABS(U7-F7)) -> 0.11764288 | AC7: =AVERAGE(ABS(W7),ABS(Z7)) -> 0.073850269 | AD7: =AVERAGE(ABS(X7),ABS(AA7)) -> 0.016957571 | AE7: =AVERAGE(ABS(Y7),ABS(AB7)) -> 0.077111207 | AF7: =AVERAGE(AF4,AI4) -> 0.18115581 | AG7: =AVERAGE(AG4,AJ4) -> 0.019898439 | AH7: =AVERAGE(AH4,AK4) -> 0.29583944
A8: ='Proximal Validation'!A8 -> 0.86958753 | B8: ='Proximal Validation'!B8 -> 0.2 | C8: ='Proximal Validation'!C8 -> 0.7854 | D8: ='Proximal Validation'!D8 -> 0.66933871 | E8: ='Proximal Validation'!E8 -> 0.04 | F8: ='Proximal Validation'!F8 -> 0.7854 | G8: ='Proximal Validation'!G8 -> 2.0486074 | H8: ='Proximal Validation'!H8 -> 1.4427409 | ... O8: ='Proximal Validation'!O8 -> 0.92608899 | P8: 0.8889062 | Q8: 0.19614968 | R8: 0.78543346 | S8: 0.65129851 | T8: 0.038527912 | U8: 0.78590927 | V8: 5.6592516e-09 | W8: =P8-A8 -> 0.019318677 | X8: =Q8-B8 -> -0.0038503239 | Y8: =MIN(ABS(R8-C8),2*PI()-ABS(R8-C8)) -> 3.345719e-05 | Z8: =S8-D8 -> -0.0180402 | AA8: =T8-E8 -> -0.0014720882 | AB8: =MIN(ABS(U8-F8),2*PI()-ABS(U8-F8)) -> 0.00050927244 | AC8: =AVERAGE(ABS(W8),ABS(Z8)) -> 0.018679438 | AD8: =AVERAGE(ABS(X8),ABS(AA8)) -> 0.002661206 | AE8: =AVERAGE(ABS(Y8),ABS(AB8)) -> 0.00027136481 | AF8: =MEDIAN(AC3:AC52) -> 0.14828344 | AG8: =MEDIAN(AD3:AD52) -> 0.010117486
A9: ='Proximal Validation'!A9 -> 1.2260242 | B9: ='Proximal Validation'!B9 -> 0.2 | C9: ='Proximal Validation'!C9 -> 3.1416 | D9: ='Proximal Validation'!D9 -> 0.53124592 | E9: ='Proximal Validation'!E9 -> 0.04 | F9: ='Proximal Validation'!F9 -> 1.5708 | G9: ='Proximal Validation'!G9 -> 2.1721906 | H9: ='Proximal Validation'!H9 -> 4.859274 | ... O9: ='Proximal Validation'!O9 -> 0.72559178 | P9: 1.226009 | Q9: 0.1999997 | R9: 3.1421241 | S9: 0.53174098 | T9: 0.040192938 | U9: 1.5707493 | V9: 3.5481559e-11 | W9: =P9-A9 -> -1.5223175e-05 | X9: =Q9-B9 -> -3.0344637e-07 | Y9: =MIN(ABS(R9-C9),2*PI()-ABS(R9-C9)) -> 0.00052407453 | Z9: =S9-D9 -> 0.00049506241 | AA9: =T9-E9 -> 0.00019293766 | AB9: =MIN(ABS(U9-F9),2*PI()-ABS(U9-F9)) -> 5.0749753e-05 | AC9: =AVERAGE(ABS(W9),ABS(Z9)) -> 0.00025514279 | AD9: =AVERAGE(ABS(X9),ABS(AA9)) -> 9.6620553e-05 | AE9: =AVERAGE(ABS(Y9),ABS(AB9)) -> 0.00028741214
A10: ='Proximal Validation'!A10 -> 1.4922792 | B10: ='Proximal Validation'!B10 -> 0.2 | C10: ='Proximal Validation'!C10 -> 2.3562 | D10: ='Proximal Validation'!D10 -> 1.2493009 | E10: ='Proximal Validation'!E10 -> 0.04 | F10: ='Proximal Validation'!F10 -> 0.7854 | G10: ='Proximal Validation'!G10 -> 0.65138204 | H10: ='Proximal Validation'!H10 -> 2.3960292 | ... O10: ='Proximal Validation'!O10 -> 1.7137415 | P10: 1.4927794 | Q10: 0.19949082 | R10: 2.3697247 | S10: 1.2651625 | T10: 0.042448127 | U10: 0.78402945 | V10: 1.6223402e-08 | W10: =P10-A10 -> 0.00050013289 | X10: =Q10-B10 -> -0.00050918146 | Y10: =MIN(ABS(R10-C10),2*PI()-ABS(R10-C10)) -> 0.013524689 | Z10: =S10-D10 -> 0.015861613 | AA10: =T10-E10 -> 0.0024481273 | AB10: =MIN(ABS(U10-F10),2*PI()-ABS(U10-F10)) -> 0.001370545 | AC10: =AVERAGE(ABS(W10),ABS(Z10)) -> 0.0081808728 | AD10: =AVERAGE(ABS(X10),ABS(AA10)) -> 0.0014786544 | AE10: =AVERAGE(ABS(Y10),ABS(AB10)) -> 0.0074476172
A11: ='Proximal Validation'!A11 -> 1.425868 | B11: ='Proximal Validation'!B11 -> 0.2 | C11: ='Proximal Validation'!C11 -> 4.7124 | D11: ='Proximal Validation'!D11 -> 0.35291314 | E11: ='Proximal Validation'!E11 -> 0.04 | F11: ='Proximal Validation'!F11 -> 0 | G11: ='Proximal Validation'!G11 -> 3.481026 | H11: ='Proximal Validation'!H11 -> 1.1294031 | ... O11: ='Proximal Validation'!O11 -> -0.71812153 | P11: 1.4949052 | Q11: 0.1989041 | R11: 4.3463146 | S11: 0.81732867 | T11: 0.14362868 | U11: 6.2831853 | V11: 2.6388188e-05 | W11: =P11-A11 -> 0.069037178 | X11: =Q11-B11 -> -0.0010958977 | Y11: =MIN(ABS(R11-C11),2*PI()-ABS(R11-C11)) -> 0.36608544 | Z11: =S11-D11 -> 0.46441553 | AA11: =T11-E11 -> 0.10362868 | AB11: =MIN(ABS(U11-F11),2*PI()-ABS(U11-F11)) -> 2.220446e-14 | AC11: =AVERAGE(ABS(W11),ABS(Z11)) -> 0.26672635 | AD11: =AVERAGE(ABS(X11),ABS(AA11)) -> 0.052362287 | AE11: =AVERAGE(ABS(Y11),ABS(AB11)) -> 0.18304272
A12: ='Proximal Validation'!A12 -> 1.2847664 | B12: ='Proximal Validation'!B12 -> 0.18 | C12: ='Proximal Validation'!C12 -> 0.7854 | D12: ='Proximal Validation'!D12 -> 0.98965387 | E12: ='Proximal Validation'!E12 -> 0.04 | F12: ='Proximal Validation'!F12 -> 3.927 | G12: ='Proximal Validation'!G12 -> 3.2068327 | H12: ='Proximal Validation'!H12 -> 3.5469168 | ... O12: ='Proximal Validation'!O12 -> -0.15328422 | P12: 0.59908204 | Q12: 0.2 | R12: 1.3415606 | S12: 0.51843077 | T12: 0.2 | U12: 0.099330323 | V12: 0.0012841403 | W12: =P12-A12 -> -0.68568435 | X12: =Q12-B12 -> 0.02 | Y12: =MIN(ABS(R12-C12),2*PI()-ABS(R12-C12)) -> 0.55616064 | Z12: =S12-D12 -> -0.4712231 | AA12: =T12-E12 -> 0.16 | AB12: =MIN(ABS(U12-F12),2*PI()-ABS(U12-F12)) -> 2.4555156 | AC12: =AVERAGE(ABS(W12),ABS(Z12)) -> 0.57845373 | AD12: =AVERAGE(ABS(X12),ABS(AA12)) -> 0.09 | AE12: =AVERAGE(ABS(Y12),ABS(AB12)) -> 1.5058381
A13: ='Proximal Validation'!A13 -> 0.82078889 | B13: ='Proximal Validation'!B13 -> 0.18 | C13: ='Proximal Validation'!C13 -> 0 | D13: ='Proximal Validation'!D13 -> 1.3252826 | E13: ='Proximal Validation'!E13 -> 0.04 | F13: ='Proximal Validation'!F13 -> 0 | G13: ='Proximal Validation'!G13 -> 0.039081994 | H13: ='Proximal Validation'!H13 -> 2.9262885 | ... O13: ='Proximal Validation'!O13 -> 0.085576177 | P13: 0.84271558 | Q13: 0.17784834 | R13: 8.1567818e-10 | S13: 1.3037219 | T13: 0.038756662 | U13: 8.3406533e-10 | V13: 4.7285358e-09 | W13: =P13-A13 -> 0.021926691 | X13: =Q13-B13 -> -0.0021516578 | Y13: =MIN(ABS(R13-C13),2*PI()-ABS(R13-C13)) -> 8.1567818e-10 | Z13: =S13-D13 -> -0.021560677 | AA13: =T13-E13 -> -0.0012433376 | AB13: =MIN(ABS(U13-F13),2*PI()-ABS(U13-F13)) -> 8.3406533e-10 | AC13: =AVERAGE(ABS(W13),ABS(Z13)) -> 0.021743684 | AD13: =AVERAGE(ABS(X13),ABS(AA13)) -> 0.0016974977 | AE13: =AVERAGE(ABS(Y13),ABS(AB13)) -> 8.2487175e-10
A14: ='Proximal Validation'!A14 -> 0.51355825 | B14: ='Proximal Validation'!B14 -> 0.2 | C14: ='Proximal Validation'!C14 -> 2.3562 | D14: ='Proximal Validation'!D14 -> 0.96095191 | E14: ='Proximal Validation'!E14 -> 0.06 | F14: ='Proximal Validation'!F14 -> 0 | G14: ='Proximal Validation'!G14 -> 2.4382389 | H14: ='Proximal Validation'!H14 -> 4.2854047 | ... O14: ='Proximal Validation'!O14 -> 0.28229478 | P14: 0.50712888 | Q14: 0.2 | R14: 2.3451147 | S14: 0.95318305 | T14: 0.058657204 | U14: 8.8659105e-12 | V14: 2.4737851e-08 | W14: =P14-A14 -> -0.0064293629 | X14: =Q14-B14 -> -6.2760908e-13 | Y14: =MIN(ABS(R14-C14),2*PI()-ABS(R14-C14)) -> 0.011085265 | Z14: =S14-D14 -> -0.0077688554 | AA14: =T14-E14 -> -0.001342796 | AB14: =MIN(ABS(U14-F14),2*PI()-ABS(U14-F14)) -> 8.8659105e-12 | AC14: =AVERAGE(ABS(W14),ABS(Z14)) -> 0.0070991091 | AD14: =AVERAGE(ABS(X14),ABS(AA14)) -> 0.00067139802 | AE14: =AVERAGE(ABS(Y14),ABS(AB14)) -> 0.0055426326
A15: ='Proximal Validation'!A15 -> 0.35944565 | B15: ='Proximal Validation'!B15 -> 0.18 | C15: ='Proximal Validation'!C15 -> 5.4978 | D15: ='Proximal Validation'!D15 -> 1.2877653 | E15: ='Proximal Validation'!E15 -> 0.04 | F15: ='Proximal Validation'!F15 -> 2.3562 | G15: ='Proximal Validation'!G15 -> 2.1189458 | H15: ='Proximal Validation'!H15 -> 2.2606749 | ... O15: ='Proximal Validation'!O15 -> 0.73515439 | P15: 0.3026944 | Q15: 0.02000175 | R15: 3.3091918 | S15: 0.58981544 | T15: 0.02 | U15: 1.9260011 | V15: 0.00086431283 | W15: =P15-A15 -> -0.056751244 | X15: =Q15-B15 -> -0.15999825 | Y15: =MIN(ABS(R15-C15),2*PI()-ABS(R15-C15)) -> 2.1886082 | Z15: =S15-D15 -> -0.69794983 | AA15: =T15-E15 -> -0.02 | AB15: =MIN(ABS(U15-F15),2*PI()-ABS(U15-F15)) -> 0.43019893 | AC15: =AVERAGE(ABS(W15),ABS(Z15)) -> 0.37735054 | AD15: =AVERAGE(ABS(X15),ABS(AA15)) -> 0.089999125 | AE15: =AVERAGE(ABS(Y15),ABS(AB15)) -> 1.3094036
A16: ='Proximal Validation'!A16 -> 1.2267526 | B16: ='Proximal Validation'!B16 -> 0.16 | C16: ='Proximal Validation'!C16 -> 5.4978 | D16: ='Proximal Validation'!D16 -> 1.4944717 | E16: ='Proximal Validation'!E16 -> 0.04 | F16: ='Proximal Validation'!F16 -> 3.927 | G16: ='Proximal Validation'!G16 -> 0.31884208 | H16: ='Proximal Validation'!H16 -> 3.8007215 | ... O16: ='Proximal Validation'!O16 -> -1.7303516 | P16: 1.2960284 | Q16: 0.15410679 | R16: 5.3588917 | S16: 1.3198251 | T16: 0.024675522 | U16: 3.8815797 | V16: 7.0815608e-07 | W16: =P16-A16 -> 0.069275817 | X16: =Q16-B16 -> -0.0058932061 | Y16: =MIN(ABS(R16-C16),2*PI()-ABS(R16-C16)) -> 0.1389083 | Z16: =S16-D16 -> -0.17464661 | AA16: =T16-E16 -> -0.015324478 | AB16: =MIN(ABS(U16-F16),2*PI()-ABS(U16-F16)) -> 0.045420271 | AC16: =AVERAGE(ABS(W16),ABS(Z16)) -> 0.12196121 | AD16: =AVERAGE(ABS(X16),ABS(AA16)) -> 0.010608842 | AE16: =AVERAGE(ABS(Y16),ABS(AB16)) -> 0.092164288
A17: ='Proximal Validation'!A17 -> 0.64421489 | B17: ='Proximal Validation'!B17 -> 0.14 | C17: ='Proximal Validation'!C17 -> 0 | D17: ='Proximal Validation'!D17 -> 0.85234708 | E17: ='Proximal Validation'!E17 -> 0.02 | F17: ='Proximal Validation'!F17 -> 4.7124 | G17: ='Proximal Validation'!G17 -> 0.080437149 | H17: ='Proximal Validation'!H17 -> 0.35167971 | ... O17: ='Proximal Validation'!O17 -> -0.917853 | P17: 0.35034405 | Q17: 0.13687533 | R17: 3.1045543e-11 | S17: 0.30628486 | T17: 0.13682886 | U17: 8.7372876e-11 | V17: 0.0021061595 | W17: =P17-A17 -> -0.29387084 | X17: =Q17-B17 -> -0.0031246689 | Y17: =MIN(ABS(R17-C17),2*PI()-ABS(R17-C17)) -> 3.1045543e-11 | Z17: =S17-D17 -> -0.54606223 | AA17: =T17-E17 -> 0.11682886 | AB17: =MIN(ABS(U17-F17),2*PI()-ABS(U17-F17)) -> 1.5707853 | AC17: =AVERAGE(ABS(W17),ABS(Z17)) -> 0.41996653 | AD17: =AVERAGE(ABS(X17),ABS(AA17)) -> 0.059976766 | AE17: =AVERAGE(ABS(Y17),ABS(AB17)) -> 0.78539265
A18: ='Proximal Validation'!A18 -> 1.1302548 | B18: ='Proximal Validation'!B18 -> 0.16 | C18: ='Proximal Validation'!C18 -> 4.7124 | D18: ='Proximal Validation'!D18 -> 1.3446433 | E18: ='Proximal Validation'!E18 -> 0.04 | F18: ='Proximal Validation'!F18 -> 0 | G18: ='Proximal Validation'!G18 -> 1.0644223 | H18: ='Proximal Validation'!H18 -> 1.4761094 | ... O18: ='Proximal Validation'!O18 -> -0.79624254 | P18: 1.16813 | Q18: 0.15605927 | R18: 4.7002189 | S18: 1.3579656 | T18: 0.04120937 | U18: 0.032460819 | V18: 8.3621096e-09 | W18: =P18-A18 -> 0.037875225 | X18: =Q18-B18 -> -0.0039407279 | Y18: =MIN(ABS(R18-C18),2*PI()-ABS(R18-C18)) -> 0.012181145 | Z18: =S18-D18 -> 0.013322261 | AA18: =T18-E18 -> 0.0012093704 | AB18: =MIN(ABS(U18-F18),2*PI()-ABS(U18-F18)) -> 0.032460819 | AC18: =AVERAGE(ABS(W18),ABS(Z18)) -> 0.025598743 | AD18: =AVERAGE(ABS(X18),ABS(AA18)) -> 0.0025750491 | AE18: =AVERAGE(ABS(Y18),ABS(AB18)) -> 0.022320982
A19: ='Proximal Validation'!A19 -> 0.44052297 | B19: ='Proximal Validation'!B19 -> 0.14 | C19: ='Proximal Validation'!C19 -> 0.7854 | D19: ='Proximal Validation'!D19 -> 1.0539704 | E19: ='Proximal Validation'!E19 -> 0.02 | F19: ='Proximal Validation'!F19 -> 3.1416 | G19: ='Proximal Validation'!G19 -> 2.702723 | H19: ='Proximal Validation'!H19 -> 1.6080542 | ... O19: ='Proximal Validation'!O19 -> 0.34984213 | P19: 0.4807539 | Q19: 0.1312124 | R19: 0.77588106 | S19: 1.0861928 | T19: 0.020703918 | U19: 3.1651476 | V19: 1.1427074e-09 | W19: =P19-A19 -> 0.040230927 | X19: =Q19-B19 -> -0.0087876025 | Y19: =MIN(ABS(R19-C19),2*PI()-ABS(R19-C19)) -> 0.009518942 | Z19: =S19-D19 -> 0.032222441 | AA19: =T19-E19 -> 0.00070391773 | AB19: =MIN(ABS(U19-F19),2*PI()-ABS(U19-F19)) -> 0.023547556 | AC19: =AVERAGE(ABS(W19),ABS(Z19)) -> 0.036226684 | AD19: =AVERAGE(ABS(X19),ABS(AA19)) -> 0.0047457601 | AE19: =AVERAGE(ABS(Y19),ABS(AB19)) -> 0.016533249
A20: ='Proximal Validation'!A20 -> 1.4424756 | B20: ='Proximal Validation'!B20 -> 0.16 | C20: ='Proximal Validation'!C20 -> 0.7854 | D20: ='Proximal Validation'!D20 -> 1.1597422 | E20: ='Proximal Validation'!E20 -> 0.04 | F20: ='Proximal Validation'!F20 -> 2.3562 | G20: ='Proximal Validation'!G20 -> 4.8092587 | H20: ='Proximal Validation'!H20 -> 0.47844339 | ... O20: ='Proximal Validation'!O20 -> 1.7156174 | P20: 1.4425032 | Q20: 0.15999578 | R20: 0.78549504 | S20: 1.1596248 | T20: 0.039975876 | U20: 2.3562377 | V20: 1.101154e-10 | W20: =P20-A20 -> 2.7628479e-05 | X20: =Q20-B20 -> -4.2233605e-06 | Y20: =MIN(ABS(R20-C20),2*PI()-ABS(R20-C20)) -> 9.504284e-05 | Z20: =S20-D20 -> -0.00011741692 | AA20: =T20-E20 -> -2.4124496e-05 | AB20: =MIN(ABS(U20-F20),2*PI()-ABS(U20-F20)) -> 3.7681779e-05 | AC20: =AVERAGE(ABS(W20),ABS(Z20)) -> 7.25227e-05 | AD20: =AVERAGE(ABS(X20),ABS(AA20)) -> 1.4173928e-05 | AE20: =AVERAGE(ABS(Y20),ABS(AB20)) -> 6.636231e-05
... A52: ='Proximal Validation'!A52 -> 0.93729511 | B52: ='Proximal Validation'!B52 -> 0.14 | C52: ='Proximal Validation'!C52 -> 0.7854 | D52: ='Proximal Validation'!D52 -> 0.49250416 | E52: ='Proximal Validation'!E52 -> 0.1 | F52: ='Proximal Validation'!F52 -> 0 | G52: ='Proximal Validation'!G52 -> 0.50502447 | H52: ='Proximal Validation'!H52 -> 3.7817598 | ... O52: ='Proximal Validation'!O52 -> 0.62157619 | P52: 0.79088249 | Q52: 0.14340793 | R52: 0.85639417 | S52: 0.63989958 | T52: 0.10662776 | U52: 0.10448135 | V52: 7.5460744e-09 | W52: =P52-A52 -> -0.14641262 | X52: =Q52-B52 -> 0.0034079336 | Y52: =MIN(ABS(R52-C52),2*PI()-ABS(R52-C52)) -> 0.070994171 | Z52: =S52-D52 -> 0.14739542 | AA52: =T52-E52 -> 0.0066277568 | AB52: =MIN(ABS(U52-F52),2*PI()-ABS(U52-F52)) -> 0.10448135 | AC52: =AVERAGE(ABS(W52),ABS(Z52)) -> 0.14690402 | AD52: =AVERAGE(ABS(X52),ABS(AA52)) -> 0.0050178452 | AE52: =AVERAGE(ABS(Y52),ABS(AB52)) -> 0.087737758

Sheet Distal Vali (five truth)
A1: Ground Truth | J1: 6-Axis FT Sensor | P1: SoRoSim get_distal_value | W1: Distal Errors | AF1: Stats
A2: F1 (N) | B2: s1 (m) | C2: theta1 (rad) | D2: F2 (N) | E2: s2 (m) | F2: theta2 (rad) | G2: tau1 (N) | H2: tau2 (N) | I2: tau3 (N) | J2: Tx (Nm) | K2: Ty (Nm) | L2: Tz(Nm) | M2: Fx (N) | N2: Fy (N) | O2: Fz (N) | P2: F1 (N) | Q2: s1 (m) | R2: theta1 (rad) | S2: F2 (N) | T2: s2 (m) | U2: theta2 (rad) | V2: f_final | W2: F1 (N) | X2: s1 (m) | Y2: theta1 (rad) | Z2: F2 (N) | AA2: s2 (m) | AB2: theta2 (rad) | AC2: force_error | AD2: position_error | AE2: angle_error | AF2: Absolute Mean Error
A3: ='Proximal Validation'!A3 -> 0.57634631 | B3: ='Proximal Validation'!B3 -> 0.2 | C3: ='Proximal Validation'!C3 -> 0.7854 | D3: ='Proximal Validation'!D3 -> 1.1398025 | E3: ='Proximal Validation'!E3 -> 0.02 | F3: ='Proximal Validation'!F3 -> 5.4978 | G3: ='Proximal Validation'!G3 -> 0.49272224 | H3: ='Proximal Validation'!H3 -> 4.4756012 | ... O3: ='Proximal Validation'!O3 -> -0.73825818 | P3: 0.90625698 | Q3: 0.14965243 | R3: 1.1537599 | S3: 1.4884304 | T3: 0.048775834 | U3: 5.3154929 | V3: 2.2441655e-09 | W3: =P3-A3 -> 0.32991067 | X3: =Q3-B3 -> -0.050347571 | Y3: =MIN(ABS(R3-C3),2*PI()-ABS(R3-C3)) -> 0.36835993 | Z3: =S3-D3 -> 0.34862797 | AA3: =T3-E3 -> 0.028775834 | AB3: =MIN(ABS(U3-F3),2*PI()-ABS(U3-F3)) -> 0.18230709 | AC3: =AVERAGE(ABS(W3),ABS(Z3)) -> 0.33926932 | AD3: =AVERAGE(ABS(X3),ABS(AA3)) -> 0.039561702 | AE3: =AVERAGE(ABS(Y3),ABS(AB3)) -> 0.27533351 | AF3: F1 (N) | AG3: s1 (m) | AH3: theta1 (rad) | AI3: F2 (N) | AJ3: s2 (m) | AK3: theta2 (rad)
A4: ='Proximal Validation'!A4 -> 1.2961946 | B4: ='Proximal Validation'!B4 -> 0.2 | C4: ='Proximal Validation'!C4 -> 4.7124 | D4: ='Proximal Validation'!D4 -> 0.3190756 | E4: ='Proximal Validation'!E4 -> 0.02 | F4: ='Proximal Validation'!F4 -> 1.5708 | G4: ='Proximal Validation'!G4 -> 0.53253118 | H4: ='Proximal Validation'!H4 -> 1.6232894 | ... O4: ='Proximal Validation'!O4 -> -0.55368435 | P4: 1.2971411 | Q4: 0.19975049 | R4: 4.7123715 | S4: 0.32017148 | T4: 0.02008786 | U4: 1.5708471 | V4: 8.1812668e-11 | W4: =P4-A4 -> 0.00094659791 | X4: =Q4-B4 -> -0.00024951291 | Y4: =MIN(ABS(R4-C4),2*PI()-ABS(R4-C4)) -> 2.8537536e-05 | Z4: =S4-D4 -> 0.0010958844 | AA4: =T4-E4 -> 8.7859867e-05 | AB4: =MIN(ABS(U4-F4),2*PI()-ABS(U4-F4)) -> 4.7078392e-05 | AC4: =AVERAGE(ABS(W4),ABS(Z4)) -> 0.0010212412 | AD4: =AVERAGE(ABS(X4),ABS(AA4)) -> 0.00016868639 | AE4: =AVERAGE(ABS(Y4),ABS(AB4)) -> 3.7807964e-05 | AF4: {=AVERAGE(ABS(W3:W52))} -> 0.12329392 | AG4: {=AVERAGE(ABS(X3:X52))} -> 0.012291758 | AH4: {=AVERAGE(ABS(Y3:Y52))} -> 0.11984681 | AI4: {=AVERAGE(ABS(Z3:Z52))} -> 0.11971149 | AJ4: {=AVERAGE(ABS(AA3:AA52))} -> 0.0092228456 | AK4: {=AVERAGE(ABS(AB3:AB52))} -> 0.13042251
A5: ='Proximal Validation'!A5 -> 0.34328445 | B5: ='Proximal Validation'!B5 -> 0.2 | C5: ='Proximal Validation'!C5 -> 3.1416 | D5: ='Proximal Validation'!D5 -> 0.75633386 | E5: ='Proximal Validation'!E5 -> 0.02 | F5: ='Proximal Validation'!F5 -> 3.1416 | G5: ='Proximal Validation'!G5 -> 3.5593988 | H5: ='Proximal Validation'!H5 -> 2.6173594 | ... O5: ='Proximal Validation'!O5 -> 0.004011631 | P5: 0.42711147 | Q5: 0.075577426 | R5: 4.3006985 | S5: 1.005194 | T5: 0.075574499 | U5: 2.7431261 | V5: 7.3406622e-07 | W5: =P5-A5 -> 0.083827017 | X5: =Q5-B5 -> -0.12442257 | Y5: =MIN(ABS(R5-C5),2*PI()-ABS(R5-C5)) -> 1.1590985 | Z5: =S5-D5 -> 0.24886017 | AA5: =T5-E5 -> 0.055574499 | AB5: =MIN(ABS(U5-F5),2*PI()-ABS(U5-F5)) -> 0.3984739 | AC5: =AVERAGE(ABS(W5),ABS(Z5)) -> 0.16634359 | AD5: =AVERAGE(ABS(X5),ABS(AA5)) -> 0.089998536 | AE5: =AVERAGE(ABS(Y5),ABS(AB5)) -> 0.77878621 | AF5: Absolute Mean Error (Across Both Forces)
A6: ='Proximal Validation'!A6 -> 0.83277602 | B6: ='Proximal Validation'!B6 -> 0.2 | C6: ='Proximal Validation'!C6 -> 4.7124 | D6: ='Proximal Validation'!D6 -> 1.4193655 | E6: ='Proximal Validation'!E6 -> 0.04 | F6: ='Proximal Validation'!F6 -> 5.4978 | G6: ='Proximal Validation'!G6 -> 4.2084859 | H6: ='Proximal Validation'!H6 -> 0.52916698 | ... O6: ='Proximal Validation'!O6 -> -1.7768694 | P6: 0.83161022 | Q6: 0.19974485 | R6: 4.7102902 | S6: 1.4207166 | T6: 0.040270618 | U6: 5.4983213 | V6: 3.6038085e-10 | W6: =P6-A6 -> -0.0011658044 | X6: =Q6-B6 -> -0.0002551489 | Y6: =MIN(ABS(R6-C6),2*PI()-ABS(R6-C6)) -> 0.0021098354 | Z6: =S6-D6 -> 0.001351128 | AA6: =T6-E6 -> 0.0002706184 | AB6: =MIN(ABS(U6-F6),2*PI()-ABS(U6-F6)) -> 0.00052126722 | AC6: =AVERAGE(ABS(W6),ABS(Z6)) -> 0.0012584662 | AD6: =AVERAGE(ABS(X6),ABS(AA6)) -> 0.00026288365 | AE6: =AVERAGE(ABS(Y6),ABS(AB6)) -> 0.0013155513 | AF6: force_error | AG6: position_error | AH6: angle_error
A7: ='Proximal Validation'!A7 -> 0.38984039 | B7: ='Proximal Validation'!B7 -> 0.2 | C7: ='Proximal Validation'!C7 -> 1.5708 | D7: ='Proximal Validation'!D7 -> 0.45028829 | E7: ='Proximal Validation'!E7 -> 0.04 | F7: ='Proximal Validation'!F7 -> 2.3562 | G7: ='Proximal Validation'!G7 -> 0.34676129 | H7: ='Proximal Validation'!H7 -> 0.93612471 | ... O7: ='Proximal Validation'!O7 -> 0.54981846 | P7: 0.93529444 | Q7: 0.11115767 | R7: 1.4276347 | S7: 0.50217359 | T7: 0.060778051 | U7: 3.598749 | V7: 4.855898e-07 | W7: =P7-A7 -> 0.54545405 | X7: =Q7-B7 -> -0.088842329 | Y7: =MIN(ABS(R7-C7),2*PI()-ABS(R7-C7)) -> 0.14316527 | Z7: =S7-D7 -> 0.0518853 | AA7: =T7-E7 -> 0.020778051 | AB7: =MIN(ABS(U7-F7),2*PI()-ABS(U7-F7)) -> 1.242549 | AC7: =AVERAGE(ABS(W7),ABS(Z7)) -> 0.29866967 | AD7: =AVERAGE(ABS(X7),ABS(AA7)) -> 0.05481019 | AE7: =AVERAGE(ABS(Y7),ABS(AB7)) -> 0.69285715 | AF7: =AVERAGE(AF4,AI4) -> 0.1215027 | AG7: =AVERAGE(AG4,AJ4) -> 0.010757302 | AH7: =AVERAGE(AH4,AK4) -> 0.12513466
A8: ='Proximal Validation'!A8 -> 0.86958753 | B8: ='Proximal Validation'!B8 -> 0.2 | C8: ='Proximal Validation'!C8 -> 0.7854 | D8: ='Proximal Validation'!D8 -> 0.66933871 | E8: ='Proximal Validation'!E8 -> 0.04 | F8: ='Proximal Validation'!F8 -> 0.7854 | G8: ='Proximal Validation'!G8 -> 2.0486074 | H8: ='Proximal Validation'!H8 -> 1.4427409 | ... O8: ='Proximal Validation'!O8 -> 0.92608899 | P8: 1.246585 | Q8: 0.1314851 | R8: 0.64953163 | S8: 0.30134921 | T8: 0.12816517 | U8: 1.3538468 | V8: 1.4378588e-05 | W8: =P8-A8 -> 0.37699743 | X8: =Q8-B8 -> -0.068514902 | Y8: =MIN(ABS(R8-C8),2*PI()-ABS(R8-C8)) -> 0.13586837 | Z8: =S8-D8 -> -0.3679895 | AA8: =T8-E8 -> 0.088165167 | AB8: =MIN(ABS(U8-F8),2*PI()-ABS(U8-F8)) -> 0.56844677 | AC8: =AVERAGE(ABS(W8),ABS(Z8)) -> 0.37249347 | AD8: =AVERAGE(ABS(X8),ABS(AA8)) -> 0.078340035 | AE8: =AVERAGE(ABS(Y8),ABS(AB8)) -> 0.35215757 | AF8: =MEDIAN(AC3:AC52) -> 0.045469562 | AG8: =MEDIAN(AD3:AD52) -> 0.0033837106
A9: ='Proximal Validation'!A9 -> 1.2260242 | B9: ='Proximal Validation'!B9 -> 0.2 | C9: ='Proximal Validation'!C9 -> 3.1416 | D9: ='Proximal Validation'!D9 -> 0.53124592 | E9: ='Proximal Validation'!E9 -> 0.04 | F9: ='Proximal Validation'!F9 -> 1.5708 | G9: ='Proximal Validation'!G9 -> 2.1721906 | H9: ='Proximal Validation'!H9 -> 4.859274 | ... O9: ='Proximal Validation'!O9 -> 0.72559178 | P9: 1.2383263 | Q9: 0.1971402 | R9: 3.1302764 | S9: 0.51934182 | T9: 0.035743889 | U9: 1.5458615 | V9: 7.3189705e-09 | W9: =P9-A9 -> 0.012302103 | X9: =Q9-B9 -> -0.0028598045 | Y9: =MIN(ABS(R9-C9),2*PI()-ABS(R9-C9)) -> 0.011323599 | Z9: =S9-D9 -> -0.011904095 | AA9: =T9-E9 -> -0.004256111 | AB9: =MIN(ABS(U9-F9),2*PI()-ABS(U9-F9)) -> 0.024938482 | AC9: =AVERAGE(ABS(W9),ABS(Z9)) -> 0.012103099 | AD9: =AVERAGE(ABS(X9),ABS(AA9)) -> 0.0035579578 | AE9: =AVERAGE(ABS(Y9),ABS(AB9)) -> 0.01813104
A10: ='Proximal Validation'!A10 -> 1.4922792 | B10: ='Proximal Validation'!B10 -> 0.2 | C10: ='Proximal Validation'!C10 -> 2.3562 | D10: ='Proximal Validation'!D10 -> 1.2493009 | E10: ='Proximal Validation'!E10 -> 0.04 | F10: ='Proximal Validation'!F10 -> 0.7854 | G10: ='Proximal Validation'!G10 -> 0.65138204 | H10: ='Proximal Validation'!H10 -> 2.3960292 | ... O10: ='Proximal Validation'!O10 -> 1.7137415 | P10: 1.4922426 | Q10: 0.19998355 | R10: 2.3559777 | S10: 1.2490204 | T10: 0.039957173 | U10: 0.78540748 | V10: 1.4552097e-10 | W10: =P10-A10 -> -3.6599369e-05 | X10: =Q10-B10 -> -1.6452698e-05 | Y10: =MIN(ABS(R10-C10),2*PI()-ABS(R10-C10)) -> 0.00022230288 | Z10: =S10-D10 -> -0.00028043408 | AA10: =T10-E10 -> -4.2826703e-05 | AB10: =MIN(ABS(U10-F10),2*PI()-ABS(U10-F10)) -> 7.4771338e-06 | AC10: =AVERAGE(ABS(W10),ABS(Z10)) -> 0.00015851672 | AD10: =AVERAGE(ABS(X10),ABS(AA10)) -> 2.9639701e-05 | AE10: =AVERAGE(ABS(Y10),ABS(AB10)) -> 0.00011489001
A11: ='Proximal Validation'!A11 -> 1.425868 | B11: ='Proximal Validation'!B11 -> 0.2 | C11: ='Proximal Validation'!C11 -> 4.7124 | D11: ='Proximal Validation'!D11 -> 0.35291314 | E11: ='Proximal Validation'!E11 -> 0.04 | F11: ='Proximal Validation'!F11 -> 0 | G11: ='Proximal Validation'!G11 -> 3.481026 | H11: ='Proximal Validation'!H11 -> 1.1294031 | ... O11: ='Proximal Validation'!O11 -> -0.71812153 | P11: 1.4517135 | Q11: 0.19539021 | R11: 4.6966662 | S11: 0.37078696 | T11: 0.048388311 | U11: 0.085930755 | V11: 5.2073779e-09 | W11: =P11-A11 -> 0.02584547 | X11: =Q11-B11 -> -0.0046097864 | Y11: =MIN(ABS(R11-C11),2*PI()-ABS(R11-C11)) -> 0.015733755 | Z11: =S11-D11 -> 0.017873816 | AA11: =T11-E11 -> 0.008388311 | AB11: =MIN(ABS(U11-F11),2*PI()-ABS(U11-F11)) -> 0.085930755 | AC11: =AVERAGE(ABS(W11),ABS(Z11)) -> 0.021859643 | AD11: =AVERAGE(ABS(X11),ABS(AA11)) -> 0.0064990487 | AE11: =AVERAGE(ABS(Y11),ABS(AB11)) -> 0.050832255
