Workbook

Sheet Proximal Validation
A1: Ground Truth | G1: 6-Axis FT Sensor | M1: SoRoSim get_proximal_value | S1: Proximal Errors
A2: F (N) | B2: s (m) | C2: theta (rad) | D2: tau1 (N) | E2: tau2 (N) | F2: tau3 (N) | G2: Tx (Nm) | H2: Ty (Nm) | I2: Tz(Nm) | J2: Fx (N) | K2: Fy (N) | L2: Fz (N) | M2: Tx (Nm) | N2: Ty (Nm) | O2: Tz(Nm) | P2: Fx (N) | Q2: Fy (N) | R2: Fz (N) | S2: Tx (Nm) | T2: Ty (Nm) | U2: Tz(Nm) | V2: Fx (N) | W2: Fy (N) | X2: Fz (N)
A3: 0.4 | B3: 0.06 | C3: =PI()/2 -> 1.5707963 | D3: 0 | E3: 0 | F3: 0 | G3: -0.00043792196 | H3: -0.054464955 | I3: -0.00028745097 | J3: -0.021312971 | K3: 0.0001851581 | L3: 0.34822303 | S3: =G3-M3 -> -0.00043792196 | T3: =H3-N3 -> -0.054464955 | U3: =I3-O3 -> -0.00028745097 | V3: =J3-P3 -> -0.021312971 | W3: =K3-Q3 -> 0.0001851581 | X3: =L3-R3 -> 0.34822303
A4: 0.8 | B4: 0.06 | C4: =PI()/2 -> 1.5707963 | D4: 0 | E4: 0 | F4: 0 | G4: -0.0012904059 | H4: -0.13089056 | I4: -0.00050724833 | J4: -0.12710035 | K4: 0.0033702701 | L4: 0.83409011 | S4: =G4-M4 -> -0.0012904059 | T4: =H4-N4 -> -0.13089056 | U4: =I4-O4 -> -0.00050724833 | V4: =J4-P4 -> -0.12710035 | W4: =K4-Q4 -> 0.0033702701 | X4: =L4-R4 -> 0.83409011
A5: 0.3 | B5: 0.08 | C5: =PI()/2 -> 1.5707963 | D5: 0 | E5: 0 | F5: 0 | G5: -0.00044532004 | H5: -0.047905073 | I5: -0.0001454872 | J5: -0.015221856 | K5: -0.00016181916 | L5: 0.26909974 | S5: =G5-M5 -> -0.00044532004 | T5: =H5-N5 -> -0.047905073 | U5: =I5-O5 -> -0.0001454872 | V5: =J5-P5 -> -0.015221856 | W5: =K5-Q5 -> -0.00016181916 | X5: =L5-R5 -> 0.26909974
A6: 0.5 | B6: 0.1 | C6: =PI()/2 -> 1.5707963 | D6: 0 | E6: 0 | F6: 0 | G6: -0.001170564 | H6: -0.094456188 | I6: -0.0012032345 | J6: -0.11118765 | K6: -0.0032553412 | L6: 0.47075057 | S6: =G6-M6 -> -0.001170564 | T6: =H6-N6 -> -0.094456188 | U6: =I6-O6 -> -0.0012032345 | V6: =J6-P6 -> -0.11118765 | W6: =K6-Q6 -> -0.0032553412 | X6: =L6-R6 -> 0.47075057
A7: 0.7 | B7: 0.1 | C7: =PI()/2 -> 1.5707963 | D7: 0 | E7: 0 | F7: 0 | G7: -0.0015179969 | H7: -0.13914527 | I7: -0.0016895274 | J7: -0.20834762 | K7: -0.0026145354 | L7: 0.69233716 | S7: =G7-M7 -> -0.0015179969 | T7: =H7-N7 -> -0.13914527 | U7: =I7-O7 -> -0.0016895274 | V7: =J7-P7 -> -0.20834762 | W7: =K7-Q7 -> -0.0026145354 | X7: =L7-R7 -> 0.69233716
A8: 0.4 | B8: 0.16 | C8: =PI()/2 -> 1.5707963 | D8: 0 | E8: 0 | F8: 0 | G8: -0.00060909818 | H8: -0.093464263 | I8: -0.0014227356 | J8: -0.18325244 | K8: -0.001301948 | L8: 0.33158547 | S8: =G8-M8 -> -0.00060909818 | T8: =H8-N8 -> -0.093464263 | U8: =I8-O8 -> -0.0014227356 | V8: =J8-P8 -> -0.18325244 | W8: =K8-Q8 -> -0.001301948 | X8: =L8-R8 -> 0.33158547
A9: 0.6 | B9: 0.16 | C9: =PI()/2 -> 1.5707963 | D9: 0 | E9: 0 | F9: 0 | G9: -0.00084166456 | H9: -0.14134772 | I9: -0.0024875707 | J9: -0.39468729 | K9: -0.00092538819 | L9: 0.46994856 | S9: =G9-M9 -> -0.00084166456 | T9: =H9-N9 -> -0.14134772 | U9: =I9-O9 -> -0.0024875707 | V9: =J9-P9 -> -0.39468729 | W9: =K9-Q9 -> -0.00092538819 | X9: =L9-R9 -> 0.46994856
A10: 0.8 | B10: 0.18 | C10: =PI()/2 -> 1.5707963 | D10: 0 | E10: 0 | F10: 0 | G10: -0.0025411225 | H10: -0.16168536 | I10: -0.0020260578 | J10: -0.81751561 | K10: 0.01462714 | L10: 0.27560678 | S10: =G10-M10 -> -0.0025411225 | T10: =H10-N10 -> -0.16168536 | U10: =I10-O10 -> -0.0020260578 | V10: =J10-P10 -> -0.81751561 | W10: =K10-Q10 -> 0.01462714 | X10: =L10-R10 -> 0.27560678
A11: 0.3 | B11: 0.2 | C11: =PI()/2 -> 1.5707963 | D11: 0 | E11: 0 | F11: 0 | G11: -0.00077232125 | H11: -0.071722366 | I11: -0.00078877644 | J11: -0.14824972 | K11: -0.00025316514 | L11: 0.21111466 | S11: =G11-M11 -> -0.00077232125 | T11: =H11-N11 -> -0.071722366 | U11: =I11-O11 -> -0.00078877644 | V11: =J11-P11 -> -0.14824972 | W11: =K11-Q11 -> -0.00025316514 | X11: =L11-R11 -> 0.21111466
A12: 0.7 | B12: 0.2 | C12: =PI()/2 -> 1.5707963 | D12: 0 | E12: 0 | F12: 0 | G12: -0.0013749812 | H12: -0.132386 | I12: -0.0019598384 | J12: -0.64118612 | K12: 0.0095805265 | L12: 0.17886317 | S12: =G12-M12 -> -0.0013749812 | T12: =H12-N12 -> -0.132386 | U12: =I12-O12 -> -0.0019598384 | V12: =J12-P12 -> -0.64118612 | W12: =K12-Q12 -> 0.0095805265 | X12: =L12-R12 -> 0.17886317

Sheet Distal Vali (0N perturb)
A1: Ground Truth | G1: 6-Axis FT Sensor | M1: SoRoSim get_distal_value | Q1: Distal Errors | T1: ABS Distal Errors
A2: F (N) | B2: s (m) | C2: theta (rad) | D2: tau1 (N) | E2: tau2 (N) | F2: tau3 (N) | G2: Tx (Nm) | H2: Ty (Nm) | I2: Tz(Nm) | J2: Fx (N) | K2: Fy (N) | L2: Fz (N) | M2: F (N) | N2: s (m) | O2: theta (rad) | P2: f_final | Q2: F (N) | R2: s (m) | S2: theta (rad) | T2: F (N) | U2: s (m) | V2: theta (rad) | W2: Absolute Mean Error
A3: ='Proximal Validation'!A3 -> 0.4 | B3: ='Proximal Validation'!B3 -> 0.06 | C3: ='Proximal Validation'!C3 -> 1.5707963 | D3: ='Proximal Validation'!D3 -> 0 | E3: ='Proximal Validation'!E3 -> 0 | F3: ='Proximal Validation'!F3 -> 0 | G3: ='Proximal Validation'!G3 -> -0.00043792196 | H3: ='Proximal Validation'!H3 -> -0.054464955 | ... L3: ='Proximal Validation'!L3 -> 0.34822303 | M3: 0.15746338 | N3: 0.14706767 | O3: 1.5839466 | P3: 5.8832285e-11 | Q3: =M3-A3 -> -0.24253662 | R3: =N3-B3 -> 0.087067667 | S3: =O3-C3 -> 0.013150237 | T3: =ABS(Q3) -> 0.24253662 | U3: =ABS(R3) -> 0.087067667 | V3: =ABS(S3) -> 0.013150237 | W3: F1 (N) | X3: s1 (m) | Y3: el1 (rad)
A4: ='Proximal Validation'!A4 -> 0.8 | B4: ='Proximal Validation'!B4 -> 0.06 | C4: ='Proximal Validation'!C4 -> 1.5707963 | D4: ='Proximal Validation'!D4 -> 0 | E4: ='Proximal Validation'!E4 -> 0 | F4: ='Proximal Validation'!F4 -> 0 | G4: ='Proximal Validation'!G4 -> -0.0012904059 | H4: ='Proximal Validation'!H4 -> -0.13089056 | ... L4: ='Proximal Validation'!L4 -> 0.83409011 | M4: 0.35990391 | N4: 0.15739171 | O4: 1.5853158 | P4: 3.0256104e-19 | Q4: =M4-A4 -> -0.44009609 | R4: =N4-B4 -> 0.097391713 | S4: =O4-C4 -> 0.014519522 | T4: =ABS(Q4) -> 0.44009609 | U4: =ABS(R4) -> 0.097391713 | V4: =ABS(S4) -> 0.014519522 | W4: {=AVERAGE(ABS(Q7:Q12))} -> 0.079819944 | X4: {=AVERAGE(ABS(R7:R12))} -> 0.012849522 | Y4: {=AVERAGE(ABS(S7:S12))} -> 0.021152589
A5: ='Proximal Validation'!A5 -> 0.3 | B5: ='Proximal Validation'!B5 -> 0.08 | C5: ='Proximal Validation'!C5 -> 1.5707963 | D5: ='Proximal Validation'!D5 -> 0 | E5: ='Proximal Validation'!E5 -> 0 | F5: ='Proximal Validation'!F5 -> 0 | G5: ='Proximal Validation'!G5 -> -0.00044532004 | H5: ='Proximal Validation'!H5 -> -0.047905073 | ... L5: ='Proximal Validation'!L5 -> 0.26909974 | M5: 0.46841583 | N5: 0.050651509 | O5: 1.5763237 | P5: 1.7289105e-08 | Q5: =M5-A5 -> 0.16841583 | R5: =N5-B5 -> -0.029348491 | S5: =O5-C5 -> 0.0055273759 | T5: =ABS(Q5) -> 0.16841583 | U5: =ABS(R5) -> 0.029348491 | V5: =ABS(S5) -> 0.0055273759
A6: ='Proximal Validation'!A6 -> 0.5 | B6: ='Proximal Validation'!B6 -> 0.1 | C6: ='Proximal Validation'!C6 -> 1.5707963 | D6: ='Proximal Validation'!D6 -> 0 | E6: ='Proximal Validation'!E6 -> 0 | F6: ='Proximal Validation'!F6 -> 0 | G6: ='Proximal Validation'!G6 -> -0.001170564 | H6: ='Proximal Validation'!H6 -> -0.094456188 | ... L6: ='Proximal Validation'!L6 -> 0.47075057 | M6: 0.33133836 | N6: 0.15929515 | O6: 1.5882697 | P6: 1.9162677e-14 | Q6: =M6-A6 -> -0.16866164 | R6: =N6-B6 -> 0.059295147 | S6: =O6-C6 -> 0.017473325 | T6: =ABS(Q6) -> 0.16866164 | U6: =ABS(R6) -> 0.059295147 | V6: =ABS(S6) -> 0.017473325
A7: ='Proximal Validation'!A7 -> 0.7 | B7: ='Proximal Validation'!B7 -> 0.1 | C7: ='Proximal Validation'!C7 -> 1.5707963 | D7: ='Proximal Validation'!D7 -> 0 | E7: ='Proximal Validation'!E7 -> 0 | F7: ='Proximal Validation'!F7 -> 0 | G7: ='Proximal Validation'!G7 -> -0.0015179969 | H7: ='Proximal Validation'!H7 -> -0.13914527 | ... L7: ='Proximal Validation'!L7 -> 0.69233716 | M7: 0.83498129 | N7: 0.092715576 | O7: 1.5897206 | P7: 8.015653e-18 | Q7: =M7-A7 -> 0.13498129 | R7: =N7-B7 -> -0.007284424 | S7: =O7-C7 -> 0.018924275 | T7: =ABS(Q7) -> 0.13498129 | U7: =ABS(R7) -> 0.007284424 | V7: =ABS(S7) -> 0.018924275
A8: ='Proximal Validation'!A8 -> 0.4 | B8: ='Proximal Validation'!B8 -> 0.16 | C8: ='Proximal Validation'!C8 -> 1.5707963 | D8: ='Proximal Validation'!D8 -> 0 | E8: ='Proximal Validation'!E8 -> 0 | F8: ='Proximal Validation'!F8 -> 0 | G8: ='Proximal Validation'!G8 -> -0.00060909818 | H8: ='Proximal Validation'!H8 -> -0.093464263 | ... L8: ='Proximal Validation'!L8 -> 0.33158547 | M8: 0.34005574 | N8: 0.19439455 | O8: 1.5913142 | P8: 1.0518386e-12 | Q8: =M8-A8 -> -0.059944259 | R8: =N8-B8 -> 0.034394555 | S8: =O8-C8 -> 0.020517844 | T8: =ABS(Q8) -> 0.059944259 | U8: =ABS(R8) -> 0.034394555 | V8: =ABS(S8) -> 0.020517844
A9: ='Proximal Validation'!A9 -> 0.6 | B9: ='Proximal Validation'!B9 -> 0.16 | C9: ='Proximal Validation'!C9 -> 1.5707963 | D9: ='Proximal Validation'!D9 -> 0 | E9: ='Proximal Validation'!E9 -> 0 | F9: ='Proximal Validation'!F9 -> 0 | G9: ='Proximal Validation'!G9 -> -0.00084166456 | H9: ='Proximal Validation'!H9 -> -0.14134772 | ... L9: ='Proximal Validation'!L9 -> 0.46994856 | M9: 0.69606551 | N9: 0.1486414 | O9: 1.5950644 | P9: 7.9283572e-13 | Q9: =M9-A9 -> 0.09606551 | R9: =N9-B9 -> -0.0113586 | S9: =O9-C9 -> 0.024268118 | T9: =ABS(Q9) -> 0.09606551 | U9: =ABS(R9) -> 0.0113586 | V9: =ABS(S9) -> 0.024268118
A10: ='Proximal Validation'!A10 -> 0.8 | B10: ='Proximal Validation'!B10 -> 0.18 | C10: ='Proximal Validation'!C10 -> 1.5707963 | D10: ='Proximal Validation'!D10 -> 0 | E10: ='Proximal Validation'!E10 -> 0 | F10: ='Proximal Validation'!F10 -> 0 | G10: ='Proximal Validation'!G10 -> -0.0025411225 | H10: ='Proximal Validation'!H10 -> -0.16168536 | ... L10: ='Proximal Validation'!L10 -> 0.27560678 | M10: 0.95031341 | N10: 0.16549589 | O10: 1.5952105 | P10: 2.0224901e-11 | Q10: =M10-A10 -> 0.15031341 | R10: =N10-B10 -> -0.014504108 | S10: =O10-C10 -> 0.024414218 | T10: =ABS(Q10) -> 0.15031341 | U10: =ABS(R10) -> 0.014504108 | V10: =ABS(S10) -> 0.024414218
A11: ='Proximal Validation'!A11 -> 0.3 | B11: ='Proximal Validation'!B11 -> 0.2 | C11: ='Proximal Validation'!C11 -> 1.5707963 | D11: ='Proximal Validation'!D11 -> 0 | E11: ='Proximal Validation'!E11 -> 0 | F11: ='Proximal Validation'!F11 -> 0 | G11: ='Proximal Validation'!G11 -> -0.00077232125 | H11: ='Proximal Validation'!H11 -> -0.071722366 | ... L11: ='Proximal Validation'!L11 -> 0.21111466 | M11: 0.27958835 | N11: 0.2 | O11: 1.5853242 | P11: 9.1453865e-07 | Q11: =M11-A11 -> -0.020411645 | R11: =N11-B11 -> -2.2454261e-14 | S11: =O11-C11 -> 0.014527836 | T11: =ABS(Q11) -> 0.020411645 | U11: =ABS(R11) -> 2.2454261e-14 | V11: =ABS(S11) -> 0.014527836
A12: ='Proximal Validation'!A12 -> 0.7 | B12: ='Proximal Validation'!B12 -> 0.2 | C12: ='Proximal Validation'!C12 -> 1.5707963 | D12: ='Proximal Validation'!D12 -> 0 | E12: ='Proximal Validation'!E12 -> 0 | F12: ='Proximal Validation'!F12 -> 0 | G12: ='Proximal Validation'!G12 -> -0.0013749812 | H12: ='Proximal Validation'!H12 -> -0.132386 | ... L12: ='Proximal Validation'!L12 -> 0.17886317 | M12: 0.71720355 | N12: 0.19044455 | O12: 1.5950596 | P12: 3.0224751e-14 | Q12: =M12-A12 -> 0.017203554 | R12: =N12-B12 -> -0.009555448 | S12: =O12-C12 -> 0.024263243 | T12: =ABS(Q12) -> 0.017203554 | U12: =ABS(R12) -> 0.009555448 | V12: =ABS(S12) -> 0.024263243

Sheet Distal Vali (0N pert 6prox)
A1: Ground Truth | G1: 6-Axis FT Sensor | M1: SoRoSim get_distal_value | Q1: Distal Errors | T1: ABS Distal Errors
A2: F (N) | B2: s (m) | C2: theta (rad) | D2: tau1 (N) | E2: tau2 (N) | F2: tau3 (N) | G2: Tx (Nm) | H2: Ty (Nm) | I2: Tz(Nm) | J2: Fx (N) | K2: Fy (N) | L2: Fz (N) | M2: F (N) | N2: s (m) | O2: theta (rad) | P2: f_final | Q2: F (N) | R2: s (m) | S2: theta (rad) | T2: F (N) | U2: s (m) | V2: theta (rad) | W2: Absolute Mean Error
A3: ='Proximal Validation'!A3 -> 0.4 | B3: ='Proximal Validation'!B3 -> 0.06 | C3: ='Proximal Validation'!C3 -> 1.5707963 | D3: ='Proximal Validation'!D3 -> 0 | E3: ='Proximal Validation'!E3 -> 0 | F3: ='Proximal Validation'!F3 -> 0 | G3: ='Proximal Validation'!G3 -> -0.00043792196 | H3: ='Proximal Validation'!H3 -> -0.054464955 | ... L3: ='Proximal Validation'!L3 -> 0.34822303 | Q3: =M3-A3 -> -0.4 | R3: =N3-B3 -> -0.06 | S3: =O3-C3 -> -1.5707963 | T3: =ABS(Q3) -> 0.4 | U3: =ABS(R3) -> 0.06 | V3: =ABS(S3) -> 1.5707963 | W3: F1 (N) | X3: s1 (m) | Y3: el1 (rad)
A4: ='Proximal Validation'!A4 -> 0.8 | B4: ='Proximal Validation'!B4 -> 0.06 | C4: ='Proximal Validation'!C4 -> 1.5707963 | D4: ='Proximal Validation'!D4 -> 0 | E4: ='Proximal Validation'!E4 -> 0 | F4: ='Proximal Validation'!F4 -> 0 | G4: ='Proximal Validation'!G4 -> -0.0012904059 | H4: ='Proximal Validation'!H4 -> -0.13089056 | ... L4: ='Proximal Validation'!L4 -> 0.83409011 | Q4: =M4-A4 -> -0.8 | R4: =N4-B4 -> -0.06 | S4: =O4-C4 -> -1.5707963 | T4: =ABS(Q4) -> 0.8 | U4: =ABS(R4) -> 0.06 | V4: =ABS(S4) -> 1.5707963 | W4: {=AVERAGE(ABS(Q7:Q12))} -> 0.036765321 | X4: {=AVERAGE(ABS(R7:R12))} -> 0.005574909 | Y4: {=AVERAGE(ABS(S7:S12))} -> 0.0174171
A5: ='Proximal Validation'!A5 -> 0.3 | B5: ='Proximal Validation'!B5 -> 0.08 | C5: ='Proximal Validation'!C5 -> 1.5707963 | D5: ='Proximal Validation'!D5 -> 0 | E5: ='Proximal Validation'!E5 -> 0 | F5: ='Proximal Validation'!F5 -> 0 | G5: ='Proximal Validation'!G5 -> -0.00044532004 | H5: ='Proximal Validation'!H5 -> -0.047905073 | ... L5: ='Proximal Validation'!L5 -> 0.26909974 | Q5: =M5-A5 -> -0.3 | R5: =N5-B5 -> -0.08 | S5: =O5-C5 -> -1.5707963 | T5: =ABS(Q5) -> 0.3 | U5: =ABS(R5) -> 0.08 | V5: =ABS(S5) -> 1.5707963
A6: ='Proximal Validation'!A6 -> 0.5 | B6: ='Proximal Validation'!B6 -> 0.1 | C6: ='Proximal Validation'!C6 -> 1.5707963 | D6: ='Proximal Validation'!D6 -> 0 | E6: ='Proximal Validation'!E6 -> 0 | F6: ='Proximal Validation'!F6 -> 0 | G6: ='Proximal Validation'!G6 -> -0.001170564 | H6: ='Proximal Validation'!H6 -> -0.094456188 | ... L6: ='Proximal Validation'!L6 -> 0.47075057 | Q6: =M6-A6 -> -0.5 | R6: =N6-B6 -> -0.1 | S6: =O6-C6 -> -1.5707963 | T6: =ABS(Q6) -> 0.5 | U6: =ABS(R6) -> 0.1 | V6: =ABS(S6) -> 1.5707963
A7: ='Proximal Validation'!A7 -> 0.7 | B7: ='Proximal Validation'!B7 -> 0.1 | C7: ='Proximal Validation'!C7 -> 1.5707963 | D7: ='Proximal Validation'!D7 -> 0 | E7: ='Proximal Validation'!E7 -> 0 | F7: ='Proximal Validation'!F7 -> 0 | G7: ='Proximal Validation'!G7 -> -0.0015179969 | H7: ='Proximal Validation'!H7 -> -0.13914527 | ... L7: ='Proximal Validation'!L7 -> 0.69233716 | M7: 0.72494635 | N7: 0.10662095 | O7: 1.5829152 | P7: 0.00033288808 | Q7: =M7-A7 -> 0.02494635 | R7: =N7-B7 -> 0.0066209494 | S7: =O7-C7 -> 0.012118889 | T7: =ABS(Q7) -> 0.02494635 | U7: =ABS(R7) -> 0.0066209494 | V7: =ABS(S7) -> 0.012118889
A8: ='Proximal Validation'!A8 -> 0.4 | B8: ='Proximal Validation'!B8 -> 0.16 | C8: ='Proximal Validation'!C8 -> 1.5707963 | D8: ='Proximal Validation'!D8 -> 0 | E8: ='Proximal Validation'!E8 -> 0 | F8: ='Proximal Validation'!F8 -> 0 | G8: ='Proximal Validation'!G8 -> -0.00060909818 | H8: ='Proximal Validation'!H8 -> -0.093464263 | ... L8: ='Proximal Validation'!L8 -> 0.33158547 | M8: 0.37461773 | N8: 0.17584727 | O8: 1.5878003 | P8: 0.00012109855 | Q8: =M8-A8 -> -0.025382274 | R8: =N8-B8 -> 0.015847268 | S8: =O8-C8 -> 0.017003995 | T8: =ABS(Q8) -> 0.025382274 | U8: =ABS(R8) -> 0.015847268 | V8: =ABS(S8) -> 0.017003995
A9: ='Proximal Validation'!A9 -> 0.6 | B9: ='Proximal Validation'!B9 -> 0.16 | C9: ='Proximal Validation'!C9 -> 1.5707963 | D9: ='Proximal Validation'!D9 -> 0 | E9: ='Proximal Validation'!E9 -> 0 | F9: ='Proximal Validation'!F9 -> 0 | G9: ='Proximal Validation'!G9 -> -0.00084166456 | H9: ='Proximal Validation'!H9 -> -0.14134772 | ... L9: ='Proximal Validation'!L9 -> 0.46994856 | M9: 0.62483473 | N9: 0.16677169 | O9: 1.5909035 | P9: 0.00048729855 | Q9: =M9-A9 -> 0.024834725 | R9: =N9-B9 -> 0.0067716884 | S9: =O9-C9 -> 0.020107165 | T9: =ABS(Q9) -> 0.024834725 | U9: =ABS(R9) -> 0.0067716884 | V9: =ABS(S9) -> 0.020107165
A10: ='Proximal Validation'!A10 -> 0.8 | B10: ='Proximal Validation'!B10 -> 0.18 | C10: ='Proximal Validation'!C10 -> 1.5707963 | D10: ='Proximal Validation'!D10 -> 0 | E10: ='Proximal Validation'!E10 -> 0 | F10: ='Proximal Validation'!F10 -> 0 | G10: ='Proximal Validation'!G10 -> -0.0025411225 | H10: ='Proximal Validation'!H10 -> -0.16168536 | ... L10: ='Proximal Validation'!L10 -> 0.27560678 | M10: 0.89432811 | N10: 0.18420955 | O10: 1.5920039 | P10: 0.0033236579 | Q10: =M10-A10 -> 0.094328109 | R10: =N10-B10 -> 0.0042095481 | S10: =O10-C10 -> 0.021207599 | T10: =ABS(Q10) -> 0.094328109 | U10: =ABS(R10) -> 0.0042095481 | V10: =ABS(S10) -> 0.021207599
A11: ='Proximal Validation'!A11 -> 0.3 | B11: ='Proximal Validation'!B11 -> 0.2 | C11: ='Proximal Validation'!C11 -> 1.5707963 | D11: ='Proximal Validation'!D11 -> 0 | E11: ='Proximal Validation'!E11 -> 0 | F11: ='Proximal Validation'!F11 -> 0 | G11: ='Proximal Validation'!G11 -> -0.00077232125 | H11: ='Proximal Validation'!H11 -> -0.071722366 | ... L11: ='Proximal Validation'!L11 -> 0.21111466 | M11: 0.27403783 | N11: 0.2 | O11: 1.5832391 | P11: 0.0016539267 | Q11: =M11-A11 -> -0.025962173 | R11: =N11-B11 -> -2.409184e-14 | S11: =O11-C11 -> 0.012442797 | T11: =ABS(Q11) -> 0.025962173 | U11: =ABS(R11) -> 2.409184e-14 | V11: =ABS(S11) -> 0.012442797
A12: ='Proximal Validation'!A12 -> 0.7 | B12: ='Proximal Validation'!B12 -> 0.2 | C12: ='Proximal Validation'!C12 -> 1.5707963 | D12: ='Proximal Validation'!D12 -> 0 | E12: ='Proximal Validation'!E12 -> 0 | F12: ='Proximal Validation'!F12 -> 0 | G12: ='Proximal Validation'!G12 -> -0.0013749812 | H12: ='Proximal Validation'!H12 -> -0.132386 | ... L12: ='Proximal Validation'!L12 -> 0.17886317 | M12: 0.7251383 | N12: 0.2 | O12: 1.5924185 | P12: 0.0096305608 | Q12: =M12-A12 -> 0.025138297 | R12: =N12-B12 -> -7.7660101e-14 | S12: =O12-C12 -> 0.021622157 | T12: =ABS(Q12) -> 0.025138297 | U12: =ABS(R12) -> 7.7660101e-14 | V12: =ABS(S12) -> 0.021622157

Sheet Distal Vali (0.5N perturb)
A1: Ground Truth | G1: 6-Axis FT Sensor | M1: SoRoSim get_distal_value (lambda = 0.5) | Q1: Distal Errors | T1: ABS Distal Errors
A2: F (N) | B2: s (m) | C2: theta (rad) | D2: tau1 (N) | E2: tau2 (N) | F2: tau3 (N) | G2: Tx (Nm) | H2: Ty (Nm) | I2: Tz(Nm) | J2: Fx (N) | K2: Fy (N) | L2: Fz (N) | M2: F (N) | N2: s (m) | O2: theta (rad) | P2: f_final | Q2: F (N) | R2: s (m) | S2: theta (rad) | T2: F (N) | U2: s (m) | V2: theta (rad) | W2: Absolute Mean Error
A3: ='Proximal Validation'!A3 -> 0.4 | B3: ='Proximal Validation'!B3 -> 0.06 | C3: ='Proximal Validation'!C3 -> 1.5707963 | D3: ='Proximal Validation'!D3 -> 0 | E3: ='Proximal Validation'!E3 -> 0 | F3: ='Proximal Validation'!F3 -> 0 | G3: ='Proximal Validation'!G3 -> -0.00043792196 | H3: ='Proximal Validation'!H3 -> -0.054464955 | ... L3: ='Proximal Validation'!L3 -> 0.34822303 | Q3: =M3-A3 -> -0.4 | R3: =N3-B3 -> -0.06 | S3: =O3-C3 -> -1.5707963 | T3: =ABS(Q3) -> 0.4 | U3: =ABS(R3) -> 0.06 | V3: =ABS(S3) -> 1.5707963 | W3: F1 (N) | X3: s1 (m) | Y3: el1 (rad)
A4: ='Proximal Validation'!A4 -> 0.8 | B4: ='Proximal Validation'!B4 -> 0.06 | C4: ='Proximal Validation'!C4 -> 1.5707963 | D4: ='Proximal Validation'!D4 -> 0 | E4: ='Proximal Validation'!E4 -> 0 | F4: ='Proximal Validation'!F4 -> 0 | G4: ='Proximal Validation'!G4 -> -0.0012904059 | H4: ='Proximal Validation'!H4 -> -0.13089056 | ... L4: ='Proximal Validation'!L4 -> 0.83409011 | Q4: =M4-A4 -> -0.8 | R4: =N4-B4 -> -0.06 | S4: =O4-C4 -> -1.5707963 | T4: =ABS(Q4) -> 0.8 | U4: =ABS(R4) -> 0.06 | V4: =ABS(S4) -> 1.5707963 | W4: {=AVERAGE(ABS(Q3:Q12))} -> 0.55 | X4: {=AVERAGE(ABS(R3:R12))} -> 0.13 | Y4: {=AVERAGE(ABS(S3:S12))} -> 1.5707963
A5: ='Proximal Validation'!A5 -> 0.3 | B5: ='Proximal Validation'!B5 -> 0.08 | C5: ='Proximal Validation'!C5 -> 1.5707963 | D5: ='Proximal Validation'!D5 -> 0 | E5: ='Proximal Validation'!E5 -> 0 | F5: ='Proximal Validation'!F5 -> 0 | G5: ='Proximal Validation'!G5 -> -0.00044532004 | H5: ='Proximal Validation'!H5 -> -0.047905073 | ... L5: ='Proximal Validation'!L5 -> 0.26909974 | Q5: =M5-A5 -> -0.3 | R5: =N5-B5 -> -0.08 | S5: =O5-C5 -> -1.5707963 | T5: =ABS(Q5) -> 0.3 | U5: =ABS(R5) -> 0.08 | V5: =ABS(S5) -> 1.5707963
A6: ='Proximal Validation'!A6 -> 0.5 | B6: ='Proximal Validation'!B6 -> 0.1 | C6: ='Proximal Validation'!C6 -> 1.5707963 | D6: ='Proximal Validation'!D6 -> 0 | E6: ='Proximal Validation'!E6 -> 0 | F6: ='Proximal Validation'!F6 -> 0 | G6: ='Proximal Validation'!G6 -> -0.001170564 | H6: ='Proximal Validation'!H6 -> -0.094456188 | ... L6: ='Proximal Validation'!L6 -> 0.47075057 | Q6: =M6-A6 -> -0.5 | R6: =N6-B6 -> -0.1 | S6: =O6-C6 -> -1.5707963 | T6: =ABS(Q6) -> 0.5 | U6: =ABS(R6) -> 0.1 | V6: =ABS(S6) -> 1.5707963
A7: ='Proximal Validation'!A7 -> 0.7 | B7: ='Proximal Validation'!B7 -> 0.1 | C7: ='Proximal Validation'!C7 -> 1.5707963 | D7: ='Proximal Validation'!D7 -> 0 | E7: ='Proximal Validation'!E7 -> 0 | F7: ='Proximal Validation'!F7 -> 0 | G7: ='Proximal Validation'!G7 -> -0.0015179969 | H7: ='Proximal Validation'!H7 -> -0.13914527 | ... L7: ='Proximal Validation'!L7 -> 0.69233716 | Q7: =M7-A7 -> -0.7 | R7: =N7-B7 -> -0.1 | S7: =O7-C7 -> -1.5707963 | T7: =ABS(Q7) -> 0.7 | U7: =ABS(R7) -> 0.1 | V7: =ABS(S7) -> 1.5707963
A8: ='Proximal Validation'!A8 -> 0.4 | B8: ='Proximal Validation'!B8 -> 0.16 | C8: ='Proximal Validation'!C8 -> 1.5707963 | D8: ='Proximal Validation'!D8 -> 0 | E8: ='Proximal Validation'!E8 -> 0 | F8: ='Proximal Validation'!F8 -> 0 | G8: ='Proximal Validation'!G8 -> -0.00060909818 | H8: ='Proximal Validation'!H8 -> -0.093464263 | ... L8: ='Proximal Validation'!L8 -> 0.33158547 | Q8: =M8-A8 -> -0.4 | R8: =N8-B8 -> -0.16 | S8: =O8-C8 -> -1.5707963 | T8: =ABS(Q8) -> 0.4 | U8: =ABS(R8) -> 0.16 | V8: =ABS(S8) -> 1.5707963
A9: ='Proximal Validation'!A9 -> 0.6 | B9: ='Proximal Validation'!B9 -> 0.16 | C9: ='Proximal Validation'!C9 -> 1.5707963 | D9: ='Proximal Validation'!D9 -> 0 | E9: ='Proximal Validation'!E9 -> 0 | F9: ='Proximal Validation'!F9 -> 0 | G9: ='Proximal Validation'!G9 -> -0.00084166456 | H9: ='Proximal Validation'!H9 -> -0.14134772 | ... L9: ='Proximal Validation'!L9 -> 0.46994856 | Q9: =M9-A9 -> -0.6 | R9: =N9-B9 -> -0.16 | S9: =O9-C9 -> -1.5707963 | T9: =ABS(Q9) -> 0.6 | U9: =ABS(R9) -> 0.16 | V9: =ABS(S9) -> 1.5707963
A10: ='Proximal Validation'!A10 -> 0.8 | B10: ='Proximal Validation'!B10 -> 0.18 | C10: ='Proximal Validation'!C10 -> 1.5707963 | D10: ='Proximal Validation'!D10 -> 0 | E10: ='Proximal Validation'!E10 -> 0 | F10: ='Proximal Validation'!F10 -> 0 | G10: ='Proximal Validation'!G10 -> -0.0025411225 | H10: ='Proximal Validation'!H10 -> -0.16168536 | ... L10: ='Proximal Validation'!L10 -> 0.27560678 | Q10: =M10-A10 -> -0.8 | R10: =N10-B10 -> -0.18 | S10: =O10-C10 -> -1.5707963 | T10: =ABS(Q10) -> 0.8 | U10: =ABS(R10) -> 0.18 | V10: =ABS(S10) -> 1.5707963
A11: ='Proximal Validation'!A11 -> 0.3 | B11: ='Proximal Validation'!B11 -> 0.2 | C11: ='Proximal Validation'!C11 -> 1.5707963 | D11: ='Proximal Validation'!D11 -> 0 | E11: ='Proximal Validation'!E11 -> 0 | F11: ='Proximal Validation'!F11 -> 0 | G11: ='Proximal Validation'!G11 -> -0.00077232125 | H11: ='Proximal Validation'!H11 -> -0.071722366 | ... L11: ='Proximal Validation'!L11 -> 0.21111466 | Q11: =M11-A11 -> -0.3 | R11: =N11-B11 -> -0.2 | S11: =O11-C11 -> -1.5707963 | T11: =ABS(Q11) -> 0.3 | U11: =ABS(R11) -> 0.2 | V11: =ABS(S11) -> 1.5707963
A12: ='Proximal Validation'!A12 -> 0.7 | B12: ='Proximal Validation'!B12 -> 0.2 | C12: ='Proximal Validation'!C12 -> 1.5707963 | D12: ='Proximal Validation'!D12 -> 0 | E12: ='Proximal Validation'!E12 -> 0 | F12: ='Proximal Validation'!F12 -> 0 | G12: ='Proximal Validation'!G12 -> -0.0013749812 | H12: ='Proximal Validation'!H12 -> -0.132386 | ... L12: ='Proximal Validation'!L12 -> 0.17886317 | Q12: =M12-A12 -> -0.7 | R12: =N12-B12 -> -0.2 | S12: =O12-C12 -> -1.5707963 | T12: =ABS(Q12) -> 0.7 | U12: =ABS(R12) -> 0.2 | V12: =ABS(S12) -> 1.5707963
A14: Perturbation
A15: 0.5 | B15: 0 | C15: 0
A16: 0 | B16: 0.5 | C16: 0
A17: 0 | B17: 0 | C17: 0.5
C20: Trial # | D20: tau1 (N) | E20: tau2 (N) | F20: tau3 (N) | G20: Supporting Measurments w Perturbation
C21: 1 | D21: =D3 -> 0 | E21: =E3 -> 0 | F21: =F3 -> 0 | G21: =G3 -> -0.00043792196 | H21: =H3 -> -0.054464955 | I21: =I3 -> -0.00028745097 | J21: =J3 -> -0.021312971 | K21: =K3 -> 0.0001851581 | L21: =L3 -> 0.34822303
C22: 1 | D22: =A15+D$21 -> 0.5 | E22: =B15+E$21 -> 0 | F22: =C15+F$21 -> 0 | G22: -0.00010226411 | H22: -0.049233463 | I22: -0.00029947638 | J22: -0.016571488 | K22: -0.0013392493 | L22: 0.31748384
C23: 1 | D23: =A16+D$21 -> 0 | E23: =B16+E$21 -> 0.5 | F23: =C16+F$21 -> 0 | G23: -0.00042643712 | H23: -0.048638277 | I23: -0.00027974934 | J23: -0.016359337 | K23: 0.0013240017 | L23: 0.31480351
C24: 1 | D24: =A17+D$21 -> 0 | E24: =B17+E$21 -> 0 | F24: =C17+F$21 -> 0.5 | G24: -0.00028887985 | H24: -0.057832427 | I24: -0.00034862931 | J24: -0.019577505 | K24: 0.00054720044 | L24: 0.3746936
C25: 2 | D25: 0 | E25: 0 | F25: 0 | G25: =G4 -> -0.0012904059 | H25: =H4 -> -0.13089056 | I25: =I4 -> -0.00050724833 | J25: =J4 -> -0.12710035 | K25: =K4 -> 0.0033702701 | L25: =L4 -> 0.83409011
C26: 2 | D26: 0.5 | E26: 0 | F26: 0 | G26: -0.0007565585 | H26: -0.12717237 | I26: -0.00068982423 | J26: -0.12189347 | K26: 0.00054381788 | L26: 0.81394112
C27: 2 | D27: 0 | E27: 0.5 | F27: 0 | G27: -0.0016186913 | H27: -0.12622461 | I27: -0.00027284108 | J27: -0.12119073 | K27: 0.0059388876 | L27: 0.81022829
C28: 2 | D28: 0 | E28: 0 | F28: 0.5 | G28: -0.0012862352 | H28: -0.13277906 | I28: -0.00048934319 | J28: -0.12763685 | K28: 0.0040640682 | L28: 0.85237813
C29: 3 | D29: 0 | E29: 0 | F29: 0 | G29: =G5 -> -0.00044532004 | H29: =H5 -> -0.047905073 | I29: =I5 -> -0.0001454872 | J29: =J5 -> -0.015221856 | K29: =K5 -> -0.00016181916 | L29: =L5 -> 0.26909974
C30: 3 | D30: 0.5 | E30: 0 | F30: 0 | G30: -0.00010291673 | H30: -0.040455386 | I30: -0.00019746993 | J30: -0.013778557 | K30: -0.0019923076 | L30: 0.22861606
C31: 3 | D31: 0 | E31: 0.5 | F31: 0 | G31: -0.00052102975 | H31: -0.039230645 | I31: -5.4417731e-05 | J31: -0.01025647 | K31: 0.00080219656 | L31: 0.22224036
C32: 3 | D32: 0 | E32: 0 | F32: 0.5 | G32: -0.00049925747 | H32: -0.051998798 | I32: -0.00013459765 | J32: -0.015688423 | K32: 5.8252364e-05 | L32: 0.29535106
C33: 4 | D33: 0 | E33: 0 | F33: 0 | G33: =G6 -> -0.001170564 | H33: =H6 -> -0.094456188 | I33: =I6 -> -0.0012032345 | J33: =J6 -> -0.11118765 | K33: =K6 -> -0.0032553412 | L33: =L6 -> 0.47075057
C34: 4 | D34: 0.5 | E34: 0 | F34: 0 | G34: -0.00043118373 | H34: -0.089639507 | I34: -0.0016416889 | J34: -0.10492411 | K34: -0.0073592812 | L34: 0.44790044
C35: 4 | D35: 0 | E35: 0.5 | F35: 0 | G35: -0.0018029769 | H35: -0.087559678 | I35: -0.00067153916 | J35: -0.10215356 | K35: -2.1431595e-05 | L35: 0.43895808
C36: 4 | D36: 0 | E36: 0 | F36: 0.5 | G36: -0.0014795207 | H36: -0.09911716 | I36: -0.0011116047 | J36: -0.11587341 | K36: -0.0023469403 | L36: 0.49583638
C37: 5 | D37: 0 | E37: 0 | F37: 0 | G37: =G7 -> -0.0015179969 | H37: =H7 -> -0.13914527 | I37: =I7 -> -0.0016895274 | J37: =J7 -> -0.20834762 | K37: =K7 -> -0.0026145354 | L37: =L7 -> 0.69233716
C38: 5 | D38: 0.5 | E38: 0 | F38: 0 | G38: -0.00035102316 | H38: -0.13304213 | I38: -0.0024027161 | J38: -0.19618353 | K38: -0.0090570524 | L38: 0.66389406
C39: 5 | D39: 0 | E39: 0.5 | F39: 0 | G39: -0.0024652022 | H39: -0.13107772 | I39: -0.00082595617 | J39: -0.19345121 | K39: 0.0030057281 | L39: 0.65493339
C40: 5 | D40: 0 | E40: 0 | F40: 0.5 | G40: -0.0019036105 | H40: -0.14096364 | I40: -0.0014126808 | J40: -0.21145742 | K40: -0.00084137172 | L40: 0.70331705
C41: 6 | D41: 0 | E41: 0 | F41: 0 | G41: =G8 -> -0.00060909818 | H41: =H8 -> -0.093464263 | I41: =I8 -> -0.0014227356 | J41: =J8 -> -0.18325244 | K41: =K8 -> -0.001301948 | L41: =L8 -> 0.33158547
C42: 6 | D42: 0.5 | E42: 0 | F42: 0 | G42: 0.001203709 | H42: -0.086668573 | I42: -0.0029307436 | J42: -0.17014571 | K42: -0.011143077 | L42: 0.30808723
C43: 6 | D43: 0 | E43: 0.5 | F43: 0 | G43: -0.0018327645 | H43: -0.085605741 | I43: -0.0001662164 | J43: -0.16719891 | K43: 0.0050233426 | L43: 0.3053053
...

Sheet Distal Vali (1N perturb)
A1: 3 Perturbations | AA1: 3 Perturbation (relative only)
A2: Ground Truth | G2: 6-Axis FT Sensor | M2: SoRoSim get_distal_value (lambda = 1) | Q2: Distal Errors | T2: ABS Distal Errors | AA2: Ground Truth | AG2: 6-Axis FT Sensor | AM2: SoRoSim get_distal_value (lambda = 1) | AQ2: Distal Errors | AT2: ABS Distal Errors
A3: F (N) | B3: s (m) | C3: theta (rad) | D3: tau1 (N) | E3: tau2 (N) | F3: tau3 (N) | G3: Tx (Nm) | H3: Ty (Nm) | I3: Tz(Nm) | J3: Fx (N) | K3: Fy (N) | L3: Fz (N) | M3: F (N) | N3: s (m) | O3: theta (rad) | P3: f_final | Q3: F (N) | R3: s (m) | S3: theta (rad) | T3: F (N) | U3: s (m) | V3: theta (rad) | W3: Absolute Mean Error | AA3: F (N) | AB3: s (m) | AC3: theta (rad) | AD3: tau1 (N) | AE3: tau2 (N) | AF3: tau3 (N) | AG3: Tx (Nm) | AH3: Ty (Nm) | AI3: Tz(Nm) | AJ3: Fx (N) | AK3: Fy (N) | AL3: Fz (N) | AM3: F (N) | AN3: s (m) | AO3: theta (rad) | AP3: f_final | AQ3: F (N) | AR3: s (m) | AS3: theta (rad) | AT3: F (N) | AU3: s (m) | AV3: theta (rad) | AW3: Absolute Mean Error
A4: ='Proximal Validation'!A3 -> 0.4 | B4: ='Proximal Validation'!B3 -> 0.06 | C4: ='Proximal Validation'!C3 -> 1.5707963 | D4: ='Proximal Validation'!D3 -> 0 | E4: ='Proximal Validation'!E3 -> 0 | F4: ='Proximal Validation'!F3 -> 0 | G4: ='Proximal Validation'!G3 -> -0.00043792196 | H4: ='Proximal Validation'!H3 -> -0.054464955 | ... L4: ='Proximal Validation'!L3 -> 0.34822303 | Q4: =M4-A4 -> -0.4 | R4: =N4-B4 -> -0.06 | S4: =O4-C4 -> -1.5707963 | T4: =ABS(Q4) -> 0.4 | U4: =ABS(R4) -> 0.06 | V4: =ABS(S4) -> 1.5707963 | W4: F1 (N) | X4: s1 (m) | Y4: el1 (rad) | AA4: ='Proximal Validation'!A3 -> 0.4 | AB4: ='Proximal Validation'!B3 -> 0.06 | AC4: ='Proximal Validation'!C3 -> 1.5707963 | AD4: ='Proximal Validation'!D3 -> 0 | AE4: ='Proximal Validation'!E3 -> 0 | AF4: ='Proximal Validation'!F3 -> 0 | AG4: ='Proximal Validation'!G3 -> -0.00043792196 | AH4: ='Proximal Validation'!H3 -> -0.054464955 | ... AL4: ='Proximal Validation'!L3 -> 0.34822303 | AM4: 0.90280937 | AN4: 0.073504807 | AO4: 1.5860914 | AP4: 0.00021199761 | AQ4: =AM4-AA4 -> 0.50280937 | AR4: =AN4-AB4 -> 0.013504807 | AS4: =AO4-AC4 -> 0.01529503 | AT4: =ABS(AQ4) -> 0.50280937 | AU4: =ABS(AR4) -> 0.013504807 | AV4: =ABS(AS4) -> 0.01529503 | AW4: F1 (N) | AX4: s1 (m) | AY4: el1 (rad)
A5: ='Proximal Validation'!A4 -> 0.8 | B5: ='Proximal Validation'!B4 -> 0.06 | C5: ='Proximal Validation'!C4 -> 1.5707963 | D5: ='Proximal Validation'!D4 -> 0 | E5: ='Proximal Validation'!E4 -> 0 | F5: ='Proximal Validation'!F4 -> 0 | G5: ='Proximal Validation'!G4 -> -0.0012904059 | H5: ='Proximal Validation'!H4 -> -0.13089056 | ... L5: ='Proximal Validation'!L4 -> 0.83409011 | Q5: =M5-A5 -> -0.8 | R5: =N5-B5 -> -0.06 | S5: =O5-C5 -> -1.5707963 | T5: =ABS(Q5) -> 0.8 | U5: =ABS(R5) -> 0.06 | V5: =ABS(S5) -> 1.5707963 | W5: {=AVERAGE(ABS(Q4:Q13))} -> 0.55 | X5: {=AVERAGE(ABS(R4:R13))} -> 0.13 | Y5: {=AVERAGE(ABS(S4:S13))} -> 1.5707963 | AA5: ='Proximal Validation'!A4 -> 0.8 | AB5: ='Proximal Validation'!B4 -> 0.06 | AC5: ='Proximal Validation'!C4 -> 1.5707963 | AD5: ='Proximal Validation'!D4 -> 0 | AE5: ='Proximal Validation'!E4 -> 0 | AF5: ='Proximal Validation'!F4 -> 0 | AG5: ='Proximal Validation'!G4 -> -0.0012904059 | AH5: ='Proximal Validation'!H4 -> -0.13089056 | ... AL5: ='Proximal Validation'!L4 -> 0.83409011 | AM5: 0.88619394 | AN5: 0.077520968 | AO5: 1.59932 | AP5: 0.00077792135 | AQ5: =AM5-AA5 -> 0.086193938 | AR5: =AN5-AB5 -> 0.017520968 | AS5: =AO5-AC5 -> 0.028523639 | AT5: =ABS(AQ5) -> 0.086193938 | AU5: =ABS(AR5) -> 0.017520968 | AV5: =ABS(AS5) -> 0.028523639 | AW5: {=AVERAGE(ABS(AQ4:AQ13))} -> 0.16765909 | AX5: {=AVERAGE(ABS(AR4:AR13))} -> 0.010799263 | AY5: {=AVERAGE(ABS(AS4:AS13))} -> 0.01340021
A6: ='Proximal Validation'!A5 -> 0.3 | B6: ='Proximal Validation'!B5 -> 0.08 | C6: ='Proximal Validation'!C5 -> 1.5707963 | D6: ='Proximal Validation'!D5 -> 0 | E6: ='Proximal Validation'!E5 -> 0 | F6: ='Proximal Validation'!F5 -> 0 | G6: ='Proximal Validation'!G5 -> -0.00044532004 | H6: ='Proximal Validation'!H5 -> -0.047905073 | ... L6: ='Proximal Validation'!L5 -> 0.26909974 | Q6: =M6-A6 -> -0.3 | R6: =N6-B6 -> -0.08 | S6: =O6-C6 -> -1.5707963 | T6: =ABS(Q6) -> 0.3 | U6: =ABS(R6) -> 0.08 | V6: =ABS(S6) -> 1.5707963 | AA6: ='Proximal Validation'!A5 -> 0.3 | AB6: ='Proximal Validation'!B5 -> 0.08 | AC6: ='Proximal Validation'!C5 -> 1.5707963 | AD6: ='Proximal Validation'!D5 -> 0 | AE6: ='Proximal Validation'!E5 -> 0 | AF6: ='Proximal Validation'!F5 -> 0 | AG6: ='Proximal Validation'!G5 -> -0.00044532004 | AH6: ='Proximal Validation'!H5 -> -0.047905073 | ... AL6: ='Proximal Validation'!L5 -> 0.26909974 | AM6: 0.63721852 | AN6: 0.08779344 | AO6: 1.5812845 | AP6: 2.170911e-05 | AQ6: =AM6-AA6 -> 0.33721852 | AR6: =AN6-AB6 -> 0.0077934401 | AS6: =AO6-AC6 -> 0.010488174 | AT6: =ABS(AQ6) -> 0.33721852 | AU6: =ABS(AR6) -> 0.0077934401 | AV6: =ABS(AS6) -> 0.010488174
A7: ='Proximal Validation'!A6 -> 0.5 | B7: ='Proximal Validation'!B6 -> 0.1 | C7: ='Proximal Validation'!C6 -> 1.5707963 | D7: ='Proximal Validation'!D6 -> 0 | E7: ='Proximal Validation'!E6 -> 0 | F7: ='Proximal Validation'!F6 -> 0 | G7: ='Proximal Validation'!G6 -> -0.001170564 | H7: ='Proximal Validation'!H6 -> -0.094456188 | ... L7: ='Proximal Validation'!L6 -> 0.47075057 | Q7: =M7-A7 -> -0.5 | R7: =N7-B7 -> -0.1 | S7: =O7-C7 -> -1.5707963 | T7: =ABS(Q7) -> 0.5 | U7: =ABS(R7) -> 0.1 | V7: =ABS(S7) -> 1.5707963 | AA7: ='Proximal Validation'!A6 -> 0.5 | AB7: ='Proximal Validation'!B6 -> 0.1 | AC7: ='Proximal Validation'!C6 -> 1.5707963 | AD7: ='Proximal Validation'!D6 -> 0 | AE7: ='Proximal Validation'!E6 -> 0 | AF7: ='Proximal Validation'!F6 -> 0 | AG7: ='Proximal Validation'!G6 -> -0.001170564 | AH7: ='Proximal Validation'!H6 -> -0.094456188 | ... AL7: ='Proximal Validation'!L6 -> 0.47075057 | AM7: 0.80752081 | AN7: 0.11162012 | AO7: 1.587466 | AP7: 6.3464188e-05 | AQ7: =AM7-AA7 -> 0.30752081 | AR7: =AN7-AB7 -> 0.01162012 | AS7: =AO7-AC7 -> 0.016669676 | AT7: =ABS(AQ7) -> 0.30752081 | AU7: =ABS(AR7) -> 0.01162012 | AV7: =ABS(AS7) -> 0.016669676
A8: ='Proximal Validation'!A7 -> 0.7 | B8: ='Proximal Validation'!B7 -> 0.1 | C8: ='Proximal Validation'!C7 -> 1.5707963 | D8: ='Proximal Validation'!D7 -> 0 | E8: ='Proximal Validation'!E7 -> 0 | F8: ='Proximal Validation'!F7 -> 0 | G8: ='Proximal Validation'!G7 -> -0.0015179969 | H8: ='Proximal Validation'!H7 -> -0.13914527 | ... L8: ='Proximal Validation'!L7 -> 0.69233716 | Q8: =M8-A8 -> -0.7 | R8: =N8-B8 -> -0.1 | S8: =O8-C8 -> -1.5707963 | T8: =ABS(Q8) -> 0.7 | U8: =ABS(R8) -> 0.1 | V8: =ABS(S8) -> 1.5707963 | AA8: ='Proximal Validation'!A7 -> 0.7 | AB8: ='Proximal Validation'!B7 -> 0.1 | AC8: ='Proximal Validation'!C7 -> 1.5707963 | AD8: ='Proximal Validation'!D7 -> 0 | AE8: ='Proximal Validation'!E7 -> 0 | AF8: ='Proximal Validation'!F7 -> 0 | AG8: ='Proximal Validation'!G7 -> -0.0015179969 | AH8: ='Proximal Validation'!H7 -> -0.13914527 | ... AL8: ='Proximal Validation'!L7 -> 0.69233716 | AM8: 0.88379744 | AN8: 0.11268547 | AO8: 1.5867762 | AP8: 9.2289562e-05 | AQ8: =AM8-AA8 -> 0.18379744 | AR8: =AN8-AB8 -> 0.01268547 | AS8: =AO8-AC8 -> 0.015979906 | AT8: =ABS(AQ8) -> 0.18379744 | AU8: =ABS(AR8) -> 0.01268547 | AV8: =ABS(AS8) -> 0.015979906
A9: ='Proximal Validation'!A8 -> 0.4 | B9: ='Proximal Validation'!B8 -> 0.16 | C9: ='Proximal Validation'!C8 -> 1.5707963 | D9: ='Proximal Validation'!D8 -> 0 | E9: ='Proximal Validation'!E8 -> 0 | F9: ='Proximal Validation'!F8 -> 0 | G9: ='Proximal Validation'!G8 -> -0.00060909818 | H9: ='Proximal Validation'!H8 -> -0.093464263 | ... L9: ='Proximal Validation'!L8 -> 0.33158547 | Q9: =M9-A9 -> -0.4 | R9: =N9-B9 -> -0.16 | S9: =O9-C9 -> -1.5707963 | T9: =ABS(Q9) -> 0.4 | U9: =ABS(R9) -> 0.16 | V9: =ABS(S9) -> 1.5707963 | AA9: ='Proximal Validation'!A8 -> 0.4 | AB9: ='Proximal Validation'!B8 -> 0.16 | AC9: ='Proximal Validation'!C8 -> 1.5707963 | AD9: ='Proximal Validation'!D8 -> 0 | AE9: ='Proximal Validation'!E8 -> 0 | AF9: ='Proximal Validation'!F8 -> 0 | AG9: ='Proximal Validation'!G8 -> -0.00060909818 | AH9: ='Proximal Validation'!H8 -> -0.093464263 | ... AL9: ='Proximal Validation'!L8 -> 0.33158547 | AM9: 0.37681577 | AN9: 0.17145294 | AO9: 1.5789639 | AP9: 0.00033490254 | AQ9: =AM9-AA9 -> -0.023184233 | AR9: =AN9-AB9 -> 0.011452938 | AS9: =AO9-AC9 -> 0.00816754 | AT9: =ABS(AQ9) -> 0.023184233 | AU9: =ABS(AR9) -> 0.011452938 | AV9: =ABS(AS9) -> 0.00816754
A10: ='Proximal Validation'!A9 -> 0.6 | B10: ='Proximal Validation'!B9 -> 0.16 | C10: ='Proximal Validation'!C9 -> 1.5707963 | D10: ='Proximal Validation'!D9 -> 0 | E10: ='Proximal Validation'!E9 -> 0 | F10: ='Proximal Validation'!F9 -> 0 | G10: ='Proximal Validation'!G9 -> -0.00084166456 | H10: ='Proximal Validation'!H9 -> -0.14134772 | ... L10: ='Proximal Validation'!L9 -> 0.46994856 | Q10: =M10-A10 -> -0.6 | R10: =N10-B10 -> -0.16 | S10: =O10-C10 -> -1.5707963 | T10: =ABS(Q10) -> 0.6 | U10: =ABS(R10) -> 0.16 | V10: =ABS(S10) -> 1.5707963 | AA10: ='Proximal Validation'!A9 -> 0.6 | AB10: ='Proximal Validation'!B9 -> 0.16 | AC10: ='Proximal Validation'!C9 -> 1.5707963 | AD10: ='Proximal Validation'!D9 -> 0 | AE10: ='Proximal Validation'!E9 -> 0 | AF10: ='Proximal Validation'!F9 -> 0 | AG10: ='Proximal Validation'!G9 -> -0.00084166456 | AH10: ='Proximal Validation'!H9 -> -0.14134772 | ... AL10: ='Proximal Validation'!L9 -> 0.46994856 | AM10: 0.53446525 | AN10: 0.16715554 | AO10: 1.5778248 | AP10: 0.00037814702 | AQ10: =AM10-AA10 -> -0.065534753 | AR10: =AN10-AB10 -> 0.0071555363 | AS10: =AO10-AC10 -> 0.0070285012 | AT10: =ABS(AQ10) -> 0.065534753 | AU10: =ABS(AR10) -> 0.0071555363 | AV10: =ABS(AS10) -> 0.0070285012
A11: ='Proximal Validation'!A10 -> 0.8 | B11: ='Proximal Validation'!B10 -> 0.18 | C11: ='Proximal Validation'!C10 -> 1.5707963 | D11: ='Proximal Validation'!D10 -> 0 | E11: ='Proximal Validation'!E10 -> 0 | F11: ='Proximal Validation'!F10 -> 0 | G11: ='Proximal Validation'!G10 -> -0.0025411225 | H11: ='Proximal Validation'!H10 -> -0.16168536 | ... L11: ='Proximal Validation'!L10 -> 0.27560678 | Q11: =M11-A11 -> -0.8 | R11: =N11-B11 -> -0.18 | S11: =O11-C11 -> -1.5707963 | T11: =ABS(Q11) -> 0.8 | U11: =ABS(R11) -> 0.18 | V11: =ABS(S11) -> 1.5707963 | AA11: ='Proximal Validation'!A10 -> 0.8 | AB11: ='Proximal Validation'!B10 -> 0.18 | AC11: ='Proximal Validation'!C10 -> 1.5707963 | AD11: ='Proximal Validation'!D10 -> 0 | AE11: ='Proximal Validation'!E10 -> 0 | AF11: ='Proximal Validation'!F10 -> 0 | AG11: ='Proximal Validation'!G10 -> -0.0025411225 | AH11: ='Proximal Validation'!H10 -> -0.16168536 | ... AL11: ='Proximal Validation'!L10 -> 0.27560678 | AM11: 0.7316347 | AN11: 0.17208978 | AO11: 1.5857556 | AP11: 0.00030318542 | AQ11: =AM11-AA11 -> -0.068365303 | AR11: =AN11-AB11 -> -0.0079102167 | AS11: =AO11-AC11 -> 0.014959296 | AT11: =ABS(AQ11) -> 0.068365303 | AU11: =ABS(AR11) -> 0.0079102167 | AV11: =ABS(AS11) -> 0.014959296
A12: ='Proximal Validation'!A11 -> 0.3 | B12: ='Proximal Validation'!B11 -> 0.2 | C12: ='Proximal Validation'!C11 -> 1.5707963 | D12: ='Proximal Validation'!D11 -> 0 | E12: ='Proximal Validation'!E11 -> 0 | F12: ='Proximal Validation'!F11 -> 0 | G12: ='Proximal Validation'!G11 -> -0.00077232125 | H12: ='Proximal Validation'!H11 -> -0.071722366 | ... L12: ='Proximal Validation'!L11 -> 0.21111466 | Q12: =M12-A12 -> -0.3 | R12: =N12-B12 -> -0.2 | S12: =O12-C12 -> -1.5707963 | T12: =ABS(Q12) -> 0.3 | U12: =ABS(R12) -> 0.2 | V12: =ABS(S12) -> 1.5707963 | AA12: ='Proximal Validation'!A11 -> 0.3 | AB12: ='Proximal Validation'!B11 -> 0.2 | AC12: ='Proximal Validation'!C11 -> 1.5707963 | AD12: ='Proximal Validation'!D11 -> 0 | AE12: ='Proximal Validation'!E11 -> 0 | AF12: ='Proximal Validation'!F11 -> 0 | AG12: ='Proximal Validation'!G11 -> -0.00077232125 | AH12: ='Proximal Validation'!H11 -> -0.071722366 | ... AL12: ='Proximal Validation'!L11 -> 0.21111466 | AM12: 0.29592508 | AN12: 0.2 | AO12: 1.578543 | AP12: 0.00069725326 | AQ12: =AM12-AA12 -> -0.0040749184 | AR12: =AN12-AB12 -> -2.220446e-14 | AS12: =AO12-AC12 -> 0.0077466234 | AT12: =ABS(AQ12) -> 0.0040749184 | AU12: =ABS(AR12) -> 2.220446e-14 | AV12: =ABS(AS12) -> 0.0077466234
A13: ='Proximal Validation'!A12 -> 0.7 | B13: ='Proximal Validation'!B12 -> 0.2 | C13: ='Proximal Validation'!C12 -> 1.5707963 | D13: ='Proximal Validation'!D12 -> 0 | E13: ='Proximal Validation'!E12 -> 0 | F13: ='Proximal Validation'!F12 -> 0 | G13: ='Proximal Validation'!G12 -> -0.0013749812 | H13: ='Proximal Validation'!H12 -> -0.132386 | ... L13: ='Proximal Validation'!L12 -> 0.17886317 | Q13: =M13-A13 -> -0.7 | R13: =N13-B13 -> -0.2 | S13: =O13-C13 -> -1.5707963 | T13: =ABS(Q13) -> 0.7 | U13: =ABS(R13) -> 0.2 | V13: =ABS(S13) -> 1.5707963 | AA13: ='Proximal Validation'!A12 -> 0.7 | AB13: ='Proximal Validation'!B12 -> 0.2 | AC13: ='Proximal Validation'!C12 -> 1.5707963 | AD13: ='Proximal Validation'!D12 -> 0 | AE13: ='Proximal Validation'!E12 -> 0 | AF13: ='Proximal Validation'!F12 -> 0 | AG13: ='Proximal Validation'!G12 -> -0.0013749812 | AH13: ='Proximal Validation'!H12 -> -0.132386 | ... AL13: ='Proximal Validation'!L12 -> 0.17886317 | AM13: 0.6021084 | AN13: 0.18165086 | AO13: 1.57994 | AP13: 0.00034643972 | AQ13: =AM13-AA13 -> -0.097891598 | AR13: =AN13-AB13 -> -0.018349136 | AS13: =AO13-AC13 -> 0.0091437122 | AT13: =ABS(AQ13) -> 0.097891598 | AU13: =ABS(AR13) -> 0.018349136 | AV13: =ABS(AS13) -> 0.0091437122
A15: Perturbation
A16: 1 | B16: 0 | C16: 0
A17: 0 | B17: 1 | C17: 0
A18: 0 | B18: 0 | C18: 1
C21: Trial # | D21: tau1 (N) | E21: tau2 (N) | F21: tau3 (N) | G21: Supporting Measurments w Perturbation
C22: 1 | D22: =D4 -> 0 | E22: =E4 -> 0 | F22: =F4 -> 0 | G22: =G4 -> -0.00043792196 | H22: =H4 -> -0.054464955 | I22: =I4 -> -0.00028745097 | J22: =J4 -> -0.021312971 | K22: =K4 -> 0.0001851581 | L22: =L4 -> 0.34822303
C23: 1 | D23: 1 | E23: 0 | F23: 0 | G23: 0.00031034613 | H23: -0.044063799 | I23: -0.00026626966 | J23: -0.012337493 | K23: -0.0020012185 | L23: 0.28711793
C24: 1 | D24: 0 | E24: 1 | F24: 0 | G24: -0.00045217655 | H24: -0.042780064 | I24: -0.00029174646 | J24: -0.010398514 | K24: 0.0028434172 | L24: 0.27934211
C25: 1 | D25: 0 | E25: 0 | F25: 1 | G25: -0.00025805319 | H25: -0.063121602 | I25: -0.00042537239 | J25: -0.021438804 | K25: 0.00085363537 | L25: 0.41041622
C26: 2 | D26: 0 | E26: 0 | F26: 0 | G26: =G5 -> -0.0012904059 | H26: =H5 -> -0.13089056 | I26: =I5 -> -0.00050724833 | J26: =J5 -> -0.12710035 | K26: =K5 -> 0.0033702701 | L26: =L5 -> 0.83409011
C27: 2 | D27: 1 | E27: 0 | F27: 0 | G27: -0.00015963241 | H27: -0.12156289 | I27: -0.00082839734 | J27: -0.115151 | K27: -0.0021543056 | L27: 0.78203225
C28: 2 | D28: 0 | E28: 1 | F28: 0 | G28: -0.0019617279 | H28: -0.12112325 | I28: -6.2098959e-05 | J28: -0.11508367 | K28: 0.00861644 | L28: 0.77998018
C29: 2 | D29: 0 | E29: 0 | F29: 1 | G29: -0.0012581681 | H29: -0.1355927 | I29: -0.00053044769 | J29: -0.13436604 | K29: 0.004158631 | L29: 0.87226921
C30: 3 | D30: 0 | E30: 0 | F30: 0 | G30: =G6 -> -0.00044532004 | H30: =H6 -> -0.047905073 | I30: =I6 -> -0.0001454872 | J30: =J6 -> -0.015221856 | K30: =K6 -> -0.00016181916 | L30: =L6 -> 0.26909974
C31: 3 | D31: 1 | E31: 0 | F31: 0 | G31: 0.00019974157 | H31: -0.032512676 | I31: -0.00017105712 | J31: -0.0080844657 | K31: -0.0031807572 | L31: 0.18479598
C32: 3 | D32: 0 | E32: 1 | F32: 0 | G32: -0.000575768 | H32: -0.030636495 | I32: -9.7063734e-05 | J32: -0.0072050262 | K32: 0.0018094089 | L32: 0.17424859
C33: 3 | D33: 0 | E33: 0 | F33: 1 | G33: -0.00058534357 | H33: -0.060917992 | I33: -0.00014559276 | J33: -0.018382957 | K33: 0.00091800466 | L33: 0.34572017
C34: 4 | D34: 0 | E34: 0 | F34: 0 | G34: =G7 -> -0.001170564 | H34: =H7 -> -0.094456188 | I34: =I7 -> -0.0012032345 | J34: =J7 -> -0.11118765 | K34: =K7 -> -0.0032553412 | L34: =L7 -> 0.47075057
C35: 4 | D35: 1 | E35: 0 | F35: 0 | G35: 8.7243388e-05 | H35: -0.081967004 | I35: -0.0018417513 | J35: -0.095461011 | K35: -0.010244839 | L35: 0.41104403
C36: 4 | D36: 0 | E36: 1 | F36: 0 | G36: -0.0026281357 | H36: -0.079778142 | I36: 8.1456965e-06 | J36: -0.091968797 | K36: 0.0049324837 | L36: 0.40118694
C37: 4 | D37: 0 | E37: 0 | F37: 1 | G37: -0.0017928606 | H37: -0.10628338 | I37: -0.0010514269 | J37: -0.12429389 | K37: -0.0018899888 | L37: 0.53177243
C38: 5 | D38: 0 | E38: 0 | F38: 0 | G38: =G8 -> -0.0015179969 | H38: =H8 -> -0.13914527 | I38: =I8 -> -0.0016895274 | J38: =J8 -> -0.20834762 | K38: =K8 -> -0.0026145354 | L38: =L8 -> 0.69233716
C39: 5 | D39: 1 | E39: 0 | F39: 0 | G39: 0.0004032026 | H39: -0.12612909 | I39: -0.0027437012 | J39: -0.18591291 | K39: -0.012886427 | L39: 0.63056266
C40: 5 | D40: 0 | E40: 1 | F40: 0 | G40: -0.0036035974 | H40: -0.1232848 | I40: 0.00013838161 | J40: -0.18036614 | K40: 0.0095373616 | L40: 0.61717546
C41: 5 | D41: 0 | E41: 0 | F41: 1 | G41: -0.0020965661 | H41: -0.14749147 | I41: -0.0013944744 | J41: -0.22115432 | K41: -3.3147633e-05 | L41: 0.73367012
C42: 6 | D42: 0 | E42: 0 | F42: 0 | G42: =G9 -> -0.00060909818 | H42: =H9 -> -0.093464263 | I42: =I9 -> -0.0014227356 | J42: =J9 -> -0.18325244 | K42: =K9 -> -0.001301948 | L42: =L9 -> 0.33158547
C43: 6 | D43: 1 | E43: 0 | F43: 0 | G43: 0.0021256739 | H43: -0.081501223 | I43: -0.0036365092 | J43: -0.15839048 | K43: -0.015761573 | L43: 0.29118153
...

Sheet Distal Vali (1.5N perturb)
A1: Ground Truth | G1: 6-Axis FT Sensor | M1: SoRoSim get_distal_value (3 Perturbations) | Q1: Distal Errors | T1: ABS Distal Errors
A2: F (N) | B2: s (m) | C2: theta (rad) | D2: tau1 (N) | E2: tau2 (N) | F2: tau3 (N) | G2: Tx (Nm) | H2: Ty (Nm) | I2: Tz(Nm) | J2: Fx (N) | K2: Fy (N) | L2: Fz (N) | M2: F (N) | N2: s (m) | O2: theta (rad) | P2: f_final | Q2: F (N) | R2: s (m) | S2: theta (rad) | T2: F (N) | U2: s (m) | V2: theta (rad) | W2: Absolute Mean Error
A3: ='Proximal Validation'!A3 -> 0.4 | B3: ='Proximal Validation'!B3 -> 0.06 | C3: ='Proximal Validation'!C3 -> 1.5707963 | D3: ='Proximal Validation'!D3 -> 0 | E3: ='Proximal Validation'!E3 -> 0 | F3: ='Proximal Validation'!F3 -> 0 | G3: ='Proximal Validation'!G3 -> -0.00043792196 | H3: ='Proximal Validation'!H3 -> -0.054464955 | ... L3: ='Proximal Validation'!L3 -> 0.34822303 | M3: 0.31408272 | N3: 0.2 | O3: 1.5865549 | P3: 0.0048770789 | Q3: =M3-A3 -> -0.085917284 | R3: =N3-B3 -> 0.14 | S3: =O3-C3 -> 0.015758599 | T3: =ABS(Q3) -> 0.085917284 | U3: =ABS(R3) -> 0.14 | V3: =ABS(S3) -> 0.015758599 | W3: F1 (N) | X3: s1 (m) | Y3: el1 (rad)
A4: ='Proximal Validation'!A4 -> 0.8 | B4: ='Proximal Validation'!B4 -> 0.06 | C4: ='Proximal Validation'!C4 -> 1.5707963 | D4: ='Proximal Validation'!D4 -> 0 | E4: ='Proximal Validation'!E4 -> 0 | F4: ='Proximal Validation'!F4 -> 0 | G4: ='Proximal Validation'!G4 -> -0.0012904059 | H4: ='Proximal Validation'!H4 -> -0.13089056 | ... L4: ='Proximal Validation'!L4 -> 0.83409011 | M4: 0.31623114 | N4: 0.2 | O4: 1.5953492 | P4: 0.0019835039 | Q4: =M4-A4 -> -0.48376886 | R4: =N4-B4 -> 0.14 | S4: =O4-C4 -> 0.024552889 | T4: =ABS(Q4) -> 0.48376886 | U4: =ABS(R4) -> 0.14 | V4: =ABS(S4) -> 0.024552889 | W4: {=AVERAGE(ABS(Q7:Q12))} -> 0.043732468 | X4: {=AVERAGE(ABS(R7:R12))} -> 0.0092053044 | Y4: {=AVERAGE(ABS(S7:S12))} -> 0.012277037
A5: ='Proximal Validation'!A5 -> 0.3 | B5: ='Proximal Validation'!B5 -> 0.08 | C5: ='Proximal Validation'!C5 -> 1.5707963 | D5: ='Proximal Validation'!D5 -> 0 | E5: ='Proximal Validation'!E5 -> 0 | F5: ='Proximal Validation'!F5 -> 0 | G5: ='Proximal Validation'!G5 -> -0.00044532004 | H5: ='Proximal Validation'!H5 -> -0.047905073 | ... L5: ='Proximal Validation'!L5 -> 0.26909974 | M5: 0.24194171 | N5: 0.19999999 | O5: 1.5786471 | P5: 0.00086554941 | Q5: =M5-A5 -> -0.05805829 | R5: =N5-B5 -> 0.11999999 | S5: =O5-C5 -> 0.0078507295 | T5: =ABS(Q5) -> 0.05805829 | U5: =ABS(R5) -> 0.11999999 | V5: =ABS(S5) -> 0.0078507295
A6: ='Proximal Validation'!A6 -> 0.5 | B6: ='Proximal Validation'!B6 -> 0.1 | C6: ='Proximal Validation'!C6 -> 1.5707963 | D6: ='Proximal Validation'!D6 -> 0 | E6: ='Proximal Validation'!E6 -> 0 | F6: ='Proximal Validation'!F6 -> 0 | G6: ='Proximal Validation'!G6 -> -0.001170564 | H6: ='Proximal Validation'!H6 -> -0.094456188 | ... L6: ='Proximal Validation'!L6 -> 0.47075057 | M6: 0.64434807 | N6: 0.084705518 | O6: 1.5888921 | P6: 0.0016532908 | Q6: =M6-A6 -> 0.14434807 | R6: =N6-B6 -> -0.015294482 | S6: =O6-C6 -> 0.018095791 | T6: =ABS(Q6) -> 0.14434807 | U6: =ABS(R6) -> 0.015294482 | V6: =ABS(S6) -> 0.018095791
A7: ='Proximal Validation'!A7 -> 0.7 | B7: ='Proximal Validation'!B7 -> 0.1 | C7: ='Proximal Validation'!C7 -> 1.5707963 | D7: ='Proximal Validation'!D7 -> 0 | E7: ='Proximal Validation'!E7 -> 0 | F7: ='Proximal Validation'!F7 -> 0 | G7: ='Proximal Validation'!G7 -> -0.0015179969 | H7: ='Proximal Validation'!H7 -> -0.13914527 | ... L7: ='Proximal Validation'!L7 -> 0.69233716 | M7: 0.69615948 | N7: 0.10071392 | O7: 1.5905381 | P7: 0.0039969747 | Q7: =M7-A7 -> -0.0038405201 | R7: =N7-B7 -> 0.00071391549 | S7: =O7-C7 -> 0.019741802 | T7: =ABS(Q7) -> 0.0038405201 | U7: =ABS(R7) -> 0.00071391549 | V7: =ABS(S7) -> 0.019741802
A8: ='Proximal Validation'!A8 -> 0.4 | B8: ='Proximal Validation'!B8 -> 0.16 | C8: ='Proximal Validation'!C8 -> 1.5707963 | D8: ='Proximal Validation'!D8 -> 0 | E8: ='Proximal Validation'!E8 -> 0 | F8: ='Proximal Validation'!F8 -> 0 | G8: ='Proximal Validation'!G8 -> -0.00060909818 | H8: ='Proximal Validation'!H8 -> -0.093464263 | ... L8: ='Proximal Validation'!L8 -> 0.33158547 | M8: 0.51201171 | N8: 0.13758461 | O8: 1.5836855 | P8: 0.02375351 | Q8: =M8-A8 -> 0.11201171 | R8: =N8-B8 -> -0.022415389 | S8: =O8-C8 -> 0.012889136 | T8: =ABS(Q8) -> 0.11201171 | U8: =ABS(R8) -> 0.022415389 | V8: =ABS(S8) -> 0.012889136
A9: ='Proximal Validation'!A9 -> 0.6 | B9: ='Proximal Validation'!B9 -> 0.16 | C9: ='Proximal Validation'!C9 -> 1.5707963 | D9: ='Proximal Validation'!D9 -> 0 | E9: ='Proximal Validation'!E9 -> 0 | F9: ='Proximal Validation'!F9 -> 0 | G9: ='Proximal Validation'!G9 -> -0.00084166456 | H9: ='Proximal Validation'!H9 -> -0.14134772 | ... L9: ='Proximal Validation'!L9 -> 0.46994856 | M9: 0.63861944 | N9: 0.16064876 | O9: 1.5794605 | P9: 0.024814226 | Q9: =M9-A9 -> 0.038619441 | R9: =N9-B9 -> 0.00064875762 | S9: =O9-C9 -> 0.0086641426 | T9: =ABS(Q9) -> 0.038619441 | U9: =ABS(R9) -> 0.00064875762 | V9: =ABS(S9) -> 0.0086641426
A10: ='Proximal Validation'!A10 -> 0.8 | B10: ='Proximal Validation'!B10 -> 0.18 | C10: ='Proximal Validation'!C10 -> 1.5707963 | D10: ='Proximal Validation'!D10 -> 0 | E10: ='Proximal Validation'!E10 -> 0 | F10: ='Proximal Validation'!F10 -> 0 | G10: ='Proximal Validation'!G10 -> -0.0025411225 | H10: ='Proximal Validation'!H10 -> -0.16168536 | ... L10: ='Proximal Validation'!L10 -> 0.27560678 | M10: 0.80509763 | N10: 0.18463606 | O10: 1.5841618 | P10: 0.002622565 | Q10: =M10-A10 -> 0.005097632 | R10: =N10-B10 -> 0.0046360553 | S10: =O10-C10 -> 0.013365471 | T10: =ABS(Q10) -> 0.005097632 | U10: =ABS(R10) -> 0.0046360553 | V10: =ABS(S10) -> 0.013365471
A11: ='Proximal Validation'!A11 -> 0.3 | B11: ='Proximal Validation'!B11 -> 0.2 | C11: ='Proximal Validation'!C11 -> 1.5707963 | D11: ='Proximal Validation'!D11 -> 0 | E11: ='Proximal Validation'!E11 -> 0 | F11: ='Proximal Validation'!F11 -> 0 | G11: ='Proximal Validation'!G11 -> -0.00077232125 | H11: ='Proximal Validation'!H11 -> -0.071722366 | ... L11: ='Proximal Validation'!L11 -> 0.21111466 | M11: 0.32040703 | N11: 0.19999615 | O11: 1.5800047 | P11: 0.044421447 | Q11: =M11-A11 -> 0.020407034 | R11: =N11-B11 -> -3.8504344e-06 | S11: =O11-C11 -> 0.0092083297 | T11: =ABS(Q11) -> 0.020407034 | U11: =ABS(R11) -> 3.8504344e-06 | V11: =ABS(S11) -> 0.0092083297
A12: ='Proximal Validation'!A12 -> 0.7 | B12: ='Proximal Validation'!B12 -> 0.2 | C12: ='Proximal Validation'!C12 -> 1.5707963 | D12: ='Proximal Validation'!D12 -> 0 | E12: ='Proximal Validation'!E12 -> 0 | F12: ='Proximal Validation'!F12 -> 0 | G12: ='Proximal Validation'!G12 -> -0.0013749812 | H12: ='Proximal Validation'!H12 -> -0.132386 | ... L12: ='Proximal Validation'!L12 -> 0.17886317 | M12: 0.78241847 | N12: 0.17318614 | O12: 1.5805897 | P12: 0.0071493408 | Q12: =M12-A12 -> 0.08241847 | R12: =N12-B12 -> -0.026813858 | S12: =O12-C12 -> 0.0097933407 | T12: =ABS(Q12) -> 0.08241847 | U12: =ABS(R12) -> 0.026813858 | V12: =ABS(S12) -> 0.0097933407
M13: SoRoSim get_distal_value (2 Perturbations) | Q13: Distal Errors | T13: ABS Distal Errors
A14: Perturbation | M14: F (N) | N14: s (m) | O14: theta (rad) | P14: f_final | Q14: F (N) | R14: s (m) | S14: theta (rad) | T14: F (N) | U14: s (m) | V14: theta (rad) | W14: Absolute Mean Error
A15: 1.5 | B15: 0 | C15: 0 | Q15: =M15-A3 -> -0.4 | R15: =N15-B3 -> -0.06 | S15: =O15-C3 -> -1.5707963 | T15: =ABS(Q15) -> 0.4 | U15: =ABS(R15) -> 0.06 | V15: =ABS(S15) -> 1.5707963 | W15: F1 (N) | X15: s1 (m) | Y15: el1 (rad)
A16: 0 | B16: 1.5 | C16: 0 | Q16: =M16-A4 -> -0.8 | R16: =N16-B4 -> -0.06 | S16: =O16-C4 -> -1.5707963 | T16: =ABS(Q16) -> 0.8 | U16: =ABS(R16) -> 0.06 | V16: =ABS(S16) -> 1.5707963 | W16: {=AVERAGE(ABS(Q19:Q24))} -> 0.068903239 | X16: {=AVERAGE(ABS(R19:R24))} -> 0.01200375 | Y16: {=AVERAGE(ABS(S19:S24))} -> 0.027237272
A17: 0 | B17: 0 | C17: 1.5 | Q17: =M17-A5 -> -0.3 | R17: =N17-B5 -> -0.08 | S17: =O17-C5 -> -1.5707963 | T17: =ABS(Q17) -> 0.3 | U17: =ABS(R17) -> 0.08 | V17: =ABS(S17) -> 1.5707963
Q18: =M18-A6 -> -0.5 | R18: =N18-B6 -> -0.1 | S18: =O18-C6 -> -1.5707963 | T18: =ABS(Q18) -> 0.5 | U18: =ABS(R18) -> 0.1 | V18: =ABS(S18) -> 1.5707963
M19: 0.64689639 | N19: 0.11746669 | O19: 1.6043991 | P19: 0.0028122989 | Q19: =M19-A7 -> -0.05310361 | R19: =N19-B7 -> 0.017466688 | S19: =O19-C7 -> 0.03360277 | T19: =ABS(Q19) -> 0.05310361 | U19: =ABS(R19) -> 0.017466688 | V19: =ABS(S19) -> 0.03360277
C20: Trial # | D20: tau1 (N) | E20: tau2 (N) | F20: tau3 (N) | G20: Supporting Measurments w Perturbation | M20: 0.43690579 | N20: 0.1543228 | O20: 1.5941795 | P20: 0.023164011 | Q20: =M20-A8 -> 0.036905785 | R20: =N20-B8 -> -0.0056772041 | S20: =O20-C8 -> 0.02338315 | T20: =ABS(Q20) -> 0.036905785 | U20: =ABS(R20) -> 0.0056772041 | V20: =ABS(S20) -> 0.02338315
C21: 1 | D21: =D3 -> 0 | E21: =E3 -> 0 | F21: =F3 -> 0 | G21: =G3 -> -0.00043792196 | H21: =H3 -> -0.054464955 | I21: =I3 -> -0.00028745097 | J21: =J3 -> -0.021312971 | K21: =K3 -> 0.0001851581 | L21: =L3 -> 0.34822303 | M21: 0.63574976 | N21: 0.16115678 | O21: 1.5891344 | P21: 0.024396183 | Q21: =M21-A9 -> 0.035749764 | R21: =N21-B9 -> 0.0011567849 | S21: =O21-C9 -> 0.018338043 | T21: =ABS(Q21) -> 0.035749764 | U21: =ABS(R21) -> 0.0011567849 | V21: =ABS(S21) -> 0.018338043
C22: 1 | D22: 1.5 | E22: 0 | F22: 0 | G22: 0.00064009009 | H22: -0.039186381 | I22: -0.00020346988 | J22: -0.0087062009 | K22: -0.0026137903 | L22: 0.25637445 | M22: 1 | N22: 0.15559907 | O22: 1.6056567 | P22: 0.00022135648 | Q22: =M22-A10 -> 0.2 | R22: =N22-B10 -> -0.02440093 | S22: =O22-C10 -> 0.034860362 | T22: =ABS(Q22) -> 0.2 | U22: =ABS(R22) -> 0.02440093 | V22: =ABS(S22) -> 0.034860362
C23: 1 | D23: 0 | E23: 1.5 | F23: 0 | G23: -0.00044407684 | H23: -0.037313752 | I23: -0.00034176128 | J23: -0.007134032 | K23: 0.0042913072 | L23: 0.24494989 | M23: 0.32061445 | N23: 0.2 | O23: 1.5962639 | P23: 0.043153616 | Q23: =M23-A11 -> 0.020614447 | R23: =N23-B11 -> -2.5609292e-11 | S23: =O23-C11 -> 0.02546759 | T23: =ABS(Q23) -> 0.020614447 | U23: =ABS(R23) -> 2.5609292e-11 | V23: =ABS(S23) -> 0.02546759
C24: 1 | D24: 0 | E24: 0 | F24: 1.5 | G24: -0.00021057413 | H24: -0.068292372 | I24: -0.00048863201 | J24: -0.023314979 | K24: 0.0011897385 | L24: 0.44520068 | M24: 0.76704583 | N24: 0.17667911 | O24: 1.598568 | P24: 0.0058782116 | Q24: =M24-A12 -> 0.067045829 | R24: =N24-B12 -> -0.023320894 | S24: =O24-C12 -> 0.027771717 | T24: =ABS(Q24) -> 0.067045829 | U24: =ABS(R24) -> 0.023320894 | V24: =ABS(S24) -> 0.027771717
C25: 2 | D25: 0 | E25: 0 | F25: 0 | G25: =G4 -> -0.0012904059 | H25: =H4 -> -0.13089056 | I25: =I4 -> -0.00050724833 | J25: =J4 -> -0.12710035 | K25: =K4 -> 0.0033702701 | L25: =L4 -> 0.83409011 | M25: SoRoSim get_distal_value (1 Perturbations) | Q25: Distal Errors | T25: ABS Distal Errors
C26: 2 | D26: 1.5 | E26: 0 | F26: 0 | G26: 0.00030013942 | H26: -0.11715973 | I26: -0.00095811707 | J26: -0.10919022 | K26: -0.0042116493 | L26: 0.7561636 | M26: F (N) | N26: s (m) | O26: theta (rad) | P26: f_final | Q26: F (N) | R26: s (m) | S26: theta (rad) | T26: F (N) | U26: s (m) | V26: theta (rad) | W26: Absolute Mean Error
C27: 2 | D27: 0 | E27: 1.5 | F27: 0 | G27: -0.002406874 | H27: -0.11526973 | I27: 0.0001714665 | J27: -0.10486201 | K27: 0.012097605 | L27: 0.74502885 | Q27: =M27-A3 -> -0.4 | R27: =N27-B3 -> -0.06 | S27: =O27-C3 -> -1.5707963 | T27: =ABS(Q27) -> 0.4 | U27: =ABS(R27) -> 0.06 | V27: =ABS(S27) -> 1.5707963 | W27: F1 (N) | X27: s1 (m) | Y27: el1 (rad)
C28: 2 | D28: 0 | E28: 0 | F28: 1.5 | G28: -0.0012936294 | H28: -0.14033698 | I28: -0.00052493752 | J28: -0.13638584 | K28: 0.0054708421 | L28: 0.90219867 | Q28: =M28-A4 -> -0.8 | R28: =N28-B4 -> -0.06 | S28: =O28-C4 -> -1.5707963 | T28: =ABS(Q28) -> 0.8 | U28: =ABS(R28) -> 0.06 | V28: =ABS(S28) -> 1.5707963 | W28: {=AVERAGE(ABS(Q31:Q36))} -> 0.11062793 | X28: {=AVERAGE(ABS(R31:R36))} -> 0.028492893 | Y28: {=AVERAGE(ABS(S31:S36))} -> 0.097190398
C29: 3 | D29: 0 | E29: 0 | F29: 0 | G29: =G5 -> -0.00044532004 | H29: =H5 -> -0.047905073 | I29: =I5 -> -0.0001454872 | J29: =J5 -> -0.015221856 | K29: =K5 -> -0.00016181916 | L29: =L5 -> 0.26909974 | Q29: =M29-A5 -> -0.3 | R29: =N29-B5 -> -0.08 | S29: =O29-C5 -> -1.5707963 | T29: =ABS(Q29) -> 0.3 | U29: =ABS(R29) -> 0.08 | V29: =ABS(S29) -> 1.5707963
C30: 3 | D30: 1.5 | E30: 0 | F30: 0 | G30: 0.00036067312 | H30: -0.025460945 | I30: -6.9049012e-05 | J30: -0.0039108382 | K30: -0.0036880877 | L30: 0.14487913 | Q30: =M30-A6 -> -0.5 | R30: =N30-B6 -> -0.1 | S30: =O30-C6 -> -1.5707963 | T30: =ABS(Q30) -> 0.5 | U30: =ABS(R30) -> 0.1 | V30: =ABS(S30) -> 1.5707963
C31: 3 | D31: 0 | E31: 1.5 | F31: 0 | G31: -0.00058282528 | H31: -0.022284376 | I31: -0.00023676283 | J31: -0.0029866775 | K31: 0.002317287 | L31: 0.12679215 | M31: 0.59737949 | N31: 0.12607916 | O31: 1.5518258 | P31: 2.0462629e-24 | Q31: =M31-A7 -> -0.10262051 | R31: =N31-B7 -> 0.026079156 | S31: =O31-C7 -> -0.018970522 | T31: =ABS(Q31) -> 0.10262051 | U31: =ABS(R31) -> 0.026079156 | V31: =ABS(S31) -> 0.018970522
C32: 3 | D32: 0 | E32: 0 | F32: 1.5 | G32: -0.0007407252 | H32: -0.069483139 | I32: -0.00014320144 | J32: -0.020069636 | K32: 0.0015197359 | L32: 0.39420795 | M32: 0.59920053 | N32: 0.11745251 | O32: 1.4756419 | P32: 4.7535702e-18 | Q32: =M32-A8 -> 0.19920053 | R32: =N32-B8 -> -0.042547492 | S32: =O32-C8 -> -0.095154449 | T32: =ABS(Q32) -> 0.19920053 | U32: =ABS(R32) -> 0.042547492 | V32: =ABS(S32) -> 0.095154449
C33: 4 | D33: 0 | E33: 0 | F33: 0 | G33: =G6 -> -0.001170564 | H33: =H6 -> -0.094456188 | I33: =I6 -> -0.0012032345 | J33: =J6 -> -0.11118765 | K33: =K6 -> -0.0032553412 | L33: =L6 -> 0.47075057 | M33: 0.68097058 | N33: 0.15168074 | O33: 1.440367 | P33: 2.7651277e-19 | Q33: =M33-A9 -> 0.080970577 | R33: =N33-B9 -> -0.0083192593 | S33: =O33-C9 -> -0.13042931 | T33: =ABS(Q33) -> 0.080970577 | U33: =ABS(R33) -> 0.0083192593 | V33: =ABS(S33) -> 0.13042931
C34: 4 | D34: 1.5 | E34: 0 | F34: 0 | G34: 0.0005322299 | H34: -0.074818015 | I34: -0.0019516762 | J34: -0.086167961 | K34: -0.012447476 | L34: 0.37600705 | M34: 0.85136648 | N34: 0.19091597 | O34: 1.4678008 | P34: 3.3374479e-19 | Q34: =M34-A10 -> 0.051366479 | R34: =N34-B10 -> 0.010915968 | S34: =O34-C10 -> -0.10299555 | T34: =ABS(Q34) -> 0.051366479 | U34: =ABS(R34) -> 0.010915968 | V34: =ABS(S34) -> 0.10299555
C35: 4 | D35: 0 | E35: 1.5 | F35: 0 | G35: -0.0033548074 | H35: -0.071954973 | I35: 0.00056110381 | J35: -0.082473382 | K35: 0.0090126023 | L35: 0.36251399 | M35: 0.46372242 | N35: 0.13979486 | O35: 1.4405984 | P35: 2.1132132e-05 | Q35: =M35-A11 -> 0.16372242 | R35: =N35-B11 -> -0.060205141 | S35: =O35-C11 -> -0.13019794 | T35: =ABS(Q35) -> 0.16372242 | U35: =ABS(R35) -> 0.060205141 | V35: =ABS(S35) -> 0.13019794
