Workbook

Sheet Proximal Validation
A1: Ground Truth | G1: 6-Axis FT Sensor | M1: SoRoSim get_proximal_value | S1: Proximal Errors
A2: F (N) | B2: s (m) | C2: theta (rad) | D2: tau1 (N) | E2: tau2 (N) | F2: tau3 (N) | G2: Tx (Nm) | H2: Ty (Nm) | I2: Tz(Nm) | J2: Fx (N) | K2: Fy (N) | L2: Fz (N) | M2: Tx (Nm) | N2: Ty (Nm) | O2: Tz(Nm) | P2: Fx (N) | Q2: Fy (N) | R2: Fz (N) | S2: Tx (Nm) | T2: Ty (Nm) | U2: Tz(Nm) | V2: Fx (N) | W2: Fy (N) | X2: Fz (N)
A3: 0.4 | B3: 0.06 | C3: =PI()/2 -> 1.5707963 | D3: 0 | E3: 0 | F3: 0 | G3: -0.00028477586 | H3: -0.058327373 | I3: -0.0001506703 | J3: 0.0060134237 | K3: 0.0022609532 | L3: 0.37637502 | M3: 1.2756063e-29 | N3: -0.023938745 | O3: -4.9099187e-12 | P3: -0.027810769 | Q3: -8.1842762e-11 | R3: 0.39903166 | S3: =G3-M3 -> -0.00028477586 | T3: =H3-N3 -> -0.034388628 | U3: =I3-O3 -> -0.00015067029 | V3: =J3-P3 -> 0.033824193 | W3: =K3-Q3 -> 0.0022609533 | X3: =L3-R3 -> -0.022656642
A4: 0.8 | B4: 0.06 | C4: =PI()/2 -> 1.5707963 | D4: 0 | E4: 0 | F4: 0 | G4: -0.001375952 | H4: -0.12723181 | I4: -0.0015217981 | J4: -0.08266665 | K4: -0.004741177 | L4: 0.8163234 | M4: 8.6570498e-29 | N4: -0.047808943 | O4: -9.8057781e-12 | P4: -0.11091139 | Q4: -1.6249758e-10 | R4: 0.79227139 | S4: =G4-M4 -> -0.001375952 | T4: =H4-N4 -> -0.079422864 | U4: =I4-O4 -> -0.0015217981 | V4: =J4-P4 -> 0.02824474 | W4: =K4-Q4 -> -0.0047411768 | X4: =L4-R4 -> 0.024052011
A5: 0.3 | B5: 0.08 | C5: =PI()/2 -> 1.5707963 | D5: 0 | E5: 0 | F5: 0 | G5: -0.00028428674 | H5: -0.043962169 | I5: -0.00019410931 | J5: -0.014232989 | K5: 0.00080315024 | L5: 0.24872187 | M5: 7.8837026e-29 | N5: -0.023964778 | O5: -4.9152581e-12 | P5: -0.027727407 | Q5: -6.1267608e-11 | R5: 0.29871567 | S5: =G5-M5 -> -0.00028428674 | T5: =H5-N5 -> -0.019997392 | U5: =I5-O5 -> -0.0001941093 | V5: =J5-P5 -> 0.013494418 | W5: =K5-Q5 -> 0.0008031503 | X5: =L5-R5 -> -0.049993802
A6: 0.5 | B6: 0.1 | C6: =PI()/2 -> 1.5707963 | D6: 0 | E6: 0 | F6: 0 | G6: -0.00090206554 | H6: -0.095010705 | I6: -0.00031485432 | J6: -0.14170778 | K6: 0.0032724366 | L6: 0.46851912 | M6: -3.9218389e-28 | N6: -0.04970704 | O6: -1.0195084e-11 | P6: -0.1204181 | Q6: -9.9532887e-11 | R6: 0.48528144 | S6: =G6-M6 -> -0.00090206554 | T6: =H6-N6 -> -0.045303665 | U6: =I6-O6 -> -0.00031485431 | V6: =J6-P6 -> -0.02128968 | W6: =K6-Q6 -> 0.0032724367 | X6: =L6-R6 -> -0.01676232
A7: 0.7 | B7: 0.1 | C7: =PI()/2 -> 1.5707963 | D7: 0 | E7: 0 | F7: 0 | G7: -0.0013697715 | H7: -0.12989934 | I7: -0.0011154995 | J7: -0.27736902 | K7: 0.002998434 | L7: 0.62586665 | M7: -1.4743273e-29 | N7: -0.069199881 | O7: -1.4193133e-11 | P7: -0.23336075 | Q7: -1.3535853e-10 | R7: 0.65995253 | S7: =G7-M7 -> -0.0013697715 | T7: =H7-N7 -> -0.060699457 | U7: =I7-O7 -> -0.0011154995 | V7: =J7-P7 -> -0.04400827 | W7: =K7-Q7 -> 0.0029984341 | X7: =L7-R7 -> -0.034085874
A8: 0.4 | B8: 0.16 | C8: =PI()/2 -> 1.5707963 | D8: 0 | E8: 0 | F8: 0 | G8: -0.0013016209 | H8: -0.09177132 | I8: -0.00068558258 | J8: -0.18813878 | K8: 0.0035599116 | L8: 0.31649771 | M8: 1.228844e-27 | N8: -0.062523329 | O8: -1.2823749e-11 | P8: -0.19044524 | Q8: -7.2145777e-11 | R8: 0.35175315 | S8: =G8-M8 -> -0.0013016209 | T8: =H8-N8 -> -0.02924799 | U8: =I8-O8 -> -0.00068558256 | V8: =J8-P8 -> 0.0023064552 | W8: =K8-Q8 -> 0.0035599117 | X8: =L8-R8 -> -0.035255434
A9: 0.6 | B9: 0.16 | C9: =PI()/2 -> 1.5707963 | D9: 0 | E9: 0 | F9: 0 | G9: -0.0021819151 | H9: -0.13427521 | I9: -0.00028121364 | J9: -0.47822568 | K9: 0.01204087 | L9: 0.39143002 | M9: -1.1392875e-27 | N9: -0.090970656 | O9: -1.8658393e-11 | P9: -0.40318659 | Q9: -9.1135864e-11 | R9: 0.44434101 | S9: =G9-M9 -> -0.0021819151 | T9: =H9-N9 -> -0.043304557 | U9: =I9-O9 -> -0.00028121362 | V9: =J9-P9 -> -0.075039085 | W9: =K9-Q9 -> 0.01204087 | X9: =L9-R9 -> -0.052910987
A10: 0.8 | B10: 0.18 | C10: =PI()/2 -> 1.5707963 | D10: 0 | E10: 0 | F10: 0 | G10: -0.0010585423 | H10: -0.13548036 | I10: -0.0012497484 | J10: -0.72550738 | K10: 0.029684354 | L10: 0.1316857 | M10: -9.0492831e-27 | N10: -0.12381202 | O10: -2.5394269e-11 | P10: -0.74838044 | Q10: -5.798412e-11 | R10: 0.28270673 | S10: =G10-M10 -> -0.0010585423 | T10: =H10-N10 -> -0.011668344 | U10: =I10-O10 -> -0.0012497484 | V10: =J10-P10 -> 0.022873065 | W10: =K10-Q10 -> 0.029684354 | X10: =L10-R10 -> -0.15102103
A11: 0.3 | B11: 0.2 | C11: =PI()/2 -> 1.5707963 | D11: 0 | E11: 0 | F11: 0 | G11: -0.00088630803 | H11: -0.067533724 | I11: -0.00047554963 | J11: -0.16650236 | K11: 0.002737375 | L11: 0.18086977 | M11: -5.1505969e-29 | N11: -0.057439839 | O11: -1.1781108e-11 | P11: -0.16082531 | Q11: -5.1942303e-11 | R11: 0.25324931 | S11: =G11-M11 -> -0.00088630803 | T11: =H11-N11 -> -0.010093885 | U11: =I11-O11 -> -0.00047554962 | V11: =J11-P11 -> -0.0056770493 | W11: =K11-Q11 -> 0.002737375 | X11: =L11-R11 -> -0.072379542
A12: 0.7 | B12: 0.2 | C12: =PI()/2 -> 1.5707963 | D12: 0 | E12: 0 | F12: 0 | G12: -0.0027598871 | H12: -0.12722152 | I12: -0.00088058261 | J12: -0.6718719 | K12: 0.017920591 | L12: 0.066542283 | M12: -7.8162421e-27 | N12: -0.11696093 | O12: -2.3989088e-11 | P12: -0.66679933 | Q12: -4.3691604e-11 | R12: 0.2130223 | S12: =G12-M12 -> -0.0027598871 | T12: =H12-N12 -> -0.010260592 | U12: =I12-O12 -> -0.00088058258 | V12: =J12-P12 -> -0.0050725717 | W12: =K12-Q12 -> 0.017920591 | X12: =L12-R12 -> -0.14648002

Sheet Distal Vali (0N perturb)
A1: Ground Truth | G1: 6-Axis FT Sensor | M1: SoRoSim get_distal_value | Q1: Distal Errors | T1: ABS Distal Errors
A2: F (N) | B2: s (m) | C2: theta (rad) | D2: tau1 (N) | E2: tau2 (N) | F2: tau3 (N) | G2: Tx (Nm) | H2: Ty (Nm) | I2: Tz(Nm) | J2: Fx (N) | K2: Fy (N) | L2: Fz (N) | M2: F (N) | N2: s (m) | O2: theta (rad) | P2: f_final | Q2: F (N) | R2: s (m) | S2: theta (rad) | T2: F (N) | U2: s (m) | V2: theta (rad) | W2: Absolute Mean Error
A3: ='Proximal Validation'!A3 -> 0.4 | B3: ='Proximal Validation'!B3 -> 0.06 | C3: ='Proximal Validation'!C3 -> 1.5707963 | D3: ='Proximal Validation'!D3 -> 0 | E3: ='Proximal Validation'!E3 -> 0 | F3: ='Proximal Validation'!F3 -> 0 | G3: ='Proximal Validation'!G3 -> -0.00028477586 | H3: ='Proximal Validation'!H3 -> -0.058327373 | ... L3: ='Proximal Validation'!L3 -> 0.37637502 | M3: 0.32075783 | N3: 0.074003821 | O3: 1.5853023 | P3: 2.6149565e-06 | Q3: =M3-A3 -> -0.079242172 | R3: =N3-B3 -> 0.014003821 | S3: =O3-C3 -> 0.014505996 | T3: =ABS(Q3) -> 0.079242172 | U3: =ABS(R3) -> 0.014003821 | V3: =ABS(S3) -> 0.014505996 | W3: F1 (N) | X3: s1 (m) | Y3: el1 (rad)
A4: ='Proximal Validation'!A4 -> 0.8 | B4: ='Proximal Validation'!B4 -> 0.06 | C4: ='Proximal Validation'!C4 -> 1.5707963 | D4: ='Proximal Validation'!D4 -> 0 | E4: ='Proximal Validation'!E4 -> 0 | F4: ='Proximal Validation'!F4 -> 0 | G4: ='Proximal Validation'!G4 -> -0.001375952 | H4: ='Proximal Validation'!H4 -> -0.12723181 | ... L4: ='Proximal Validation'!L4 -> 0.8163234 | M4: 0.69921488 | N4: 0.073995548 | O4: 1.5911626 | P4: 5.8117386e-06 | Q4: =M4-A4 -> -0.10078512 | R4: =N4-B4 -> 0.013995548 | S4: =O4-C4 -> 0.020366261 | T4: =ABS(Q4) -> 0.10078512 | U4: =ABS(R4) -> 0.013995548 | V4: =ABS(S4) -> 0.020366261 | W4: {=AVERAGE(ABS(Q3:Q12))} -> 0.12164731 | X4: {=AVERAGE(ABS(R3:R12))} -> 0.031777696 | Y4: {=AVERAGE(ABS(S3:S12))} -> 0.017360683
A5: ='Proximal Validation'!A5 -> 0.3 | B5: ='Proximal Validation'!B5 -> 0.08 | C5: ='Proximal Validation'!C5 -> 1.5707963 | D5: ='Proximal Validation'!D5 -> 0 | E5: ='Proximal Validation'!E5 -> 0 | F5: ='Proximal Validation'!F5 -> 0 | G5: ='Proximal Validation'!G5 -> -0.00028428674 | H5: ='Proximal Validation'!H5 -> -0.043962169 | ... L5: ='Proximal Validation'!L5 -> 0.24872187 | M5: 0.28895388 | N5: 0.07421784 | O5: 1.5831417 | P5: 1.4716481e-07 | Q5: =M5-A5 -> -0.011046119 | R5: =N5-B5 -> -0.0057821602 | S5: =O5-C5 -> 0.01234539 | T5: =ABS(Q5) -> 0.011046119 | U5: =ABS(R5) -> 0.0057821602 | V5: =ABS(S5) -> 0.01234539
A6: ='Proximal Validation'!A6 -> 0.5 | B6: ='Proximal Validation'!B6 -> 0.1 | C6: ='Proximal Validation'!C6 -> 1.5707963 | D6: ='Proximal Validation'!D6 -> 0 | E6: ='Proximal Validation'!E6 -> 0 | F6: ='Proximal Validation'!F6 -> 0 | G6: ='Proximal Validation'!G6 -> -0.00090206554 | H6: ='Proximal Validation'!H6 -> -0.095010705 | ... L6: ='Proximal Validation'!L6 -> 0.46851912 | M6: 0.45239181 | N6: 0.11835714 | O6: 1.5823274 | P6: 4.4460842e-08 | Q6: =M6-A6 -> -0.047608189 | R6: =N6-B6 -> 0.01835714 | S6: =O6-C6 -> 0.011531044 | T6: =ABS(Q6) -> 0.047608189 | U6: =ABS(R6) -> 0.01835714 | V6: =ABS(S6) -> 0.011531044
A7: ='Proximal Validation'!A7 -> 0.7 | B7: ='Proximal Validation'!B7 -> 0.1 | C7: ='Proximal Validation'!C7 -> 1.5707963 | D7: ='Proximal Validation'!D7 -> 0 | E7: ='Proximal Validation'!E7 -> 0 | F7: ='Proximal Validation'!F7 -> 0 | G7: ='Proximal Validation'!G7 -> -0.0013697715 | H7: ='Proximal Validation'!H7 -> -0.12989934 | ... L7: ='Proximal Validation'!L7 -> 0.62586665 | M7: 0.63538729 | N7: 0.11895321 | O7: 1.5896242 | P7: 2.239848e-07 | Q7: =M7-A7 -> -0.064612711 | R7: =N7-B7 -> 0.018953208 | S7: =O7-C7 -> 0.018827917 | T7: =ABS(Q7) -> 0.064612711 | U7: =ABS(R7) -> 0.018953208 | V7: =ABS(S7) -> 0.018827917
A8: ='Proximal Validation'!A8 -> 0.4 | B8: ='Proximal Validation'!B8 -> 0.16 | C8: ='Proximal Validation'!C8 -> 1.5707963 | D8: ='Proximal Validation'!D8 -> 0 | E8: ='Proximal Validation'!E8 -> 0 | F8: ='Proximal Validation'!F8 -> 0 | G8: ='Proximal Validation'!G8 -> -0.0013016209 | H8: ='Proximal Validation'!H8 -> -0.09177132 | ... L8: ='Proximal Validation'!L8 -> 0.31649771 | M8: 0.84373583 | N8: 0.075210385 | O8: 1.5866906 | P8: 4.1836825e-08 | Q8: =M8-A8 -> 0.44373583 | R8: =N8-B8 -> -0.084789615 | S8: =O8-C8 -> 0.015894226 | T8: =ABS(Q8) -> 0.44373583 | U8: =ABS(R8) -> 0.084789615 | V8: =ABS(S8) -> 0.015894226
A9: ='Proximal Validation'!A9 -> 0.6 | B9: ='Proximal Validation'!B9 -> 0.16 | C9: ='Proximal Validation'!C9 -> 1.5707963 | D9: ='Proximal Validation'!D9 -> 0 | E9: ='Proximal Validation'!E9 -> 0 | F9: ='Proximal Validation'!F9 -> 0 | G9: ='Proximal Validation'!G9 -> -0.0021819151 | H9: ='Proximal Validation'!H9 -> -0.13427521 | ... L9: ='Proximal Validation'!L9 -> 0.39143002 | M9: 0.71228992 | N9: 0.14679798 | O9: 1.5845758 | P9: 7.1171167e-12 | Q9: =M9-A9 -> 0.11228992 | R9: =N9-B9 -> -0.013202023 | S9: =O9-C9 -> 0.013779445 | T9: =ABS(Q9) -> 0.11228992 | U9: =ABS(R9) -> 0.013202023 | V9: =ABS(S9) -> 0.013779445
A10: ='Proximal Validation'!A10 -> 0.8 | B10: ='Proximal Validation'!B10 -> 0.18 | C10: ='Proximal Validation'!C10 -> 1.5707963 | D10: ='Proximal Validation'!D10 -> 0 | E10: ='Proximal Validation'!E10 -> 0 | F10: ='Proximal Validation'!F10 -> 0 | G10: ='Proximal Validation'!G10 -> -0.0010585423 | H10: ='Proximal Validation'!H10 -> -0.13548036 | ... L10: ='Proximal Validation'!L10 -> 0.1316857 | M10: 0.86927639 | N10: 0.15651368 | O10: 1.6025044 | P10: 3.654877e-07 | Q10: =M10-A10 -> 0.069276391 | R10: =N10-B10 -> -0.023486317 | S10: =O10-C10 -> 0.03170807 | T10: =ABS(Q10) -> 0.069276391 | U10: =ABS(R10) -> 0.023486317 | V10: =ABS(S10) -> 0.03170807
A11: ='Proximal Validation'!A11 -> 0.3 | B11: ='Proximal Validation'!B11 -> 0.2 | C11: ='Proximal Validation'!C11 -> 1.5707963 | D11: ='Proximal Validation'!D11 -> 0 | E11: ='Proximal Validation'!E11 -> 0 | F11: ='Proximal Validation'!F11 -> 0 | G11: ='Proximal Validation'!G11 -> -0.00088630803 | H11: ='Proximal Validation'!H11 -> -0.067533724 | ... L11: ='Proximal Validation'!L11 -> 0.18086977 | M11: 0.45012259 | N11: 0.11838762 | O11: 1.5848804 | P11: 2.5820283e-06 | Q11: =M11-A11 -> 0.15012259 | R11: =N11-B11 -> -0.081612384 | S11: =O11-C11 -> 0.014084027 | T11: =ABS(Q11) -> 0.15012259 | U11: =ABS(R11) -> 0.081612384 | V11: =ABS(S11) -> 0.014084027
A12: ='Proximal Validation'!A12 -> 0.7 | B12: ='Proximal Validation'!B12 -> 0.2 | C12: ='Proximal Validation'!C12 -> 1.5707963 | D12: ='Proximal Validation'!D12 -> 0 | E12: ='Proximal Validation'!E12 -> 0 | F12: ='Proximal Validation'!F12 -> 0 | G12: ='Proximal Validation'!G12 -> -0.0027598871 | H12: ='Proximal Validation'!H12 -> -0.12722152 | ... L12: ='Proximal Validation'!L12 -> 0.066542283 | M12: 0.83775405 | N12: 0.15640526 | O12: 1.5913608 | P12: 1.8885843e-06 | Q12: =M12-A12 -> 0.13775405 | R12: =N12-B12 -> -0.043594738 | S12: =O12-C12 -> 0.020564454 | T12: =ABS(Q12) -> 0.13775405 | U12: =ABS(R12) -> 0.043594738 | V12: =ABS(S12) -> 0.020564454

Sheet Distal Vali (0N pert 6 prox)
A1: Ground Truth | G1: 6-Axis FT Sensor | M1: SoRoSim get_distal_value | Q1: Distal Errors | T1: ABS Distal Errors
A2: F (N) | B2: s (m) | C2: theta (rad) | D2: tau1 (N) | E2: tau2 (N) | F2: tau3 (N) | G2: Tx (Nm) | H2: Ty (Nm) | I2: Tz(Nm) | J2: Fx (N) | K2: Fy (N) | L2: Fz (N) | M2: F (N) | N2: s (m) | O2: theta (rad) | P2: f_final | Q2: F (N) | R2: s (m) | S2: theta (rad) | T2: F (N) | U2: s (m) | V2: theta (rad) | W2: Absolute Mean Error
A3: ='Proximal Validation'!A3 -> 0.4 | B3: ='Proximal Validation'!B3 -> 0.06 | C3: ='Proximal Validation'!C3 -> 1.5707963 | D3: ='Proximal Validation'!D3 -> 0 | E3: ='Proximal Validation'!E3 -> 0 | F3: ='Proximal Validation'!F3 -> 0 | G3: ='Proximal Validation'!G3 -> -0.00028477586 | H3: ='Proximal Validation'!H3 -> -0.058327373 | ... L3: ='Proximal Validation'!L3 -> 0.37637502 | Q3: =M3-A3 -> -0.4 | R3: =N3-B3 -> -0.06 | S3: =O3-C3 -> -1.5707963 | T3: =ABS(Q3) -> 0.4 | U3: =ABS(R3) -> 0.06 | V3: =ABS(S3) -> 1.5707963 | W3: F1 (N) | X3: s1 (m) | Y3: el1 (rad)
A4: ='Proximal Validation'!A4 -> 0.8 | B4: ='Proximal Validation'!B4 -> 0.06 | C4: ='Proximal Validation'!C4 -> 1.5707963 | D4: ='Proximal Validation'!D4 -> 0 | E4: ='Proximal Validation'!E4 -> 0 | F4: ='Proximal Validation'!F4 -> 0 | G4: ='Proximal Validation'!G4 -> -0.001375952 | H4: ='Proximal Validation'!H4 -> -0.12723181 | ... L4: ='Proximal Validation'!L4 -> 0.8163234 | Q4: =M4-A4 -> -0.8 | R4: =N4-B4 -> -0.06 | S4: =O4-C4 -> -1.5707963 | T4: =ABS(Q4) -> 0.8 | U4: =ABS(R4) -> 0.06 | V4: =ABS(S4) -> 1.5707963 | W4: {=AVERAGE(ABS(Q7:Q12))} -> 0.03173097 | X4: {=AVERAGE(ABS(R7:R12))} -> 0.0097509645 | Y4: {=AVERAGE(ABS(S7:S12))} -> 0.013980338
A5: ='Proximal Validation'!A5 -> 0.3 | B5: ='Proximal Validation'!B5 -> 0.08 | C5: ='Proximal Validation'!C5 -> 1.5707963 | D5: ='Proximal Validation'!D5 -> 0 | E5: ='Proximal Validation'!E5 -> 0 | F5: ='Proximal Validation'!F5 -> 0 | G5: ='Proximal Validation'!G5 -> -0.00028428674 | H5: ='Proximal Validation'!H5 -> -0.043962169 | ... L5: ='Proximal Validation'!L5 -> 0.24872187 | Q5: =M5-A5 -> -0.3 | R5: =N5-B5 -> -0.08 | S5: =O5-C5 -> -1.5707963 | T5: =ABS(Q5) -> 0.3 | U5: =ABS(R5) -> 0.08 | V5: =ABS(S5) -> 1.5707963
A6: ='Proximal Validation'!A6 -> 0.5 | B6: ='Proximal Validation'!B6 -> 0.1 | C6: ='Proximal Validation'!C6 -> 1.5707963 | D6: ='Proximal Validation'!D6 -> 0 | E6: ='Proximal Validation'!E6 -> 0 | F6: ='Proximal Validation'!F6 -> 0 | G6: ='Proximal Validation'!G6 -> -0.00090206554 | H6: ='Proximal Validation'!H6 -> -0.095010705 | ... L6: ='Proximal Validation'!L6 -> 0.46851912 | Q6: =M6-A6 -> -0.5 | R6: =N6-B6 -> -0.1 | S6: =O6-C6 -> -1.5707963 | T6: =ABS(Q6) -> 0.5 | U6: =ABS(R6) -> 0.1 | V6: =ABS(S6) -> 1.5707963
A7: ='Proximal Validation'!A7 -> 0.7 | B7: ='Proximal Validation'!B7 -> 0.1 | C7: ='Proximal Validation'!C7 -> 1.5707963 | D7: ='Proximal Validation'!D7 -> 0 | E7: ='Proximal Validation'!E7 -> 0 | F7: ='Proximal Validation'!F7 -> 0 | G7: ='Proximal Validation'!G7 -> -0.0013697715 | H7: ='Proximal Validation'!H7 -> -0.12989934 | ... L7: ='Proximal Validation'!L7 -> 0.62586665 | M7: 0.68118703 | N7: 0.1106944 | O7: 1.5797576 | P7: 0.00041736093 | Q7: =M7-A7 -> -0.018812973 | R7: =N7-B7 -> 0.010694397 | S7: =O7-C7 -> 0.0089612851 | T7: =ABS(Q7) -> 0.018812973 | U7: =ABS(R7) -> 0.010694397 | V7: =ABS(S7) -> 0.0089612851
A8: ='Proximal Validation'!A8 -> 0.4 | B8: ='Proximal Validation'!B8 -> 0.16 | C8: ='Proximal Validation'!C8 -> 1.5707963 | D8: ='Proximal Validation'!D8 -> 0 | E8: ='Proximal Validation'!E8 -> 0 | F8: ='Proximal Validation'!F8 -> 0 | G8: ='Proximal Validation'!G8 -> -0.0013016209 | H8: ='Proximal Validation'!H8 -> -0.09177132 | ... L8: ='Proximal Validation'!L8 -> 0.31649771 | M8: 0.37093282 | N8: 0.17455943 | O8: 1.581239 | P8: 0.00026759737 | Q8: =M8-A8 -> -0.029067175 | R8: =N8-B8 -> 0.014559427 | S8: =O8-C8 -> 0.010442714 | T8: =ABS(Q8) -> 0.029067175 | U8: =ABS(R8) -> 0.014559427 | V8: =ABS(S8) -> 0.010442714
A9: ='Proximal Validation'!A9 -> 0.6 | B9: ='Proximal Validation'!B9 -> 0.16 | C9: ='Proximal Validation'!C9 -> 1.5707963 | D9: ='Proximal Validation'!D9 -> 0 | E9: ='Proximal Validation'!E9 -> 0 | F9: ='Proximal Validation'!F9 -> 0 | G9: ='Proximal Validation'!G9 -> -0.0021819151 | H9: ='Proximal Validation'!H9 -> -0.13427521 | ... L9: ='Proximal Validation'!L9 -> 0.39143002 | M9: 0.61813795 | N9: 0.17325196 | O9: 1.5785591 | P9: 0.00073911051 | Q9: =M9-A9 -> 0.018137954 | R9: =N9-B9 -> 0.013251963 | S9: =O9-C9 -> 0.0077627707 | T9: =ABS(Q9) -> 0.018137954 | U9: =ABS(R9) -> 0.013251963 | V9: =ABS(S9) -> 0.0077627707
A10: ='Proximal Validation'!A10 -> 0.8 | B10: ='Proximal Validation'!B10 -> 0.18 | C10: ='Proximal Validation'!C10 -> 1.5707963 | D10: ='Proximal Validation'!D10 -> 0 | E10: ='Proximal Validation'!E10 -> 0 | F10: ='Proximal Validation'!F10 -> 0 | G10: ='Proximal Validation'!G10 -> -0.0010585423 | H10: ='Proximal Validation'!H10 -> -0.13548036 | ... L10: ='Proximal Validation'!L10 -> 0.1316857 | M10: 0.76314101 | N10: 0.2 | O10: 1.5990499 | P10: 0.0024474852 | Q10: =M10-A10 -> -0.036858987 | R10: =N10-B10 -> 0.02 | S10: =O10-C10 -> 0.028253589 | T10: =ABS(Q10) -> 0.036858987 | U10: =ABS(R10) -> 0.02 | V10: =ABS(S10) -> 0.028253589
A11: ='Proximal Validation'!A11 -> 0.3 | B11: ='Proximal Validation'!B11 -> 0.2 | C11: ='Proximal Validation'!C11 -> 1.5707963 | D11: ='Proximal Validation'!D11 -> 0 | E11: ='Proximal Validation'!E11 -> 0 | F11: ='Proximal Validation'!F11 -> 0 | G11: ='Proximal Validation'!G11 -> -0.00088630803 | H11: ='Proximal Validation'!H11 -> -0.067533724 | ... L11: ='Proximal Validation'!L11 -> 0.18086977 | M11: 0.26631059 | N11: 0.2 | O11: 1.5808428 | P11: 0.0043007979 | Q11: =M11-A11 -> -0.033689409 | R11: =N11-B11 -> -8.2973628e-12 | S11: =O11-C11 -> 0.010046523 | T11: =ABS(Q11) -> 0.033689409 | U11: =ABS(R11) -> 8.2973628e-12 | V11: =ABS(S11) -> 0.010046523
A12: ='Proximal Validation'!A12 -> 0.7 | B12: ='Proximal Validation'!B12 -> 0.2 | C12: ='Proximal Validation'!C12 -> 1.5707963 | D12: ='Proximal Validation'!D12 -> 0 | E12: ='Proximal Validation'!E12 -> 0 | F12: ='Proximal Validation'!F12 -> 0 | G12: ='Proximal Validation'!G12 -> -0.0027598871 | H12: ='Proximal Validation'!H12 -> -0.12722152 | ... L12: ='Proximal Validation'!L12 -> 0.066542283 | M12: 0.75381932 | N12: 0.2 | O12: 1.5892115 | P12: 0.015559916 | Q12: =M12-A12 -> 0.05381932 | R12: =N12-B12 -> -2.0397573e-13 | S12: =O12-C12 -> 0.018415148 | T12: =ABS(Q12) -> 0.05381932 | U12: =ABS(R12) -> 2.0397573e-13 | V12: =ABS(S12) -> 0.018415148

Sheet Distal Vali (0.5N perturb)
A1: Ground Truth | G1: 6-Axis FT Sensor | M1: SoRoSim get_distal_value (lambda = 0.5) | Q1: Distal Errors | T1: ABS Distal Errors
A2: F (N) | B2: s (m) | C2: theta (rad) | D2: tau1 (N) | E2: tau2 (N) | F2: tau3 (N) | G2: Tx (Nm) | H2: Ty (Nm) | I2: Tz(Nm) | J2: Fx (N) | K2: Fy (N) | L2: Fz (N) | M2: F (N) | N2: s (m) | O2: theta (rad) | P2: f_final | Q2: F (N) | R2: s (m) | S2: theta (rad) | T2: F (N) | U2: s (m) | V2: theta (rad) | W2: Absolute Mean Error
A3: ='Proximal Validation'!A3 -> 0.4 | B3: ='Proximal Validation'!B3 -> 0.06 | C3: ='Proximal Validation'!C3 -> 1.5707963 | D3: ='Proximal Validation'!D3 -> 0 | E3: ='Proximal Validation'!E3 -> 0 | F3: ='Proximal Validation'!F3 -> 0 | G3: ='Proximal Validation'!G3 -> -0.00028477586 | H3: ='Proximal Validation'!H3 -> -0.058327373 | ... L3: ='Proximal Validation'!L3 -> 0.37637502 | M3: 0.41842606 | N3: 0.072239827 | O3: 1.5755253 | P3: 0.00023105174 | Q3: =M3-A3 -> 0.018426055 | R3: =N3-B3 -> 0.012239827 | S3: =O3-C3 -> 0.0047290225 | T3: =ABS(Q3) -> 0.018426055 | U3: =ABS(R3) -> 0.012239827 | V3: =ABS(S3) -> 0.0047290225 | W3: F1 (N) | X3: s1 (m) | Y3: el1 (rad)
A4: ='Proximal Validation'!A4 -> 0.8 | B4: ='Proximal Validation'!B4 -> 0.06 | C4: ='Proximal Validation'!C4 -> 1.5707963 | D4: ='Proximal Validation'!D4 -> 0 | E4: ='Proximal Validation'!E4 -> 0 | F4: ='Proximal Validation'!F4 -> 0 | G4: ='Proximal Validation'!G4 -> -0.001375952 | H4: ='Proximal Validation'!H4 -> -0.12723181 | ... L4: ='Proximal Validation'!L4 -> 0.8163234 | M4: 0.75391514 | N4: 0.073114233 | O4: 1.5947577 | P4: 0.00060886897 | Q4: =M4-A4 -> -0.046084859 | R4: =N4-B4 -> 0.013114233 | S4: =O4-C4 -> 0.023961326 | T4: =ABS(Q4) -> 0.046084859 | U4: =ABS(R4) -> 0.013114233 | V4: =ABS(S4) -> 0.023961326 | W4: {=AVERAGE(ABS(Q3:Q12))} -> 0.045169067 | X4: {=AVERAGE(ABS(R3:R12))} -> 0.015924434 | Y4: {=AVERAGE(ABS(S3:S12))} -> 0.024517619
A5: ='Proximal Validation'!A5 -> 0.3 | B5: ='Proximal Validation'!B5 -> 0.08 | C5: ='Proximal Validation'!C5 -> 1.5707963 | D5: ='Proximal Validation'!D5 -> 0 | E5: ='Proximal Validation'!E5 -> 0 | F5: ='Proximal Validation'!F5 -> 0 | G5: ='Proximal Validation'!G5 -> -0.00028428674 | H5: ='Proximal Validation'!H5 -> -0.043962169 | ... L5: ='Proximal Validation'!L5 -> 0.24872187 | M5: 0.29191364 | N5: 0.087335291 | O5: 1.5874002 | P5: 4.9943127e-05 | Q5: =M5-A5 -> -0.0080863632 | R5: =N5-B5 -> 0.0073352909 | S5: =O5-C5 -> 0.016603891 | T5: =ABS(Q5) -> 0.0080863632 | U5: =ABS(R5) -> 0.0073352909 | V5: =ABS(S5) -> 0.016603891
A6: ='Proximal Validation'!A6 -> 0.5 | B6: ='Proximal Validation'!B6 -> 0.1 | C6: ='Proximal Validation'!C6 -> 1.5707963 | D6: ='Proximal Validation'!D6 -> 0 | E6: ='Proximal Validation'!E6 -> 0 | F6: ='Proximal Validation'!F6 -> 0 | G6: ='Proximal Validation'!G6 -> -0.00090206554 | H6: ='Proximal Validation'!H6 -> -0.095010705 | ... L6: ='Proximal Validation'!L6 -> 0.46851912 | M6: 0.50454258 | N6: 0.10805125 | O6: 1.5698912 | P6: 0.00012594867 | Q6: =M6-A6 -> 0.0045425848 | R6: =N6-B6 -> 0.0080512523 | S6: =O6-C6 -> -0.00090510907 | T6: =ABS(Q6) -> 0.0045425848 | U6: =ABS(R6) -> 0.0080512523 | V6: =ABS(S6) -> 0.00090510907
A7: ='Proximal Validation'!A7 -> 0.7 | B7: ='Proximal Validation'!B7 -> 0.1 | C7: ='Proximal Validation'!C7 -> 1.5707963 | D7: ='Proximal Validation'!D7 -> 0 | E7: ='Proximal Validation'!E7 -> 0 | F7: ='Proximal Validation'!F7 -> 0 | G7: ='Proximal Validation'!G7 -> -0.0013697715 | H7: ='Proximal Validation'!H7 -> -0.12989934 | ... L7: ='Proximal Validation'!L7 -> 0.62586665 | M7: 0.74900663 | N7: 0.10419115 | O7: 1.5883947 | P7: 0.00022753188 | Q7: =M7-A7 -> 0.049006632 | R7: =N7-B7 -> 0.004191146 | S7: =O7-C7 -> 0.017598344 | T7: =ABS(Q7) -> 0.049006632 | U7: =ABS(R7) -> 0.004191146 | V7: =ABS(S7) -> 0.017598344
A8: ='Proximal Validation'!A8 -> 0.4 | B8: ='Proximal Validation'!B8 -> 0.16 | C8: ='Proximal Validation'!C8 -> 1.5707963 | D8: ='Proximal Validation'!D8 -> 0 | E8: ='Proximal Validation'!E8 -> 0 | F8: ='Proximal Validation'!F8 -> 0 | G8: ='Proximal Validation'!G8 -> -0.0013016209 | H8: ='Proximal Validation'!H8 -> -0.09177132 | ... L8: ='Proximal Validation'!L8 -> 0.31649771 | M8: 0.34959329 | N8: 0.15969012 | O8: 1.545772 | P8: 0.00054004468 | Q8: =M8-A8 -> -0.050406712 | R8: =N8-B8 -> -0.00030988069 | S8: =O8-C8 -> -0.025024305 | T8: =ABS(Q8) -> 0.050406712 | U8: =ABS(R8) -> 0.00030988069 | V8: =ABS(S8) -> 0.025024305
A9: ='Proximal Validation'!A9 -> 0.6 | B9: ='Proximal Validation'!B9 -> 0.16 | C9: ='Proximal Validation'!C9 -> 1.5707963 | D9: ='Proximal Validation'!D9 -> 0 | E9: ='Proximal Validation'!E9 -> 0 | F9: ='Proximal Validation'!F9 -> 0 | G9: ='Proximal Validation'!G9 -> -0.0021819151 | H9: ='Proximal Validation'!H9 -> -0.13427521 | ... L9: ='Proximal Validation'!L9 -> 0.39143002 | M9: 0.71265373 | N9: 0.13362845 | O9: 1.5644185 | P9: 0.00031582003 | Q9: =M9-A9 -> 0.11265373 | R9: =N9-B9 -> -0.026371547 | S9: =O9-C9 -> -0.0063778626 | T9: =ABS(Q9) -> 0.11265373 | U9: =ABS(R9) -> 0.026371547 | V9: =ABS(S9) -> 0.0063778626
A10: ='Proximal Validation'!A10 -> 0.8 | B10: ='Proximal Validation'!B10 -> 0.18 | C10: ='Proximal Validation'!C10 -> 1.5707963 | D10: ='Proximal Validation'!D10 -> 0 | E10: ='Proximal Validation'!E10 -> 0 | F10: ='Proximal Validation'!F10 -> 0 | G10: ='Proximal Validation'!G10 -> -0.0010585423 | H10: ='Proximal Validation'!H10 -> -0.13548036 | ... L10: ='Proximal Validation'!L10 -> 0.1316857 | M10: 0.80383407 | N10: 0.14965332 | O10: 1.6227512 | P10: 0.00033327362 | Q10: =M10-A10 -> 0.0038340683 | R10: =N10-B10 -> -0.030346677 | S10: =O10-C10 -> 0.051954841 | T10: =ABS(Q10) -> 0.0038340683 | U10: =ABS(R10) -> 0.030346677 | V10: =ABS(S10) -> 0.051954841
A11: ='Proximal Validation'!A11 -> 0.3 | B11: ='Proximal Validation'!B11 -> 0.2 | C11: ='Proximal Validation'!C11 -> 1.5707963 | D11: ='Proximal Validation'!D11 -> 0 | E11: ='Proximal Validation'!E11 -> 0 | F11: ='Proximal Validation'!F11 -> 0 | G11: ='Proximal Validation'!G11 -> -0.00088630803 | H11: ='Proximal Validation'!H11 -> -0.067533724 | ... L11: ='Proximal Validation'!L11 -> 0.18086977 | M11: 0.28964087 | N11: 0.2 | O11: 1.5720494 | P11: 0.00080054399 | Q11: =M11-A11 -> -0.010359126 | R11: =N11-B11 -> -1.1518564e-13 | S11: =O11-C11 -> 0.0012531056 | T11: =ABS(Q11) -> 0.010359126 | U11: =ABS(R11) -> 1.1518564e-13 | V11: =ABS(S11) -> 0.0012531056
A12: ='Proximal Validation'!A12 -> 0.7 | B12: ='Proximal Validation'!B12 -> 0.2 | C12: ='Proximal Validation'!C12 -> 1.5707963 | D12: ='Proximal Validation'!D12 -> 0 | E12: ='Proximal Validation'!E12 -> 0 | F12: ='Proximal Validation'!F12 -> 0 | G12: ='Proximal Validation'!G12 -> -0.0027598871 | H12: ='Proximal Validation'!H12 -> -0.12722152 | ... L12: ='Proximal Validation'!L12 -> 0.066542283 | M12: 0.84829055 | N12: 0.14271552 | O12: 1.6675647 | P12: 0.00047704038 | Q12: =M12-A12 -> 0.14829055 | R12: =N12-B12 -> -0.057284482 | S12: =O12-C12 -> 0.096768381 | T12: =ABS(Q12) -> 0.14829055 | U12: =ABS(R12) -> 0.057284482 | V12: =ABS(S12) -> 0.096768381
A14: Perturbation
A15: 0.5 | B15: 0 | C15: 0
A16: 0 | B16: 0.5 | C16: 0
A17: 0 | B17: 0 | C17: 0.5
C20: Trial # | D20: tau1 (N) | E20: tau2 (N) | F20: tau3 (N) | G20: Supporting Measurments w Perturbation
C21: 1 | D21: =D3 -> 0 | E21: =E3 -> 0 | F21: =F3 -> 0 | G21: =G3 -> -0.00028477586 | H21: =H3 -> -0.058327373 | I21: =I3 -> -0.0001506703 | J21: =J3 -> 0.0060134237 | K21: =K3 -> 0.0022609532 | L21: =L3 -> 0.37637502
C22: 1 | D22: =A15+D$21 -> 0.5 | E22: =B15+E$21 -> 0 | F22: =C15+F$21 -> 0 | G22: 0.00023011875 | H22: -0.053271987 | I22: -0.00020681828 | J22: 0.00989193 | K22: 0.00086640567 | L22: 0.34659576
C23: 1 | D23: =A16+D$21 -> 0 | E23: =B16+E$21 -> 0.5 | F23: =C16+F$21 -> 0 | G23: -0.00042876659 | H23: -0.052273326 | I23: -1.9059516e-05 | J23: 0.014312151 | K23: 0.0057477541 | L23: 0.34222141
C24: 1 | D24: =A17+D$21 -> 0 | E24: =B17+E$21 -> 0 | F24: =C17+F$21 -> 0.5 | G24: -0.00020206731 | H24: -0.063044883 | I24: -0.00014381617 | J24: 0.016669281 | K24: 0.0042362064 | L24: 0.41187611
C25: 2 | D25: 0 | E25: 0 | F25: 0 | G25: =G4 -> -0.001375952 | H25: =H4 -> -0.12723181 | I25: =I4 -> -0.0015217981 | J25: =J4 -> -0.08266665 | K25: =K4 -> -0.004741177 | L25: =L4 -> 0.8163234
C26: 2 | D26: 0.5 | E26: 0 | F26: 0 | G26: -0.00064265868 | H26: -0.12265829 | I26: -0.0017822726 | J26: -0.077889577 | K26: -0.0083601624 | L26: 0.7912792
C27: 2 | D27: 0 | E27: 0.5 | F27: 0 | G27: -0.0020508959 | H27: -0.12170491 | I27: -0.0010077952 | J27: -0.072200365 | K27: 0.00047361106 | L27: 0.78733724
C28: 2 | D28: 0 | E28: 0 | F28: 0.5 | G28: -0.0015927674 | H28: -0.13021459 | I28: -0.0014390036 | J28: -0.081000239 | K28: -0.0031956732 | L28: 0.84179682
C29: 3 | D29: 0 | E29: 0 | F29: 0 | G29: =G5 -> -0.00028428674 | H29: =H5 -> -0.043962169 | I29: =I5 -> -0.00019410931 | J29: =J5 -> -0.014232989 | K29: =K5 -> 0.00080315024 | L29: =L5 -> 0.24872187
C30: 3 | D30: 0.5 | E30: 0 | F30: 0 | G30: 0.00014990487 | H30: -0.037795465 | I30: -0.00027046184 | J30: -0.0091095464 | K30: -0.0013357587 | L30: 0.21453136
C31: 3 | D31: 0 | E31: 0.5 | F31: 0 | G31: -0.00053684256 | H31: -0.036707275 | I31: 1.2792007e-06 | J31: -0.0061279573 | K31: 0.002995003 | L31: 0.20982361
C32: 3 | D32: 0 | E32: 0 | F32: 0.5 | G32: -0.00033422245 | H32: -0.051604051 | I32: -0.00016764805 | J32: -0.015388811 | K32: 0.0017663017 | L32: 0.2945576
C33: 4 | D33: 0 | E33: 0 | F33: 0 | G33: =G6 -> -0.00090206554 | H33: =H6 -> -0.095010705 | I33: =I6 -> -0.00031485432 | J33: =J6 -> -0.14170778 | K33: =K6 -> 0.0032724366 | L33: =L6 -> 0.46851912
C34: 4 | D34: 0.5 | E34: 0 | F34: 0 | G34: 0.00024599349 | H34: -0.090344101 | I34: -0.00099040195 | J34: -0.13324884 | K34: -0.002883181 | L34: 0.44684243
C35: 4 | D35: 0 | E35: 0.5 | F35: 0 | G35: -0.0018506368 | H35: -0.088594556 | I35: 0.00041975238 | J35: -0.12672122 | K35: 0.0093478858 | L35: 0.4398866
C36: 4 | D36: 0 | E36: 0 | F36: 0.5 | G36: -0.0011307185 | H36: -0.10034258 | I36: -0.0001616184 | J36: -0.14653116 | K36: 0.0049810112 | L36: 0.49788347
C37: 5 | D37: 0 | E37: 0 | F37: 0 | G37: =G7 -> -0.0013697715 | H37: =H7 -> -0.12989934 | I37: =I7 -> -0.0011154995 | J37: =J7 -> -0.27736902 | K37: =K7 -> 0.002998434 | L37: =L7 -> 0.62586665
C38: 5 | D38: 0.5 | E38: 0 | F38: 0 | G38: 0.00032646046 | H38: -0.1240313 | I38: -0.0020632716 | J38: -0.26052999 | K38: -0.0062308013 | L38: 0.59941602
C39: 5 | D39: 0 | E39: 0.5 | F39: 0 | G39: -0.0027219807 | H39: -0.12263767 | I39: -0.00013472384 | J39: -0.25649419 | K39: 0.011550099 | L39: 0.59437549
C40: 5 | D40: 0 | E40: 0 | F40: 0.5 | G40: -0.0016475921 | H40: -0.13209011 | I40: -0.0009523828 | J40: -0.27622804 | K40: 0.0053521544 | L40: 0.63961709
C41: 6 | D41: 0 | E41: 0 | F41: 0 | G41: =G8 -> -0.0013016209 | H41: =H8 -> -0.09177132 | I41: =I8 -> -0.00068558258 | J41: =J8 -> -0.18813878 | K41: =K8 -> 0.0035599116 | L41: =L8 -> 0.31649771
C42: 6 | D42: 0.5 | E42: 0 | F42: 0 | G42: 0.00096381898 | H42: -0.085903972 | I42: -0.0025404219 | J42: -0.17557143 | K42: -0.0083203129 | L42: 0.29679263
C43: 6 | D43: 0 | E43: 0.5 | F43: 0 | G43: -0.0031982432 | H43: -0.085218042 | I43: 0.001140643 | J43: -0.17052031 | K43: 0.014079059 | L43: 0.29610446
...

Sheet Distal Vali (1N perturb)
A1: 3 Perturbations | AA1: 3 Perturbations (relative only)
A2: Ground Truth | G2: 6-Axis FT Sensor | M2: SoRoSim get_distal_value | Q2: Distal Errors | T2: ABS Distal Errors | AA2: Ground Truth | AG2: 6-Axis FT Sensor | AM2: SoRoSim get_distal_value | AQ2: Distal Errors | AT2: ABS Distal Errors
A3: F (N) | B3: s (m) | C3: theta (rad) | D3: tau1 (N) | E3: tau2 (N) | F3: tau3 (N) | G3: Tx (Nm) | H3: Ty (Nm) | I3: Tz(Nm) | J3: Fx (N) | K3: Fy (N) | L3: Fz (N) | M3: F (N) | N3: s (m) | O3: theta (rad) | P3: f_final | Q3: F (N) | R3: s (m) | S3: theta (rad) | T3: F (N) | U3: s (m) | V3: theta (rad) | W3: Absolute Mean Error | AA3: F (N) | AB3: s (m) | AC3: theta (rad) | AD3: tau1 (N) | AE3: tau2 (N) | AF3: tau3 (N) | AG3: Tx (Nm) | AH3: Ty (Nm) | AI3: Tz(Nm) | AJ3: Fx (N) | AK3: Fy (N) | AL3: Fz (N) | AM3: F (N) | AN3: s (m) | AO3: theta (rad) | AP3: f_final | AQ3: F (N) | AR3: s (m) | AS3: theta (rad) | AT3: F (N) | AU3: s (m) | AV3: theta (rad) | AW3: Absolute Mean Error
A4: ='Proximal Validation'!A3 -> 0.4 | B4: ='Proximal Validation'!B3 -> 0.06 | C4: ='Proximal Validation'!C3 -> 1.5707963 | D4: ='Proximal Validation'!D3 -> 0 | E4: ='Proximal Validation'!E3 -> 0 | F4: ='Proximal Validation'!F3 -> 0 | G4: ='Proximal Validation'!G3 -> -0.00028477586 | H4: ='Proximal Validation'!H3 -> -0.058327373 | ... L4: ='Proximal Validation'!L3 -> 0.37637502 | M4: 0.44724257 | N4: 0.071236218 | O4: 1.5725247 | P4: 0.00018044118 | Q4: =M4-A4 -> 0.047242569 | R4: =N4-B4 -> 0.011236218 | S4: =O4-C4 -> 0.0017283989 | T4: =ABS(Q4) -> 0.047242569 | U4: =ABS(R4) -> 0.011236218 | V4: =ABS(S4) -> 0.0017283989 | W4: F1 (N) | X4: s1 (m) | Y4: el1 (rad) | AA4: ='Proximal Validation'!A3 -> 0.4 | AB4: ='Proximal Validation'!B3 -> 0.06 | AC4: ='Proximal Validation'!C3 -> 1.5707963 | AD4: ='Proximal Validation'!D3 -> 0 | AE4: ='Proximal Validation'!E3 -> 0 | AF4: ='Proximal Validation'!F3 -> 0 | AG4: ='Proximal Validation'!G3 -> -0.00028477586 | AH4: ='Proximal Validation'!H3 -> -0.058327373 | ... AL4: ='Proximal Validation'!L3 -> 0.37637502 | AM4: 0.93080923 | AN4: 0.074280472 | AO4: 1.5698072 | AP4: 0.00011507858 | AQ4: =AM4-AA4 -> 0.53080923 | AR4: =AN4-AB4 -> 0.014280472 | AS4: =AO4-AC4 -> -0.00098910523 | AT4: =ABS(AQ4) -> 0.53080923 | AU4: =ABS(AR4) -> 0.014280472 | AV4: =ABS(AS4) -> 0.00098910523 | AW4: F1 (N) | AX4: s1 (m) | AY4: el1 (rad)
A5: ='Proximal Validation'!A4 -> 0.8 | B5: ='Proximal Validation'!B4 -> 0.06 | C5: ='Proximal Validation'!C4 -> 1.5707963 | D5: ='Proximal Validation'!D4 -> 0 | E5: ='Proximal Validation'!E4 -> 0 | F5: ='Proximal Validation'!F4 -> 0 | G5: ='Proximal Validation'!G4 -> -0.001375952 | H5: ='Proximal Validation'!H4 -> -0.12723181 | ... L5: ='Proximal Validation'!L4 -> 0.8163234 | M5: 0.72482627 | N5: 0.074627259 | O5: 1.5958562 | P5: 0.00019585031 | Q5: =M5-A5 -> -0.075173726 | R5: =N5-B5 -> 0.014627259 | S5: =O5-C5 -> 0.025059852 | T5: =ABS(Q5) -> 0.075173726 | U5: =ABS(R5) -> 0.014627259 | V5: =ABS(S5) -> 0.025059852 | W5: {=AVERAGE(ABS(Q4:Q13))} -> 0.038162384 | X5: {=AVERAGE(ABS(R4:R13))} -> 0.013003253 | Y5: {=AVERAGE(ABS(S4:S13))} -> 0.016045352 | AA5: ='Proximal Validation'!A4 -> 0.8 | AB5: ='Proximal Validation'!B4 -> 0.06 | AC5: ='Proximal Validation'!C4 -> 1.5707963 | AD5: ='Proximal Validation'!D4 -> 0 | AE5: ='Proximal Validation'!E4 -> 0 | AF5: ='Proximal Validation'!F4 -> 0 | AG5: ='Proximal Validation'!G4 -> -0.001375952 | AH5: ='Proximal Validation'!H4 -> -0.12723181 | ... AL5: ='Proximal Validation'!L4 -> 0.8163234 | AM5: 0.91833498 | AN5: 0.080400599 | AO5: 1.5960797 | AP5: 0.00023695019 | AQ5: =AM5-AA5 -> 0.11833498 | AR5: =AN5-AB5 -> 0.020400599 | AS5: =AO5-AC5 -> 0.02528342 | AT5: =ABS(AQ5) -> 0.11833498 | AU5: =ABS(AR5) -> 0.020400599 | AV5: =ABS(AS5) -> 0.02528342 | AW5: {=AVERAGE(ABS(AQ4:AQ13))} -> 0.18453176 | AX5: {=AVERAGE(ABS(AR4:AR13))} -> 0.013022283 | AY5: {=AVERAGE(ABS(AS4:AS13))} -> 0.015310298
A6: ='Proximal Validation'!A5 -> 0.3 | B6: ='Proximal Validation'!B5 -> 0.08 | C6: ='Proximal Validation'!C5 -> 1.5707963 | D6: ='Proximal Validation'!D5 -> 0 | E6: ='Proximal Validation'!E5 -> 0 | F6: ='Proximal Validation'!F5 -> 0 | G6: ='Proximal Validation'!G5 -> -0.00028428674 | H6: ='Proximal Validation'!H5 -> -0.043962169 | ... L6: ='Proximal Validation'!L5 -> 0.24872187 | M6: 0.30067881 | N6: 0.088419965 | O6: 1.5781921 | P6: 3.1521522e-05 | Q6: =M6-A6 -> 0.00067881278 | R6: =N6-B6 -> 0.0084199653 | S6: =O6-C6 -> 0.0073957678 | T6: =ABS(Q6) -> 0.00067881278 | U6: =ABS(R6) -> 0.0084199653 | V6: =ABS(S6) -> 0.0073957678 | AA6: ='Proximal Validation'!A5 -> 0.3 | AB6: ='Proximal Validation'!B5 -> 0.08 | AC6: ='Proximal Validation'!C5 -> 1.5707963 | AD6: ='Proximal Validation'!D5 -> 0 | AE6: ='Proximal Validation'!E5 -> 0 | AF6: ='Proximal Validation'!F5 -> 0 | AG6: ='Proximal Validation'!G5 -> -0.00028428674 | AH6: ='Proximal Validation'!H5 -> -0.043962169 | ... AL6: ='Proximal Validation'!L5 -> 0.24872187 | AM6: 0.49728631 | AN6: 0.087942568 | AO6: 1.578111 | AP6: 1.0945855e-05 | AQ6: =AM6-AA6 -> 0.19728631 | AR6: =AN6-AB6 -> 0.0079425682 | AS6: =AO6-AC6 -> 0.0073147047 | AT6: =ABS(AQ6) -> 0.19728631 | AU6: =ABS(AR6) -> 0.0079425682 | AV6: =ABS(AS6) -> 0.0073147047
A7: ='Proximal Validation'!A6 -> 0.5 | B7: ='Proximal Validation'!B6 -> 0.1 | C7: ='Proximal Validation'!C6 -> 1.5707963 | D7: ='Proximal Validation'!D6 -> 0 | E7: ='Proximal Validation'!E6 -> 0 | F7: ='Proximal Validation'!F6 -> 0 | G7: ='Proximal Validation'!G6 -> -0.00090206554 | H7: ='Proximal Validation'!H6 -> -0.095010705 | ... L7: ='Proximal Validation'!L6 -> 0.46851912 | M7: 0.50010643 | N7: 0.11069488 | O7: 1.5808506 | P7: 8.7772175e-05 | Q7: =M7-A7 -> 0.00010643412 | R7: =N7-B7 -> 0.010694878 | S7: =O7-C7 -> 0.010054299 | T7: =ABS(Q7) -> 0.00010643412 | U7: =ABS(R7) -> 0.010694878 | V7: =ABS(S7) -> 0.010054299 | AA7: ='Proximal Validation'!A6 -> 0.5 | AB7: ='Proximal Validation'!B6 -> 0.1 | AC7: ='Proximal Validation'!C6 -> 1.5707963 | AD7: ='Proximal Validation'!D6 -> 0 | AE7: ='Proximal Validation'!E6 -> 0 | AF7: ='Proximal Validation'!F6 -> 0 | AG7: ='Proximal Validation'!G6 -> -0.00090206554 | AH7: ='Proximal Validation'!H6 -> -0.095010705 | ... AL7: ='Proximal Validation'!L6 -> 0.46851912 | AM7: 0.72760623 | AN7: 0.11093945 | AO7: 1.5798657 | AP7: 0.00010518136 | AQ7: =AM7-AA7 -> 0.22760623 | AR7: =AN7-AB7 -> 0.010939449 | AS7: =AO7-AC7 -> 0.009069387 | AT7: =ABS(AQ7) -> 0.22760623 | AU7: =ABS(AR7) -> 0.010939449 | AV7: =ABS(AS7) -> 0.009069387
A8: ='Proximal Validation'!A7 -> 0.7 | B8: ='Proximal Validation'!B7 -> 0.1 | C8: ='Proximal Validation'!C7 -> 1.5707963 | D8: ='Proximal Validation'!D7 -> 0 | E8: ='Proximal Validation'!E7 -> 0 | F8: ='Proximal Validation'!F7 -> 0 | G8: ='Proximal Validation'!G7 -> -0.0013697715 | H8: ='Proximal Validation'!H7 -> -0.12989934 | ... L8: ='Proximal Validation'!L7 -> 0.62586665 | M8: 0.69555108 | N8: 0.10817762 | O8: 1.5877814 | P8: 5.8431032e-05 | Q8: =M8-A8 -> -0.0044489168 | R8: =N8-B8 -> 0.0081776161 | S8: =O8-C8 -> 0.016985077 | T8: =ABS(Q8) -> 0.0044489168 | U8: =ABS(R8) -> 0.0081776161 | V8: =ABS(S8) -> 0.016985077 | AA8: ='Proximal Validation'!A7 -> 0.7 | AB8: ='Proximal Validation'!B7 -> 0.1 | AC8: ='Proximal Validation'!C7 -> 1.5707963 | AD8: ='Proximal Validation'!D7 -> 0 | AE8: ='Proximal Validation'!E7 -> 0 | AF8: ='Proximal Validation'!F7 -> 0 | AG8: ='Proximal Validation'!G7 -> -0.0013697715 | AH8: ='Proximal Validation'!H7 -> -0.12989934 | ... AL8: ='Proximal Validation'!L7 -> 0.62586665 | AM8: 0.89351581 | AN8: 0.1086271 | AO8: 1.5864782 | AP8: 9.8187916e-05 | AQ8: =AM8-AA8 -> 0.19351581 | AR8: =AN8-AB8 -> 0.008627101 | AS8: =AO8-AC8 -> 0.015681894 | AT8: =ABS(AQ8) -> 0.19351581 | AU8: =ABS(AR8) -> 0.008627101 | AV8: =ABS(AS8) -> 0.015681894
A9: ='Proximal Validation'!A8 -> 0.4 | B9: ='Proximal Validation'!B8 -> 0.16 | C9: ='Proximal Validation'!C8 -> 1.5707963 | D9: ='Proximal Validation'!D8 -> 0 | E9: ='Proximal Validation'!E8 -> 0 | F9: ='Proximal Validation'!F8 -> 0 | G9: ='Proximal Validation'!G8 -> -0.0013016209 | H9: ='Proximal Validation'!H8 -> -0.09177132 | ... L9: ='Proximal Validation'!L8 -> 0.31649771 | M9: 0.37708508 | N9: 0.16990424 | O9: 1.5783104 | P9: 0.00029633396 | Q9: =M9-A9 -> -0.022914918 | R9: =N9-B9 -> 0.0099042384 | S9: =O9-C9 -> 0.0075140707 | T9: =ABS(Q9) -> 0.022914918 | U9: =ABS(R9) -> 0.0099042384 | V9: =ABS(S9) -> 0.0075140707 | AA9: ='Proximal Validation'!A8 -> 0.4 | AB9: ='Proximal Validation'!B8 -> 0.16 | AC9: ='Proximal Validation'!C8 -> 1.5707963 | AD9: ='Proximal Validation'!D8 -> 0 | AE9: ='Proximal Validation'!E8 -> 0 | AF9: ='Proximal Validation'!F8 -> 0 | AG9: ='Proximal Validation'!G8 -> -0.0013016209 | AH9: ='Proximal Validation'!H8 -> -0.09177132 | ... AL9: ='Proximal Validation'!L8 -> 0.31649771 | AM9: 0.32723128 | AN9: 0.16889019 | AO9: 1.5727231 | AP9: 0.00042686043 | AQ9: =AM9-AA9 -> -0.072768719 | AR9: =AN9-AB9 -> 0.0088901918 | AS9: =AO9-AC9 -> 0.0019267942 | AT9: =ABS(AQ9) -> 0.072768719 | AU9: =ABS(AR9) -> 0.0088901918 | AV9: =ABS(AS9) -> 0.0019267942
A10: ='Proximal Validation'!A9 -> 0.6 | B10: ='Proximal Validation'!B9 -> 0.16 | C10: ='Proximal Validation'!C9 -> 1.5707963 | D10: ='Proximal Validation'!D9 -> 0 | E10: ='Proximal Validation'!E9 -> 0 | F10: ='Proximal Validation'!F9 -> 0 | G10: ='Proximal Validation'!G9 -> -0.0021819151 | H10: ='Proximal Validation'!H9 -> -0.13427521 | ... L10: ='Proximal Validation'!L9 -> 0.39143002 | M10: 0.66507098 | N10: 0.15884717 | O10: 1.5774824 | P10: 7.8056946e-05 | Q10: =M10-A10 -> 0.065070985 | R10: =N10-B10 -> -0.0011528268 | S10: =O10-C10 -> 0.0066860675 | T10: =ABS(Q10) -> 0.065070985 | U10: =ABS(R10) -> 0.0011528268 | V10: =ABS(S10) -> 0.0066860675 | AA10: ='Proximal Validation'!A9 -> 0.6 | AB10: ='Proximal Validation'!B9 -> 0.16 | AC10: ='Proximal Validation'!C9 -> 1.5707963 | AD10: ='Proximal Validation'!D9 -> 0 | AE10: ='Proximal Validation'!E9 -> 0 | AF10: ='Proximal Validation'!F9 -> 0 | AG10: ='Proximal Validation'!G9 -> -0.0021819151 | AH10: ='Proximal Validation'!H9 -> -0.13427521 | ... AL10: ='Proximal Validation'!L9 -> 0.39143002 | AM10: 0.57262647 | AN10: 0.15712241 | AO10: 1.5745723 | AP10: 0.00030106499 | AQ10: =AM10-AA10 -> -0.027373527 | AR10: =AN10-AB10 -> -0.002877589 | AS10: =AO10-AC10 -> 0.0037759325 | AT10: =ABS(AQ10) -> 0.027373527 | AU10: =ABS(AR10) -> 0.002877589 | AV10: =ABS(AS10) -> 0.0037759325
A11: ='Proximal Validation'!A10 -> 0.8 | B11: ='Proximal Validation'!B10 -> 0.18 | C11: ='Proximal Validation'!C10 -> 1.5707963 | D11: ='Proximal Validation'!D10 -> 0 | E11: ='Proximal Validation'!E10 -> 0 | F11: ='Proximal Validation'!F10 -> 0 | G11: ='Proximal Validation'!G10 -> -0.0010585423 | H11: ='Proximal Validation'!H10 -> -0.13548036 | ... L11: ='Proximal Validation'!L10 -> 0.1316857 | M11: 0.66551651 | N11: 0.2 | O11: 1.5825969 | P11: 0.0011596895 | Q11: =M11-A11 -> -0.13448349 | R11: =N11-B11 -> 0.02 | S11: =O11-C11 -> 0.01180058 | T11: =ABS(Q11) -> 0.13448349 | U11: =ABS(R11) -> 0.02 | V11: =ABS(S11) -> 0.01180058 | AA11: ='Proximal Validation'!A10 -> 0.8 | AB11: ='Proximal Validation'!B10 -> 0.18 | AC11: ='Proximal Validation'!C10 -> 1.5707963 | AD11: ='Proximal Validation'!D10 -> 0 | AE11: ='Proximal Validation'!E10 -> 0 | AF11: ='Proximal Validation'!F10 -> 0 | AG11: ='Proximal Validation'!G10 -> -0.0010585423 | AH11: ='Proximal Validation'!H10 -> -0.13548036 | ... AL11: ='Proximal Validation'!L10 -> 0.1316857 | AM11: 0.61376622 | AN11: 0.2 | AO11: 1.5863923 | AP11: 0.0012011069 | AQ11: =AM11-AA11 -> -0.18623378 | AR11: =AN11-AB11 -> 0.02 | AS11: =AO11-AC11 -> 0.015595982 | AT11: =ABS(AQ11) -> 0.18623378 | AU11: =ABS(AR11) -> 0.02 | AV11: =ABS(AS11) -> 0.015595982
A12: ='Proximal Validation'!A11 -> 0.3 | B12: ='Proximal Validation'!B11 -> 0.2 | C12: ='Proximal Validation'!C11 -> 1.5707963 | D12: ='Proximal Validation'!D11 -> 0 | E12: ='Proximal Validation'!E11 -> 0 | F12: ='Proximal Validation'!F11 -> 0 | G12: ='Proximal Validation'!G11 -> -0.00088630803 | H12: ='Proximal Validation'!H11 -> -0.067533724 | ... L12: ='Proximal Validation'!L11 -> 0.18086977 | M12: 0.30864666 | N12: 0.2 | O12: 1.5887844 | P12: 0.00056320515 | Q12: =M12-A12 -> 0.0086466568 | R12: =N12-B12 -> -5.9696428e-10 | S12: =O12-C12 -> 0.017988047 | T12: =ABS(Q12) -> 0.0086466568 | U12: =ABS(R12) -> 5.9696428e-10 | V12: =ABS(S12) -> 0.017988047 | AA12: ='Proximal Validation'!A11 -> 0.3 | AB12: ='Proximal Validation'!B11 -> 0.2 | AC12: ='Proximal Validation'!C11 -> 1.5707963 | AD12: ='Proximal Validation'!D11 -> 0 | AE12: ='Proximal Validation'!E11 -> 0 | AF12: ='Proximal Validation'!F11 -> 0 | AG12: ='Proximal Validation'!G11 -> -0.00088630803 | AH12: ='Proximal Validation'!H11 -> -0.067533724 | ... AL12: ='Proximal Validation'!L11 -> 0.18086977 | AM12: 0.2930873 | AN12: 0.19681113 | AO12: 1.5860176 | AP12: 0.00078804649 | AQ12: =AM12-AA12 -> -0.0069126974 | AR12: =AN12-AB12 -> -0.0031888704 | AS12: =AO12-AC12 -> 0.015221291 | AT12: =ABS(AQ12) -> 0.0069126974 | AU12: =ABS(AR12) -> 0.0031888704 | AV12: =ABS(AS12) -> 0.015221291
A13: ='Proximal Validation'!A12 -> 0.7 | B13: ='Proximal Validation'!B12 -> 0.2 | C13: ='Proximal Validation'!C12 -> 1.5707963 | D13: ='Proximal Validation'!D12 -> 0 | E13: ='Proximal Validation'!E12 -> 0 | F13: ='Proximal Validation'!F12 -> 0 | G13: ='Proximal Validation'!G12 -> -0.0027598871 | H13: ='Proximal Validation'!H12 -> -0.12722152 | ... L13: ='Proximal Validation'!L12 -> 0.066542283 | M13: 0.72285733 | N13: 0.15418047 | O13: 1.6260377 | P13: 0.00051373894 | Q13: =M13-A13 -> 0.022857332 | R13: =N13-B13 -> -0.045819528 | S13: =O13-C13 -> 0.055241363 | T13: =ABS(Q13) -> 0.022857332 | U13: =ABS(R13) -> 0.045819528 | V13: =ABS(S13) -> 0.055241363 | AA13: ='Proximal Validation'!A12 -> 0.7 | AB13: ='Proximal Validation'!B12 -> 0.2 | AC13: ='Proximal Validation'!C12 -> 1.5707963 | AD13: ='Proximal Validation'!D12 -> 0 | AE13: ='Proximal Validation'!E12 -> 0 | AF13: ='Proximal Validation'!F12 -> 0 | AG13: ='Proximal Validation'!G12 -> -0.0027598871 | AH13: ='Proximal Validation'!H12 -> -0.12722152 | ... AL13: ='Proximal Validation'!L12 -> 0.066542283 | AM13: 0.41552372 | AN13: 0.16692401 | AO13: 1.6290408 | AP13: 0.0006350051 | AQ13: =AM13-AA13 -> -0.28447628 | AR13: =AN13-AB13 -> -0.033075987 | AS13: =AO13-AC13 -> 0.058244465 | AT13: =ABS(AQ13) -> 0.28447628 | AU13: =ABS(AR13) -> 0.033075987 | AV13: =ABS(AS13) -> 0.058244465
A15: Perturbation
A16: 1 | B16: 0 | C16: 0
A17: 0 | B17: 1 | C17: 0
A18: 0 | B18: 0 | C18: 1
C21: Trial # | D21: tau1 (N) | E21: tau2 (N) | F21: tau3 (N) | G21: Supporting Measurments w Perturbation
C22: 1 | D22: =D4 -> 0 | E22: =E4 -> 0 | F22: =F4 -> 0 | G22: =G4 -> -0.00028477586 | H22: =H4 -> -0.058327373 | I22: =I4 -> -0.0001506703 | J22: =J4 -> 0.0060134237 | K22: =K4 -> 0.0022609532 | L22: =L4 -> 0.37637502
C23: 1 | D23: 1 | E23: 0 | F23: 0 | G23: 0.0006742329 | H23: -0.046691336 | I23: -0.00019840943 | J23: 0.019254899 | K23: -2.2761524e-05 | L23: 0.30847231
C24: 1 | D24: 0 | E24: 1 | F24: 0 | G24: -0.00060618203 | H24: -0.045500007 | I24: 6.9612463e-05 | J24: 0.024782635 | K24: 0.0094752312 | L24: 0.30106655
C25: 1 | D25: 0 | E25: 0 | F25: 1 | G25: -0.00013268134 | H25: -0.070247285 | I25: -0.00013355067 | J25: 0.023433084 | K25: 0.0062583163 | L25: 0.46214235
C26: 2 | D26: 0 | E26: 0 | F26: 0 | G26: =G5 -> -0.001375952 | H26: =H5 -> -0.12723181 | I26: =I5 -> -0.0015217981 | J26: =J5 -> -0.08266665 | K26: =K5 -> -0.004741177 | L26: =L5 -> 0.8163234
C27: 2 | D27: 1 | E27: 0 | F27: 0 | G27: -0.00017096614 | H27: -0.1171831 | I27: -0.0018990501 | J27: -0.066881448 | K27: -0.010641232 | L27: 0.76001531
C28: 2 | D28: 0 | E28: 1 | F28: 0 | G28: -0.0031106716 | H28: -0.11575355 | I28: -0.00038996659 | J28: -0.062772378 | K28: 0.006840378 | L28: 0.75269461
C29: 2 | D29: 0 | E29: 0 | F29: 1 | G29: -0.0019608403 | H29: -0.13725764 | I29: -0.0014088807 | J29: -0.079848483 | K29: -0.0018499047 | L29: 0.88854027
C30: 3 | D30: 0 | E30: 0 | F30: 0 | G30: =G6 -> -0.00028428674 | H30: =H6 -> -0.043962169 | I30: =I6 -> -0.00019410931 | J30: =J6 -> -0.014232989 | K30: =K6 -> 0.00080315024 | L30: =L6 -> 0.24872187
C31: 3 | D31: 1 | E31: 0 | F31: 0 | G31: 0.00046094938 | H31: -0.028747313 | I31: -0.0001744804 | J31: -0.0007492404 | K31: -0.001912374 | L31: 0.16522677
C32: 3 | D32: 0 | E32: 1 | F32: 0 | G32: -0.00076827023 | H32: -0.027165767 | I32: 2.1368774e-05 | J32: 0.0047830418 | K32: 0.0057868864 | L32: 0.15646727
C33: 3 | D33: 0 | E33: 0 | F33: 1 | G33: -0.00053039403 | H33: -0.061754897 | I33: -0.00013558881 | J33: -0.010850213 | K33: 0.0031783395 | L33: 0.35227984
C34: 4 | D34: 0 | E34: 0 | F34: 0 | G34: =G7 -> -0.00090206554 | H34: =H7 -> -0.095010705 | I34: =I7 -> -0.00031485432 | J34: =J7 -> -0.14170778 | K34: =K7 -> 0.0032724366 | L34: =L7 -> 0.46851912
C35: 4 | D35: 1 | E35: 0 | F35: 0 | G35: 0.0011199807 | H35: -0.082509451 | I35: -0.0014147388 | J35: -0.11533803 | K35: -0.0068659633 | L35: 0.41186845
C36: 4 | D36: 0 | E36: 1 | F36: 0 | G36: -0.0030216267 | H36: -0.081563368 | I36: 0.0012483229 | J36: -0.11234917 | K36: 0.01672242 | L36: 0.40724611
C37: 4 | D37: 0 | E37: 0 | F37: 1 | G37: -0.001327834 | H37: -0.10619107 | I37: -5.5953569e-05 | J37: -0.15105042 | K37: 0.0071365274 | L37: 0.5285213
C38: 5 | D38: 0 | E38: 0 | F38: 0 | G38: =G8 -> -0.0013697715 | H38: =H8 -> -0.12989934 | I38: =I8 -> -0.0011154995 | J38: =J8 -> -0.27736902 | K38: =K8 -> 0.002998434 | L38: =L8 -> 0.62586665
C39: 5 | D39: 1 | E39: 0 | F39: 0 | G39: 0.0010789594 | H39: -0.11674865 | I39: -0.002389512 | J39: -0.23966138 | K39: -0.0099661052 | L39: 0.56697065
C40: 5 | D40: 0 | E40: 1 | F40: 0 | G40: -0.0043625883 | H40: -0.11445073 | I40: 0.00099701353 | J40: -0.23323938 | K40: 0.021434955 | L40: 0.55733347
C41: 5 | D41: 0 | E41: 0 | F41: 1 | G41: -0.0021919934 | H41: -0.1420071 | I41: -0.00076931558 | J41: -0.29801038 | K41: 0.0080182031 | L41: 0.68905413
C42: 6 | D42: 0 | E42: 0 | F42: 0 | G42: =G9 -> -0.0013016209 | H42: =H9 -> -0.09177132 | I42: =I9 -> -0.00068558258 | J42: =J9 -> -0.18813878 | K42: =K9 -> 0.0035599116 | L42: =L9 -> 0.31649771
C43: 6 | D43: 1 | E43: 0 | F43: 0 | G43: 0.0021334765 | H43: -0.078673288 | I43: -0.0033856691 | J43: -0.15782742 | K43: -0.013936561 | L43: 0.2747671
...

Sheet Distal Vali (1.5N perturb)
A1: Ground Truth | G1: 6-Axis FT Sensor | M1: SoRoSim get_distal_value (3 perturbations) | Q1: Distal Errors | T1: ABS Distal Errors
A2: F (N) | B2: s (m) | C2: theta (rad) | D2: tau1 (N) | E2: tau2 (N) | F2: tau3 (N) | G2: Tx (Nm) | H2: Ty (Nm) | I2: Tz(Nm) | J2: Fx (N) | K2: Fy (N) | L2: Fz (N) | M2: F (N) | N2: s (m) | O2: theta (rad) | P2: f_final | Q2: F (N) | R2: s (m) | S2: theta (rad) | T2: F (N) | U2: s (m) | V2: theta (rad) | W2: Absolute Mean Error
A3: ='Proximal Validation'!A3 -> 0.4 | B3: ='Proximal Validation'!B3 -> 0.06 | C3: ='Proximal Validation'!C3 -> 1.5707963 | D3: ='Proximal Validation'!D3 -> 0 | E3: ='Proximal Validation'!E3 -> 0 | F3: ='Proximal Validation'!F3 -> 0 | G3: ='Proximal Validation'!G3 -> -0.00028477586 | H3: ='Proximal Validation'!H3 -> -0.058327373 | ... L3: ='Proximal Validation'!L3 -> 0.37637502 | Q3: =M3-A3 -> -0.4 | R3: =N3-B3 -> -0.06 | S3: =O3-C3 -> -1.5707963 | T3: =ABS(Q3) -> 0.4 | U3: =ABS(R3) -> 0.06 | V3: =ABS(S3) -> 1.5707963 | W3: F1 (N) | X3: s1 (m) | Y3: el1 (rad)
A4: ='Proximal Validation'!A4 -> 0.8 | B4: ='Proximal Validation'!B4 -> 0.06 | C4: ='Proximal Validation'!C4 -> 1.5707963 | D4: ='Proximal Validation'!D4 -> 0 | E4: ='Proximal Validation'!E4 -> 0 | F4: ='Proximal Validation'!F4 -> 0 | G4: ='Proximal Validation'!G4 -> -0.001375952 | H4: ='Proximal Validation'!H4 -> -0.12723181 | ... L4: ='Proximal Validation'!L4 -> 0.8163234 | Q4: =M4-A4 -> -0.8 | R4: =N4-B4 -> -0.06 | S4: =O4-C4 -> -1.5707963 | T4: =ABS(Q4) -> 0.8 | U4: =ABS(R4) -> 0.06 | V4: =ABS(S4) -> 1.5707963 | W4: {=AVERAGE(ABS(Q7:Q12))} -> 0.22261181 | X4: {=AVERAGE(ABS(R7:R12))} -> 0.049827157 | Y4: {=AVERAGE(ABS(S7:S12))} -> 0.018926136
A5: ='Proximal Validation'!A5 -> 0.3 | B5: ='Proximal Validation'!B5 -> 0.08 | C5: ='Proximal Validation'!C5 -> 1.5707963 | D5: ='Proximal Validation'!D5 -> 0 | E5: ='Proximal Validation'!E5 -> 0 | F5: ='Proximal Validation'!F5 -> 0 | G5: ='Proximal Validation'!G5 -> -0.00028428674 | H5: ='Proximal Validation'!H5 -> -0.043962169 | ... L5: ='Proximal Validation'!L5 -> 0.24872187 | Q5: =M5-A5 -> -0.3 | R5: =N5-B5 -> -0.08 | S5: =O5-C5 -> -1.5707963 | T5: =ABS(Q5) -> 0.3 | U5: =ABS(R5) -> 0.08 | V5: =ABS(S5) -> 1.5707963
A6: ='Proximal Validation'!A6 -> 0.5 | B6: ='Proximal Validation'!B6 -> 0.1 | C6: ='Proximal Validation'!C6 -> 1.5707963 | D6: ='Proximal Validation'!D6 -> 0 | E6: ='Proximal Validation'!E6 -> 0 | F6: ='Proximal Validation'!F6 -> 0 | G6: ='Proximal Validation'!G6 -> -0.00090206554 | H6: ='Proximal Validation'!H6 -> -0.095010705 | ... L6: ='Proximal Validation'!L6 -> 0.46851912 | Q6: =M6-A6 -> -0.5 | R6: =N6-B6 -> -0.1 | S6: =O6-C6 -> -1.5707963 | T6: =ABS(Q6) -> 0.5 | U6: =ABS(R6) -> 0.1 | V6: =ABS(S6) -> 1.5707963
A7: ='Proximal Validation'!A7 -> 0.7 | B7: ='Proximal Validation'!B7 -> 0.1 | C7: ='Proximal Validation'!C7 -> 1.5707963 | D7: ='Proximal Validation'!D7 -> 0 | E7: ='Proximal Validation'!E7 -> 0 | F7: ='Proximal Validation'!F7 -> 0 | G7: ='Proximal Validation'!G7 -> -0.0013697715 | H7: ='Proximal Validation'!H7 -> -0.12989934 | ... L7: ='Proximal Validation'!L7 -> 0.62586665 | M7: 0.7897685 | N7: 0.099547186 | O7: 1.5872342 | P7: 0.001645939 | Q7: =M7-A7 -> 0.089768504 | R7: =N7-B7 -> -0.00045281404 | S7: =O7-C7 -> 0.016437867 | T7: =ABS(Q7) -> 0.089768504 | U7: =ABS(R7) -> 0.00045281404 | V7: =ABS(S7) -> 0.016437867
A8: ='Proximal Validation'!A8 -> 0.4 | B8: ='Proximal Validation'!B8 -> 0.16 | C8: ='Proximal Validation'!C8 -> 1.5707963 | D8: ='Proximal Validation'!D8 -> 0 | E8: ='Proximal Validation'!E8 -> 0 | F8: ='Proximal Validation'!F8 -> 0 | G8: ='Proximal Validation'!G8 -> -0.0013016209 | H8: ='Proximal Validation'!H8 -> -0.09177132 | ... L8: ='Proximal Validation'!L8 -> 0.31649771 | M8: 0.78111143 | N8: 0.091808431 | O8: 1.5835867 | P8: 0.033037298 | Q8: =M8-A8 -> 0.38111143 | R8: =N8-B8 -> -0.068191569 | S8: =O8-C8 -> 0.012790337 | T8: =ABS(Q8) -> 0.38111143 | U8: =ABS(R8) -> 0.068191569 | V8: =ABS(S8) -> 0.012790337
A9: ='Proximal Validation'!A9 -> 0.6 | B9: ='Proximal Validation'!B9 -> 0.16 | C9: ='Proximal Validation'!C9 -> 1.5707963 | D9: ='Proximal Validation'!D9 -> 0 | E9: ='Proximal Validation'!E9 -> 0 | F9: ='Proximal Validation'!F9 -> 0 | G9: ='Proximal Validation'!G9 -> -0.0021819151 | H9: ='Proximal Validation'!H9 -> -0.13427521 | ... L9: ='Proximal Validation'!L9 -> 0.39143002 | M9: 0.83001903 | N9: 0.1253309 | O9: 1.5805608 | P9: 0.010687609 | Q9: =M9-A9 -> 0.23001903 | R9: =N9-B9 -> -0.034669104 | S9: =O9-C9 -> 0.0097644495 | T9: =ABS(Q9) -> 0.23001903 | U9: =ABS(R9) -> 0.034669104 | V9: =ABS(S9) -> 0.0097644495
A10: ='Proximal Validation'!A10 -> 0.8 | B10: ='Proximal Validation'!B10 -> 0.18 | C10: ='Proximal Validation'!C10 -> 1.5707963 | D10: ='Proximal Validation'!D10 -> 0 | E10: ='Proximal Validation'!E10 -> 0 | F10: ='Proximal Validation'!F10 -> 0 | G10: ='Proximal Validation'!G10 -> -0.0010585423 | H10: ='Proximal Validation'!H10 -> -0.13548036 | ... L10: ='Proximal Validation'!L10 -> 0.1316857 | M10: 0.85564647 | N10: 0.13988919 | O10: 1.5321318 | P10: 0.0082963147 | Q10: =M10-A10 -> 0.055646468 | R10: =N10-B10 -> -0.040110808 | S10: =O10-C10 -> -0.038664489 | T10: =ABS(Q10) -> 0.055646468 | U10: =ABS(R10) -> 0.040110808 | V10: =ABS(S10) -> 0.038664489
A11: ='Proximal Validation'!A11 -> 0.3 | B11: ='Proximal Validation'!B11 -> 0.2 | C11: ='Proximal Validation'!C11 -> 1.5707963 | D11: ='Proximal Validation'!D11 -> 0 | E11: ='Proximal Validation'!E11 -> 0 | F11: ='Proximal Validation'!F11 -> 0 | G11: ='Proximal Validation'!G11 -> -0.00088630803 | H11: ='Proximal Validation'!H11 -> -0.067533724 | ... L11: ='Proximal Validation'!L11 -> 0.18086977 | M11: 0.74008865 | N11: 0.091741523 | O11: 1.5926037 | P11: 0.050844864 | Q11: =M11-A11 -> 0.44008865 | R11: =N11-B11 -> -0.10825848 | S11: =O11-C11 -> 0.021807415 | T11: =ABS(Q11) -> 0.44008865 | U11: =ABS(R11) -> 0.10825848 | V11: =ABS(S11) -> 0.021807415
A12: ='Proximal Validation'!A12 -> 0.7 | B12: ='Proximal Validation'!B12 -> 0.2 | C12: ='Proximal Validation'!C12 -> 1.5707963 | D12: ='Proximal Validation'!D12 -> 0 | E12: ='Proximal Validation'!E12 -> 0 | F12: ='Proximal Validation'!F12 -> 0 | G12: ='Proximal Validation'!G12 -> -0.0027598871 | H12: ='Proximal Validation'!H12 -> -0.12722152 | ... L12: ='Proximal Validation'!L12 -> 0.066542283 | M12: 0.83903675 | N12: 0.15271983 | O12: 1.5848886 | P12: 0.016203975 | Q12: =M12-A12 -> 0.13903675 | R12: =N12-B12 -> -0.047280173 | S12: =O12-C12 -> 0.014092255 | T12: =ABS(Q12) -> 0.13903675 | U12: =ABS(R12) -> 0.047280173 | V12: =ABS(S12) -> 0.014092255
M13: SoRoSim get_distal_value (2 perturbations) | Q13: Distal Errors | T13: ABS Distal Errors
A14: Perturbation | M14: F (N) | N14: s (m) | O14: theta (rad) | P14: f_final | Q14: F (N) | R14: s (m) | S14: theta (rad) | T14: F (N) | U14: s (m) | V14: theta (rad) | W14: Absolute Mean Error
A15: 1.5 | B15: 0 | C15: 0 | Q15: =M15-A3 -> -0.4 | R15: =N15-B3 -> -0.06 | S15: =O15-C3 -> -1.5707963 | T15: =ABS(Q15) -> 0.4 | U15: =ABS(R15) -> 0.06 | V15: =ABS(S15) -> 1.5707963 | W15: F1 (N) | X15: s1 (m) | Y15: el1 (rad)
A16: 0 | B16: 1.5 | C16: 0 | Q16: =M16-A4 -> -0.8 | R16: =N16-B4 -> -0.06 | S16: =O16-C4 -> -1.5707963 | T16: =ABS(Q16) -> 0.8 | U16: =ABS(R16) -> 0.06 | V16: =ABS(S16) -> 1.5707963 | W16: {=AVERAGE(ABS(Q19:Q24))} -> 0.41453416 | X16: {=AVERAGE(ABS(R19:R24))} -> 0.070991912 | Y16: {=AVERAGE(ABS(S19:S24))} -> 0.028823511
A17: 0 | B17: 0 | C17: 1.5 | Q17: =M17-A5 -> -0.3 | R17: =N17-B5 -> -0.08 | S17: =O17-C5 -> -1.5707963 | T17: =ABS(Q17) -> 0.3 | U17: =ABS(R17) -> 0.08 | V17: =ABS(S17) -> 1.5707963
Q18: =M18-A6 -> -0.5 | R18: =N18-B6 -> -0.1 | S18: =O18-C6 -> -1.5707963 | T18: =ABS(Q18) -> 0.5 | U18: =ABS(R18) -> 0.1 | V18: =ABS(S18) -> 1.5707963
M19: 1 | N19: 0.078089144 | O19: 1.587723 | P19: 0.0016056364 | Q19: =M19-A7 -> 0.3 | R19: =N19-B7 -> -0.021910856 | S19: =O19-C7 -> 0.016926634 | T19: =ABS(Q19) -> 0.3 | U19: =ABS(R19) -> 0.021910856 | V19: =ABS(S19) -> 0.016926634
C20: Trial # | D20: tau1 (N) | E20: tau2 (N) | F20: tau3 (N) | G20: Supporting Measurments w Perturbation | M20: 1 | N20: 0.070779197 | O20: 1.6012212 | P20: 0.031529307 | Q20: =M20-A8 -> 0.6 | R20: =N20-B8 -> -0.089220803 | S20: =O20-C8 -> 0.030424876 | T20: =ABS(Q20) -> 0.6 | U20: =ABS(R20) -> 0.089220803 | V20: =ABS(S20) -> 0.030424876
C21: 1 | D21: =D3 -> 0 | E21: =E3 -> 0 | F21: =F3 -> 0 | G21: =G3 -> -0.00028477586 | H21: =H3 -> -0.058327373 | I21: =I3 -> -0.0001506703 | J21: =J3 -> 0.0060134237 | K21: =K3 -> 0.0022609532 | L21: =L3 -> 0.37637502 | M21: 0.99999999 | N21: 0.10245949 | O21: 1.587447 | P21: 0.010466521 | Q21: =M21-A9 -> 0.39999999 | R21: =N21-B9 -> -0.057540508 | S21: =O21-C9 -> 0.016650638 | T21: =ABS(Q21) -> 0.39999999 | U21: =ABS(R21) -> 0.057540508 | V21: =ABS(S21) -> 0.016650638
C22: 1 | D22: 1.5 | E22: 0 | F22: 0 | G22: 0.0010835963 | H22: -0.038952094 | I22: -8.8399393e-05 | J22: 0.026931612 | K22: 0.0012965277 | L22: 0.25999218 | M22: 0.98720496 | N22: 0.1323295 | O22: 1.6046348 | P22: 0.00025904099 | Q22: =M22-A10 -> 0.18720496 | R22: =N22-B10 -> -0.047670504 | S22: =O22-C10 -> 0.033838431 | T22: =ABS(Q22) -> 0.18720496 | U22: =ABS(R22) -> 0.047670504 | V22: =ABS(S22) -> 0.033838431
C23: 1 | D23: 0 | E23: 1.5 | F23: 0 | G23: -0.00060350576 | H23: -0.039121877 | I23: 3.6299578e-05 | J23: 0.031976171 | K23: 0.011962704 | L23: 0.26262808 | M23: 1 | N23: 0.066227539 | O23: 1.6100461 | P23: 0.049255432 | Q23: =M23-A11 -> 0.7 | R23: =N23-B11 -> -0.13377246 | S23: =O23-C11 -> 0.039249768 | T23: =ABS(Q23) -> 0.7 | U23: =ABS(R23) -> 0.13377246 | V23: =ABS(S23) -> 0.039249768
C24: 1 | D24: 0 | E24: 0 | F24: 1.5 | G24: -1.6045989e-05 | H24: -0.076417178 | I24: -0.0001832167 | J24: 0.030589286 | K24: 0.0080633685 | L24: 0.50434405 | M24: 0.99999999 | N24: 0.12416366 | O24: 1.606647 | P24: 0.014596613 | Q24: =M24-A12 -> 0.29999999 | R24: =N24-B12 -> -0.075836341 | S24: =O24-C12 -> 0.03585072 | T24: =ABS(Q24) -> 0.29999999 | U24: =ABS(R24) -> 0.075836341 | V24: =ABS(S24) -> 0.03585072
C25: 2 | D25: 0 | E25: 0 | F25: 0 | G25: =G4 -> -0.001375952 | H25: =H4 -> -0.12723181 | I25: =I4 -> -0.0015217981 | J25: =J4 -> -0.08266665 | K25: =K4 -> -0.004741177 | L25: =L4 -> 0.8163234 | M25: SoRoSim get_distal_value (1 perturbations) | Q25: Distal Errors | T25: ABS Distal Errors
C26: 2 | D26: 1.5 | E26: 0 | F26: 0 | G26: 0.00027286122 | H26: -0.11211783 | I26: -0.0020007757 | J26: -0.057639904 | K26: -0.012371033 | L26: 0.72908455 | M26: F (N) | N26: s (m) | O26: theta (rad) | P26: f_final | Q26: F (N) | R26: s (m) | S26: theta (rad) | T26: F (N) | U26: s (m) | V26: theta (rad) | W26: Absolute Mean Error
C27: 2 | D27: 0 | E27: 1.5 | F27: 0 | G27: -0.0039176177 | H27: -0.11045328 | I27: 9.8139455e-05 | J27: -0.053478844 | K27: 0.0121741 | L27: 0.72120184 | Q27: =M27-A3 -> -0.4 | R27: =N27-B3 -> -0.06 | S27: =O27-C3 -> -1.5707963 | T27: =ABS(Q27) -> 0.4 | U27: =ABS(R27) -> 0.06 | V27: =ABS(S27) -> 1.5707963 | W27: F1 (N) | X27: s1 (m) | Y27: el1 (rad)
C28: 2 | D28: 0 | E28: 0 | F28: 1.5 | G28: -0.00220025 | H28: -0.1433492 | I28: -0.001373284 | J28: -0.081474617 | K28: -0.00055378675 | L28: 0.92903924 | Q28: =M28-A4 -> -0.8 | R28: =N28-B4 -> -0.06 | S28: =O28-C4 -> -1.5707963 | T28: =ABS(Q28) -> 0.8 | U28: =ABS(R28) -> 0.06 | V28: =ABS(S28) -> 1.5707963 | W28: {=AVERAGE(ABS(Q31:Q36))} -> 0.12115048 | X28: {=AVERAGE(ABS(R31:R36))} -> 0.03174704 | Y28: {=AVERAGE(ABS(S31:S36))} -> 0.12689221
