Workbook

Sheet Proximal Validation (double)
A1: Ground Truth | L1: 6-Axis FT Sensor | R1: SoRoSim get_proximal_value | X1: Proximal Errors
A2: F1 (N) | B2: s1 (m) | C2: el1 (rad) | D2: az1 (rad) | E2: F2 (N) | F2: s2 (m) | G2: el2 (rad) | H2: az2 (rad) | I2: tau1 (N) | J2: tau2 (N) | K2: tau3 (N) | L2: Tx (Nm) | M2: Ty (Nm) | N2: Tz(Nm) | O2: Fx (N) | P2: Fy (N) | Q2: Fz (N) | R2: Tx (Nm) | S2: Ty (Nm) | T2: Tz(Nm) | U2: Fx (N) | V2: Fy (N) | W2: Fz (N) | X2: Tx (Nm) | Y2: Ty (Nm) | Z2: Tz(Nm) | AA2: Fx (N) | AB2: Fy (N) | AC2: Fz (N)
A3: 0.2 | B3: 0.1 | C3: 1.571 | D3: =PI()/2 -> 1.5707963 | E3: 1 | F3: 0.04 | G3: 3.142 | H3: =PI()/2 -> 1.5707963 | I3: 1.4 | J3: 0 | K3: 0 | L3: -0.0019976702 | M3: -0.03319085 | N3: -0.13983804 | O3: -0.015990611 | P3: -1.0412544 | Q3: 0.19511425 | R3: 6.3593774e-05 | S3: -0.037943379 | T3: -0.13000957 | U3: -0.0028238971 | V3: -1.0000554 | W3: 0.19957227 | X3: =ABS(L3)-ABS(R3) -> 0.0019340764 | Y3: =ABS(M3)-ABS(S3) -> -0.0047525289 | Z3: =ABS(N3)-ABS(T3) -> 0.0098284725 | AA3: =ABS(O3)-ABS(U3) -> 0.013166714 | AB3: =ABS(P3)-ABS(V3) -> 0.041198982 | AC3: =ABS(Q3)-ABS(W3) -> -0.0044580181
A4: 1 | B4: 0.1 | C4: 1.571 | D4: =PI()/2 -> 1.5707963 | E4: 1 | F4: 0.08 | G4: 3.142 | H4: =PI()/2 -> 1.5707963 | I4: 0 | J4: 0 | K4: 0 | L4: -0.0013075336 | M4: -0.21146439 | N4: -0.15480977 | O4: -0.11514878 | P4: -0.88536769 | Q4: 1.091455 | R4: 1.2514809e-11 | S4: -0.18984404 | T4: -0.16999026 | U4: -0.0440426 | V4: -0.99984999 | W4: 0.9989733 | X4: =ABS(L4)-ABS(R4) -> 0.0013075336 | Y4: =ABS(M4)-ABS(S4) -> 0.021620346 | Z4: =ABS(N4)-ABS(T4) -> -0.015180491 | AA4: =ABS(O4)-ABS(U4) -> 0.071106175 | AB4: =ABS(P4)-ABS(V4) -> -0.1144823 | AC4: =ABS(Q4)-ABS(W4) -> 0.092481678
A5: 0.5 | B5: 0.1 | C5: 1.571 | D5: =PI()/2 -> 1.5707963 | E5: 0.2 | F5: 0.02 | G5: 3.927 | H5: =PI()/2 -> 1.5707963 | I5: 0 | J5: 0 | K5: 0 | L5: 0.00048654911 | M5: -0.099444382 | N5: -0.010887475 | O5: -0.029133603 | P5: -0.12781015 | Q5: 0.45268995 | R5: 3.6278388e-17 | S5: -0.07943516 | T5: -0.015575539 | U5: -0.0075837263 | V5: -0.14152173 | W5: 0.35851823 | X5: =ABS(L5)-ABS(R5) -> 0.00048654911 | Y5: =ABS(M5)-ABS(S5) -> 0.020009222 | Z5: =ABS(N5)-ABS(T5) -> -0.0046880638 | AA5: =ABS(O5)-ABS(U5) -> 0.021549877 | AB5: =ABS(P5)-ABS(V5) -> -0.013711576 | AC5: =ABS(Q5)-ABS(W5) -> 0.094171714
A6: 0.9 | B6: 0.1 | C6: 1.571 | D6: =PI()/2 -> 1.5707963 | E6: 0.2 | F6: 0.08 | G6: 4.712 | H6: =PI()/2 -> 1.5707963 | I6: 1.2 | J6: 0 | K6: 0 | L6: 0.0021138785 | M6: -0.17721578 | N6: 0.003866273 | O6: -0.097615689 | P6: 0.028949752 | Q6: 0.88741946 | R6: 0.00021251522 | S6: -0.1369385 | T6: -6.0502751e-05 | U6: -0.024142075 | V6: -0.00036234209 | W6: 0.69959146 | X6: =ABS(L6)-ABS(R6) -> 0.0019013633 | Y6: =ABS(M6)-ABS(S6) -> 0.040277285 | Z6: =ABS(N6)-ABS(T6) -> 0.0038057702 | AA6: =ABS(O6)-ABS(U6) -> 0.073473614 | AB6: =ABS(P6)-ABS(V6) -> 0.02858741 | AC6: =ABS(Q6)-ABS(W6) -> 0.187828
A7: 0.1 | B7: 0.12 | C7: 1.571 | D7: =PI()/2 -> 1.5707963 | E7: 1 | F7: 0.06 | G7: 3.927 | H7: =PI()/2 -> 1.5707963 | I7: 0 | J7: 0 | K7: 0 | L7: -0.0014075441 | M7: 0.07288304 | N7: -0.11806335 | O7: 0.002719406 | P7: -0.758407 | Q7: -0.50915515 | R7: 2.0768267e-14 | S7: 0.08506708 | T7: -0.1060691 | U7: -0.0017701045 | V7: -0.70711888 | W7: -0.60711354 | X7: =ABS(L7)-ABS(R7) -> 0.0014075441 | Y7: =ABS(M7)-ABS(S7) -> -0.012184041 | Z7: =ABS(N7)-ABS(T7) -> 0.011994241 | AA7: =ABS(O7)-ABS(U7) -> 0.00094930157 | AB7: =ABS(P7)-ABS(V7) -> 0.051288122 | AC7: =ABS(Q7)-ABS(W7) -> -0.097958391
A8: 0.8 | B8: 0.16 | C8: 1.571 | D8: =PI()/2 -> 1.5707963 | E8: 0.8 | F8: 0.06 | G8: 3.927 | H8: =PI()/2 -> 1.5707963 | I8: 1.4 | J8: 0 | K8: 0 | L8: 0.0034910832 | M8: -0.18494511 | N8: -0.090413325 | O8: -0.4012619 | P8: -0.60379952 | Q8: 0.49847054 | R8: 0.0024837032 | S8: -0.10814299 | T8: -0.086006944 | U8: -0.22293507 | V8: -0.57314464 | W8: 0.19699601 | X8: =ABS(L8)-ABS(R8) -> 0.00100738 | Y8: =ABS(M8)-ABS(S8) -> 0.076802112 | Z8: =ABS(N8)-ABS(T8) -> 0.0044063802 | AA8: =ABS(O8)-ABS(U8) -> 0.17832682 | AB8: =ABS(P8)-ABS(V8) -> 0.030654886 | AC8: =ABS(Q8)-ABS(W8) -> 0.30147454
A9: 0.1 | B9: 0.18 | C9: 1.571 | D9: =PI()/2 -> 1.5707963 | E9: 0.1 | F9: 0.02 | G9: 3.142 | H9: =PI()/2 -> 1.5707963 | I9: 1.2 | J9: 0 | K9: 0 | L9: 0.001590815 | M9: -0.034777381 | N9: -0.015904162 | O9: -0.020381898 | P9: -0.14476515 | Q9: 0.11709622 | R9: 0.00044382727 | S9: -0.026869973 | T9: -0.011069103 | U9: -0.010528278 | V9: -0.10042994 | W9: 0.099399542 | X9: =ABS(L9)-ABS(R9) -> 0.0011469878 | Y9: =ABS(M9)-ABS(S9) -> 0.0079074072 | Z9: =ABS(N9)-ABS(T9) -> 0.0048350589 | AA9: =ABS(O9)-ABS(U9) -> 0.0098536197 | AB9: =ABS(P9)-ABS(V9) -> 0.044335212 | AC9: =ABS(Q9)-ABS(W9) -> 0.017696674
A10: 0.9 | B10: 0.18 | C10: 1.571 | D10: =PI()/2 -> 1.5707963 | E10: 0.1 | F10: 0.08 | G10: 4.712 | H10: =PI()/2 -> 1.5707963 | I10: 0 | J10: 0 | K10: 0 | L10: 0.0023236712 | M10: -0.20482215 | N10: 0.0061566709 | O10: -0.39857343 | P10: 0.027593434 | Q10: 0.66701603 | R10: 8.0876545e-15 | S10: -0.20707877 | T10: -5.2207475e-05 | U10: -0.40492469 | V10: -0.00020169903 | W10: 0.70085548 | X10: =ABS(L10)-ABS(R10) -> 0.0023236712 | Y10: =ABS(M10)-ABS(S10) -> -0.002256622 | Z10: =ABS(N10)-ABS(T10) -> 0.0061044634 | AA10: =ABS(O10)-ABS(U10) -> -0.0063512573 | AB10: =ABS(P10)-ABS(V10) -> 0.027391735 | AC10: =ABS(Q10)-ABS(W10) -> -0.033839446
A11: 0.3 | B11: 0.18 | C11: 1.571 | D11: =PI()/2 -> 1.5707963 | E11: 0.9 | F11: 0.08 | G11: 4.712 | H11: =PI()/2 -> 1.5707963 | I11: 1 | J11: 0 | K11: 0 | L11: 0.0016893346 | M11: 0.095554247 | N11: -0.00088441034 | O11: -0.045536973 | P11: -0.0059180781 | Q11: -0.73156416 | R11: 0.0010230325 | S11: 0.073116425 | T11: -0.00033942386 | U11: -0.046565899 | V11: -0.0021599014 | W11: -0.60541619 | X11: =ABS(L11)-ABS(R11) -> 0.00066630213 | Y11: =ABS(M11)-ABS(S11) -> 0.022437823 | Z11: =ABS(N11)-ABS(T11) -> 0.00054498648 | AA11: =ABS(O11)-ABS(U11) -> -0.0010289261 | AB11: =ABS(P11)-ABS(V11) -> 0.0037581767 | AC11: =ABS(Q11)-ABS(W11) -> 0.12614797
A12: 0.9 | B12: 0.2 | C12: 1.571 | D12: =PI()/2 -> 1.5707963 | E12: 1 | F12: 0.02 | G12: 3.142 | H12: =PI()/2 -> 1.5707963 | I12: 0.4 | J12: 0 | K12: 0 | L12: 0.0012135198 | M12: -0.18293566 | N12: -0.10479864 | O12: -0.48353463 | P12: -0.98798037 | Q12: 0.51245713 | R12: 0.0017585898 | S12: -0.22190858 | T12: -0.11093483 | U12: -0.5463225 | V12: -1.0072866 | W12: 0.71469841 | X12: =ABS(L12)-ABS(R12) -> -0.00054506995 | Y12: =ABS(M12)-ABS(S12) -> -0.038972924 | Z12: =ABS(N12)-ABS(T12) -> -0.0061361871 | AA12: =ABS(O12)-ABS(U12) -> -0.062787871 | AB12: =ABS(P12)-ABS(V12) -> -0.019306265 | AC12: =ABS(Q12)-ABS(W12) -> -0.20224127
A13: 0.1 | B13: 0.2 | C13: 1.571 | D13: =PI()/2 -> 1.5707963 | E13: 0.3 | F13: 0.08 | G13: 3.142 | H13: =PI()/2 -> 1.5707963 | I13: 0.2 | J13: 0 | K13: 0 | L13: -0.00065936521 | M13: 0.0031013913 | N13: -0.067128308 | O13: 0.031099312 | P13: -0.38181251 | Q13: -0.0304524 | R13: 0.00010286971 | S13: -0.028595158 | T13: -0.051007253 | U13: -0.0089683117 | V13: -0.30003682 | W13: 0.099549956 | X13: =ABS(L13)-ABS(R13) -> 0.0005564955 | Y13: =ABS(M13)-ABS(S13) -> -0.025493767 | Z13: =ABS(N13)-ABS(T13) -> 0.016121055 | AA13: =ABS(O13)-ABS(U13) -> 0.022131 | AB13: =ABS(P13)-ABS(V13) -> 0.081775697 | AC13: =ABS(Q13)-ABS(W13) -> -0.069097556 | AG13: =0.17*0.01 -> 0.0017
A14: 0.9 | B14: 0.2 | C14: 1.571 | D14: =PI()/2 -> 1.5707963 | E14: 0.3 | F14: 0.02 | G14: 4.712 | H14: =PI()/2 -> 1.5707963 | I14: 1.4 | J14: 0 | K14: 0 | L14: 0.0087932777 | M14: -0.16019897 | N14: -0.0024834895 | O14: -0.46627718 | P14: -0.019136451 | Q14: 0.27873135 | R14: 0.0061138315 | S14: -0.1840208 | T14: -0.0035282492 | U14: -0.57405013 | V14: -0.027516678 | W14: 0.39218059 | X14: =ABS(L14)-ABS(R14) -> 0.0026794462 | Y14: =ABS(M14)-ABS(S14) -> -0.023821826 | Z14: =ABS(N14)-ABS(T14) -> -0.0010447598 | AA14: =ABS(O14)-ABS(U14) -> -0.10777295 | AB14: =ABS(P14)-ABS(V14) -> -0.0083802264 | AC14: =ABS(Q14)-ABS(W14) -> -0.11344924
A15: 0.9 | B15: 0.1 | C15: 2.356 | D15: =PI()/2 -> 1.5707963 | E15: 0.9 | F15: 0.02 | G15: 4.712 | H15: =PI()/2 -> 1.5707963 | I15: 0.4 | J15: 0 | K15: 0 | L15: -0.0079012457 | M15: -0.043984719 | N15: -0.14196087 | O15: 0.086025655 | P15: -0.6940586 | Q15: -0.18663806 | R15: 8.704473e-05 | S15: -0.02190576 | T15: -0.12090057 | U15: -0.023124793 | V15: -0.63641942 | W15: -0.26371643 | X15: =ABS(L15)-ABS(R15) -> 0.007814201 | Y15: =ABS(M15)-ABS(S15) -> 0.022078959 | Z15: =ABS(N15)-ABS(T15) -> 0.021060306 | AA15: =ABS(O15)-ABS(U15) -> 0.062900862 | AB15: =ABS(P15)-ABS(V15) -> 0.057639182 | AC15: =ABS(Q15)-ABS(W15) -> -0.077078376
A16: 0.4 | B16: 0.12 | C16: 2.356 | D16: =PI()/2 -> 1.5707963 | E16: 0.1 | F16: 0.06 | G16: 3.142 | H16: =PI()/2 -> 1.5707963 | I16: 0.4 | J16: 0 | K16: 0 | L16: -0.0039040381 | M16: -0.067934044 | N16: -0.085464723 | O16: 0.026761934 | P16: -0.41294175 | Q16: 0.30062127 | R16: 8.7914633e-05 | S16: -0.059386979 | T16: -0.074372299 | U16: -0.010767215 | V16: -0.38270711 | W16: 0.28275139 | X16: =ABS(L16)-ABS(R16) -> 0.0038161235 | Y16: =ABS(M16)-ABS(S16) -> 0.0085470648 | Z16: =ABS(N16)-ABS(T16) -> 0.011092424 | AA16: =ABS(O16)-ABS(U16) -> 0.015994719 | AB16: =ABS(P16)-ABS(V16) -> 0.030234648 | AC16: =ABS(Q16)-ABS(W16) -> 0.017869884
A17: 1 | B17: 0.14 | C17: 2.356 | D17: =PI()/2 -> 1.5707963 | E17: 0.4 | F17: 0.04 | G17: 3.927 | H17: =PI()/2 -> 1.5707963 | I17: 0.6 | J17: 0 | K17: 0 | L17: -0.0028297976 | M17: -0.18058619 | N17: -0.23388143 | O17: -0.26429382 | P17: -1.1066046 | Q17: 0.67185998 | R17: 0.0007512695 | S17: -0.12443249 | T17: -0.19810865 | U17: -0.15147434 | V17: -0.98242112 | W17: 0.41545764 | X17: =ABS(L17)-ABS(R17) -> 0.0020785281 | Y17: =ABS(M17)-ABS(S17) -> 0.056153703 | Z17: =ABS(N17)-ABS(T17) -> 0.035772783 | AA17: =ABS(O17)-ABS(U17) -> 0.11281948 | AB17: =ABS(P17)-ABS(V17) -> 0.12418346 | AC17: =ABS(Q17)-ABS(W17) -> 0.25640234
A18: 0.4 | B18: 0.18 | C18: 2.356 | D18: =PI()/2 -> 1.5707963 | E18: 0.7 | F18: 0.04 | G18: 3.142 | H18: =PI()/2 -> 1.5707963 | I18: 0 | J18: 0 | K18: 0 | L18: -0.0062234225 | M18: -0.058960229 | N18: -0.1536632 | O18: -0.05501027 | P18: -0.88742548 | Q18: 0.18511915 | R18: 2.5166354e-14 | S18: -0.075129988 | T18: -0.16613493 | U18: -0.085610834 | V18: -0.97635689 | W18: 0.27620746 | X18: =ABS(L18)-ABS(R18) -> 0.0062234225 | Y18: =ABS(M18)-ABS(S18) -> -0.016169759 | Z18: =ABS(N18)-ABS(T18) -> -0.012471727 | AA18: =ABS(O18)-ABS(U18) -> -0.030600564 | AB18: =ABS(P18)-ABS(V18) -> -0.088931408 | AC18: =ABS(Q18)-ABS(W18) -> -0.091088306
A19: 0.1 | B19: 0.18 | C19: 2.356 | D19: =PI()/2 -> 1.5707963 | E19: 0.2 | F19: 0.06 | G19: 4.712 | H19: =PI()/2 -> 1.5707963 | I19: 0.4 | J19: 0 | K19: 0 | L19: 0.0033402334 | M19: 0.014506238 | N19: -0.015207892 | O19: -0.018622696 | P19: -0.047658216 | Q19: -0.14300856 | R19: 0.00016324742 | S19: 0.01092222 | T19: -0.019089625 | U19: -0.0036935071 | V19: -0.070740478 | W19: -0.12937429 | X19: =ABS(L19)-ABS(R19) -> 0.0031769859 | Y19: =ABS(M19)-ABS(S19) -> 0.0035840177 | Z19: =ABS(N19)-ABS(T19) -> -0.003881733 | AA19: =ABS(O19)-ABS(U19) -> 0.014929189 | AB19: =ABS(P19)-ABS(V19) -> -0.023082262 | AC19: =ABS(Q19)-ABS(W19) -> 0.01363427
A20: 0.9 | B20: 0.2 | C20: 2.356 | D20: =PI()/2 -> 1.5707963 | E20: 0.3 | F20: 0.06 | G20: 3.142 | H20: =PI()/2 -> 1.5707963 | I20: 1.2 | J20: 0 | K20: 0 | L20: 0.0099984761 | M20: -0.16704941 | N20: -0.21110177 | O20: -0.65643388 | P20: -0.80316579 | Q20: 0.5047884 | R20: 0.0059109947 | S20: -0.15824306 | T20: -0.20689861 | U20: -0.52353575 | V20: -0.83705637 | W20: 0.50639605 | X20: =ABS(L20)-ABS(R20) -> 0.0040874814 | Y20: =ABS(M20)-ABS(S20) -> 0.0088063443 | Z20: =ABS(N20)-ABS(T20) -> 0.0042031627 | AA20: =ABS(O20)-ABS(U20) -> 0.13289813 | AB20: =ABS(P20)-ABS(V20) -> -0.033890573 | AC20: =ABS(Q20)-ABS(W20) -> -0.0016076547
A21: 0.1 | B21: 0.1 | C21: 3.142 | D21: =PI()/2 -> 1.5707963 | E21: 0.3 | F21: 0.08 | G21: 3.927 | H21: =PI()/2 -> 1.5707963 | I21: 1.2 | J21: 0 | K21: 0 | L21: -0.00041311281 | M21: 0.033949088 | N21: -0.054488845 | O21: -0.0057915412 | P21: -0.31081975 | Q21: -0.19208579 | R21: 4.9478286e-06 | S21: 0.036069994 | T21: -0.055061291 | U21: 0.00054940458 | V21: -0.31212792 | W21: -0.2121731 | X21: =ABS(L21)-ABS(R21) -> 0.00040816498 | Y21: =ABS(M21)-ABS(S21) -> -0.0021209061 | Z21: =ABS(N21)-ABS(T21) -> -0.00057244622 | AA21: =ABS(O21)-ABS(U21) -> 0.0052421366 | AB21: =ABS(P21)-ABS(V21) -> -0.0013081766 | AC21: =ABS(Q21)-ABS(W21) -> -0.020087313
A22: 0.1 | B22: 0.2 | C22: 3.142 | D22: =PI()/2 -> 1.5707963 | E22: 0.8 | F22: 0.02 | G22: 3.927 | H22: =PI()/2 -> 1.5707963 | I22: 1.2 | J22: 0 | K22: 0 | L22: -0.0010830942 | M22: 0.048130438 | N22: -0.081404999 | O22: -0.038113974 | P22: -0.69519579 | Q22: -0.43949088 | R22: 0.00034450527 | S22: 0.062217164 | T22: -0.090891629 | U22: 0.0019621471 | V22: -0.66566073 | W22: -0.56563646 | X22: =ABS(L22)-ABS(R22) -> 0.00073858889 | Y22: =ABS(M22)-ABS(S22) -> -0.014086726 | Z22: =ABS(N22)-ABS(T22) -> -0.0094866298 | AA22: =ABS(O22)-ABS(U22) -> 0.036151827 | AB22: =ABS(P22)-ABS(V22) -> 0.029535063 | AC22: =ABS(Q22)-ABS(W22) -> -0.12614558
A23: 0.9 | B23: 0.1 | C23: 3.927 | D23: =PI()/2 -> 1.5707963 | E23: 0.2 | F23: 0.02 | G23: 3.142 | H23: =PI()/2 -> 1.5707963 | I23: 1.4 | J23: 0 | K23: 0 | L23: -0.010050362 | M23: 0.12748645 | N23: -0.17898215 | O23: 0.028237749 | P23: -1.0124334 | Q23: -0.6058498 | R23: -8.1804653e-05 | S23: 0.12091876 | T23: -0.14290508 | U23: -0.010876102 | V23: -0.83634045 | W23: -0.63643948 | X23: =ABS(L23)-ABS(R23) -> 0.0099685573 | Y23: =ABS(M23)-ABS(S23) -> 0.006567696 | Z23: =ABS(N23)-ABS(T23) -> 0.036077078 | AA23: =ABS(O23)-ABS(U23) -> 0.017361647 | AB23: =ABS(P23)-ABS(V23) -> 0.17609296 | AC23: =ABS(Q23)-ABS(W23) -> -0.030589677
A24: 0.2 | B24: 0.12 | C24: 3.927 | D24: =PI()/2 -> 1.5707963 | E24: 0.2 | F24: 0.02 | G24: 4.712 | H24: =PI()/2 -> 1.5707963 | I24: 1.2 | J24: 0 | K24: 0 | L24: -0.00018197205 | M24: 0.048199806 | N24: -0.028443847 | O24: 0.013900647 | P24: -0.13246818 | Q24: -0.32060724 | R24: -3.5341546e-05 | S24: 0.051697111 | T24: -0.029701093 | U24: 0.0026096253 | V24: -0.14147144 | W24: -0.34141866 | X24: =ABS(L24)-ABS(R24) -> 0.0001466305 | Y24: =ABS(M24)-ABS(S24) -> -0.0034973043 | Z24: =ABS(N24)-ABS(T24) -> -0.0012572462 | AA24: =ABS(O24)-ABS(U24) -> 0.011291022 | AB24: =ABS(P24)-ABS(V24) -> -0.0090032561 | AC24: =ABS(Q24)-ABS(W24) -> -0.020811416
A25: 0.6 | B25: 0.12 | C25: 3.927 | D25: =PI()/2 -> 1.5707963 | E25: 0.5 | F25: 0.08 | G25: 4.712 | H25: =PI()/2 -> 1.5707963 | I25: 0.2 | J25: 0 | K25: 0 | L25: -0.00094277319 | M25: 0.1937201 | N25: -0.11552855 | O25: 0.04316394 | P25: -0.53577322 | Q25: -0.98622829 | R25: -2.6956575e-05 | S25: 0.17401658 | T25: -0.08907149 | U25: -0.035907182 | V25: -0.42407539 | W25: -0.92371517 | X25: =ABS(L25)-ABS(R25) -> 0.00091581661 | Y25: =ABS(M25)-ABS(S25) -> 0.019703521 | Z25: =ABS(N25)-ABS(T25) -> 0.026457057 | AA25: =ABS(O25)-ABS(U25) -> 0.0072567584 | AB25: =ABS(P25)-ABS(V25) -> 0.11169783 | AC25: =ABS(Q25)-ABS(W25) -> 0.062513117
... A42: 0.2 | B42: 0.2 | C42: 4.712 | D42: =PI()/2 -> 1.5707963 | E42: 0.1 | F42: 0.08 | G42: 3.927 | H42: =PI()/2 -> 1.5707963 | I42: 0 | J42: 0 | K42: 0 | L42: -0.0012752726 | M42: 0.042479593 | N42: -0.010458088 | O42: -0.0027824324 | P42: -0.054970372 | Q42: -0.1535165 | R42: -3.5639316e-13 | S42: 0.068976346 | T42: -0.012039043 | U42: -0.030104293 | V42: -0.070759952 | W42: -0.26861184 | X42: =ABS(L42)-ABS(R42) -> 0.0012752726 | Y42: =ABS(M42)-ABS(S42) -> -0.026496753 | Z42: =ABS(N42)-ABS(T42) -> -0.0015809547 | AA42: =ABS(O42)-ABS(U42) -> -0.02732186 | AB42: =ABS(P42)-ABS(V42) -> -0.015789579 | AC42: =ABS(Q42)-ABS(W42) -> -0.11509533
X44: =AVERAGE(X3:X42) -> 0.0022374059 | Y44: =AVERAGE(Y3:Y42) -> 0.0070939595 | Z44: =AVERAGE(Z3:Z42) -> 0.0066149356 | AA44: =AVERAGE(AA3:AA42) -> 0.017416788 | AB44: =AVERAGE(AB3:AB42) -> 0.024593539 | AC44: =AVERAGE(AC3:AC42) -> 0.011426307

Sheet Distal Vali (double, simulated)
A1: Ground Truth | L1: 6-Axis FT Sensor | R1: SoRoSim get_distal_value | AA1: Distal Errors | AI1: Stats
A2: F1 (N) | B2: s1 (m) | C2: el1 (rad) | D2: az1 (rad) | E2: F2 (N) | F2: s2 (m) | G2: el2 (rad) | H2: az2 (rad) | I2: tau1 (N) | J2: tau2 (N) | K2: tau3 (N) | L2: Tx (Nm) | M2: Ty (Nm) | N2: Tz(Nm) | O2: Fx (N) | P2: Fy (N) | Q2: Fz (N) | R2: F1 (N) | S2: s1 (m) | T2: el1 (rad) | U2: az1 (rad) | V2: F2 (N) | W2: s2 (m) | X2: el2 (rad) | Y2: az2 (rad) | Z2: f_final | AA2: F1 (N) | AB2: s1 (m) | AC2: el1 (rad) | AD2: az1 (rad) | AE2: F2 (N) | AF2: s2 (m) | AG2: el2 (rad) | AH2: az2 (rad) | AI2: force_error | AJ2: position_error | AK2: angle_error | AL2: min_f | AN2: Absolute Mean Error
A3: ='Proximal Validation (double)'!A3 -> 0.2 | B3: ='Proximal Validation (double)'!B3 -> 0.1 | C3: ='Proximal Validation (double)'!C3 -> 1.571 | D3: ='Proximal Validation (double)'!D3 -> 1.5707963 | E3: ='Proximal Validation (double)'!E3 -> 1 | F3: ='Proximal Validation (double)'!F3 -> 0.04 | G3: ='Proximal Validation (double)'!G3 -> 3.142 | H3: ='Proximal Validation (double)'!H3 -> 1.5707963 | ... K3: ='Proximal Validation (double)'!K3 -> 0 | R3: 0.22547476 | S3: 0.11383244 | T3: 2.2803398 | U3: 1.5707963 | V3: 0.85359593 | W3: 0.027190558 | X3: 3.1081982 | Y3: 1.5707963 | Z3: 7.0657008e-07 | AA3: =R3-A3 -> 0.025474764 | AB3: =S3-B3 -> 0.013832444 | AC3: =T3-C3 -> 0.70933978 | AD3: =U3-D3 -> 0 | AE3: =V3-E3 -> -0.14640407 | AF3: =W3-F3 -> -0.012809442 | AG3: =X3-G3 -> -0.033801752 | AH3: =Y3-H3 -> 0 | AI3: =AVERAGE(ABS(AA3),ABS(AE3)) -> 0.085939417 | AJ3: =AVERAGE(ABS(AB3),ABS(AF3)) -> 0.013320943 | AK3: =AVERAGE(ABS(AC3),ABS(AG3)) -> 0.37157076 | AL3: =MIN(A3,E3) -> 0.2 | AN3: F1 (N) | AO3: s1 (m) | AP3: el1 (rad) | AQ3: az1 (rad) | AR3: F2 (N) | AS3: s2 (m) | AT3: el2 (rad) | AU3: az2 (rad)
A4: ='Proximal Validation (double)'!A4 -> 1 | B4: ='Proximal Validation (double)'!B4 -> 0.1 | C4: ='Proximal Validation (double)'!C4 -> 1.571 | D4: ='Proximal Validation (double)'!D4 -> 1.5707963 | E4: ='Proximal Validation (double)'!E4 -> 1 | F4: ='Proximal Validation (double)'!F4 -> 0.08 | G4: ='Proximal Validation (double)'!G4 -> 3.142 | H4: ='Proximal Validation (double)'!H4 -> 1.5707963 | ... K4: ='Proximal Validation (double)'!K4 -> 0 | R4: 0.80543726 | S4: 0.10619206 | T4: 1.8507048 | U4: 1.5707963 | V4: 0.80964876 | W4: 0.072180857 | X4: 2.8592387 | Y4: 1.5707963 | Z4: 3.0314235e-06 | AA4: =R4-A4 -> -0.19456274 | AB4: =S4-B4 -> 0.0061920644 | AC4: =T4-C4 -> 0.27970479 | AD4: =U4-D4 -> 0 | AE4: =V4-E4 -> -0.19035124 | AF4: =W4-F4 -> -0.007819143 | AG4: =X4-G4 -> -0.28276126 | AH4: =Y4-H4 -> 0 | AI4: =AVERAGE(ABS(AA4),ABS(AE4)) -> 0.19245699 | AJ4: =AVERAGE(ABS(AB4),ABS(AF4)) -> 0.0070056037 | AK4: =AVERAGE(ABS(AC4),ABS(AG4)) -> 0.28123302 | AL4: =MIN(A4,E4) -> 1 | AN4: {=AVERAGE(ABS(AA3:AA42))} -> 0.17122841 | AO4: {=AVERAGE(ABS(AB3:AB42))} -> 0.026636849 | AP4: {=AVERAGE(ABS(AC3:AC42))} -> 0.40222669 | AQ4: {=AVERAGE(ABS(AD3:AD42))} -> 0 | AR4: {=AVERAGE(ABS(AE3:AE42))} -> 0.22050928 | AS4: {=AVERAGE(ABS(AF3:AF42))} -> 0.031118941 | AT4: {=AVERAGE(ABS(AG3:AG42))} -> 0.36293546 | AU4: {=AVERAGE(ABS(AH3:AH42))} -> 0
A5: ='Proximal Validation (double)'!A5 -> 0.5 | B5: ='Proximal Validation (double)'!B5 -> 0.1 | C5: ='Proximal Validation (double)'!C5 -> 1.571 | D5: ='Proximal Validation (double)'!D5 -> 1.5707963 | E5: ='Proximal Validation (double)'!E5 -> 0.2 | F5: ='Proximal Validation (double)'!F5 -> 0.02 | G5: ='Proximal Validation (double)'!G5 -> 3.927 | H5: ='Proximal Validation (double)'!H5 -> 1.5707963 | ... K5: ='Proximal Validation (double)'!K5 -> 0 | R5: 0.4885413 | S5: 0.19986731 | T5: 5.8705441 | U5: 1.5707963 | V5: 0.80825762 | W5: 0.15446928 | X5: 2.3859268 | Y5: 1.5707963 | Z5: 1.3429432e-08 | AA5: =R5-A5 -> -0.011458696 | AB5: =S5-B5 -> 0.099867312 | AC5: =T5-C5 -> 4.2995441 | AD5: =U5-D5 -> 0 | AE5: =V5-E5 -> 0.60825762 | AF5: =W5-F5 -> 0.13446928 | AG5: =X5-G5 -> -1.5410732 | AH5: =Y5-H5 -> 0 | AI5: =AVERAGE(ABS(AA5),ABS(AE5)) -> 0.30985816 | AJ5: =AVERAGE(ABS(AB5),ABS(AF5)) -> 0.1171683 | AK5: =AVERAGE(ABS(AC5),ABS(AG5)) -> 2.9203087 | AL5: =MIN(A5,E5) -> 0.2 | AN5: Absolute Mean Error (Across Both Forces)
A6: ='Proximal Validation (double)'!A6 -> 0.9 | B6: ='Proximal Validation (double)'!B6 -> 0.1 | C6: ='Proximal Validation (double)'!C6 -> 1.571 | D6: ='Proximal Validation (double)'!D6 -> 1.5707963 | E6: ='Proximal Validation (double)'!E6 -> 0.2 | F6: ='Proximal Validation (double)'!F6 -> 0.08 | G6: ='Proximal Validation (double)'!G6 -> 4.712 | H6: ='Proximal Validation (double)'!H6 -> 1.5707963 | ... K6: ='Proximal Validation (double)'!K6 -> 0 | R6: 0.82907776 | S6: 0.10511964 | T6: 2.0520399 | U6: 1.5707963 | V6: 0.38509788 | W6: 0.10499181 | X6: 6.1926018 | Y6: 1.5707963 | Z6: 2.4985503e-07 | AA6: =R6-A6 -> -0.070922244 | AB6: =S6-B6 -> 0.0051196357 | AC6: =T6-C6 -> 0.48103989 | AD6: =U6-D6 -> 0 | AE6: =V6-E6 -> 0.18509788 | AF6: =W6-F6 -> 0.024991813 | AG6: =X6-G6 -> 1.4806018 | AH6: =Y6-H6 -> 0 | AI6: =AVERAGE(ABS(AA6),ABS(AE6)) -> 0.12801006 | AJ6: =AVERAGE(ABS(AB6),ABS(AF6)) -> 0.015055724 | AK6: =AVERAGE(ABS(AC6),ABS(AG6)) -> 0.98082082 | AL6: =MIN(A6,E6) -> 0.2 | AN6: force_error | AO6: position_error | AP6: angle_error
A7: ='Proximal Validation (double)'!A7 -> 0.1 | B7: ='Proximal Validation (double)'!B7 -> 0.12 | C7: ='Proximal Validation (double)'!C7 -> 1.571 | D7: ='Proximal Validation (double)'!D7 -> 1.5707963 | E7: ='Proximal Validation (double)'!E7 -> 1 | F7: ='Proximal Validation (double)'!F7 -> 0.06 | G7: ='Proximal Validation (double)'!G7 -> 3.927 | H7: ='Proximal Validation (double)'!H7 -> 1.5707963 | ... K7: ='Proximal Validation (double)'!K7 -> 0 | R7: 0.19539383 | S7: 0.079883256 | T7: 2.8082368 | U7: 1.5707963 | V7: 0.85046849 | W7: 0.053046359 | X7: 4.050828 | Y7: 1.5707963 | Z7: 8.2314199e-09 | AA7: =R7-A7 -> 0.095393835 | AB7: =S7-B7 -> -0.040116744 | AC7: =T7-C7 -> 1.2372368 | AD7: =U7-D7 -> 0 | AE7: =V7-E7 -> -0.14953151 | AF7: =W7-F7 -> -0.0069536413 | AG7: =X7-G7 -> 0.12382801 | AH7: =Y7-H7 -> 0 | AI7: =AVERAGE(ABS(AA7),ABS(AE7)) -> 0.12246267 | AJ7: =AVERAGE(ABS(AB7),ABS(AF7)) -> 0.023535193 | AK7: =AVERAGE(ABS(AC7),ABS(AG7)) -> 0.6805324 | AL7: =MIN(A7,E7) -> 0.1 | AN7: =AVERAGE(AN4,AR4) -> 0.19586884 | AO7: =AVERAGE(AO4,AS4) -> 0.028877895 | AP7: =AVERAGE(AP4,AT4) -> 0.38258108
A8: ='Proximal Validation (double)'!A8 -> 0.8 | B8: ='Proximal Validation (double)'!B8 -> 0.16 | C8: ='Proximal Validation (double)'!C8 -> 1.571 | D8: ='Proximal Validation (double)'!D8 -> 1.5707963 | E8: ='Proximal Validation (double)'!E8 -> 0.8 | F8: ='Proximal Validation (double)'!F8 -> 0.06 | G8: ='Proximal Validation (double)'!G8 -> 3.927 | H8: ='Proximal Validation (double)'!H8 -> 1.5707963 | ... K8: ='Proximal Validation (double)'!K8 -> 0 | R8: 0.70764446 | S8: 0.16700381 | T8: 1.6376329 | U8: 1.5707963 | V8: 0.7015794 | W8: 0.050549756 | X8: 3.8772688 | Y8: 1.5707963 | Z8: 9.7388293e-08 | AA8: =R8-A8 -> -0.09235554 | AB8: =S8-B8 -> 0.0070038067 | AC8: =T8-C8 -> 0.066632903 | AD8: =U8-D8 -> 0 | AE8: =V8-E8 -> -0.098420596 | AF8: =W8-F8 -> -0.0094502437 | AG8: =X8-G8 -> -0.049731217 | AH8: =Y8-H8 -> 0 | AI8: =AVERAGE(ABS(AA8),ABS(AE8)) -> 0.095388068 | AJ8: =AVERAGE(ABS(AB8),ABS(AF8)) -> 0.0082270252 | AK8: =AVERAGE(ABS(AC8),ABS(AG8)) -> 0.05818206 | AL8: =MIN(A8,E8) -> 0.8 | AN8: with 0.1 cuttoff
A9: ='Proximal Validation (double)'!A9 -> 0.1 | B9: ='Proximal Validation (double)'!B9 -> 0.18 | C9: ='Proximal Validation (double)'!C9 -> 1.571 | D9: ='Proximal Validation (double)'!D9 -> 1.5707963 | E9: ='Proximal Validation (double)'!E9 -> 0.1 | F9: ='Proximal Validation (double)'!F9 -> 0.02 | G9: ='Proximal Validation (double)'!G9 -> 3.142 | H9: ='Proximal Validation (double)'!H9 -> 1.5707963 | ... K9: ='Proximal Validation (double)'!K9 -> 0 | R9: 0.5735698 | S9: 0.11963616 | T9: 0.78463508 | U9: 1.5707963 | V9: 0.59113532 | W9: 0.099947918 | X9: 3.6848769 | Y9: 1.5707963 | Z9: 1.2138656e-07 | AA9: =R9-A9 -> 0.4735698 | AB9: =S9-B9 -> -0.060363839 | AC9: =T9-C9 -> -0.78636492 | AD9: =U9-D9 -> 0 | AE9: =V9-E9 -> 0.49113532 | AF9: =W9-F9 -> 0.079947918 | AG9: =X9-G9 -> 0.54287694 | AH9: =Y9-H9 -> 0 | AI9: =AVERAGE(ABS(AA9),ABS(AE9)) -> 0.48235256 | AJ9: =AVERAGE(ABS(AB9),ABS(AF9)) -> 0.070155878 | AK9: =AVERAGE(ABS(AC9),ABS(AG9)) -> 0.66462093 | AL9: =MIN(A9,E9) -> 0.1 | AN9: =AVERAGE(AI3,AI4,AI5,AI6,AI8,AI11,AI12,AI14,AI15,AI17,AI18,AI20,AI23,AI24,AI25,AI26,AI29,AI30,AI32,AI35,AI36,AI37,AI38,AI40,AI41) -> 0.11995914 | AO9: =AVERAGE(AJ3,AJ4,AJ5,AJ6,AJ8,AJ11,AJ12,AJ14,AJ15,AJ17,AJ18,AJ20,AJ23,AJ24,AJ25,AJ26,AJ29,AJ30,AJ32,AJ35,AJ36,AJ37,AJ38,AJ40,AJ41) -> 0.021010645 | AP9: =AVERAGE(AK3,AK4,AK5,AK6,AK8,AK11,AK12,AK14,AK15,AK17,AK18,AK20,AK23,AK24,AK25,AK26,AK29,AK30,AK32,AK35,AK36,AK37,AK38,AK40,AK41) -> 0.32295366
A10: ='Proximal Validation (double)'!A10 -> 0.9 | B10: ='Proximal Validation (double)'!B10 -> 0.18 | C10: ='Proximal Validation (double)'!C10 -> 1.571 | D10: ='Proximal Validation (double)'!D10 -> 1.5707963 | E10: ='Proximal Validation (double)'!E10 -> 0.1 | F10: ='Proximal Validation (double)'!F10 -> 0.08 | G10: ='Proximal Validation (double)'!G10 -> 4.712 | H10: ='Proximal Validation (double)'!H10 -> 1.5707963 | ... K10: ='Proximal Validation (double)'!K10 -> 0 | R10: 0.53332271 | S10: 0.19182642 | T10: 0.27596289 | U10: 1.5707963 | V10: 0.83948774 | W10: 0.1918178 | X10: 2.2287845 | Y10: 1.5707963 | Z10: 3.7168067e-07 | AA10: =R10-A10 -> -0.36667729 | AB10: =S10-B10 -> 0.011826419 | AC10: =T10-C10 -> -1.2950371 | AD10: =U10-D10 -> 0 | AE10: =V10-E10 -> 0.73948774 | AF10: =W10-F10 -> 0.1118178 | AG10: =X10-G10 -> -2.4832155 | AH10: =Y10-H10 -> 0 | AI10: =AVERAGE(ABS(AA10),ABS(AE10)) -> 0.55308251 | AJ10: =AVERAGE(ABS(AB10),ABS(AF10)) -> 0.06182211 | AK10: =AVERAGE(ABS(AC10),ABS(AG10)) -> 1.8891263 | AL10: =MIN(A10,E10) -> 0.1 | AN10: with 0.2 cuttof
A11: ='Proximal Validation (double)'!A11 -> 0.3 | B11: ='Proximal Validation (double)'!B11 -> 0.18 | C11: ='Proximal Validation (double)'!C11 -> 1.571 | D11: ='Proximal Validation (double)'!D11 -> 1.5707963 | E11: ='Proximal Validation (double)'!E11 -> 0.9 | F11: ='Proximal Validation (double)'!F11 -> 0.08 | G11: ='Proximal Validation (double)'!G11 -> 4.712 | H11: ='Proximal Validation (double)'!H11 -> 1.5707963 | ... K11: ='Proximal Validation (double)'!K11 -> 0 | R11: 0.2738423 | S11: 0.19100968 | T11: 1.5711914 | U11: 1.5707963 | V11: 0.87336164 | W11: 0.080253982 | X11: 4.7121184 | Y11: 1.5707963 | Z11: 1.4723e-08 | AA11: =R11-A11 -> -0.026157698 | AB11: =S11-B11 -> 0.011009682 | AC11: =T11-C11 -> 0.00019138948 | AD11: =U11-D11 -> 0 | AE11: =V11-E11 -> -0.026638357 | AF11: =W11-F11 -> 0.00025398211 | AG11: =X11-G11 -> 0.00011843569 | AH11: =Y11-H11 -> 0 | AI11: =AVERAGE(ABS(AA11),ABS(AE11)) -> 0.026398027 | AJ11: =AVERAGE(ABS(AB11),ABS(AF11)) -> 0.0056318321 | AK11: =AVERAGE(ABS(AC11),ABS(AG11)) -> 0.00015491258 | AL11: =MIN(A11,E11) -> 0.3 | AN11: =AVERAGE(AI4,AI8,AI11,AI12,AI14,AI15,AI17,AI18,AI20,AI25,AI26,AI30,AI32,AI35,AI36,AI37,AI40,AI41) -> 0.10433109 | AO11: =AVERAGE(AJ4,AJ8,AJ11,AJ12,AJ14,AJ15,AJ17,AJ18,AJ20,AJ25,AJ26,AJ30,AJ32,AJ35,AJ36,AJ37,AJ40,AJ41) -> 0.011263999 | AP11: =AVERAGE(AK4,AK8,AK11,AK12,AK14,AK15,AK17,AK18,AK20,AK25,AK26,AK30,AK32,AK35,AK36,AK37,AK40,AK41) -> 0.11315865
A12: ='Proximal Validation (double)'!A12 -> 0.9 | B12: ='Proximal Validation (double)'!B12 -> 0.2 | C12: ='Proximal Validation (double)'!C12 -> 1.571 | D12: ='Proximal Validation (double)'!D12 -> 1.5707963 | E12: ='Proximal Validation (double)'!E12 -> 1 | F12: ='Proximal Validation (double)'!F12 -> 0.02 | G12: ='Proximal Validation (double)'!G12 -> 3.142 | H12: ='Proximal Validation (double)'!H12 -> 1.5707963 | ... K12: ='Proximal Validation (double)'!K12 -> 0 | R12: 0.90049966 | S12: 0.19980159 | T12: 1.5734121 | U12: 1.5707963 | V12: 0.99816728 | W12: 0.020000012 | X12: 3.1427762 | Y12: 1.5707963 | Z12: 1.2346604e-07 | AA12: =R12-A12 -> 0.00049966066 | AB12: =S12-B12 -> -0.00019840819 | AC12: =T12-C12 -> 0.0024121352 | AD12: =U12-D12 -> 0 | AE12: =V12-E12 -> -0.0018327249 | AF12: =W12-F12 -> 1.1799858e-08 | AG12: =X12-G12 -> 0.00077622586 | AH12: =Y12-H12 -> 0 | AI12: =AVERAGE(ABS(AA12),ABS(AE12)) -> 0.0011661928 | AJ12: =AVERAGE(ABS(AB12),ABS(AF12)) -> 9.9209994e-05 | AK12: =AVERAGE(ABS(AC12),ABS(AG12)) -> 0.0015941805 | AL12: =MIN(A12,E12) -> 0.9 | AN12: 0.2 cutoof + no close
A13: ='Proximal Validation (double)'!A13 -> 0.1 | B13: ='Proximal Validation (double)'!B13 -> 0.2 | C13: ='Proximal Validation (double)'!C13 -> 1.571 | D13: ='Proximal Validation (double)'!D13 -> 1.5707963 | E13: ='Proximal Validation (double)'!E13 -> 0.3 | F13: ='Proximal Validation (double)'!F13 -> 0.08 | G13: ='Proximal Validation (double)'!G13 -> 3.142 | H13: ='Proximal Validation (double)'!H13 -> 1.5707963 | ... K13: ='Proximal Validation (double)'!K13 -> 0 | R13: 0.19055945 | S13: 0.15353675 | T13: 2.3652999 | U13: 1.5707963 | V13: 0.16747321 | W13: 0.020000001 | X13: 3.3437355 | Y13: 1.5707963 | Z13: 1.2413494e-07 | AA13: =R13-A13 -> 0.090559451 | AB13: =S13-B13 -> -0.046463246 | AC13: =T13-C13 -> 0.79429986 | AD13: =U13-D13 -> 0 | AE13: =V13-E13 -> -0.13252679 | AF13: =W13-F13 -> -0.059999999 | AG13: =X13-G13 -> 0.20173545 | AH13: =Y13-H13 -> 0 | AI13: =AVERAGE(ABS(AA13),ABS(AE13)) -> 0.11154312 | AJ13: =AVERAGE(ABS(AB13),ABS(AF13)) -> 0.053231623 | AK13: =AVERAGE(ABS(AC13),ABS(AG13)) -> 0.49801766 | AL13: =MIN(A13,E13) -> 0.1 | AN13: =AVERAGE(AI8,AI11,AI12,AI14,AI15,AI17,AI18,AI20,AI26,AI30,AI32,AI35,AI37,AI40,AI41) -> 0.068832561 | AO13: =AVERAGE(AJ8,AJ11,AJ12,AJ14,AJ15,AJ17,AJ18,AJ20,AJ26,AJ30,AJ32,AJ35,AJ37,AJ40,AJ41) -> 0.0092324665 | AP13: =AVERAGE(AK8,AK11,AK12,AK14,AK15,AK17,AK18,AK20,AK26,AK30,AK32,AK35,AK37,AK40,AK41) -> 0.063501007
A14: ='Proximal Validation (double)'!A14 -> 0.9 | B14: ='Proximal Validation (double)'!B14 -> 0.2 | C14: ='Proximal Validation (double)'!C14 -> 1.571 | D14: ='Proximal Validation (double)'!D14 -> 1.5707963 | E14: ='Proximal Validation (double)'!E14 -> 0.3 | F14: ='Proximal Validation (double)'!F14 -> 0.02 | G14: ='Proximal Validation (double)'!G14 -> 4.712 | H14: ='Proximal Validation (double)'!H14 -> 1.5707963 | ... K14: ='Proximal Validation (double)'!K14 -> 0 | R14: 0.9224609 | S14: 0.19467646 | T14: 1.5706802 | U14: 1.5707963 | V14: 0.32885379 | W14: 0.024583795 | X14: 4.7095245 | Y14: 1.5707963 | Z14: 6.2014404e-08 | AA14: =R14-A14 -> 0.022460901 | AB14: =S14-B14 -> -0.0053235405 | AC14: =T14-C14 -> -0.00031978205 | AD14: =U14-D14 -> 0 | AE14: =V14-E14 -> 0.028853786 | AF14: =W14-F14 -> 0.0045837952 | AG14: =X14-G14 -> -0.002475514 | AH14: =Y14-H14 -> 0 | AI14: =AVERAGE(ABS(AA14),ABS(AE14)) -> 0.025657343 | AJ14: =AVERAGE(ABS(AB14),ABS(AF14)) -> 0.0049536679 | AK14: =AVERAGE(ABS(AC14),ABS(AG14)) -> 0.001397648 | AL14: =MIN(A14,E14) -> 0.3
A15: ='Proximal Validation (double)'!A15 -> 0.9 | B15: ='Proximal Validation (double)'!B15 -> 0.1 | C15: ='Proximal Validation (double)'!C15 -> 2.356 | D15: ='Proximal Validation (double)'!D15 -> 1.5707963 | E15: ='Proximal Validation (double)'!E15 -> 0.9 | F15: ='Proximal Validation (double)'!F15 -> 0.02 | G15: ='Proximal Validation (double)'!G15 -> 4.712 | H15: ='Proximal Validation (double)'!H15 -> 1.5707963 | ... K15: ='Proximal Validation (double)'!K15 -> 0 | R15: 0.91550308 | S15: 0.099195561 | T15: 2.3470108 | U15: 1.5707963 | V15: 0.91675215 | W15: 0.021094355 | X15: 4.7175794 | Y15: 1.5707963 | Z15: 2.0749134e-08 | AA15: =R15-A15 -> 0.01550308 | AB15: =S15-B15 -> -0.00080443914 | AC15: =T15-C15 -> -0.0089891837 | AD15: =U15-D15 -> 0 | AE15: =V15-E15 -> 0.016752154 | AF15: =W15-F15 -> 0.0010943547 | AG15: =X15-G15 -> 0.0055794136 | AH15: =Y15-H15 -> 0 | AI15: =AVERAGE(ABS(AA15),ABS(AE15)) -> 0.016127617 | AJ15: =AVERAGE(ABS(AB15),ABS(AF15)) -> 0.00094939691 | AK15: =AVERAGE(ABS(AC15),ABS(AG15)) -> 0.0072842987 | AL15: =MIN(A15,E15) -> 0.9
A16: ='Proximal Validation (double)'!A16 -> 0.4 | B16: ='Proximal Validation (double)'!B16 -> 0.12 | C16: ='Proximal Validation (double)'!C16 -> 2.356 | D16: ='Proximal Validation (double)'!D16 -> 1.5707963 | E16: ='Proximal Validation (double)'!E16 -> 0.1 | F16: ='Proximal Validation (double)'!F16 -> 0.06 | G16: ='Proximal Validation (double)'!G16 -> 3.142 | H16: ='Proximal Validation (double)'!H16 -> 1.5707963 | ... K16: ='Proximal Validation (double)'!K16 -> 0 | R16: 0.51175535 | S16: 0.11530748 | T16: 1.1709203 | U16: 1.5707963 | V16: 0.61177625 | W16: 0.10803659 | X16: 3.4548621 | Y16: 1.5707963 | Z16: 4.0947298e-09 | AA16: =R16-A16 -> 0.11175535 | AB16: =S16-B16 -> -0.0046925216 | AC16: =T16-C16 -> -1.1850797 | AD16: =U16-D16 -> 0 | AE16: =V16-E16 -> 0.51177625 | AF16: =W16-F16 -> 0.048036591 | AG16: =X16-G16 -> 0.31286214 | AH16: =Y16-H16 -> 0 | AI16: =AVERAGE(ABS(AA16),ABS(AE16)) -> 0.3117658 | AJ16: =AVERAGE(ABS(AB16),ABS(AF16)) -> 0.026364556 | AK16: =AVERAGE(ABS(AC16),ABS(AG16)) -> 0.74897092 | AL16: =MIN(A16,E16) -> 0.1
A17: ='Proximal Validation (double)'!A17 -> 1 | B17: ='Proximal Validation (double)'!B17 -> 0.14 | C17: ='Proximal Validation (double)'!C17 -> 2.356 | D17: ='Proximal Validation (double)'!D17 -> 1.5707963 | E17: ='Proximal Validation (double)'!E17 -> 0.4 | F17: ='Proximal Validation (double)'!F17 -> 0.04 | G17: ='Proximal Validation (double)'!G17 -> 3.927 | H17: ='Proximal Validation (double)'!H17 -> 1.5707963 | ... K17: ='Proximal Validation (double)'!K17 -> 0 | R17: 0.99978787 | S17: 0.13963844 | T17: 2.1719559 | U17: 1.5707963 | V17: 0.58147093 | W17: 0.071887493 | X17: 3.8968966 | Y17: 1.5707963 | Z17: 2.4428602e-06 | AA17: =R17-A17 -> -0.00021213205 | AB17: =S17-B17 -> -0.00036156213 | AC17: =T17-C17 -> -0.18404413 | AD17: =U17-D17 -> 0 | AE17: =V17-E17 -> 0.18147093 | AF17: =W17-F17 -> 0.031887493 | AG17: =X17-G17 -> -0.030103413 | AH17: =Y17-H17 -> 0 | AI17: =AVERAGE(ABS(AA17),ABS(AE17)) -> 0.090841531 | AJ17: =AVERAGE(ABS(AB17),ABS(AF17)) -> 0.016124528 | AK17: =AVERAGE(ABS(AC17),ABS(AG17)) -> 0.10707377 | AL17: =MIN(A17,E17) -> 0.4
A18: ='Proximal Validation (double)'!A18 -> 0.4 | B18: ='Proximal Validation (double)'!B18 -> 0.18 | C18: ='Proximal Validation (double)'!C18 -> 2.356 | D18: ='Proximal Validation (double)'!D18 -> 1.5707963 | E18: ='Proximal Validation (double)'!E18 -> 0.7 | F18: ='Proximal Validation (double)'!F18 -> 0.04 | G18: ='Proximal Validation (double)'!G18 -> 3.142 | H18: ='Proximal Validation (double)'!H18 -> 1.5707963 | ... K18: ='Proximal Validation (double)'!K18 -> 0 | R18: 0.36856869 | S18: 0.18846391 | T18: 2.3312146 | U18: 1.5707963 | V18: 0.72924992 | W18: 0.042776626 | X18: 3.1193618 | Y18: 1.5707963 | Z18: 7.9960652e-14 | AA18: =R18-A18 -> -0.03143131 | AB18: =S18-B18 -> 0.0084639147 | AC18: =T18-C18 -> -0.024785434 | AD18: =U18-D18 -> 0 | AE18: =V18-E18 -> 0.029249923 | AF18: =W18-F18 -> 0.0027766261 | AG18: =X18-G18 -> -0.022638214 | AH18: =Y18-H18 -> 0 | AI18: =AVERAGE(ABS(AA18),ABS(AE18)) -> 0.030340616 | AJ18: =AVERAGE(ABS(AB18),ABS(AF18)) -> 0.0056202704 | AK18: =AVERAGE(ABS(AC18),ABS(AG18)) -> 0.023711824 | AL18: =MIN(A18,E18) -> 0.4
A19: ='Proximal Validation (double)'!A19 -> 0.1 | B19: ='Proximal Validation (double)'!B19 -> 0.18 | C19: ='Proximal Validation (double)'!C19 -> 2.356 | D19: ='Proximal Validation (double)'!D19 -> 1.5707963 | E19: ='Proximal Validation (double)'!E19 -> 0.2 | F19: ='Proximal Validation (double)'!F19 -> 0.06 | G19: ='Proximal Validation (double)'!G19 -> 4.712 | H19: ='Proximal Validation (double)'!H19 -> 1.5707963 | ... K19: ='Proximal Validation (double)'!K19 -> 0 | R19: 0.2043161 | S19: 0.13889568 | T19: 2.1602992 | U19: 1.5707963 | V19: 0.3021959 | W19: 0.076283938 | X19: 4.8543772 | Y19: 1.5707963 | Z19: 5.8928476e-08 | AA19: =R19-A19 -> 0.1043161 | AB19: =S19-B19 -> -0.041104318 | AC19: =T19-C19 -> -0.19570079 | AD19: =U19-D19 -> 0 | AE19: =V19-E19 -> 0.1021959 | AF19: =W19-F19 -> 0.016283938 | AG19: =X19-G19 -> 0.14237716 | AH19: =Y19-H19 -> 0 | AI19: =AVERAGE(ABS(AA19),ABS(AE19)) -> 0.103256 | AJ19: =AVERAGE(ABS(AB19),ABS(AF19)) -> 0.028694128 | AK19: =AVERAGE(ABS(AC19),ABS(AG19)) -> 0.16903898 | AL19: =MIN(A19,E19) -> 0.1
A20: ='Proximal Validation (double)'!A20 -> 0.9 | B20: ='Proximal Validation (double)'!B20 -> 0.2 | C20: ='Proximal Validation (double)'!C20 -> 2.356 | D20: ='Proximal Validation (double)'!D20 -> 1.5707963 | E20: ='Proximal Validation (double)'!E20 -> 0.3 | F20: ='Proximal Validation (double)'!F20 -> 0.06 | G20: ='Proximal Validation (double)'!G20 -> 3.142 | H20: ='Proximal Validation (double)'!H20 -> 1.5707963 | ... K20: ='Proximal Validation (double)'!K20 -> 0 | R20: 0.92494272 | S20: 0.19519421 | T20: 2.3610726 | U20: 1.5707963 | V20: 0.27794418 | W20: 0.056612427 | X20: 3.2050693 | Y20: 1.5707963 | Z20: 4.4629547e-08 | AA20: =R20-A20 -> 0.024942725 | AB20: =S20-B20 -> -0.0048057941 | AC20: =T20-C20 -> 0.0050725529 | AD20: =U20-D20 -> 0 | AE20: =V20-E20 -> -0.022055817 | AF20: =W20-F20 -> -0.0033875726 | AG20: =X20-G20 -> 0.063069303 | AH20: =Y20-H20 -> 0 | AI20: =AVERAGE(ABS(AA20),ABS(AE20)) -> 0.023499271 | AJ20: =AVERAGE(ABS(AB20),ABS(AF20)) -> 0.0040966833 | AK20: =AVERAGE(ABS(AC20),ABS(AG20)) -> 0.034070928 | AL20: =MIN(A20,E20) -> 0.3
A21: ='Proximal Validation (double)'!A21 -> 0.1 | B21: ='Proximal Validation (double)'!B21 -> 0.1 | C21: ='Proximal Validation (double)'!C21 -> 3.142 | D21: ='Proximal Validation (double)'!D21 -> 1.5707963 | E21: ='Proximal Validation (double)'!E21 -> 0.3 | F21: ='Proximal Validation (double)'!F21 -> 0.08 | G21: ='Proximal Validation (double)'!G21 -> 3.927 | H21: ='Proximal Validation (double)'!H21 -> 1.5707963 | ... K21: ='Proximal Validation (double)'!K21 -> 0 | R21: 0.24931862 | S21: 0.087862751 | T21: 3.0492851 | U21: 1.5707963 | V21: 0.24368015 | W21: 0.080556753 | X21: 4.4472012 | Y21: 1.5707963 | Z21: 2.3128171e-07 | AA21: =R21-A21 -> 0.14931862 | AB21: =S21-B21 -> -0.012137249 | AC21: =T21-C21 -> -0.092714901 | AD21: =U21-D21 -> 0 | AE21: =V21-E21 -> -0.056319849 | AF21: =W21-F21 -> 0.0005567527 | AG21: =X21-G21 -> 0.52020115 | AH21: =Y21-H21 -> 0 | AI21: =AVERAGE(ABS(AA21),ABS(AE21)) -> 0.10281923 | AJ21: =AVERAGE(ABS(AB21),ABS(AF21)) -> 0.0063470008 | AK21: =AVERAGE(ABS(AC21),ABS(AG21)) -> 0.30645803 | AL21: =MIN(A21,E21) -> 0.1
A22: ='Proximal Validation (double)'!A22 -> 0.1 | B22: ='Proximal Validation (double)'!B22 -> 0.2 | C22: ='Proximal Validation (double)'!C22 -> 3.142 | D22: ='Proximal Validation (double)'!D22 -> 1.5707963 | E22: ='Proximal Validation (double)'!E22 -> 0.8 | F22: ='Proximal Validation (double)'!F22 -> 0.02 | G22: ='Proximal Validation (double)'!G22 -> 3.927 | H22: ='Proximal Validation (double)'!H22 -> 1.5707963 | ... K22: ='Proximal Validation (double)'!K22 -> 0 | R22: 0.50277019 | S22: 0.055468089 | T22: 3.1456282 | U22: 1.5707963 | V22: 0.58675798 | W22: 0.020000543 | X22: 4.4310777 | Y22: 1.5707963 | Z22: 2.0980264e-06 | AA22: =R22-A22 -> 0.40277019 | AB22: =S22-B22 -> -0.14453191 | AC22: =T22-C22 -> 0.0036281941 | AD22: =U22-D22 -> 0 | AE22: =V22-E22 -> -0.21324202 | AF22: =W22-F22 -> 5.4280708e-07 | AG22: =X22-G22 -> 0.50407775 | AH22: =Y22-H22 -> 0 | AI22: =AVERAGE(ABS(AA22),ABS(AE22)) -> 0.30800611 | AJ22: =AVERAGE(ABS(AB22),ABS(AF22)) -> 0.072266227 | AK22: =AVERAGE(ABS(AC22),ABS(AG22)) -> 0.25385297 | AL22: =MIN(A22,E22) -> 0.1
A23: ='Proximal Validation (double)'!A23 -> 0.9 | B23: ='Proximal Validation (double)'!B23 -> 0.1 | C23: ='Proximal Validation (double)'!C23 -> 3.927 | D23: ='Proximal Validation (double)'!D23 -> 1.5707963 | E23: ='Proximal Validation (double)'!E23 -> 0.2 | F23: ='Proximal Validation (double)'!F23 -> 0.02 | G23: ='Proximal Validation (double)'!G23 -> 3.142 | H23: ='Proximal Validation (double)'!H23 -> 1.5707963 | ... K23: ='Proximal Validation (double)'!K23 -> 0 | R23: 0.86699225 | S23: 0.095388051 | T23: 4.1313562 | U23: 1.5707963 | V23: 0.37110664 | W23: 0.062327476 | X23: 2.9015003 | Y23: 1.5707963 | Z23: 2.7426181e-07 | AA23: =R23-A23 -> -0.033007751 | AB23: =S23-B23 -> -0.0046119491 | AC23: =T23-C23 -> 0.20435619 | AD23: =U23-D23 -> 0 | AE23: =V23-E23 -> 0.17110664 | AF23: =W23-F23 -> 0.042327476 | AG23: =X23-G23 -> -0.24049974 | AH23: =Y23-H23 -> 0 | AI23: =AVERAGE(ABS(AA23),ABS(AE23)) -> 0.10205719 | AJ23: =AVERAGE(ABS(AB23),ABS(AF23)) -> 0.023469712 | AK23: =AVERAGE(ABS(AC23),ABS(AG23)) -> 0.22242796 | AL23: =MIN(A23,E23) -> 0.2
A24: ='Proximal Validation (double)'!A24 -> 0.2 | B24: ='Proximal Validation (double)'!B24 -> 0.12 | C24: ='Proximal Validation (double)'!C24 -> 3.927 | D24: ='Proximal Validation (double)'!D24 -> 1.5707963 | E24: ='Proximal Validation (double)'!E24 -> 0.2 | F24: ='Proximal Validation (double)'!F24 -> 0.02 | G24: ='Proximal Validation (double)'!G24 -> 4.712 | H24: ='Proximal Validation (double)'!H24 -> 1.5707963 | ... K24: ='Proximal Validation (double)'!K24 -> 0 | R24: 0.21797974 | S24: 0.10255681 | T24: 3.7596769 | U24: 1.5707963 | V24: 0.21807441 | W24: 0.037357957 | X24: 4.8792028 | Y24: 1.5707963 | Z24: 1.2421441e-06 | AA24: =R24-A24 -> 0.01797974 | AB24: =S24-B24 -> -0.017443187 | AC24: =T24-C24 -> -0.16732312 | AD24: =U24-D24 -> 0 | AE24: =V24-E24 -> 0.018074407 | AF24: =W24-F24 -> 0.017357957 | AG24: =X24-G24 -> 0.16720275 | AH24: =Y24-H24 -> 0 | AI24: =AVERAGE(ABS(AA24),ABS(AE24)) -> 0.018027074 | AJ24: =AVERAGE(ABS(AB24),ABS(AF24)) -> 0.017400572 | AK24: =AVERAGE(ABS(AC24),ABS(AG24)) -> 0.16726294 | AL24: =MIN(A24,E24) -> 0.2
A25: ='Proximal Validation (double)'!A25 -> 0.6 | B25: ='Proximal Validation (double)'!B25 -> 0.12 | C25: ='Proximal Validation (double)'!C25 -> 3.927 | D25: ='Proximal Validation (double)'!D25 -> 1.5707963 | E25: ='Proximal Validation (double)'!E25 -> 0.5 | F25: ='Proximal Validation (double)'!F25 -> 0.08 | G25: ='Proximal Validation (double)'!G25 -> 4.712 | H25: ='Proximal Validation (double)'!H25 -> 1.5707963 | ... K25: ='Proximal Validation (double)'!K25 -> 0 | R25: 0.11836566 | S25: 0.17599701 | T25: 3.178204 | U25: 1.5707963 | V25: 0.9695049 | W25: 0.097769743 | X25: 4.3910435 | Y25: 1.5707963 | Z25: 3.8510462e-08 | AA25: =R25-A25 -> -0.48163434 | AB25: =S25-B25 -> 0.055997006 | AC25: =T25-C25 -> -0.74879601 | AD25: =U25-D25 -> 0 | AE25: =V25-E25 -> 0.4695049 | AF25: =W25-F25 -> 0.017769743 | AG25: =X25-G25 -> -0.32095646 | AH25: =Y25-H25 -> 0 | AI25: =AVERAGE(ABS(AA25),ABS(AE25)) -> 0.47556962 | AJ25: =AVERAGE(ABS(AB25),ABS(AF25)) -> 0.036883374 | AK25: =AVERAGE(ABS(AC25),ABS(AG25)) -> 0.53487624 | AL25: =MIN(A25,E25) -> 0.5
... A42: ='Proximal Validation (double)'!A42 -> 0.2 | B42: ='Proximal Validation (double)'!B42 -> 0.2 | C42: ='Proximal Validation (double)'!C42 -> 4.712 | D42: ='Proximal Validation (double)'!D42 -> 1.5707963 | E42: ='Proximal Validation (double)'!E42 -> 0.1 | F42: ='Proximal Validation (double)'!F42 -> 0.08 | G42: ='Proximal Validation (double)'!G42 -> 3.927 | H42: ='Proximal Validation (double)'!H42 -> 1.5707963 | ... K42: ='Proximal Validation (double)'!K42 -> 0 | R42: 0.77323848 | S42: 0.15589596 | T42: 5.3945005 | U42: 1.5707963 | V42: 0.64831036 | W42: 0.14617789 | X42: 2.6075519 | Y42: 1.5707963 | Z42: 1.6443335e-07 | AA42: =R42-A42 -> 0.57323848 | AB42: =S42-B42 -> -0.044104038 | AC42: =T42-C42 -> 0.6825005 | AD42: =U42-D42 -> 0 | AE42: =V42-E42 -> 0.54831036 | AF42: =W42-F42 -> 0.066177888 | AG42: =X42-G42 -> -1.3194481 | AH42: =Y42-H42 -> 0 | AI42: =AVERAGE(ABS(AA42),ABS(AE42)) -> 0.56077442 | AJ42: =AVERAGE(ABS(AB42),ABS(AF42)) -> 0.055140963 | AK42: =AVERAGE(ABS(AC42),ABS(AG42)) -> 1.0009743 | AL42: =MIN(A42,E42) -> 0.1

Sheet Distal Vali (double, tight)
A1: Ground Truth | L1: 6-Axis FT Sensor | R1: SoRoSim get_distal_value | Z1: Distal Errors | AH1: Stats
A2: F1 (N) | B2: s1 (m) | C2: el1 (rad) | D2: az1 (rad) | E2: F2 (N) | F2: s2 (m) | G2: el2 (rad) | H2: az2 (rad) | I2: tau1 (N) | J2: tau2 (N) | K2: tau3 (N) | L2: Tx (Nm) | M2: Ty (Nm) | N2: Tz(Nm) | O2: Fx (N) | P2: Fy (N) | Q2: Fz (N) | R2: F1 (N) | S2: s1 (m) | T2: el1 (rad) | U2: az1 (rad) | V2: F2 (N) | W2: s2 (m) | X2: el2 (rad) | Y2: az2 (rad) | Z2: F1 (N) | AA2: s1 (m) | AB2: el1 (rad) | AC2: az1 (rad) | AD2: F2 (N) | AE2: s2 (m) | AF2: el2 (rad) | AG2: az2 (rad) | AH2: force_error | AI2: position_error | AJ2: angle_error | AK2: Absolute Mean Error
A3: ='Proximal Validation (double)'!A3 -> 0.2 | B3: ='Proximal Validation (double)'!B3 -> 0.1 | C3: ='Proximal Validation (double)'!C3 -> 1.571 | D3: ='Proximal Validation (double)'!D3 -> 1.5707963 | E3: ='Proximal Validation (double)'!E3 -> 1 | F3: ='Proximal Validation (double)'!F3 -> 0.04 | G3: ='Proximal Validation (double)'!G3 -> 3.142 | H3: ='Proximal Validation (double)'!H3 -> 1.5707963 | ... Q3: ='Proximal Validation (double)'!Q3 -> 0.19511425 | R3: 0.3629 | S3: 0.1089 | T3: 2.5763 | U3: 1.5708 | V3: 0.7347 | W3: 0.02 | X3: 3.1416 | Y3: 1.5708 | Z3: =R3-A3 -> 0.1629 | AA3: =S3-B3 -> 0.0089 | AB3: =T3-C3 -> 1.0053 | AC3: =U3-D3 -> 3.6732051e-06 | AD3: =V3-E3 -> -0.2653 | AE3: =W3-F3 -> -0.02 | AF3: =X3-G3 -> -0.0004 | AG3: =Y3-H3 -> 3.6732051e-06 | AH3: =AVERAGE(ABS(Z3),ABS(AD3)) -> 0.2141 | AI3: =AVERAGE(ABS(AA3),ABS(AE3)) -> 0.01445 | AJ3: =AVERAGE(ABS(AB3),ABS(AF3)) -> 0.50285 | AK3: F1 (N) | AL3: s1 (m) | AM3: el1 (rad) | AN3: az1 (rad) | AO3: F2 (N) | AP3: s2 (m) | AQ3: el2 (rad) | AR3: az2 (rad)
A4: ='Proximal Validation (double)'!A4 -> 1 | B4: ='Proximal Validation (double)'!B4 -> 0.1 | C4: ='Proximal Validation (double)'!C4 -> 1.571 | D4: ='Proximal Validation (double)'!D4 -> 1.5707963 | E4: ='Proximal Validation (double)'!E4 -> 1 | F4: ='Proximal Validation (double)'!F4 -> 0.08 | G4: ='Proximal Validation (double)'!G4 -> 3.142 | H4: ='Proximal Validation (double)'!H4 -> 1.5707963 | ... Q4: ='Proximal Validation (double)'!Q4 -> 1.091455 | R4: 1 | S4: 0.1272 | T4: 1.5759 | U4: 1.5708 | V4: 0.882 | W4: 0.08 | X4: 3.1416 | Y4: 1.5708 | Z4: =R4-A4 -> 0 | AA4: =S4-B4 -> 0.0272 | AB4: =T4-C4 -> 0.0049 | AC4: =U4-D4 -> 3.6732051e-06 | AD4: =V4-E4 -> -0.118 | AE4: =W4-F4 -> 0 | AF4: =X4-G4 -> -0.0004 | AG4: =Y4-H4 -> 3.6732051e-06 | AH4: =AVERAGE(ABS(Z4),ABS(AD4)) -> 0.059 | AI4: =AVERAGE(ABS(AA4),ABS(AE4)) -> 0.0136 | AJ4: =AVERAGE(ABS(AB4),ABS(AF4)) -> 0.00265 | AK4: {=AVERAGE(ABS(Z3:Z42))} -> 0.1045075 | AL4: {=AVERAGE(ABS(AA3:AA42))} -> 0.0268525 | AM4: {=AVERAGE(ABS(AB3:AB42))} -> 0.405275 | AN4: {=AVERAGE(ABS(AC3:AC42))} -> 3.6732051e-06 | AO4: {=AVERAGE(ABS(AD3:AD42))} -> 0.138175 | AP4: {=AVERAGE(ABS(AE3:AE42))} -> 0.01529 | AQ4: {=AVERAGE(ABS(AF3:AF42))} -> 0.2080475 | AR4: {=AVERAGE(ABS(AG3:AG42))} -> 3.6732051e-06
A5: ='Proximal Validation (double)'!A5 -> 0.5 | B5: ='Proximal Validation (double)'!B5 -> 0.1 | C5: ='Proximal Validation (double)'!C5 -> 1.571 | D5: ='Proximal Validation (double)'!D5 -> 1.5707963 | E5: ='Proximal Validation (double)'!E5 -> 0.2 | F5: ='Proximal Validation (double)'!F5 -> 0.02 | G5: ='Proximal Validation (double)'!G5 -> 3.927 | H5: ='Proximal Validation (double)'!H5 -> 1.5707963 | ... Q5: ='Proximal Validation (double)'!Q5 -> 0.45268995 | R5: 0.5209 | S5: 0.1279 | T5: 1.5718 | U5: 1.5708 | V5: 0.144 | W5: 0.033 | X5: 3.6412 | Y5: 1.5708 | Z5: =R5-A5 -> 0.0209 | AA5: =S5-B5 -> 0.0279 | AB5: =T5-C5 -> 0.0008 | AC5: =U5-D5 -> 3.6732051e-06 | AD5: =V5-E5 -> -0.056 | AE5: =W5-F5 -> 0.013 | AF5: =X5-G5 -> -0.2858 | AG5: =Y5-H5 -> 3.6732051e-06 | AH5: =AVERAGE(ABS(Z5),ABS(AD5)) -> 0.03845 | AI5: =AVERAGE(ABS(AA5),ABS(AE5)) -> 0.02045 | AJ5: =AVERAGE(ABS(AB5),ABS(AF5)) -> 0.1433 | AK5: Absolute Mean Error (Across Both Forces)
A6: ='Proximal Validation (double)'!A6 -> 0.9 | B6: ='Proximal Validation (double)'!B6 -> 0.1 | C6: ='Proximal Validation (double)'!C6 -> 1.571 | D6: ='Proximal Validation (double)'!D6 -> 1.5707963 | E6: ='Proximal Validation (double)'!E6 -> 0.2 | F6: ='Proximal Validation (double)'!F6 -> 0.08 | G6: ='Proximal Validation (double)'!G6 -> 4.712 | H6: ='Proximal Validation (double)'!H6 -> 1.5707963 | ... Q6: ='Proximal Validation (double)'!Q6 -> 0.88741946 | R6: 0.9892 | S6: 0.1245 | T6: 1.5708 | U6: 1.5708 | V6: 0.1 | W6: 0.08 | X6: 4.7123 | Y6: 1.5708 | Z6: =R6-A6 -> 0.0892 | AA6: =S6-B6 -> 0.0245 | AB6: =T6-C6 -> -0.0002 | AC6: =U6-D6 -> 3.6732051e-06 | AD6: =V6-E6 -> -0.1 | AE6: =W6-F6 -> 0 | AF6: =X6-G6 -> 0.0003 | AG6: =Y6-H6 -> 3.6732051e-06 | AH6: =AVERAGE(ABS(Z6),ABS(AD6)) -> 0.0946 | AI6: =AVERAGE(ABS(AA6),ABS(AE6)) -> 0.01225 | AJ6: =AVERAGE(ABS(AB6),ABS(AF6)) -> 0.00025 | AK6: force_error | AL6: position_error | AM6: angle_error
A7: ='Proximal Validation (double)'!A7 -> 0.1 | B7: ='Proximal Validation (double)'!B7 -> 0.12 | C7: ='Proximal Validation (double)'!C7 -> 1.571 | D7: ='Proximal Validation (double)'!D7 -> 1.5707963 | E7: ='Proximal Validation (double)'!E7 -> 1 | F7: ='Proximal Validation (double)'!F7 -> 0.06 | G7: ='Proximal Validation (double)'!G7 -> 3.927 | H7: ='Proximal Validation (double)'!H7 -> 1.5707963 | ... Q7: ='Proximal Validation (double)'!Q7 -> -0.50915515 | R7: 0.2014 | S7: 0.1 | T7: 3.2376 | U7: 1.5708 | V7: 0.7426 | W7: 0.0504 | X7: 3.862 | Y7: 1.5708 | Z7: =R7-A7 -> 0.1014 | AA7: =S7-B7 -> -0.02 | AB7: =T7-C7 -> 1.6666 | AC7: =U7-D7 -> 3.6732051e-06 | AD7: =V7-E7 -> -0.2574 | AE7: =W7-F7 -> -0.0096 | AF7: =X7-G7 -> -0.065 | AG7: =Y7-H7 -> 3.6732051e-06 | AH7: =AVERAGE(ABS(Z7),ABS(AD7)) -> 0.1794 | AI7: =AVERAGE(ABS(AA7),ABS(AE7)) -> 0.0148 | AJ7: =AVERAGE(ABS(AB7),ABS(AF7)) -> 0.8658 | AK7: =AVERAGE(AK4,AO4) -> 0.12134125 | AL7: =AVERAGE(AL4,AP4) -> 0.02107125 | AM7: =AVERAGE(AM4,AQ4) -> 0.30666125
A8: ='Proximal Validation (double)'!A8 -> 0.8 | B8: ='Proximal Validation (double)'!B8 -> 0.16 | C8: ='Proximal Validation (double)'!C8 -> 1.571 | D8: ='Proximal Validation (double)'!D8 -> 1.5707963 | E8: ='Proximal Validation (double)'!E8 -> 0.8 | F8: ='Proximal Validation (double)'!F8 -> 0.06 | G8: ='Proximal Validation (double)'!G8 -> 3.927 | H8: ='Proximal Validation (double)'!H8 -> 1.5707963 | ... Q8: ='Proximal Validation (double)'!Q8 -> 0.49847054 | R8: 0.9076 | S8: 0.1739 | T8: 1.7493 | U8: 1.5708 | V8: 0.5345 | W8: 0.02 | X8: 3.736 | Y8: 1.5708 | Z8: =R8-A8 -> 0.1076 | AA8: =S8-B8 -> 0.0139 | AB8: =T8-C8 -> 0.1783 | AC8: =U8-D8 -> 3.6732051e-06 | AD8: =V8-E8 -> -0.2655 | AE8: =W8-F8 -> -0.04 | AF8: =X8-G8 -> -0.191 | AG8: =Y8-H8 -> 3.6732051e-06 | AH8: =AVERAGE(ABS(Z8),ABS(AD8)) -> 0.18655 | AI8: =AVERAGE(ABS(AA8),ABS(AE8)) -> 0.02695 | AJ8: =AVERAGE(ABS(AB8),ABS(AF8)) -> 0.18465
A9: ='Proximal Validation (double)'!A9 -> 0.1 | B9: ='Proximal Validation (double)'!B9 -> 0.18 | C9: ='Proximal Validation (double)'!C9 -> 1.571 | D9: ='Proximal Validation (double)'!D9 -> 1.5707963 | E9: ='Proximal Validation (double)'!E9 -> 0.1 | F9: ='Proximal Validation (double)'!F9 -> 0.02 | G9: ='Proximal Validation (double)'!G9 -> 3.142 | H9: ='Proximal Validation (double)'!H9 -> 1.5707963 | ... Q9: ='Proximal Validation (double)'!Q9 -> 0.11709622 | R9: 0.1563 | S9: 0.1738 | T9: 1.5708 | U9: 1.5708 | V9: 0.1488 | W9: 0.0255 | X9: 3.402 | Y9: 1.5708 | Z9: =R9-A9 -> 0.0563 | AA9: =S9-B9 -> -0.0062 | AB9: =T9-C9 -> -0.0002 | AC9: =U9-D9 -> 3.6732051e-06 | AD9: =V9-E9 -> 0.0488 | AE9: =W9-F9 -> 0.0055 | AF9: =X9-G9 -> 0.26 | AG9: =Y9-H9 -> 3.6732051e-06 | AH9: =AVERAGE(ABS(Z9),ABS(AD9)) -> 0.05255 | AI9: =AVERAGE(ABS(AA9),ABS(AE9)) -> 0.00585 | AJ9: =AVERAGE(ABS(AB9),ABS(AF9)) -> 0.1301
A10: ='Proximal Validation (double)'!A10 -> 0.9 | B10: ='Proximal Validation (double)'!B10 -> 0.18 | C10: ='Proximal Validation (double)'!C10 -> 1.571 | D10: ='Proximal Validation (double)'!D10 -> 1.5707963 | E10: ='Proximal Validation (double)'!E10 -> 0.1 | F10: ='Proximal Validation (double)'!F10 -> 0.08 | G10: ='Proximal Validation (double)'!G10 -> 4.712 | H10: ='Proximal Validation (double)'!H10 -> 1.5707963 | ... Q10: ='Proximal Validation (double)'!Q10 -> 0.66701603 | R10: 0.8689 | S10: 0.182 | T10: 1.5708 | U10: 1.5708 | V10: 0.1049 | W10: 0.0329 | X10: 4.7124 | Y10: 1.5708 | Z10: =R10-A10 -> -0.0311 | AA10: =S10-B10 -> 0.002 | AB10: =T10-C10 -> -0.0002 | AC10: =U10-D10 -> 3.6732051e-06 | AD10: =V10-E10 -> 0.0049 | AE10: =W10-F10 -> -0.0471 | AF10: =X10-G10 -> 0.0004 | AG10: =Y10-H10 -> 3.6732051e-06 | AH10: =AVERAGE(ABS(Z10),ABS(AD10)) -> 0.018 | AI10: =AVERAGE(ABS(AA10),ABS(AE10)) -> 0.02455 | AJ10: =AVERAGE(ABS(AB10),ABS(AF10)) -> 0.0003
A11: ='Proximal Validation (double)'!A11 -> 0.3 | B11: ='Proximal Validation (double)'!B11 -> 0.18 | C11: ='Proximal Validation (double)'!C11 -> 1.571 | D11: ='Proximal Validation (double)'!D11 -> 1.5707963 | E11: ='Proximal Validation (double)'!E11 -> 0.9 | F11: ='Proximal Validation (double)'!F11 -> 0.08 | G11: ='Proximal Validation (double)'!G11 -> 4.712 | H11: ='Proximal Validation (double)'!H11 -> 1.5707963 | ... Q11: ='Proximal Validation (double)'!Q11 -> -0.73156416 | R11: 0.2047 | S11: 0.1123 | T11: 4.6963 | U11: 1.5708 | V11: 0.5268 | W11: 0.02 | X11: 4.7068 | Y11: 1.5708 | Z11: =R11-A11 -> -0.0953 | AA11: =S11-B11 -> -0.0677 | AB11: =T11-C11 -> 3.1253 | AC11: =U11-D11 -> 3.6732051e-06 | AD11: =V11-E11 -> -0.3732 | AE11: =W11-F11 -> -0.06 | AF11: =X11-G11 -> -0.0052 | AG11: =Y11-H11 -> 3.6732051e-06 | AH11: =AVERAGE(ABS(Z11),ABS(AD11)) -> 0.23425 | AI11: =AVERAGE(ABS(AA11),ABS(AE11)) -> 0.06385 | AJ11: =AVERAGE(ABS(AB11),ABS(AF11)) -> 1.56525
A12: ='Proximal Validation (double)'!A12 -> 0.9 | B12: ='Proximal Validation (double)'!B12 -> 0.2 | C12: ='Proximal Validation (double)'!C12 -> 1.571 | D12: ='Proximal Validation (double)'!D12 -> 1.5707963 | E12: ='Proximal Validation (double)'!E12 -> 1 | F12: ='Proximal Validation (double)'!F12 -> 0.02 | G12: ='Proximal Validation (double)'!G12 -> 3.142 | H12: ='Proximal Validation (double)'!H12 -> 1.5707963 | ... Q12: ='Proximal Validation (double)'!Q12 -> 0.51245713 | R12: 0.8403 | S12: 0.2 | T12: 1.5708 | U12: 1.5708 | V12: 0.9968 | W12: 0.02 | X12: 3.3195 | Y12: 1.5708 | Z12: =R12-A12 -> -0.0597 | AA12: =S12-B12 -> 0 | AB12: =T12-C12 -> -0.0002 | AC12: =U12-D12 -> 3.6732051e-06 | AD12: =V12-E12 -> -0.0032 | AE12: =W12-F12 -> 0 | AF12: =X12-G12 -> 0.1775 | AG12: =Y12-H12 -> 3.6732051e-06 | AH12: =AVERAGE(ABS(Z12),ABS(AD12)) -> 0.03145 | AI12: =AVERAGE(ABS(AA12),ABS(AE12)) -> 0 | AJ12: =AVERAGE(ABS(AB12),ABS(AF12)) -> 0.08885
A13: ='Proximal Validation (double)'!A13 -> 0.1 | B13: ='Proximal Validation (double)'!B13 -> 0.2 | C13: ='Proximal Validation (double)'!C13 -> 1.571 | D13: ='Proximal Validation (double)'!D13 -> 1.5707963 | E13: ='Proximal Validation (double)'!E13 -> 0.3 | F13: ='Proximal Validation (double)'!F13 -> 0.08 | G13: ='Proximal Validation (double)'!G13 -> 3.142 | H13: ='Proximal Validation (double)'!H13 -> 1.5707963 | ... Q13: ='Proximal Validation (double)'!Q13 -> -0.0304524 | R13: 0.1801 | S13: 0.1 | T13: 3.0131 | U13: 1.5708 | V13: 0.2107 | W13: 0.0492 | X13: 3.3986 | Y13: 1.5708 | Z13: =R13-A13 -> 0.0801 | AA13: =S13-B13 -> -0.1 | AB13: =T13-C13 -> 1.4421 | AC13: =U13-D13 -> 3.6732051e-06 | AD13: =V13-E13 -> -0.0893 | AE13: =W13-F13 -> -0.0308 | AF13: =X13-G13 -> 0.2566 | AG13: =Y13-H13 -> 3.6732051e-06 | AH13: =AVERAGE(ABS(Z13),ABS(AD13)) -> 0.0847 | AI13: =AVERAGE(ABS(AA13),ABS(AE13)) -> 0.0654 | AJ13: =AVERAGE(ABS(AB13),ABS(AF13)) -> 0.84935
A14: ='Proximal Validation (double)'!A14 -> 0.9 | B14: ='Proximal Validation (double)'!B14 -> 0.2 | C14: ='Proximal Validation (double)'!C14 -> 1.571 | D14: ='Proximal Validation (double)'!D14 -> 1.5707963 | E14: ='Proximal Validation (double)'!E14 -> 0.3 | F14: ='Proximal Validation (double)'!F14 -> 0.02 | G14: ='Proximal Validation (double)'!G14 -> 4.712 | H14: ='Proximal Validation (double)'!H14 -> 1.5707963 | ... Q14: ='Proximal Validation (double)'!Q14 -> 0.27873135 | R14: 0.8367 | S14: 0.1908 | T14: 1.5709 | U14: 1.5708 | V14: 0.4153 | W14: 0.0215 | X14: 4.7124 | Y14: 1.5708 | Z14: =R14-A14 -> -0.0633 | AA14: =S14-B14 -> -0.0092 | AB14: =T14-C14 -> -0.0001 | AC14: =U14-D14 -> 3.6732051e-06 | AD14: =V14-E14 -> 0.1153 | AE14: =W14-F14 -> 0.0015 | AF14: =X14-G14 -> 0.0004 | AG14: =Y14-H14 -> 3.6732051e-06 | AH14: =AVERAGE(ABS(Z14),ABS(AD14)) -> 0.0893 | AI14: =AVERAGE(ABS(AA14),ABS(AE14)) -> 0.00535 | AJ14: =AVERAGE(ABS(AB14),ABS(AF14)) -> 0.00025
A15: ='Proximal Validation (double)'!A15 -> 0.9 | B15: ='Proximal Validation (double)'!B15 -> 0.1 | C15: ='Proximal Validation (double)'!C15 -> 2.356 | D15: ='Proximal Validation (double)'!D15 -> 1.5707963 | E15: ='Proximal Validation (double)'!E15 -> 0.9 | F15: ='Proximal Validation (double)'!F15 -> 0.02 | G15: ='Proximal Validation (double)'!G15 -> 4.712 | H15: ='Proximal Validation (double)'!H15 -> 1.5707963 | ... Q15: ='Proximal Validation (double)'!Q15 -> -0.18663806 | R15: 0.609 | S15: 0.1 | T15: 2.4152 | U15: 1.5708 | V15: 0.6355 | W15: 0.02 | X15: 4.3218 | Y15: 1.5708 | Z15: =R15-A15 -> -0.291 | AA15: =S15-B15 -> 0 | AB15: =T15-C15 -> 0.0592 | AC15: =U15-D15 -> 3.6732051e-06 | AD15: =V15-E15 -> -0.2645 | AE15: =W15-F15 -> 0 | AF15: =X15-G15 -> -0.3902 | AG15: =Y15-H15 -> 3.6732051e-06 | AH15: =AVERAGE(ABS(Z15),ABS(AD15)) -> 0.27775 | AI15: =AVERAGE(ABS(AA15),ABS(AE15)) -> 0 | AJ15: =AVERAGE(ABS(AB15),ABS(AF15)) -> 0.2247
A16: ='Proximal Validation (double)'!A16 -> 0.4 | B16: ='Proximal Validation (double)'!B16 -> 0.12 | C16: ='Proximal Validation (double)'!C16 -> 2.356 | D16: ='Proximal Validation (double)'!D16 -> 1.5707963 | E16: ='Proximal Validation (double)'!E16 -> 0.1 | F16: ='Proximal Validation (double)'!F16 -> 0.06 | G16: ='Proximal Validation (double)'!G16 -> 3.142 | H16: ='Proximal Validation (double)'!H16 -> 1.5707963 | ... Q16: ='Proximal Validation (double)'!Q16 -> 0.30062127 | R16: 0.4448 | S16: 0.1 | T16: 2.277 | U16: 1.5708 | V16: 0.1307 | W16: 0.0797 | X16: 3.4281 | Y16: 1.5708 | Z16: =R16-A16 -> 0.0448 | AA16: =S16-B16 -> -0.02 | AB16: =T16-C16 -> -0.079 | AC16: =U16-D16 -> 3.6732051e-06 | AD16: =V16-E16 -> 0.0307 | AE16: =W16-F16 -> 0.0197 | AF16: =X16-G16 -> 0.2861 | AG16: =Y16-H16 -> 3.6732051e-06 | AH16: =AVERAGE(ABS(Z16),ABS(AD16)) -> 0.03775 | AI16: =AVERAGE(ABS(AA16),ABS(AE16)) -> 0.01985 | AJ16: =AVERAGE(ABS(AB16),ABS(AF16)) -> 0.18255
A17: ='Proximal Validation (double)'!A17 -> 1 | B17: ='Proximal Validation (double)'!B17 -> 0.14 | C17: ='Proximal Validation (double)'!C17 -> 2.356 | D17: ='Proximal Validation (double)'!D17 -> 1.5707963 | E17: ='Proximal Validation (double)'!E17 -> 0.4 | F17: ='Proximal Validation (double)'!F17 -> 0.04 | G17: ='Proximal Validation (double)'!G17 -> 3.927 | H17: ='Proximal Validation (double)'!H17 -> 1.5707963 | ... Q17: ='Proximal Validation (double)'!Q17 -> 0.67185998 | R17: 1 | S17: 0.1528 | T17: 2.1778 | U17: 1.5708 | V17: 0.5674 | W17: 0.08 | X17: 3.3569 | Y17: 1.5708 | Z17: =R17-A17 -> 0 | AA17: =S17-B17 -> 0.0128 | AB17: =T17-C17 -> -0.1782 | AC17: =U17-D17 -> 3.6732051e-06 | AD17: =V17-E17 -> 0.1674 | AE17: =W17-F17 -> 0.04 | AF17: =X17-G17 -> -0.5701 | AG17: =Y17-H17 -> 3.6732051e-06 | AH17: =AVERAGE(ABS(Z17),ABS(AD17)) -> 0.0837 | AI17: =AVERAGE(ABS(AA17),ABS(AE17)) -> 0.0264 | AJ17: =AVERAGE(ABS(AB17),ABS(AF17)) -> 0.37415
A18: ='Proximal Validation (double)'!A18 -> 0.4 | B18: ='Proximal Validation (double)'!B18 -> 0.18 | C18: ='Proximal Validation (double)'!C18 -> 2.356 | D18: ='Proximal Validation (double)'!D18 -> 1.5707963 | E18: ='Proximal Validation (double)'!E18 -> 0.7 | F18: ='Proximal Validation (double)'!F18 -> 0.04 | G18: ='Proximal Validation (double)'!G18 -> 3.142 | H18: ='Proximal Validation (double)'!H18 -> 1.5707963 | ... Q18: ='Proximal Validation (double)'!Q18 -> 0.18511915 | R18: 0.4654 | S18: 0.1525 | T18: 2.4117 | U18: 1.5708 | V18: 0.5568 | W18: 0.0389 | X18: 3.3644 | Y18: 1.5708 | Z18: =R18-A18 -> 0.0654 | AA18: =S18-B18 -> -0.0275 | AB18: =T18-C18 -> 0.0557 | AC18: =U18-D18 -> 3.6732051e-06 | AD18: =V18-E18 -> -0.1432 | AE18: =W18-F18 -> -0.0011 | AF18: =X18-G18 -> 0.2224 | AG18: =Y18-H18 -> 3.6732051e-06 | AH18: =AVERAGE(ABS(Z18),ABS(AD18)) -> 0.1043 | AI18: =AVERAGE(ABS(AA18),ABS(AE18)) -> 0.0143 | AJ18: =AVERAGE(ABS(AB18),ABS(AF18)) -> 0.13905
