Workbook

Sheet Proximal Validation (double)
A1: Ground Truth | L1: 6-Axis FT Sensor | R1: SoRoSim get_proximal_value | X1: Proximal Errors
A2: F1 (N) | B2: s1 (m) | C2: el1 (rad) | D2: az1 (rad) | E2: F2 (N) | F2: s2 (m) | G2: el2 (rad) | H2: az2 (rad) | I2: tau1 (N) | J2: tau2 (N) | K2: tau3 (N) | L2: Tx (Nm) | M2: Ty (Nm) | N2: Tz(Nm) | O2: Fx (N) | P2: Fy (N) | Q2: Fz (N) | R2: Tx (Nm) | S2: Ty (Nm) | T2: Tz(Nm) | U2: Fx (N) | V2: Fy (N) | W2: Fz (N) | X2: Tx (Nm) | Y2: Ty (Nm) | Z2: Tz(Nm) | AA2: Fx (N) | AB2: Fy (N) | AC2: Fz (N)
A3: 0.3 | B3: 0.2 | C3: 1.57 | D3: =PI()/2 -> 1.5707963 | E3: 0.3 | F3: 0.08 | G3: 3.142 | H3: =PI()/2 -> 1.5707963 | I3: 0 | J3: 0 | K3: 0 | X3: =L3-R3 -> 0 | Y3: =M3-S3 -> 0 | Z3: =N3-T3 -> 0 | AA3: =O3-U3 -> 0 | AB3: =P3-V3 -> 0 | AC3: =Q3-W3 -> 0
A4: 0.4 | B4: 0.1 | C4: 1.57 | D4: =PI()/2 -> 1.5707963 | E4: 0.5 | F4: 0.06 | G4: 4.712 | H4: =PI()/2 -> 1.5707963 | I4: 0.8 | J4: 0 | K4: 0 | L4: -0.00069790857 | M4: -0.0073205647 | N4: -0.00034127428 | O4: -0.055667467 | P4: -0.001031287 | Q4: -0.078237303 | R4: 0.000285698 | S4: -0.0010087776 | T4: 2.174308e-05 | U4: -0.0042225169 | V4: -1.5537279e-05 | W4: -0.10037541 | X4: =L4-R4 -> -0.00098360657 | Y4: =M4-S4 -> -0.0063117871 | Z4: =N4-T4 -> -0.00036301736 | AA4: =O4-U4 -> -0.051444951 | AB4: =P4-V4 -> -0.0010157497 | AC4: =Q4-W4 -> 0.022138106
A5: 0.7 | B5: 0.16 | C5: 1.57 | D5: =PI()/2 -> 1.5707963 | E5: 0.7 | F5: 0.02 | G5: 4.712 | H5: =PI()/2 -> 1.5707963 | I5: 0 | J5: 0 | K5: 0 | L5: -0.0010536192 | M5: -0.078555815 | N5: -0.00084829383 | O5: -0.29072845 | P5: -0.005124703 | Q5: -0.1495057 | R5: -5.9414687e-14 | S5: -0.091673923 | T5: 0.00010413138 | U5: -0.21863285 | V5: 0.00024029001 | W5: -0.055548671 | X5: =L5-R5 -> -0.0010536192 | Y5: =M5-S5 -> 0.013118108 | Z5: =N5-T5 -> -0.00095242521 | AA5: =O5-U5 -> -0.072095603 | AB5: =P5-V5 -> -0.0053649931 | AC5: =Q5-W5 -> -0.093957034
A6: 0.7 | B6: 0.18 | C6: 2.356 | D6: =PI()/2 -> 1.5707963 | E6: 0.8 | F6: 0.06 | G6: 3.142 | H6: =PI()/2 -> 1.5707963 | I6: 0.8 | J6: 0 | K6: 0 | L6: 0.0057581165 | M6: -0.10363681 | N6: -0.23897853 | O6: -0.52015883 | P6: -1.0992656 | Q6: 0.26735616 | R6: 0.0034925323 | S6: -0.12347861 | T6: -0.24049207 | U6: -0.57507161 | V6: -1.1870392 | W6: 0.40300529 | X6: =L6-R6 -> 0.0022655842 | Y6: =M6-S6 -> 0.019841804 | Z6: =N6-T6 -> 0.0015135353 | AA6: =O6-U6 -> 0.054912782 | AB6: =P6-V6 -> 0.087773643 | AC6: =Q6-W6 -> -0.13564913
A7: 0.6 | B7: 0.12 | C7: 2.356 | D7: =PI()/2 -> 1.5707963 | E7: 0.3 | F7: 0.04 | G7: 3.927 | H7: =PI()/2 -> 1.5707963 | I7: 0.4 | J7: 0 | K7: 0 | L7: -0.002448665 | M7: -0.066844538 | N7: -0.11393435 | O7: -0.1313771 | P7: -0.5928942 | Q7: 0.26247159 | R7: 0.00061658666 | S7: -0.060719965 | T7: -0.11561777 | U7: -0.11970484 | V7: -0.62771751 | W7: 0.20413645 | X7: =L7-R7 -> -0.0030652516 | Y7: =M7-S7 -> -0.0061245729 | Z7: =N7-T7 -> 0.0016834236 | AA7: =O7-U7 -> -0.011672263 | AB7: =P7-V7 -> 0.034823318 | AC7: =Q7-W7 -> 0.058335136
A8: 0.8 | B8: 0.12 | C8: 2.356 | D8: =PI()/2 -> 1.5707963 | E8: 0.5 | F8: 0.06 | G8: 3.927 | H8: =PI()/2 -> 1.5707963 | I8: 0.4 | J8: 0 | K8: 0 | L8: -0.0025066524 | M8: -0.075730748 | N8: -0.18031727 | O8: -0.29059055 | P8: -0.92200559 | Q8: 0.27903903 | R8: 0.00079878182 | S8: -0.063983584 | T8: -0.16900056 | U8: -0.22623757 | V8: -0.89475975 | W8: 0.19533585 | X8: =L8-R8 -> -0.0033054342 | Y8: =M8-S8 -> -0.011747165 | Z8: =N8-T8 -> -0.011316707 | AA8: =O8-U8 -> -0.064352989 | AB8: =P8-V8 -> -0.027245845 | AC8: =Q8-W8 -> 0.083703172
A9: 0.3 | B9: 0.18 | C9: 3.142 | D9: =PI()/2 -> 1.5707963 | E9: 0.4 | F9: 0.04 | G9: 3.927 | H9: =PI()/2 -> 1.5707963 | I9: 1.2 | J9: 0 | K9: 0 | L9: 0.00085229939 | M9: 0.034337111 | N9: -0.094974354 | O9: -0.018785402 | P9: -0.50129873 | Q9: -0.25437981 | R9: 0.0010626163 | S9: 0.036640843 | T9: -0.11726999 | U9: -0.074921234 | V9: -0.57752928 | W9: -0.28300033 | X9: =L9-R9 -> -0.00021031693 | Y9: =M9-S9 -> -0.0023037326 | Z9: =N9-T9 -> 0.022295638 | AA9: =O9-U9 -> 0.056135832 | AB9: =P9-V9 -> 0.076230551 | AC9: =Q9-W9 -> 0.028620526
A10: 0.5 | B10: 0.2 | C10: 3.142 | D10: =PI()/2 -> 1.5707963 | E10: 0.7 | F10: 0.04 | G10: 3.927 | H10: =PI()/2 -> 1.5707963 | I10: 0.4 | J10: 0 | K10: 0 | L10: 0.0006182529 | M10: 0.055208318 | N10: -0.18095528 | O10: -0.24768664 | P10: -0.86978924 | Q10: -0.40951335 | R10: 0.00070644552 | S10: 0.063818821 | T10: -0.20101919 | U10: -0.31092897 | V10: -0.93737974 | W10: -0.49187066 | X10: =L10-R10 -> -8.8192615e-05 | Y10: =M10-S10 -> -0.0086105035 | Z10: =N10-T10 -> 0.020063918 | AA10: =O10-U10 -> 0.063242327 | AB10: =P10-V10 -> 0.067590502 | AC10: =Q10-W10 -> 0.08235731
A11: 0.4 | B11: 0.14 | C11: 3.927 | D11: =PI()/2 -> 1.5707963 | E11: 0.5 | F11: 0.02 | G11: 3.142 | H11: =PI()/2 -> 1.5707963 | I11: 0.8 | J11: 0 | K11: 0 | L11: -0.00091634737 | M11: 0.053316057 | N11: -0.11144441 | O11: -0.05330443 | P11: -0.72502011 | Q11: -0.2260839 | R11: -0.00028985343 | S11: 0.064758143 | T11: -0.11939818 | U11: -0.074125361 | V11: -0.77956146 | W11: -0.2797794 | X11: =L11-R11 -> -0.00062649395 | Y11: =M11-S11 -> -0.011442086 | Z11: =N11-T11 -> 0.0079537622 | AA11: =O11-U11 -> 0.020820931 | AB11: =P11-V11 -> 0.054541352 | AC11: =Q11-W11 -> 0.0536955
A12: 0.7 | B12: 0.12 | C12: 3.927 | D12: =PI()/2 -> 1.5707963 | E12: 0.7 | F12: 0.08 | G12: 3.927 | H12: =PI()/2 -> 1.5707963 | I12: 1.2 | J12: 0 | K12: 0 | L12: -0.0017120782 | M12: 0.15619831 | N12: -0.19836304 | O12: -0.20334189 | P12: -1.019968 | Q12: -0.78116876 | R12: -0.00084782218 | S12: 0.18377196 | T12: -0.18381761 | U12: -0.39139553 | V12: -0.95145894 | W12: -0.94941477 | X12: =L12-R12 -> -0.00086425605 | Y12: =M12-S12 -> -0.027573656 | Z12: =N12-T12 -> -0.014545431 | AA12: =O12-U12 -> 0.18805364 | AB12: =P12-V12 -> -0.068509094 | AC12: =Q12-W12 -> 0.16824601
A13: 0.3 | B13: 0.1 | C13: 3.927 | D13: =PI()/2 -> 1.5707963 | E13: 0.8 | F13: 0.04 | G13: 4.712 | H13: =PI()/2 -> 1.5707963 | I13: 0 | J13: 0 | K13: 0 | L13: 0.00051190471 | M13: 0.12445409 | N13: -0.033203859 | O13: -0.022600364 | P13: -0.1709877 | Q13: -0.86582863 | R13: 1.078715e-11 | S13: 0.14384394 | T13: -0.040206545 | U13: -0.076307825 | V13: -0.21112633 | W13: -1.0094616 | X13: =L13-R13 -> 0.0005119047 | Y13: =M13-S13 -> -0.019389849 | Z13: =N13-T13 -> 0.0070026856 | AA13: =O13-U13 -> 0.053707461 | AB13: =P13-V13 -> 0.040138634 | AC13: =Q13-W13 -> 0.14363299
A14: 0.6 | B14: 0.18 | C14: 3.927 | D14: =PI()/2 -> 1.5707963 | E14: 0.4 | F14: 0.08 | G14: 4.712 | H14: =PI()/2 -> 1.5707963 | I14: 0 | J14: 0 | K14: 0 | L14: -0.00057422183 | M14: 0.16228636 | N14: -0.11205181 | O14: -0.35012972 | P14: -0.37300897 | Q14: -0.69461757 | R14: 1.5387708e-10 | S14: 0.17397565 | T14: -0.10784276 | U14: -0.39573747 | V14: -0.36765931 | W14: -0.75114085 | X14: =L14-R14 -> -0.00057422199 | Y14: =M14-S14 -> -0.011689293 | Z14: =N14-T14 -> -0.0042090504 | AA14: =O14-U14 -> 0.045607744 | AB14: =P14-V14 -> -0.0053496591 | AC14: =Q14-W14 -> 0.056523278
A15: 0.7 | B15: 0.1 | C15: 4.712 | D15: =PI()/2 -> 1.5707963 | E15: 0.4 | F15: 0.04 | G15: 3.142 | H15: =PI()/2 -> 1.5707963 | I15: 0 | J15: 0 | K15: 0 | L15: -0.00094429776 | M15: 0.14865591 | N15: -0.052504346 | O15: -0.1629331 | P15: -0.39005202 | Q15: -0.75469375 | R15: -4.5486019e-11 | S15: 0.13196654 | T15: -0.051824804 | U15: -0.1199888 | V15: -0.39893904 | W15: -0.6905471 | X15: =L15-R15 -> -0.00094429772 | Y15: =M15-S15 -> 0.016689363 | Z15: =N15-T15 -> -0.0006795415 | AA15: =O15-U15 -> -0.042944294 | AB15: =P15-V15 -> 0.0088870229 | AC15: =Q15-W15 -> -0.064146646
... A17: 0.8 | B17: 0.2 | C17: 4.712 | D17: =PI()/2 -> 1.5707963 | E17: 0.3 | F17: 0.02 | G17: 4.712 | H17: =PI()/2 -> 1.5707963 | I17: 0.8 | J17: 0 | K17: 0 | L17: -0.0073545799 | M17: 0.22923256 | N17: -0.015391938 | O17: -0.71000016 | P17: -0.10407741 | Q17: -0.75926924 | R17: -0.004016476 | S17: 0.23867144 | T17: -2.7393135e-05 | U17: -0.5506102 | V17: -0.010171678 | W17: -0.91220761 | X17: =L17-R17 -> -0.0033381039 | Y17: =M17-S17 -> -0.0094388723 | Z17: =N17-T17 -> -0.015364545 | AA17: =O17-U17 -> -0.15938996 | AB17: =P17-V17 -> -0.093905728 | AC17: =Q17-W17 -> 0.15293837
A18: 0.3 | B18: 0.2 | C18: 1.57 | D18: 1.5707963 | E18: 0.3 | F18: 0.08 | G18: 3.142 | H18: 1.5707963 | I18: 0 | J18: 0 | K18: 0 | L18: -0.00043059303 | M18: -0.042151313 | N18: -0.054176919 | O18: -0.010742351 | P18: -0.32212555 | Q18: 0.11247401 | R18: 1.0281939e-10 | S18: -0.083694063 | T18: -0.050534032 | U18: -0.11054708 | V18: -0.2965019 | W18: 0.28215785 | X18: =L18-R18 -> -0.00043059314 | Y18: =M18-S18 -> 0.041542749 | Z18: =N18-T18 -> -0.0036428875 | AA18: =O18-U18 -> 0.099804726 | AB18: =P18-V18 -> -0.025623658 | AC18: =Q18-W18 -> -0.16968384
A19: 0.4 | B19: 0.1 | C19: 1.57 | D19: 1.5707963 | E19: 0.5 | F19: 0.06 | G19: 4.712 | H19: 1.5707963 | I19: 0.8 | J19: 0 | K19: 0 | L19: -0.00070192455 | M19: -0.01889527 | N19: 0.00065155933 | O19: -0.0034051635 | P19: 0.0074966699 | Q19: -0.030580966 | R19: 0.00027143079 | S19: -0.0010008976 | T19: 1.7497561e-05 | U19: -0.0060959065 | V19: -3.5604485e-05 | W19: -0.10042698 | X19: =L19-R19 -> -0.00097335535 | Y19: =M19-S19 -> -0.017894373 | Z19: =N19-T19 -> 0.00063406177 | AA19: =O19-U19 -> 0.002690743 | AB19: =P19-V19 -> 0.0075322744 | AC19: =Q19-W19 -> 0.069846012
A20: 0.7 | B20: 0.16 | C20: 1.57 | D20: 1.5707963 | E20: 0.7 | F20: 0.02 | G20: 4.712 | H20: 1.5707963 | I20: 0 | J20: 0 | K20: 0 | L20: -0.0011449491 | M20: -0.087871559 | N20: 0.0012581461 | O20: -0.25905412 | P20: 0.016173899 | Q20: -0.10142371 | R20: -2.4098101e-14 | S20: -0.089694541 | T20: 0.00010257002 | U20: -0.25642536 | V20: 0.00023238761 | W20: -0.065649632 | X20: =L20-R20 -> -0.0011449491 | Y20: =M20-S20 -> 0.0018229816 | Z20: =N20-T20 -> 0.0011555761 | AA20: =O20-U20 -> -0.0026287614 | AB20: =P20-V20 -> 0.015941512 | AC20: =Q20-W20 -> -0.035774079
A21: 0.7 | B21: 0.18 | C21: 2.356 | D21: 1.5707963 | E21: 0.8 | F21: 0.06 | G21: 3.142 | H21: 1.5707963 | I21: 0.8 | J21: 0 | K21: 0 | L21: 0.006440552 | M21: -0.096120387 | N21: -0.21380894 | O21: -0.53791088 | P21: -1.0106633 | Q21: 0.272531 | R21: 0.003939657 | S21: -0.12033416 | T21: -0.23830753 | U21: -0.57020296 | V21: -1.1827594 | W21: 0.38991688 | X21: =L21-R21 -> 0.0025008949 | Y21: =M21-S21 -> 0.024213778 | Z21: =N21-T21 -> 0.02449859 | AA21: =O21-U21 -> 0.032292081 | AB21: =P21-V21 -> 0.17209615 | AC21: =Q21-W21 -> -0.11738588
A22: 0.6 | B22: 0.12 | C22: 2.356 | D22: 1.5707963 | E22: 0.3 | F22: 0.04 | G22: 3.927 | H22: 1.5707963 | I22: 0.4 | J22: 0 | K22: 0 | L22: -0.0012948727 | M22: -0.06035408 | N22: -0.10349265 | O22: -0.12080407 | P22: -0.51357687 | Q22: 0.20345819 | R22: 0.00057347539 | S22: -0.060807952 | T22: -0.11575851 | U22: -0.10933291 | V22: -0.62926015 | W22: 0.20531021 | X22: =L22-R22 -> -0.0018683481 | Y22: =M22-S22 -> 0.00045387195 | Z22: =N22-T22 -> 0.012265862 | AA22: =O22-U22 -> -0.011471158 | AB22: =P22-V22 -> 0.11568329 | AC22: =Q22-W22 -> -0.0018520203
A23: 0.8 | B23: 0.12 | C23: 2.356 | D23: 1.5707963 | E23: 0.5 | F23: 0.06 | G23: 3.927 | H23: 1.5707963 | I23: 0.4 | J23: 0 | K23: 0 | L23: -0.0015304168 | M23: -0.058196127 | N23: -0.16341306 | O23: -0.25818381 | P23: -0.79976714 | Q23: 0.14228719 | R23: 0.00074597716 | S23: -0.064154236 | T23: -0.16942635 | U23: -0.20482799 | V23: -0.89941042 | W23: 0.19771314 | X23: =L23-R23 -> -0.0022763939 | Y23: =M23-S23 -> 0.0059581091 | Z23: =N23-T23 -> 0.0060132917 | AA23: =O23-U23 -> -0.053355813 | AB23: =P23-V23 -> 0.099643286 | AC23: =Q23-W23 -> -0.055425943
A24: 0.3 | B24: 0.18 | C24: 3.142 | D24: 1.5707963 | E24: 0.4 | F24: 0.04 | G24: 3.927 | H24: 1.5707963 | I24: 1.2 | J24: 0 | K24: 0 | L24: 0.0012701484 | M24: 0.032061167 | N24: -0.089157112 | O24: -0.002972709 | P24: -0.42995858 | Q24: -0.22458756 | R24: 0.0012483168 | S24: 0.03661247 | T24: -0.11731381 | U24: -0.066707795 | V24: -0.57831503 | W24: -0.28306346 | X24: =L24-R24 -> 2.1831675e-05 | Y24: =M24-S24 -> -0.0045513034 | Z24: =N24-T24 -> 0.028156693 | AA24: =O24-U24 -> 0.063735086 | AB24: =P24-V24 -> 0.14835645 | AC24: =Q24-W24 -> 0.058475903
A25: 0.5 | B25: 0.2 | C25: 3.142 | D25: 1.5707963 | E25: 0.7 | F25: 0.04 | G25: 3.927 | H25: 1.5707963 | I25: 0.4 | J25: 0 | K25: 0 | L25: -0.00067927502 | M25: 0.056959674 | N25: -0.1776637 | O25: -0.28621101 | P25: -0.79048735 | Q25: -0.42087454 | R25: 0.00088534208 | S25: 0.063961813 | T25: -0.19770374 | U25: -0.32302862 | V25: -0.9217162 | W25: -0.49338601 | X25: =L25-R25 -> -0.0015646171 | Y25: =M25-S25 -> -0.007002139 | Z25: =N25-T25 -> 0.020040046 | AA25: =O25-U25 -> 0.036817609 | AB25: =P25-V25 -> 0.13122886 | AC25: =Q25-W25 -> 0.072511476
A26: 0.4 | B26: 0.14 | C26: 3.927 | D26: 1.5707963 | E26: 0.5 | F26: 0.02 | G26: 3.142 | H26: 1.5707963 | I26: 0.8 | J26: 0 | K26: 0 | L26: -0.00188526 | M26: 0.062983148 | N26: -0.11185148 | O26: -0.032080602 | P26: -0.69933581 | Q26: -0.26614279 | R26: -0.00029250796 | S26: 0.064812569 | T26: -0.11946024 | U26: -0.06408533 | V26: -0.78024602 | W26: -0.28040112 | X26: =L26-R26 -> -0.001592752 | Y26: =M26-S26 -> -0.0018294213 | Z26: =N26-T26 -> 0.0076087668 | AA26: =O26-U26 -> 0.032004728 | AB26: =P26-V26 -> 0.08091021 | AC26: =Q26-W26 -> 0.014258336
A27: 0.7 | B27: 0.12 | C27: 3.927 | D27: 1.5707963 | E27: 0.7 | F27: 0.08 | G27: 3.927 | H27: 1.5707963 | I27: 1.2 | J27: 0 | K27: 0 | L27: -0.003717537 | M27: 0.17499575 | N27: -0.20276137 | O27: -0.35743338 | P27: -1.0157691 | Q27: -0.8504957 | R27: -0.000757647 | S27: 0.1848712 | T27: -0.18490908 | U27: -0.33320516 | V27: -0.96223825 | W27: -0.9606706 | X27: =L27-R27 -> -0.00295989 | Y27: =M27-S27 -> -0.0098754518 | Z27: =N27-T27 -> -0.017852291 | AA27: =O27-U27 -> -0.024228215 | AB27: =P27-V27 -> -0.053530879 | AC27: =Q27-W27 -> 0.11017491
A28: 0.3 | B28: 0.1 | C28: 3.927 | D28: 1.5707963 | E28: 0.8 | F28: 0.04 | G28: 4.712 | H28: 1.5707963 | I28: 0 | J28: 0 | K28: 0 | L28: -0.0002498161 | M28: 0.14310579 | N28: -0.042481523 | O28: -0.067212105 | P28: -0.22611594 | Q28: -0.98430818 | R28: 5.2957685e-12 | S28: 0.14394788 | T28: -0.040256908 | U28: -0.059004686 | V28: -0.21162267 | W28: -1.0105138 | X28: =L28-R28 -> -0.00024981611 | Y28: =M28-S28 -> -0.00084208801 | Z28: =N28-T28 -> -0.0022246151 | AA28: =O28-U28 -> -0.0082074187 | AB28: =P28-V28 -> -0.014493274 | AC28: =Q28-W28 -> 0.026205596
A29: 0.6 | B29: 0.18 | C29: 3.927 | D29: 1.5707963 | E29: 0.4 | F29: 0.08 | G29: 4.712 | H29: 1.5707963 | I29: 0 | J29: 0 | K29: 0 | L29: -0.0013586492 | M29: 0.15828507 | N29: -0.10169891 | O29: -0.36798006 | P29: -0.32599631 | Q29: -0.6542244 | R29: 1.489349e-10 | S29: 0.17171109 | T29: -0.10553244 | U29: -0.41339099 | V29: -0.35721403 | W29: -0.74175584 | X29: =L29-R29 -> -0.0013586494 | Y29: =M29-S29 -> -0.013426025 | Z29: =N29-T29 -> 0.0038335261 | AA29: =O29-U29 -> 0.045410925 | AB29: =P29-V29 -> 0.031217718 | AC29: =Q29-W29 -> 0.087531448
... A32: 0.8 | B32: 0.2 | C32: 4.712 | D32: 1.5707963 | E32: 0.3 | F32: 0.02 | G32: 4.712 | H32: 1.5707963 | I32: 0.8 | J32: 0 | K32: 0 | L32: -0.011667065 | M32: 0.23207891 | N32: -0.017367871 | O32: -0.68982279 | P32: -0.12469035 | Q32: -0.78086811 | R32: -0.0049138297 | S32: 0.22384018 | T32: -0.00079064999 | U32: -0.61727008 | V32: -0.017504905 | W32: -0.83773899 | X32: =L32-R32 -> -0.0067532356 | Y32: =M32-S32 -> 0.0082387336 | Z32: =N32-T32 -> -0.016577221 | AA32: =O32-U32 -> -0.07255271 | AB32: =P32-V32 -> -0.10718545 | AC32: =Q32-W32 -> 0.056870873
X33: Systematic Bias
X34: =AVERAGE(X4:X32) -> -0.0012177573 | Y34: =AVERAGE(Y4:Y32) -> -0.0013714938 | Z34: =AVERAGE(Z4:Z32) -> 0.0024964835 | AA34: =AVERAGE(AA4:AA32) -> 0.0054927274 | AB34: =AVERAGE(AB4:AB32) -> 0.026226579 | AC34: =AVERAGE(AC4:AC32) -> 0.02600292
X35: Centered Data (Subtract the Mean)
X36: =X4-X$34 -> 0.00023415072 | Y36: =Y4-Y$34 -> -0.0049402934 | Z36: =Z4-Z$34 -> -0.0028595008 | AA36: =AA4-AA$34 -> -0.056937678 | AB36: =AB4-AB$34 -> -0.027242329 | AC36: =AC4-AC$34 -> -0.0038648137
X37: =X5-X$34 -> 0.00016413809 | Y37: =Y5-Y$34 -> 0.014489602 | Z37: =Z5-Z$34 -> -0.0034489087 | AA37: =AA5-AA$34 -> -0.07758833 | AB37: =AB5-AB$34 -> -0.031591572 | AC37: =AC5-AC$34 -> -0.11995995
X38: =X6-X$34 -> 0.0034833415 | Y38: =Y6-Y$34 -> 0.021213298 | Z38: =Z6-Z$34 -> -0.0009829482 | AA38: =AA6-AA$34 -> 0.049420055 | AB38: =AB6-AB$34 -> 0.061547064 | AC38: =AC6-AC$34 -> -0.16165205
X39: =X7-X$34 -> -0.0018474943 | Y39: =Y7-Y$34 -> -0.0047530791 | Z39: =Z7-Z$34 -> -0.00081305987 | AA39: =AA7-AA$34 -> -0.01716499 | AB39: =AB7-AB$34 -> 0.0085967394 | AC39: =AC7-AC$34 -> 0.032332217
X40: =X8-X$34 -> -0.0020876769 | Y40: =Y8-Y$34 -> -0.010375671 | Z40: =Z8-Z$34 -> -0.013813191 | AA40: =AA8-AA$34 -> -0.069845716 | AB40: =AB8-AB$34 -> -0.053472424 | AC40: =AC8-AC$34 -> 0.057700253
X41: =X9-X$34 -> 0.0010074404 | Y41: =Y9-Y$34 -> -0.00093223886 | Z41: =Z9-Z$34 -> 0.019799154 | AA41: =AA9-AA$34 -> 0.050643105 | AB41: =AB9-AB$34 -> 0.050003972 | AC41: =AC9-AC$34 -> 0.0026176062
X42: =X10-X$34 -> 0.0011295647 | Y42: =Y10-Y$34 -> -0.0072390097 | Z42: =Z10-Z$34 -> 0.017567434 | AA42: =AA10-AA$34 -> 0.057749599 | AB42: =AB10-AB$34 -> 0.041363923 | AC42: =AC10-AC$34 -> 0.05635439
X43: =X11-X$34 -> 0.00059126335 | Y43: =Y11-Y$34 -> -0.010070592 | Z43: =Z11-Z$34 -> 0.0054572787 | AA43: =AA11-AA$34 -> 0.015328203 | AB43: =AB11-AB$34 -> 0.028314773 | AC43: =AC11-AC$34 -> 0.02769258
...

Sheet Sensor_Error
A1: Static Noise test under 1.2N load (z-direction)
A2: Tx (Nm) | B2: Ty (Nm) | C2: Tz(Nm) | D2: Fx (N) | E2: Fy (N) | F2: Fz (N)
A3: -0.0017544741 | B3: -0.31834593 | C3: -0.0062641464 | D3: -0.67475188 | E3: 0.0031938329 | F3: 0.96315092
A4: -0.0017534195 | B4: -0.31835026 | C4: -0.0062434999 | D4: -0.67515111 | E4: 0.003249865 | F4: 0.96419638
A5: -0.00175065 | B5: -0.3183178 | C5: -0.0062407386 | D5: -0.67596114 | E5: 0.003219787 | F5: 0.96527058
A6: -0.00176247 | B6: -0.318362 | C6: -0.0062614218 | D6: -0.67551816 | E6: 0.0031419545 | F6: 0.96570301
A7: -0.0017611502 | B7: -0.31840476 | C7: -0.0062717665 | D7: -0.67516607 | E7: 0.0032033063 | F7: 0.96672642
A8: -0.0017708013 | B8: -0.31842884 | C8: -0.0062596272 | D8: -0.67413068 | E8: 0.0030201077 | F8: 0.9674567
A9: -0.0017753852 | B9: -0.31843546 | C9: -0.0062413448 | D9: -0.67258775 | E9: 0.0028775595 | F9: 0.96834368
A10: -0.0017675861 | B10: -0.31845599 | C10: -0.0062550427 | D10: -0.67437357 | E10: 0.0031309016 | F10: 0.96913028
A11: -0.001760295 | B11: -0.31848273 | C11: -0.0062672496 | D11: -0.67366177 | E11: 0.0030561797 | F11: 0.96976024
A12: -0.0017629904 | B12: -0.31848401 | C12: -0.006263535 | D12: -0.6721319 | E12: 0.002911929 | F12: 0.97022724
A13: -0.0017632052 | B13: -0.31846476 | C13: -0.0062491959 | D13: -0.67392349 | E13: 0.0028755814 | F13: 0.9705947
A14: -0.0017737487 | B14: -0.31846607 | C14: -0.006240231 | D14: -0.67248791 | E14: 0.0027865358 | F14: 0.97107357
... A27: -0.0017444015 | B27: -0.31862673 | C27: -0.0062394086 | D27: -0.66939992 | E27: 0.0021561831 | F27: 0.97596657
A28: Sensor_Error Standard Deviation
A29: =_xlfn.STDEV.S(A3:A27) -> 1.1289891e-05 | B29: =_xlfn.STDEV.S(B3:B27) -> 8.6804022e-05 | C29: =_xlfn.STDEV.S(C3:C27) -> 9.4816636e-06 | D29: =_xlfn.STDEV.S(D3:D27) -> 0.0020238276 | E29: =_xlfn.STDEV.S(E3:E27) -> 0.00037348373 | F29: =_xlfn.STDEV.S(F3:F27) -> 0.003767216
A30: Corrected (assuming symmetric and isotropic)
A31: =A29 -> 1.1289891e-05 | B31: =MAX(B29:C29) -> 8.6804022e-05 | C31: =MAX(B29:C29) -> 8.6804022e-05 | D31: =D29 -> 0.0020238276 | E31: =MAX(E29,F29) -> 0.003767216 | F31: =MAX(E29,F29) -> 0.003767216

Sheet Hysteresis_Error
A1: Applied weight (g) | B1: Applied force (N) | C1: Up | I1: Down | O1: Errors
A2: Applied weight (g) | C2: Tx (Nm) | D2: Ty (Nm) | E2: Tz(Nm) | F2: Fx (N) | G2: Fy (N) | H2: Fz (N) | I2: Tx (Nm) | J2: Ty (Nm) | K2: Tz(Nm) | L2: Fx (N) | M2: Fy (N) | N2: Fz (N) | O2: Tx (Nm) | P2: Ty (Nm) | Q2: Tz(Nm) | R2: Fx (N) | S2: Fy (N) | T2: Fz (N)
A3: 0 | B3: 0 | C3: -1.6087802e-06 | D3: 1.8846531e-05 | E3: 2.8883799e-06 | F3: -0.00098100444 | G3: 1.3394689e-05 | H3: -0.00092765869 | I3: 6.2304316e-05 | J3: -0.00041646138 | K3: 4.042537e-05 | L3: 0.011366883 | M3: -0.0013664588 | N3: 0.013270041 | O3: =ABS(I3-C3) -> 6.3913096e-05 | P3: =ABS(J3-D3) -> 0.00043530791 | Q3: =ABS(K3-E3) -> 3.753699e-05 | R3: =ABS(L3-F3) -> 0.012347888 | S3: =ABS(M3-G3) -> 0.0013798535 | T3: =ABS(N3-H3) -> 0.0141977
A4: 50 | B4: =(A3+A4)/1000*9.81 -> 0.4905 | C4: -0.00030997174 | D4: -0.12928464 | E4: -0.0022936268 | F4: -0.26717237 | G4: 0.0015018564 | H4: 0.39772457 | I4: -0.00060571008 | J4: -0.12970544 | K4: -0.0024937091 | L4: -0.27222991 | M4: -0.00094631687 | N4: 0.41247585 | O4: =ABS(I4-C4) -> 0.00029573834 | P4: =ABS(J4-D4) -> 0.00042080879 | Q4: =ABS(K4-E4) -> 0.00020008232 | R4: =ABS(L4-F4) -> 0.0050575435 | S4: =ABS(M4-G4) -> 0.0024481732 | T4: =ABS(N4-H4) -> 0.014751285
A5: 50 | B5: =(A3+A4+A5)/1000*9.81 -> 0.981 | C5: -0.0013172396 | D5: -0.26506674 | E5: -0.0051040533 | F5: -0.5514158 | G5: 0.0026175641 | H5: 0.80131876 | I5: -0.0015634394 | J5: -0.26617882 | K5: -0.0052859844 | L5: -0.55877525 | M5: 0.0018646903 | N5: 0.81001902 | O5: =ABS(I5-C5) -> 0.00024619978 | P5: =ABS(J5-D5) -> 0.0011120737 | Q5: =ABS(K5-E5) -> 0.00018193107 | R5: =ABS(L5-F5) -> 0.0073594451 | S5: =ABS(M5-G5) -> 0.00075287372 | T5: =ABS(N5-H5) -> 0.0087002516
A6: 20 | B6: =(A3+A4+A5+A6)/1000*9.81 -> 1.1772 | C6: -0.0017683464 | D6: -0.31844446 | E6: -0.0062346826 | F6: -0.67402482 | G6: 0.0032806806 | H6: 0.96414262 | I6: -0.0017683464 | J6: -0.31844446 | K6: -0.0062346826 | L6: -0.67402482 | M6: 0.0032806806 | N6: 0.96414262 | O6: =ABS(I6-C6) -> 0 | P6: =ABS(J6-D6) -> 0 | Q6: =ABS(K6-E6) -> 0 | R6: =ABS(L6-F6) -> 0 | S6: =ABS(M6-G6) -> 0 | T6: =ABS(N6-H6) -> 0
O7: Max
O8: =MAX(O3:O6) -> 0.00029573834 | P8: =MAX(P3:P6) -> 0.0011120737 | Q8: =MAX(Q3:Q6) -> 0.00020008232 | R8: =MAX(R3:R6) -> 0.012347888 | S8: =MAX(S3:S6) -> 0.0024481732 | T8: =MAX(T3:T6) -> 0.014751285
O9: Hysteresis_Error Standard Deviation
O10: =O8/(2*SQRT(3)) -> 8.5372305e-05 | P10: =P8/(2*SQRT(3)) -> 0.00032102801 | Q10: =Q8/(2*SQRT(3)) -> 5.7758789e-05 | R10: =R8/(2*SQRT(3)) -> 0.0035645282 | S10: =S8/(2*SQRT(3)) -> 0.00070672674 | T10: =T8/(2*SQRT(3)) -> 0.0042583293
O11: Corrected (assuming symmetric and isotropic)
O12: =O10 -> 8.5372305e-05 | P12: =MAX(P10,Q10) -> 0.00032102801 | Q12: =MAX(P10,Q10) -> 0.00032102801 | R12: =R10 -> 0.0035645282 | S12: =MAX(S10:T10) -> 0.0042583293 | T12: =MAX(S10:T10) -> 0.0042583293
C13: -0.0017683464 | D13: -0.31844446 | E13: -0.0062346826 | F13: -0.67402482 | G13: 0.0032806806 | H13: 0.96414262
C14: -0.0015634394 | D14: -0.26617882 | E14: -0.0052859844 | F14: -0.55877525 | G14: 0.0018646903 | H14: 0.81001902
C15: -0.00060571008 | D15: -0.12970544 | E15: -0.0024937091 | F15: -0.27222991 | G15: -0.00094631687 | H15: 0.41247585
C16: 6.2304316e-05 | D16: -0.00041646138 | E16: 4.042537e-05 | F16: 0.011366883 | G16: -0.0013664588 | H16: 0.013270041

Sheet Angle_Error
N1: 6-Axis FT Sensor | U1: |W_nominal - W_tilted|
A2: Experiment Name | B2: Tilt1 (deg) | C2: Tilt2 (deg) | E2: F1 (N) | F2: s1 (m) | G2: theta1 (rad) | H2: pitch1 (rad) | I2: F2 (N) | J2: s2 (m) | K2: theta2 (rad) | L2: pitch2 (rad) | N2: Tx (Nm) | O2: Ty (Nm) | P2: Tz(Nm) | Q2: Fx (N) | R2: Fy (N) | S2: Fz (N) | U2: Tx (Nm) | V2: Ty (Nm) | W2: Tz(Nm) | X2: Fx (N) | Y2: Fy (N) | Z2: Fz (N)
A3: Baseline (r=2 mm cylindrical) Direction (y-axis) | B3: 0 | C3: 0 | E3: 1.2 | F3: 0.2 | G3: 0 | H3: =PI()/2 -> 1.5707963 | I3: 1.2 | J3: 0.18 | K3: 0 | L3: =PI()/2 -> 1.5707963 | N3: 0 | O3: 0 | P3: 0.3561 | Q3: -2.3912 | R3: 0.2054 | S3: 0
A4: Scenario A: Direction (y-axis) Both Tilt Up | B4: 3 | C4: 3 | E4: 1.2 | F4: 0.2 | G4: 0 | H4: =H$3+RADIANS(B4) -> 1.6231562 | I4: 1.2 | J4: 0.18 | K4: 0 | L4: =L$3+RADIANS(C4) -> 1.6231562 | N4: 0 | O4: 0 | P4: 0.347 | Q4: -2.3965 | R4: 0.129 | S4: 0 | U4: =ABS(N$3-N4) -> 0 | V4: =ABS(O$3-O4) -> 0 | W4: =ABS(P$3-P4) -> 0.0091 | X4: =ABS(Q$3-Q4) -> 0.0053 | Y4: =ABS(R$3-R4) -> 0.0764 | Z4: =ABS(S$3-S4) -> 0
A5: Scenario B: Direction (y-axis) Both Tilt Down | B5: -3 | C5: -3 | E5: 1.2 | F5: 0.2 | G5: 0 | H5: =H$3+RADIANS(B5) -> 1.5184364 | I5: 1.2 | J5: 0.18 | K5: 0 | L5: =L$3+RADIANS(C5) -> 1.5184364 | N5: 0 | O5: 0 | P5: 0.3647 | Q5: -2.3824 | R5: 0.2895 | S5: 0 | U5: =ABS(N$3-N5) -> 0 | V5: =ABS(O$3-O5) -> 0 | W5: =ABS(P$3-P5) -> 0.0086 | X5: =ABS(Q$3-Q5) -> 0.0088 | Y5: =ABS(R$3-R5) -> 0.0841 | Z5: =ABS(S$3-S5) -> 0
A6: Scenario C: Direction (y-axis) Opposite Tilt | B6: 3 | C6: -3 | E6: 1.2 | F6: 0.2 | G6: 0 | H6: =H$3+RADIANS(B6) -> 1.6231562 | I6: 1.2 | J6: 0.18 | K6: 0 | L6: =L$3+RADIANS(C6) -> 1.5184364 | N6: 0 | O6: 0 | P6: 0.3558 | Q6: -2.387 | R6: 0.2098 | S6: 0 | U6: =ABS(N$3-N6) -> 0 | V6: =ABS(O$3-O6) -> 0 | W6: =ABS(P$3-P6) -> 0.0003 | X6: =ABS(Q$3-Q6) -> 0.0042 | Y6: =ABS(R$3-R6) -> 0.0044 | Z6: =ABS(S$3-S6) -> 0
A7: Scenario D: Direction (y-axis) Opposite Tilt Flipped | B7: -3 | C7: 3 | E7: 1.2 | F7: 0.2 | G7: 0 | H7: =H$3+RADIANS(B7) -> 1.5184364 | I7: 1.2 | J7: 0.18 | K7: 0 | L7: =L$3+RADIANS(C7) -> 1.6231562 | N7: 0 | O7: 0 | P7: 0.3559 | Q7: -2.388 | R7: 0.2088 | S7: 0 | U7: =ABS(N$3-N7) -> 0 | V7: =ABS(O$3-O7) -> 0 | W7: =ABS(P$3-P7) -> 0.0002 | X7: =ABS(Q$3-Q7) -> 0.0032 | Y7: =ABS(R$3-R7) -> 0.0034 | Z7: =ABS(S$3-S7) -> 0
A8: Baseline (r=2 mm cylindrical) Direction (z-axis) | B8: 0 | C8: 0 | E8: 1.2 | F8: 0.2 | G8: =PI()/2 -> 1.5707963 | H8: =H$3+RADIANS(B8) -> 1.5707963 | I8: 1.2 | J8: 0.18 | K8: =PI()/2 -> 1.5707963 | L8: =L$3+RADIANS(C8) -> 1.5707963 | N8: 0 | O8: -0.3561 | P8: 0 | Q8: -2.3912 | R8: 0 | S8: 0.2054
A9: Scenario E: Direction (z-axis) Both Tilt Up | B9: 3 | C9: 3 | E9: 1.2 | F9: 0.2 | G9: =PI()/2 -> 1.5707963 | H9: =H$3+RADIANS(B9) -> 1.6231562 | I9: 1.2 | J9: 0.18 | K9: =PI()/2 -> 1.5707963 | L9: =L$3+RADIANS(C9) -> 1.6231562 | N9: 0 | O9: -0.347 | P9: 0 | Q9: -2.3965 | R9: 0 | S9: 0.129 | U9: =ABS(N$8-N9) -> 0 | V9: =ABS(O$8-O9) -> 0.0091 | W9: =ABS(P$8-P9) -> 0 | X9: =ABS(Q$8-Q9) -> 0.0053 | Y9: =ABS(R$8-R9) -> 0 | Z9: =ABS(S$8-S9) -> 0.0764
A10: Scenario F: Direction (z-axis) Both Tilt Down | B10: -3 | C10: -3 | E10: 1.2 | F10: 0.2 | G10: =PI()/2 -> 1.5707963 | H10: =H$3+RADIANS(B10) -> 1.5184364 | I10: 1.2 | J10: 0.18 | K10: =PI()/2 -> 1.5707963 | L10: =L$3+RADIANS(C10) -> 1.5184364 | N10: 0 | O10: -0.3647 | P10: 0 | Q10: -2.3824 | R10: 0 | S10: 0.2895 | U10: =ABS(N$8-N10) -> 0 | V10: =ABS(O$8-O10) -> 0.0086 | W10: =ABS(P$8-P10) -> 0 | X10: =ABS(Q$8-Q10) -> 0.0088 | Y10: =ABS(R$8-R10) -> 0 | Z10: =ABS(S$8-S10) -> 0.0841
A11: Scenario G: Direction (z-axis) Opposite Tilt | B11: 3 | C11: -3 | E11: 1.2 | F11: 0.2 | G11: =PI()/2 -> 1.5707963 | H11: =H$3+RADIANS(B11) -> 1.6231562 | I11: 1.2 | J11: 0.18 | K11: =PI()/2 -> 1.5707963 | L11: =L$3+RADIANS(C11) -> 1.5184364 | N11: 0 | O11: -0.3558 | P11: 0 | Q11: -2.387 | R11: 0 | S11: 0.2098 | U11: =ABS(N$8-N11) -> 0 | V11: =ABS(O$8-O11) -> 0.0003 | W11: =ABS(P$8-P11) -> 0 | X11: =ABS(Q$8-Q11) -> 0.0042 | Y11: =ABS(R$8-R11) -> 0 | Z11: =ABS(S$8-S11) -> 0.0044
A12: Scenario H: Direction (z-axis) Opposite Tilt Flipped | B12: -3 | C12: 3 | E12: 1.2 | F12: 0.2 | G12: =PI()/2 -> 1.5707963 | H12: =H$3+RADIANS(B12) -> 1.5184364 | I12: 1.2 | J12: 0.18 | K12: =PI()/2 -> 1.5707963 | L12: =L$3+RADIANS(C12) -> 1.6231562 | N12: 0 | O12: -0.3559 | P12: 0 | Q12: -2.388 | R12: 0 | S12: 0.2088 | U12: =ABS(N$8-N12) -> 0 | V12: =ABS(O$8-O12) -> 0.0002 | W12: =ABS(P$8-P12) -> 0 | X12: =ABS(Q$8-Q12) -> 0.0032 | Y12: =ABS(R$8-R12) -> 0 | Z12: =ABS(S$8-S12) -> 0.0034
U13: Maximum difference per channel
U14: =MAX(U4:U12) -> 0 | V14: =MAX(V4:V12) -> 0.0091 | W14: =MAX(W4:W12) -> 0.0091 | X14: =MAX(X4:X12) -> 0.0088 | Y14: =MAX(Y4:Y12) -> 0.0841 | Z14: =MAX(Z4:Z12) -> 0.0841
U15: Angle_Error Standard Deviation (assuming "Max Error" as the 3_sigma limit)
U16: =U14/3 -> 0 | V16: =V14/3 -> 0.0030333333 | W16: =W14/3 -> 0.0030333333 | X16: =X14/3 -> 0.0029333333 | Y16: =Y14/3 -> 0.028033333 | Z16: =Z14/3 -> 0.028033333

Sheet Overall_Error
A1: Tx (Nm) | B1: Ty (Nm) | C1: Tz(Nm) | D1: Fx (N) | E1: Fy (N) | F1: Fz (N)
A2: Sensor_Error Standard Deviation
A3: =Sensor_Error!A31 -> 1.1289891e-05 | B3: =Sensor_Error!B31 -> 8.6804022e-05 | C3: =Sensor_Error!C31 -> 8.6804022e-05 | D3: =Sensor_Error!D31 -> 0.0020238276 | E3: =Sensor_Error!E31 -> 0.003767216 | F3: =Sensor_Error!F31 -> 0.003767216
A4: Hysteresis_Error Standard Deviation
A5: =Hysteresis_Error!O12 -> 8.5372305e-05 | B5: =Hysteresis_Error!P12 -> 0.00032102801 | C5: =Hysteresis_Error!Q12 -> 0.00032102801 | D5: =Hysteresis_Error!R12 -> 0.0035645282 | E5: =Hysteresis_Error!S12 -> 0.0042583293 | F5: =Hysteresis_Error!T12 -> 0.0042583293
A6: Angle_Error Standard Deviation
A7: =Angle_Error!U16 -> 0 | B7: =Angle_Error!V16 -> 0.0030333333 | C7: =Angle_Error!W16 -> 0.0030333333 | D7: =Angle_Error!X16 -> 0.0029333333 | E7: =Angle_Error!Y16 -> 0.028033333 | F7: =Angle_Error!Z16 -> 0.028033333
A8: Overall Standard deviation
A9: =SQRT((A3)^2+(A5)^2+(A7)^2) -> 8.6115574e-05 | B9: =SQRT((B3)^2+(B5)^2+(B7)^2) -> 0.0030515086 | C9: =SQRT((C3)^2+(C5)^2+(C7)^2) -> 0.0030515086 | D9: =SQRT((D3)^2+(D5)^2+(D7)^2) -> 0.0050404547 | E9: =SQRT((E3)^2+(E5)^2+(E7)^2) -> 0.028604074 | F9: =SQRT((F3)^2+(F5)^2+(F7)^2) -> 0.028604074
