Workbook

Sheet Proximal Validation (double)
A1: Ground Truth | J1: 6-Axis FT Sensor | P1: SoRoSim get_proximal_value | V1: Proximal Errors
A2: F1 (N) | B2: s1 (m) | C2: el1 (rad) | D2: F2 (N) | E2: s2 (m) | F2: el2 (rad) | G2: tau1 (N) | H2: tau2 (N) | I2: tau3 (N) | J2: Tx (Nm) | K2: Ty (Nm) | L2: Tz(Nm) | M2: Fx (N) | N2: Fy (N) | O2: Fz (N) | P2: Tx (Nm) | Q2: Ty (Nm) | R2: Tz(Nm) | S2: Fx (N) | T2: Fy (N) | U2: Fz (N) | V2: Tx (Nm) | W2: Ty (Nm) | X2: Tz(Nm) | Y2: Fx (N) | Z2: Fy (N) | AA2: Fz (N)
A3: 0.7 | B3: 0.18 | C3: 2.356 | D3: 0.8 | E3: 0.06 | F3: 3.142 | G3: 0.8 | H3: 0 | I3: 0 | J3: 0.032339975 | K3: -0.05516617 | L3: -0.18954194 | M3: -0.67983842 | N3: -0.92226362 | O3: -0.11201197 | V3: =J3-P3 -> 0.032339975 | W3: =K3-Q3 -> -0.05516617 | X3: =L3-R3 -> -0.18954194 | Y3: =M3-S3 -> -0.67983842 | Z3: =N3-T3 -> -0.92226362 | AA3: =O3-U3 -> -0.11201197
A4: 0.6 | B4: 0.12 | C4: 2.356 | D4: 0.3 | E4: 0.04 | F4: 3.927 | G4: 0.4 | H4: 0 | I4: 0 | J4: 0.011516096 | K4: -0.049660508 | L4: -0.12653816 | M4: -0.35200155 | N4: -0.6693756 | O4: 0.073106274 | V4: =J4-P4 -> 0.011516096 | W4: =K4-Q4 -> -0.049660508 | X4: =L4-R4 -> -0.12653816 | Y4: =M4-S4 -> -0.35200155 | Z4: =N4-T4 -> -0.6693756 | AA4: =O4-U4 -> 0.073106274
A5: 0.8 | B5: 0.12 | C5: 2.356 | D5: 0.5 | E5: 0.06 | F5: 3.927 | G5: 0.4 | H5: 0 | I5: 0 | J5: 0.012158022 | K5: -0.055947427 | L5: -0.1395517 | M5: -0.49113488 | N5: -0.66529179 | O5: 0.049178556 | V5: =J5-P5 -> 0.012158022 | W5: =K5-Q5 -> -0.055947427 | X5: =L5-R5 -> -0.1395517 | Y5: =M5-S5 -> -0.49113488 | Z5: =N5-T5 -> -0.66529179 | AA5: =O5-U5 -> 0.049178556
A6: 0.3 | B6: 0.18 | C6: 3.142 | D6: 0.4 | E6: 0.04 | F6: 3.927 | G6: 1.2 | H6: 0 | I6: 0 | J6: 0.004800796 | K6: 0.04382915 | L6: -0.10502016 | M6: -0.040011849 | N6: -0.49215788 | O6: -0.30727568 | V6: =J6-P6 -> 0.004800796 | W6: =K6-Q6 -> 0.04382915 | X6: =L6-R6 -> -0.10502016 | Y6: =M6-S6 -> -0.040011849 | Z6: =N6-T6 -> -0.49215788 | AA6: =O6-U6 -> -0.30727568
A7: 0.5 | B7: 0.2 | C7: 3.142 | D7: 0.7 | E7: 0.04 | F7: 3.927 | G7: 0.4 | H7: 0 | I7: 0 | J7: 0.0033965623 | K7: 0.063226528 | L7: -0.19356807 | M7: -0.30557531 | N7: -0.88097358 | O7: -0.48669517 | V7: =J7-P7 -> 0.0033965623 | W7: =K7-Q7 -> 0.063226528 | X7: =L7-R7 -> -0.19356807 | Y7: =M7-S7 -> -0.30557531 | Z7: =N7-T7 -> -0.88097358 | AA7: =O7-U7 -> -0.48669517
A8: 0.4 | B8: 0.14 | C8: 3.927 | D8: 0.5 | E8: 0.02 | F8: 3.142 | G8: 0.8 | H8: 0 | I8: 0 | J8: -0.0059819799 | K8: 0.062610559 | L8: -0.12849849 | M8: -0.095138475 | N8: -0.78571397 | O8: -0.234833 | V8: =J8-P8 -> -0.0059819799 | W8: =K8-Q8 -> 0.062610559 | X8: =L8-R8 -> -0.12849849 | Y8: =M8-S8 -> -0.095138475 | Z8: =N8-T8 -> -0.78571397 | AA8: =O8-U8 -> -0.234833
A9: 0.7 | B9: 0.12 | C9: 3.927 | D9: 0.7 | E9: 0.08 | F9: 3.927 | G9: 1.2 | H9: 0 | I9: 0 | J9: -0.66562104 | K9: 1.0376637 | L9: -0.42349041 | M9: -0.20376933 | N9: -0.14496209 | O9: -0.021244271 | V9: =J9-P9 -> -0.66562104 | W9: =K9-Q9 -> 1.0376637 | X9: =L9-R9 -> -0.42349041 | Y9: =M9-S9 -> -0.20376933 | Z9: =N9-T9 -> -0.14496209 | AA9: =O9-U9 -> -0.021244271
A10: 0.3 | B10: 0.1 | C10: 3.927 | D10: 0.8 | E10: 0.04 | F10: 4.712 | G10: 0 | H10: 0 | I10: 0 | J10: -0.9477824 | K10: 0.24910346 | L10: -0.13659769 | M10: -0.045941409 | N10: -0.13913904 | O10: -0.0028178236 | V10: =J10-P10 -> -0.9477824 | W10: =K10-Q10 -> 0.24910346 | X10: =L10-R10 -> -0.13659769 | Y10: =M10-S10 -> -0.045941409 | Z10: =N10-T10 -> -0.13913904 | AA10: =O10-U10 -> -0.0028178236
V11: =AVERAGE(V3:V10) -> -0.19439675 | W11: =AVERAGE(W3:W10) -> 0.16195741 | X11: =AVERAGE(X3:X10) -> -0.18035083 | Y11: =AVERAGE(Y3:Y10) -> -0.2766764 | Z11: =AVERAGE(Z3:Z10) -> -0.5874847 | AA11: =AVERAGE(AA3:AA10) -> -0.13032414

Sheet Sheet2

Sheet Distal Validati (double)
A1: Ground Truth | J1: 6-Axis FT Sensor | P1: SoRoSim get_distal_value | W1: Distal Errors | AC1: Stats
A2: F1 (N) | B2: s1 (m) | C2: el1 (rad) | D2: F2 (N) | E2: s2 (m) | F2: el2 (rad) | G2: tau1 (N) | H2: tau2 (N) | I2: tau3 (N) | J2: Tx (Nm) | K2: Ty (Nm) | L2: Tz(Nm) | M2: Fx (N) | N2: Fy (N) | O2: Fz (N) | P2: F1 (N) | Q2: s1 (m) | R2: el1 (rad) | S2: F2 (N) | T2: s2 (m) | U2: el2 (rad) | V2: f_final | W2: F1 (N) | X2: s1 (m) | Y2: el1 (rad) | Z2: F2 (N) | AA2: s2 (m) | AB2: el2 (rad) | AC2: force_error | AD2: position_error | AE2: angle_error | AF2: Absolute Mean Error
A3: ='Proximal Validation (double)'!A3 -> 0.7 | B3: ='Proximal Validation (double)'!B3 -> 0.18 | C3: ='Proximal Validation (double)'!C3 -> 2.356 | D3: ='Proximal Validation (double)'!D3 -> 0.8 | E3: ='Proximal Validation (double)'!E3 -> 0.06 | F3: ='Proximal Validation (double)'!F3 -> 3.142 | G3: ='Proximal Validation (double)'!G3 -> 0.8 | H3: ='Proximal Validation (double)'!H3 -> 0 | ... O3: ='Proximal Validation (double)'!O3 -> -0.11201197 | P3: 1 | Q3: 0.14311583 | R3: 2.5534632 | S3: 0.46658201 | T3: 0.02 | U3: 4.2172045 | V3: 0.011683698 | W3: =P3-A3 -> 0.3 | X3: =Q3-B3 -> -0.036884168 | Y3: =R3-C3 -> 0.19746315 | Z3: =S3-D3 -> -0.33341799 | AA3: =T3-E3 -> -0.04 | AB3: =U3-F3 -> 1.0752045 | AC3: =AVERAGE(ABS(W3),ABS(Z3)) -> 0.316709 | AD3: =AVERAGE(ABS(X3),ABS(AA3)) -> 0.038442084 | AE3: =AVERAGE(ABS(Y3),ABS(AB3)) -> 0.63633382 | AF3: F1 (N) | AG3: s1 (m) | AH3: el1 (rad) | AI3: F2 (N) | AJ3: s2 (m) | AK3: el2 (rad)
A4: ='Proximal Validation (double)'!A4 -> 0.6 | B4: ='Proximal Validation (double)'!B4 -> 0.12 | C4: ='Proximal Validation (double)'!C4 -> 2.356 | D4: ='Proximal Validation (double)'!D4 -> 0.3 | E4: ='Proximal Validation (double)'!E4 -> 0.04 | F4: ='Proximal Validation (double)'!F4 -> 3.927 | G4: ='Proximal Validation (double)'!G4 -> 0.4 | H4: ='Proximal Validation (double)'!H4 -> 0 | ... O4: ='Proximal Validation (double)'!O4 -> 0.073106274 | P4: 0.56702431 | Q4: 0.18135171 | R4: 1.1318375 | S4: 1 | T4: 0.12230488 | U4: 3.4858687 | V4: 0.010367105 | W4: =P4-A4 -> -0.032975692 | X4: =Q4-B4 -> 0.061351713 | Y4: =R4-C4 -> -1.2241625 | Z4: =S4-D4 -> 0.7 | AA4: =T4-E4 -> 0.08230488 | AB4: =U4-F4 -> -0.44113135 | AC4: =AVERAGE(ABS(W4),ABS(Z4)) -> 0.36648785 | AD4: =AVERAGE(ABS(X4),ABS(AA4)) -> 0.071828297 | AE4: =AVERAGE(ABS(Y4),ABS(AB4)) -> 0.83264691 | AF4: {=AVERAGE(ABS(W3:W8))} -> 0.22860975 | AG4: {=AVERAGE(ABS(X3:X8))} -> 0.031745665 | AH4: {=AVERAGE(ABS(Y3:Y8))} -> 0.47276771 | AI4: {=AVERAGE(ABS(Z3:Z8))} -> 0.251924 | AJ4: {=AVERAGE(ABS(AA3:AA8))} -> 0.044777671 | AK4: {=AVERAGE(ABS(AB3:AB10))} -> 0.68075773
A5: ='Proximal Validation (double)'!A5 -> 0.8 | B5: ='Proximal Validation (double)'!B5 -> 0.12 | C5: ='Proximal Validation (double)'!C5 -> 2.356 | D5: ='Proximal Validation (double)'!D5 -> 0.5 | E5: ='Proximal Validation (double)'!E5 -> 0.06 | F5: ='Proximal Validation (double)'!F5 -> 3.927 | G5: ='Proximal Validation (double)'!G5 -> 0.4 | H5: ='Proximal Validation (double)'!H5 -> 0 | ... O5: ='Proximal Validation (double)'!O5 -> 0.049178556 | P5: 1 | Q5: 0.11135302 | R5: 2.4898077 | S5: 0.45533115 | T5: 0.02 | U5: 4.8812818 | V5: 0.019737606 | W5: =P5-A5 -> 0.2 | X5: =Q5-B5 -> -0.008646982 | Y5: =R5-C5 -> 0.13380765 | Z5: =S5-D5 -> -0.044668854 | AA5: =T5-E5 -> -0.04 | AB5: =U5-F5 -> 0.95428181 | AC5: =AVERAGE(ABS(W5),ABS(Z5)) -> 0.12233443 | AD5: =AVERAGE(ABS(X5),ABS(AA5)) -> 0.024323491 | AE5: =AVERAGE(ABS(Y5),ABS(AB5)) -> 0.54404473 | AF5: Absolute Mean Error (Across Both Forces)
A6: ='Proximal Validation (double)'!A6 -> 0.3 | B6: ='Proximal Validation (double)'!B6 -> 0.18 | C6: ='Proximal Validation (double)'!C6 -> 3.142 | D6: ='Proximal Validation (double)'!D6 -> 0.4 | E6: ='Proximal Validation (double)'!E6 -> 0.04 | F6: ='Proximal Validation (double)'!F6 -> 3.927 | G6: ='Proximal Validation (double)'!G6 -> 1.2 | H6: ='Proximal Validation (double)'!H6 -> 0 | ... O6: ='Proximal Validation (double)'!O6 -> -0.30727568 | P6: 0.19030564 | Q6: 0.1998792 | R6: 2.4500697 | S6: 0.55450803 | T6: 0.090565681 | U6: 4.0339353 | V6: 0.001619745 | W6: =P6-A6 -> -0.10969436 | X6: =Q6-B6 -> 0.0198792 | Y6: =R6-C6 -> -0.69193033 | Z6: =S6-D6 -> 0.15450803 | AA6: =T6-E6 -> 0.050565681 | AB6: =U6-F6 -> 0.10693528 | AC6: =AVERAGE(ABS(W6),ABS(Z6)) -> 0.1321012 | AD6: =AVERAGE(ABS(X6),ABS(AA6)) -> 0.03522244 | AE6: =AVERAGE(ABS(Y6),ABS(AB6)) -> 0.39943281 | AF6: force_error | AG6: position_error | AH6: angle_error
A7: ='Proximal Validation (double)'!A7 -> 0.5 | B7: ='Proximal Validation (double)'!B7 -> 0.2 | C7: ='Proximal Validation (double)'!C7 -> 3.142 | D7: ='Proximal Validation (double)'!D7 -> 0.7 | E7: ='Proximal Validation (double)'!E7 -> 0.04 | F7: ='Proximal Validation (double)'!F7 -> 3.927 | G7: ='Proximal Validation (double)'!G7 -> 0.4 | H7: ='Proximal Validation (double)'!H7 -> 0 | ... O7: ='Proximal Validation (double)'!O7 -> -0.48669517 | P7: 0.37100883 | Q7: 0.2 | R7: 2.5754335 | S7: 0.92618934 | T7: 0.085998425 | U7: 3.9755473 | V7: 0.00027827099 | W7: =P7-A7 -> -0.12899117 | X7: =Q7-B7 -> -4.0495385e-14 | Y7: =R7-C7 -> -0.56656648 | Z7: =S7-D7 -> 0.22618934 | AA7: =T7-E7 -> 0.045998425 | AB7: =U7-F7 -> 0.048547258 | AC7: =AVERAGE(ABS(W7),ABS(Z7)) -> 0.17759026 | AD7: =AVERAGE(ABS(X7),ABS(AA7)) -> 0.022999213 | AE7: =AVERAGE(ABS(Y7),ABS(AB7)) -> 0.30755687 | AF7: =AVERAGE(AF4,AI4) -> 0.24026688 | AG7: =AVERAGE(AG4,AJ4) -> 0.038261668 | AH7: =AVERAGE(AH4,AK4) -> 0.57676272
A8: ='Proximal Validation (double)'!A8 -> 0.4 | B8: ='Proximal Validation (double)'!B8 -> 0.14 | C8: ='Proximal Validation (double)'!C8 -> 3.927 | D8: ='Proximal Validation (double)'!D8 -> 0.5 | E8: ='Proximal Validation (double)'!E8 -> 0.02 | F8: ='Proximal Validation (double)'!F8 -> 3.142 | G8: ='Proximal Validation (double)'!G8 -> 0.8 | H8: ='Proximal Validation (double)'!H8 -> 0 | ... O8: ='Proximal Validation (double)'!O8 -> -0.234833 | P8: 0.9999973 | Q8: 0.076288076 | R8: 3.9043238 | S8: 0.44724023 | T8: 0.029797041 | U8: 1.7268608 | V8: 0.0029143271 | W8: =P8-A8 -> 0.5999973 | X8: =Q8-B8 -> -0.063711924 | Y8: =R8-C8 -> -0.022676194 | Z8: =S8-D8 -> -0.052759772 | AA8: =T8-E8 -> 0.0097970406 | AB8: =U8-F8 -> -1.4151392 | AC8: =AVERAGE(ABS(W8),ABS(Z8)) -> 0.32637854 | AD8: =AVERAGE(ABS(X8),ABS(AA8)) -> 0.036754482 | AE8: =AVERAGE(ABS(Y8),ABS(AB8)) -> 0.7189077
A9: ='Proximal Validation (double)'!A9 -> 0.7 | B9: ='Proximal Validation (double)'!B9 -> 0.12 | C9: ='Proximal Validation (double)'!C9 -> 3.927 | D9: ='Proximal Validation (double)'!D9 -> 0.7 | E9: ='Proximal Validation (double)'!E9 -> 0.08 | F9: ='Proximal Validation (double)'!F9 -> 3.927 | G9: ='Proximal Validation (double)'!G9 -> 1.2 | H9: ='Proximal Validation (double)'!H9 -> 0 | ... O9: ='Proximal Validation (double)'!O9 -> -0.021244271 | P9: 0.98865522 | Q9: 0.1999475 | R9: 3.5071064 | S9: 0.9815433 | T9: 0.167055 | U9: 3.6796607 | V9: 117.30864 | W9: =P9-A9 -> 0.28865522 | X9: =Q9-B9 -> 0.079947496 | Y9: =R9-C9 -> -0.41989361 | Z9: =S9-D9 -> 0.2815433 | AA9: =T9-E9 -> 0.087054997 | AB9: =U9-F9 -> -0.24733932 | AC9: =AVERAGE(ABS(W9),ABS(Z9)) -> 0.28509926 | AD9: =AVERAGE(ABS(X9),ABS(AA9)) -> 0.083501247 | AE9: =AVERAGE(ABS(Y9),ABS(AB9)) -> 0.33361647
A10: ='Proximal Validation (double)'!A10 -> 0.3 | B10: ='Proximal Validation (double)'!B10 -> 0.1 | C10: ='Proximal Validation (double)'!C10 -> 3.927 | D10: ='Proximal Validation (double)'!D10 -> 0.8 | E10: ='Proximal Validation (double)'!E10 -> 0.04 | F10: ='Proximal Validation (double)'!F10 -> 4.712 | G10: ='Proximal Validation (double)'!G10 -> 0 | H10: ='Proximal Validation (double)'!H10 -> 0 | ... O10: ='Proximal Validation (double)'!O10 -> -0.0028178236 | P10: 0.99881193 | Q10: 0.19999785 | R10: 3.5528287 | S10: 0.99813105 | T10: 0.19999741 | U10: 3.5545169 | V10: 64.880144 | W10: =P10-A10 -> 0.69881193 | X10: =Q10-B10 -> 0.099997849 | Y10: =R10-C10 -> -0.37417127 | Z10: =S10-D10 -> 0.19813105 | AA10: =T10-E10 -> 0.15999741 | AB10: =U10-F10 -> -1.1574831 | AC10: =AVERAGE(ABS(W10),ABS(Z10)) -> 0.44847149 | AD10: =AVERAGE(ABS(X10),ABS(AA10)) -> 0.12999763 | AE10: =AVERAGE(ABS(Y10),ABS(AB10)) -> 0.76582721

Sheet Sheet1
A1: [ | B1: 0.7 | C1: 0.1 | D1: 1.57 | E1: =PI()/2 -> 1.5707963 | F1: 0.4 | G1: 0.04 | H1: =3*PI()/2 -> 4.712389 | I1: =PI()/2 -> 1.5707963 | J1: 0 | K1: 0 | L1: 1.4 | M1: ;
B2: 0.7 | C2: 0.12 | D2: 1.57 | E2: =PI()/2 -> 1.5707963 | F2: 0.3 | G2: 0.06 | H2: =3*PI()/2 -> 4.712389 | I2: =PI()/2 -> 1.5707963 | J2: 0 | K2: 0 | L2: 0 | M2: ;
B3: 0.5 | C3: 0.12 | D3: 1.57 | E3: =PI()/2 -> 1.5707963 | F3: 0.6 | G3: 0.08 | H3: =3*PI()/2 -> 4.712389 | I3: =PI()/2 -> 1.5707963 | J3: 0 | K3: 0 | L3: 1.4 | M3: ;
B4: 0.4 | C4: 0.14 | D4: 1.57 | E4: =PI()/2 -> 1.5707963 | F4: 0.8 | G4: 0.04 | H4: =3*PI()/2 -> 4.712389 | I4: =PI()/2 -> 1.5707963 | J4: 0 | K4: 0 | L4: 0 | M4: ;
B5: 0.6 | C5: 0.16 | D5: 1.57 | E5: =PI()/2 -> 1.5707963 | F5: 0.7 | G5: 0.02 | H5: =3*PI()/2 -> 4.712389 | I5: =PI()/2 -> 1.5707963 | J5: 0 | K5: 0 | L5: 0 | M5: ;
B6: 0.8 | C6: 0.18 | D6: 1.57 | E6: =PI()/2 -> 1.5707963 | F6: 0.7 | G6: 0.06 | H6: =3*PI()/2 -> 4.712389 | I6: =PI()/2 -> 1.5707963 | J6: 0 | K6: 0 | L6: 1.4 | M6: ;
B7: 0.3 | C7: 0.18 | D7: 1.57 | E7: =PI()/2 -> 1.5707963 | F7: 0.4 | G7: 0.08 | H7: =3*PI()/2 -> 4.712389 | I7: =PI()/2 -> 1.5707963 | J7: 0 | K7: 0 | L7: 0 | M7: ;
B8: 0.4 | C8: 0.2 | D8: 1.57 | E8: =PI()/2 -> 1.5707963 | F8: 0.5 | G8: 0.04 | H8: =3*PI()/2 -> 4.712389 | I8: =PI()/2 -> 1.5707963 | J8: 0 | K8: 0 | L8: 0 | M8: ;
B9: 0.4 | C9: 0.1 | D9: 4.712 | E9: =PI()/2 -> 1.5707963 | F9: 0.7 | G9: 0.06 | H9: =PI()/2 -> 1.5707963 | I9: =PI()/2 -> 1.5707963 | J9: 0 | K9: 0 | L9: 0 | M9: ;
B10: 0.8 | C10: 0.12 | D10: 4.712 | E10: =PI()/2 -> 1.5707963 | F10: 0.4 | G10: 0.02 | H10: =PI()/2 -> 1.5707963 | I10: =PI()/2 -> 1.5707963 | J10: 0 | K10: 0 | L10: 0 | M10: ;
B11: 0.3 | C11: 0.12 | D11: 4.712 | E11: =PI()/2 -> 1.5707963 | F11: 0.7 | G11: 0.04 | H11: =PI()/2 -> 1.5707963 | I11: =PI()/2 -> 1.5707963 | J11: 0 | K11: 0 | L11: 1.4 | M11: ;
B12: 0.5 | C12: 0.16 | D12: 4.712 | E12: =PI()/2 -> 1.5707963 | F12: 0.4 | G12: 0.06 | H12: =PI()/2 -> 1.5707963 | I12: =PI()/2 -> 1.5707963 | J12: 0 | K12: 0 | L12: 1.4 | M12: ;
B13: 0.4 | C13: 0.18 | D13: 4.712 | E13: =PI()/2 -> 1.5707963 | F13: 0.3 | G13: 0.02 | H13: =PI()/2 -> 1.5707963 | I13: =PI()/2 -> 1.5707963 | J13: 0 | K13: 0 | L13: 1.4 | M13: ;
B14: 0.7 | C14: 0.18 | D14: 4.712 | E14: =PI()/2 -> 1.5707963 | F14: 0.6 | G14: 0.04 | H14: =PI()/2 -> 1.5707963 | I14: =PI()/2 -> 1.5707963 | J14: 0 | K14: 0 | L14: 0 | M14: ;
B15: 0.7 | C15: 0.2 | D15: 4.712 | E15: =PI()/2 -> 1.5707963 | F15: 0.8 | G15: 0.08 | H15: =PI()/2 -> 1.5707963 | I15: =PI()/2 -> 1.5707963 | J15: 0 | K15: 0 | L15: 1.4 | M15: ]
A18: [ | B18: 1.2354019e-06 | C18: -0.080901492 | D18: 8.5561521e-05 | E18: -0.035094358 | F18: 0.00039991822 | G18: 0.29830922 | H18: 0 | I18: 0 | J18: 1.4 | K18: ; | P18: 0.011516096 | Q18: -0.049660508 | R18: -0.12653816 | S18: -0.35200155 | T18: -0.6693756 | U18: 0.073106274 | V18: 0.4 | W18: 0 | X18: 0
B19: -2.7164795e-14 | C19: -0.10063141 | D19: 9.8377411e-05 | E19: -0.10133876 | F19: 0.00043086256 | G19: 0.38844544 | H19: 0 | I19: 0 | J19: 0 | K19: ;
B20: 1.0847211e-06 | C20: -0.0030631078 | D20: 4.4039699e-05 | E20: 0.005590752 | F20: 0.00016521798 | G20: -0.099934204 | H20: 0 | I20: 0 | J20: 1.4 | K20: ;
B21: -1.238702e-14 | C21: 0.012355603 | D21: 3.2415892e-05 | E21: -0.026613777 | F21: 3.6387721e-06 | G21: -0.40428596 | H21: 0 | I21: 0 | J21: 0 | K21: ;
B22: -1.7242899e-14 | C22: -0.067858637 | D22: 8.5193682e-05 | E22: -0.18693874 | F22: 0.00017163039 | G22: -0.14209995 | H22: 0 | I22: 0 | J22: 0 | K22: ;
B23: 6.1334369e-06 | C23: -0.098740492 | D23: 0.00012077822 | E23: -0.25119989 | F23: 0.00027830697 | G23: 0.011765869 | H23: 0 | I23: 0 | J23: 1.4 | K23: ;
B24: -2.1949623e-14 | C24: -0.012292826 | D24: 3.7399967e-05 | E24: -0.028941645 | F24: 7.8230457e-05 | G24: -0.10555199 | H24: 0 | I24: 0 | J24: 0 | K24: ;
B25: -3.0608683e-14 | C25: -0.044614772 | D25: 6.1880699e-05 | E25: -0.12800902 | F25: 9.4362999e-05 | G25: -0.13633748 | H25: 0 | I25: 0 | J25: 0 | K25: ;
B26: -1.4075277e-15 | C26: -0.028931929 | D26: -5.0915077e-05 | E26: -0.0014051346 | F26: -0.0002980458 | G26: 0.30013002 | H26: 0 | I26: 0 | J26: 0 | K26: ;
B27: -1.296378e-14 | C27: 0.12137596 | D27: -7.3117525e-05 | E27: -0.17556762 | F27: -0.00038304533 | G27: -0.37598748 | H27: 0 | I27: 0 | J27: 0 | K27: ;
B28: -4.5574354e-07 | C28: -0.02819327 | D28: -4.288017e-05 | E28: -0.015838311 | F28: -0.00025842595 | G28: 0.40264857 | H28: 0 | I28: 0 | J28: 1.4 | K28: ;
B29: -1.4551865e-06 | C29: 0.059586564 | D29: -5.8731597e-05 | E29: -0.14074332 | F29: -0.00026243052 | G29: -0.062484229 | H29: 0 | I29: 0 | J29: 1.4 | K29: ;
B30: -1.5336159e-06 | C30: 0.06798682 | D30: -4.6234121e-05 | E30: -0.17804261 | F30: -0.00020161661 | G30: -0.051081523 | H30: 0 | I30: 0 | J30: 1.4 | K30: ;
... B32: -3.5374644e-06 | C32: 0.029450059 | D32: -9.090809e-05 | E32: -0.30601686 | F32: -0.00034868217 | G32: 0.30684314 | H32: 0 | I32: 0 | J32: 1.4 | K32: ]
D36: [ | E36: -0.00070192455 | F36: -0.01889527 | G36: 0.00065155933 | H36: -0.0034051635 | I36: 0.0074966699 | J36: -0.030580966 | K36: 0.8 | L36: 0 | M36: 0 | N36: ;
E37: -0.0011449491 | F37: -0.087871559 | G37: 0.0012581461 | H37: -0.25905412 | I37: 0.016173899 | J37: -0.10142371 | K37: 0 | L37: 0 | M37: 0 | N37: ;
E38: -0.003717537 | F38: 0.17499575 | G38: -0.20276137 | H38: -0.35743338 | I38: -1.0157691 | J38: -0.8504957 | K38: 1.2 | L38: 0 | M38: 0 | N38: ;
E39: -0.011667065 | F39: 0.23207891 | G39: -0.017367871 | H39: -0.68982279 | I39: -0.12469035 | J39: -0.78086811 | K39: 0.8 | L39: 0 | M39: 0 | N39: ]
F48: { | G48: [ | H48: 0.032339975 | I48: -0.05516617 | J48: -0.18954194 | K48: -0.67983842 | L48: -0.92226362 | M48: -0.11201197 | N48: 0.8 | O48: 0 | P48: 0 | Q48: ] | R48: ;
G49: [ | H49: 0.011516096 | I49: -0.049660508 | J49: -0.12653816 | K49: -0.35200155 | L49: -0.6693756 | M49: 0.073106274 | N49: 0.4 | O49: 0 | P49: 0 | Q49: ] | R49: ;
G50: [ | H50: 0.012158022 | I50: -0.055947427 | J50: -0.1395517 | K50: -0.49113488 | L50: -0.66529179 | M50: 0.049178556 | N50: 0.4 | O50: 0 | P50: 0 | Q50: ] | R50: ;
G51: [ | H51: 0.004800796 | I51: 0.04382915 | J51: -0.10502016 | K51: -0.040011849 | L51: -0.49215788 | M51: -0.30727568 | N51: 1.2 | O51: 0 | P51: 0 | Q51: ] | R51: ;
G52: [ | H52: 0.0033965623 | I52: 0.063226528 | J52: -0.19356807 | K52: -0.30557531 | L52: -0.88097358 | M52: -0.48669517 | N52: 0.4 | O52: 0 | P52: 0 | Q52: ] | R52: ;
G53: [ | H53: -0.0059819799 | I53: 0.062610559 | J53: -0.12849849 | K53: -0.095138475 | L53: -0.78571397 | M53: -0.234833 | N53: 0.8 | O53: 0 | P53: 0 | Q53: ] | R53: ;
G54: [ | H54: -0.66562104 | I54: 1.0376637 | J54: -0.42349041 | K54: -0.20376933 | L54: -0.14496209 | M54: -0.021244271 | N54: 1.2 | O54: 0 | P54: 0 | Q54: ] | R54: ;
...

Sheet Conversion
A1: Raw Data | H1: Converted
A2: Fx | B2: Fy | C2: Fz | D2: Tx | E2: Ty | F2: Tz | H2: Tx | I2: Ty | J2: Tz | K2: Fx | L2: Fy | M2: Fz
A3: 0.073106274 | B3: 0.6693756 | C3: -0.35200155 | D3: -0.12653816 | E3: 0.049660508 | F3: 0.011516096 | H3: =$F3 -> 0.011516096 | I3: =-1*$E3 -> -0.049660508 | J3: =$D3 -> -0.12653816 | K3: =$C3 -> -0.35200155 | L3: =-1*$B3 -> -0.6693756 | M3: =$A3 -> 0.073106274
A4: -0.31853122 | B4: 0.59025228 | C4: -0.086961806 | D4: -0.093866155 | E4: -0.030018121 | F4: 0.0067626 | H4: =$F4 -> 0.0067626 | I4: =-1*$E4 -> 0.030018121 | J4: =$D4 -> -0.093866155 | K4: =$C4 -> -0.086961806 | L4: =-1*$B4 -> -0.59025228 | M4: =$A4 -> -0.31853122
A5: -0.30727568 | B5: 0.49215788 | C5: -0.040011849 | D5: -0.10502016 | E5: -0.04382915 | F5: 0.004800796 | H5: =$F5 -> 0.004800796 | I5: =-1*$E5 -> 0.04382915 | J5: =$D5 -> -0.10502016 | K5: =$C5 -> -0.040011849 | L5: =-1*$B5 -> -0.49215788 | M5: =$A5 -> -0.30727568
A6: -0.18820059 | B6: 0.76759619 | C6: -0.097403154 | D6: -0.12236099 | E6: -0.054155547 | F6: -0.005481883 | H6: =$F6 -> -0.005481883 | I6: =-1*$E6 -> 0.054155547 | J6: =$D6 -> -0.12236099 | K6: =$C6 -> -0.097403154 | L6: =-1*$B6 -> -0.76759619 | M6: =$A6 -> -0.18820059
A7: -0.234833 | B7: 0.78571397 | C7: -0.095138475 | D7: -0.12849849 | E7: -0.062610559 | F7: -0.0059819799 | H7: =$F7 -> -0.0059819799 | I7: =-1*$E7 -> 0.062610559 | J7: =$D7 -> -0.12849849 | K7: =$C7 -> -0.095138475 | L7: =-1*$B7 -> -0.78571397 | M7: =$A7 -> -0.234833
A8: -0.48669517 | B8: 0.88097358 | C8: -0.30557531 | D8: -0.19356807 | E8: -0.063226528 | F8: 0.0033965623 | H8: =$F8 -> 0.0033965623 | I8: =-1*$E8 -> 0.063226528 | J8: =$D8 -> -0.19356807 | K8: =$C8 -> -0.30557531 | L8: =-1*$B8 -> -0.88097358 | M8: =$A8 -> -0.48669517
A9: 0.049178556 | B9: 0.66529179 | C9: -0.49113488 | D9: -0.1395517 | E9: 0.055947427 | F9: 0.012158022 | H9: =$F9 -> 0.012158022 | I9: =-1*$E9 -> -0.055947427 | J9: =$D9 -> -0.1395517 | K9: =$C9 -> -0.49113488 | L9: =-1*$B9 -> -0.66529179 | M9: =$A9 -> 0.049178556
A10: -0.11201197 | B10: 0.92226362 | C10: -0.67983842 | D10: -0.18954194 | E10: 0.05516617 | F10: 0.032339975 | H10: =$F10 -> 0.032339975 | I10: =-1*$E10 -> -0.05516617 | J10: =$D10 -> -0.18954194 | K10: =$C10 -> -0.67983842 | L10: =-1*$B10 -> -0.92226362 | M10: =$A10 -> -0.11201197
H11: =$F11 -> 0 | I11: =-1*$E11 -> 0 | J11: =$D11 -> 0 | K11: =$C11 -> 0 | L11: =-1*$B11 -> 0 | M11: =$A11 -> 0
H12: =$F12 -> 0 | I12: =-1*$E12 -> 0 | J12: =$D12 -> 0 | K12: =$C12 -> 0 | L12: =-1*$B12 -> 0 | M12: =$A12 -> 0
H13: =$F13 -> 0 | I13: =-1*$E13 -> 0 | J13: =$D13 -> 0 | K13: =$C13 -> 0 | L13: =-1*$B13 -> 0 | M13: =$A13 -> 0
H14: =$F14 -> 0 | I14: =-1*$E14 -> 0 | J14: =$D14 -> 0 | K14: =$C14 -> 0 | L14: =-1*$B14 -> 0 | M14: =$A14 -> 0
H15: =$F15 -> 0 | I15: =-1*$E15 -> 0 | J15: =$D15 -> 0 | K15: =$C15 -> 0 | L15: =-1*$B15 -> 0 | M15: =$A15 -> 0
H16: =$F16 -> 0 | I16: =-1*$E16 -> 0 | J16: =$D16 -> 0 | K16: =$C16 -> 0 | L16: =-1*$B16 -> 0 | M16: =$A16 -> 0
H17: =$F17 -> 0 | I17: =-1*$E17 -> 0 | J17: =$D17 -> 0 | K17: =$C17 -> 0 | L17: =-1*$B17 -> 0 | M17: =$A17 -> 0
H18: =$F18 -> 0 | I18: =-1*$E18 -> 0 | J18: =$D18 -> 0 | K18: =$C18 -> 0 | L18: =-1*$B18 -> 0 | M18: =$A18 -> 0
