Workbook

Sheet Proximal Validation (single)
A1: Ground Truth | H1: 6-Axis FT Sensor | N1: SoRoSim get_proximal_value | T1: Proximal Errors
A2: F (N) | B2: s (m) | C2: roll (rad) | D2: pitch (deg) | E2: tau1 (N) | F2: tau2 (N) | G2: tau3 (N) | H2: Tx (Nm) | I2: Ty (Nm) | J2: Tz(Nm) | K2: Fx (N) | L2: Fy (N) | M2: Fz (N) | N2: Tx (Nm) | O2: Ty (Nm) | P2: Tz(Nm) | Q2: Fx (N) | R2: Fy (N) | S2: Fz (N) | T2: Tx (Nm) | U2: Ty (Nm) | V2: Tz(Nm) | W2: Fx (N) | X2: Fy (N) | Y2: Fz (N)
A3: 0.3 | B3: 0.08 | C3: 1.571 | D3: 0.785 | E3: 1.4 | F3: 0 | G3: 0 | H3: 0.00083457411 | I3: -0.034524299 | J3: -0.0014681163 | K3: 0.17940304 | L3: -0.0075630695 | M3: 0.20382217 | N3: 0.00064981486 | O3: -0.038734583 | P3: 0.0020651668 | Q3: 0.18685539 | R3: 0.015592854 | S3: 0.23417893 | T3: =ABS(H3-N3) -> 0.00018475925 | U3: =ABS(I3-O3) -> 0.004210284 | V3: =ABS(J3-P3) -> 0.0035332831 | W3: =ABS(K3-Q3) -> 0.0074523497 | X3: =ABS(L3-R3) -> 0.023155923 | Y3: =ABS(M3-S3) -> 0.030356763
A4: 0.4 | B4: 0.14 | C4: 1.571 | D4: 0.785 | E4: 0 | F4: 0 | G4: 0 | H4: -0.00080810196 | I4: -0.066743046 | J4: 0.00044342974 | K4: 0.21195751 | L4: 0.0011818819 | M4: 0.30656093 | N4: -3.7772879e-22 | O4: -0.074513816 | P4: -1.5176468e-05 | Q4: 0.19288278 | R4: -7.1371718e-05 | S4: 0.35042271 | T4: =ABS(H4-N4) -> 0.00080810196 | U4: =ABS(I4-O4) -> 0.0077707702 | V4: =ABS(J4-P4) -> 0.00045860621 | W4: =ABS(K4-Q4) -> 0.019074733 | X4: =ABS(L4-R4) -> 0.0012532536 | Y4: =ABS(M4-S4) -> 0.043861779
A5: 0.6 | B5: 0.16 | C5: 1.571 | D5: 0.785 | E5: 1.4 | F5: 0 | G5: 0 | H5: 0.0078557301 | I5: -0.12781028 | J5: -0.011611282 | K5: 0.02856116 | L5: -0.047612399 | M5: 0.55316103 | N5: 0.0055029485 | O5: -0.13325241 | P5: 0.011318003 | Q5: 0.06260152 | R5: 0.053035799 | S5: 0.59435496 | T5: =ABS(H5-N5) -> 0.0023527816 | U5: =ABS(I5-O5) -> 0.0054421232 | V5: =ABS(J5-P5) -> 0.022929285 | W5: =ABS(K5-Q5) -> 0.03404036 | X5: =ABS(L5-R5) -> 0.1006482 | Y5: =ABS(M5-S5) -> 0.041193939
A6: 0.4 | B6: 0.06 | C6: 1.571 | D6: 1.571 | E6: 1.4 | F6: 0 | G6: 0 | H6: 0.0011252735 | I6: -0.055980932 | J6: -0.00074938103 | K6: -0.035423979 | L6: -0.010494843 | M6: 0.35301661 | N6: 0.00068201096 | O6: -0.059716799 | P6: -7.8735274e-05 | Q6: -0.040876346 | R6: -0.00099146332 | S6: 0.3979014 | T6: =ABS(H6-N6) -> 0.00044326257 | U6: =ABS(I6-O6) -> 0.0037358668 | V6: =ABS(J6-P6) -> 0.00067064575 | W6: =ABS(K6-Q6) -> 0.0054523667 | X6: =ABS(L6-R6) -> 0.0095033798 | Y6: =ABS(M6-S6) -> 0.044884786
A7: 0.8 | B7: 0.08 | C7: 1.571 | D7: 1.571 | E7: 0 | F7: 0 | G7: 0 | H7: -0.00055839424 | I7: -0.11975701 | J7: -0.00099074037 | K7: -0.19020733 | L7: -0.0026012212 | M7: 0.66739637 | N7: -3.6558238e-22 | O7: -0.13340417 | P7: -2.7170856e-05 | Q7: -0.19526642 | R7: -0.00015800945 | S7: 0.77579889 | T7: =ABS(H7-N7) -> 0.00055839424 | U7: =ABS(I7-O7) -> 0.01364716 | V7: =ABS(J7-P7) -> 0.00096356952 | W7: =ABS(K7-Q7) -> 0.005059086 | X7: =ABS(L7-R7) -> 0.0024432118 | Y7: =ABS(M7-S7) -> 0.10840252
A8: 0.7 | B8: 0.16 | C8: 1.571 | D8: 1.571 | E8: 1.4 | F8: 0 | G8: 0 | H8: 0.010437043 | I8: -0.12975721 | J8: -0.0073771281 | K8: -0.55726922 | L8: -0.060898364 | M8: 0.32599643 | N8: 0.0081742887 | O8: -0.13915056 | P8: -0.0010658797 | Q8: -0.56100538 | R8: -0.036150604 | S8: 0.41707689 | T8: =ABS(H8-N8) -> 0.0022627547 | U8: =ABS(I8-O8) -> 0.0093933461 | V8: =ABS(J8-P8) -> 0.0063112484 | W8: =ABS(K8-Q8) -> 0.003736164 | X8: =ABS(L8-R8) -> 0.024747759 | Y8: =ABS(M8-S8) -> 0.091080466
A9: 0.7 | B9: 0.2 | C9: 1.571 | D9: 1.571 | E9: 0 | F9: 0 | G9: 0 | H9: -0.00053893542 | I9: -0.11880944 | J9: 0.0034749229 | K9: -0.62149334 | L9: 0.015605319 | M9: 0.10576335 | N9: 7.3177615e-21 | O9: -0.13611421 | P9: -2.7722817e-05 | Q9: -0.6668314 | R9: -4.3366485e-05 | S9: 0.21292189 | T9: =ABS(H9-N9) -> 0.00053893542 | U9: =ABS(I9-O9) -> 0.017304767 | V9: =ABS(J9-P9) -> 0.0035026457 | W9: =ABS(K9-Q9) -> 0.045338056 | X9: =ABS(L9-R9) -> 0.015648686 | Y9: =ABS(M9-S9) -> 0.10715855
A10: 0.7 | B10: 0.06 | C10: 3.665 | D10: 0.785 | E10: 0 | F10: 0 | G10: 0 | H10: -0.00078150304 | I10: 0.044897478 | J10: -0.082051888 | K10: 0.48326424 | L10: -0.55701375 | M10: -0.30146328 | N10: -1.0114603e-19 | O10: 0.03935443 | P10: -0.068194016 | Q10: 0.45002174 | R10: -0.46438879 | S10: -0.26799647 | T10: =ABS(H10-N10) -> 0.00078150304 | U10: =ABS(I10-O10) -> 0.0055430484 | V10: =ABS(J10-P10) -> 0.013857872 | W10: =ABS(K10-Q10) -> 0.033242496 | X10: =ABS(L10-R10) -> 0.092624965 | Y10: =ABS(M10-S10) -> 0.033466803
A11: 0.6 | B11: 0.1 | C11: 3.665 | D11: 0.785 | E11: 0 | F11: 0 | G11: 0 | H11: -0.00048895599 | I11: 0.046247739 | J11: -0.083231397 | K11: 0.33926415 | L11: -0.45690826 | M11: -0.2506513 | N11: 7.4470674e-19 | O11: 0.045314988 | P11: -0.078522572 | Q11: 0.32464755 | R11: -0.43702875 | S11: -0.25220713 | T11: =ABS(H11-N11) -> 0.00048895599 | U11: =ABS(I11-O11) -> 0.0009327513 | V11: =ABS(J11-P11) -> 0.0047088254 | W11: =ABS(K11-Q11) -> 0.014616602 | X11: =ABS(L11-R11) -> 0.019879508 | Y11: =ABS(M11-S11) -> 0.0015558311
A12: 0.8 | B12: 0.18 | C12: 3.665 | D12: 0.785 | E12: 1.4 | F12: 0 | G12: 0 | H12: 0.0017005717 | I12: 0.08478865 | J12: -0.14360036 | K12: 0.28701612 | L12: -0.64443815 | M12: -0.37070236 | N12: 2.3827044e-06 | O12: 0.095040235 | P12: -0.1646973 | Q12: 0.0136144 | R12: -0.69280155 | S12: -0.39978791 | T12: =ABS(H12-N12) -> 0.001698189 | U12: =ABS(I12-O12) -> 0.010251584 | V12: =ABS(J12-P12) -> 0.021096944 | W12: =ABS(K12-Q12) -> 0.27340172 | X12: =ABS(L12-R12) -> 0.048363403 | Y12: =ABS(M12-S12) -> 0.029085556
A13: 0.4 | B13: 0.2 | C13: 3.665 | D13: 0.785 | E13: 1.4 | F13: 0 | G13: 0 | H13: 0.001073956 | I13: 0.041172292 | J13: -0.06770768 | K13: 0.18796542 | L13: -0.24406707 | M13: -0.14198835 | N13: 1.3548913e-06 | O13: 0.045873252 | P13: -0.079495579 | Q13: 0.17563388 | R13: -0.31127058 | S13: -0.17961698 | T13: =ABS(H13-N13) -> 0.0010726011 | U13: =ABS(I13-O13) -> 0.0047009596 | V13: =ABS(J13-P13) -> 0.011787898 | W13: =ABS(K13-Q13) -> 0.012331545 | X13: =ABS(L13-R13) -> 0.067203509 | Y13: =ABS(M13-S13) -> 0.03762863
A14: 0.4 | B14: 0.1 | C14: 3.665 | D14: 1.571 | E14: 1.4 | F14: 0 | G14: 0 | H14: -0.00048927497 | I14: 0.032692719 | J14: -0.058575917 | K14: -0.01288351 | L14: -0.2920453 | M14: -0.16083619 | N14: 4.4731453e-07 | O14: 0.037910529 | P14: -0.065692039 | Q14: -0.03433953 | R14: -0.34516715 | S14: -0.19919437 | T14: =ABS(H14-N14) -> 0.00048972229 | U14: =ABS(I14-O14) -> 0.0052178101 | V14: =ABS(J14-P14) -> 0.0071161221 | W14: =ABS(K14-Q14) -> 0.02145602 | X14: =ABS(L14-R14) -> 0.053121851 | Y14: =ABS(M14-S14) -> 0.038358183
... A17: 0.3 | B17: 0.18 | C17: 3.665 | D17: 1.571 | E17: 0 | F17: 0 | G17: 0 | H17: 0.00035051629 | I17: 0.032155216 | J17: -0.054656163 | K17: -0.10698747 | L17: -0.16471621 | M17: -0.09704788 | N17: 2.4885535e-19 | O17: 0.038480328 | P17: -0.066679358 | Q17: -0.13700256 | R17: -0.23115898 | S17: -0.13340071 | T17: =ABS(H17-N17) -> 0.00035051629 | U17: =ABS(I17-O17) -> 0.0063251124 | V17: =ABS(J17-P17) -> 0.012023195 | W17: =ABS(K17-Q17) -> 0.030015087 | X17: =ABS(L17-R17) -> 0.066442768 | Y17: =ABS(M17-S17) -> 0.036352826
H18: {=AVERAGE(ABS(H3:H17))} -> 0.0018354399 | I18: {=AVERAGE(ABS(I3:I17))} -> 0.06952431 | J18: {=AVERAGE(ABS(J3:J17))} -> 0.047046432 | K18: {=AVERAGE(ABS(K3:K17))} -> 0.239841 | L18: {=AVERAGE(ABS(L3:L17))} -> 0.22160022 | M18: {=AVERAGE(ABS(M3:M17))} -> 0.28629773

Sheet Distal Validation (single)
A1: Ground Truth | H1: 6-Axis FT Sensor | N1: SoRoSim get_distal_value | S1: Distal Errors | W1: Mean Average Error
A2: F (N) | B2: s (m) | C2: roll (rad) | D2: pitch (deg) | E2: tau1 (N) | F2: tau2 (N) | G2: tau3 (N) | H2: Tx (Nm) | I2: Ty (Nm) | J2: Tz(Nm) | K2: Fx (N) | L2: Fy (N) | M2: Fz (N) | N2: F (N) | O2: s (m) | P2: roll (rad) | Q2: pitch (deg) | R2: f_final | S2: Force Error | T2: Position Error | U2: Roll Error | V2: Pitch Error | W2: Force Error | X2: Position Error | Y2: Roll Error | Z2: Pitch Error
A3: ='Proximal Validation (single)'!A3 -> 0.3 | B3: ='Proximal Validation (single)'!B3 -> 0.08 | C3: ='Proximal Validation (single)'!C3 -> 1.571 | D3: ='Proximal Validation (single)'!D3 -> 0.785 | E3: ='Proximal Validation (single)'!E3 -> 1.4 | F3: ='Proximal Validation (single)'!F3 -> 0 | G3: ='Proximal Validation (single)'!G3 -> 0 | H3: ='Proximal Validation (single)'!H3 -> 0.00083457411 | ... M3: ='Proximal Validation (single)'!M3 -> 0.20382217 | N3: 0.27164045 | O3: 0.084499382 | P3: 1.6893021 | Q3: 0.74434928 | R3: 1.8059252e-07 | S3: =ABS(N3-A3) -> 0.028359546 | T3: =ABS(O3-B3) -> 0.0044993818 | U3: =ABS(P3-C3) -> 0.11830208 | V3: =ABS(Q3-D3) -> 0.040650717 | W3: =AVERAGE(S3:S17) -> 0.052210427 | X3: =AVERAGE(T3:T17) -> 0.0085104304 | Y3: =AVERAGE(U3:U17) -> 0.038349266 | Z3: =AVERAGE(V3:V17) -> 0.073272114
A4: ='Proximal Validation (single)'!A4 -> 0.4 | B4: ='Proximal Validation (single)'!B4 -> 0.14 | C4: ='Proximal Validation (single)'!C4 -> 1.571 | D4: ='Proximal Validation (single)'!D4 -> 0.785 | E4: ='Proximal Validation (single)'!E4 -> 0 | F4: ='Proximal Validation (single)'!F4 -> 0 | G4: ='Proximal Validation (single)'!G4 -> 0 | H4: ='Proximal Validation (single)'!H4 -> -0.00080810196 | ... M4: ='Proximal Validation (single)'!M4 -> 0.30656093 | N4: 0.37270241 | O4: 0.14931754 | P4: 1.5668149 | Q4: 0.69337967 | R4: 6.8609991e-07 | S4: =ABS(N4-A4) -> 0.027297595 | T4: =ABS(O4-B4) -> 0.0093175382 | U4: =ABS(P4-C4) -> 0.0041851412 | V4: =ABS(Q4-D4) -> 0.091620326 | Y4: =DEGREES(Y3) -> 2.1972511 | Z4: =DEGREES(Z3) -> 4.1981829
A5: ='Proximal Validation (single)'!A5 -> 0.6 | B5: ='Proximal Validation (single)'!B5 -> 0.16 | C5: ='Proximal Validation (single)'!C5 -> 1.571 | D5: ='Proximal Validation (single)'!D5 -> 0.785 | E5: ='Proximal Validation (single)'!E5 -> 1.4 | F5: ='Proximal Validation (single)'!F5 -> 0 | G5: ='Proximal Validation (single)'!G5 -> 0 | H5: ='Proximal Validation (single)'!H5 -> 0.0078557301 | ... M5: ='Proximal Validation (single)'!M5 -> 0.55316103 | N5: 0.55589379 | O5: 0.16425033 | P5: 1.7447593 | Q5: 0.85072996 | R5: 3.0592111e-06 | S5: =ABS(N5-A5) -> 0.044106208 | T5: =ABS(O5-B5) -> 0.0042503332 | U5: =ABS(P5-C5) -> 0.17375933 | V5: =ABS(Q5-D5) -> 0.065729965
A6: ='Proximal Validation (single)'!A6 -> 0.4 | B6: ='Proximal Validation (single)'!B6 -> 0.06 | C6: ='Proximal Validation (single)'!C6 -> 1.571 | D6: ='Proximal Validation (single)'!D6 -> 1.571 | E6: ='Proximal Validation (single)'!E6 -> 1.4 | F6: ='Proximal Validation (single)'!F6 -> 0 | G6: ='Proximal Validation (single)'!G6 -> 0 | H6: ='Proximal Validation (single)'!H6 -> 0.0011252735 | ... M6: ='Proximal Validation (single)'!M6 -> 0.35301661 | N6: 0.35494399 | O6: 0.068448725 | P6: 1.5982334 | Q6: 1.5552473 | R6: 7.8555777e-07 | S6: =ABS(N6-A6) -> 0.04505601 | T6: =ABS(O6-B6) -> 0.0084487247 | U6: =ABS(P6-C6) -> 0.027233379 | V6: =ABS(Q6-D6) -> 0.015752654
A7: ='Proximal Validation (single)'!A7 -> 0.8 | B7: ='Proximal Validation (single)'!B7 -> 0.08 | C7: ='Proximal Validation (single)'!C7 -> 1.571 | D7: ='Proximal Validation (single)'!D7 -> 1.571 | E7: ='Proximal Validation (single)'!E7 -> 0 | F7: ='Proximal Validation (single)'!F7 -> 0 | G7: ='Proximal Validation (single)'!G7 -> 0 | H7: ='Proximal Validation (single)'!H7 -> -0.00055839424 | ... M7: ='Proximal Validation (single)'!M7 -> 0.66739637 | N7: 0.69397994 | O7: 0.086808379 | P7: 1.5748304 | Q7: 1.5963839 | R7: 5.777893e-07 | S7: =ABS(N7-A7) -> 0.10602006 | T7: =ABS(O7-B7) -> 0.0068083789 | U7: =ABS(P7-C7) -> 0.0038303574 | V7: =ABS(Q7-D7) -> 0.025383869
A8: ='Proximal Validation (single)'!A8 -> 0.7 | B8: ='Proximal Validation (single)'!B8 -> 0.16 | C8: ='Proximal Validation (single)'!C8 -> 1.571 | D8: ='Proximal Validation (single)'!D8 -> 1.571 | E8: ='Proximal Validation (single)'!E8 -> 1.4 | F8: ='Proximal Validation (single)'!F8 -> 0 | G8: ='Proximal Validation (single)'!G8 -> 0 | H8: ='Proximal Validation (single)'!H8 -> 0.010437043 | ... M8: ='Proximal Validation (single)'!M8 -> 0.32599643 | N8: 0.64844298 | O8: 0.17566911 | P8: 1.6243456 | Q8: 1.5862148 | R8: 2.1500991e-06 | S8: =ABS(N8-A8) -> 0.051557023 | T8: =ABS(O8-B8) -> 0.015669108 | U8: =ABS(P8-C8) -> 0.053345569 | V8: =ABS(Q8-D8) -> 0.015214757
A9: ='Proximal Validation (single)'!A9 -> 0.7 | B9: ='Proximal Validation (single)'!B9 -> 0.2 | C9: ='Proximal Validation (single)'!C9 -> 1.571 | D9: ='Proximal Validation (single)'!D9 -> 1.571 | E9: ='Proximal Validation (single)'!E9 -> 0 | F9: ='Proximal Validation (single)'!F9 -> 0 | G9: ='Proximal Validation (single)'!G9 -> 0 | H9: ='Proximal Validation (single)'!H9 -> -0.00053893542 | ... M9: ='Proximal Validation (single)'!M9 -> 0.10576335 | N9: 0.63635868 | O9: 0.2 | P9: 1.4819608 | Q9: 1.9605262 | R9: 0.00054437032 | S9: =ABS(N9-A9) -> 0.063641321 | T9: =ABS(O9-B9) -> 0 | U9: =ABS(P9-C9) -> 0.089039196 | V9: =ABS(Q9-D9) -> 0.38952623
A10: ='Proximal Validation (single)'!A10 -> 0.7 | B10: ='Proximal Validation (single)'!B10 -> 0.06 | C10: ='Proximal Validation (single)'!C10 -> 3.665 | D10: ='Proximal Validation (single)'!D10 -> 0.785 | E10: ='Proximal Validation (single)'!E10 -> 0 | F10: ='Proximal Validation (single)'!F10 -> 0 | G10: ='Proximal Validation (single)'!G10 -> 0 | H10: ='Proximal Validation (single)'!H10 -> -0.00078150304 | ... M10: ='Proximal Validation (single)'!M10 -> -0.30146328 | N10: 0.79667511 | O10: 0.061275299 | P10: 3.6377632 | Q10: 0.81215353 | R10: 7.92415e-07 | S10: =ABS(N10-A10) -> 0.096675114 | T10: =ABS(O10-B10) -> 0.0012752994 | U10: =ABS(P10-C10) -> 0.027236833 | V10: =ABS(Q10-D10) -> 0.027153534
A11: ='Proximal Validation (single)'!A11 -> 0.6 | B11: ='Proximal Validation (single)'!B11 -> 0.1 | C11: ='Proximal Validation (single)'!C11 -> 3.665 | D11: ='Proximal Validation (single)'!D11 -> 0.785 | E11: ='Proximal Validation (single)'!E11 -> 0 | F11: ='Proximal Validation (single)'!F11 -> 0 | G11: ='Proximal Validation (single)'!G11 -> 0 | H11: ='Proximal Validation (single)'!H11 -> -0.00048895599 | ... M11: ='Proximal Validation (single)'!M11 -> -0.2506513 | N11: 0.62184636 | O11: 0.10513156 | P11: 3.643521 | Q11: 0.75420788 | R11: 4.9674371e-07 | S11: =ABS(N11-A11) -> 0.021846365 | T11: =ABS(O11-B11) -> 0.0051315614 | U11: =ABS(P11-C11) -> 0.021478981 | V11: =ABS(Q11-D11) -> 0.030792119
A12: ='Proximal Validation (single)'!A12 -> 0.8 | B12: ='Proximal Validation (single)'!B12 -> 0.18 | C12: ='Proximal Validation (single)'!C12 -> 3.665 | D12: ='Proximal Validation (single)'!D12 -> 0.785 | E12: ='Proximal Validation (single)'!E12 -> 1.4 | F12: ='Proximal Validation (single)'!F12 -> 0 | G12: ='Proximal Validation (single)'!G12 -> 0 | H12: ='Proximal Validation (single)'!H12 -> 0.0017005717 | ... M12: ='Proximal Validation (single)'!M12 -> -0.37070236 | N12: 0.79694074 | O12: 0.1868547 | P12: 3.6643086 | Q12: 0.58530558 | R12: 6.2637421e-06 | S12: =ABS(N12-A12) -> 0.0030592648 | T12: =ABS(O12-B12) -> 0.0068546967 | U12: =ABS(P12-C12) -> 0.00069141173 | V12: =ABS(Q12-D12) -> 0.19969442
A13: ='Proximal Validation (single)'!A13 -> 0.4 | B13: ='Proximal Validation (single)'!B13 -> 0.2 | C13: ='Proximal Validation (single)'!C13 -> 3.665 | D13: ='Proximal Validation (single)'!D13 -> 0.785 | E13: ='Proximal Validation (single)'!E13 -> 1.4 | F13: ='Proximal Validation (single)'!F13 -> 0 | G13: ='Proximal Validation (single)'!G13 -> 0 | H13: ='Proximal Validation (single)'!H13 -> 0.001073956 | ... M13: ='Proximal Validation (single)'!M13 -> -0.14198835 | N13: 0.34027249 | O13: 0.2 | P13: 3.6689281 | Q13: 0.75660415 | R13: 3.8676445e-05 | S13: =ABS(N13-A13) -> 0.059727508 | T13: =ABS(O13-B13) -> 0 | U13: =ABS(P13-C13) -> 0.0039281498 | V13: =ABS(Q13-D13) -> 0.02839585
A14: ='Proximal Validation (single)'!A14 -> 0.4 | B14: ='Proximal Validation (single)'!B14 -> 0.1 | C14: ='Proximal Validation (single)'!C14 -> 3.665 | D14: ='Proximal Validation (single)'!D14 -> 1.571 | E14: ='Proximal Validation (single)'!E14 -> 1.4 | F14: ='Proximal Validation (single)'!F14 -> 0 | G14: ='Proximal Validation (single)'!G14 -> 0 | H14: ='Proximal Validation (single)'!H14 -> -0.00048927497 | ... M14: ='Proximal Validation (single)'!M14 -> -0.16083619 | N14: 0.3336564 | O14: 0.11119871 | P14: 3.6453055 | Q14: 1.5291752 | R14: 4.2538904e-07 | S14: =ABS(N14-A14) -> 0.066343602 | T14: =ABS(O14-B14) -> 0.011198715 | U14: =ABS(P14-C14) -> 0.019694492 | V14: =ABS(Q14-D14) -> 0.041824824
A15: ='Proximal Validation (single)'!A15 -> 0.7 | B15: ='Proximal Validation (single)'!B15 -> 0.1 | C15: ='Proximal Validation (single)'!C15 -> 3.665 | D15: ='Proximal Validation (single)'!D15 -> 1.571 | E15: ='Proximal Validation (single)'!E15 -> 1.4 | F15: ='Proximal Validation (single)'!F15 -> 0 | G15: ='Proximal Validation (single)'!G15 -> 0 | H15: ='Proximal Validation (single)'!H15 -> -0.00016112858 | ... M15: ='Proximal Validation (single)'!M15 -> -0.31810004 | N15: 0.68574347 | O15: 0.11148287 | P15: 3.6451678 | Q15: 1.554172 | R15: 1.1951938e-06 | S15: =ABS(N15-A15) -> 0.014256529 | T15: =ABS(O15-B15) -> 0.011482872 | U15: =ABS(P15-C15) -> 0.019832167 | V15: =ABS(Q15-D15) -> 0.016827968
A16: ='Proximal Validation (single)'!A16 -> 0.4 | B16: ='Proximal Validation (single)'!B16 -> 0.16 | C16: ='Proximal Validation (single)'!C16 -> 3.665 | D16: ='Proximal Validation (single)'!D16 -> 1.571 | E16: ='Proximal Validation (single)'!E16 -> 0 | F16: ='Proximal Validation (single)'!F16 -> 0 | G16: ='Proximal Validation (single)'!G16 -> 0 | H16: ='Proximal Validation (single)'!H16 -> 0.00032763835 | ... M16: ='Proximal Validation (single)'!M16 -> -0.13795975 | N16: 0.32457484 | O16: 0.18271985 | P16: 3.6612785 | Q16: 1.5859515 | R16: 1.705182e-07 | S16: =ABS(N16-A16) -> 0.075425163 | T16: =ABS(O16-B16) -> 0.022719847 | U16: =ABS(P16-C16) -> 0.0037214859 | V16: =ABS(Q16-D16) -> 0.014951457
A17: ='Proximal Validation (single)'!A17 -> 0.3 | B17: ='Proximal Validation (single)'!B17 -> 0.18 | C17: ='Proximal Validation (single)'!C17 -> 3.665 | D17: ='Proximal Validation (single)'!D17 -> 1.571 | E17: ='Proximal Validation (single)'!E17 -> 0 | F17: ='Proximal Validation (single)'!F17 -> 0 | G17: ='Proximal Validation (single)'!G17 -> 0 | H17: ='Proximal Validation (single)'!H17 -> 0.00035051629 | ... M17: ='Proximal Validation (single)'!M17 -> -0.09704788 | N17: 0.22021491 | O17: 0.2 | P17: 3.6739604 | Q17: 1.666563 | R17: 1.8029033e-05 | S17: =ABS(N17-A17) -> 0.079785094 | T17: =ABS(O17-B17) -> 0.02 | U17: =ABS(P17-C17) -> 0.0089604204 | V17: =ABS(Q17-D17) -> 0.095563017

Sheet Distal Vali (noise 0.5x spec)
A1: Ground Truth | H1: 6-Axis FT Sensor | N1: SoRoSim get_distal_value | S1: Distal Errors | W1: Mean Average Error
A2: F (N) | B2: s (m) | C2: roll (rad) | D2: pitch (deg) | E2: tau1 (N) | F2: tau2 (N) | G2: tau3 (N) | H2: Tx (Nm) | I2: Ty (Nm) | J2: Tz(Nm) | K2: Fx (N) | L2: Fy (N) | M2: Fz (N) | N2: F (N) | O2: s (m) | P2: roll (rad) | Q2: pitch (deg) | R2: f_final | S2: Force Error | T2: Position Error | U2: Roll Error | V2: Pitch Error | W2: Force Error | X2: Position Error | Y2: Roll Error | Z2: Pitch Error
A3: 0.3 | B3: 0.08 | C3: 1.571 | D3: 0.785 | E3: 1.4 | F3: 0 | G3: 0 | H3: ='Proximal Validation (single)'!H3 -> 0.00083457411 | I3: ='Proximal Validation (single)'!I3 -> -0.034524299 | J3: ='Proximal Validation (single)'!J3 -> -0.0014681163 | K3: ='Proximal Validation (single)'!K3 -> 0.17940304 | L3: ='Proximal Validation (single)'!L3 -> -0.0075630695 | M3: ='Proximal Validation (single)'!M3 -> 0.20382217 | N3: 0.28805771 | O3: 0.040666102 | P3: 1.6397823 | Q3: 1.4004752 | R3: 3.3600282e-05 | S3: =ABS(N3-A3) -> 0.011942291 | T3: =ABS(O3-B3) -> 0.039333898 | U3: =ABS(P3-C3) -> 0.068782257 | V3: =ABS(Q3-D3) -> 0.61547523 | W3: =AVERAGE(S3:S152) -> 0.074192434 | X3: =AVERAGE(T3:T152) -> 0.025400424 | Y3: =AVERAGE(U3:U152) -> 0.15641092 | Z3: =AVERAGE(V3:V152) -> 0.27675098
A4: 0.4 | B4: 0.14 | C4: 1.571 | D4: 0.785 | E4: 0 | F4: 0 | G4: 0 | H4: ='Proximal Validation (single)'!H4 -> -0.00080810196 | I4: ='Proximal Validation (single)'!I4 -> -0.066743046 | J4: ='Proximal Validation (single)'!J4 -> 0.00044342974 | K4: ='Proximal Validation (single)'!K4 -> 0.21195751 | L4: ='Proximal Validation (single)'!L4 -> 0.0011818819 | M4: ='Proximal Validation (single)'!M4 -> 0.30656093 | N4: 0.41359235 | O4: 0.13166107 | P4: 1.2728764 | Q4: 0.61932133 | R4: 0.00042446249 | S4: =ABS(N4-A4) -> 0.013592352 | T4: =ABS(O4-B4) -> 0.0083389334 | U4: =ABS(P4-C4) -> 0.29812364 | V4: =ABS(Q4-D4) -> 0.16567867 | Y4: =DEGREES(Y3) -> 8.9616857 | Z4: =DEGREES(Z3) -> 15.856663
A5: 0.6 | B5: 0.16 | C5: 1.571 | D5: 0.785 | E5: 1.4 | F5: 0 | G5: 0 | H5: ='Proximal Validation (single)'!H5 -> 0.0078557301 | I5: ='Proximal Validation (single)'!I5 -> -0.12781028 | J5: ='Proximal Validation (single)'!J5 -> -0.011611282 | K5: ='Proximal Validation (single)'!K5 -> 0.02856116 | L5: ='Proximal Validation (single)'!L5 -> -0.047612399 | M5: ='Proximal Validation (single)'!M5 -> 0.55316103 | N5: 0.55661181 | O5: 0.19075715 | P5: 1.9950279 | Q5: 0.5104209 | R5: 0.00041302129 | S5: =ABS(N5-A5) -> 0.043388193 | T5: =ABS(O5-B5) -> 0.030757148 | U5: =ABS(P5-C5) -> 0.42402795 | V5: =ABS(Q5-D5) -> 0.2745791
A6: 0.4 | B6: 0.06 | C6: 1.571 | D6: 1.571 | E6: 1.4 | F6: 0 | G6: 0 | H6: ='Proximal Validation (single)'!H6 -> 0.0011252735 | I6: ='Proximal Validation (single)'!I6 -> -0.055980932 | J6: ='Proximal Validation (single)'!J6 -> -0.00074938103 | K6: ='Proximal Validation (single)'!K6 -> -0.035423979 | L6: ='Proximal Validation (single)'!L6 -> -0.010494843 | M6: ='Proximal Validation (single)'!M6 -> 0.35301661 | N6: 0.38372205 | O6: 0.059156394 | P6: 1.5180655 | Q6: 1.6423707 | R6: 8.5791101e-05 | S6: =ABS(N6-A6) -> 0.016277952 | T6: =ABS(O6-B6) -> 0.00084360622 | U6: =ABS(P6-C6) -> 0.052934463 | V6: =ABS(Q6-D6) -> 0.071370733
A7: 0.8 | B7: 0.08 | C7: 1.571 | D7: 1.571 | E7: 0 | F7: 0 | G7: 0 | H7: ='Proximal Validation (single)'!H7 -> -0.00055839424 | I7: ='Proximal Validation (single)'!I7 -> -0.11975701 | J7: ='Proximal Validation (single)'!J7 -> -0.00099074037 | K7: ='Proximal Validation (single)'!K7 -> -0.19020733 | L7: ='Proximal Validation (single)'!L7 -> -0.0026012212 | M7: ='Proximal Validation (single)'!M7 -> 0.66739637 | N7: 0.72018108 | O7: 0.075769159 | P7: 1.5019972 | Q7: 1.4642364 | R7: 0.00015740035 | S7: =ABS(N7-A7) -> 0.079818922 | T7: =ABS(O7-B7) -> 0.004230841 | U7: =ABS(P7-C7) -> 0.069002788 | V7: =ABS(Q7-D7) -> 0.10676362
A8: 0.7 | B8: 0.16 | C8: 1.571 | D8: 1.571 | E8: 1.4 | F8: 0 | G8: 0 | H8: ='Proximal Validation (single)'!H8 -> 0.010437043 | I8: ='Proximal Validation (single)'!I8 -> -0.12975721 | J8: ='Proximal Validation (single)'!J8 -> -0.0073771281 | K8: ='Proximal Validation (single)'!K8 -> -0.55726922 | L8: ='Proximal Validation (single)'!L8 -> -0.060898364 | M8: ='Proximal Validation (single)'!M8 -> 0.32599643 | N8: 0.70593716 | O8: 0.17982833 | P8: 1.6884655 | Q8: 1.5645918 | R8: 0.00015592001 | S8: =ABS(N8-A8) -> 0.0059371569 | T8: =ABS(O8-B8) -> 0.019828328 | U8: =ABS(P8-C8) -> 0.11746553 | V8: =ABS(Q8-D8) -> 0.0064081563
A9: 0.7 | B9: 0.2 | C9: 1.571 | D9: 1.571 | E9: 0 | F9: 0 | G9: 0 | H9: ='Proximal Validation (single)'!H9 -> -0.00053893542 | I9: ='Proximal Validation (single)'!I9 -> -0.11880944 | J9: ='Proximal Validation (single)'!J9 -> 0.0034749229 | K9: ='Proximal Validation (single)'!K9 -> -0.62149334 | L9: ='Proximal Validation (single)'!L9 -> 0.015605319 | M9: ='Proximal Validation (single)'!M9 -> 0.10576335 | N9: 0.87453493 | O9: 0.19324762 | P9: 1.5675293 | Q9: 1.7481864 | R9: 0.00060809956 | S9: =ABS(N9-A9) -> 0.17453493 | T9: =ABS(O9-B9) -> 0.006752382 | U9: =ABS(P9-C9) -> 0.0034706862 | V9: =ABS(Q9-D9) -> 0.17718638
A10: 0.7 | B10: 0.06 | C10: 3.665 | D10: 0.785 | E10: 0 | F10: 0 | G10: 0 | H10: ='Proximal Validation (single)'!H10 -> -0.00078150304 | I10: ='Proximal Validation (single)'!I10 -> 0.044897478 | J10: ='Proximal Validation (single)'!J10 -> -0.082051888 | K10: ='Proximal Validation (single)'!K10 -> 0.48326424 | L10: ='Proximal Validation (single)'!L10 -> -0.55701375 | M10: ='Proximal Validation (single)'!M10 -> -0.30146328 | N10: 0.87736651 | O10: 0.035561111 | P10: 3.5684017 | Q10: 0.92087949 | R10: 0.0001656878 | S10: =ABS(N10-A10) -> 0.17736651 | T10: =ABS(O10-B10) -> 0.024438889 | U10: =ABS(P10-C10) -> 0.096598303 | V10: =ABS(Q10-D10) -> 0.13587949
A11: 0.6 | B11: 0.1 | C11: 3.665 | D11: 0.785 | E11: 0 | F11: 0 | G11: 0 | H11: ='Proximal Validation (single)'!H11 -> -0.00048895599 | I11: ='Proximal Validation (single)'!I11 -> 0.046247739 | J11: ='Proximal Validation (single)'!J11 -> -0.083231397 | K11: ='Proximal Validation (single)'!K11 -> 0.33926415 | L11: ='Proximal Validation (single)'!L11 -> -0.45690826 | M11: ='Proximal Validation (single)'!M11 -> -0.2506513 | N11: 0.6132093 | O11: 0.092890104 | P11: 3.525225 | Q11: 0.94630098 | R11: 0.00011004704 | S11: =ABS(N11-A11) -> 0.013209295 | T11: =ABS(O11-B11) -> 0.0071098962 | U11: =ABS(P11-C11) -> 0.139775 | V11: =ABS(Q11-D11) -> 0.16130098
A12: 0.8 | B12: 0.18 | C12: 3.665 | D12: 0.785 | E12: 1.4 | F12: 0 | G12: 0 | H12: ='Proximal Validation (single)'!H12 -> 0.0017005717 | I12: ='Proximal Validation (single)'!I12 -> 0.08478865 | J12: ='Proximal Validation (single)'!J12 -> -0.14360036 | K12: ='Proximal Validation (single)'!K12 -> 0.28701612 | L12: ='Proximal Validation (single)'!L12 -> -0.64443815 | M12: ='Proximal Validation (single)'!M12 -> -0.37070236 | N12: 0.84468688 | O12: 0.18415633 | P12: 3.7149973 | Q12: 0.52258083 | R12: 7.819939e-05 | S12: =ABS(N12-A12) -> 0.044686882 | T12: =ABS(O12-B12) -> 0.0041563251 | U12: =ABS(P12-C12) -> 0.049997262 | V12: =ABS(Q12-D12) -> 0.26241917
A13: 0.4 | B13: 0.2 | C13: 3.665 | D13: 0.785 | E13: 1.4 | F13: 0 | G13: 0 | H13: ='Proximal Validation (single)'!H13 -> 0.001073956 | I13: ='Proximal Validation (single)'!I13 -> 0.041172292 | J13: ='Proximal Validation (single)'!J13 -> -0.06770768 | K13: ='Proximal Validation (single)'!K13 -> 0.18796542 | L13: ='Proximal Validation (single)'!L13 -> -0.24406707 | M13: ='Proximal Validation (single)'!M13 -> -0.14198835 | N13: 0.35460713 | O13: 0.1971574 | P13: 3.6486762 | Q13: 0.74723783 | R13: 3.6426228e-05 | S13: =ABS(N13-A13) -> 0.045392867 | T13: =ABS(O13-B13) -> 0.0028426036 | U13: =ABS(P13-C13) -> 0.016323845 | V13: =ABS(Q13-D13) -> 0.037762169
A14: 0.4 | B14: 0.1 | C14: 3.665 | D14: 1.571 | E14: 1.4 | F14: 0 | G14: 0 | H14: ='Proximal Validation (single)'!H14 -> -0.00048927497 | I14: ='Proximal Validation (single)'!I14 -> 0.032692719 | J14: ='Proximal Validation (single)'!J14 -> -0.058575917 | K14: ='Proximal Validation (single)'!K14 -> -0.01288351 | L14: ='Proximal Validation (single)'!L14 -> -0.2920453 | M14: ='Proximal Validation (single)'!M14 -> -0.16083619 | N14: 0.40106909 | O14: 0.13464288 | P14: 3.0027021 | Q14: 2.4838914 | R14: 0.0010564613 | S14: =ABS(N14-A14) -> 0.0010690865 | T14: =ABS(O14-B14) -> 0.034642884 | U14: =ABS(P14-C14) -> 0.6622979 | V14: =ABS(Q14-D14) -> 0.91289139
A15: 0.7 | B15: 0.1 | C15: 3.665 | D15: 1.571 | E15: 1.4 | F15: 0 | G15: 0 | H15: ='Proximal Validation (single)'!H15 -> -0.00016112858 | I15: ='Proximal Validation (single)'!I15 -> 0.066224433 | J15: ='Proximal Validation (single)'!J15 -> -0.1180518 | K15: ='Proximal Validation (single)'!K15 -> -0.18827668 | L15: ='Proximal Validation (single)'!L15 -> -0.57758576 | M15: ='Proximal Validation (single)'!M15 -> -0.31810004 | N15: 0.66070929 | O15: 0.11484241 | P15: 3.6249085 | Q15: 1.4761237 | R15: 0.00012145035 | S15: =ABS(N15-A15) -> 0.039290709 | T15: =ABS(O15-B15) -> 0.014842407 | U15: =ABS(P15-C15) -> 0.040091496 | V15: =ABS(Q15-D15) -> 0.094876319
A16: 0.4 | B16: 0.16 | C16: 3.665 | D16: 1.571 | E16: 0 | F16: 0 | G16: 0 | H16: ='Proximal Validation (single)'!H16 -> 0.00032763835 | I16: ='Proximal Validation (single)'!I16 -> 0.041303895 | J16: ='Proximal Validation (single)'!J16 -> -0.071706265 | K16: ='Proximal Validation (single)'!K16 -> -0.16764185 | L16: ='Proximal Validation (single)'!L16 -> -0.24127176 | M16: ='Proximal Validation (single)'!M16 -> -0.13795975 | N16: 0.53476983 | O16: 0.098005479 | P16: 3.6654958 | Q16: 2.0161467 | R16: 6.1697275e-06 | S16: =ABS(N16-A16) -> 0.13476983 | T16: =ABS(O16-B16) -> 0.061994521 | U16: =ABS(P16-C16) -> 0.00049578524 | V16: =ABS(Q16-D16) -> 0.44514673
A17: 0.3 | B17: 0.18 | C17: 3.665 | D17: 1.571 | E17: 0 | F17: 0 | G17: 0 | H17: ='Proximal Validation (single)'!H17 -> 0.00035051629 | I17: ='Proximal Validation (single)'!I17 -> 0.032155216 | J17: ='Proximal Validation (single)'!J17 -> -0.054656163 | K17: ='Proximal Validation (single)'!K17 -> -0.10698747 | L17: ='Proximal Validation (single)'!L17 -> -0.16471621 | M17: ='Proximal Validation (single)'!M17 -> -0.09704788 | N17: 0.22358121 | O17: 0.1995728 | P17: 3.8951705 | Q17: 1.9098087 | R17: 0.00027717719 | S17: =ABS(N17-A17) -> 0.07641879 | T17: =ABS(O17-B17) -> 0.0195728 | U17: =ABS(P17-C17) -> 0.23017053 | V17: =ABS(Q17-D17) -> 0.3388087
A18: 0.3 | B18: 0.08 | C18: 1.571 | D18: 0.785 | E18: 1.4 | F18: 0 | G18: 0 | N18: 0.45758985 | O18: 0.031488738 | P18: 1.7756162 | Q18: 0.63025866 | R18: 4.2340556e-05 | S18: =ABS(N18-A18) -> 0.15758985 | T18: =ABS(O18-B18) -> 0.048511262 | U18: =ABS(P18-C18) -> 0.20461623 | V18: =ABS(Q18-D18) -> 0.15474134
A19: 0.4 | B19: 0.14 | C19: 1.571 | D19: 0.785 | E19: 0 | F19: 0 | G19: 0 | N19: 0.34686102 | O19: 0.093176044 | P19: 1.8055944 | Q19: 1.4305022 | R19: 0.00034437644 | S19: =ABS(N19-A19) -> 0.053138983 | T19: =ABS(O19-B19) -> 0.046823956 | U19: =ABS(P19-C19) -> 0.23459438 | V19: =ABS(Q19-D19) -> 0.64550224
A20: 0.6 | B20: 0.16 | C20: 1.571 | D20: 0.785 | E20: 1.4 | F20: 0 | G20: 0 | N20: 0.50296531 | O20: 0.19139395 | P20: 1.7711514 | Q20: 0.70421754 | R20: 0.00013160038 | S20: =ABS(N20-A20) -> 0.097034695 | T20: =ABS(O20-B20) -> 0.03139395 | U20: =ABS(P20-C20) -> 0.20015139 | V20: =ABS(Q20-D20) -> 0.080782457
A21: 0.4 | B21: 0.06 | C21: 1.571 | D21: 1.571 | E21: 1.4 | F21: 0 | G21: 0 | N21: 0.36066406 | O21: 0.073809144 | P21: 1.7010568 | Q21: 1.1531301 | R21: 0.00013520144 | S21: =ABS(N21-A21) -> 0.039335943 | T21: =ABS(O21-B21) -> 0.013809144 | U21: =ABS(P21-C21) -> 0.13005677 | V21: =ABS(Q21-D21) -> 0.41786988
A22: 0.8 | B22: 0.08 | C22: 1.571 | D22: 1.571 | E22: 0 | F22: 0 | G22: 0 | N22: 0.80620973 | O22: 0.060368068 | P22: 1.4958334 | Q22: 1.757437 | R22: 0.00011406114 | S22: =ABS(N22-A22) -> 0.0062097323 | T22: =ABS(O22-B22) -> 0.019631932 | U22: =ABS(P22-C22) -> 0.075166567 | V22: =ABS(Q22-D22) -> 0.18643701
A23: 0.7 | B23: 0.16 | C23: 1.571 | D23: 1.571 | E23: 1.4 | F23: 0 | G23: 0 | N23: 0.46093035 | O23: 0.19999648 | P23: 1.6143801 | Q23: 1.3483747 | R23: 0.00051222291 | S23: =ABS(N23-A23) -> 0.23906965 | T23: =ABS(O23-B23) -> 0.039996476 | U23: =ABS(P23-C23) -> 0.04338006 | V23: =ABS(Q23-D23) -> 0.22262535
A24: 0.7 | B24: 0.2 | C24: 1.571 | D24: 1.571 | E24: 0 | F24: 0 | G24: 0 | N24: 0.65651907 | O24: 0.19999798 | P24: 1.6598015 | Q24: 2.2565183 | R24: 0.0043749251 | S24: =ABS(N24-A24) -> 0.043480928 | T24: =ABS(O24-B24) -> 2.0178064e-06 | U24: =ABS(P24-C24) -> 0.088801503 | V24: =ABS(Q24-D24) -> 0.68551834
A25: 0.7 | B25: 0.06 | C25: 3.665 | D25: 0.785 | E25: 0 | F25: 0 | G25: 0 | N25: 0.66181286 | O25: 0.09259818 | P25: 3.7779421 | Q25: 0.79567669 | R25: 0.00018288723 | S25: =ABS(N25-A25) -> 0.038187141 | T25: =ABS(O25-B25) -> 0.03259818 | U25: =ABS(P25-C25) -> 0.11294207 | V25: =ABS(Q25-D25) -> 0.010676694
A26: 0.6 | B26: 0.1 | C26: 3.665 | D26: 0.785 | E26: 0 | F26: 0 | G26: 0 | N26: 0.65440247 | O26: 0.10758937 | P26: 3.5447642 | Q26: 0.64439739 | R26: 0.00019881184 | S26: =ABS(N26-A26) -> 0.054402474 | T26: =ABS(O26-B26) -> 0.0075893674 | U26: =ABS(P26-C26) -> 0.12023579 | V26: =ABS(Q26-D26) -> 0.14060261
A27: 0.8 | B27: 0.18 | C27: 3.665 | D27: 0.785 | E27: 1.4 | F27: 0 | G27: 0 | N27: 0.84437806 | O27: 0.13699666 | P27: 3.6404424 | Q27: 0.8431076 | R27: 0.0001640435 | S27: =ABS(N27-A27) -> 0.044378063 | T27: =ABS(O27-B27) -> 0.043003341 | U27: =ABS(P27-C27) -> 0.024557648 | V27: =ABS(Q27-D27) -> 0.058107597
A28: 0.4 | B28: 0.2 | C28: 3.665 | D28: 0.785 | E28: 1.4 | F28: 0 | G28: 0 | N28: 0.41809297 | O28: 0.19999597 | P28: 3.4933289 | Q28: 0.46083993 | R28: 0.00050939088 | S28: =ABS(N28-A28) -> 0.018092965 | T28: =ABS(O28-B28) -> 4.0294883e-06 | U28: =ABS(P28-C28) -> 0.1716711 | V28: =ABS(Q28-D28) -> 0.32416007
A29: 0.4 | B29: 0.1 | C29: 3.665 | D29: 1.571 | E29: 1.4 | F29: 0 | G29: 0 | N29: 0.3404418 | O29: 0.11523272 | P29: 3.557401 | Q29: 1.3988885 | R29: 2.9027481e-05 | S29: =ABS(N29-A29) -> 0.0595582 | T29: =ABS(O29-B29) -> 0.01523272 | U29: =ABS(P29-C29) -> 0.10759895 | V29: =ABS(Q29-D29) -> 0.17211147
... A152: 0.3 | B152: 0.18 | C152: 3.665 | D152: 1.571 | E152: 0 | F152: 0 | G152: 0 | N152: 0.21959525 | O152: 0.18821145 | P152: 3.7963234 | Q152: 1.4854784 | R152: 5.3898113e-05 | S152: =ABS(N152-A152) -> 0.080404752 | T152: =ABS(O152-B152) -> 0.0082114479 | U152: =ABS(P152-C152) -> 0.13132337 | V152: =ABS(Q152-D152) -> 0.085521588

Sheet Distal Vali (noise 1.0x spec)
A1: Ground Truth | H1: 6-Axis FT Sensor | N1: SoRoSim get_distal_value | S1: Distal Errors | W1: Mean Average Error
A2: F (N) | B2: s (m) | C2: roll (rad) | D2: pitch (deg) | E2: tau1 (N) | F2: tau2 (N) | G2: tau3 (N) | H2: Tx (Nm) | I2: Ty (Nm) | J2: Tz(Nm) | K2: Fx (N) | L2: Fy (N) | M2: Fz (N) | N2: F (N) | O2: s (m) | P2: roll (rad) | Q2: pitch (deg) | R2: f_final | S2: Force Error | T2: Position Error | U2: Roll Error | V2: Pitch Error | W2: Force Error | X2: Position Error | Y2: Roll Error | Z2: Pitch Error
A3: 0.3 | B3: 0.08 | C3: 1.571 | D3: 0.785 | E3: 1.4 | F3: 0 | G3: 0 | H3: ='Proximal Validation (single)'!H3 -> 0.00083457411 | I3: ='Proximal Validation (single)'!I3 -> -0.034524299 | J3: ='Proximal Validation (single)'!J3 -> -0.0014681163 | K3: ='Proximal Validation (single)'!K3 -> 0.17940304 | L3: ='Proximal Validation (single)'!L3 -> -0.0075630695 | M3: ='Proximal Validation (single)'!M3 -> 0.20382217 | N3: 0.38232083 | O3: 0.023883629 | P3: 1.6418321 | Q3: 1.8321748 | R3: 0.00014181769 | S3: =ABS(N3-A3) -> 0.082320833 | T3: =ABS(O3-B3) -> 0.056116371 | U3: =ABS(P3-C3) -> 0.070832096 | V3: =ABS(Q3-D3) -> 1.0471748 | W3: =AVERAGE(S3:S152) -> 0.13692678 | X3: =AVERAGE(T3:T152) -> 0.044260126 | Y3: =AVERAGE(U3:U152) -> 0.32314991 | Z3: =AVERAGE(V3:V152) -> 0.45474182
A4: 0.4 | B4: 0.14 | C4: 1.571 | D4: 0.785 | E4: 0 | F4: 0 | G4: 0 | H4: ='Proximal Validation (single)'!H4 -> -0.00080810196 | I4: ='Proximal Validation (single)'!I4 -> -0.066743046 | J4: ='Proximal Validation (single)'!J4 -> 0.00044342974 | K4: ='Proximal Validation (single)'!K4 -> 0.21195751 | L4: ='Proximal Validation (single)'!L4 -> 0.0011818819 | M4: ='Proximal Validation (single)'!M4 -> 0.30656093 | N4: 0.47921047 | O4: 0.070609704 | P4: 0.99365874 | Q4: 0.69439584 | R4: 0.0014073209 | S4: =ABS(N4-A4) -> 0.079210469 | T4: =ABS(O4-B4) -> 0.069390296 | U4: =ABS(P4-C4) -> 0.57734126 | V4: =ABS(Q4-D4) -> 0.090604161 | Y4: =DEGREES(Y3) -> 18.515126 | Z4: =DEGREES(Z3) -> 26.054787
A5: 0.6 | B5: 0.16 | C5: 1.571 | D5: 0.785 | E5: 1.4 | F5: 0 | G5: 0 | H5: ='Proximal Validation (single)'!H5 -> 0.0078557301 | I5: ='Proximal Validation (single)'!I5 -> -0.12781028 | J5: ='Proximal Validation (single)'!J5 -> -0.011611282 | K5: ='Proximal Validation (single)'!K5 -> 0.02856116 | L5: ='Proximal Validation (single)'!L5 -> -0.047612399 | M5: ='Proximal Validation (single)'!M5 -> 0.55316103 | N5: 0.64352882 | O5: 0.18736347 | P5: 2.2636144 | Q5: 0.34643889 | R5: 0.0017178141 | S5: =ABS(N5-A5) -> 0.043528818 | T5: =ABS(O5-B5) -> 0.027363474 | U5: =ABS(P5-C5) -> 0.69261437 | V5: =ABS(Q5-D5) -> 0.43856111
A6: 0.4 | B6: 0.06 | C6: 1.571 | D6: 1.571 | E6: 1.4 | F6: 0 | G6: 0 | H6: ='Proximal Validation (single)'!H6 -> 0.0011252735 | I6: ='Proximal Validation (single)'!I6 -> -0.055980932 | J6: ='Proximal Validation (single)'!J6 -> -0.00074938103 | K6: ='Proximal Validation (single)'!K6 -> -0.035423979 | L6: ='Proximal Validation (single)'!L6 -> -0.010494843 | M6: ='Proximal Validation (single)'!M6 -> 0.35301661 | N6: 0.41619744 | O6: 0.048442083 | P6: 1.4493915 | Q6: 1.7235377 | R6: 0.00034700378 | S6: =ABS(N6-A6) -> 0.01619744 | T6: =ABS(O6-B6) -> 0.011557917 | U6: =ABS(P6-C6) -> 0.12160855 | V6: =ABS(Q6-D6) -> 0.15253768 | W6: =AVERAGE(S3:S17) -> 0.12076858 | X6: =AVERAGE(T3:T17) -> 0.032697249 | Y6: =AVERAGE(U3:U17) -> 0.29816622 | Z6: =AVERAGE(V3:V17) -> 0.37915663
A7: 0.8 | B7: 0.08 | C7: 1.571 | D7: 1.571 | E7: 0 | F7: 0 | G7: 0 | H7: ='Proximal Validation (single)'!H7 -> -0.00055839424 | I7: ='Proximal Validation (single)'!I7 -> -0.11975701 | J7: ='Proximal Validation (single)'!J7 -> -0.00099074037 | K7: ='Proximal Validation (single)'!K7 -> -0.19020733 | L7: ='Proximal Validation (single)'!L7 -> -0.0026012212 | M7: ='Proximal Validation (single)'!M7 -> 0.66739637 | N7: 0.77258339 | O7: 0.06323482 | P7: 1.4382618 | Q7: 1.3495354 | R7: 0.00053965056 | S7: =ABS(N7-A7) -> 0.027416615 | T7: =ABS(O7-B7) -> 0.01676518 | U7: =ABS(P7-C7) -> 0.13273822 | V7: =ABS(Q7-D7) -> 0.22146457 | W7: =AVERAGE(S18:S32) -> 0.14085117 | X7: =AVERAGE(T18:T32) -> 0.053926527 | Y7: =AVERAGE(U18:U32) -> 0.37859991 | Z7: =AVERAGE(V18:V32) -> 0.476027
A8: 0.7 | B8: 0.16 | C8: 1.571 | D8: 1.571 | E8: 1.4 | F8: 0 | G8: 0 | H8: ='Proximal Validation (single)'!H8 -> 0.010437043 | I8: ='Proximal Validation (single)'!I8 -> -0.12975721 | J8: ='Proximal Validation (single)'!J8 -> -0.0073771281 | K8: ='Proximal Validation (single)'!K8 -> -0.55726922 | L8: ='Proximal Validation (single)'!L8 -> -0.060898364 | M8: ='Proximal Validation (single)'!M8 -> 0.32599643 | N8: 0.7702302 | O8: 0.18173081 | P8: 1.7590247 | Q8: 1.5347651 | R8: 0.00068554349 | S8: =ABS(N8-A8) -> 0.070230205 | T8: =ABS(O8-B8) -> 0.021730806 | U8: =ABS(P8-C8) -> 0.18802471 | V8: =ABS(Q8-D8) -> 0.036234916
A9: 0.7 | B9: 0.2 | C9: 1.571 | D9: 1.571 | E9: 0 | F9: 0 | G9: 0 | H9: ='Proximal Validation (single)'!H9 -> -0.00053893542 | I9: ='Proximal Validation (single)'!I9 -> -0.11880944 | J9: ='Proximal Validation (single)'!J9 -> 0.0034749229 | K9: ='Proximal Validation (single)'!K9 -> -0.62149334 | L9: ='Proximal Validation (single)'!L9 -> 0.015605319 | M9: ='Proximal Validation (single)'!M9 -> 0.10576335 | N9: 0.99999971 | O9: 0.18942737 | P9: 1.6864349 | Q9: 1.7283823 | R9: 0.018924331 | S9: =ABS(N9-A9) -> 0.29999971 | T9: =ABS(O9-B9) -> 0.010572632 | U9: =ABS(P9-C9) -> 0.11543488 | V9: =ABS(Q9-D9) -> 0.15738231
A10: 0.7 | B10: 0.06 | C10: 3.665 | D10: 0.785 | E10: 0 | F10: 0 | G10: 0 | H10: ='Proximal Validation (single)'!H10 -> -0.00078150304 | I10: ='Proximal Validation (single)'!I10 -> 0.044897478 | J10: ='Proximal Validation (single)'!J10 -> -0.082051888 | K10: ='Proximal Validation (single)'!K10 -> 0.48326424 | L10: ='Proximal Validation (single)'!L10 -> -0.55701375 | M10: ='Proximal Validation (single)'!M10 -> -0.30146328 | N10: 0.96161018 | O10: 0.016786271 | P10: 3.5135299 | Q10: 0.99422411 | R10: 0.00058624101 | S10: =ABS(N10-A10) -> 0.26161018 | T10: =ABS(O10-B10) -> 0.043213729 | U10: =ABS(P10-C10) -> 0.15147007 | V10: =ABS(Q10-D10) -> 0.20922411
A11: 0.6 | B11: 0.1 | C11: 3.665 | D11: 0.785 | E11: 0 | F11: 0 | G11: 0 | H11: ='Proximal Validation (single)'!H11 -> -0.00048895599 | I11: ='Proximal Validation (single)'!I11 -> 0.046247739 | J11: ='Proximal Validation (single)'!J11 -> -0.083231397 | K11: ='Proximal Validation (single)'!K11 -> 0.33926415 | L11: ='Proximal Validation (single)'!L11 -> -0.45690826 | M11: ='Proximal Validation (single)'!M11 -> -0.2506513 | N11: 0.62850336 | O11: 0.081463813 | P11: 3.4238547 | Q11: 1.1432088 | R11: 0.00038593081 | S11: =ABS(N11-A11) -> 0.028503365 | T11: =ABS(O11-B11) -> 0.018536187 | U11: =ABS(P11-C11) -> 0.24114532 | V11: =ABS(Q11-D11) -> 0.35820882
A12: 0.8 | B12: 0.18 | C12: 3.665 | D12: 0.785 | E12: 1.4 | F12: 0 | G12: 0 | H12: ='Proximal Validation (single)'!H12 -> 0.0017005717 | I12: ='Proximal Validation (single)'!I12 -> 0.08478865 | J12: ='Proximal Validation (single)'!J12 -> -0.14360036 | K12: ='Proximal Validation (single)'!K12 -> 0.28701612 | L12: ='Proximal Validation (single)'!L12 -> -0.64443815 | M12: ='Proximal Validation (single)'!M12 -> -0.37070236 | N12: 0.90524212 | O12: 0.17999602 | P12: 3.7630734 | Q12: 0.47022503 | R12: 0.00031644634 | S12: =ABS(N12-A12) -> 0.10524212 | T12: =ABS(O12-B12) -> 3.9804993e-06 | U12: =ABS(P12-C12) -> 0.098073392 | V12: =ABS(Q12-D12) -> 0.31477497
A13: 0.4 | B13: 0.2 | C13: 3.665 | D13: 0.785 | E13: 1.4 | F13: 0 | G13: 0 | H13: ='Proximal Validation (single)'!H13 -> 0.001073956 | I13: ='Proximal Validation (single)'!I13 -> 0.041172292 | J13: ='Proximal Validation (single)'!J13 -> -0.06770768 | K13: ='Proximal Validation (single)'!K13 -> 0.18796542 | L13: ='Proximal Validation (single)'!L13 -> -0.24406707 | M13: ='Proximal Validation (single)'!M13 -> -0.14198835 | N13: 0.36938014 | O13: 0.19666942 | P13: 3.6304098 | Q13: 0.74025518 | R13: 4.1862242e-05 | S13: =ABS(N13-A13) -> 0.030619864 | T13: =ABS(O13-B13) -> 0.0033305827 | U13: =ABS(P13-C13) -> 0.034590152 | V13: =ABS(Q13-D13) -> 0.044744816
A14: 0.4 | B14: 0.1 | C14: 3.665 | D14: 1.571 | E14: 1.4 | F14: 0 | G14: 0 | H14: ='Proximal Validation (single)'!H14 -> -0.00048927497 | I14: ='Proximal Validation (single)'!I14 -> 0.032692719 | J14: ='Proximal Validation (single)'!J14 -> -0.058575917 | K14: ='Proximal Validation (single)'!K14 -> -0.01288351 | L14: ='Proximal Validation (single)'!L14 -> -0.2920453 | M14: ='Proximal Validation (single)'!M14 -> -0.16083619 | N14: 0.70379022 | O14: 0.010090874 | P14: 2.1924262 | Q14: 2.8161468 | R14: 0.003368213 | S14: =ABS(N14-A14) -> 0.30379022 | T14: =ABS(O14-B14) -> 0.089909126 | U14: =ABS(P14-C14) -> 1.4725738 | V14: =ABS(Q14-D14) -> 1.2451468
A15: 0.7 | B15: 0.1 | C15: 3.665 | D15: 1.571 | E15: 1.4 | F15: 0 | G15: 0 | H15: ='Proximal Validation (single)'!H15 -> -0.00016112858 | I15: ='Proximal Validation (single)'!I15 -> 0.066224433 | J15: ='Proximal Validation (single)'!J15 -> -0.1180518 | K15: ='Proximal Validation (single)'!K15 -> -0.18827668 | L15: ='Proximal Validation (single)'!L15 -> -0.57758576 | M15: ='Proximal Validation (single)'!M15 -> -0.31810004 | N15: 0.63981223 | O15: 0.11784324 | P15: 3.604332 | Q15: 1.3961629 | R15: 0.00044010209 | S15: =ABS(N15-A15) -> 0.060187773 | T15: =ABS(O15-B15) -> 0.017843237 | U15: =ABS(P15-C15) -> 0.060668022 | V15: =ABS(Q15-D15) -> 0.17483707
A16: 0.4 | B16: 0.16 | C16: 3.665 | D16: 1.571 | E16: 0 | F16: 0 | G16: 0 | H16: ='Proximal Validation (single)'!H16 -> 0.00032763835 | I16: ='Proximal Validation (single)'!I16 -> 0.041303895 | J16: ='Proximal Validation (single)'!J16 -> -0.071706265 | K16: ='Proximal Validation (single)'!K16 -> -0.16764185 | L16: ='Proximal Validation (single)'!L16 -> -0.24127176 | M16: ='Proximal Validation (single)'!M16 -> -0.13795975 | N16: 0.74849542 | O16: 0.056497637 | P16: 3.6678799 | Q16: 2.1967331 | R16: 1.9837695e-05 | S16: =ABS(N16-A16) -> 0.34849542 | T16: =ABS(O16-B16) -> 0.10350236 | U16: =ABS(P16-C16) -> 0.0028798823 | V16: =ABS(Q16-D16) -> 0.62573309
A17: 0.3 | B17: 0.18 | C17: 3.665 | D17: 1.571 | E17: 0 | F17: 0 | G17: 0 | H17: ='Proximal Validation (single)'!H17 -> 0.00035051629 | I17: ='Proximal Validation (single)'!I17 -> 0.032155216 | J17: ='Proximal Validation (single)'!J17 -> -0.054656163 | K17: ='Proximal Validation (single)'!K17 -> -0.10698747 | L17: ='Proximal Validation (single)'!L17 -> -0.16471621 | M17: ='Proximal Validation (single)'!M17 -> -0.09704788 | N17: 0.24582439 | O17: 0.18062285 | P17: 4.1774985 | Q17: 2.1417203 | R17: 0.0010632716 | S17: =ABS(N17-A17) -> 0.05417561 | T17: =ABS(O17-B17) -> 0.000622851 | U17: =ABS(P17-C17) -> 0.51249852 | V17: =ABS(Q17-D17) -> 0.57072032
A18: 0.3 | B18: 0.08 | C18: 1.571 | D18: 0.785 | E18: 1.4 | F18: 0 | G18: 0 | N18: 0.65208469 | O18: 0.010180289 | P18: 1.8190571 | Q18: 0.57274082 | R18: 0.000158078 | S18: =ABS(N18-A18) -> 0.35208469 | T18: =ABS(O18-B18) -> 0.069819711 | U18: =ABS(P18-C18) -> 0.24805707 | V18: =ABS(Q18-D18) -> 0.21225918
A19: 0.4 | B19: 0.14 | C19: 1.571 | D19: 0.785 | E19: 0 | F19: 0 | G19: 0 | N19: 0.45746932 | O19: 0.051504507 | P19: 1.9915844 | Q19: 2.0078406 | R19: 0.001023049 | S19: =ABS(N19-A19) -> 0.057469321 | T19: =ABS(O19-B19) -> 0.088495493 | U19: =ABS(P19-C19) -> 0.42058436 | V19: =ABS(Q19-D19) -> 1.2228406
A20: 0.6 | B20: 0.16 | C20: 1.571 | D20: 0.785 | E20: 1.4 | F20: 0 | G20: 0 | N20: 0.4551518 | O20: 0.19999377 | P20: 1.7698293 | Q20: 0.67920833 | R20: 0.0007890928 | S20: =ABS(N20-A20) -> 0.1448482 | T20: =ABS(O20-B20) -> 0.039993774 | U20: =ABS(P20-C20) -> 0.19882931 | V20: =ABS(Q20-D20) -> 0.10579167
A21: 0.4 | B21: 0.06 | C21: 1.571 | D21: 1.571 | E21: 1.4 | F21: 0 | G21: 0 | N21: 0.41931056 | O21: 0.071297682 | P21: 1.8087101 | Q21: 0.83806937 | R21: 0.00051214714 | S21: =ABS(N21-A21) -> 0.019310561 | T21: =ABS(O21-B21) -> 0.011297682 | U21: =ABS(P21-C21) -> 0.23771005 | V21: =ABS(Q21-D21) -> 0.73293063
A22: 0.8 | B22: 0.08 | C22: 1.571 | D22: 1.571 | E22: 0 | F22: 0 | G22: 0 | N22: 0.92324619 | O22: 0.03899198 | P22: 1.4340249 | Q22: 1.8659264 | R22: 0.00034916757 | S22: =ABS(N22-A22) -> 0.12324619 | T22: =ABS(O22-B22) -> 0.04100802 | U22: =ABS(P22-C22) -> 0.13697514 | V22: =ABS(Q22-D22) -> 0.29492635
A23: 0.7 | B23: 0.16 | C23: 1.571 | D23: 1.571 | E23: 1.4 | F23: 0 | G23: 0 | N23: 0.36126025 | O23: 0.19999981 | P23: 1.6156509 | Q23: 1.0125375 | R23: 0.0025731046 | S23: =ABS(N23-A23) -> 0.33873975 | T23: =ABS(O23-B23) -> 0.039999814 | U23: =ABS(P23-C23) -> 0.04465089 | V23: =ABS(Q23-D23) -> 0.55846248
A24: 0.7 | B24: 0.2 | C24: 1.571 | D24: 1.571 | E24: 0 | F24: 0 | G24: 0 | N24: 0.66714116 | O24: 0.010000001 | P24: 3.8893787 | Q24: 2.9716917 | R24: 0.016451845 | S24: =ABS(N24-A24) -> 0.032858836 | T24: =ABS(O24-B24) -> 0.19 | U24: =ABS(P24-C24) -> 2.3183787 | V24: =ABS(Q24-D24) -> 1.4006917
A25: 0.7 | B25: 0.06 | C25: 3.665 | D25: 0.785 | E25: 0 | F25: 0 | G25: 0 | N25: 0.54682358 | O25: 0.12009237 | P25: 3.9553401 | Q25: 0.83330406 | R25: 0.0010385239 | S25: =ABS(N25-A25) -> 0.15317642 | T25: =ABS(O25-B25) -> 0.06009237 | U25: =ABS(P25-C25) -> 0.29034014 | V25: =ABS(Q25-D25) -> 0.048304064
A26: 0.6 | B26: 0.1 | C26: 3.665 | D26: 0.785 | E26: 0 | F26: 0 | G26: 0 | N26: 0.69870144 | O26: 0.11518434 | P26: 3.4399721 | Q26: 0.53111505 | R26: 0.00079052321 | S26: =ABS(N26-A26) -> 0.09870144 | T26: =ABS(O26-B26) -> 0.015184338 | U26: =ABS(P26-C26) -> 0.22502792 | V26: =ABS(Q26-D26) -> 0.25388495
A27: 0.8 | B27: 0.18 | C27: 3.665 | D27: 0.785 | E27: 1.4 | F27: 0 | G27: 0 | N27: 0.8984722 | O27: 0.11076394 | P27: 3.6182717 | Q27: 1.0242695 | R27: 0.0006669541 | S27: =ABS(N27-A27) -> 0.098472201 | T27: =ABS(O27-B27) -> 0.069236063 | U27: =ABS(P27-C27) -> 0.046728318 | V27: =ABS(Q27-D27) -> 0.2392695
A28: 0.4 | B28: 0.2 | C28: 3.665 | D28: 0.785 | E28: 1.4 | F28: 0 | G28: 0 | N28: 0.54549785 | O28: 0.1999838 | P28: 3.321388 | Q28: 0.29502661 | R28: 0.0013599939 | S28: =ABS(N28-A28) -> 0.14549785 | T28: =ABS(O28-B28) -> 1.6200188e-05 | U28: =ABS(P28-C28) -> 0.34361203 | V28: =ABS(Q28-D28) -> 0.48997339
A29: 0.4 | B29: 0.1 | C29: 3.665 | D29: 1.571 | E29: 1.4 | F29: 0 | G29: 0 | N29: 0.35447836 | O29: 0.11741682 | P29: 3.4760606 | Q29: 1.2776032 | R29: 0.00010475499 | S29: =ABS(N29-A29) -> 0.045521641 | T29: =ABS(O29-B29) -> 0.017416819 | U29: =ABS(P29-C29) -> 0.18893935 | V29: =ABS(Q29-D29) -> 0.29339681
... A152: 0.3 | B152: 0.18 | C152: 3.665 | D152: 1.571 | E152: 0 | F152: 0 | G152: 0 | N152: 0.23170369 | O152: 0.17439269 | P152: 3.9001907 | Q152: 1.3236371 | R152: 0.00015493041 | S152: =ABS(N152-A152) -> 0.068296306 | T152: =ABS(O152-B152) -> 0.0056073121 | U152: =ABS(P152-C152) -> 0.23519066 | V152: =ABS(Q152-D152) -> 0.24736288
R153: =AVERAGE(R3:R152) -> 0.0019635254

Sheet Distal Vali (noise 0.5x spec 2)
A1: σ = [0, 0.003125, 0, 0.150, 0, 0]
A2: Ground Truth | H2: 6-Axis FT Sensor | N2: SoRoSim get_distal_value | S2: Distal Errors | W2: Mean Average Error
A3: F (N) | B3: s (m) | C3: roll (rad) | D3: pitch (deg) | E3: tau1 (N) | F3: tau2 (N) | G3: tau3 (N) | H3: Tx (Nm) | I3: Ty (Nm) | J3: Tz(Nm) | K3: Fx (N) | L3: Fy (N) | M3: Fz (N) | N3: F (N) | O3: s (m) | P3: roll (rad) | Q3: pitch (deg) | R3: f_final | S3: Force Error | T3: Position Error | U3: Roll Error | V3: Pitch Error | W3: Force Error | X3: Position Error | Y3: Roll Error | Z3: Pitch Error
A4: 0.3 | B4: 0.08 | C4: 1.571 | D4: 0.785 | E4: 1.4 | F4: 0 | G4: 0 | H4: ='Proximal Validation (single)'!H3 -> 0.00083457411 | I4: ='Proximal Validation (single)'!I3 -> -0.034524299 | J4: ='Proximal Validation (single)'!J3 -> -0.0014681163 | K4: ='Proximal Validation (single)'!K3 -> 0.17940304 | L4: ='Proximal Validation (single)'!L3 -> -0.0075630695 | M4: ='Proximal Validation (single)'!M3 -> 0.20382217 | N4: 0.20726438 | O4: 0.095151743 | P4: 1.6296573 | Q4: 1.2581023 | R4: 8.4182328e-06 | S4: =ABS(N4-A4) -> 0.092735622 | T4: =ABS(O4-B4) -> 0.015151743 | U4: =ABS(P4-C4) -> 0.05865734 | V4: =ABS(Q4-D4) -> 0.4731023 | W4: =AVERAGE(S4:S78) -> 0.066726958 | X4: =AVERAGE(T4:T78) -> 0.010168322 | Y4: =AVERAGE(U4:U78) -> 0.038242732 | Z4: =AVERAGE(V4:V78) -> 0.25614209
A5: 0.4 | B5: 0.14 | C5: 1.571 | D5: 0.785 | E5: 0 | F5: 0 | G5: 0 | H5: ='Proximal Validation (single)'!H4 -> -0.00080810196 | I5: ='Proximal Validation (single)'!I4 -> -0.066743046 | J5: ='Proximal Validation (single)'!J4 -> 0.00044342974 | K5: ='Proximal Validation (single)'!K4 -> 0.21195751 | L5: ='Proximal Validation (single)'!L4 -> 0.0011818819 | M5: ='Proximal Validation (single)'!M4 -> 0.30656093 | N5: 0.4142697 | O5: 0.13613909 | P5: 1.5676871 | Q5: 0.61173879 | R5: 1.01875e-05 | S5: =ABS(N5-A5) -> 0.014269697 | T5: =ABS(O5-B5) -> 0.0038609051 | U5: =ABS(P5-C5) -> 0.0033128735 | V5: =ABS(Q5-D5) -> 0.17326121
A6: 0.6 | B6: 0.16 | C6: 1.571 | D6: 0.785 | E6: 1.4 | F6: 0 | G6: 0 | H6: ='Proximal Validation (single)'!H5 -> 0.0078557301 | I6: ='Proximal Validation (single)'!I5 -> -0.12781028 | J6: ='Proximal Validation (single)'!J5 -> -0.011611282 | K6: ='Proximal Validation (single)'!K5 -> 0.02856116 | L6: ='Proximal Validation (single)'!L5 -> -0.047612399 | M6: ='Proximal Validation (single)'!M5 -> 0.55316103 | N6: 0.60573852 | O6: 0.16277539 | P6: 1.8088201 | Q6: 0.59918927 | R6: 4.3004341e-05 | S6: =ABS(N6-A6) -> 0.005738518 | T6: =ABS(O6-B6) -> 0.0027753866 | U6: =ABS(P6-C6) -> 0.23782009 | V6: =ABS(Q6-D6) -> 0.18581073
A7: 0.4 | B7: 0.06 | C7: 1.571 | D7: 1.571 | E7: 1.4 | F7: 0 | G7: 0 | H7: ='Proximal Validation (single)'!H6 -> 0.0011252735 | I7: ='Proximal Validation (single)'!I6 -> -0.055980932 | J7: ='Proximal Validation (single)'!J6 -> -0.00074938103 | K7: ='Proximal Validation (single)'!K6 -> -0.035423979 | L7: ='Proximal Validation (single)'!L6 -> -0.010494843 | M7: ='Proximal Validation (single)'!M6 -> 0.35301661 | N7: 0.35917631 | O7: 0.070239887 | P7: 1.5948322 | Q7: 1.6324841 | R7: 1.4501007e-05 | S7: =ABS(N7-A7) -> 0.040823694 | T7: =ABS(O7-B7) -> 0.010239887 | U7: =ABS(P7-C7) -> 0.023832154 | V7: =ABS(Q7-D7) -> 0.061484147
A8: 0.8 | B8: 0.08 | C8: 1.571 | D8: 1.571 | E8: 0 | F8: 0 | G8: 0 | H8: ='Proximal Validation (single)'!H7 -> -0.00055839424 | I8: ='Proximal Validation (single)'!I7 -> -0.11975701 | J8: ='Proximal Validation (single)'!J7 -> -0.00099074037 | K8: ='Proximal Validation (single)'!K7 -> -0.19020733 | L8: ='Proximal Validation (single)'!L7 -> -0.0026012212 | M8: ='Proximal Validation (single)'!M7 -> 0.66739637 | N8: 0.67067245 | O8: 0.089096403 | P8: 1.5755312 | Q8: 1.4135752 | R8: 1.0351311e-05 | S8: =ABS(N8-A8) -> 0.12932755 | T8: =ABS(O8-B8) -> 0.0090964027 | U8: =ABS(P8-C8) -> 0.0045312149 | V8: =ABS(Q8-D8) -> 0.15742479
A9: 0.7 | B9: 0.16 | C9: 1.571 | D9: 1.571 | E9: 1.4 | F9: 0 | G9: 0 | H9: ='Proximal Validation (single)'!H8 -> 0.010437043 | I9: ='Proximal Validation (single)'!I8 -> -0.12975721 | J9: ='Proximal Validation (single)'!J8 -> -0.0073771281 | K9: ='Proximal Validation (single)'!K8 -> -0.55726922 | L9: ='Proximal Validation (single)'!L8 -> -0.060898364 | M9: ='Proximal Validation (single)'!M8 -> 0.32599643 | N9: 0.71877108 | O9: 0.17035782 | P9: 1.6045486 | Q9: 1.6143948 | R9: 1.5524009e-06 | S9: =ABS(N9-A9) -> 0.018771081 | T9: =ABS(O9-B9) -> 0.010357825 | U9: =ABS(P9-C9) -> 0.033548604 | V9: =ABS(Q9-D9) -> 0.043394829
A10: 0.7 | B10: 0.2 | C10: 1.571 | D10: 1.571 | E10: 0 | F10: 0 | G10: 0 | H10: ='Proximal Validation (single)'!H9 -> -0.00053893542 | I10: ='Proximal Validation (single)'!I9 -> -0.11880944 | J10: ='Proximal Validation (single)'!J9 -> 0.0034749229 | K10: ='Proximal Validation (single)'!K9 -> -0.62149334 | L10: ='Proximal Validation (single)'!L9 -> 0.015605319 | M10: ='Proximal Validation (single)'!M9 -> 0.10576335 | N10: 0.88087513 | O10: 0.1761382 | P10: 1.4921492 | Q10: 1.8876785 | R10: 9.4356714e-05 | S10: =ABS(N10-A10) -> 0.18087513 | T10: =ABS(O10-B10) -> 0.023861799 | U10: =ABS(P10-C10) -> 0.078850807 | V10: =ABS(Q10-D10) -> 0.31667845
A11: 0.7 | B11: 0.06 | C11: 3.665 | D11: 0.785 | E11: 0 | F11: 0 | G11: 0 | H11: ='Proximal Validation (single)'!H10 -> -0.00078150304 | I11: ='Proximal Validation (single)'!I10 -> 0.044897478 | J11: ='Proximal Validation (single)'!J10 -> -0.082051888 | K11: ='Proximal Validation (single)'!K10 -> 0.48326424 | L11: ='Proximal Validation (single)'!L10 -> -0.55701375 | M11: ='Proximal Validation (single)'!M10 -> -0.30146328 | N11: 0.80722438 | O11: 0.055443582 | P11: 3.6387801 | Q11: 0.81310512 | R11: 2.4908726e-05 | S11: =ABS(N11-A11) -> 0.10722438 | T11: =ABS(O11-B11) -> 0.0045564179 | U11: =ABS(P11-C11) -> 0.026219908 | V11: =ABS(Q11-D11) -> 0.028105121
A12: 0.6 | B12: 0.1 | C12: 3.665 | D12: 0.785 | E12: 0 | F12: 0 | G12: 0 | H12: ='Proximal Validation (single)'!H11 -> -0.00048895599 | I12: ='Proximal Validation (single)'!I11 -> 0.046247739 | J12: ='Proximal Validation (single)'!J11 -> -0.083231397 | K12: ='Proximal Validation (single)'!K11 -> 0.33926415 | L12: ='Proximal Validation (single)'!L11 -> -0.45690826 | M12: ='Proximal Validation (single)'!M11 -> -0.2506513 | N12: 0.57598167 | O12: 0.10940153 | P12: 3.6421584 | Q12: 0.86576281 | R12: 1.3153007e-05 | S12: =ABS(N12-A12) -> 0.024018329 | T12: =ABS(O12-B12) -> 0.0094015256 | U12: =ABS(P12-C12) -> 0.022841636 | V12: =ABS(Q12-D12) -> 0.08076281
A13: 0.8 | B13: 0.18 | C13: 3.665 | D13: 0.785 | E13: 1.4 | F13: 0 | G13: 0 | H13: ='Proximal Validation (single)'!H12 -> 0.0017005717 | I13: ='Proximal Validation (single)'!I12 -> 0.08478865 | J13: ='Proximal Validation (single)'!J12 -> -0.14360036 | K13: ='Proximal Validation (single)'!K12 -> 0.28701612 | L13: ='Proximal Validation (single)'!L12 -> -0.64443815 | M13: ='Proximal Validation (single)'!M12 -> -0.37070236 | N13: 0.84284431 | O13: 0.1849689 | P13: 3.6648834 | Q13: 0.51998782 | R13: 5.8334292e-05 | S13: =ABS(N13-A13) -> 0.042844308 | T13: =ABS(O13-B13) -> 0.0049688981 | U13: =ABS(P13-C13) -> 0.00011659125 | V13: =ABS(Q13-D13) -> 0.26501218
A14: 0.4 | B14: 0.2 | C14: 3.665 | D14: 0.785 | E14: 1.4 | F14: 0 | G14: 0 | H14: ='Proximal Validation (single)'!H13 -> 0.001073956 | I14: ='Proximal Validation (single)'!I13 -> 0.041172292 | J14: ='Proximal Validation (single)'!J13 -> -0.06770768 | K14: ='Proximal Validation (single)'!K13 -> 0.18796542 | L14: ='Proximal Validation (single)'!L13 -> -0.24406707 | M14: ='Proximal Validation (single)'!M13 -> -0.14198835 | N14: 0.34365241 | O14: 0.19998753 | P14: 3.6686242 | Q14: 0.74514633 | R14: 6.3371155e-05 | S14: =ABS(N14-A14) -> 0.056347591 | T14: =ABS(O14-B14) -> 1.2465552e-05 | U14: =ABS(P14-C14) -> 0.0036242106 | V14: =ABS(Q14-D14) -> 0.039853668
A15: 0.4 | B15: 0.1 | C15: 3.665 | D15: 1.571 | E15: 1.4 | F15: 0 | G15: 0 | H15: ='Proximal Validation (single)'!H14 -> -0.00048927497 | I15: ='Proximal Validation (single)'!I14 -> 0.032692719 | J15: ='Proximal Validation (single)'!J14 -> -0.058575917 | K15: ='Proximal Validation (single)'!K14 -> -0.01288351 | L15: ='Proximal Validation (single)'!L14 -> -0.2920453 | M15: ='Proximal Validation (single)'!M14 -> -0.16083619 | N15: 0.47592643 | O15: 0.095229834 | P15: 3.64127 | Q15: 2.3144831 | R15: 6.6594644e-06 | S15: =ABS(N15-A15) -> 0.075926432 | T15: =ABS(O15-B15) -> 0.0047701657 | U15: =ABS(P15-C15) -> 0.023729994 | V15: =ABS(Q15-D15) -> 0.74348314
A16: 0.7 | B16: 0.1 | C16: 3.665 | D16: 1.571 | E16: 1.4 | F16: 0 | G16: 0 | H16: ='Proximal Validation (single)'!H15 -> -0.00016112858 | I16: ='Proximal Validation (single)'!I15 -> 0.066224433 | J16: ='Proximal Validation (single)'!J15 -> -0.1180518 | K16: ='Proximal Validation (single)'!K15 -> -0.18827668 | L16: ='Proximal Validation (single)'!L15 -> -0.57758576 | M16: ='Proximal Validation (single)'!M15 -> -0.31810004 | N16: 0.67299655 | O16: 0.11134583 | P16: 3.6472339 | Q16: 1.4865897 | R16: 5.3177643e-05 | S16: =ABS(N16-A16) -> 0.027003452 | T16: =ABS(O16-B16) -> 0.011345828 | U16: =ABS(P16-C16) -> 0.017766107 | V16: =ABS(Q16-D16) -> 0.084410345
... A18: 0.3 | B18: 0.18 | C18: 3.665 | D18: 1.571 | E18: 0 | F18: 0 | G18: 0 | H18: ='Proximal Validation (single)'!H17 -> 0.00035051629 | I18: ='Proximal Validation (single)'!I17 -> 0.032155216 | J18: ='Proximal Validation (single)'!J17 -> -0.054656163 | K18: ='Proximal Validation (single)'!K17 -> -0.10698747 | L18: ='Proximal Validation (single)'!L17 -> -0.16471621 | M18: ='Proximal Validation (single)'!M17 -> -0.09704788 | N18: 0.24242483 | O18: 0.19215593 | P18: 3.6714316 | Q18: 1.8128564 | R18: 3.0618842e-06 | S18: =ABS(N18-A18) -> 0.057575175 | T18: =ABS(O18-B18) -> 0.012155929 | U18: =ABS(P18-C18) -> 0.0064315665 | V18: =ABS(Q18-D18) -> 0.24185645
A19: 0.3 | B19: 0.08 | C19: 1.571 | D19: 0.785 | E19: 1.4 | F19: 0 | G19: 0 | N19: 0.41651868 | O19: 0.075495969 | P19: 1.755045 | Q19: 0.43105223 | R19: 7.174735e-06 | S19: =ABS(N19-A19) -> 0.11651868 | T19: =ABS(O19-B19) -> 0.0045040309 | U19: =ABS(P19-C19) -> 0.184045 | V19: =ABS(Q19-D19) -> 0.35394777
A20: 0.4 | B20: 0.14 | C20: 1.571 | D20: 0.785 | E20: 0 | F20: 0 | G20: 0 | N20: 0.30659382 | O20: 0.12545497 | P20: 1.5655851 | Q20: 1.3446567 | R20: 4.7532196e-06 | S20: =ABS(N20-A20) -> 0.093406175 | T20: =ABS(O20-B20) -> 0.014545031 | U20: =ABS(P20-C20) -> 0.0054149455 | V20: =ABS(Q20-D20) -> 0.55965675
A21: 0.6 | B21: 0.16 | C21: 1.571 | D21: 0.785 | E21: 1.4 | F21: 0 | G21: 0 | N21: 0.55842501 | O21: 0.1774917 | P21: 1.7728844 | Q21: 0.74182988 | R21: 8.0398769e-06 | S21: =ABS(N21-A21) -> 0.041574993 | T21: =ABS(O21-B21) -> 0.017491696 | U21: =ABS(P21-C21) -> 0.20188436 | V21: =ABS(Q21-D21) -> 0.043170116
A22: 0.4 | B22: 0.06 | C22: 1.571 | D22: 1.571 | E22: 1.4 | F22: 0 | G22: 0 | N22: 0.36875743 | O22: 0.072413341 | P22: 1.6239719 | Q22: 1.1562194 | R22: 5.2801322e-05 | S22: =ABS(N22-A22) -> 0.031242565 | T22: =ABS(O22-B22) -> 0.012413341 | U22: =ABS(P22-C22) -> 0.052971935 | V22: =ABS(Q22-D22) -> 0.4147806
A23: 0.8 | B23: 0.08 | C23: 1.571 | D23: 1.571 | E23: 0 | F23: 0 | G23: 0 | N23: 0.71517165 | O23: 0.080469264 | P23: 1.5748642 | Q23: 1.7197807 | R23: 8.546771e-07 | S23: =ABS(N23-A23) -> 0.084828348 | T23: =ABS(O23-B23) -> 0.00046926392 | U23: =ABS(P23-C23) -> 0.0038641526 | V23: =ABS(Q23-D23) -> 0.14878075
A24: 0.7 | B24: 0.16 | C24: 1.571 | D24: 1.571 | E24: 1.4 | F24: 0 | G24: 0 | N24: 0.45772282 | O24: 0.19991835 | P24: 1.7026718 | Q24: 1.3785097 | R24: 0.0005709833 | S24: =ABS(N24-A24) -> 0.24227718 | T24: =ABS(O24-B24) -> 0.039918351 | U24: =ABS(P24-C24) -> 0.13167177 | V24: =ABS(Q24-D24) -> 0.19249032
A25: 0.7 | B25: 0.2 | C25: 1.571 | D25: 1.571 | E25: 0 | F25: 0 | G25: 0 | N25: 0.65311819 | O25: 0.19999715 | P25: 1.4696422 | Q25: 1.9245042 | R25: 0.00036148211 | S25: =ABS(N25-A25) -> 0.046881812 | T25: =ABS(O25-B25) -> 2.8489684e-06 | U25: =ABS(P25-C25) -> 0.10135782 | V25: =ABS(Q25-D25) -> 0.35350419
A26: 0.7 | B26: 0.06 | C26: 3.665 | D26: 0.785 | E26: 0 | F26: 0 | G26: 0 | N26: 0.72761916 | O26: 0.068733366 | P26: 3.6377668 | Q26: 0.92185062 | R26: 7.8778127e-07 | S26: =ABS(N26-A26) -> 0.027619156 | T26: =ABS(O26-B26) -> 0.008733366 | U26: =ABS(P26-C26) -> 0.027233152 | V26: =ABS(Q26-D26) -> 0.13685062
