Workbook

Sheet Proximal Validation (single)
A1: Ground Truth | H1: 6-Axis FT Sensor | N1: SoRoSim get_proximal_value | T1: Proximal Errors
A2: F (N) | B2: s (m) | C2: roll (rad) | D2: pitch (deg) | E2: tau1 (N) | F2: tau2 (N) | G2: tau3 (N) | H2: Tx (Nm) | I2: Ty (Nm) | J2: Tz(Nm) | K2: Fx (N) | L2: Fy (N) | M2: Fz (N) | N2: Tx (Nm) | O2: Ty (Nm) | P2: Tz(Nm) | Q2: Fx (N) | R2: Fy (N) | S2: Fz (N) | T2: Tx (Nm) | U2: Ty (Nm) | V2: Tz(Nm) | W2: Fx (N) | X2: Fy (N) | Y2: Fz (N)
A3: 0.3 | B3: 0.08 | C3: 1.571 | D3: 0.785 | E3: 1.4 | F3: 0 | G3: 0 | H3: 0.00026342465 | I3: -0.032978263 | J3: 0.00056162861 | K3: 0.18583472 | L3: 0.0011325702 | M3: 0.19288233 | N3: 0.00025576522 | O3: -0.037226281 | P3: 0.00094620553 | Q3: 0.20223599 | R3: 0.0070017163 | S3: 0.22147414 | T3: =ABS(H3-N3) -> 7.6594287e-06 | U3: =ABS(I3-O3) -> 0.0042480179 | V3: =ABS(J3-P3) -> 0.00038457692 | W3: =ABS(K3-Q3) -> 0.016401273 | X3: =ABS(L3-R3) -> 0.0058691461 | Y3: =ABS(M3-S3) -> 0.028591807
A4: 0.4 | B4: 0.14 | C4: 1.571 | D4: 0.785 | E4: 0 | F4: 0 | G4: 0 | H4: -0.00043474312 | I4: -0.062425632 | J4: 0.0025845002 | K4: 0.25303724 | L4: 0.010736909 | M4: 0.27653545 | N4: -2.3506608e-22 | O4: -0.070209886 | P4: -1.4299873e-05 | Q4: 0.24315923 | R4: -6.4687768e-05 | S4: 0.31760568 | T4: =ABS(H4-N4) -> 0.00043474312 | U4: =ABS(I4-O4) -> 0.0077842544 | V4: =ABS(J4-P4) -> 0.0025988001 | W4: =ABS(K4-Q4) -> 0.0098780155 | X4: =ABS(L4-R4) -> 0.010801597 | Y4: =ABS(M4-S4) -> 0.041070232
A5: 0.6 | B5: 0.16 | C5: 1.571 | D5: 0.785 | E5: 1.4 | F5: 0 | G5: 0 | H5: 0.0053234044 | I5: -0.12275674 | J5: -0.0083989212 | K5: 0.26806161 | L5: -0.024467468 | M5: 0.5263381 | N5: 0.0027985419 | O5: -0.1262598 | P5: 0.0083980934 | Q5: 0.2482473 | R5: 0.04168268 | S5: 0.54462429 | T5: =ABS(H5-N5) -> 0.0025248626 | U5: =ABS(I5-O5) -> 0.0035030546 | V5: =ABS(J5-P5) -> 0.016797015 | W5: =ABS(K5-Q5) -> 0.019814311 | X5: =ABS(L5-R5) -> 0.066150148 | Y5: =ABS(M5-S5) -> 0.018286188
A6: 0.4 | B6: 0.06 | C6: 1.571 | D6: 1.571 | E6: 1.4 | F6: 0 | G6: 0 | H6: 0.00067002582 | I6: -0.066750191 | J6: 0.0016002768 | K6: -0.039701398 | L6: 0.0073561743 | M6: 0.42381418 | N6: 0.00025448514 | O6: -0.059915075 | P6: -2.2999105e-05 | Q6: -0.015544496 | R6: -0.00021944765 | S6: 0.39969696 | T6: =ABS(H6-N6) -> 0.00041554068 | U6: =ABS(I6-O6) -> 0.006835116 | V6: =ABS(J6-P6) -> 0.0016232759 | W6: =ABS(K6-Q6) -> 0.024156903 | X6: =ABS(L6-R6) -> 0.0075756219 | Y6: =ABS(M6-S6) -> 0.024117213
A7: 0.8 | B7: 0.08 | C7: 1.571 | D7: 1.571 | E7: 0 | F7: 0 | G7: 0 | H7: 0.00074092089 | I7: -0.14775538 | J7: 0.0034220633 | K7: -0.16136234 | L7: 0.020262048 | M7: 0.82944489 | N7: -1.7162285e-22 | O7: -0.13554725 | P7: -2.7607344e-05 | Q7: -0.077940341 | R7: -0.00016216311 | S7: 0.79619263 | T7: =ABS(H7-N7) -> 0.00074092089 | U7: =ABS(I7-O7) -> 0.01220813 | V7: =ABS(J7-P7) -> 0.0034496707 | W7: =ABS(K7-Q7) -> 0.083421994 | X7: =ABS(L7-R7) -> 0.020424211 | Y7: =ABS(M7-S7) -> 0.033252256
A8: 0.7 | B8: 0.16 | C8: 1.571 | D8: 1.571 | E8: 1.4 | F8: 0 | G8: 0 | H8: 0.0066551082 | I8: -0.1483079 | J8: -0.0010527462 | K8: -0.44470632 | L8: -0.021994621 | M8: 0.48979318 | N8: 0.0043386998 | O8: -0.16297255 | P8: -0.00076315492 | Q8: -0.33942039 | R8: -0.011902291 | S8: 0.61206529 | T8: =ABS(H8-N8) -> 0.0023164084 | U8: =ABS(I8-O8) -> 0.014664642 | V8: =ABS(J8-P8) -> 0.00028959128 | W8: =ABS(K8-Q8) -> 0.10528593 | X8: =ABS(L8-R8) -> 0.01009233 | Y8: =ABS(M8-S8) -> 0.12227211
A9: 0.7 | B9: 0.2 | C9: 1.571 | D9: 1.571 | E9: 0 | F9: 0 | G9: 0 | H9: 0.00087637117 | I9: -0.16448845 | J9: 0.0037763002 | K9: -0.58729076 | L9: 0.0078071319 | M9: 0.38755593 | N9: -5.5758537e-23 | O9: -0.17090379 | P9: -3.4808524e-05 | Q9: -0.4922976 | R9: -0.00010135522 | S9: 0.4976365 | T9: =ABS(H9-N9) -> 0.00087637117 | U9: =ABS(I9-O9) -> 0.006415342 | V9: =ABS(J9-P9) -> 0.0038111088 | W9: =ABS(K9-Q9) -> 0.094993166 | X9: =ABS(L9-R9) -> 0.0079084871 | Y9: =ABS(M9-S9) -> 0.11008057
A10: 0.7 | B10: 0.06 | C10: 3.665 | D10: 0.785 | E10: 0 | F10: 0 | G10: 0 | H10: -0.00086323917 | I10: 0.042902049 | J10: -0.080319755 | K10: 0.61245459 | L10: -0.54026973 | M10: -0.28817487 | N10: 2.799559e-20 | O10: 0.037925348 | P10: -0.065717679 | Q10: 0.47927589 | R10: -0.44188673 | S10: -0.25501065 | T10: =ABS(H10-N10) -> 0.00086323917 | U10: =ABS(I10-O10) -> 0.0049767007 | V10: =ABS(J10-P10) -> 0.014602075 | W10: =ABS(K10-Q10) -> 0.13317871 | X10: =ABS(L10-R10) -> 0.098383007 | Y10: =ABS(M10-S10) -> 0.033164222
A11: 0.6 | B11: 0.1 | C11: 3.665 | D11: 0.785 | E11: 0 | F11: 0 | G11: 0 | H11: -0.00080120983 | I11: 0.042666439 | J11: -0.080293678 | K11: 0.4433108 | L11: -0.42717016 | M11: -0.22529536 | N11: 1.5747451e-19 | O11: 0.042595103 | P11: -0.073809508 | Q11: 0.38527891 | R11: -0.39837767 | S11: -0.22990178 | T11: =ABS(H11-N11) -> 0.00080120983 | U11: =ABS(I11-O11) -> 7.1336445e-05 | V11: =ABS(J11-P11) -> 0.0064841694 | W11: =ABS(K11-Q11) -> 0.058031885 | X11: =ABS(L11-R11) -> 0.028792488 | Y11: =ABS(M11-S11) -> 0.0046064193
A12: 0.8 | B12: 0.18 | C12: 3.665 | D12: 0.785 | E12: 1.4 | F12: 0 | G12: 0 | H12: -5.5334065e-05 | I12: 0.077956624 | J12: -0.13737398 | K12: 0.41918036 | L12: -0.5512532 | M12: -0.30630308 | N12: 1.2806708e-06 | O12: 0.089598765 | P12: -0.15526664 | Q12: 0.32090141 | R12: -0.63470132 | S12: -0.36626056 | T12: =ABS(H12-N12) -> 5.6614736e-05 | U12: =ABS(I12-O12) -> 0.01164214 | V12: =ABS(J12-P12) -> 0.017892656 | W12: =ABS(K12-Q12) -> 0.098278951 | X12: =ABS(L12-R12) -> 0.083448122 | Y12: =ABS(M12-S12) -> 0.059957476
A13: 0.4 | B13: 0.2 | C13: 3.665 | D13: 0.785 | E13: 1.4 | F13: 0 | G13: 0 | H13: -9.6024014e-05 | I13: 0.034424368 | J13: -0.061656475 | K13: 0.26709822 | L13: -0.21448079 | M13: -0.11506069 | N13: 7.959213e-07 | O13: 0.042758901 | P13: -0.074098745 | Q13: 0.24266051 | R13: -0.27541643 | S13: -0.15892727 | T13: =ABS(H13-N13) -> 9.6819935e-05 | U13: =ABS(I13-O13) -> 0.0083345331 | V13: =ABS(J13-P13) -> 0.01244227 | W13: =ABS(K13-Q13) -> 0.024437713 | X13: =ABS(L13-R13) -> 0.060935645 | Y13: =ABS(M13-S13) -> 0.043866582
A14: 0.4 | B14: 0.1 | C14: 3.665 | D14: 1.571 | E14: 1.4 | F14: 0 | G14: 0 | H14: -0.00037108036 | I14: 0.037644271 | J14: -0.067399666 | K14: 0.016782975 | L14: -0.33880779 | M14: -0.18529797 | N14: 1.8798558e-07 | O14: 0.037977348 | P14: -0.065807796 | Q14: -0.011664715 | R14: -0.34629978 | S14: -0.19984789 | T14: =ABS(H14-N14) -> 0.00037126834 | U14: =ABS(I14-O14) -> 0.00033307674 | V14: =ABS(J14-P14) -> 0.0015918695 | W14: =ABS(K14-Q14) -> 0.02844769 | X14: =ABS(L14-R14) -> 0.0074919861 | Y14: =ABS(M14-S14) -> 0.014549924
... A17: 0.3 | B17: 0.18 | C17: 3.665 | D17: 1.571 | E17: 0 | F17: 0 | G17: 0 | H17: 3.8368395e-05 | I17: 0.032897148 | J17: -0.058571801 | K17: -0.063505612 | L17: -0.19738522 | M17: -0.10824893 | N17: -8.8159604e-19 | O17: 0.039820341 | P17: -0.069001356 | Q17: -0.079390645 | R17: -0.2505725 | S17: -0.14460415 | T17: =ABS(H17-N17) -> 3.8368395e-05 | U17: =ABS(I17-O17) -> 0.0069231931 | V17: =ABS(J17-P17) -> 0.010429555 | W17: =ABS(K17-Q17) -> 0.015885033 | X17: =ABS(L17-R17) -> 0.053187275 | Y17: =ABS(M17-S17) -> 0.036355223

Sheet Distal Validation (single)
A1: Ground Truth | H1: 6-Axis FT Sensor | N1: SoRoSim get_distal_value | S1: Distal Errors | W1: Mean Average Error
A2: F (N) | B2: s (m) | C2: roll (rad) | D2: pitch (deg) | E2: tau1 (N) | F2: tau2 (N) | G2: tau3 (N) | H2: Tx (Nm) | I2: Ty (Nm) | J2: Tz(Nm) | K2: Fx (N) | L2: Fy (N) | M2: Fz (N) | N2: F (N) | O2: s (m) | P2: roll (rad) | Q2: pitch (deg) | R2: f_final | S2: Force Error | T2: Position Error | U2: Roll Error | V2: Pitch Error | W2: Force Error | X2: Position Error | Y2: Roll Error | Z2: Pitch Error
A3: ='Proximal Validation (single)'!A3 -> 0.3 | B3: ='Proximal Validation (single)'!B3 -> 0.08 | C3: ='Proximal Validation (single)'!C3 -> 1.571 | D3: ='Proximal Validation (single)'!D3 -> 0.785 | E3: ='Proximal Validation (single)'!E3 -> 1.4 | F3: ='Proximal Validation (single)'!F3 -> 0 | G3: ='Proximal Validation (single)'!G3 -> 0 | H3: ='Proximal Validation (single)'!H3 -> 0.00026342465 | ... M3: ='Proximal Validation (single)'!M3 -> 0.19288233 | N3: 0.26784524 | O3: 0.082926449 | P3: 1.6001679 | Q3: 0.75936828 | R3: 3.5206046e-07 | S3: =ABS(N3-A3) -> 0.032154759 | T3: =ABS(O3-B3) -> 0.0029264494 | U3: =ABS(P3-C3) -> 0.029167862 | V3: =ABS(Q3-D3) -> 0.025631716 | W3: =AVERAGE(S3:S17) -> 0.041514744 | X3: =AVERAGE(T3:T17) -> 0.0084886614 | Y3: =AVERAGE(U3:U17) -> 0.032385738 | Z3: =AVERAGE(V3:V17) -> 0.085712787
A4: ='Proximal Validation (single)'!A4 -> 0.4 | B4: ='Proximal Validation (single)'!B4 -> 0.14 | C4: ='Proximal Validation (single)'!C4 -> 1.571 | D4: ='Proximal Validation (single)'!D4 -> 0.785 | E4: ='Proximal Validation (single)'!E4 -> 0 | F4: ='Proximal Validation (single)'!F4 -> 0 | G4: ='Proximal Validation (single)'!G4 -> 0 | H4: ='Proximal Validation (single)'!H4 -> -0.00043474312 | ... M4: ='Proximal Validation (single)'!M4 -> 0.27653545 | N4: 0.37498688 | O4: 0.14629245 | P4: 1.5318646 | Q4: 0.70267597 | R4: 2.1354571e-07 | S4: =ABS(N4-A4) -> 0.02501312 | T4: =ABS(O4-B4) -> 0.0062924462 | U4: =ABS(P4-C4) -> 0.039135368 | V4: =ABS(Q4-D4) -> 0.082324025 | Y4: =DEGREES(Y3) -> 1.8555661 | Z4: =DEGREES(Z3) -> 4.9109809
A5: ='Proximal Validation (single)'!A5 -> 0.6 | B5: ='Proximal Validation (single)'!B5 -> 0.16 | C5: ='Proximal Validation (single)'!C5 -> 1.571 | D5: ='Proximal Validation (single)'!D5 -> 0.785 | E5: ='Proximal Validation (single)'!E5 -> 1.4 | F5: ='Proximal Validation (single)'!F5 -> 0 | G5: ='Proximal Validation (single)'!G5 -> 0 | H5: ='Proximal Validation (single)'!H5 -> 0.0053234044 | ... M5: ='Proximal Validation (single)'!M5 -> 0.5263381 | N5: 0.59113223 | O5: 0.16485708 | P5: 1.7130465 | Q5: 0.74340021 | R5: 6.374006e-06 | S5: =ABS(N5-A5) -> 0.0088677684 | T5: =ABS(O5-B5) -> 0.0048570759 | U5: =ABS(P5-C5) -> 0.14204651 | V5: =ABS(Q5-D5) -> 0.041599789
A6: ='Proximal Validation (single)'!A6 -> 0.4 | B6: ='Proximal Validation (single)'!B6 -> 0.06 | C6: ='Proximal Validation (single)'!C6 -> 1.571 | D6: ='Proximal Validation (single)'!D6 -> 1.571 | E6: ='Proximal Validation (single)'!E6 -> 1.4 | F6: ='Proximal Validation (single)'!F6 -> 0 | G6: ='Proximal Validation (single)'!G6 -> 0 | H6: ='Proximal Validation (single)'!H6 -> 0.00067002582 | ... M6: ='Proximal Validation (single)'!M6 -> 0.42381418 | N6: 0.42573318 | O6: 0.067481728 | P6: 1.5516581 | Q6: 1.6132217 | R6: 2.6866251e-07 | S6: =ABS(N6-A6) -> 0.025733176 | T6: =ABS(O6-B6) -> 0.0074817277 | U6: =ABS(P6-C6) -> 0.01934194 | V6: =ABS(Q6-D6) -> 0.04222166
A7: ='Proximal Validation (single)'!A7 -> 0.8 | B7: ='Proximal Validation (single)'!B7 -> 0.08 | C7: ='Proximal Validation (single)'!C7 -> 1.571 | D7: ='Proximal Validation (single)'!D7 -> 1.571 | E7: ='Proximal Validation (single)'!E7 -> 0 | F7: ='Proximal Validation (single)'!F7 -> 0 | G7: ='Proximal Validation (single)'!G7 -> 0 | H7: ='Proximal Validation (single)'!H7 -> 0.00074092089 | ... M7: ='Proximal Validation (single)'!M7 -> 0.82944489 | N7: 0.84524021 | O7: 0.087183959 | P7: 1.5464117 | Q7: 1.6376698 | R7: 5.8297183e-07 | S7: =ABS(N7-A7) -> 0.045240212 | T7: =ABS(O7-B7) -> 0.0071839591 | U7: =ABS(P7-C7) -> 0.024588281 | V7: =ABS(Q7-D7) -> 0.066669825
A8: ='Proximal Validation (single)'!A8 -> 0.7 | B8: ='Proximal Validation (single)'!B8 -> 0.16 | C8: ='Proximal Validation (single)'!C8 -> 1.571 | D8: ='Proximal Validation (single)'!D8 -> 1.571 | E8: ='Proximal Validation (single)'!E8 -> 1.4 | F8: ='Proximal Validation (single)'!F8 -> 0 | G8: ='Proximal Validation (single)'!G8 -> 0 | H8: ='Proximal Validation (single)'!H8 -> 0.0066551082 | ... M8: ='Proximal Validation (single)'!M8 -> 0.48979318 | N8: 0.66189889 | O8: 0.17541314 | P8: 1.5629917 | Q8: 1.7129397 | R8: 3.5747724e-06 | S8: =ABS(N8-A8) -> 0.038101109 | T8: =ABS(O8-B8) -> 0.015413139 | U8: =ABS(P8-C8) -> 0.008008252 | V8: =ABS(Q8-D8) -> 0.14193966
A9: ='Proximal Validation (single)'!A9 -> 0.7 | B9: ='Proximal Validation (single)'!B9 -> 0.2 | C9: ='Proximal Validation (single)'!C9 -> 1.571 | D9: ='Proximal Validation (single)'!D9 -> 1.571 | E9: ='Proximal Validation (single)'!E9 -> 0 | F9: ='Proximal Validation (single)'!F9 -> 0 | G9: ='Proximal Validation (single)'!G9 -> 0 | H9: ='Proximal Validation (single)'!H9 -> 0.00087637117 | ... M9: ='Proximal Validation (single)'!M9 -> 0.38755593 | N9: 0.707613 | O9: 0.2 | P9: 1.5502642 | Q9: 1.8187206 | R9: 0.0002662912 | S9: =ABS(N9-A9) -> 0.0076129991 | T9: =ABS(O9-B9) -> 0 | U9: =ABS(P9-C9) -> 0.020735848 | V9: =ABS(Q9-D9) -> 0.2477206
A10: ='Proximal Validation (single)'!A10 -> 0.7 | B10: ='Proximal Validation (single)'!B10 -> 0.06 | C10: ='Proximal Validation (single)'!C10 -> 3.665 | D10: ='Proximal Validation (single)'!D10 -> 0.785 | E10: ='Proximal Validation (single)'!E10 -> 0 | F10: ='Proximal Validation (single)'!F10 -> 0 | G10: ='Proximal Validation (single)'!G10 -> 0 | H10: ='Proximal Validation (single)'!H10 -> -0.00086323917 | ... M10: ='Proximal Validation (single)'!M10 -> -0.28817487 | N10: 0.86604704 | O10: 0.060317948 | P10: 3.6316073 | Q10: 0.74713989 | R10: 7.4794518e-07 | S10: =ABS(N10-A10) -> 0.16604704 | T10: =ABS(O10-B10) -> 0.00031794825 | U10: =ABS(P10-C10) -> 0.033392705 | V10: =ABS(Q10-D10) -> 0.037860114
A11: ='Proximal Validation (single)'!A11 -> 0.6 | B11: ='Proximal Validation (single)'!B11 -> 0.1 | C11: ='Proximal Validation (single)'!C11 -> 3.665 | D11: ='Proximal Validation (single)'!D11 -> 0.785 | E11: ='Proximal Validation (single)'!E11 -> 0 | F11: ='Proximal Validation (single)'!F11 -> 0 | G11: ='Proximal Validation (single)'!G11 -> 0 | H11: ='Proximal Validation (single)'!H11 -> -0.00080120983 | ... M11: ='Proximal Validation (single)'!M11 -> -0.22529536 | N11: 0.65555895 | O11: 0.1044416 | P11: 3.6270359 | Q11: 0.72703274 | R11: 7.1856603e-07 | S11: =ABS(N11-A11) -> 0.055558949 | T11: =ABS(O11-B11) -> 0.0044416045 | U11: =ABS(P11-C11) -> 0.037964052 | V11: =ABS(Q11-D11) -> 0.057967263
A12: ='Proximal Validation (single)'!A12 -> 0.8 | B12: ='Proximal Validation (single)'!B12 -> 0.18 | C12: ='Proximal Validation (single)'!C12 -> 3.665 | D12: ='Proximal Validation (single)'!D12 -> 0.785 | E12: ='Proximal Validation (single)'!E12 -> 1.4 | F12: ='Proximal Validation (single)'!F12 -> 0 | G12: ='Proximal Validation (single)'!G12 -> 0 | H12: ='Proximal Validation (single)'!H12 -> -5.5334065e-05 | ... M12: ='Proximal Validation (single)'!M12 -> -0.30630308 | N12: 0.75729704 | O12: 0.2 | P12: 3.6521772 | Q12: 0.63682675 | R12: 1.8459139e-06 | S12: =ABS(N12-A12) -> 0.042702955 | T12: =ABS(O12-B12) -> 0.02 | U12: =ABS(P12-C12) -> 0.012822822 | V12: =ABS(Q12-D12) -> 0.14817325
A13: ='Proximal Validation (single)'!A13 -> 0.4 | B13: ='Proximal Validation (single)'!B13 -> 0.2 | C13: ='Proximal Validation (single)'!C13 -> 3.665 | D13: ='Proximal Validation (single)'!D13 -> 0.785 | E13: ='Proximal Validation (single)'!E13 -> 1.4 | F13: ='Proximal Validation (single)'!F13 -> 0 | G13: ='Proximal Validation (single)'!G13 -> 0 | H13: ='Proximal Validation (single)'!H13 -> -9.6024014e-05 | ... M13: ='Proximal Validation (single)'!M13 -> -0.11506069 | N13: 0.36208646 | O13: 0.2 | P13: 3.6411087 | Q13: 0.67613484 | R13: 2.1474948e-05 | S13: =ABS(N13-A13) -> 0.037913536 | T13: =ABS(O13-B13) -> 0 | U13: =ABS(P13-C13) -> 0.023891337 | V13: =ABS(Q13-D13) -> 0.10886516
A14: ='Proximal Validation (single)'!A14 -> 0.4 | B14: ='Proximal Validation (single)'!B14 -> 0.1 | C14: ='Proximal Validation (single)'!C14 -> 3.665 | D14: ='Proximal Validation (single)'!D14 -> 1.571 | E14: ='Proximal Validation (single)'!E14 -> 1.4 | F14: ='Proximal Validation (single)'!F14 -> 0 | G14: ='Proximal Validation (single)'!G14 -> 0 | H14: ='Proximal Validation (single)'!H14 -> -0.00037108036 | ... M14: ='Proximal Validation (single)'!M14 -> -0.18529797 | N14: 0.38653499 | O14: 0.11011821 | P14: 3.6425184 | Q14: 1.4898941 | R14: 6.0897641e-07 | S14: =ABS(N14-A14) -> 0.013465007 | T14: =ABS(O14-B14) -> 0.010118208 | U14: =ABS(P14-C14) -> 0.022481581 | V14: =ABS(Q14-D14) -> 0.081105897
A15: ='Proximal Validation (single)'!A15 -> 0.7 | B15: ='Proximal Validation (single)'!B15 -> 0.1 | C15: ='Proximal Validation (single)'!C15 -> 3.665 | D15: ='Proximal Validation (single)'!D15 -> 1.571 | E15: ='Proximal Validation (single)'!E15 -> 1.4 | F15: ='Proximal Validation (single)'!F15 -> 0 | G15: ='Proximal Validation (single)'!G15 -> 0 | H15: ='Proximal Validation (single)'!H15 -> -0.0010242919 | ... M15: ='Proximal Validation (single)'!M15 -> -0.34651768 | N15: 0.72465465 | O15: 0.1105228 | P15: 3.6410775 | Q15: 1.4863396 | R15: 2.841859e-06 | S15: =ABS(N15-A15) -> 0.02465465 | T15: =ABS(O15-B15) -> 0.010522798 | U15: =ABS(P15-C15) -> 0.023922451 | V15: =ABS(Q15-D15) -> 0.084660429
A16: ='Proximal Validation (single)'!A16 -> 0.4 | B16: ='Proximal Validation (single)'!B16 -> 0.16 | C16: ='Proximal Validation (single)'!C16 -> 3.665 | D16: ='Proximal Validation (single)'!D16 -> 1.571 | E16: ='Proximal Validation (single)'!E16 -> 0 | F16: ='Proximal Validation (single)'!F16 -> 0 | G16: ='Proximal Validation (single)'!G16 -> 0 | H16: ='Proximal Validation (single)'!H16 -> -0.00060879067 | ... M16: ='Proximal Validation (single)'!M16 -> -0.17043319 | N16: 0.36612739 | O16: 0.17777457 | P16: 3.6376809 | Q16: 1.4590277 | R16: 1.4221141e-06 | S16: =ABS(N16-A16) -> 0.033872613 | T16: =ABS(O16-B16) -> 0.017774566 | U16: =ABS(P16-C16) -> 0.027319053 | V16: =ABS(Q16-D16) -> 0.11197227
A17: ='Proximal Validation (single)'!A17 -> 0.3 | B17: ='Proximal Validation (single)'!B17 -> 0.18 | C17: ='Proximal Validation (single)'!C17 -> 3.665 | D17: ='Proximal Validation (single)'!D17 -> 1.571 | E17: ='Proximal Validation (single)'!E17 -> 0 | F17: ='Proximal Validation (single)'!F17 -> 0 | G17: ='Proximal Validation (single)'!G17 -> 0 | H17: ='Proximal Validation (single)'!H17 -> 3.8368395e-05 | ... M17: ='Proximal Validation (single)'!M17 -> -0.10824893 | N17: 0.23421673 | O17: 0.2 | P17: 3.644032 | Q17: 1.5779801 | R17: 1.7244629e-06 | S17: =ABS(N17-A17) -> 0.065783271 | T17: =ABS(O17-B17) -> 0.02 | U17: =ABS(P17-C17) -> 0.020968013 | V17: =ABS(Q17-D17) -> 0.006980147

Sheet Distal Vali (noise 0.5x spec)
A1: Ground Truth | H1: 6-Axis FT Sensor | N1: SoRoSim get_distal_value | S1: Distal Errors | W1: Mean Average Error
A2: F (N) | B2: s (m) | C2: roll (rad) | D2: pitch (deg) | E2: tau1 (N) | F2: tau2 (N) | G2: tau3 (N) | H2: Tx (Nm) | I2: Ty (Nm) | J2: Tz(Nm) | K2: Fx (N) | L2: Fy (N) | M2: Fz (N) | N2: F (N) | O2: s (m) | P2: roll (rad) | Q2: pitch (deg) | R2: f_final | S2: Force Error | T2: Position Error | U2: Roll Error | V2: Pitch Error | W2: Force Error | X2: Position Error | Y2: Roll Error | Z2: Pitch Error
A3: 0.3 | B3: 0.08 | C3: 1.571 | D3: 0.785 | E3: 1.4 | F3: 0 | G3: 0 | H3: ='Proximal Validation (single)'!H3 -> 0.00026342465 | I3: ='Proximal Validation (single)'!I3 -> -0.032978263 | J3: ='Proximal Validation (single)'!J3 -> 0.00056162861 | K3: ='Proximal Validation (single)'!K3 -> 0.18583472 | L3: ='Proximal Validation (single)'!L3 -> 0.0011325702 | M3: ='Proximal Validation (single)'!M3 -> 0.19288233 | N3: 0.27774619 | O3: 0.040975423 | P3: 1.6067076 | Q3: 1.3988737 | R3: 4.4664331e-05 | S3: =ABS(N3-A3) -> 0.022253812 | T3: =ABS(O3-B3) -> 0.039024577 | U3: =ABS(P3-C3) -> 0.035707592 | V3: =ABS(Q3-D3) -> 0.61387371 | W3: =AVERAGE(S3:S152) -> 0.077779237 | X3: =AVERAGE(T3:T152) -> 0.024188656 | Y3: =AVERAGE(U3:U152) -> 0.13309406 | Z3: =AVERAGE(V3:V152) -> 0.25245781
A4: 0.4 | B4: 0.14 | C4: 1.571 | D4: 0.785 | E4: 0 | F4: 0 | G4: 0 | H4: ='Proximal Validation (single)'!H4 -> -0.00043474312 | I4: ='Proximal Validation (single)'!I4 -> -0.062425632 | J4: ='Proximal Validation (single)'!J4 -> 0.0025845002 | K4: ='Proximal Validation (single)'!K4 -> 0.25303724 | L4: ='Proximal Validation (single)'!L4 -> 0.010736909 | M4: ='Proximal Validation (single)'!M4 -> 0.27653545 | N4: 0.4253367 | O4: 0.12215216 | P4: 1.2093064 | Q4: 0.63665086 | R4: 0.00044126492 | S4: =ABS(N4-A4) -> 0.025336702 | T4: =ABS(O4-B4) -> 0.017847837 | U4: =ABS(P4-C4) -> 0.36169359 | V4: =ABS(Q4-D4) -> 0.14834914 | Y4: =DEGREES(Y3) -> 7.6257278 | Z4: =DEGREES(Z3) -> 14.464767
A5: 0.6 | B5: 0.16 | C5: 1.571 | D5: 0.785 | E5: 1.4 | F5: 0 | G5: 0 | H5: ='Proximal Validation (single)'!H5 -> 0.0053234044 | I5: ='Proximal Validation (single)'!I5 -> -0.12275674 | J5: ='Proximal Validation (single)'!J5 -> -0.0083989212 | K5: ='Proximal Validation (single)'!K5 -> 0.26806161 | L5: ='Proximal Validation (single)'!L5 -> -0.024467468 | M5: ='Proximal Validation (single)'!M5 -> 0.5263381 | N5: 0.67236059 | O5: 0.18284444 | P5: 1.9753465 | Q5: 0.43493429 | R5: 0.00032318153 | S5: =ABS(N5-A5) -> 0.072360591 | T5: =ABS(O5-B5) -> 0.022844445 | U5: =ABS(P5-C5) -> 0.40434651 | V5: =ABS(Q5-D5) -> 0.35006571
A6: 0.4 | B6: 0.06 | C6: 1.571 | D6: 1.571 | E6: 1.4 | F6: 0 | G6: 0 | H6: ='Proximal Validation (single)'!H6 -> 0.00067002582 | I6: ='Proximal Validation (single)'!I6 -> -0.066750191 | J6: ='Proximal Validation (single)'!J6 -> 0.0016002768 | K6: ='Proximal Validation (single)'!K6 -> -0.039701398 | L6: ='Proximal Validation (single)'!L6 -> 0.0073561743 | M6: ='Proximal Validation (single)'!M6 -> 0.42381418 | N6: 0.45530647 | O6: 0.058971501 | P6: 1.4891783 | Q6: 1.6819344 | R6: 8.9140644e-05 | S6: =ABS(N6-A6) -> 0.055306471 | T6: =ABS(O6-B6) -> 0.0010284989 | U6: =ABS(P6-C6) -> 0.081821711 | V6: =ABS(Q6-D6) -> 0.11093444
A7: 0.8 | B7: 0.08 | C7: 1.571 | D7: 1.571 | E7: 0 | F7: 0 | G7: 0 | H7: ='Proximal Validation (single)'!H7 -> 0.00074092089 | I7: ='Proximal Validation (single)'!I7 -> -0.14775538 | J7: ='Proximal Validation (single)'!J7 -> 0.0034220633 | K7: ='Proximal Validation (single)'!K7 -> -0.16136234 | L7: ='Proximal Validation (single)'!L7 -> 0.020262048 | M7: ='Proximal Validation (single)'!M7 -> 0.82944489 | N7: 0.88126118 | O7: 0.077032301 | P7: 1.4886538 | Q7: 1.514925 | R7: 0.00013775843 | S7: =ABS(N7-A7) -> 0.081261182 | T7: =ABS(O7-B7) -> 0.002967699 | U7: =ABS(P7-C7) -> 0.082346151 | V7: =ABS(Q7-D7) -> 0.056074983
A8: 0.7 | B8: 0.16 | C8: 1.571 | D8: 1.571 | E8: 1.4 | F8: 0 | G8: 0 | H8: ='Proximal Validation (single)'!H8 -> 0.0066551082 | I8: ='Proximal Validation (single)'!I8 -> -0.1483079 | J8: ='Proximal Validation (single)'!J8 -> -0.0010527462 | K8: ='Proximal Validation (single)'!K8 -> -0.44470632 | L8: ='Proximal Validation (single)'!L8 -> -0.021994621 | M8: ='Proximal Validation (single)'!M8 -> 0.48979318 | N8: 0.69553959 | O8: 0.18661615 | P8: 1.6072299 | Q8: 1.7058173 | R8: 0.00012340762 | S8: =ABS(N8-A8) -> 0.0044604059 | T8: =ABS(O8-B8) -> 0.02661615 | U8: =ABS(P8-C8) -> 0.03622991 | V8: =ABS(Q8-D8) -> 0.13481726
A9: 0.7 | B9: 0.2 | C9: 1.571 | D9: 1.571 | E9: 0 | F9: 0 | G9: 0 | H9: ='Proximal Validation (single)'!H9 -> 0.00087637117 | I9: ='Proximal Validation (single)'!I9 -> -0.16448845 | J9: ='Proximal Validation (single)'!J9 -> 0.0037763002 | K9: ='Proximal Validation (single)'!K9 -> -0.58729076 | L9: ='Proximal Validation (single)'!L9 -> 0.0078071319 | M9: ='Proximal Validation (single)'!M9 -> 0.38755593 | N9: 0.88833235 | O9: 0.19998891 | P9: 1.5191059 | Q9: 2.008809 | R9: 0.00075065779 | S9: =ABS(N9-A9) -> 0.18833235 | T9: =ABS(O9-B9) -> 1.1087742e-05 | U9: =ABS(P9-C9) -> 0.051894074 | V9: =ABS(Q9-D9) -> 0.43780899
A10: 0.7 | B10: 0.06 | C10: 3.665 | D10: 0.785 | E10: 0 | F10: 0 | G10: 0 | H10: ='Proximal Validation (single)'!H10 -> -0.00086323917 | I10: ='Proximal Validation (single)'!I10 -> 0.042902049 | J10: ='Proximal Validation (single)'!J10 -> -0.080319755 | K10: ='Proximal Validation (single)'!K10 -> 0.61245459 | L10: ='Proximal Validation (single)'!L10 -> -0.54026973 | M10: ='Proximal Validation (single)'!M10 -> -0.28817487 | N10: 0.9413605 | O10: 0.035340404 | P10: 3.5609491 | Q10: 0.82365613 | R10: 0.00015470316 | S10: =ABS(N10-A10) -> 0.2413605 | T10: =ABS(O10-B10) -> 0.024659596 | U10: =ABS(P10-C10) -> 0.10405085 | V10: =ABS(Q10-D10) -> 0.038656131
A11: 0.6 | B11: 0.1 | C11: 3.665 | D11: 0.785 | E11: 0 | F11: 0 | G11: 0 | H11: ='Proximal Validation (single)'!H11 -> -0.00080120983 | I11: ='Proximal Validation (single)'!I11 -> 0.042666439 | J11: ='Proximal Validation (single)'!J11 -> -0.080293678 | K11: ='Proximal Validation (single)'!K11 -> 0.4433108 | L11: ='Proximal Validation (single)'!L11 -> -0.42717016 | M11: ='Proximal Validation (single)'!M11 -> -0.22529536 | N11: 0.63060068 | O11: 0.094140701 | P11: 3.5017778 | Q11: 0.8954813 | R11: 0.00011432198 | S11: =ABS(N11-A11) -> 0.030600681 | T11: =ABS(O11-B11) -> 0.0058592991 | U11: =ABS(P11-C11) -> 0.1632222 | V11: =ABS(Q11-D11) -> 0.1104813
A12: 0.8 | B12: 0.18 | C12: 3.665 | D12: 0.785 | E12: 1.4 | F12: 0 | G12: 0 | H12: ='Proximal Validation (single)'!H12 -> -5.5334065e-05 | I12: ='Proximal Validation (single)'!I12 -> 0.077956624 | J12: ='Proximal Validation (single)'!J12 -> -0.13737398 | K12: ='Proximal Validation (single)'!K12 -> 0.41918036 | L12: ='Proximal Validation (single)'!L12 -> -0.5512532 | M12: ='Proximal Validation (single)'!M12 -> -0.30630308 | N12: 0.8240885 | O12: 0.19484017 | P12: 3.7114017 | Q12: 0.55778255 | R12: 8.215207e-05 | S12: =ABS(N12-A12) -> 0.024088503 | T12: =ABS(O12-B12) -> 0.014840172 | U12: =ABS(P12-C12) -> 0.04640174 | V12: =ABS(Q12-D12) -> 0.22721745
A13: 0.4 | B13: 0.2 | C13: 3.665 | D13: 0.785 | E13: 1.4 | F13: 0 | G13: 0 | H13: ='Proximal Validation (single)'!H13 -> -9.6024014e-05 | I13: ='Proximal Validation (single)'!I13 -> 0.034424368 | J13: ='Proximal Validation (single)'!J13 -> -0.061656475 | K13: ='Proximal Validation (single)'!K13 -> 0.26709822 | L13: ='Proximal Validation (single)'!L13 -> -0.21448079 | M13: ='Proximal Validation (single)'!M13 -> -0.11506069 | N13: 0.37539718 | O13: 0.19999883 | P13: 3.6203973 | Q13: 0.68152178 | R13: 1.8289058e-05 | S13: =ABS(N13-A13) -> 0.024602825 | T13: =ABS(O13-B13) -> 1.1696963e-06 | U13: =ABS(P13-C13) -> 0.044602743 | V13: =ABS(Q13-D13) -> 0.10347822
A14: 0.4 | B14: 0.1 | C14: 3.665 | D14: 1.571 | E14: 1.4 | F14: 0 | G14: 0 | H14: ='Proximal Validation (single)'!H14 -> -0.00037108036 | I14: ='Proximal Validation (single)'!I14 -> 0.037644271 | J14: ='Proximal Validation (single)'!J14 -> -0.067399666 | K14: ='Proximal Validation (single)'!K14 -> 0.016782975 | L14: ='Proximal Validation (single)'!L14 -> -0.33880779 | M14: ='Proximal Validation (single)'!M14 -> -0.18529797 | N14: 0.40432575 | O14: 0.15357178 | P14: 3.1664275 | Q14: 2.3785535 | R14: 0.00088780632 | S14: =ABS(N14-A14) -> 0.0043257453 | T14: =ABS(O14-B14) -> 0.05357178 | U14: =ABS(P14-C14) -> 0.49857245 | V14: =ABS(Q14-D14) -> 0.80755351
A15: 0.7 | B15: 0.1 | C15: 3.665 | D15: 1.571 | E15: 1.4 | F15: 0 | G15: 0 | H15: ='Proximal Validation (single)'!H15 -> -0.0010242919 | I15: ='Proximal Validation (single)'!I15 -> 0.070613205 | J15: ='Proximal Validation (single)'!J15 -> -0.12678832 | K15: ='Proximal Validation (single)'!K15 -> -0.029671347 | L15: ='Proximal Validation (single)'!L15 -> -0.63574088 | M15: ='Proximal Validation (single)'!M15 -> -0.34651768 | N15: 0.71194151 | O15: 0.11262051 | P15: 3.6225419 | Q15: 1.4101608 | R15: 0.00013090746 | S15: =ABS(N15-A15) -> 0.011941511 | T15: =ABS(O15-B15) -> 0.012620512 | U15: =ABS(P15-C15) -> 0.042458145 | V15: =ABS(Q15-D15) -> 0.16083923
A16: 0.4 | B16: 0.16 | C16: 3.665 | D16: 1.571 | E16: 0 | F16: 0 | G16: 0 | H16: ='Proximal Validation (single)'!H16 -> -0.00060879067 | I16: ='Proximal Validation (single)'!I16 -> 0.047145899 | J16: ='Proximal Validation (single)'!J16 -> -0.085028917 | K16: ='Proximal Validation (single)'!K16 -> -0.074065492 | L16: ='Proximal Validation (single)'!L16 -> -0.3154611 | M16: ='Proximal Validation (single)'!M16 -> -0.17043319 | N16: 0.55442235 | O16: 0.10166803 | P16: 3.6476579 | Q16: 1.9002186 | R16: 1.9951131e-06 | S16: =ABS(N16-A16) -> 0.15442235 | T16: =ABS(O16-B16) -> 0.058331966 | U16: =ABS(P16-C16) -> 0.017342108 | V16: =ABS(Q16-D16) -> 0.32921857
A17: 0.3 | B17: 0.18 | C17: 3.665 | D17: 1.571 | E17: 0 | F17: 0 | G17: 0 | H17: ='Proximal Validation (single)'!H17 -> 3.8368395e-05 | I17: ='Proximal Validation (single)'!I17 -> 0.032897148 | J17: ='Proximal Validation (single)'!J17 -> -0.058571801 | K17: ='Proximal Validation (single)'!K17 -> -0.063505612 | L17: ='Proximal Validation (single)'!L17 -> -0.19738522 | M17: ='Proximal Validation (single)'!M17 -> -0.10824893 | N17: 0.22496618 | O17: 0.19998159 | P17: 3.8312019 | Q17: 1.8112269 | R17: 0.00020191668 | S17: =ABS(N17-A17) -> 0.075033821 | T17: =ABS(O17-B17) -> 0.01998159 | U17: =ABS(P17-C17) -> 0.16620191 | V17: =ABS(Q17-D17) -> 0.24022694
A18: 0.3 | B18: 0.08 | C18: 1.571 | D18: 0.785 | E18: 1.4 | F18: 0 | G18: 0 | N18: 0.45538996 | O18: 0.029543702 | P18: 1.7215304 | Q18: 0.61655335 | R18: 3.8828797e-05 | S18: =ABS(N18-A18) -> 0.15538996 | T18: =ABS(O18-B18) -> 0.050456298 | U18: =ABS(P18-C18) -> 0.15053043 | V18: =ABS(Q18-D18) -> 0.16844665
A19: 0.4 | B19: 0.14 | C19: 1.571 | D19: 0.785 | E19: 0 | F19: 0 | G19: 0 | N19: 0.3178591 | O19: 0.097066635 | P19: 1.797915 | Q19: 1.3869157 | R19: 0.00036381364 | S19: =ABS(N19-A19) -> 0.082140904 | T19: =ABS(O19-B19) -> 0.042933365 | U19: =ABS(P19-C19) -> 0.22691499 | V19: =ABS(Q19-D19) -> 0.60191574
A20: 0.6 | B20: 0.16 | C20: 1.571 | D20: 0.785 | E20: 1.4 | F20: 0 | G20: 0 | N20: 0.55811343 | O20: 0.19933497 | P20: 1.7927638 | Q20: 0.5501808 | R20: 0.00012172351 | S20: =ABS(N20-A20) -> 0.041886575 | T20: =ABS(O20-B20) -> 0.03933497 | U20: =ABS(P20-C20) -> 0.22176382 | V20: =ABS(Q20-D20) -> 0.2348192
A21: 0.4 | B21: 0.06 | C21: 1.571 | D21: 1.571 | E21: 1.4 | F21: 0 | G21: 0 | N21: 0.42628116 | O21: 0.073094879 | P21: 1.6210088 | Q21: 1.2735976 | R21: 0.00011767378 | S21: =ABS(N21-A21) -> 0.026281157 | T21: =ABS(O21-B21) -> 0.013094879 | U21: =ABS(P21-C21) -> 0.050008825 | V21: =ABS(Q21-D21) -> 0.29740244
A22: 0.8 | B22: 0.08 | C22: 1.571 | D22: 1.571 | E22: 0 | F22: 0 | G22: 0 | N22: 0.95514239 | O22: 0.064547982 | P22: 1.4842206 | Q22: 1.7423129 | R22: 0.00011282227 | S22: =ABS(N22-A22) -> 0.15514239 | T22: =ABS(O22-B22) -> 0.015452018 | U22: =ABS(P22-C22) -> 0.086779361 | V22: =ABS(Q22-D22) -> 0.17131292
A23: 0.7 | B23: 0.16 | C23: 1.571 | D23: 1.571 | E23: 1.4 | F23: 0 | G23: 0 | N23: 0.53796693 | O23: 0.19855612 | P23: 1.5654173 | Q23: 1.2493049 | R23: 0.00013228723 | S23: =ABS(N23-A23) -> 0.16203307 | T23: =ABS(O23-B23) -> 0.038556117 | U23: =ABS(P23-C23) -> 0.0055826757 | V23: =ABS(Q23-D23) -> 0.32169512
A24: 0.7 | B24: 0.2 | C24: 1.571 | D24: 1.571 | E24: 0 | F24: 0 | G24: 0 | N24: 0.68184273 | O24: 0.19999693 | P24: 1.6808771 | Q24: 2.0410364 | R24: 0.0024914398 | S24: =ABS(N24-A24) -> 0.018157267 | T24: =ABS(O24-B24) -> 3.0713136e-06 | U24: =ABS(P24-C24) -> 0.10987713 | V24: =ABS(Q24-D24) -> 0.47003638
A25: 0.7 | B25: 0.06 | C25: 3.665 | D25: 0.785 | E25: 0 | F25: 0 | G25: 0 | N25: 0.72376998 | O25: 0.091227954 | P25: 3.7763175 | Q25: 0.7490286 | R25: 0.00019468214 | S25: =ABS(N25-A25) -> 0.023769976 | T25: =ABS(O25-B25) -> 0.031227954 | U25: =ABS(P25-C25) -> 0.11131747 | V25: =ABS(Q25-D25) -> 0.035971403
A26: 0.6 | B26: 0.1 | C26: 3.665 | D26: 0.785 | E26: 0 | F26: 0 | G26: 0 | N26: 0.70007789 | O26: 0.10907386 | P26: 3.5200589 | Q26: 0.62203594 | R26: 0.00018932594 | S26: =ABS(N26-A26) -> 0.10007789 | T26: =ABS(O26-B26) -> 0.0090738626 | U26: =ABS(P26-C26) -> 0.14494113 | V26: =ABS(Q26-D26) -> 0.16296406
A27: 0.8 | B27: 0.18 | C27: 3.665 | D27: 0.785 | E27: 1.4 | F27: 0 | G27: 0 | N27: 0.78847105 | O27: 0.15006986 | P27: 3.6237627 | Q27: 0.86376534 | R27: 0.00020234957 | S27: =ABS(N27-A27) -> 0.011528954 | T27: =ABS(O27-B27) -> 0.02993014 | U27: =ABS(P27-C27) -> 0.041237263 | V27: =ABS(Q27-D27) -> 0.07876534
A28: 0.4 | B28: 0.2 | C28: 3.665 | D28: 0.785 | E28: 1.4 | F28: 0 | G28: 0 | N28: 0.46797587 | O28: 0.19890607 | P28: 3.4413065 | Q28: 0.41667014 | R28: 0.00045138572 | S28: =ABS(N28-A28) -> 0.067975875 | T28: =ABS(O28-B28) -> 0.0010939275 | U28: =ABS(P28-C28) -> 0.22369353 | V28: =ABS(Q28-D28) -> 0.36832986
A29: 0.4 | B29: 0.1 | C29: 3.665 | D29: 1.571 | E29: 1.4 | F29: 0 | G29: 0 | N29: 0.39609595 | O29: 0.11331022 | P29: 3.565753 | Q29: 1.3842896 | R29: 2.9593874e-05 | S29: =ABS(N29-A29) -> 0.0039040547 | T29: =ABS(O29-B29) -> 0.013310224 | U29: =ABS(P29-C29) -> 0.09924698 | V29: =ABS(Q29-D29) -> 0.18671041
... A152: 0.3 | B152: 0.18 | C152: 3.665 | D152: 1.571 | E152: 0 | F152: 0 | G152: 0 | N152: 0.24326419 | O152: 0.18190236 | P152: 3.7523753 | Q152: 1.4334486 | R152: 3.3565184e-05 | S152: =ABS(N152-A152) -> 0.056735807 | T152: =ABS(O152-B152) -> 0.0019023647 | U152: =ABS(P152-C152) -> 0.087375264 | V152: =ABS(Q152-D152) -> 0.13755143

Sheet Distal Vali (noise 1.0x spec)
A1: Ground Truth | H1: 6-Axis FT Sensor | N1: SoRoSim get_distal_value | S1: Distal Errors | W1: Mean Average Error
A2: F (N) | B2: s (m) | C2: roll (rad) | D2: pitch (deg) | E2: tau1 (N) | F2: tau2 (N) | G2: tau3 (N) | H2: Tx (Nm) | I2: Ty (Nm) | J2: Tz(Nm) | K2: Fx (N) | L2: Fy (N) | M2: Fz (N) | N2: F (N) | O2: s (m) | P2: roll (rad) | Q2: pitch (deg) | R2: f_final | S2: Force Error | T2: Position Error | U2: Roll Error | V2: Pitch Error | W2: Force Error | X2: Position Error | Y2: Roll Error | Z2: Pitch Error
A3: 0.3 | B3: 0.08 | C3: 1.571 | D3: 0.785 | E3: 1.4 | F3: 0 | G3: 0 | H3: ='Proximal Validation (single)'!H3 -> 0.00026342465 | I3: ='Proximal Validation (single)'!I3 -> -0.032978263 | J3: ='Proximal Validation (single)'!J3 -> 0.00056162861 | K3: ='Proximal Validation (single)'!K3 -> 0.18583472 | L3: ='Proximal Validation (single)'!L3 -> 0.0011325702 | M3: ='Proximal Validation (single)'!M3 -> 0.19288233 | N3: 0.36966498 | O3: 0.019400933 | P3: 1.6247245 | Q3: 1.8378869 | R3: 0.00016572261 | S3: =ABS(N3-A3) -> 0.06966498 | T3: =ABS(O3-B3) -> 0.060599067 | U3: =ABS(P3-C3) -> 0.053724538 | V3: =ABS(Q3-D3) -> 1.0528869 | W3: =AVERAGE(S3:S152) -> 0.14060614 | X3: =AVERAGE(T3:T152) -> 0.039545783 | Y3: =AVERAGE(U3:U152) -> 0.26107523 | Z3: =AVERAGE(V3:V152) -> 0.41308954 | AC3: 0.082320833 | AD3: 0.056116371 | AF3: =ABS(AC3-S3) -> 0.012655854 | AG3: =ABS(AD3-T3) -> 0.0044826966
A4: 0.4 | B4: 0.14 | C4: 1.571 | D4: 0.785 | E4: 0 | F4: 0 | G4: 0 | H4: ='Proximal Validation (single)'!H4 -> -0.00043474312 | I4: ='Proximal Validation (single)'!I4 -> -0.062425632 | J4: ='Proximal Validation (single)'!J4 -> 0.0025845002 | K4: ='Proximal Validation (single)'!K4 -> 0.25303724 | L4: ='Proximal Validation (single)'!L4 -> 0.010736909 | M4: ='Proximal Validation (single)'!M4 -> 0.27653545 | N4: 0.49760943 | O4: 0.061329227 | P4: 0.91591914 | Q4: 0.66320843 | R4: 0.0013804237 | S4: =ABS(N4-A4) -> 0.097609434 | T4: =ABS(O4-B4) -> 0.078670773 | U4: =ABS(P4-C4) -> 0.65508086 | V4: =ABS(Q4-D4) -> 0.12179157 | Y4: =DEGREES(Y3) -> 14.958509 | Z4: =DEGREES(Z3) -> 23.668287 | AC4: 0.079210469 | AD4: 0.069390296 | AF4: =ABS(AC4-S4) -> 0.018398964 | AG4: =ABS(AD4-T4) -> 0.0092804767
A5: 0.6 | B5: 0.16 | C5: 1.571 | D5: 0.785 | E5: 1.4 | F5: 0 | G5: 0 | H5: ='Proximal Validation (single)'!H5 -> 0.0053234044 | I5: ='Proximal Validation (single)'!I5 -> -0.12275674 | J5: ='Proximal Validation (single)'!J5 -> -0.0083989212 | K5: ='Proximal Validation (single)'!K5 -> 0.26806161 | L5: ='Proximal Validation (single)'!L5 -> -0.024467468 | M5: ='Proximal Validation (single)'!M5 -> 0.5263381 | N5: 0.81133861 | O5: 0.19125554 | P5: 2.3250311 | Q5: 0.27594525 | R5: 0.0014122186 | S5: =ABS(N5-A5) -> 0.21133861 | T5: =ABS(O5-B5) -> 0.031255536 | U5: =ABS(P5-C5) -> 0.75403112 | V5: =ABS(Q5-D5) -> 0.50905475 | AC5: 0.043528818 | AD5: 0.027363474 | AF5: =ABS(AC5-S5) -> 0.16780979 | AG5: =ABS(AD5-T5) -> 0.003892062
A6: 0.4 | B6: 0.06 | C6: 1.571 | D6: 1.571 | E6: 1.4 | F6: 0 | G6: 0 | H6: ='Proximal Validation (single)'!H6 -> 0.00067002582 | I6: ='Proximal Validation (single)'!I6 -> -0.066750191 | J6: ='Proximal Validation (single)'!J6 -> 0.0016002768 | K6: ='Proximal Validation (single)'!K6 -> -0.039701398 | L6: ='Proximal Validation (single)'!L6 -> 0.0073561743 | M6: ='Proximal Validation (single)'!M6 -> 0.42381418 | N6: 0.48793984 | O6: 0.049498427 | P6: 1.4339249 | Q6: 1.7433202 | R6: 0.00034942065 | S6: =ABS(N6-A6) -> 0.087939836 | T6: =ABS(O6-B6) -> 0.010501573 | U6: =ABS(P6-C6) -> 0.13707514 | V6: =ABS(Q6-D6) -> 0.17232023 | W6: =AVERAGE(S3:S17) -> 0.13952986 | X6: =AVERAGE(T3:T17) -> 0.033652152 | Y6: =AVERAGE(U3:U17) -> 0.28194927 | Z6: =AVERAGE(V3:V17) -> 0.39917021 | AC6: 0.01619744 | AD6: 0.011557917 | AF6: =ABS(AC6-S6) -> 0.071742396 | AG6: =ABS(AD6-T6) -> 0.0010563443
A7: 0.8 | B7: 0.08 | C7: 1.571 | D7: 1.571 | E7: 0 | F7: 0 | G7: 0 | H7: ='Proximal Validation (single)'!H7 -> 0.00074092089 | I7: ='Proximal Validation (single)'!I7 -> -0.14775538 | J7: ='Proximal Validation (single)'!J7 -> 0.0034220633 | K7: ='Proximal Validation (single)'!K7 -> -0.16136234 | L7: ='Proximal Validation (single)'!L7 -> 0.020262048 | M7: ='Proximal Validation (single)'!M7 -> 0.82944489 | N7: 0.93802323 | O7: 0.066370584 | P7: 1.4369274 | Q7: 1.4045433 | R7: 0.00050375282 | S7: =ABS(N7-A7) -> 0.13802323 | T7: =ABS(O7-B7) -> 0.013629416 | U7: =ABS(P7-C7) -> 0.13407265 | V7: =ABS(Q7-D7) -> 0.16645674 | W7: =AVERAGE(S18:S32) -> 0.12109166 | X7: =AVERAGE(T18:T32) -> 0.039639296 | Y7: =AVERAGE(U18:U32) -> 0.23549518 | Z7: =AVERAGE(V18:V32) -> 0.43341014 | AC7: 0.027416615 | AD7: 0.01676518 | AF7: =ABS(AC7-S7) -> 0.11060662 | AG7: =ABS(AD7-T7) -> 0.0031357639
A8: 0.7 | B8: 0.16 | C8: 1.571 | D8: 1.571 | E8: 1.4 | F8: 0 | G8: 0 | H8: ='Proximal Validation (single)'!H8 -> 0.0066551082 | I8: ='Proximal Validation (single)'!I8 -> -0.1483079 | J8: ='Proximal Validation (single)'!J8 -> -0.0010527462 | K8: ='Proximal Validation (single)'!K8 -> -0.44470632 | L8: ='Proximal Validation (single)'!L8 -> -0.021994621 | M8: ='Proximal Validation (single)'!M8 -> 0.48979318 | N8: 0.7393213 | O8: 0.19692931 | P8: 1.6564444 | Q8: 1.6776827 | R8: 0.00048244429 | S8: =ABS(N8-A8) -> 0.039321298 | T8: =ABS(O8-B8) -> 0.036929312 | U8: =ABS(P8-C8) -> 0.085444369 | V8: =ABS(Q8-D8) -> 0.10668271 | AC8: 0.070230205 | AD8: 0.021730806 | AF8: =ABS(AC8-S8) -> 0.030908907 | AG8: =ABS(AD8-T8) -> 0.015198506
A9: 0.7 | B9: 0.2 | C9: 1.571 | D9: 1.571 | E9: 0 | F9: 0 | G9: 0 | H9: ='Proximal Validation (single)'!H9 -> 0.00087637117 | I9: ='Proximal Validation (single)'!I9 -> -0.16448845 | J9: ='Proximal Validation (single)'!J9 -> 0.0037763002 | K9: ='Proximal Validation (single)'!K9 -> -0.58729076 | L9: ='Proximal Validation (single)'!L9 -> 0.0078071319 | M9: ='Proximal Validation (single)'!M9 -> 0.38755593 | N9: 1 | O9: 0.19999942 | P9: 1.470877 | Q9: 2.2165654 | R9: 0.014074865 | S9: =ABS(N9-A9) -> 0.3 | T9: =ABS(O9-B9) -> 5.7746137e-07 | U9: =ABS(P9-C9) -> 0.10012301 | V9: =ABS(Q9-D9) -> 0.64556538 | AC9: 0.29999971 | AD9: 0.010572632 | AF9: =ABS(AC9-S9) -> 2.8335216e-07 | AG9: =ABS(AD9-T9) -> 0.010572055
A10: 0.7 | B10: 0.06 | C10: 3.665 | D10: 0.785 | E10: 0 | F10: 0 | G10: 0 | H10: ='Proximal Validation (single)'!H10 -> -0.00086323917 | I10: ='Proximal Validation (single)'!I10 -> 0.042902049 | J10: ='Proximal Validation (single)'!J10 -> -0.080319755 | K10: ='Proximal Validation (single)'!K10 -> 0.61245459 | L10: ='Proximal Validation (single)'!L10 -> -0.54026973 | M10: ='Proximal Validation (single)'!M10 -> -0.28817487 | N10: 0.9999946 | O10: 0.01776111 | P10: 3.5054643 | Q10: 0.88147801 | R10: 0.0010186517 | S10: =ABS(N10-A10) -> 0.2999946 | T10: =ABS(O10-B10) -> 0.04223889 | U10: =ABS(P10-C10) -> 0.15953573 | V10: =ABS(Q10-D10) -> 0.096478005 | AC10: 0.26161018 | AD10: 0.043213729 | AF10: =ABS(AC10-S10) -> 0.038384421 | AG10: =ABS(AD10-T10) -> 0.00097483838
A11: 0.6 | B11: 0.1 | C11: 3.665 | D11: 0.785 | E11: 0 | F11: 0 | G11: 0 | H11: ='Proximal Validation (single)'!H11 -> -0.00080120983 | I11: ='Proximal Validation (single)'!I11 -> 0.042666439 | J11: ='Proximal Validation (single)'!J11 -> -0.080293678 | K11: ='Proximal Validation (single)'!K11 -> 0.4433108 | L11: ='Proximal Validation (single)'!L11 -> -0.42717016 | M11: ='Proximal Validation (single)'!M11 -> -0.22529536 | N11: 0.62872721 | O11: 0.083069505 | P11: 3.3960182 | Q11: 1.0796318 | R11: 0.00039773548 | S11: =ABS(N11-A11) -> 0.028727213 | T11: =ABS(O11-B11) -> 0.016930495 | U11: =ABS(P11-C11) -> 0.26898176 | V11: =ABS(Q11-D11) -> 0.29463182 | AC11: 0.028503365 | AD11: 0.018536187 | AF11: =ABS(AC11-S11) -> 0.00022384891 | AG11: =ABS(AD11-T11) -> 0.0016056916
A12: 0.8 | B12: 0.18 | C12: 3.665 | D12: 0.785 | E12: 1.4 | F12: 0 | G12: 0 | H12: ='Proximal Validation (single)'!H12 -> -5.5334065e-05 | I12: ='Proximal Validation (single)'!I12 -> 0.077956624 | J12: ='Proximal Validation (single)'!J12 -> -0.13737398 | K12: ='Proximal Validation (single)'!K12 -> 0.41918036 | L12: ='Proximal Validation (single)'!L12 -> -0.5512532 | M12: ='Proximal Validation (single)'!M12 -> -0.30630308 | N12: 0.90136946 | O12: 0.19212421 | P12: 3.7666246 | Q12: 0.49104823 | R12: 0.00033932588 | S12: =ABS(N12-A12) -> 0.10136946 | T12: =ABS(O12-B12) -> 0.012124208 | U12: =ABS(P12-C12) -> 0.10162463 | V12: =ABS(Q12-D12) -> 0.29395177 | AC12: 0.10524212 | AD12: 3.9804993e-06 | AF12: =ABS(AC12-S12) -> 0.0038726513 | AG12: =ABS(AD12-T12) -> 0.012120227
A13: 0.4 | B13: 0.2 | C13: 3.665 | D13: 0.785 | E13: 1.4 | F13: 0 | G13: 0 | H13: ='Proximal Validation (single)'!H13 -> -9.6024014e-05 | I13: ='Proximal Validation (single)'!I13 -> 0.034424368 | J13: ='Proximal Validation (single)'!J13 -> -0.061656475 | K13: ='Proximal Validation (single)'!K13 -> 0.26709822 | L13: ='Proximal Validation (single)'!L13 -> -0.21448079 | M13: ='Proximal Validation (single)'!M13 -> -0.11506069 | N13: 0.38931034 | O13: 0.19570704 | P13: 3.6007064 | Q13: 0.6865197 | R13: 3.3771303e-05 | S13: =ABS(N13-A13) -> 0.010689659 | T13: =ABS(O13-B13) -> 0.0042929575 | U13: =ABS(P13-C13) -> 0.064293606 | V13: =ABS(Q13-D13) -> 0.098480303 | AC13: 0.030619864 | AD13: 0.0033305827 | AF13: =ABS(AC13-S13) -> 0.019930205 | AG13: =ABS(AD13-T13) -> 0.00096237482
A14: 0.4 | B14: 0.1 | C14: 3.665 | D14: 1.571 | E14: 1.4 | F14: 0 | G14: 0 | H14: ='Proximal Validation (single)'!H14 -> -0.00037108036 | I14: ='Proximal Validation (single)'!I14 -> 0.037644271 | J14: ='Proximal Validation (single)'!J14 -> -0.067399666 | K14: ='Proximal Validation (single)'!K14 -> 0.016782975 | L14: ='Proximal Validation (single)'!L14 -> -0.33880779 | M14: ='Proximal Validation (single)'!M14 -> -0.18529797 | N14: 0.68063333 | O14: 0.026908562 | P14: 2.4200511 | Q14: 2.7824325 | R14: 0.0039150892 | S14: =ABS(N14-A14) -> 0.28063333 | T14: =ABS(O14-B14) -> 0.073091438 | U14: =ABS(P14-C14) -> 1.2449489 | V14: =ABS(Q14-D14) -> 1.2114325 | AC14: 0.30379022 | AD14: 0.089909126 | AF14: =ABS(AC14-S14) -> 0.023156891 | AG14: =ABS(AD14-T14) -> 0.016817689
A15: 0.7 | B15: 0.1 | C15: 3.665 | D15: 1.571 | E15: 1.4 | F15: 0 | G15: 0 | H15: ='Proximal Validation (single)'!H15 -> -0.0010242919 | I15: ='Proximal Validation (single)'!I15 -> 0.070613205 | J15: ='Proximal Validation (single)'!J15 -> -0.12678832 | K15: ='Proximal Validation (single)'!K15 -> -0.029671347 | L15: ='Proximal Validation (single)'!L15 -> -0.63574088 | M15: ='Proximal Validation (single)'!M15 -> -0.34651768 | N15: 0.70367278 | O15: 0.11427229 | P15: 3.60355 | Q15: 1.3333255 | R15: 0.00045367125 | S15: =ABS(N15-A15) -> 0.0036727825 | T15: =ABS(O15-B15) -> 0.014272289 | U15: =ABS(P15-C15) -> 0.061449978 | V15: =ABS(Q15-D15) -> 0.23767449 | AC15: 0.060187773 | AD15: 0.017843237 | AF15: =ABS(AC15-S15) -> 0.05651499 | AG15: =ABS(AD15-T15) -> 0.0035709475
A16: 0.4 | B16: 0.16 | C16: 3.665 | D16: 1.571 | E16: 0 | F16: 0 | G16: 0 | H16: ='Proximal Validation (single)'!H16 -> -0.00060879067 | I16: ='Proximal Validation (single)'!I16 -> 0.047145899 | J16: ='Proximal Validation (single)'!J16 -> -0.085028917 | K16: ='Proximal Validation (single)'!K16 -> -0.074065492 | L16: ='Proximal Validation (single)'!L16 -> -0.3154611 | M16: ='Proximal Validation (single)'!M16 -> -0.17043319 | N16: 0.75782779 | O16: 0.061151189 | P16: 3.6535707 | Q16: 2.0811557 | R16: 1.338625e-05 | S16: =ABS(N16-A16) -> 0.35782779 | T16: =ABS(O16-B16) -> 0.098848811 | U16: =ABS(P16-C16) -> 0.011429273 | V16: =ABS(Q16-D16) -> 0.51015566 | AC16: 0.34849542 | AD16: 0.10350236 | AF16: =ABS(AC16-S16) -> 0.0093323683 | AG16: =ABS(AD16-T16) -> 0.0046535518
A17: 0.3 | B17: 0.18 | C17: 3.665 | D17: 1.571 | E17: 0 | F17: 0 | G17: 0 | H17: ='Proximal Validation (single)'!H17 -> 3.8368395e-05 | I17: ='Proximal Validation (single)'!I17 -> 0.032897148 | J17: ='Proximal Validation (single)'!J17 -> -0.058571801 | K17: ='Proximal Validation (single)'!K17 -> -0.063505612 | L17: ='Proximal Validation (single)'!L17 -> -0.19738522 | M17: ='Proximal Validation (single)'!M17 -> -0.10824893 | N17: 0.23386438 | O17: 0.19139693 | P17: 4.0624235 | Q17: 2.0409904 | R17: 0.00084812897 | S17: =ABS(N17-A17) -> 0.066135621 | T17: =ABS(O17-B17) -> 0.011396934 | U17: =ABS(P17-C17) -> 0.39742345 | V17: =ABS(Q17-D17) -> 0.46999037 | AC17: 0.05417561 | AD17: 0.000622851 | AF17: =ABS(AC17-S17) -> 0.011960011 | AG17: =ABS(AD17-T17) -> 0.010774083
A18: 0.3 | B18: 0.08 | C18: 1.571 | D18: 0.785 | E18: 1.4 | F18: 0 | G18: 0 | N18: 0.65070371 | O18: 0.010526078 | P18: 1.7923442 | Q18: 0.5532196 | R18: 0.00015094479 | S18: =ABS(N18-A18) -> 0.35070371 | T18: =ABS(O18-B18) -> 0.069473922 | U18: =ABS(P18-C18) -> 0.22134422 | V18: =ABS(Q18-D18) -> 0.2317804 | AC18: 0.35208469 | AD18: 0.069819711 | AF18: =ABS(AC18-S18) -> 0.0013809826 | AG18: =ABS(AD18-T18) -> 0.00034578909
A19: 0.4 | B19: 0.14 | C19: 1.571 | D19: 0.785 | E19: 0 | F19: 0 | G19: 0 | N19: 0.411109 | O19: 0.050599281 | P19: 2.000843 | Q19: 1.9921765 | R19: 0.0010582881 | S19: =ABS(N19-A19) -> 0.011109 | T19: =ABS(O19-B19) -> 0.089400719 | U19: =ABS(P19-C19) -> 0.42984296 | V19: =ABS(Q19-D19) -> 1.2071765 | AC19: 0.057469321 | AD19: 0.088495493 | AF19: =ABS(AC19-S19) -> 0.046360321 | AG19: =ABS(AD19-T19) -> 0.00090522635
A20: 0.6 | B20: 0.16 | C20: 1.571 | D20: 0.785 | E20: 1.4 | F20: 0 | G20: 0 | N20: 0.5317451 | O20: 0.19994663 | P20: 1.7930801 | Q20: 0.49683736 | R20: 0.0008567391 | S20: =ABS(N20-A20) -> 0.068254901 | T20: =ABS(O20-B20) -> 0.039946627 | U20: =ABS(P20-C20) -> 0.22208014 | V20: =ABS(Q20-D20) -> 0.28816264 | AC20: 0.1448482 | AD20: 0.039993774 | AF20: =ABS(AC20-S20) -> 0.076593299 | AG20: =ABS(AD20-T20) -> 4.7147087e-05
A21: 0.4 | B21: 0.06 | C21: 1.571 | D21: 1.571 | E21: 1.4 | F21: 0 | G21: 0 | N21: 0.47308479 | O21: 0.075205951 | P21: 1.6950059 | Q21: 0.97504984 | R21: 0.00046527806 | S21: =ABS(N21-A21) -> 0.07308479 | T21: =ABS(O21-B21) -> 0.015205951 | U21: =ABS(P21-C21) -> 0.12400595 | V21: =ABS(Q21-D21) -> 0.59595016 | AC21: 0.019310561 | AD21: 0.011297682 | AF21: =ABS(AC21-S21) -> 0.053774229 | AG21: =ABS(AD21-T21) -> 0.0039082691
A22: 0.8 | B22: 0.08 | C22: 1.571 | D22: 1.571 | E22: 0 | F22: 0 | G22: 0 | N22: 0.99999999 | O22: 0.054818442 | P22: 1.4335684 | Q22: 1.8000005 | R22: 0.0052476995 | S22: =ABS(N22-A22) -> 0.19999999 | T22: =ABS(O22-B22) -> 0.025181558 | U22: =ABS(P22-C22) -> 0.1374316 | V22: =ABS(Q22-D22) -> 0.22900051 | AC22: 0.12324619 | AD22: 0.04100802 | AF22: =ABS(AC22-S22) -> 0.076753809 | AG22: =ABS(AD22-T22) -> 0.015826462
A23: 0.7 | B23: 0.16 | C23: 1.571 | D23: 1.571 | E23: 1.4 | F23: 0 | G23: 0 | N23: 0.5198007 | O23: 0.19994296 | P23: 1.5741435 | Q23: 0.86743186 | R23: 0.00098796764 | S23: =ABS(N23-A23) -> 0.1801993 | T23: =ABS(O23-B23) -> 0.039942957 | U23: =ABS(P23-C23) -> 0.0031435217 | V23: =ABS(Q23-D23) -> 0.70356814 | AC23: 0.33873975 | AD23: 0.039999814 | AF23: =ABS(AC23-S23) -> 0.15854045 | AG23: =ABS(AD23-T23) -> 5.6856919e-05
A24: 0.7 | B24: 0.2 | C24: 1.571 | D24: 1.571 | E24: 0 | F24: 0 | G24: 0 | N24: 0.66985467 | O24: 0.19999999 | P24: 1.8934478 | Q24: 2.2598348 | R24: 0.0079023621 | S24: =ABS(N24-A24) -> 0.030145329 | T24: =ABS(O24-B24) -> 1.1863995e-08 | U24: =ABS(P24-C24) -> 0.32244775 | V24: =ABS(Q24-D24) -> 0.68883482 | AC24: 0.032858836 | AD24: 0.19 | AF24: =ABS(AC24-S24) -> 0.0027135075 | AG24: =ABS(AD24-T24) -> 0.18999999
A25: 0.7 | B25: 0.06 | C25: 3.665 | D25: 0.785 | E25: 0 | F25: 0 | G25: 0 | N25: 0.59615178 | O25: 0.11781635 | P25: 3.9603789 | Q25: 0.78772279 | R25: 0.0010840807 | S25: =ABS(N25-A25) -> 0.10384822 | T25: =ABS(O25-B25) -> 0.057816353 | U25: =ABS(P25-C25) -> 0.29537891 | V25: =ABS(Q25-D25) -> 0.0027227948 | AC25: 0.15317642 | AD25: 0.06009237 | AF25: =ABS(AC25-S25) -> 0.049328201 | AG25: =ABS(AD25-T25) -> 0.0022760162
A26: 0.6 | B26: 0.1 | C26: 3.665 | D26: 0.785 | E26: 0 | F26: 0 | G26: 0 | N26: 0.75435681 | O26: 0.10853339 | P26: 3.40629 | Q26: 0.54553291 | R26: 0.00078904984 | S26: =ABS(N26-A26) -> 0.15435681 | T26: =ABS(O26-B26) -> 0.0085333928 | U26: =ABS(P26-C26) -> 0.25871001 | V26: =ABS(Q26-D26) -> 0.23946709 | AC26: 0.09870144 | AD26: 0.015184338 | AF26: =ABS(AC26-S26) -> 0.055655369 | AG26: =ABS(AD26-T26) -> 0.0066509452
A27: 0.8 | B27: 0.18 | C27: 3.665 | D27: 0.785 | E27: 1.4 | F27: 0 | G27: 0 | N27: 0.82826825 | O27: 0.12471051 | P27: 3.5992341 | Q27: 1.0199881 | R27: 0.0007442676 | S27: =ABS(N27-A27) -> 0.028268246 | T27: =ABS(O27-B27) -> 0.055289493 | U27: =ABS(P27-C27) -> 0.065765873 | V27: =ABS(Q27-D27) -> 0.2349881 | AC27: 0.098472201 | AD27: 0.069236063 | AF27: =ABS(AC27-S27) -> 0.070203955 | AG27: =ABS(AD27-T27) -> 0.01394657
A28: 0.4 | B28: 0.2 | C28: 3.665 | D28: 0.785 | E28: 1.4 | F28: 0 | G28: 0 | N28: 0.61162715 | O28: 0.19841746 | P28: 3.2420643 | Q28: 0.28109668 | R28: 0.0013479842 | S28: =ABS(N28-A28) -> 0.21162715 | T28: =ABS(O28-B28) -> 0.0015825388 | U28: =ABS(P28-C28) -> 0.42293573 | V28: =ABS(Q28-D28) -> 0.50390332 | AC28: 0.14549785 | AD28: 1.6200188e-05 | AF28: =ABS(AC28-S28) -> 0.066129295 | AG28: =ABS(AD28-T28) -> 0.0015663386
A29: 0.4 | B29: 0.1 | C29: 3.665 | D29: 1.571 | E29: 1.4 | F29: 0 | G29: 0 | N29: 0.41176321 | O29: 0.11497844 | P29: 3.4927294 | Q29: 1.2864985 | R29: 0.00010413455 | S29: =ABS(N29-A29) -> 0.011763213 | T29: =ABS(O29-B29) -> 0.014978439 | U29: =ABS(P29-C29) -> 0.17227065 | V29: =ABS(Q29-D29) -> 0.28450146 | AC29: 0.045521641 | AD29: 0.017416819 | AF29: =ABS(AC29-S29) -> 0.033758428 | AG29: =ABS(AD29-T29) -> 0.00243838
... A152: 0.3 | B152: 0.18 | C152: 3.665 | D152: 1.571 | E152: 0 | F152: 0 | G152: 0 | N152: 0.26330253 | O152: 0.15973049 | P152: 3.8471753 | Q152: 1.3195334 | R152: 0.00012309724 | S152: =ABS(N152-A152) -> 0.036697467 | T152: =ABS(O152-B152) -> 0.020269511 | U152: =ABS(P152-C152) -> 0.18217532 | V152: =ABS(Q152-D152) -> 0.25146663 | AC152: 0.068296306 | AD152: 0.0056073121 | AF152: =ABS(AC152-S152) -> 0.031598838 | AG152: =ABS(AD152-T152) -> 0.014662199

Sheet Distal Vali (noise 0.5x spec 2)
A1: σ = [0, 0.003125, 0, 0.150, 0, 0]
A2: Ground Truth | H2: 6-Axis FT Sensor | N2: SoRoSim get_distal_value | S2: Distal Errors | W2: Mean Average Error
A3: F (N) | B3: s (m) | C3: roll (rad) | D3: pitch (deg) | E3: tau1 (N) | F3: tau2 (N) | G3: tau3 (N) | H3: Tx (Nm) | I3: Ty (Nm) | J3: Tz(Nm) | K3: Fx (N) | L3: Fy (N) | M3: Fz (N) | N3: F (N) | O3: s (m) | P3: roll (rad) | Q3: pitch (deg) | R3: f_final | S3: Force Error | T3: Position Error | U3: Roll Error | V3: Pitch Error | W3: Force Error | X3: Position Error | Y3: Roll Error | Z3: Pitch Error
A4: 0.3 | B4: 0.08 | C4: 1.571 | D4: 0.785 | E4: 1.4 | F4: 0 | G4: 0 | H4: ='Proximal Validation (single)'!H3 -> 0.00026342465 | I4: ='Proximal Validation (single)'!I3 -> -0.032978263 | J4: ='Proximal Validation (single)'!J3 -> 0.00056162861 | K4: ='Proximal Validation (single)'!K3 -> 0.18583472 | L4: ='Proximal Validation (single)'!L3 -> 0.0011325702 | M4: ='Proximal Validation (single)'!M3 -> 0.19288233 | S4: =ABS(N4-A4) -> 0.3 | T4: =ABS(O4-B4) -> 0.08 | U4: =ABS(P4-C4) -> 1.571 | V4: =ABS(Q4-D4) -> 0.785 | W4: =AVERAGE(S4:S78) -> 0.54666667 | X4: =AVERAGE(T4:T78) -> 0.13066667 | Y4: =AVERAGE(U4:U78) -> 2.6878 | Z4: =AVERAGE(V4:V78) -> 1.2042
A5: 0.4 | B5: 0.14 | C5: 1.571 | D5: 0.785 | E5: 0 | F5: 0 | G5: 0 | H5: ='Proximal Validation (single)'!H4 -> -0.00043474312 | I5: ='Proximal Validation (single)'!I4 -> -0.062425632 | J5: ='Proximal Validation (single)'!J4 -> 0.0025845002 | K5: ='Proximal Validation (single)'!K4 -> 0.25303724 | L5: ='Proximal Validation (single)'!L4 -> 0.010736909 | M5: ='Proximal Validation (single)'!M4 -> 0.27653545 | S5: =ABS(N5-A5) -> 0.4 | T5: =ABS(O5-B5) -> 0.14 | U5: =ABS(P5-C5) -> 1.571 | V5: =ABS(Q5-D5) -> 0.785 | Y5: =DEGREES(Y4) -> 153.9996 | Z5: =DEGREES(Z4) -> 68.995578
A6: 0.6 | B6: 0.16 | C6: 1.571 | D6: 0.785 | E6: 1.4 | F6: 0 | G6: 0 | H6: ='Proximal Validation (single)'!H5 -> 0.0053234044 | I6: ='Proximal Validation (single)'!I5 -> -0.12275674 | J6: ='Proximal Validation (single)'!J5 -> -0.0083989212 | K6: ='Proximal Validation (single)'!K5 -> 0.26806161 | L6: ='Proximal Validation (single)'!L5 -> -0.024467468 | M6: ='Proximal Validation (single)'!M5 -> 0.5263381 | S6: =ABS(N6-A6) -> 0.6 | T6: =ABS(O6-B6) -> 0.16 | U6: =ABS(P6-C6) -> 1.571 | V6: =ABS(Q6-D6) -> 0.785
A7: 0.4 | B7: 0.06 | C7: 1.571 | D7: 1.571 | E7: 1.4 | F7: 0 | G7: 0 | H7: ='Proximal Validation (single)'!H6 -> 0.00067002582 | I7: ='Proximal Validation (single)'!I6 -> -0.066750191 | J7: ='Proximal Validation (single)'!J6 -> 0.0016002768 | K7: ='Proximal Validation (single)'!K6 -> -0.039701398 | L7: ='Proximal Validation (single)'!L6 -> 0.0073561743 | M7: ='Proximal Validation (single)'!M6 -> 0.42381418 | S7: =ABS(N7-A7) -> 0.4 | T7: =ABS(O7-B7) -> 0.06 | U7: =ABS(P7-C7) -> 1.571 | V7: =ABS(Q7-D7) -> 1.571
A8: 0.8 | B8: 0.08 | C8: 1.571 | D8: 1.571 | E8: 0 | F8: 0 | G8: 0 | H8: ='Proximal Validation (single)'!H7 -> 0.00074092089 | I8: ='Proximal Validation (single)'!I7 -> -0.14775538 | J8: ='Proximal Validation (single)'!J7 -> 0.0034220633 | K8: ='Proximal Validation (single)'!K7 -> -0.16136234 | L8: ='Proximal Validation (single)'!L7 -> 0.020262048 | M8: ='Proximal Validation (single)'!M7 -> 0.82944489 | S8: =ABS(N8-A8) -> 0.8 | T8: =ABS(O8-B8) -> 0.08 | U8: =ABS(P8-C8) -> 1.571 | V8: =ABS(Q8-D8) -> 1.571
A9: 0.7 | B9: 0.16 | C9: 1.571 | D9: 1.571 | E9: 1.4 | F9: 0 | G9: 0 | H9: ='Proximal Validation (single)'!H8 -> 0.0066551082 | I9: ='Proximal Validation (single)'!I8 -> -0.1483079 | J9: ='Proximal Validation (single)'!J8 -> -0.0010527462 | K9: ='Proximal Validation (single)'!K8 -> -0.44470632 | L9: ='Proximal Validation (single)'!L8 -> -0.021994621 | M9: ='Proximal Validation (single)'!M8 -> 0.48979318 | S9: =ABS(N9-A9) -> 0.7 | T9: =ABS(O9-B9) -> 0.16 | U9: =ABS(P9-C9) -> 1.571 | V9: =ABS(Q9-D9) -> 1.571
A10: 0.7 | B10: 0.2 | C10: 1.571 | D10: 1.571 | E10: 0 | F10: 0 | G10: 0 | H10: ='Proximal Validation (single)'!H9 -> 0.00087637117 | I10: ='Proximal Validation (single)'!I9 -> -0.16448845 | J10: ='Proximal Validation (single)'!J9 -> 0.0037763002 | K10: ='Proximal Validation (single)'!K9 -> -0.58729076 | L10: ='Proximal Validation (single)'!L9 -> 0.0078071319 | M10: ='Proximal Validation (single)'!M9 -> 0.38755593 | S10: =ABS(N10-A10) -> 0.7 | T10: =ABS(O10-B10) -> 0.2 | U10: =ABS(P10-C10) -> 1.571 | V10: =ABS(Q10-D10) -> 1.571
A11: 0.7 | B11: 0.06 | C11: 3.665 | D11: 0.785 | E11: 0 | F11: 0 | G11: 0 | H11: ='Proximal Validation (single)'!H10 -> -0.00086323917 | I11: ='Proximal Validation (single)'!I10 -> 0.042902049 | J11: ='Proximal Validation (single)'!J10 -> -0.080319755 | K11: ='Proximal Validation (single)'!K10 -> 0.61245459 | L11: ='Proximal Validation (single)'!L10 -> -0.54026973 | M11: ='Proximal Validation (single)'!M10 -> -0.28817487 | S11: =ABS(N11-A11) -> 0.7 | T11: =ABS(O11-B11) -> 0.06 | U11: =ABS(P11-C11) -> 3.665 | V11: =ABS(Q11-D11) -> 0.785
A12: 0.6 | B12: 0.1 | C12: 3.665 | D12: 0.785 | E12: 0 | F12: 0 | G12: 0 | H12: ='Proximal Validation (single)'!H11 -> -0.00080120983 | I12: ='Proximal Validation (single)'!I11 -> 0.042666439 | J12: ='Proximal Validation (single)'!J11 -> -0.080293678 | K12: ='Proximal Validation (single)'!K11 -> 0.4433108 | L12: ='Proximal Validation (single)'!L11 -> -0.42717016 | M12: ='Proximal Validation (single)'!M11 -> -0.22529536 | S12: =ABS(N12-A12) -> 0.6 | T12: =ABS(O12-B12) -> 0.1 | U12: =ABS(P12-C12) -> 3.665 | V12: =ABS(Q12-D12) -> 0.785
A13: 0.8 | B13: 0.18 | C13: 3.665 | D13: 0.785 | E13: 1.4 | F13: 0 | G13: 0 | H13: ='Proximal Validation (single)'!H12 -> -5.5334065e-05 | I13: ='Proximal Validation (single)'!I12 -> 0.077956624 | J13: ='Proximal Validation (single)'!J12 -> -0.13737398 | K13: ='Proximal Validation (single)'!K12 -> 0.41918036 | L13: ='Proximal Validation (single)'!L12 -> -0.5512532 | M13: ='Proximal Validation (single)'!M12 -> -0.30630308 | S13: =ABS(N13-A13) -> 0.8 | T13: =ABS(O13-B13) -> 0.18 | U13: =ABS(P13-C13) -> 3.665 | V13: =ABS(Q13-D13) -> 0.785
A14: 0.4 | B14: 0.2 | C14: 3.665 | D14: 0.785 | E14: 1.4 | F14: 0 | G14: 0 | H14: ='Proximal Validation (single)'!H13 -> -9.6024014e-05 | I14: ='Proximal Validation (single)'!I13 -> 0.034424368 | J14: ='Proximal Validation (single)'!J13 -> -0.061656475 | K14: ='Proximal Validation (single)'!K13 -> 0.26709822 | L14: ='Proximal Validation (single)'!L13 -> -0.21448079 | M14: ='Proximal Validation (single)'!M13 -> -0.11506069 | S14: =ABS(N14-A14) -> 0.4 | T14: =ABS(O14-B14) -> 0.2 | U14: =ABS(P14-C14) -> 3.665 | V14: =ABS(Q14-D14) -> 0.785
A15: 0.4 | B15: 0.1 | C15: 3.665 | D15: 1.571 | E15: 1.4 | F15: 0 | G15: 0 | H15: ='Proximal Validation (single)'!H14 -> -0.00037108036 | I15: ='Proximal Validation (single)'!I14 -> 0.037644271 | J15: ='Proximal Validation (single)'!J14 -> -0.067399666 | K15: ='Proximal Validation (single)'!K14 -> 0.016782975 | L15: ='Proximal Validation (single)'!L14 -> -0.33880779 | M15: ='Proximal Validation (single)'!M14 -> -0.18529797 | S15: =ABS(N15-A15) -> 0.4 | T15: =ABS(O15-B15) -> 0.1 | U15: =ABS(P15-C15) -> 3.665 | V15: =ABS(Q15-D15) -> 1.571
A16: 0.7 | B16: 0.1 | C16: 3.665 | D16: 1.571 | E16: 1.4 | F16: 0 | G16: 0 | H16: ='Proximal Validation (single)'!H15 -> -0.0010242919 | I16: ='Proximal Validation (single)'!I15 -> 0.070613205 | J16: ='Proximal Validation (single)'!J15 -> -0.12678832 | K16: ='Proximal Validation (single)'!K15 -> -0.029671347 | L16: ='Proximal Validation (single)'!L15 -> -0.63574088 | M16: ='Proximal Validation (single)'!M15 -> -0.34651768 | S16: =ABS(N16-A16) -> 0.7 | T16: =ABS(O16-B16) -> 0.1 | U16: =ABS(P16-C16) -> 3.665 | V16: =ABS(Q16-D16) -> 1.571
A17: 0.4 | B17: 0.16 | C17: 3.665 | D17: 1.571 | E17: 0 | F17: 0 | G17: 0 | H17: ='Proximal Validation (single)'!H16 -> -0.00060879067 | I17: ='Proximal Validation (single)'!I16 -> 0.047145899 | J17: ='Proximal Validation (single)'!J16 -> -0.085028917 | K17: ='Proximal Validation (single)'!K16 -> -0.074065492 | L17: ='Proximal Validation (single)'!L16 -> -0.3154611 | M17: ='Proximal Validation (single)'!M16 -> -0.17043319 | S17: =ABS(N17-A17) -> 0.4 | T17: =ABS(O17-B17) -> 0.16 | U17: =ABS(P17-C17) -> 3.665 | V17: =ABS(Q17-D17) -> 1.571
A18: 0.3 | B18: 0.18 | C18: 3.665 | D18: 1.571 | E18: 0 | F18: 0 | G18: 0 | H18: ='Proximal Validation (single)'!H17 -> 3.8368395e-05 | I18: ='Proximal Validation (single)'!I17 -> 0.032897148 | J18: ='Proximal Validation (single)'!J17 -> -0.058571801 | K18: ='Proximal Validation (single)'!K17 -> -0.063505612 | L18: ='Proximal Validation (single)'!L17 -> -0.19738522 | M18: ='Proximal Validation (single)'!M17 -> -0.10824893 | S18: =ABS(N18-A18) -> 0.3 | T18: =ABS(O18-B18) -> 0.18 | U18: =ABS(P18-C18) -> 3.665 | V18: =ABS(Q18-D18) -> 1.571
A19: 0.3 | B19: 0.08 | C19: 1.571 | D19: 0.785 | E19: 1.4 | F19: 0 | G19: 0 | S19: =ABS(N19-A19) -> 0.3 | T19: =ABS(O19-B19) -> 0.08 | U19: =ABS(P19-C19) -> 1.571 | V19: =ABS(Q19-D19) -> 0.785
A20: 0.4 | B20: 0.14 | C20: 1.571 | D20: 0.785 | E20: 0 | F20: 0 | G20: 0 | S20: =ABS(N20-A20) -> 0.4 | T20: =ABS(O20-B20) -> 0.14 | U20: =ABS(P20-C20) -> 1.571 | V20: =ABS(Q20-D20) -> 0.785
A21: 0.6 | B21: 0.16 | C21: 1.571 | D21: 0.785 | E21: 1.4 | F21: 0 | G21: 0 | S21: =ABS(N21-A21) -> 0.6 | T21: =ABS(O21-B21) -> 0.16 | U21: =ABS(P21-C21) -> 1.571 | V21: =ABS(Q21-D21) -> 0.785
