Workbook

Sheet get_proximal_value Validation
G2: 6-Axis FT Sensor | N2: SoRoSim get_proximal_value(with tendon lookup) | AB2: Conversion
A3: F (N) | B3: s (m) | C3: el (rad) | D3: az (rad) | E3: pre tau (N) | F3: tau (N) | G3: Tx (Nm) | H3: Ty (Nm) | I3: Tz(Nm) | J3: Fx (N) | K3: Fy (N) | L3: Fz (N) | M3: Tau (N) | N3: Tx (Nm) | O3: Ty (Nm) | P3: Tz(Nm) | Q3: Fx (N) | R3: Fy (N) | S3: Fz (N) | T3: Tau (N) | AB3: Tx is Tz(col G) | AC3: Ty is -Ty(col F) | AD3: Tz is Tx(col E) | AE3: Fx is Fz(col D) | AF3: Fy is -Fy(col C) | AG3: Fz is Fx (col B)
A4: 0.14182976 | B4: 0.0720242 | C4: 0 | D4: -0.91174491 | E4: 0.30351324 | F4: 0.304 | G4: -0.00091163395 | H4: -0.00108513 | I4: -0.0025136897 | J4: -0.1970371 | K4: -0.1292484 | L4: 0.0084088072 | M4: 0.304 | N4: -0.0002835952 | O4: 9.35023e-05 | P4: -0.0010362583 | Q4: -0.2070441 | R4: -0.11330786 | S4: 0.0023606159 | T4: -0.311 | U4: =ABS(G4-N4) -> 0.00062803875 | V4: =ABS(H4-O4) -> 0.0011786323 | W4: =ABS(I4-P4) -> 0.0014774314 | X4: =ABS(J4-Q4) -> 0.010007001 | Y4: =ABS(K4-R4) -> 0.015940534 | Z4: =ABS(L4-S4) -> 0.0060481913 | AB4: [ATI_Sensor_Log(2.0to1.0).csv]ATI_Sensor_Log(2.0to1.0)'!$G2 | AC4: -1*'[ATI_Sensor_Log(2.0to1.0).csv]ATI_Sensor_Log(2.0to1.0)'!$F2' | AD4: [ATI_Sensor_Log(2.0to1.0).csv]ATI_Sensor_Log(2.0to1.0)'!$E2 | AF4: -1*'[ATI_Sensor_Log(2.0to1.0).csv]ATI_Sensor_Log(2.0to1.0)'!$C2' | AG4: [ATI_Sensor_Log(2.0to1.0).csv]ATI_Sensor_Log(2.0to1.0)'!$B2
A5: 0.60745837 | B5: 0.09706437 | C5: 0 | D5: 1.7524402 | E5: 0.57808471 | F5: 0.378 | G5: 0.00057326164 | H5: -0.00084196427 | I5: 0.072134018 | J5: -0.55127585 | K5: 0.51616353 | L5: 0.017094016 | M5: 0.378 | N5: -0.0003516309 | O5: 0.0001116527 | P5: 0.072870909 | Q5: -0.58514474 | R5: 0.56133963 | S5: 0.002899454 | T5: -0.378 | U5: =ABS(G5-N5) -> 0.00092489254 | V5: =ABS(H5-O5) -> 0.00095361697 | W5: =ABS(I5-P5) -> 0.00073689086 | X5: =ABS(J5-Q5) -> 0.033868888 | Y5: =ABS(K5-R5) -> 0.0451761 | Z5: =ABS(L5-S5) -> 0.014194562 | AB5: ='[1]ATI_Sensor_Log(2.0to1.0)'!$G2 -> 0 | AC5: =-1*'[1]ATI_Sensor_Log(2.0to1.0)'!$F2 -> 0 | AD5: ='[1]ATI_Sensor_Log(2.0to1.0)'!$E2 -> 0 | AE5: ='[1]ATI_Sensor_Log(2.0to1.0)'!$D2 -> 0 | AF5: =-1*'[1]ATI_Sensor_Log(2.0to1.0)'!$C2 -> 0 | AG5: ='[1]ATI_Sensor_Log(2.0to1.0)'!$B2 -> 0
A6: 0.88365584 | B6: 0.05400872 | C6: 0 | D6: -0.91161608 | E6: 0.57138001 | F6: 0.617 | G6: -0.0023927321 | H6: -0.0034488118 | I6: -0.026666744 | J6: -0.028852019 | K6: -0.67019284 | L6: 0.034370363 | M6: 0.617 | N6: -0.0004682635 | O6: 0.0001427676 | P6: -0.032085328 | Q6: 0.05924615 | R6: -0.70716975 | S6: 0.0038231764 | T6: -0.502 | U6: =ABS(G6-N6) -> 0.0019244686 | V6: =ABS(H6-O6) -> 0.0035915794 | W6: =ABS(I6-P6) -> 0.0054185841 | X6: =ABS(J6-Q6) -> 0.08809817 | Y6: =ABS(K6-R6) -> 0.036976908 | Z6: =ABS(L6-S6) -> 0.030547186 | AB6: ='[1]ATI_Sensor_Log(2.0to1.0)'!$G3 -> 0 | AC6: =-1*'[1]ATI_Sensor_Log(2.0to1.0)'!$F3 -> 0 | AD6: ='[1]ATI_Sensor_Log(2.0to1.0)'!$E3 -> 0 | AE6: ='[1]ATI_Sensor_Log(2.0to1.0)'!$D3 -> 0 | AF6: =-1*'[1]ATI_Sensor_Log(2.0to1.0)'!$C3 -> 0 | AG6: ='[1]ATI_Sensor_Log(2.0to1.0)'!$B3 -> 0
A7: 0.09252606 | B7: 0.07631133 | C7: 0 | D7: -1.8008197 | E7: 0.20000874 | F7: 0.21 | G7: -0.00044885097 | H7: -0.00013324013 | I7: -0.0035143313 | J7: -0.22372764 | K7: -0.10044436 | L7: 0.006375704 | M7: 0.21 | N7: -0.0001572432 | O7: 5.97944e-05 | P7: -0.0031501951 | Q7: -0.19244806 | R7: -0.091929783 | S7: 0.0013599166 | T7: -0.178 | U7: =ABS(G7-N7) -> 0.00029160777 | V7: =ABS(H7-O7) -> 0.00019303453 | W7: =ABS(I7-P7) -> 0.0003641362 | X7: =ABS(J7-Q7) -> 0.031279582 | Y7: =ABS(K7-R7) -> 0.0085145784 | Z7: =ABS(L7-S7) -> 0.0050157874 | AB7: ='[1]ATI_Sensor_Log(2.0to1.0)'!$G4 -> 0 | AC7: =-1*'[1]ATI_Sensor_Log(2.0to1.0)'!$F4 -> 0 | AD7: ='[1]ATI_Sensor_Log(2.0to1.0)'!$E4 -> 0 | AE7: ='[1]ATI_Sensor_Log(2.0to1.0)'!$D4 -> 0 | AF7: =-1*'[1]ATI_Sensor_Log(2.0to1.0)'!$C4 -> 0 | AG7: ='[1]ATI_Sensor_Log(2.0to1.0)'!$B4 -> 0
A8: 0.26582482 | B8: 0.11576127 | C8: 0 | D8: 1.628884 | E8: 0.56468087 | F8: 0.43 | G8: 0.00039714668 | H8: -0.0008116056 | I8: 0.045337979 | J8: -0.44326165 | K8: 0.2432449 | L8: 0.014269143 | M8: 0.43 | N8: -0.0004002278 | O8: 0.0001246172 | P8: 0.044657178 | Q8: -0.47485988 | R8: 0.25410778 | S8: 0.0032843383 | T8: -0.43 | U8: =ABS(G8-N8) -> 0.00079737448 | V8: =ABS(H8-O8) -> 0.0009362228 | W8: =ABS(I8-P8) -> 0.00068080105 | X8: =ABS(J8-Q8) -> 0.031598223 | Y8: =ABS(K8-R8) -> 0.010862877 | Z8: =ABS(L8-S8) -> 0.010984805 | AB8: ='[1]ATI_Sensor_Log(2.0to1.0)'!$G5 -> 0 | AC8: =-1*'[1]ATI_Sensor_Log(2.0to1.0)'!$F5 -> 0 | AD8: ='[1]ATI_Sensor_Log(2.0to1.0)'!$E5 -> 0 | AE8: ='[1]ATI_Sensor_Log(2.0to1.0)'!$D5 -> 0 | AF8: =-1*'[1]ATI_Sensor_Log(2.0to1.0)'!$C5 -> 0 | AG8: ='[1]ATI_Sensor_Log(2.0to1.0)'!$B5 -> 0
A9: 0.45 | B9: 0.17373299 | C9: 0 | D9: -2.0085329 | E9: 0.2667928 | F9: 0.768 | G9: -0.0028824871 | H9: -0.0026444176 | I9: -0.055171221 | J9: -0.96715474 | K9: -0.3389644 | L9: 0.043315858 | M9: 0.768 | N9: -0.0007306868 | O9: 0.0002127763 | P9: -0.05675508 | Q9: -0.94569726 | R9: -0.40452304 | S9: 0.0059015519 | T9: -0.768 | U9: =ABS(G9-N9) -> 0.0021518003 | V9: =ABS(H9-O9) -> 0.0028571939 | W9: =ABS(I9-P9) -> 0.0015838587 | X9: =ABS(J9-Q9) -> 0.021457481 | Y9: =ABS(K9-R9) -> 0.065558639 | Z9: =ABS(L9-S9) -> 0.037414306 | AB9: ='[1]ATI_Sensor_Log(2.0to1.0)'!$G6 -> 0 | AC9: =-1*'[1]ATI_Sensor_Log(2.0to1.0)'!$F6 -> 0 | AD9: ='[1]ATI_Sensor_Log(2.0to1.0)'!$E6 -> 0 | AE9: ='[1]ATI_Sensor_Log(2.0to1.0)'!$D6 -> 0 | AF9: =-1*'[1]ATI_Sensor_Log(2.0to1.0)'!$C6 -> 0 | AG9: ='[1]ATI_Sensor_Log(2.0to1.0)'!$B6 -> 0
A10: 0.17540121 | B10: 0.14381803 | C10: 0 | D10: -1.1118403 | E10: 0.38917187 | F10: 0.497 | G10: -0.0014106487 | H10: -0.0025641322 | I10: -0.011485542 | J10: -0.36418968 | K10: -0.14991148 | L10: 0.021329515 | M10: 0.497 | N10: -0.0004682635 | O10: 0.0001427676 | P10: -0.010207614 | Q10: -0.38892716 | R10: -0.155645 | S10: 0.0038231764 | T10: -0.497 | U10: =ABS(G10-N10) -> 0.00094238519 | V10: =ABS(H10-O10) -> 0.0027068998 | W10: =ABS(I10-P10) -> 0.0012779287 | X10: =ABS(J10-Q10) -> 0.02473748 | Y10: =ABS(K10-R10) -> 0.0057335245 | Z10: =ABS(L10-S10) -> 0.017506338 | AB10: ='[1]ATI_Sensor_Log(2.0to1.0)'!$G7 -> 0 | AC10: =-1*'[1]ATI_Sensor_Log(2.0to1.0)'!$F7 -> 0 | AD10: ='[1]ATI_Sensor_Log(2.0to1.0)'!$E7 -> 0 | AE10: ='[1]ATI_Sensor_Log(2.0to1.0)'!$D7 -> 0 | AF10: =-1*'[1]ATI_Sensor_Log(2.0to1.0)'!$C7 -> 0 | AG10: ='[1]ATI_Sensor_Log(2.0to1.0)'!$B7 -> 0
A11: 0.91138323 | B11: 0.10326727 | C11: 0 | D11: -2.1051698 | E11: 0.01130865 | F11: 0.23 | G11: -0.0020074253 | H11: -0.00045337807 | I11: -0.078970164 | J11: -0.77051401 | K11: -0.66304511 | L11: 0.044688791 | M11: 0.23 | N11: -0.0002058401 | O11: 7.27589e-05 | P11: -0.079263196 | Q11: -0.80579254 | R11: -0.69916631 | S11: 0.0017448009 | T11: -0.23 | U11: =ABS(G11-N11) -> 0.0018015852 | V11: =ABS(H11-O11) -> 0.00052613697 | W11: =ABS(I11-P11) -> 0.00029303174 | X11: =ABS(J11-Q11) -> 0.035278529 | Y11: =ABS(K11-R11) -> 0.036121204 | Z11: =ABS(L11-S11) -> 0.04294399 | AB11: ='[1]ATI_Sensor_Log(2.0to1.0)'!$G8 -> 0 | AC11: =-1*'[1]ATI_Sensor_Log(2.0to1.0)'!$F8 -> 0 | AD11: ='[1]ATI_Sensor_Log(2.0to1.0)'!$E8 -> 0 | AE11: ='[1]ATI_Sensor_Log(2.0to1.0)'!$D8 -> 0 | AF11: =-1*'[1]ATI_Sensor_Log(2.0to1.0)'!$C8 -> 0 | AG11: ='[1]ATI_Sensor_Log(2.0to1.0)'!$B8 -> 0
A12: 0.67321675 | B12: 0.15658333 | C12: 0 | D12: 1.9850789 | E12: 0.19040074 | F12: 0 | G12: 0.00064870692 | H12: -0.0013466317 | I12: 0.08968015 | J12: -0.53976345 | K12: 0.37859005 | L12: 0.0152964 | M12: 0 | N12: 7.9863e-06 | O12: 1.57149e-05 | P12: 0.088698333 | Q12: -0.53453877 | R12: 0.42169224 | S12: 5.13098e-05 | T12: -0.013 | U12: =ABS(G12-N12) -> 0.00064072062 | V12: =ABS(H12-O12) -> 0.0013623466 | W12: =ABS(I12-P12) -> 0.00098181705 | X12: =ABS(J12-Q12) -> 0.0052246851 | Y12: =ABS(K12-R12) -> 0.043102192 | Z12: =ABS(L12-S12) -> 0.01524509 | AB12: ='[1]ATI_Sensor_Log(2.0to1.0)'!$G9 -> 0 | AC12: =-1*'[1]ATI_Sensor_Log(2.0to1.0)'!$F9 -> 0 | AD12: ='[1]ATI_Sensor_Log(2.0to1.0)'!$E9 -> 0 | AE12: ='[1]ATI_Sensor_Log(2.0to1.0)'!$D9 -> 0 | AF12: =-1*'[1]ATI_Sensor_Log(2.0to1.0)'!$C9 -> 0 | AG12: ='[1]ATI_Sensor_Log(2.0to1.0)'!$B9 -> 0
A13: 0.51328966 | B13: 0.18841874 | C13: 0 | D13: 1.9513617 | E13: 0.15918219 | F13: 0 | G13: 0.0021531186 | H13: -0.0018589736 | I13: 0.073820367 | J13: -0.43470159 | K13: 0.22742748 | L13: 0.03358762 | M13: 0 | N13: 0 | O13: 0 | P13: 0.075702147 | Q13: -0.42884206 | R13: 0.28148505 | S13: 0 | T13: 0 | U13: =ABS(G13-N13) -> 0.0021531186 | V13: =ABS(H13-O13) -> 0.0018589736 | W13: =ABS(I13-P13) -> 0.00188178 | X13: =ABS(J13-Q13) -> 0.0058595346 | Y13: =ABS(K13-R13) -> 0.054057564 | Z13: =ABS(L13-S13) -> 0.03358762 | AB13: ='[1]ATI_Sensor_Log(2.0to1.0)'!$G10 -> 0 | AC13: =-1*'[1]ATI_Sensor_Log(2.0to1.0)'!$F10 -> 0 | AD13: ='[1]ATI_Sensor_Log(2.0to1.0)'!$E10 -> 0 | AE13: ='[1]ATI_Sensor_Log(2.0to1.0)'!$D10 -> 0 | AF13: =-1*'[1]ATI_Sensor_Log(2.0to1.0)'!$C10 -> 0 | AG13: ='[1]ATI_Sensor_Log(2.0to1.0)'!$B10 -> 0
A14: 0.419021 | B14: 0.19321867 | C14: 0 | D14: -1.9452887 | E14: 0.07570924 | F14: 0.768 | G14: -0.0015093171 | H14: -0.0022329169 | I14: -0.059763666 | J14: -0.94436967 | K14: -0.32222292 | L14: 0.027182862 | M14: 0.768 | N14: -0.0007306868 | O14: 0.0002127763 | P14: -0.059708396 | Q14: -0.90742565 | R14: -0.38896645 | S14: 0.0059015519 | T14: -0.768 | U14: =ABS(G14-N14) -> 0.00077863028 | V14: =ABS(H14-O14) -> 0.0024456932 | W14: =ABS(I14-P14) -> 5.5269742e-05 | X14: =ABS(J14-Q14) -> 0.036944027 | Y14: =ABS(K14-R14) -> 0.066743531 | Z14: =ABS(L14-S14) -> 0.02128131 | AB14: ='[1]ATI_Sensor_Log(2.0to1.0)'!$G11 -> 0 | AC14: =-1*'[1]ATI_Sensor_Log(2.0to1.0)'!$F11 -> 0 | AD14: ='[1]ATI_Sensor_Log(2.0to1.0)'!$E11 -> 0 | AE14: ='[1]ATI_Sensor_Log(2.0to1.0)'!$D11 -> 0 | AF14: =-1*'[1]ATI_Sensor_Log(2.0to1.0)'!$C11 -> 0 | AG14: ='[1]ATI_Sensor_Log(2.0to1.0)'!$B11 -> 0
A15: 0.34660519 | B15: 0.13028766 | C15: 0 | D15: 2.329639 | E15: 0.24459961 | F15: 0.1 | G15: -0.00030693307 | H15: -9.609526e-05 | I15: 0.03556199 | J15: -0.36243445 | K15: 0.20112582 | L15: 0.0054567307 | M15: 0.1 | N15: -7.94881e-05 | O15: 3.90511e-05 | P15: 0.035514024 | Q15: -0.3677256 | R15: 0.21486411 | S15: 0.0007441016 | T15: -0.1 | U15: =ABS(G15-N15) -> 0.00022744497 | V15: =ABS(H15-O15) -> 0.00013514636 | W15: =ABS(I15-P15) -> 4.7966393e-05 | X15: =ABS(J15-Q15) -> 0.0052911494 | Y15: =ABS(K15-R15) -> 0.013738291 | Z15: =ABS(L15-S15) -> 0.0047126291 | AB15: ='[1]ATI_Sensor_Log(2.0to1.0)'!$G12 -> 0 | AC15: =-1*'[1]ATI_Sensor_Log(2.0to1.0)'!$F12 -> 0 | AD15: ='[1]ATI_Sensor_Log(2.0to1.0)'!$E12 -> 0 | AE15: ='[1]ATI_Sensor_Log(2.0to1.0)'!$D12 -> 0 | AF15: =-1*'[1]ATI_Sensor_Log(2.0to1.0)'!$C12 -> 0 | AG15: ='[1]ATI_Sensor_Log(2.0to1.0)'!$B12 -> 0
A16: 0.37136376 | B16: 0.19169604 | C16: 0 | D16: 1.7061867 | E16: 0.6685239 | F16: 0 | G16: 0.0010567735 | H16: -0.001795731 | I16: 0.064393625 | J16: -0.26715282 | K16: 0.23288587 | L16: 0.018380418 | M16: 0 | N16: 0 | O16: 0 | P16: 0.067136236 | Q16: -0.2250331 | R16: 0.29494572 | S16: 0 | T16: 0 | U16: =ABS(G16-N16) -> 0.0010567735 | V16: =ABS(H16-O16) -> 0.001795731 | W16: =ABS(I16-P16) -> 0.0027426114 | X16: =ABS(J16-Q16) -> 0.042119719 | Y16: =ABS(K16-R16) -> 0.062059857 | Z16: =ABS(L16-S16) -> 0.018380418 | AB16: ='[1]ATI_Sensor_Log(2.0to1.0)'!$G13 -> 0 | AC16: =-1*'[1]ATI_Sensor_Log(2.0to1.0)'!$F13 -> 0 | AD16: ='[1]ATI_Sensor_Log(2.0to1.0)'!$E13 -> 0 | AE16: ='[1]ATI_Sensor_Log(2.0to1.0)'!$D13 -> 0 | AF16: =-1*'[1]ATI_Sensor_Log(2.0to1.0)'!$C13 -> 0 | AG16: ='[1]ATI_Sensor_Log(2.0to1.0)'!$B13 -> 0
... A18: 0.7314164 | B18: 0.10712663 | C18: 0 | D18: -1.2846379 | E18: 0.75296912 | F18: 0.991 | G18: -0.002833806 | H18: -0.0038975424 | I18: -0.052740231 | J18: -0.73136902 | K18: -0.64403772 | L18: 0.035194248 | M18: 0.991 | N18: -0.000759845 | O18: 0.000220555 | P18: -0.060835118 | Q18: -0.56612886 | R18: -0.71153494 | S18: 0.0061324825 | T18: -1.028 | U18: =ABS(G18-N18) -> 0.002073961 | V18: =ABS(H18-O18) -> 0.0041180974 | W18: =ABS(I18-P18) -> 0.0080948865 | X18: =ABS(J18-Q18) -> 0.16524016 | Y18: =ABS(K18-R18) -> 0.067497218 | Z18: =ABS(L18-S18) -> 0.029061765 | AB18: ='[1]ATI_Sensor_Log(2.0to1.0)'!$G15 -> 0 | AC18: =-1*'[1]ATI_Sensor_Log(2.0to1.0)'!$F15 -> 0 | AD18: ='[1]ATI_Sensor_Log(2.0to1.0)'!$E15 -> 0 | AE18: ='[1]ATI_Sensor_Log(2.0to1.0)'!$D15 -> 0 | AF18: =-1*'[1]ATI_Sensor_Log(2.0to1.0)'!$C15 -> 0 | AG18: ='[1]ATI_Sensor_Log(2.0to1.0)'!$B15 -> 0
A19: 0.92824048 | B19: 0.06149902 | C19: 0 | D19: 2.2133732 | E19: 0.49874279 | F19: 0.412 | G19: -0.0027264871 | H19: -0.00029036915 | I19: 0.065401524 | J19: -0.99009567 | K19: 0.68135464 | L19: -0.0097361505 | M19: 0.412 | N19: -0.000380789 | O19: 0.0001194314 | P19: 0.062403555 | Q19: -1.010435 | R19: 0.68763079 | S19: 0.0031303846 | T19: -0.412 | U19: =ABS(G19-N19) -> 0.0023456981 | V19: =ABS(H19-O19) -> 0.00040980055 | W19: =ABS(I19-P19) -> 0.0029979691 | X19: =ABS(J19-Q19) -> 0.020339335 | Y19: =ABS(K19-R19) -> 0.0062761499 | Z19: =ABS(L19-S19) -> 0.012866535 | AB19: ='[1]ATI_Sensor_Log(2.0to1.0)'!$G16 -> 0 | AC19: =-1*'[1]ATI_Sensor_Log(2.0to1.0)'!$F16 -> 0 | AD19: ='[1]ATI_Sensor_Log(2.0to1.0)'!$E16 -> 0 | AE19: ='[1]ATI_Sensor_Log(2.0to1.0)'!$D16 -> 0 | AF19: =-1*'[1]ATI_Sensor_Log(2.0to1.0)'!$C16 -> 0 | AG19: ='[1]ATI_Sensor_Log(2.0to1.0)'!$B16 -> 0 | AI19: `
A20: 0.48677182 | B20: 0.1926011 | C20: 0 | D20: -1.973832 | E20: 0.40514359 | F20: 1.265 | G20: -0.002446743 | H20: -0.0039606718 | I20: -0.065584555 | J20: -1.3344798 | K20: -0.42153305 | L20: 0.030811608 | M20: 1.265 | N20: -0.000759845 | O20: 0.000220555 | P20: -0.074722673 | Q20: -0.87859898 | R20: -0.47921755 | S20: 0.0061324825 | T20: -1.222 | U20: =ABS(G20-N20) -> 0.001686898 | V20: =ABS(H20-O20) -> 0.0041812268 | W20: =ABS(I20-P20) -> 0.0091381179 | X20: =ABS(J20-Q20) -> 0.45588083 | Y20: =ABS(K20-R20) -> 0.057684503 | Z20: =ABS(L20-S20) -> 0.024679125 | AB20: ='[1]ATI_Sensor_Log(2.0to1.0)'!$G17 -> 0 | AC20: =-1*'[1]ATI_Sensor_Log(2.0to1.0)'!$F17 -> 0 | AD20: ='[1]ATI_Sensor_Log(2.0to1.0)'!$E17 -> 0 | AE20: ='[1]ATI_Sensor_Log(2.0to1.0)'!$D17 -> 0 | AF20: =-1*'[1]ATI_Sensor_Log(2.0to1.0)'!$C17 -> 0 | AG20: ='[1]ATI_Sensor_Log(2.0to1.0)'!$B17 -> 0
A21: 0.75984845 | B21: 0.11235321 | C21: 0 | D21: -2.0615692 | E21: 0.03440639 | F21: 0.286 | G21: -0.0022109633 | H21: -0.001399263 | I21: -0.073739819 | J21: -0.77465367 | K21: -0.54947281 | L21: 0.039404124 | M21: 0.286 | N21: -0.0002738758 | O21: 9.09093e-05 | P21: -0.071483594 | Q21: -0.74512941 | R21: -0.60854157 | S21: 0.002283639 | T21: -0.296 | U21: =ABS(G21-N21) -> 0.0019370875 | V21: =ABS(H21-O21) -> 0.0014901723 | W21: =ABS(I21-P21) -> 0.0022562255 | X21: =ABS(J21-Q21) -> 0.029524263 | Y21: =ABS(K21-R21) -> 0.059068765 | Z21: =ABS(L21-S21) -> 0.037120485 | AB21: ='[1]ATI_Sensor_Log(2.0to1.0)'!$G18 -> 0 | AC21: =-1*'[1]ATI_Sensor_Log(2.0to1.0)'!$F18 -> 0 | AD21: ='[1]ATI_Sensor_Log(2.0to1.0)'!$E18 -> 0 | AE21: ='[1]ATI_Sensor_Log(2.0to1.0)'!$D18 -> 0 | AF21: =-1*'[1]ATI_Sensor_Log(2.0to1.0)'!$C18 -> 0 | AG21: ='[1]ATI_Sensor_Log(2.0to1.0)'!$B18 -> 0
A22: 0.06040008 | B22: 0.17999249 | C22: 0 | D22: -2.2005078 | E22: 0.04680562 | F22: 0.125 | G22: -0.00052654784 | H22: -0.0006819627 | I22: -0.0079568028 | J22: -0.14130574 | K22: -0.054839768 | L22: 0.015218697 | M22: 0.125 | N22: -9.89269e-05 | O22: 4.42369e-05 | P22: -0.0062335924 | Q22: -0.14926663 | R22: -0.049555829 | S22: 0.0008980553 | T22: -0.125 | U22: =ABS(G22-N22) -> 0.00042762094 | V22: =ABS(H22-O22) -> 0.0007261996 | W22: =ABS(I22-P22) -> 0.0017232104 | X22: =ABS(J22-Q22) -> 0.0079608894 | Y22: =ABS(K22-R22) -> 0.005283939 | Z22: =ABS(L22-S22) -> 0.014320642 | AB22: ='[1]ATI_Sensor_Log(2.0to1.0)'!$G19 -> 0 | AC22: =-1*'[1]ATI_Sensor_Log(2.0to1.0)'!$F19 -> 0 | AD22: ='[1]ATI_Sensor_Log(2.0to1.0)'!$E19 -> 0 | AE22: ='[1]ATI_Sensor_Log(2.0to1.0)'!$D19 -> 0 | AF22: =-1*'[1]ATI_Sensor_Log(2.0to1.0)'!$C19 -> 0 | AG22: ='[1]ATI_Sensor_Log(2.0to1.0)'!$B19 -> 0
A23: 0.17360725 | B23: 0.1759999 | C23: 0 | D23: -1.7273927 | E23: 0.33001808 | F23: 0.539 | G23: -0.0012194762 | H23: -0.0017251453 | I23: -0.017789617 | J23: -0.53096002 | K23: -0.15755756 | L23: 0.017692722 | M23: 0.539 | N23: -0.000507141 | O23: 0.0001531393 | P23: -0.01815927 | Q23: -0.52423488 | R23: -0.17878596 | S23: 0.0041310839 | T23: -0.539 | U23: =ABS(G23-N23) -> 0.00071233522 | V23: =ABS(H23-O23) -> 0.0018782846 | W23: =ABS(I23-P23) -> 0.00036965312 | X23: =ABS(J23-Q23) -> 0.0067251414 | Y23: =ABS(K23-R23) -> 0.021228399 | Z23: =ABS(L23-S23) -> 0.013561638 | AB23: ='[1]ATI_Sensor_Log(2.0to1.0)'!$G20 -> 0 | AC23: =-1*'[1]ATI_Sensor_Log(2.0to1.0)'!$F20 -> 0 | AD23: ='[1]ATI_Sensor_Log(2.0to1.0)'!$E20 -> 0 | AE23: ='[1]ATI_Sensor_Log(2.0to1.0)'!$D20 -> 0 | AF23: =-1*'[1]ATI_Sensor_Log(2.0to1.0)'!$C20 -> 0 | AG23: ='[1]ATI_Sensor_Log(2.0to1.0)'!$B20 -> 0
A24: 0.10809269 | B24: 0.0923211 | C24: 3.1415927 | D24: 2.1803239 | E24: 0.50234589 | AB24: ='[1]ATI_Sensor_Log(2.0to1.0)'!$G21 -> 0 | AC24: =-1*'[1]ATI_Sensor_Log(2.0to1.0)'!$F21 -> 0 | AD24: ='[1]ATI_Sensor_Log(2.0to1.0)'!$E21 -> 0 | AE24: ='[1]ATI_Sensor_Log(2.0to1.0)'!$D21 -> 0 | AF24: =-1*'[1]ATI_Sensor_Log(2.0to1.0)'!$C21 -> 0 | AG24: ='[1]ATI_Sensor_Log(2.0to1.0)'!$B21 -> 0
A25: 0.9856183 | B25: 0.17793179 | C25: 0 | D25: 1.2977671 | E25: 0.66740032 | AB25: ='[1]ATI_Sensor_Log(2.0to1.0)'!$G22 -> 0 | AC25: =-1*'[1]ATI_Sensor_Log(2.0to1.0)'!$F22 -> 0 | AD25: ='[1]ATI_Sensor_Log(2.0to1.0)'!$E22 -> 0 | AE25: ='[1]ATI_Sensor_Log(2.0to1.0)'!$D22 -> 0 | AF25: =-1*'[1]ATI_Sensor_Log(2.0to1.0)'!$C22 -> 0 | AG25: ='[1]ATI_Sensor_Log(2.0to1.0)'!$B22 -> 0
A26: 0.26891645 | B26: 0.05251121 | C26: 0 | D26: 0.90552483 | E26: 0.03685137 | AB26: ='[1]ATI_Sensor_Log(2.0to1.0)'!$G23 -> 0 | AC26: =-1*'[1]ATI_Sensor_Log(2.0to1.0)'!$F23 -> 0 | AD26: ='[1]ATI_Sensor_Log(2.0to1.0)'!$E23 -> 0 | AE26: ='[1]ATI_Sensor_Log(2.0to1.0)'!$D23 -> 0 | AF26: =-1*'[1]ATI_Sensor_Log(2.0to1.0)'!$C23 -> 0 | AG26: ='[1]ATI_Sensor_Log(2.0to1.0)'!$B23 -> 0
A27: 0.56002419 | B27: 0.18469824 | C27: 3.1415927 | D27: 2.1227517 | E27: 0.13839265 | AB27: ='[1]ATI_Sensor_Log(2.0to1.0)'!$G24 -> 0 | AC27: =-1*'[1]ATI_Sensor_Log(2.0to1.0)'!$F24 -> 0 | AD27: ='[1]ATI_Sensor_Log(2.0to1.0)'!$E24 -> 0 | AE27: ='[1]ATI_Sensor_Log(2.0to1.0)'!$D24 -> 0 | AF27: =-1*'[1]ATI_Sensor_Log(2.0to1.0)'!$C24 -> 0 | AG27: ='[1]ATI_Sensor_Log(2.0to1.0)'!$B24 -> 0
A28: 0.83422354 | B28: 0.17161942 | C28: 3.1415927 | D28: 0.79461192 | E28: 0.62881962 | AB28: ='[1]ATI_Sensor_Log(2.0to1.0)'!$G25 -> 0 | AC28: =-1*'[1]ATI_Sensor_Log(2.0to1.0)'!$F25 -> 0 | AD28: ='[1]ATI_Sensor_Log(2.0to1.0)'!$E25 -> 0 | AE28: ='[1]ATI_Sensor_Log(2.0to1.0)'!$D25 -> 0 | AF28: =-1*'[1]ATI_Sensor_Log(2.0to1.0)'!$C25 -> 0 | AG28: ='[1]ATI_Sensor_Log(2.0to1.0)'!$B25 -> 0
A29: 0.55995869 | B29: 0.05160554 | C29: 0 | D29: 2.1179067 | E29: 0.01202191 | AB29: ='[1]ATI_Sensor_Log(2.0to1.0)'!$G26 -> 0 | AC29: =-1*'[1]ATI_Sensor_Log(2.0to1.0)'!$F26 -> 0 | AD29: ='[1]ATI_Sensor_Log(2.0to1.0)'!$E26 -> 0 | AE29: ='[1]ATI_Sensor_Log(2.0to1.0)'!$D26 -> 0 | AF29: =-1*'[1]ATI_Sensor_Log(2.0to1.0)'!$C26 -> 0 | AG29: ='[1]ATI_Sensor_Log(2.0to1.0)'!$B26 -> 0
A30: 0.44980114 | B30: 0.10200598 | C30: 3.1415927 | D30: 1.768032 | E30: 0.00998814 | AB30: ='[1]ATI_Sensor_Log(2.0to1.0)'!$G27 -> 0 | AC30: =-1*'[1]ATI_Sensor_Log(2.0to1.0)'!$F27 -> 0 | AD30: ='[1]ATI_Sensor_Log(2.0to1.0)'!$E27 -> 0 | AE30: ='[1]ATI_Sensor_Log(2.0to1.0)'!$D27 -> 0 | AF30: =-1*'[1]ATI_Sensor_Log(2.0to1.0)'!$C27 -> 0 | AG30: ='[1]ATI_Sensor_Log(2.0to1.0)'!$B27 -> 0
A31: 0.32506988 | B31: 0.07823982 | C31: 0 | D31: 0.84911296 | E31: 0.13584011 | AB31: ='[1]ATI_Sensor_Log(2.0to1.0)'!$G28 -> 0 | AC31: =-1*'[1]ATI_Sensor_Log(2.0to1.0)'!$F28 -> 0 | AD31: ='[1]ATI_Sensor_Log(2.0to1.0)'!$E28 -> 0 | AE31: ='[1]ATI_Sensor_Log(2.0to1.0)'!$D28 -> 0 | AF31: =-1*'[1]ATI_Sensor_Log(2.0to1.0)'!$C28 -> 0 | AG31: ='[1]ATI_Sensor_Log(2.0to1.0)'!$B28 -> 0
A32: 0.83641872 | B32: 0.17572318 | C32: 0 | D32: 1.836054 | E32: 0.14203721 | AB32: ='[1]ATI_Sensor_Log(2.0to1.0)'!$G29 -> 0 | AC32: =-1*'[1]ATI_Sensor_Log(2.0to1.0)'!$F29 -> 0 | AD32: ='[1]ATI_Sensor_Log(2.0to1.0)'!$E29 -> 0 | AE32: ='[1]ATI_Sensor_Log(2.0to1.0)'!$D29 -> 0 | AF32: =-1*'[1]ATI_Sensor_Log(2.0to1.0)'!$C29 -> 0 | AG32: ='[1]ATI_Sensor_Log(2.0to1.0)'!$B29 -> 0
A33: 0.9265193 | B33: 0.17963874 | C33: 0 | D33: 1.5472841 | E33: 0.36612027 | AB33: ='[1]ATI_Sensor_Log(2.0to1.0)'!$G30 -> 0 | AC33: =-1*'[1]ATI_Sensor_Log(2.0to1.0)'!$F30 -> 0 | AD33: ='[1]ATI_Sensor_Log(2.0to1.0)'!$E30 -> 0 | AE33: ='[1]ATI_Sensor_Log(2.0to1.0)'!$D30 -> 0 | AF33: =-1*'[1]ATI_Sensor_Log(2.0to1.0)'!$C30 -> 0 | AG33: ='[1]ATI_Sensor_Log(2.0to1.0)'!$B30 -> 0
AB34: ='[1]ATI_Sensor_Log(2.0to1.0)'!$G31 -> 0 | AC34: =-1*'[1]ATI_Sensor_Log(2.0to1.0)'!$F31 -> 0 | AD34: ='[1]ATI_Sensor_Log(2.0to1.0)'!$E31 -> 0 | AE34: ='[1]ATI_Sensor_Log(2.0to1.0)'!$D31 -> 0 | AF34: =-1*'[1]ATI_Sensor_Log(2.0to1.0)'!$C31 -> 0 | AG34: ='[1]ATI_Sensor_Log(2.0to1.0)'!$B31 -> 0
AB35: ='[1]ATI_Sensor_Log(2.0to1.0)'!$G32 -> 0 | AC35: =-1*'[1]ATI_Sensor_Log(2.0to1.0)'!$F32 -> 0 | AD35: ='[1]ATI_Sensor_Log(2.0to1.0)'!$E32 -> 0 | AE35: ='[1]ATI_Sensor_Log(2.0to1.0)'!$D32 -> 0 | AF35: =-1*'[1]ATI_Sensor_Log(2.0to1.0)'!$C32 -> 0 | AG35: ='[1]ATI_Sensor_Log(2.0to1.0)'!$B32 -> 0
AB36: ='[1]ATI_Sensor_Log(2.0to1.0)'!$G33 -> 0 | AC36: =-1*'[1]ATI_Sensor_Log(2.0to1.0)'!$F33 -> 0 | AD36: ='[1]ATI_Sensor_Log(2.0to1.0)'!$E33 -> 0 | AE36: ='[1]ATI_Sensor_Log(2.0to1.0)'!$D33 -> 0 | AF36: =-1*'[1]ATI_Sensor_Log(2.0to1.0)'!$C33 -> 0 | AG36: ='[1]ATI_Sensor_Log(2.0to1.0)'!$B33 -> 0
AB37: ='[1]ATI_Sensor_Log(2.0to1.0)'!$G34 -> 0 | AC37: =-1*'[1]ATI_Sensor_Log(2.0to1.0)'!$F34 -> 0 | AD37: ='[1]ATI_Sensor_Log(2.0to1.0)'!$E34 -> 0 | AE37: ='[1]ATI_Sensor_Log(2.0to1.0)'!$D34 -> 0 | AF37: =-1*'[1]ATI_Sensor_Log(2.0to1.0)'!$C34 -> 0 | AG37: ='[1]ATI_Sensor_Log(2.0to1.0)'!$B34 -> 0
AB38: ='[1]ATI_Sensor_Log(2.0to1.0)'!$G35 -> 0 | AC38: =-1*'[1]ATI_Sensor_Log(2.0to1.0)'!$F35 -> 0 | AD38: ='[1]ATI_Sensor_Log(2.0to1.0)'!$E35 -> 0 | AE38: ='[1]ATI_Sensor_Log(2.0to1.0)'!$D35 -> 0 | AF38: =-1*'[1]ATI_Sensor_Log(2.0to1.0)'!$C35 -> 0 | AG38: ='[1]ATI_Sensor_Log(2.0to1.0)'!$B35 -> 0
AB39: ='[1]ATI_Sensor_Log(2.0to1.0)'!$G36 -> 0 | AC39: =-1*'[1]ATI_Sensor_Log(2.0to1.0)'!$F36 -> 0 | AD39: ='[1]ATI_Sensor_Log(2.0to1.0)'!$E36 -> 0 | AE39: ='[1]ATI_Sensor_Log(2.0to1.0)'!$D36 -> 0 | AF39: =-1*'[1]ATI_Sensor_Log(2.0to1.0)'!$C36 -> 0 | AG39: ='[1]ATI_Sensor_Log(2.0to1.0)'!$B36 -> 0
AB40: ='[1]ATI_Sensor_Log(2.0to1.0)'!$G37 -> 0 | AC40: =-1*'[1]ATI_Sensor_Log(2.0to1.0)'!$F37 -> 0 | AD40: ='[1]ATI_Sensor_Log(2.0to1.0)'!$E37 -> 0 | AE40: ='[1]ATI_Sensor_Log(2.0to1.0)'!$D37 -> 0 | AF40: =-1*'[1]ATI_Sensor_Log(2.0to1.0)'!$C37 -> 0 | AG40: ='[1]ATI_Sensor_Log(2.0to1.0)'!$B37 -> 0
AB41: ='[1]ATI_Sensor_Log(2.0to1.0)'!$G38 -> -4.6970417e-06 | AC41: =-1*'[1]ATI_Sensor_Log(2.0to1.0)'!$F38 -> 1.0438451e-05 | AD41: ='[1]ATI_Sensor_Log(2.0to1.0)'!$E38 -> 1.7066902e-06 | AE41: ='[1]ATI_Sensor_Log(2.0to1.0)'!$D38 -> 5.808565e-05 | AF41: =-1*'[1]ATI_Sensor_Log(2.0to1.0)'!$C38 -> -0.00078196364 | AG41: ='[1]ATI_Sensor_Log(2.0to1.0)'!$B38 -> 0.00012485386
AB42: ='[1]ATI_Sensor_Log(2.0to1.0)'!$G39 -> -0.00091163395 | AC42: =-1*'[1]ATI_Sensor_Log(2.0to1.0)'!$F39 -> -0.00108513 | AD42: ='[1]ATI_Sensor_Log(2.0to1.0)'!$E39 -> -0.0025136897 | AE42: ='[1]ATI_Sensor_Log(2.0to1.0)'!$D39 -> -0.1970371 | AF42: =-1*'[1]ATI_Sensor_Log(2.0to1.0)'!$C39 -> -0.1292484 | AG42: ='[1]ATI_Sensor_Log(2.0to1.0)'!$B39 -> 0.0084088072
...

Sheet get_distal_value Validation
G2: 6-Axis FT Sensor | N2: SoRoSim get_distal_value | S2: Distal differences | W2: Sum of distal differences squared
A3: F (N) | B3: s (m) | C3: el (rad) | D3: az (rad) | E3: pre tau (N) | F3: tau (N) | G3: Tx (Nm) | H3: Ty (Nm) | I3: Tz(Nm) | J3: Fx (N) | K3: Fy (N) | L3: Fz (N) | M3: tau (N) | N3: F (N) | O3: s (m) | P3: el (rad) | Q3: az (rad) | R3: tau (N) | S3: F (N) | T3: s (m) | U3: el (rad) | V3: az (rad)
A4: ='get_proximal_value Validation'!A4 -> 0.14182976 | B4: ='get_proximal_value Validation'!B4 -> 0.0720242 | C4: ='get_proximal_value Validation'!C4 -> 0 | D4: ='get_proximal_value Validation'!D4 -> -0.91174491 | E4: ='get_proximal_value Validation'!E4 -> 0.30351324 | F4: ='get_proximal_value Validation'!F4 -> 0.304 | G4: ='get_proximal_value Validation'!G4 -> -0.00091163395 | H4: ='get_proximal_value Validation'!H4 -> -0.00108513 | ... M4: ='get_proximal_value Validation'!M4 -> 0.304 | N4: 0.1552202 | O4: 0.071353471 | P4: 0.039434929 | Q4: -0.97199648 | R4: 0.304 | S4: =N4-A4 -> 0.013390441 | T4: =O4-B4 -> -0.0006707295 | U4: =P4-C4 -> 0.039434929 | V4: =Q4-D4 -> -0.060251568 | W4: =SUM(S4:V4)^2 -> 6.5560233e-05
A5: ='get_proximal_value Validation'!A5 -> 0.60745837 | B5: ='get_proximal_value Validation'!B5 -> 0.09706437 | C5: ='get_proximal_value Validation'!C5 -> 0 | D5: ='get_proximal_value Validation'!D5 -> 1.7524402 | E5: ='get_proximal_value Validation'!E5 -> 0.57808471 | F5: ='get_proximal_value Validation'!F5 -> 0.378 | G5: ='get_proximal_value Validation'!G5 -> 0.00057326164 | H5: ='get_proximal_value Validation'!H5 -> -0.00084196427 | ... M5: ='get_proximal_value Validation'!M5 -> 0.378 | N5: 0.5529468 | O5: 0.10493461 | P5: 0.026531147 | Q5: 1.7006167 | R5: 0.378 | S5: =N5-A5 -> -0.054511573 | T5: =O5-B5 -> 0.007870237 | U5: =P5-C5 -> 0.026531147 | V5: =Q5-D5 -> -0.051823495 | W5: =SUM(S5:V5)^2 -> 0.0051744549
A6: ='get_proximal_value Validation'!A6 -> 0.88365584 | B6: ='get_proximal_value Validation'!B6 -> 0.05400872 | C6: ='get_proximal_value Validation'!C6 -> 0 | D6: ='get_proximal_value Validation'!D6 -> -0.91161608 | E6: ='get_proximal_value Validation'!E6 -> 0.57138001 | F6: ='get_proximal_value Validation'!F6 -> 0.617 | G6: ='get_proximal_value Validation'!G6 -> -0.0023927321 | H6: ='get_proximal_value Validation'!H6 -> -0.0034488118 | ... M6: ='get_proximal_value Validation'!M6 -> 0.617 | N6: 0.87128266 | O6: 0.054308712 | P6: 0.033026538 | Q6: -0.87068177 | R6: 0.617 | S6: =N6-A6 -> -0.012373184 | T6: =O6-B6 -> 0.0002999916 | U6: =P6-C6 -> 0.033026538 | V6: =Q6-D6 -> 0.040934307 | W6: =SUM(S6:V6)^2 -> 0.0038300814
A7: ='get_proximal_value Validation'!A7 -> 0.09252606 | B7: ='get_proximal_value Validation'!B7 -> 0.07631133 | C7: ='get_proximal_value Validation'!C7 -> 0 | D7: ='get_proximal_value Validation'!D7 -> -1.8008197 | E7: ='get_proximal_value Validation'!E7 -> 0.20000874 | F7: ='get_proximal_value Validation'!F7 -> 0.21 | G7: ='get_proximal_value Validation'!G7 -> -0.00044885097 | H7: ='get_proximal_value Validation'!H7 -> -0.00013324013 | ... M7: ='get_proximal_value Validation'!M7 -> 0.21 | N7: 0.10168109 | O7: 0.080464167 | P7: 0.047018613 | Q7: -1.8110142 | R7: 0.21 | S7: =N7-A7 -> 0.0091550341 | T7: =O7-B7 -> 0.0041528374 | U7: =P7-C7 -> 0.047018613 | V7: =Q7-D7 -> -0.01019447 | W7: =SUM(S7:V7)^2 -> 0.0025132188
A8: ='get_proximal_value Validation'!A8 -> 0.26582482 | B8: ='get_proximal_value Validation'!B8 -> 0.11576127 | C8: ='get_proximal_value Validation'!C8 -> 0 | D8: ='get_proximal_value Validation'!D8 -> 1.628884 | E8: ='get_proximal_value Validation'!E8 -> 0.56468087 | F8: ='get_proximal_value Validation'!F8 -> 0.43 | G8: ='get_proximal_value Validation'!G8 -> 0.00039714668 | H8: ='get_proximal_value Validation'!H8 -> -0.0008116056 | ... M8: ='get_proximal_value Validation'!M8 -> 0.43 | N8: 0.24965929 | O8: 0.12562618 | P8: 0.043942473 | Q8: 1.4859878 | R8: 0.43 | S8: =N8-A8 -> -0.016165532 | T8: =O8-B8 -> 0.0098649112 | U8: =P8-C8 -> 0.043942473 | V8: =Q8-D8 -> -0.14289625 | W8: =SUM(S8:V8)^2 -> 0.011078487
A9: ='get_proximal_value Validation'!A9 -> 0.45 | B9: ='get_proximal_value Validation'!B9 -> 0.17373299 | C9: ='get_proximal_value Validation'!C9 -> 0 | D9: ='get_proximal_value Validation'!D9 -> -2.0085329 | E9: ='get_proximal_value Validation'!E9 -> 0.2667928 | F9: ='get_proximal_value Validation'!F9 -> 0.768 | G9: ='get_proximal_value Validation'!G9 -> -0.0028824871 | H9: ='get_proximal_value Validation'!H9 -> -0.0026444176 | ... M9: ='get_proximal_value Validation'!M9 -> 0.768 | N9: 0.40711207 | O9: 0.2 | P9: 0.12081072 | Q9: -2.1884714 | R9: 0.768 | S9: =N9-A9 -> -0.042887932 | T9: =O9-B9 -> 0.02626701 | U9: =P9-C9 -> 0.12081072 | V9: =Q9-D9 -> -0.17993851 | W9: =SUM(S9:V9)^2 -> 0.0057378667
A10: ='get_proximal_value Validation'!A10 -> 0.17540121 | B10: ='get_proximal_value Validation'!B10 -> 0.14381803 | C10: ='get_proximal_value Validation'!C10 -> 0 | D10: ='get_proximal_value Validation'!D10 -> -1.1118403 | E10: ='get_proximal_value Validation'!E10 -> 0.38917187 | F10: ='get_proximal_value Validation'!F10 -> 0.497 | G10: ='get_proximal_value Validation'!G10 -> -0.0014106487 | H10: ='get_proximal_value Validation'!H10 -> -0.0025641322 | ... M10: ='get_proximal_value Validation'!M10 -> 0.497 | N10: 0.1850449 | O10: 0.15870553 | P10: 0.086093612 | Q10: -0.99703021 | R10: 0.497 | S10: =N10-A10 -> 0.0096436943 | T10: =O10-B10 -> 0.014887497 | U10: =P10-C10 -> 0.086093612 | V10: =Q10-D10 -> 0.11481007 | W10: =SUM(S10:V10)^2 -> 0.05082088
A11: ='get_proximal_value Validation'!A11 -> 0.91138323 | B11: ='get_proximal_value Validation'!B11 -> 0.10326727 | C11: ='get_proximal_value Validation'!C11 -> 0 | D11: ='get_proximal_value Validation'!D11 -> -2.1051698 | E11: ='get_proximal_value Validation'!E11 -> 0.01130865 | F11: ='get_proximal_value Validation'!F11 -> 0.23 | G11: ='get_proximal_value Validation'!G11 -> -0.0020074253 | H11: ='get_proximal_value Validation'!H11 -> -0.00045337807 | ... M11: ='get_proximal_value Validation'!M11 -> 0.23 | N11: 0.86172973 | O11: 0.10789736 | P11: 0.057107836 | Q11: -2.0893219 | R11: 0.23 | S11: =N11-A11 -> -0.049653504 | T11: =O11-B11 -> 0.0046300867 | U11: =P11-C11 -> 0.057107836 | V11: =Q11-D11 -> 0.015847852 | W11: =SUM(S11:V11)^2 -> 0.00078021181
A12: ='get_proximal_value Validation'!A12 -> 0.67321675 | B12: ='get_proximal_value Validation'!B12 -> 0.15658333 | C12: ='get_proximal_value Validation'!C12 -> 0 | D12: ='get_proximal_value Validation'!D12 -> 1.9850789 | E12: ='get_proximal_value Validation'!E12 -> 0.19040074 | F12: ='get_proximal_value Validation'!F12 -> 0 | G12: ='get_proximal_value Validation'!G12 -> 0.00064870692 | H12: ='get_proximal_value Validation'!H12 -> -0.0013466317 | ... M12: ='get_proximal_value Validation'!M12 -> 0 | N12: 0.6595487 | O12: 0.16738955 | P12: 0.036041738 | Q12: 1.9652106 | R12: 0 | S12: =N12-A12 -> -0.013668049 | T12: =O12-B12 -> 0.010806225 | U12: =P12-C12 -> 0.036041738 | V12: =Q12-D12 -> -0.019868268 | W12: =SUM(S12:V12)^2 -> 0.00017719993
A13: ='get_proximal_value Validation'!A13 -> 0.51328966 | B13: ='get_proximal_value Validation'!B13 -> 0.18841874 | C13: ='get_proximal_value Validation'!C13 -> 0 | D13: ='get_proximal_value Validation'!D13 -> 1.9513617 | E13: ='get_proximal_value Validation'!E13 -> 0.15918219 | F13: ='get_proximal_value Validation'!F13 -> 0 | G13: ='get_proximal_value Validation'!G13 -> 0.0021531186 | H13: ='get_proximal_value Validation'!H13 -> -0.0018589736 | ... M13: ='get_proximal_value Validation'!M13 -> 0 | N13: 0.49264698 | O13: 0.2 | P13: 0.12149234 | Q13: 2.0402252 | R13: 0 | S13: =N13-A13 -> -0.020642682 | T13: =O13-B13 -> 0.01158126 | U13: =P13-C13 -> 0.12149234 | V13: =Q13-D13 -> 0.088863525 | W13: =SUM(S13:V13)^2 -> 0.040519451
A14: ='get_proximal_value Validation'!A14 -> 0.419021 | B14: ='get_proximal_value Validation'!B14 -> 0.19321867 | C14: ='get_proximal_value Validation'!C14 -> 0 | D14: ='get_proximal_value Validation'!D14 -> -1.9452887 | E14: ='get_proximal_value Validation'!E14 -> 0.07570924 | F14: ='get_proximal_value Validation'!F14 -> 0.768 | G14: ='get_proximal_value Validation'!G14 -> -0.0015093171 | H14: ='get_proximal_value Validation'!H14 -> -0.0022329169 | ... M14: ='get_proximal_value Validation'!M14 -> 0.768 | N14: 0.38119508 | O14: 0.2 | P14: 0.072169631 | Q14: -2.2004415 | R14: 0.768 | S14: =N14-A14 -> -0.037825917 | T14: =O14-B14 -> 0.00678133 | U14: =P14-C14 -> 0.072169631 | V14: =Q14-D14 -> -0.25515282 | W14: =SUM(S14:V14)^2 -> 0.04580789
A15: ='get_proximal_value Validation'!A15 -> 0.34660519 | B15: ='get_proximal_value Validation'!B15 -> 0.13028766 | C15: ='get_proximal_value Validation'!C15 -> 0 | D15: ='get_proximal_value Validation'!D15 -> 2.329639 | E15: ='get_proximal_value Validation'!E15 -> 0.24459961 | F15: ='get_proximal_value Validation'!F15 -> 0.1 | G15: ='get_proximal_value Validation'!G15 -> -0.00030693307 | H15: ='get_proximal_value Validation'!H15 -> -9.609526e-05 | ... M15: ='get_proximal_value Validation'!M15 -> 0.1 | N15: 0.33444876 | O15: 0.13783737 | P15: 0.015982782 | Q15: 2.3345412 | R15: 0.1 | S15: =N15-A15 -> -0.012156426 | T15: =O15-B15 -> 0.0075497093 | U15: =P15-C15 -> 0.015982782 | V15: =Q15-D15 -> 0.004902277 | W15: =SUM(S15:V15)^2 -> 0.00026498444
... A23: ='get_proximal_value Validation'!A23 -> 0.17360725 | B23: ='get_proximal_value Validation'!B23 -> 0.1759999 | C23: ='get_proximal_value Validation'!C23 -> 0 | D23: ='get_proximal_value Validation'!D23 -> -1.7273927 | E23: ='get_proximal_value Validation'!E23 -> 0.33001808 | F23: ='get_proximal_value Validation'!F23 -> 0.539 | G23: ='get_proximal_value Validation'!G23 -> -0.0012194762 | H23: ='get_proximal_value Validation'!H23 -> -0.0017251453 | ... M23: ='get_proximal_value Validation'!M23 -> 0.539 | N23: 0.15403878 | O23: 0.2 | P23: 0.088658265 | Q23: -1.834518 | R23: 0.539 | S23: =N23-A23 -> -0.019568466 | T23: =O23-B23 -> 0.0240001 | U23: =P23-C23 -> 0.088658265 | V23: =Q23-D23 -> -0.10712537 | W23: =SUM(S23:V23)^2 -> 0.00019699456
A24: ='get_proximal_value Validation'!A24 -> 0.10809269 | B24: ='get_proximal_value Validation'!B24 -> 0.0923211 | C24: ='get_proximal_value Validation'!C24 -> 3.1415927 | D24: ='get_proximal_value Validation'!D24 -> 2.1803239 | E24: ='get_proximal_value Validation'!E24 -> 0.50234589 | F24: ='get_proximal_value Validation'!F24 -> 0
A25: ='get_proximal_value Validation'!A25 -> 0.9856183 | B25: ='get_proximal_value Validation'!B25 -> 0.17793179 | C25: ='get_proximal_value Validation'!C25 -> 0 | D25: ='get_proximal_value Validation'!D25 -> 1.2977671 | E25: ='get_proximal_value Validation'!E25 -> 0.66740032 | F25: ='get_proximal_value Validation'!F25 -> 0
A26: ='get_proximal_value Validation'!A26 -> 0.26891645 | B26: ='get_proximal_value Validation'!B26 -> 0.05251121 | C26: ='get_proximal_value Validation'!C26 -> 0 | D26: ='get_proximal_value Validation'!D26 -> 0.90552483 | E26: ='get_proximal_value Validation'!E26 -> 0.03685137 | F26: ='get_proximal_value Validation'!F26 -> 0
A27: ='get_proximal_value Validation'!A27 -> 0.56002419 | B27: ='get_proximal_value Validation'!B27 -> 0.18469824 | C27: ='get_proximal_value Validation'!C27 -> 3.1415927 | D27: ='get_proximal_value Validation'!D27 -> 2.1227517 | E27: ='get_proximal_value Validation'!E27 -> 0.13839265 | F27: ='get_proximal_value Validation'!F27 -> 0
A28: ='get_proximal_value Validation'!A28 -> 0.83422354 | B28: ='get_proximal_value Validation'!B28 -> 0.17161942 | C28: ='get_proximal_value Validation'!C28 -> 3.1415927 | D28: ='get_proximal_value Validation'!D28 -> 0.79461192 | E28: ='get_proximal_value Validation'!E28 -> 0.62881962 | F28: ='get_proximal_value Validation'!F28 -> 0
A29: ='get_proximal_value Validation'!A29 -> 0.55995869 | B29: ='get_proximal_value Validation'!B29 -> 0.05160554 | C29: ='get_proximal_value Validation'!C29 -> 0 | D29: ='get_proximal_value Validation'!D29 -> 2.1179067 | E29: ='get_proximal_value Validation'!E29 -> 0.01202191 | F29: ='get_proximal_value Validation'!F29 -> 0
A30: ='get_proximal_value Validation'!A30 -> 0.44980114 | B30: ='get_proximal_value Validation'!B30 -> 0.10200598 | C30: ='get_proximal_value Validation'!C30 -> 3.1415927 | D30: ='get_proximal_value Validation'!D30 -> 1.768032 | E30: ='get_proximal_value Validation'!E30 -> 0.00998814 | F30: ='get_proximal_value Validation'!F30 -> 0
A31: ='get_proximal_value Validation'!A31 -> 0.32506988 | B31: ='get_proximal_value Validation'!B31 -> 0.07823982 | C31: ='get_proximal_value Validation'!C31 -> 0 | D31: ='get_proximal_value Validation'!D31 -> 0.84911296 | E31: ='get_proximal_value Validation'!E31 -> 0.13584011 | F31: ='get_proximal_value Validation'!F31 -> 0
A32: ='get_proximal_value Validation'!A32 -> 0.83641872 | B32: ='get_proximal_value Validation'!B32 -> 0.17572318 | C32: ='get_proximal_value Validation'!C32 -> 0 | D32: ='get_proximal_value Validation'!D32 -> 1.836054 | E32: ='get_proximal_value Validation'!E32 -> 0.14203721 | F32: ='get_proximal_value Validation'!F32 -> 0
A33: ='get_proximal_value Validation'!A33 -> 0.9265193 | B33: ='get_proximal_value Validation'!B33 -> 0.17963874 | C33: ='get_proximal_value Validation'!C33 -> 0 | D33: ='get_proximal_value Validation'!D33 -> 1.5472841 | E33: ='get_proximal_value Validation'!E33 -> 0.36612027 | F33: ='get_proximal_value Validation'!F33 -> 0
A34: ='get_proximal_value Validation'!A34 -> 0 | B34: ='get_proximal_value Validation'!B34 -> 0 | C34: ='get_proximal_value Validation'!C34 -> 0 | D34: ='get_proximal_value Validation'!D34 -> 0 | E34: ='get_proximal_value Validation'!E34 -> 0 | F34: ='get_proximal_value Validation'!F34 -> 0
A35: ='get_proximal_value Validation'!A35 -> 0 | B35: ='get_proximal_value Validation'!B35 -> 0 | C35: ='get_proximal_value Validation'!C35 -> 0 | D35: ='get_proximal_value Validation'!D35 -> 0 | E35: ='get_proximal_value Validation'!E35 -> 0 | F35: ='get_proximal_value Validation'!F35 -> 0
... A40: ='get_proximal_value Validation'!A40 -> 0 | B40: ='get_proximal_value Validation'!B40 -> 0 | C40: ='get_proximal_value Validation'!C40 -> 0 | D40: ='get_proximal_value Validation'!D40 -> 0 | E40: ='get_proximal_value Validation'!E40 -> 0 | F40: ='get_proximal_value Validation'!F40 -> 0
A47: ='get_proximal_value Validation'!A47 -> 0 | B47: ='get_proximal_value Validation'!B47 -> 0 | C47: ='get_proximal_value Validation'!C47 -> 0 | D47: ='get_proximal_value Validation'!D47 -> 0 | F47: ='get_proximal_value Validation'!F47 -> 0 | G47: 0 | H47: 0 | I47: 0 | J47: 0 | K47: 0 | L47: 0
A48: ='get_proximal_value Validation'!A48 -> 0 | B48: ='get_proximal_value Validation'!B48 -> 0 | C48: ='get_proximal_value Validation'!C48 -> 0 | D48: ='get_proximal_value Validation'!D48 -> 0 | F48: ='get_proximal_value Validation'!F48 -> 0 | G48: 0 | H48: 0 | I48: 0 | J48: 0 | K48: 0 | L48: 0
A49: ='get_proximal_value Validation'!A49 -> 0 | B49: ='get_proximal_value Validation'!B49 -> 0 | C49: ='get_proximal_value Validation'!C49 -> 0 | D49: ='get_proximal_value Validation'!D49 -> 0 | F49: ='get_proximal_value Validation'!F49 -> 0 | G49: 0 | H49: 0 | I49: 0 | J49: 0 | K49: 0 | L49: 0 | S49: Mean error
A50: ='get_proximal_value Validation'!A50 -> 0 | B50: ='get_proximal_value Validation'!B50 -> 0 | C50: ='get_proximal_value Validation'!C50 -> 0 | D50: ='get_proximal_value Validation'!D50 -> 0 | F50: ='get_proximal_value Validation'!F50 -> 0 | G50: 0 | H50: 0 | I50: 0 | J50: 0 | K50: 0 | L50: 0 | S50: =AVERAGE(S4:S48) -> -0.0096472597 | T50: =AVERAGE(T4:T48) -> 0.0075463758 | U50: =AVERAGE(U4:U48) -> 0.065529938 | V50: =AVERAGE(V4:V48) -> -0.060887704
A51: ='get_proximal_value Validation'!A51 -> 0 | B51: ='get_proximal_value Validation'!B51 -> 0 | C51: ='get_proximal_value Validation'!C51 -> 0 | D51: ='get_proximal_value Validation'!D51 -> 0 | F51: ='get_proximal_value Validation'!F51 -> 0 | G51: 0 | H51: 0 | I51: 0 | J51: 0 | K51: 0 | L51: 0 | S51: stdev error
A52: ='get_proximal_value Validation'!A52 -> 0 | B52: ='get_proximal_value Validation'!B52 -> 0 | C52: ='get_proximal_value Validation'!C52 -> 0 | D52: ='get_proximal_value Validation'!D52 -> 0 | F52: ='get_proximal_value Validation'!F52 -> 0 | G52: 0 | H52: 0 | I52: 0 | J52: 0 | K52: 0 | L52: 0 | S52: =_xlfn.STDEV.S(S4:S48) -> 0.060123298 | T52: =_xlfn.STDEV.S(T4:T48) -> 0.0081254761 | U52: =_xlfn.STDEV.S(U4:U48) -> 0.051543813 | V52: =_xlfn.STDEV.S(V4:V48) -> 0.21212942
S53: Abs Mean error
S54: {=AVERAGE(ABS(S4:S23))} -> 0.035320439 | T54: {=AVERAGE(ABS(T4:T23))} -> 0.008651273 | U54: {=AVERAGE(ABS(U4:U23))} -> 0.067006376 | V54: {=AVERAGE(ABS(V4:V23))} -> 0.13233102
